Workbook
Name form02_11_1__100: '[1]111'!#REF!
Name form02_11_1__101: '[1]111'!#REF!
Name form02_11_1__102: '[1]111'!#REF!
Name form02_11_1__107: '[1]111'!#REF!
Name form02_11_1__108: '[1]111'!#REF!
Name form02_11_1__109: '[1]111'!#REF!
Name form02_11_1__11: '[1]111'!#REF!
Name form02_11_1__110: '[1]111'!#REF!
Name form02_11_1__115: '[1]111'!#REF!
Name form02_11_1__116: '[1]111'!#REF!
Name form02_11_1__117: '[1]111'!#REF!
Name form02_11_1__118: '[1]111'!#REF!
Name form02_11_1__12: '[1]111'!#REF!
Name form02_11_1__123: '[1]111'!#REF!
Name form02_11_1__124: '[1]111'!#REF!
Name form02_11_1__125: '[1]111'!#REF!
Name form02_11_1__126: '[1]111'!#REF!
Name form02_11_1__13: '[1]111'!#REF!
Name form02_11_1__131: '[1]111'!#REF!
Name form02_11_1__132: '[1]111'!#REF!
Name form02_11_1__133: '[1]111'!#REF!
Name form02_11_1__134: '[1]111'!#REF!
Name form02_11_1__139: '[1]111'!#REF!
Name form02_11_1__14: '[1]111'!#REF!
Name form02_11_1__140: '[1]111'!#REF!
Name form02_11_1__141: '[1]111'!#REF!
Name form02_11_1__142: '[1]111'!#REF!
Name form02_11_1__147: '[1]111'!#REF!
Name form02_11_1__148: '[1]111'!#REF!
Name form02_11_1__149: '[1]111'!#REF!
Name form02_11_1__150: '[1]111'!#REF!
Name form02_11_1__155: '[1]111'!#REF!
Name form02_11_1__156: '[1]111'!#REF!
Name form02_11_1__157: '[1]111'!#REF!
Name form02_11_1__158: '[1]111'!#REF!
Name form02_11_1__163: '[1]111'!#REF!
Name form02_11_1__164: '[1]111'!#REF!
Name form02_11_1__165: '[1]111'!#REF!
Name form02_11_1__166: '[1]111'!#REF!
Name form02_11_1__171: '[1]111'!#REF!
Name form02_11_1__172: '[1]111'!#REF!
Name form02_11_1__173: '[1]111'!#REF!
Name form02_11_1__174: '[1]111'!#REF!
Name form02_11_1__19: '[1]111'!#REF!
Name form02_11_1__20: '[1]111'!#REF!
Name form02_11_1__21: '[1]111'!#REF!
Name form02_11_1__22: '[1]111'!#REF!
Name form02_11_1__27: '[1]111'!#REF!
Name form02_11_1__28: '[1]111'!#REF!
Name form02_11_1__29: '[1]111'!#REF!
Name form02_11_1__30: '[1]111'!#REF!
Name form02_11_1__35: '[1]111'!#REF!
Name form02_11_1__36: '[1]111'!#REF!
Name form02_11_1__37: '[1]111'!#REF!
Name form02_11_1__38: '[1]111'!#REF!
Name form02_11_1__43: '[1]111'!#REF!
Name form02_11_1__44: '[1]111'!#REF!
Name form02_11_1__45: '[1]111'!#REF!
Name form02_11_1__46: '[1]111'!#REF!
Name form02_11_1__51: '[1]111'!#REF!

Sheet map
A2: 2003 | B2: Product Market | C2: Product Submarkets | D2: Geographic Markets | E2: Excel
A5: 03-1XX: Reporting Entity Profiles (steve.malowany@crtc.gc.ca, 819-953-2167)
A6: 03-110 | B6: Corporate Information | C6: - | D6: Canada | E6: 03-1XX-EN.XLS
A7: 03-111 | B7: Group Information | C7: - | D7: Canada | E7: 03-1XX-EN.XLS
A8: 03-120 | B8: Services Sold | C8: - | D8: Canada | E8: 03-1XX-EN.XLS
A9: 03-121 | B9: Facilities Managed | C9: - | D9: Canada | E9: 03-1XX-EN.XLS
A11: 03-2XX: Administrative (valerie.plaskacz@crtc.gc.ca, 819-997-4589)
A12: 03-210 | B12: Response Comments | C12: - | D12: Canada | E12: 03-2XX-EN.XLS
A13: 03-220 | B13: Data Source by Work Unit | C13: - | D13: Canada | E13: 03-2XX-EN.XLS
A15: 03-3XX: Financial (steve.malowany@crtc.gc.ca, 819-953-2167)
A16: 03-310 | B16: Income Statement | C16: - | D16: Canada | E16: 03-3XX-EN.XLS
A17: 03-311 | B17: Operating Revenues | C17: Data & Private Line; Internet | D17: Canada | E17: 03-3XX-EN.XLS
A18: 03-312 | B18: Operating Revenues | C18: Local & Access | D18: Canada | E18: 03-3XX-EN.XLS
A19: 03-313 | B19: Operating Revenues | C19: Long Distance | D19: Canada | E19: 03-3XX-EN.XLS
A20: 03-314 | B20: Operating Revenues | C20: Mobile & Paging | D20: Canada | E20: 03-3XX-EN.XLS
A21: 03-315 | B21: Operating Revenues | C21: Business (S-M-L-VL) | D21: Canada | E21: 03-3XX-EN.XLS
A22: 03-316 | B22: Intercarrier Expenses | C22: - | D22: Canada | E22: 03-3XX-EN.XLS
A23: 03-320 | B23: Balance Sheet | C23: - | D23: Canada | E23: 03-3XX-EN.XLS
A24: 03-321 | B24: Capital Expenditures | C24: - | D24: Canada | E24: 03-3XX-EN.XLS
A26: 03-4XX: Data and Private Line (john.paoletti@crtc.gc.ca, 819-997-4588)
A27: 03-410 | B27: Short-Haul | C27: Metropolitan Area Networks | D27: Cities | E27: 03-4XX-EN.XLS
A28: 03-411 | B28: Long-Haul | C28: Lit Fibre Routes | D28: Canada | E28: 03-4XX-EN.XLS
A29: 03-412 | B29: Long-Haul | C29: Private Line Terrestrial | D29: Canada | E29: 03-4XX-EN.XLS
A30: 03-413 | B30: Long-Haul | C30: Private Line Satellite | D30: Canada | E30: 03-4XX-EN.XLS
A31: 03-414 | B31: Data Link | C31: - | D31: Canada | E31: 03-4XX-EN.XLS
A33: 03-5XX: Internet (bram.abramson@crtc.gc.ca, 819-997-4489)
A34: 03-510 | B34: Internet Access | D34: Canada | E34: 03-5XX-EN.XLS
A35: 03-511 | B35: Internet Access | C35: DSL and Cable Access | D35: Canada | E35: 03-5XX-EN.XLS
A36: 03-512 | B36: Internet Access | C36: Residential High-Speed | D36: Postal Codes | E36: 03-5XX-EN.XLS
A37: 03-520 | B37: Internet Transport | C37: - | D37: Cities | E37: 03-5XX-EN.XLS
A39: 03-6XX: Local & Access (valerie.plaskacz@crtc.gc.ca, 819-997-4589)
A40: 03-610 | B40: Owned, Leased, Rebilled Facilities | C40: - | D40: Provinces & Territories | E40: 03-610-EN.XLS
A41: 03-611 | B41: NAS | C41: - | D41: Cities | E41: 03-611-EN.XLS
A43: 03-7XX: Long Distance (gregory.campbell@crtc.gc.ca, 819-953-5672)
A44: 03-710 | B44: Long Distance Traffic | C44: Billed Wireline Minutes | D44: Regions | E44: 03-710-EN.XLS
A45: 03-720 | B45: Long Distance Traffic | C45: Settlement and Interconnection | D45: Canada | E45: 03-72X-EN.XLS
A46: 03-721 | B46: International Traffic | C46: Billed Minutes | D46: Canada | E46: 03-72X-EN.XLS
A47: 03-722 | B47: International Traffic | C47: Carried Minutes | D47: Canada | E47: 03-72X-EN.XLS
A49: 03-8XX: Mobile & Paging (lizette.pepin@crtc.gc.ca, 819-953-8735)
A50: 03-810 | B50: Voice | C50: Subscriptions | D50: Regions | E50: 03-810-EN.XLS
...

Sheet Instructions
B2: 1) | C2: Coordination: Please ensure that all definitions and interpretations correspond to published guidelines. All guidelines, forms, glossary, and other instructions are available for download at <http://www.crtc.gc.ca/Part VII/eng/2003/monitor/index_03.htm>. The CRTC's telecom monitoring team may be contacted by e-mail (telinfo@crtc.gc.ca) or by telephone (+1 819 997 4597).
B3: 2) | C3: Estimates: Where precise data are not available or cannot be obtained, use best estimates. If estimates are used, record the estimation methodology on Form 03-210, making appropriate reference to form and cell numbers.
B4: 3) | C4: Form integrity: Each form includes shaded and non-shaded areas. Please provide the data requested in the shaded areas only: do not alter the form by adding, deleting, merging, or otherwise manipulating individual cells.
B5: 4) | C5: Period: Complete each form for year-end 31 December except where otherwise noted. Information should be provided for the reporting company, including any companies purchased or merged with it prior to 31 December 2002. However, separate forms are to be provided for any company acquired that is still operating as a legal entity on 31 December 2002.
B6: 5) | C6: Revenues: Report revenues net of discounts, returns or allowances, promotional offers, and rebates. These revenues should exclude federal or provincial taxes collected for remittance to a government agency (sales and excise tax, GST, PST, HST, etc.). Goods and services sales denominated in foreign currencies should be translated to Canadian dollars at the exchange rate at the time of the transaction. For example, dollars are to be reported in whole dollars, minutes in whole minutes, etc.
B7: 6) | C7: Scalors: Bandwidth amounts should be reported in millions of bits per second (Mbps). All other measures should be reported in unscaled units, except where otherwise specified.
B8: 7) | C8: Submission: Completed forms should be submitted either by e-mail, to telinfo_form@crtc.gc.ca, or on diskette or paper, to Telecom Monitoring, CRTC, Ottawa, Ontario, K1A 0N2 (courier: 1 Promenade du Portage, Hull, Québec, J8X 4B1). Forms are due by 15 May 2003.
B9: 8) | C9: Bundled Services: When providing revenues for services that are bundled with other services, please provide an explanation of how the revenues were "unbundled". Provide this explanation with appropriate references in Form 03-210.

Sheet 310
A1: FORM: 03-310 | G1: FINANCIAL
A3: Form Type: | D3: Financial | F3: Entity Name:
A4: Form Sub-type: | D4: Income Statement
A5: Reporting Basis: | D5: Total Company (Non-Consol.) | F5: Entity ID#:
A6: Geographic Market: | D6: Canada
A7: Year: | D7: 2002
B9: Note: | D9: Bundled Services: When providing revenues for a service that is bundled with other services, please provide an explanation of how the revenues where "unbundled". Provide this explanation with appropriate reference in Form 03-210.
D11: Please answer the following questions. | G11: Yes = 1 / No = 0
D12: A) Have you filed your 2002 financial statements with the CRTC?
D13: B) Are your financial statements available on the web?
D15: What were your financial results?
G16: (a) | H16: (b) | I16: (c) = (a + b)
B17: Income Statement
B19: Operating Revenues | G19: Wireline & Fixed Wireless | H19: Wireless | I19: Total
A20: 1 | C20: Data & Private Line | F20: Form 03-311, cell 11(g) | G20: ='311'!L32 -> 0 | I20: =G20 -> 0
A21: =A20+1 -> 2 | C21: Internet | F21: Form 03-311, cell 22(g) | G21: ='311'!L48 -> 0 | I21: =G21 -> 0
A22: =A21+1 -> 3 | C22: Local & Access | F22: Form 03-312, cell 22(g) | G22: ='312'!L41 -> 0 | I22: =G22 -> 0
A23: =A22+1 -> 4 | C23: Long Distance | F23: Form 03-313, cell 9(g) | G23: ='313'!L28 -> 0 | I23: =G23 -> 0
A24: =A23+1 -> 5 | C24: Mobile & Paging | F24: Form 03-314, cell 15(e) | H24: ='314'!K38 -> 0 | I24: =H24 -> 0
A25: =A24+1 -> 6 | C25: Non-Telecommunications (Broadcasting, fleet rental, etc.)
A26: =A25+1 -> 7 | E26: Total Operating Revenues | F26: (sum 1 to 6) | G26: =SUM(G20:G23) -> 0 | H26: =H24 -> 0 | I26: =SUM(I20:I25) -> 0
B27: Operating Expenses | G27: Wireline & Fixed Wireless | H27: Wireless
A28: =A26+1 -> 8 | C28: Intercarrier Expenses | F28: Form 03-316, cell 27(e) and cell 34(e) | G28: ='316'!L51 -> 0 | H28: ='316'!L59 -> 0 | I28: =SUM(G28:H28) -> 0
A29: =A28+1 -> 9 | C29: Contribution Expense | I29: =SUM(G29:H29) -> 0
A30: =A29+1 -> 10 | C30: Other Operating Expenses | I30: =SUM(G30:H30) -> 0
A31: =A30+1 -> 11 | E31: Total Operating Expenses | F31: (sum 8 to 10) | G31: =SUM(G28:G30) -> 0 | H31: =SUM(H28:H30) -> 0 | I31: =SUM(I28:I30) -> 0
A32: =A31+1 -> 12 | C32: EBITDA | F32: (7-11) | G32: =G26-G31 -> 0 | H32: =H26-H31 -> 0 | I32: =I26-I31 -> 0
A33: =A32+1 -> 13 | C33: Depreciation & Amortization
A34: =A33+1 -> 14 | C34: EBIT | F34: (12-13) | I34: =I32-I33 -> 0
B35: Non-Operating Income
A36: =A34+1 -> 15 | C36: Interest
A37: =A36+1 -> 16 | C37: Other
A38: =A37+1 -> 17 | E38: Total Non-Operating Income | F38: (15+16) | I38: =I36+I37 -> 0
B39: Non-Operating Expenses
A40: =A38+1 -> 18 | C40: Interest
A41: =A40+1 -> 19 | C41: Other Financing Charges
A42: =A41+1 -> 20 | E42: Total Financing Charges | F42: (18+19) | I42: =I40+I41 -> 0
A43: =A42+1 -> 21 | C43: Other Non-Operating Expenses
A44: =A43+1 -> 22 | E44: Total Non-Operating Expenses | F44: (20+21) | I44: =I42+I43 -> 0
B45: Extraordinary Items
...

Sheet 311
A1: FORM: 03-311 | L1: FINANCIAL
A3: Form Type: | D3: Operating Revenues | J3: Entity Name: | K3: ='310'!$G$3 -> 0
A4: Form Sub-type: | D4: Data & Private Line, Internet
A5: Reporting Basis: | D5: Total Company (Non-Consol.) | J5: Entity ID#: | K5: ='310'!$G$5 -> 0
A6: Geographic Market: | D6: Canada
A7: Year: | D7: 2002
A9: Notes:
A10: 1) | B10: Where a Data Link service is bundled with Internet connectivity, the resulting product or service should be reported under the appropriate Internet category, not under data link.
A11: 2) | B11: Data link revenues therefore include bundled private line/data link products, but exclude products bundled with Internet access.
A12: 3) | B12: Report mobile Internet access revenues on form 03-314, line 14 ("Mobile Data"). Report pay-per-use Internet access revenues on form 03-312, line 9 ("Pay-per-Use Internet Access").
A13: 4) | B13: Wholesale refers to the provision of a telecommunications service or facility to a service provider, regardless of whether that service provider rebills the service or facility to another entity, or uses that service or facility internally to support the services it bills.
D15: What were your Data, Private Line and Internet revenues?
F16: (a) | G16: (b) | H16: (c) | I16: (d) | J16: (e) | K16: (f) | L16: (g)
F17: Retail | I17: Wholesale | L17: Total (c+f)
B18: Revenues: Data, Private Line & Internet | F18: Residential | G18: Business | H18: Retail Subtotal (a+b) | I18: In-Group | J18: Out of Group | K18: Subtotal (d+e)
B19: Data
C20: Data Link
A21: 1 | D21: X.25 | H21: =SUM(F21:G21) -> 0 | K21: =I21+J21 -> 0 | L21: =H21+K21 -> 0
A22: =A21+1 -> 2 | D22: ATM | H22: =SUM(F22:G22) -> 0 | K22: =I22+J22 -> 0 | L22: =H22+K22 -> 0
A23: =A22+1 -> 3 | D23: Frame Relay | H23: =SUM(F23:G23) -> 0 | K23: =I23+J23 -> 0 | L23: =H23+K23 -> 0
A24: =A23+1 -> 4 | D24: Ethernet | H24: =SUM(F24:G24) -> 0 | K24: =I24+J24 -> 0 | L24: =H24+K24 -> 0
A25: =A24+1 -> 5 | D25: IP-VPN | H25: =SUM(F25:G25) -> 0 | K25: =I25+J25 -> 0 | L25: =H25+K25 -> 0
A26: =A25+1 -> 6 | D26: Other | H26: =SUM(F26:G26) -> 0 | K26: =I26+J26 -> 0 | L26: =H26+K26 -> 0
A27: =A26+1 -> 7 | D27: Total Data Link | E27: (sum 1 to 6) | F27: =SUM(F21:F26) -> 0 | G27: =SUM(G21:G26) -> 0 | H27: =SUM(H21:H26) -> 0 | I27: =SUM(I21:I26) -> 0 | J27: =SUM(J21:J26) -> 0 | K27: =SUM(K21:K26) -> 0 | L27: =SUM(L21:L26) -> 0
B28: Private Line
A29: =A27+1 -> 8 | C29: Long Haul Private Line | H29: =SUM(F29:G29) -> 0 | K29: =I29+J29 -> 0 | L29: =H29+K29 -> 0
A30: =A29+1 -> 9 | C30: Short Haul Private Line | H30: =SUM(F30:G30) -> 0 | K30: =I30+J30 -> 0 | L30: =H30+K30 -> 0
A31: =A30+1 -> 10 | D31: Total Private Line | E31: (8+9) | F31: =F29+F30 -> 0 | G31: =G29+G30 -> 0 | H31: =H29+H30 -> 0 | I31: =I29+I30 -> 0 | J31: =J29+J30 -> 0 | K31: =K29+K30 -> 0 | L31: =L29+L30 -> 0
A32: =A31+1 -> 11 | B32: Total Data & Private Line Revenues | E32: (7+10) | F32: =F27+F31 -> 0 | G32: =G27+G31 -> 0 | H32: =H27+H31 -> 0 | I32: =I27+I31 -> 0 | J32: =J27+J31 -> 0 | K32: =K27+K31 -> 0 | L32: =L27+L31 -> 0
B34: Internet
C35: Fixed Internet Access
A36: =A32+1 -> 12 | C36: Narrowband Internet Access | H36: =SUM(F36:G36) -> 0 | K36: =I36+J36 -> 0 | L36: =H36+K36 -> 0
A37: =A36+1 -> 13 | C37: High-Speed Internet Access | H37: =SUM(F37:G37) -> 0 | K37: =I37+J37 -> 0 | L37: =H37+K37 -> 0
A38: =A37+1 -> 14 | D38: Fixed Internet Access Subtotal | E38: (12+13) | F38: =SUM(F36:F37) -> 0 | G38: =SUM(G36:G37) -> 0 | H38: =SUM(H36:H37) -> 0 | I38: =SUM(I36:I37) -> 0 | J38: =SUM(J36:J37) -> 0 | K38: =SUM(K36:K37) -> 0 | L38: =SUM(L36:L37) -> 0
A39: =A38+1 -> 15 | C39: Terminal Equipment (Modems) | H39: =SUM(F39:G39) -> 0 | K39: =I39+J39 -> 0 | L39: =H39+K39 -> 0
A40: =A39+1 -> 16 | D40: Total Internet Access | E40: (14+15) | F40: =F38+F39 -> 0 | G40: =G38+G39 -> 0 | H40: =H38+H39 -> 0 | I40: =I38+I39 -> 0 | J40: =J38+J39 -> 0 | K40: =K38+K39 -> 0 | L40: =L38+L39 -> 0
C41: Internet Transport
A42: =A40+1 -> 17 | C42: BGP and ISP Connectivity | H42: =SUM(F42:G42) -> 0 | K42: =I42+J42 -> 0 | L42: =H42+K42 -> 0
A43: =A42+1 -> 18 | C43: Other - (Eg. Equipment & Installation, Consultancy) | H43: =SUM(F43:G43) -> 0 | K43: =I43+J43 -> 0 | L43: =H43+K43 -> 0
A44: =A43+1 -> 19 | D44: Total Internet Transport | E44: (17 + 18) | G44: =+G42+G43 -> 0 | H44: =+H42+H43 -> 0 | I44: =+I42+I43 -> 0 | J44: =+J42+J43 -> 0 | K44: =+K42+K43 -> 0 | L44: =+L42+L43 -> 0
...

Sheet 312
A1: FORM: 03-312 | H1: FINANCIAL
A3: Form Type: | D3: Operating Revenues | F3: Entity Name: | G3: ='310'!$G$3 -> 0
A4: Form Sub-type: | D4: Local & Access
A5: Reporting Basis: | D5: Total Company (Non-Consol.) | F5: Entity ID#: | G5: ='310'!$G$5 -> 0
A6: Geographic Market: | D6: Canada
A7: Year: | D7: 2002
D9: Wholesale refers to the provision of a telecommunications service or facility to a service provider, regardless of whether that service provider rebills the service or facility to another entity, or uses that service or facility internally to support the services it bills.
D11: What were your Local and Access revenues?
F13: (a) | G13: (b) | H13: (c) | I13: (d) | J13: (e) | K13: (f) | L13: (g)
B14: Revenues: Local & Access | F14: Retail | I14: Wholesale | L14: Total
F15: Residential | G15: Business | H15: Retail Subtotal (a+b) | I15: In-Group | J15: Out of Group | K15: Wholesale Subtotal (d+e) | L15: (c+f)
B16: Local Voice
A17: 1 | C17: Basic Local Service (include touchtone) | H17: =SUM(F17:G17) -> 0 | K17: =I17+J17 -> 0 | L17: =H17+K17 -> 0
A18: =A17+1 -> 2 | C18: Optional Local Features (exclude touchtone) | H18: =SUM(F18:G18) -> 0 | K18: =I18+J18 -> 0 | L18: =H18+K18 -> 0
A19: =A18+1 -> 3 | C19: Centrex | H19: =SUM(F19:G19) -> 0 | K19: =I19+J19 -> 0 | L19: =H19+K19 -> 0
A20: =A19+1 -> 4 | C20: Other User Revenues (Service charges, Inside wire, etc.) | H20: =SUM(F20:G20) -> 0 | K20: =I20+J20 -> 0 | L20: =H20+K20 -> 0
A21: =A20+1 -> 5 | D21: Subtotal--User (Excluding Terminal) | E21: (sum 1 to 4) | F21: =SUM(F17:F20) -> 0 | G21: =SUM(G17:G20) -> 0 | H21: =SUM(H17:H20) -> 0 | I21: =SUM(I17:I20) -> 0 | J21: =SUM(J17:J20) -> 0 | K21: =SUM(K17:K20) -> 0 | L21: =SUM(L17:L20) -> 0
A22: =A21+1 -> 6 | C22: Terminal Equipment | H22: =SUM(F22:G22) -> 0 | K22: =I22+J22 -> 0 | L22: =H22+K22 -> 0
A23: =A22+1 -> 7 | D23: Subtotal--User | E23: (5 + 6) | F23: =F21+F22 -> 0 | G23: =G21+G22 -> 0 | H23: =H21+H22 -> 0 | I23: =I21+I22 -> 0 | J23: =J21+J22 -> 0 | K23: =K21+K22 -> 0 | L23: =L21+L22 -> 0
A24: =A23+1 -> 8 | C24: Local Payphone | E24: Form 03-920 | K24: =I24+J24 -> 0 | L24: =H24+K24 -> 0
A25: 9 | C25: Pay-per-Use Internet Access | K25: =I25+J25 -> 0 | L25: =H25+K25 -> 0
A26: =A25+1 -> 10 | C26: Other Non-Toll Payphone Revenues | E26: Form 03-920 | K26: =I26+J26 -> 0 | L26: =H26+K26 -> 0
A27: =A26+1 -> 11 | D27: Payphone Subtotal--User | E27: (sum 8 to 10) | H27: =SUM(H24:H26) -> 0 | I27: =SUM(I24:I26) -> 0 | J27: =SUM(J24:J26) -> 0 | K27: =SUM(K24:K26) -> 0 | L27: =SUM(L24:L26) -> 0
A28: =A27+1 -> 12 | C28: Switching & Aggregation | K28: =I28+J28 -> 0 | L28: =H28+K28 -> 0
A29: =A28+1 -> 13 | C29: Other Local Interconnection | K29: =I29+J29 -> 0 | L29: =H29+K29 -> 0
A30: =A29+1 -> 14 | D30: Subtotal--Carrier | E30: (12+13) | I30: =I28+I29 -> 0 | J30: =J28+J29 -> 0 | K30: =K28+K29 -> 0 | L30: =L28+L29 -> 0
A31: =A30+1 -> 15 | C31: Contribution | H31: =SUM(F31:G31) -> 0 | L31: =H31+K31 -> 0
A32: =A31+1 -> 16 | D32: Total Local Voice | E32: (7+11+14+15) | F32: =F23+F27+F30+F31 -> 0 | G32: =G23+G27+G30+G31 -> 0 | H32: =H23+H27+H30+H31 -> 0 | I32: =I23+I27+I30+I31 -> 0 | J32: =J23+J27+J30+J31 -> 0 | K32: =K23+K27+K30+K31 -> 0 | L32: =L23+L27+L30+L31 -> 0
B33: PSTN Access
A34: =A32+1 -> 17 | C34: DEA (Digital Exchange Access) | H34: =SUM(F34:G34) -> 0 | K34: =I34+J34 -> 0 | L34: =H34+K34 -> 0
A35: =A34+1 -> 18 | C35: ISDN (BRI & PRI) | H35: =SUM(F35:G35) -> 0 | K35: =I35+J35 -> 0 | L35: =H35+K35 -> 0
A36: =A35+1 -> 19 | C36: Other | H36: =SUM(F36:G36) -> 0 | K36: =I36+J36 -> 0 | L36: =H36+K36 -> 0
A37: =A36+1 -> 20 | D37: Total PSTN Access | E37: (sum 17 to 19) | F37: =SUM(F34:F36) -> 0 | G37: =SUM(G34:G36) -> 0 | H37: =SUM(H34:H36) -> 0 | I37: =SUM(I34:I36) -> 0 | J37: =SUM(J34:J36) -> 0 | K37: =SUM(K34:K36) -> 0 | L37: =SUM(L34:L36) -> 0
A39: =A37+1 -> 21 | B39: Unbundled Loops | H39: =SUM(F39:G39) -> 0 | K39: =I39+J39 -> 0 | L39: =H39+K39 -> 0
A41: =A39+1 -> 22 | C41: Total Local & Access Revenues | E41: (16+20+21) | F41: =F32+F37+F39 -> 0 | G41: =G32+G37+G39 -> 0 | H41: =H32+H37+H39 -> 0 | I41: =I32+I37+I39 -> 0 | J41: =J32+J37+J39 -> 0 | K41: =K32+K37+K39 -> 0 | L41: =L32+L37+L39 -> 0

Sheet 313
A1: FORM: 03-313 | H1: FINANCIAL
A3: Form Type: | D3: Operating Revenues | F3: Entity Name: | G3: ='310'!$G$3 -> 0
A4: Form Sub-type: | D4: Long Distance
A5: Reporting Basis: | D5: Total Company (Non-Consol.) | F5: Entity ID#: | G5: ='310'!$G$5 -> 0
A6: Geographic Market: | D6: Canada
A7: Years: | D7: 2002
C10: Notes: 1) | D10: Settlement activities should be included in Wholesale.
C11: 2) | D11: Wholesale refers to the provision of a telecommunications service or facility to a service provider, regardless of whether that service provider rebills the service or facility to another entity, or uses that service or facility internally to support the services it bills.
C12: 3) | D12: Minute-based revenues are those revenues billed on a per-minute basis, over and above those minutes paid for as part of a discount plan subscribed to by the customer, found in Line 4.
D14: What were your Long Distance revenues?
F16: (a) | G16: (b) | H16: (c) | I16: (d) | J16: (e) | K16: (f) | L16: (g)
B17: Revenues: Wireline Long Distance | F17: Retail | I17: Wholesale | L17: Total
F18: Residential | G18: Business | H18: Retail Subtotal (a+b) | I18: In-Group | J18: Out of Group | K18: Wholesale Subtotal (d+e) | L18: (c+f)
B19: Long-Distance (Excluding Mobile)
A20: 1 | C20: Minute-based Revenues - PIC'ed Customers | H20: =SUM(F20:G20) -> 0 | K20: =I20+J20 -> 0 | L20: =H20+K20 -> 0
A21: 2 | C21: Minute-based Revenues - non-PIC'ed Customers | H21: =SUM(F21:G21) -> 0 | K21: =I21+J21 -> 0 | L21: =H21+K21 -> 0
A22: 3 | C22: Operator Handled Revenues | H22: =SUM(F22:G22) -> 0 | K22: =I22+J22 -> 0 | L22: =H22+K22 -> 0
A23: 4 | C23: Subscription Plan Fees | H23: =SUM(F23:G23) -> 0 | K23: =I23+J23 -> 0 | L23: =H23+K23 -> 0
A24: 5 | C24: Network Administration Fees | H24: =SUM(F24:G24) -> 0 | K24: =I24+J24 -> 0 | L24: =H24+K24 -> 0
A25: 6 | C25: Payphone | E25: Form 03-920 | K25: =I25+J25 -> 0 | L25: =H25+K25 -> 0
A26: 7 | C26: Settlement | E26: Form 03-720 | K26: =I26+J26 -> 0 | L26: =K26 -> 0
A27: 8 | C27: Other | H27: =SUM(F27:G27) -> 0 | K27: =I27+J27 -> 0 | L27: =H27+K27 -> 0
A28: 9 | B28: Total Long Distance Revenues | E28: sum (1 to 8) | F28: =SUM(F20:F24)+F27 -> 0 | G28: =SUM(G20:G24)+G27 -> 0 | H28: =SUM(H20:H27) -> 0 | I28: =SUM(I20:I27) -> 0 | J28: =SUM(J20:J27) -> 0 | K28: =SUM(K20:K27) -> 0 | L28: =SUM(L20:L27) -> 0

Sheet 314
A1: FORM: 03-314 | K1: FINANCIAL
A3: Form Type: | D3: Operating Revenues | I3: Entity Name: | J3: ='310'!$G$3 -> 0
A4: Form Sub-type: | D4: Mobile & Paging
A5: Reporting Basis: | D5: Total Company (Non-Consol.) | I5: Entity ID#: | J5: ='310'!$G$5 -> 0
A6: Geographic Market: | D6: Canada
A7: Year: | D7: 2002
A9: Notes:
A10: 1) | B10: For terminal equipment please provide gross revenue, including subsidies and ancillary sales for items such as mobile, earbuds and chargers.
A11: 2) | B11: Wholesale refers to the provision of a telecommunications service or facility to a service provider, regardless of whether that service provider rebills the service or facility to another entity, or uses that service or facility internally to support the services it bills.
C13: What were your Mobile & Paging Revenues?
G15: (a) | H15: (b) | I15: (c) | J15: (d) | K15: (e)
B16: Revenues: Mobile & Paging | G16: Retail | H16: Wholesale | K16: Total
H17: In-Group | I17: Out of Group | J17: Subtotal d=(b+c) | K17: e=(a+d)
B18: Mobile Voice
A19: 1 | C19: Basic Voice (Subscriptions) | E19: Form 03-810 (aggregated) | J19: =SUM(H19:I19) -> 0 | K19: =G19+J19 -> 0
A20: =A19+1 -> 2 | C20: Long Distance (Subscriptions) | E20: Form 03-810 (aggregated) | J20: =SUM(H20:I20) -> 0 | K20: =G20+J20 -> 0
C21: Roaming Charges
A22: =A20+1 -> 3 | C22: End-User | J22: =SUM(H22:I22) -> 0 | K22: =G22+J22 -> 0
A23: =A22+1 -> 4 | C23: Inter-carrier | E23: Form 03-821 | J23: =SUM(H23:I23) -> 0 | K23: =G23+J23 -> 0
A24: =A23+1 -> 5 | D24: Subtotal -- Roaming Charges | E24: (3+4) | G24: =SUM(G22:G23) -> 0 | H24: =SUM(H22:H23) -> 0 | I24: =SUM(I22:I23) -> 0 | J24: =SUM(J22:J23) -> 0 | K24: =SUM(K22:K23) -> 0
A25: =A24+1 -> 6 | C25: Mobile Interconnection | E25: Form 03-821 | J25: =SUM(H25:I25) -> 0 | K25: =G25+J25 -> 0
A26: =A25+1 -> 7 | C26: Terminal Equipment | J26: =SUM(H26:I26) -> 0 | K26: =G26+J26 -> 0
A27: =A26+1 -> 8 | D27: Subtotal -- Mobile Voice | E27: (1+2+5+6+7) | G27: =G19+G20+G24+G25+G26 -> 0 | H27: =H19+H20+H24+H25+H26 -> 0 | I27: =I19+I20+I24+I25+I26 -> 0 | J27: =J19+J20+J24+J25+J26 -> 0 | K27: =K19+K20+K24+K25+K26 -> 0
B29: Text Messaging
A30: =A27+1 -> 9 | C30: Paging (subcriptions) | E30: Form 03-810 (aggregated) | J30: =SUM(H30:I30) -> 0 | K30: =G30+J30 -> 0
A31: =A30+1 -> 10 | C31: Terminal Equipment--Paging | J31: =SUM(H31:I31) -> 0 | K31: =G31+J31 -> 0
A32: =A31+1 -> 11 | C32: Paging Interconnection | J32: =SUM(H32:I32) -> 0 | K32: =G32+J32 -> 0
A33: =A32+1 -> 12 | C33: Paging Roaming (Intercarrier) | J33: =SUM(H33:I33) -> 0 | K33: =G33+J33 -> 0
A34: =A33+1 -> 13 | D34: Subtotal Text Messaging | E34: (sum 9 to 12) | G34: =SUM(G30:G33) -> 0 | H34: =SUM(H30:H33) -> 0 | I34: =SUM(I30:I33) -> 0 | J34: =SUM(J30:J33) -> 0 | K34: =SUM(K30:K33) -> 0
A36: =A34+1 -> 14 | B36: Mobile Data | E36: Form 03-822 | J36: =SUM(H36:I36) -> 0 | K36: =G36+J36 -> 0
A38: =A36+1 -> 15 | D38: Total Mobile and Paging | E38: (8+13+14) | G38: =G27+G34+G36 -> 0 | H38: =H27+H34+H36 -> 0 | I38: =I27+I34+I36 -> 0 | J38: =J27+J34+J36 -> 0 | K38: =K27+K34+K36 -> 0

Sheet 315
A1: FORM: 03-315 | I1: FINANCIAL
A3: Form Type: | D3: Operating Revenues | F3: Entity Name: | G3: ='310'!$G$3 -> 0
A4: Form Sub-type: | D4: Business (Small, Medium, Large & Very Large)
A5: Reporting Basis: | D5: Total Company (Non-Consol.) | F5: Entity ID#: | G5: ='310'!$G$5 -> 0
A6: Geographic Market: | D6: Canada
A7: Year: | D7: 2002
A9: Notes:
A10: 1) | B10: Small businesses are defined as accounts which generated less than $6000 of overall telecommunications revenues (averaging less than $500 per month) for the reporting entity during the reporting year.
A11: 2) | B11: Medium businesses are defined as accounts which generated at least $6000, but less than $30,000 of overall telecommunications revenues (from $500 to under $2500 per month) for the reporting entity during the reporting year.
A12: 3) | B12: Large businesses are defined as accounts which generated at least $30,000, but less than $240,000 of overall telecommunications revenues (from $2,500 to under $20,000 per month) for the reporting entity during the reporting year.
A13: 4) | B13: Very Large businesses are defined as accounts which generated at least $240,000 of overall telecommunications revenues (averaging at least $20,000 per month) for the reporting entity during the reporting year.
A14: 5) | B14: For Long Distance, therefore, segment accounts and revenues into Small, Medium, Large or Very Large according to overall account size, not according to LD revenue. These revenues should be the same as reported on form 03-313 in cell 9(b).
A15: 6) | B15: For Local & Access, therefore, segment accounts and revenues into Small, Medium, Large or Very Large according to overall account size, not according to Local revenue. These revenues should be the same as reported on form 03-312 in cell 22(b).
A16: 7) | B16: For Data & Private Line, therefore, segment accounts and revenues into Small, Medium, Large or Very Large according to overall account size, not according to Data revenue. These revenues should be the same as reported on form 03-311 in cell 11(b).
F18: (a) | H18: (b)
B19: Total: Business Accounts (Units), Business Revenues | F19: Business Wireline Accounts
F20: # of Accounts (Units) | H20: Revenues | J20: Revenues per Account
A21: 1 | B21: Small Business | J21: =IF(F21=0,"-",H21/F21) -> -
A22: =A21+1 -> 2 | B22: Medium Business | J22: =IF(F22=0,"-",H22/F22) -> -
A23: =A22+1 -> 3 | B23: Large Business | J23: =IF(F23=0,"-",H23/F23) -> -
A24: =A23+1 -> 4 | B24: Very Large Business | J24: =IF(F24=0,"-",H24/F24) -> -
A25: =A24+1 -> 5 | C25: Total Business (Revenues on lines 5 and 10 must be equal) | E25: (sum 1 and 4) | F25: =SUM(F21:F24) -> 0 | H25: =SUM(H21:H24) -> 0
B27: Total Wireline Business Revenues (As Reported on Other Forms)
A28: =A25+1 -> 6 | C28: Data & Private Line | E28: Form 03-311, cell 11(b) | H28: ='311'!G32 -> 0
A29: =A28+1 -> 7 | C29: Internet | E29: Form 03-311, cell 22(b) | H29: ='311'!G48 -> 0
A30: =A29+1 -> 8 | C30: Local & Access | E30: Form 03-312, cell 22(b) | H30: ='312'!G41 -> 0
A31: =A30+1 -> 9 | C31: Long Distance | E31: Form 03-313, cell 9(b) | H31: ='313'!G28 -> 0
A32: =A31+1 -> 10 | D32: Total Wireline Business Revenues | E32: (sum 6 to 9) | H32: =SUM(H28:I31) -> 0
B34: Long Distance: Business Accounts (Units), Business Revenues | F34: Business Wireline Accounts
F35: # of LD Accounts (Units) | H35: LD Revenues
A36: =A32+1 -> 11 | B36: Small Business
A37: =A36+1 -> 12 | B37: Medium Business
A38: =A37+1 -> 13 | B38: Large Business
A39: =A38+1 -> 14 | B39: Very Large Business
A40: =A39+1 -> 15 | C40: Total Business Long Distance | E40: (sum 11 to 14) | F40: =SUM(F36:F39) -> 0 | H40: =SUM(H36:H39) -> 0
B42: Local & Access Services: Business Accounts (Units), Business Revenues | F42: Business Wireline Accounts
F43: # of Local & Access Accounts (Units) | H43: Local & Access Revenues
A44: =A40+1 -> 16 | B44: Small Business
A45: =A44+1 -> 17 | B45: Medium Business
A46: =A45+1 -> 18 | B46: Large Business
...

Sheet 316
A1: FORM: 03-316 | L1: FINANCIAL
A3: Form Type: | F3: Expenses | J3: Entity Name: | K3: ='310'!$G$3 -> 0
A4: Form Sub-type: | F4: Intercarrier Expenses
A5: Reporting Basis: | F5: Total Company (Non-Consol.) | J5: Entity ID#: | K5: ='310'!$G$5 -> 0
A6: Geographic Market: | F6: Canada
A7: Year: | F7: 2002
A9: Notes:
A10: 1) | B10: Where a carrier's expenses is allocated across various services, please provide a brief description of the allocation in Form 03-210.
A11: 2) | B11: ILEC provided services refers to the services provided by the incumbent local exchange carriers to other carriers.
A12: 3) | B12: Non ILEC provided services refers to the services provided by non incumbents to other carriers. These may be the same type of services listed on lines 1 to 10 provided by the ILECs
E14: What were your intercarrier expenses?
H15: (a) | I15: (b) | J15: (c) | K15: (d) | L15: (e)
B16: Intercarrier Expenses | H16: Local | I16: Long Distance | J16: Data & Private Line | K16: Internet | L16: Total (sum a to d)
B18: Wireline Operations
C19: ILEC Provided Services
D20: Competitor Services
A21: 1 | E21: Unbundled Loops | L21: =SUM(H21:K21) -> 0
A22: =A21+1 -> 2 | E22: Access Tandem | L22: =SUM(H22:K22) -> 0
A23: =A22+1 -> 3 | E23: Direct Connect | L23: =SUM(H23:K23) -> 0
A24: =A23+1 -> 4 | E24: CDNA (Competitive Digital Network Access) | L24: =SUM(H24:K24) -> 0
A25: =A24+1 -> 5 | E25: Co-Location | L25: =SUM(H25:K25) -> 0
A26: =A25+1 -> 6 | E26: PIC processing charge | L26: =SUM(H26:K26) -> 0
A27: =A26+1 -> 7 | E27: Access charge for toll free calls from public or semi-public telephones | L27: =SUM(H27:K27) -> 0
A28: =A27+1 -> 8 | E28: Local Operator Assistance Service (LOAS) | L28: =SUM(H28:K28) -> 0
A29: =A28+1 -> 9 | E29: Other Competitor Services | L29: =SUM(H29:K29) -> 0
A30: =A29+1 -> 10 | F30: ILEC Services Subtotal | G30: (sum 1 to 9) | H30: =SUM(H21:H29) -> 0 | I30: =SUM(I21:I29) -> 0 | J30: =SUM(J21:J29) -> 0 | K30: =SUM(K21:K29) -> 0 | L30: =SUM(L21:L29) -> 0
D32: Tariffed ILEC Services at Retail Rates
A33: =A30+1 -> 11 | E33: IXPL (Inter Exchange Private Line) | L33: =SUM(H33:K33) -> 0
A34: =A33+1 -> 12 | E34: DNA (Digital Network Access) & DEA (Digital Exchange Access) | L34: =SUM(H34:K34) -> 0
A35: =A34+1 -> 13 | E35: Centrex | L35: =SUM(H35:K35) -> 0
A36: =A35+1 -> 14 | E36: Other Tariffed Retail ILEC Services | L36: =SUM(H36:K36) -> 0
A37: =A36+1 -> 15 | F37: Subtotal | G37: (sum11 to 14) | H37: =SUM(H33:H36) -> 0 | I37: =SUM(I33:I36) -> 0 | J37: =SUM(J33:J36) -> 0 | K37: =SUM(K33:K36) -> 0 | L37: =SUM(L33:L36) -> 0
C38: Non ILEC Provided Services
A39: =A37+1 -> 16 | E39: Loops - Low Speed (less than 64K) | L39: =SUM(H39:K39) -> 0
A40: =A39+1 -> 17 | E40: Other Access (from customer to LEC at speeds greater than 64k) | L40: =SUM(H40:K40) -> 0
A41: =A40+1 -> 18 | E41: IXPL (Inter Exchange Private Line) | L41: =SUM(H41:K41) -> 0
A42: =A41+1 -> 19 | E42: PIC processing charge | L42: =SUM(H42:K42) -> 0
A43: =A42+1 -> 20 | E43: Access Charge for toll free calls from public or semi-public telephones | L43: =SUM(H43:K43) -> 0
A44: =A43+1 -> 21 | E44: Other Non ILEC Services | L44: =SUM(H44:K44) -> 0
A45: =A44+1 -> 22 | F45: Non ILEC Services Subtotal | G45: (sum 16 to 21) | H45: =SUM(H39:H44) -> 0 | I45: =SUM(I39:I44) -> 0 | J45: =SUM(J39:J44) -> 0 | K45: =SUM(K39:K44) -> 0 | L45: =SUM(L39:L44) -> 0
...

Sheet 320
A1: FORM: 03-320 | G1: FINANCIAL
A3: Form Type: | D3: Financial | F3: Entity Name: | G3: ='310'!$G$3 -> 0
A4: Form Sub-type: | D4: Balance Sheet
A5: Reporting Basis: | D5: Total Company (Non-Consol.) | F5: Entity ID#: | G5: ='310'!$G$5 -> 0
A6: Geographic Market: | D6: Canada
A7: Years: | D7: 2002
B10: Assets | G10: (a)
B12: Current Assets
A13: 1 | C13: Cash
A14: =A13+1 -> 2 | C14: Accounts Receivable
A15: =A14+1 -> 3 | C15: Prepaid Items
A16: =A15+1 -> 4 | C16: Other Current Assets
A17: =A16+1 -> 5 | C17: Total | F17: (sum 1 to 4) | G17: =SUM(G13:G16) -> 0
B18: Fixed Assets
A19: =A17+1 -> 6 | C19: Land & Buildings
A20: =A19+1 -> 7 | C20: Plant, Equipment and Other Fixed Assets
A21: =A20+1 -> 8 | C21: Accumulated Depreciation
A22: =A21+1 -> 9 | C22: Plant Under Construction (PUC)
A23: =A22+1 -> 10 | C23: Net Fixed Assets | F23: (6+7-8+9) | G23: =G19+G20-G21+G22 -> 0
B24: Other Assets
A25: =A23+1 -> 11 | C25: Deferred Charges
A26: =A25+1 -> 12 | C26: Investments
A27: =A26+1 -> 13 | C27: Other
A28: =A27+1 -> 14 | C28: Total | F28: (sum 11 to 13) | G28: =SUM(G25:G27) -> 0
A29: =A28+1 -> 15 | B29: Total Assets | F29: (5+10+14) | G29: =G17+G23+G28 -> 0
B31: Liabilities & Equity | C31: Liabilities & Equity
B32: Current Liabilities
A33: =A29+1 -> 16 | C33: Accounts Payable & Accrued Liabilities
A34: =A33+1 -> 17 | C34: Short Term Debt
A35: =A34+1 -> 18 | C35: Debt Due Within One Year
A36: =A35+1 -> 19 | C36: Other Current Liabilities
A37: =A36+1 -> 20 | C37: Total | F37: (sum 16 to 19) | G37: =SUM(G33:G36) -> 0
B38: Other Liabilities
A39: =A37+1 -> 21 | C39: Long Term Debt
A40: =A39+1 -> 22 | C40: Deferred Credits
A41: =A40+1 -> 23 | C41: Other
A42: =A41+1 -> 24 | C42: Total | F42: (sum 21 to 23) | G42: =SUM(G39:G41) -> 0
B43: Shareholders' Equity
A44: =A42+1 -> 25 | C44: Retained Earnings (Opening Balance)
A45: =A44+1 -> 26 | C45: Contributed Surplus
...

Sheet 321
A1: FORM: 03-321 | I1: FINANCIAL
A3: Form Type: | D3: Financial | F3: Entity Name: | H3: ='310'!$G$3 -> 0
A4: Form Sub-type: | D4: Capital Expenditures (Gross)
A5: Reporting Basis: | D5: Total Company | F5: Entity ID#: | H5: ='310'!$G$5 -> 0
A6: Geographic Market: | D6: Canada
A7: Years: | D7: 2002
A9: Note:
A10: 1) | B10: Computers and related software are to be assigned to the equipment they support. Example: Computers used for office functions are to be assigned to Other Non-network (Line 31).
A11: 2) | B11: Switching includes both switching hardware and switching software.
C13: What were your capital expenditures?
F15: (a) | G15: (b) | H15: (c)
F16: Growth | G16: Replacement | H16: Total (a+b)
B17: Access
C18: Transmission
A19: 1 | D19: Copper | H19: =SUM(F19:G19) -> 0
A20: =A19+1 -> 2 | D20: Fibre | H20: =SUM(F20:G20) -> 0
A21: =A20+1 -> 3 | D21: Fixed Wireless | H21: =SUM(F21:G21) -> 0
A22: =A21+1 -> 4 | D22: Satellite | H22: =SUM(F22:G22) -> 0
A23: =A22+1 -> 5 | D23: Other | H23: =SUM(F23:G23) -> 0
A24: =A23+1 -> 6 | D24: Transmission Subtotal | E24: (Sum 1 to 5) | F24: =SUM(F19:F23) -> 0 | G24: =SUM(G19:G23) -> 0 | H24: =SUM(H19:H23) -> 0
C25: Equipment
A26: =A24+1 -> 7 | D26: DSLAM | H26: =SUM(F26:G26) -> 0
A27: =A26+1 -> 8 | D27: Other Electronics | H27: =SUM(F27:G27) -> 0
A28: =A27+1 -> 9 | D28: Other | H28: =SUM(F28:G28) -> 0
A29: =A28+1 -> 10 | D29: Equipment Subtotal | E29: (Sum 7 to 9) | F29: =SUM(F26:F28) -> 0 | G29: =SUM(G26:G28) -> 0 | H29: =SUM(F29:G29) -> 0
A30: =A29+1 -> 11 | D30: Access Subtotal | E30: (6 + 10) | F30: =F24+F29 -> 0 | G30: =G24+G29 -> 0 | H30: =H24+H29 -> 0
B31: Interexchange (Intracity, Intercity)
C32: Transmission
A33: =A30+1 -> 12 | D33: Copper | H33: =SUM(F33:G33) -> 0
A34: =A33+1 -> 13 | D34: Fibre | H34: =SUM(F34:G34) -> 0
A35: =A34+1 -> 14 | D35: Fixed Wireless | H35: =SUM(F35:G35) -> 0
A36: =A35+1 -> 15 | D36: Satellite | H36: =SUM(F36:G36) -> 0
A37: =A36+1 -> 16 | D37: Other | H37: =SUM(F37:G37) -> 0
A38: =A37+1 -> 17 | D38: Transmission Subtotal | E38: (Sum 12 to 16) | F38: =SUM(F33:F37) -> 0 | G38: =SUM(G33:G37) -> 0 | H38: =SUM(H33:H37) -> 0
C39: Equipment
A40: =A38+1 -> 18 | D40: Optical | H40: =SUM(F40:G40) -> 0
A41: =A40+1 -> 19 | D41: Other Electronics | H41: =SUM(F41:G41) -> 0
A42: =A41+1 -> 20 | D42: Other | H42: =SUM(F42:G42) -> 0
A43: =A42+1 -> 21 | D43: Equipment Subtotal | E43: (Sum 18 to 20) | F43: =SUM(F40:F42) -> 0 | G43: =SUM(G40:G42) -> 0 | H43: =SUM(H40:H42) -> 0
A44: =A43+1 -> 22 | D44: Interexchange Subtotal | E44: (17 + 21) | F44: =F38+F43 -> 0 | G44: =G38+G43 -> 0 | H44: =H38+H43 -> 0
...
