Workbook
Name HideCol10: '[1]Op Metrics - Qtrly'!#REF!
Name HideCol11: '[1]Op Metrics - Mthly'!#REF!
Name HideCol12: '[1]Rate Trends - Qtrly'!#REF!
Name HideCol13: '[1]Rate Trends - Mthly'!#REF!
Name HideCol14: '[1]BCI BS - Mthly'!#REF!
Name HideCol15: '[1]BCI BS - Mthly'!#REF!
Name HideCol2: [1]Qtrly!#REF!
Name HideCol3: [1]Monthly!#REF!
Name HideCol4: '[1]GM by Product - Qtrly'!#REF!
Name HideCol5: '[1]GM by Product - Mthly'!#REF!
Name HideCol6: '[1]COS Qtrly'!#REF!
Name HideCol7: '[1]COS Mthly'!#REF!
Name HideCol8: '[1]SGA Qtrly'!#REF!
Name HideCol9: '[1]SGA Mthly'!#REF!
Name HideRow10: '[1]Op Metrics - Qtrly'!#REF!
Name HideRow11: '[1]Op Metrics - Mthly'!#REF!
Name HideRow12: '[1]Rate Trends - Qtrly'!#REF!
Name HideRow13: '[1]Rate Trends - Mthly'!#REF!
Name HideRow14: '[1]BCI BS - Mthly'!#REF!
Name HideRow15: '[1]BCI BS - Mthly'!#REF!
Name HideRow2: [1]Qtrly!#REF!
Name HideRow3: [1]Monthly!#REF!
Name HideRow4: '[1]GM by Product - Qtrly'!#REF!
Name HideRow5: '[1]GM by Product - Mthly'!#REF!
Name HideRow6: '[1]COS Qtrly'!#REF!
Name HideRow7: '[1]COS Mthly'!#REF!
Name HideRow8: '[1]SGA Qtrly'!#REF!
Name HideRow9: '[1]SGA Mthly'!#REF!

Sheet CY v. PY Qtr & YTD
A1: Cincinnati Bell Inc.
A2: Consolidated Statements of Operations
A3: (Unaudited)
B5: (in millions - except per share amounts)
C7: For the Three Months Ended
C8: June 30, | E8: March 31, | G8: December 31, | I8: September 30, | K8: June 30, | M8: March 31,
C9: 2003 | E9: 2003 | G9: 2002 | I9: 2002 | K9: 2002 | M9: 2002
B11: Revenue | C11: ='Segment P&L'!C15 -> 450.6 | E11: ='Segment P&L'!E15 -> 480.7 | G11: ='Segment P&L'!G15 -> 509.3 | I11: ='Segment P&L'!I15 -> 570.3 | K11: ='Segment P&L'!K15 -> 556.2 | M11: ='Segment P&L'!M15 -> 542.8
B13: Costs & Expenses
B14: Cost of Services and Products | C14: ='Segment P&L'!C23 -> 261.7 | E14: ='Segment P&L'!E23 -> 219.4 | G14: ='Segment P&L'!G23 -> 247.5 | I14: ='Segment P&L'!I23 -> 254.1 | K14: ='Segment P&L'!K23 -> 271.1 | M14: ='Segment P&L'!M23 -> 268
B15: Selling, General & Administrative | C15: ='Segment P&L'!C31 -> 108.2 | E15: ='Segment P&L'!E31 -> 120.3 | G15: ='Segment P&L'!G31 -> 120.8 | I15: ='Segment P&L'!I31 -> 121.6 | K15: ='Segment P&L'!K31 -> 127 | M15: ='Segment P&L'!M31 -> 127.8
B16: Depreciation and Amortization | C16: ='Segment P&L'!C39 -> 39.7 | E16: ='Segment P&L'!E39 -> 41.5 | G16: ='Segment P&L'!G39 -> 125.6 | I16: ='Segment P&L'!I39 -> 126.8 | K16: ='Segment P&L'!K39 -> 122.2 | M16: ='Segment P&L'!M39 -> 121.6
B17: Restructuring | C17: ='Segment P&L'!C47 -> -3.4 | E17: ='Segment P&L'!E47 -> 0 | G17: ='Segment P&L'!G47 -> 13.5 | I17: ='Segment P&L'!I47 -> 7.1 | K17: ='Segment P&L'!K47 -> 0 | M17: ='Segment P&L'!M47 -> 16.5
B18: Asset Impairments and Other Charges (Credits) | C18: ='Segment P&L'!C55 -> -1.1 | E18: ='Segment P&L'!E55 -> 0.3 | G18: ='Segment P&L'!G55 -> 2201.2 | I18: ='Segment P&L'!I55 -> 0 | K18: ='Segment P&L'!K55 -> 0 | M18: ='Segment P&L'!M55 -> -0.3
B19: Gain on Sale of Broadband Assets | C19: ='Segment P&L'!C63 -> -299 | E19: ='Segment P&L'!E63 -> 0 | G19: ='Segment P&L'!G63 -> 0 | I19: ='Segment P&L'!I63 -> 0 | K19: ='Segment P&L'!K63 -> 0 | M19: ='Segment P&L'!M63 -> 0
B21: Operating Income | C21: =C11-C14-C15-C16-C17-C18-C19 -> 344.5 | E21: =E11-E14-E15-E16-E17-E18-E19 -> 99.2 | G21: =G11-G14-G15-G16-G17-G18-G19 -> -2199.3 | I21: =I11-I14-I15-I16-I17-I18-I19 -> 60.7 | K21: =K11-K14-K15-K16-K17-K18-K19 -> 35.9 | M21: =M11-M14-M15-M16-M17-M18-M19 -> 9.2
B23: Minority Interest Expense | C23: 15.8 | E23: 14.1 | G23: 13.2 | I23: 15.5 | K23: 14.8 | M23: 14.2
B24: Other (Income) Expense, Net | C24: =-0.4-0.1 -> -0.5 | E24: -0.1 | G24: 9.6 | I24: 1.4 | K24: 0.4 | M24: -0.9
B25: Interest Expense | C25: 61.3 | E25: 45.3 | G25: 46.8 | I25: 40.1 | K25: 38.9 | M25: 38.3
B27: Income (Loss) from Continuing Operations before Income Taxes,
B28: Discontinued Operations and Cumulative Effect of Change in Accounting Principle | C28: =C21-C23-C24-C25 -> 267.9 | E28: =E21-E23-E24-E25 -> 39.9 | G28: =G21-G23-G24-G25 -> -2268.9 | I28: =I21-I23-I24-I25 -> 3.7 | K28: =K21-K23-K24-K25 -> -18.2 | M28: =M21-M23-M24-M25 -> -42.4
B30: Income Tax Expense (Benefit) | C30: -2 | E30: 2 | G30: 114.8 | I30: -0.3 | K30: 0.1 | M30: -8.9
B32: Income (Loss) from Continuing Operations before Discontinued
B33: Operations and Cumulative Effect of Change in Accounting Principle | C33: =C28-C30 -> 269.9 | E33: =E28-E30 -> 37.9 | G33: =G28-G30 -> -2383.7 | I33: =I28-I30 -> 4 | K33: =K28-K30 -> -18.3 | M33: =M28-M30 -> -33.5
B35: Discontinued Operations, Net of Taxes | C35: 0 | E35: 0 | G35: 0 | I35: 0 | K35: -0.2 | M35: 217.8
B37: Cumulative Effect of Change in Accounting Principle, Net of Taxes | C37: 0 | E37: 85.9 | G37: 0 | I37: 0 | K37: 0 | M37: -2008.7
B39: Net Income (Loss) | C39: =SUM(C33:C37) -> 269.9 | E39: =SUM(E33:E37) -> 123.8 | G39: =SUM(G33:G37) -> -2383.7 | I39: =SUM(I33:I37) -> 4 | K39: =SUM(K33:K37) -> -18.5 | M39: =SUM(M33:M37) -> -1824.4
B41: Preferred Stock Dividends | C41: 2.6 | E41: 2.6 | G41: 2.6 | I41: 2.6 | K41: 2.6 | M41: 2.6
B43: Net Income (Loss) Applicable to Common Shareowners | C43: =C39-C41 -> 267.3 | E43: =E39-E41 -> 121.2 | G43: =G39-G41 -> -2386.3 | I43: =I39-I41 -> 1.4 | K43: =K39-K41 -> -21.1 | M43: =M39-M41 -> -1827
B45: Basic Earnings (Loss) Per Common Share
B46: Income (Loss) from Continuing Operations before Discontinued
B47: Operations and Cumulative Effect of Change in Accounting Principle | C47: 1.22 | E47: 0.16 | G47: -10.92 | I47: 0.01 | K47: -0.1 | M47: -0.17
B48: Discontinued Operations, Net of Taxes | C48: 0 | E48: 0 | G48: 0 | I48: 0 | K48: 0 | M48: 1
B49: Cumulative Effect of Change in Accounting Principle, Net of Taxes | C49: 0 | E49: 0.39 | G49: 0 | I49: 0 | K49: 0 | M49: 0
B50: Net Earnings (Loss) Per Common Share | C50: =SUM(C47:C49) -> 1.22 | E50: =SUM(E47:E49) -> 0.55 | G50: =SUM(G47:G49) -> -10.92 | I50: =SUM(I47:I49) -> 0.01 | K50: =SUM(K47:K49) -> -0.1 | M50: =SUM(M47:M49) -> 0.83
B52: Diluted Earnings (Loss) Per Common Share
B53: Income (Loss) from Continuing Operations before Discontinued
B54: Operations and Cumulative Effect of Change in Accounting Principle | C54: 1.18 | E54: 0.16 | G54: -10.92 | I54: 0.01 | K54: -0.1 | M54: -0.17
B55: Discontinued Operations, Net of Taxes | C55: 0 | E55: 0 | G55: 0 | I55: 0 | K55: 0 | M55: 1
B56: Cumulative Effect of Change in Accounting Principle, Net of Taxes | C56: 0 | E56: 0.39 | G56: 0 | I56: 0 | K56: 0 | M56: 0
...

Sheet Segment P&L
A1: Cincinnati Bell Inc.
A2: Consolidating Statements of Operations
A3: (Unaudited)
B6: (dollars in millions) | C6: For the Three Months Ended
C7: June 30, | E7: March 31, | G7: December 31, | I7: September 30, | K7: June 30, | M7: March 31,
C8: 2003 | E8: 2003 | G8: 2002 | I8: 2002 | K8: 2002 | M8: 2002
B9: Revenue
B10: Local | C10: 203.8 | E10: 204.5 | G10: 216.5 | I10: 202.8 | K10: 205.5 | M10: 208.3
B11: Wireless | C11: 67.9 | E11: 63.9 | G11: 65.4 | I11: 68.9 | K11: 69.4 | M11: 63.5
B12: Other | C12: 20.8 | E12: 20 | G12: 21.1 | I12: 20.5 | K12: 21.1 | M12: 20.1
B13: Broadband | C13: 177 | E13: 213.2 | G13: 227.1 | I13: 298.3 | K13: =279.6+0.1 -> 279.7 | M13: 270.2
B14: Corporate and eliminations | C14: -18.9 | E14: =480.7-E13-E12-E11-E10 -> -20.9 | G14: =509.3-G13-G12-G11-G10 -> -20.8 | I14: =570.3-I13-I12-I11-I10 -> -20.2 | K14: =-19.4-0.1 -> -19.5 | M14: =542.8-M13-M12-M11-M10 -> -19.3
B15: Total Revenue | C15: =SUM(C10:C14) -> 450.6 | E15: =SUM(E10:E14) -> 480.7 | G15: =SUM(G10:G14) -> 509.3 | I15: =SUM(I10:I14) -> 570.3 | K15: =SUM(K10:K14) -> 556.2 | M15: =SUM(M10:M14) -> 542.8
B17: Cost of Services and Products
B18: Local | C18: 63.8 | E18: 65.9 | G18: =69.8 -> 69.8 | I18: 63 | K18: 63.4 | M18: =65.6+0.1 -> 65.7
B19: Wireless | C19: 25.4 | E19: 25.7 | G19: =32.9 -> 32.9 | I19: 27.8 | K19: 30 | M19: 28.8
B20: Other | C20: 13.9 | E20: 14.7 | G20: 16.5 | I20: =11.8+3.6 -> 15.4 | K20: =15.2+0.1 -> 15.3 | M20: 16.1
B21: Broadband | C21: =171.9+0.1 -> 172 | E21: 129.1 | G21: =143.5+0.1 -> 143.6 | I21: 162.7 | K21: =177.1 -> 177.1 | M21: 172.2
B22: Corporate and eliminations | C22: =261.7-C21-C20-C19-C18 -> -13.4 | E22: =219.4-E21-E20-E19-E18 -> -16 | G22: =247.5-G21-G20-G19-G18 -> -15.3 | I22: =254.1-I21-I20-I19-I18 -> -14.8 | K22: =271.1-K21-K20-K19-K18 -> -14.7 | M22: =268-M21-M20-M19-M18 -> -14.8
B23: Total Cost of Services and Products | C23: =SUM(C18:C22) -> 261.7 | E23: =SUM(E18:E22) -> 219.4 | G23: =SUM(G18:G22) -> 247.5 | I23: =SUM(I18:I22) -> 254.1 | K23: =SUM(K18:K22) -> 271.1 | M23: =SUM(M18:M22) -> 268
B25: Selling, General & Administrative
B26: Local | C26: 32.9 | E26: 35.6 | G26: =36.2+0.1 -> 36.3 | I26: 33.2 | K26: 33.6 | M26: =36.4 -> 36.4
B27: Wireless | C27: 12.5 | E27: 11.2 | G27: =11.6-0.1 -> 11.5 | I27: 10.9 | K27: 13.3 | M27: 11.5
B28: Other | C28: 3.7 | E28: 3.8 | G28: 4.2 | I28: =3.7+0.1 -> 3.8 | K28: 3.9 | M28: 4
B29: Broadband | C29: 54.2 | E29: 72.3 | G29: 72.2 | I29: 78.7 | K29: 78.9 | M29: 78.5
B30: Corporate and eliminations | C30: =108.2-C29-C28-C27-C26 -> 4.9 | E30: =120.3-E29-E28-E27-E26 -> -2.6 | G30: =120.7-G29-G28-G27-G26+0.1 -> -3.4 | I30: =121.6-I29-I28-I27-I26 -> -5 | K30: =127-K29-K28-K27-K26 -> -2.7 | M30: =127.8-M29-M28-M27-M26 -> -2.6
B31: Total Selling, General & Administrative | C31: =SUM(C26:C30) -> 108.2 | E31: =SUM(E26:E30) -> 120.3 | G31: =SUM(G26:G30) -> 120.8 | I31: =SUM(I26:I30) -> 121.6 | K31: =SUM(K26:K30) -> 127 | M31: =SUM(M26:M30) -> 127.8
B33: Depreciation and Amortization
B34: Local | C34: 31.1 | E34: 31.2 | G34: 36.8 | I34: 38 | K34: 36 | M34: 35.8
B35: Wireless | C35: 7.7 | E35: 7.7 | G35: 8 | I35: 8.2 | K35: 7.7 | M35: 7.4
B36: Other | C36: 0.6 | E36: 0.5 | G36: 0.5 | I36: 0.5 | K36: =0.5-0.1 -> 0.4 | M36: 0.5
B37: Broadband | C37: 0.2 | E37: 2 | G37: 80.1 | I37: 80 | K37: 78 | M37: 77.9
B38: Corporate and eliminations | C38: 0.1 | E38: 0.1 | G38: 0.2 | I38: 0.1 | K38: =0+0.1 -> 0.1 | M38: 0
B39: Total Depreciation and Amortization | C39: =SUM(C34:C38) -> 39.7 | E39: =SUM(E34:E38) -> 41.5 | G39: =SUM(G34:G38) -> 125.6 | I39: =SUM(I34:I38) -> 126.8 | K39: =SUM(K34:K38) -> 122.2 | M39: =SUM(M34:M38) -> 121.6
B41: Restructuring
B42: Local | C42: 0 | E42: 0 | G42: 1.1 | I42: -2 | K42: 0 | M42: 0.4
B43: Wireless | C43: 0 | E43: 0 | G43: 0 | I43: 0 | K43: 0 | M43: 0
B44: Other | C44: 0 | E44: 0 | G44: 0 | I44: 0 | K44: 0 | M44: 0
B45: Broadband | C45: -3.4 | E45: 0 | G45: 11.6 | I45: 5 | K45: 0 | M45: 15.9
B46: Corporate and eliminations | C46: 0 | E46: 0 | G46: 0.8 | I46: 4.1 | K46: 0 | M46: 0.2
...
