Workbook
Name Revised: ' High School Courses'!$A$1

Sheet  High School Courses
A1: As of: 24 February 2003 @ 1:00 | G1: File Name 03-04COR.XLS
A2: NOTE: USE THE TABS AT THE BOTTOM OF THIS SHEET TO SWITCH BETWEEN GRADES 9-12, GRADES 5-8, GRADES K-6, IB COURSES & AFCENT
A3: Scroll to the bottom of the sheet for changes (Drops and Adds) since the last publication
A4: SUBJECT AREA COLUMN: GC = Computer, GE = Soc Studies, GF = Fine Arts, GG = US Government, GH = Health, GL = Language Arts, GM = Math,
A5: GP = Phys Ed, GS = Science, GU = US Hist, GV = Careers, GD = Second Language (The G means "meets Graduation Requirements")
A6: COURSE TITLE | B6: TITLE LEN | C6: CODE | D6: GRADE | E6: LENGTH | F6: SUBJECT AREA | G6: COMMENT
A7: Staff Assistant | B7: =LEN(A7) -> 15 | C7: AAC301 | D7: 9-12 | E7: 36 | F7: No Credit | G7: (No Credit)
A8: Lunch | B8: =LEN(A8) -> 5 | C8: AAC102 | D8: 5-12 | E8: 36 | F8: No Credit | G8: (No Credit)
A9: Learning Strat I | B9: =LEN(A9) -> 16 | C9: AAC331X1 | D9: 9-12 | E9: 36 | F9: Elective | G9: Only for students on IEP. Expand Course Sequencing - Policy Change No Repeat Code
A10: Learning Strat II | B10: =LEN(A10) -> 17 | C10: AAC331X2 | D10: 9-12 | E10: 36 | F10: Elective | G10: Only for students on IEP. Expand Course Sequencing - Policy Change No Repeat Code
A11: Learning Strat III | B11: =LEN(A11) -> 18 | C11: AAC331X3 | D11: 9-12 | E11: 36 | F11: Elective | G11: Only for students on IEP. Expand Course Sequencing - Policy Change No Repeat Code
A12: Learning Strat IV | B12: =LEN(A12) -> 17 | C12: AAC331X4 | D12: 9-12 | E12: 36 | F12: Elective | G12: Only for students on IEP. Expand Course Sequencing - Policy Change No Repeat Code
A13: Advisory | B13: =LEN(A13) -> 8 | C13: AAD301 | D13: 9-12 | E13: 36 | F13: No Credit | G13: (No Credit)
A14: Seminar | B14: =LEN(A14) -> 7 | C14: AAH301 | D14: 9-12 | E14: 36 | F14: No Credit | G14: (No Credit)
A15: Seminar 9 | B15: =LEN(A15) -> 9 | C15: AAH301X1 | D15: 9 | E15: 36 | F15: No Credit | G15: (No Credit) New Course Expansion for Grade Level
A16: Seminar 10 | B16: =LEN(A16) -> 10 | C16: AAH301X2 | D16: 10 | E16: 36 | F16: No Credit | G16: (No Credit) New Course Expansion for Grade Level
A17: Seminar 11 | B17: =LEN(A17) -> 10 | C17: AAH301X3 | D17: 11 | E17: 36 | F17: No Credit | G17: (No Credit) New Course Expansion for Grade Level
A18: Seminar 12 | B18: =LEN(A18) -> 10 | C18: AAH301X4 | D18: 12 | E18: 36 | F18: No Credit | G18: (No Credit) New Course Expansion for Grade Level
A19: Avid Tutor I | B19: =LEN(A19) -> 12 | C19: AAT501X1 | D19: 11-12 | E19: 36 | F19: Elective | G19: Course Title Change, Course Code Change, and Remove "R" Repeatable.
A20: Avid Tutor II | B20: 13 | C20: AAT501X2 | D20: 11-12 | E20: 36 | F20: Elective | G20: Expand Course Sequencing - Policy Change of No Repeating Course Codes "R".
A21: Yearbook Production | B21: =LEN(A21) -> 19 | C21: AAY301 | D21: 9-12 | E21: 36 | F21: Elective | G21: Can be taken for credit
A22: Yearbook Prod II | B22: =LEN(A22) -> 16 | C22: AAY401 | D22: 10-12 | E22: 36 | F22: Elective | G22: New Course
A23: Fundamentals of Art | B23: =LEN(A23) -> 19 | C23: ARA301 | D23: 9-12 | E23: 36 | F23: GF
A24: Art Appreciation | B24: =LEN(A24) -> 16 | C24: ARA302 | D24: 9-12 | E24: 36 | F24: GF
A25: AP Art History* | B25: =LEN(A25) -> 15 | C25: ARA611 | D25: 12 | E25: 36 | F25: GF | G25: (Weighted - Must Take AP Exam)
A26: AP Art History | B26: 14 | C26: ARA611U | D26: 12 | E26: 36 | F26: GF | G26: New Course (Unweighted - Did Not Take AP Exam)
A27: AP Studio Art Draw* | B27: =LEN(A27) -> 19 | C27: ARA613 | D27: 12 | E27: 36 | F27: GF | G27: (Weighted - Must Take AP Exam)
A28: AP Studio Art Draw | B28: =LEN(A28) -> 18 | C28: ARA613U | D28: 12 | E28: 36 | F28: GF | G28: New Course (Unweighted - Did Not Take AP Exam)
A29: AP Studio Art2D Des* | B29: =LEN(A29) -> 20 | C29: ARA614 | D29: 12 | E29: 36 | F29: GF | G29: (Weighted - Must Take AP Exam)
A30: AP Studio Art2D Des | B30: =LEN(A30) -> 19 | C30: ARA614U | D30: 12 | E30: 36 | F30: GF | G30: New Course (Unweighted - Did Not Take AP Exam)
A31: AP Studio Art3D Des* | B31: =LEN(A31) -> 20 | C31: ARA615 | D31: 12 | E31: 36 | F31: GF | G31: (Weighted - Must Take AP Exam)
A32: AP Studio Art3D Des | B32: =LEN(A32) -> 19 | C32: ARA615U | D32: 12 | E32: 36 | F32: GF | G32: New Course (Unweighted - Did Not Take AP Exam)
A33: Computer Art | B33: =LEN(A33) -> 12 | C33: ARC301 | D33: 9-12 | E33: 36 | F33: GF
A34: Sculpture | B34: =LEN(A34) -> 9 | C34: ARC401 | D34: 9-12 | E34: 36 | F34: GF
A35: Ceramics I | B35: =LEN(A35) -> 10 | C35: ARE401X1 | D35: 9-12 | E35: 36 | F35: GF | G35: Course Title Change, Course Code Change, and Remove "R" Repeatable.
A36: Ceramics II | B36: =LEN(A36) -> 11 | C36: ARE401X2 | D36: 9-12 | E36: 36 | F36: GF | G36: Expand Course Sequencing - Policy Change of No Repeating Course Codes "R".
A37: Ceramics III | B37: =LEN(A37) -> 12 | C37: ARE401X3 | D37: 9-12 | E37: 36 | F37: GF | G37: Expand Course Sequencing - Policy Change of No Repeating Course Codes "R".
A38: Ceramics IV | B38: =LEN(A38) -> 11 | C38: ARE401X4 | D38: 9-12 | E38: 36 | F38: GF | G38: Expand Course Sequencing - Policy Change of No Repeating Course Codes "R".
A39: Photography I | B39: =LEN(A39) -> 13 | C39: ARH401X1 | D39: 9-12 | E39: 36 | F39: GF | G39: Course Title Change, Course Code Change, and Remove "R" Repeatable.
A40: Photography II | B40: =LEN(A40) -> 14 | C40: ARH401X2 | D40: 9-12 | E40: 36 | F40: GF | G40: Expand Course Sequencing - Policy Change of No Repeating Course Codes "R".
...

Sheet  Middle School Courses
A1: =' High School Courses'!$A$1 -> As of: 24 February 2003 @ 1:00 | H1: =' High School Courses'!$G$1 -> File Name 03-04COR.XLS
A2: NOTE: USE THE TABS AT THE BOTTOM OF THIS SHEET TO SWITCH BETWEEN GRADES 9-12, GRADES 5-8, K-6, IB COURSES & AFCENT
A3: Scroll to the bottom of the sheet for changes (Drops and Adds) since the last publication
A4: COURSE TITLE | B4: TITLE LEN | C4: CODE | D4: GRADE | E4: LENGTH | F4: SUBJECT AREA | G4: REP | H4: COMMENT
A5: Staff Assistant M | B5: =LEN(A5) -> 17 | C5: AAC101 | D5: 5-8 | E5: 18 | F5: No Credit
A6: Lunch | B6: =LEN(A6) -> 5 | C6: AAC102 | D6: 5-12 | E6: 36 | F6: No Credit
A7: Learning Strateg. M | B7: =LEN(A7) -> 19 | C7: AAC131 | D7: 5-8 | E7: 36 | F7: No Credit | H7: Only for students on IEP
A8: Advisory 5 | B8: =LEN(A8) -> 10 | C8: AADE01 | D8: 5 | E8: 36 | F8: No Credit
A9: Advisory 6 | B9: =LEN(A9) -> 10 | C9: AADF01 | D9: 6 | E9: 36 | F9: No Credit
A10: Advisory 7 | B10: =LEN(A10) -> 10 | C10: AAD101 | D10: 7 | E10: 36 | F10: No Credit
A11: Advisory 8 | B11: =LEN(A11) -> 10 | C11: AAD201 | D11: 8 | E11: 36 | F11: No Credit
A12: Seminar M | B12: =LEN(A12) -> 9 | C12: AAH101 | D12: 5-8 | E12: 36 | F12: No Credit
A13: Study Skills | B13: =LEN(A13) -> 12 | C13: AAS101 | D13: 5-8 | E13: 9 | F13: No Credit
A14: YearbookProduction M | B14: =LEN(A14) -> 20 | C14: AAY101 | D14: 7-8 | E14: 36 | F14: No Credit
A15: Art 5 A | B15: =LEN(A15) -> 7 | C15: ARAE01 | D15: 5 | E15: 9 | F15: No Credit
A16: Art 5 B | B16: =LEN(A16) -> 7 | C16: ARAE02 | D16: 5 | E16: 9 | F16: No Credit
A17: Art 5 AB | B17: =LEN(A17) -> 8 | C17: ARAE03 | D17: 5 | E17: 18 | F17: No Credit
A18: Art 6 A | B18: =LEN(A18) -> 7 | C18: ARAF01 | D18: 6 | E18: 9 | F18: No Credit
A19: Art 6 B | B19: =LEN(A19) -> 7 | C19: ARAF02 | D19: 6 | E19: 9 | F19: No Credit
A20: Art 6 AB | B20: =LEN(A20) -> 8 | C20: ARAF03 | D20: 6 | E20: 18 | F20: No Credit
A21: Art 7-8 A | B21: =LEN(A21) -> 9 | C21: ARA101 | D21: 7-8 | E21: 9 | F21: No Credit
A22: Art 7-8 B | B22: =LEN(A22) -> 9 | C22: ARA102 | D22: 7-8 | E22: 9 | F22: No Credit
A23: Art 7-8 AB | B23: =LEN(A23) -> 10 | C23: ARA103 | D23: 7-8 | E23: 18 | F23: No Credit
A24: Business Enterprise | B24: =LEN(A24) -> 19 | C24: BCB101 | D24: 6-8 | E24: 36 | F24: No Credit
A25: Computer Apps A | B25: =LEN(A25) -> 15 | C25: BCT101 | D25: 6-8 | E25: 9 | F25: No Credit | H25: Course Title Change from Technology Applic A
A26: Computer Apps B | B26: =LEN(A26) -> 15 | C26: BCT102 | D26: 6-8 | E26: 9 | F26: No Credit | H26: Course Title Change from Technology Applic B
A27: Computer Apps AB | B27: =LEN(A27) -> 16 | C27: BCT103 | D27: 6-8 | E27: 18 | F27: No Credit | H27: Course Title Change from Technology Applic AB
A28: Computer Apps | B28: =LEN(A28) -> 13 | C28: BCT104 | D28: 6-8 | E28: 36 | F28: No Credit | H28: Course Title Change from Technology Applic
A29: Keyboarding I A | B29: =LEN(A29) -> 15 | C29: BCT105 | D29: 4-8 | E29: 9 | F29: No Credit
A30: Keyboarding I B | B30: =LEN(A30) -> 15 | C30: BCT106 | D30: 4-8 | E30: 9 | F30: No Credit
A31: Keyboarding I AB | B31: =LEN(A31) -> 16 | C31: BCT107 | D31: 4-8 | E31: 18 | F31: No Credit
A32: Tech Leader Comm M | B32: =LEN(A32) -> 18 | C32: BCT108 | D32: 7-8 | E32: 36 | F32: No Credit
A33: Intro Programming A | B33: =LEN(A33) -> 19 | C33: BCC101 | D33: 7-8 | E33: 9 | F33: No Credit
A34: Intro Programming B | B34: =LEN(A34) -> 19 | C34: BCC102 | D34: 7-8 | E34: 9 | F34: No Credit
A35: Intro Programming AB | B35: =LEN(A35) -> 20 | C35: BCC103 | D35: 7-8 | E35: 18 | F35: No Credit
A36: Drama A | B36: =LEN(A36) -> 7 | C36: DRA101 | D36: 6-8 | E36: 9 | F36: No Credit
A37: Drama B | B37: =LEN(A37) -> 7 | C37: DRA102 | D37: 6-8 | E37: 9 | F37: No Credit
A38: Drama AB | B38: =LEN(A38) -> 8 | C38: DRA103 | D38: 6-8 | E38: 18 | F38: No Credit
A39: Mini Course 5 | B39: =LEN(A39) -> 13 | C39: EXME01 | D39: 5 | E39: N/A | F39: No Credit | H39: Length is less than 9 weeks. PACIFIC ONLY
A40: Mini Course 6 | B40: =LEN(A40) -> 13 | C40: EXMF01 | D40: 6 | E40: N/A | F40: No Credit | H40: Length is less than 9 weeks. PACIFIC ONLY
...

Sheet Elementary School Courses
A1: =' High School Courses'!$A$1 -> As of: 24 February 2003 @ 1:00 | H1: =' High School Courses'!$G$1 -> File Name 03-04COR.XLS
A2: NOTE: USE THE TABS AT THE BOTTOM OF THIS SHEET TO SWITCH BETWEEN GRADES 9-12, GRADES 5-8, K-6, IB COURSES & AFCENT
A3: Scroll to the bottom of the sheet for changes (Drops and Adds) since the last publication
A4: COURSE TITLE | B4: TITLE LEN | C4: CODE | D4: GRADE | E4: LENGTH | F4: SUBJECT AREA | G4: REP | H4: COMMENT
A5: Art K | B5: =LEN(A5) -> 5 | C5: ARAK04 | D5: K | F5: No Credit
A6: Art 1 | B6: =LEN(A6) -> 5 | C6: ARAA04 | D6: 1 | F6: No Credit
A7: Art 2 | B7: =LEN(A7) -> 5 | C7: ARAB04 | D7: 2 | F7: No Credit
A8: Art 3 | B8: =LEN(A8) -> 5 | C8: ARAC04 | D8: 3 | F8: No Credit
A9: Art 4 | B9: =LEN(A9) -> 5 | C9: ARAD04 | D9: 4 | F9: No Credit
A10: Art 5 | B10: =LEN(A10) -> 5 | C10: ARAE04 | D10: 5 | F10: No Credit
A11: Art 6 | B11: =LEN(A11) -> 5 | C11: ARAF04 | D11: 6 | F11: No Credit
A12: Health Ed K | B12: =LEN(A12) -> 11 | C12: HLMK04 | D12: K | F12: No Credit
A13: Health Ed 1 | B13: =LEN(A13) -> 11 | C13: HLMA04 | D13: 1 | F13: No Credit
A14: Health Ed 2 | B14: =LEN(A14) -> 11 | C14: HLMB04 | D14: 2 | F14: No Credit
A15: Health Ed 3 | B15: =LEN(A15) -> 11 | C15: HLMC04 | D15: 3 | F15: No Credit
A16: Health Ed 4 | B16: =LEN(A16) -> 11 | C16: HLMD04 | D16: 4 | F16: No Credit
A17: Health Ed 5 | B17: =LEN(A17) -> 11 | C17: HLME04 | D17: 5 | F17: No Credit
A18: Health Ed 6 | B18: =LEN(A18) -> 11 | C18: HLMF04 | D18: 6 | F18: No Credit
A19: Intercultural Ed K | B19: =LEN(A19) -> 18 | C19: ICZK04 | D19: K | F19: No Credit
A20: Intercultural Ed 1 | B20: =LEN(A20) -> 18 | C20: ICZA04 | D20: 1 | F20: No Credit
A21: Intercultural Ed 2 | B21: =LEN(A21) -> 18 | C21: ICZB04 | D21: 2 | F21: No Credit
A22: Intercultural Ed 3 | B22: =LEN(A22) -> 18 | C22: ICZC04 | D22: 3 | F22: No Credit
... A60: Physical Ed 6 | B60: =LEN(A60) -> 13 | C60: PEGF04 | D60: 6 | F60: No Credit
A61: Science K | B61: 9 | C61: SCGK01 | D61: K | F61: No Credit
A62: Science 1 | B62: 9 | C62: SCGA01 | D62: 1 | F62: No Credit
A63: Science 2 | B63: =LEN(A63) -> 9 | C63: SCGB01 | D63: 2 | F63: No Credit
A64: Science 3 | B64: =LEN(A64) -> 9 | C64: SCGC01 | D64: 3 | F64: No Credit
A65: Science 4 | B65: =LEN(A65) -> 9 | C65: SCGD01 | D65: 4 | F65: No Credit
A66: Science 5 | B66: =LEN(A66) -> 9 | C66: SCGE01 | D66: 5 | F66: No Credit
A67: Science 6 | B67: =LEN(A67) -> 9 | C67: SCGF01 | D67: 6 | F67: No Credit
A68: Community Exper. E | B68: =LEN(A68) -> 18 | C68: SEC132 | F68: No Credit | H68: Only for students on IEP (Mod to Sev) Title Change
A69: Daily Living E | B69: =LEN(A69) -> 14 | C69: SED132 | F69: No Credit | H69: Only for students on IEP (Mod to Sev) Title Change
A70: Focus Read/Write E | B70: =LEN(A70) -> 18 | C70: SEL132 | F70: No Credit | H70: Only for students on IEP (Mod to Sev) Title Change
A71: Focus Math E | B71: =LEN(A71) -> 12 | C71: SEM132 | F71: No Credit | H71: Only for students on IEP (Mod to Sev) Title Change
A72: Social Skills E | B72: =LEN(A72) -> 15 | C72: SES132 | F72: No Credit | H72: Only for students on IEP (Mod to Sev) Title Change
A73: PreVocat. Skills E | B73: =LEN(A73) -> 18 | C73: SEV132 | F73: No Credit | H73: Only for students on IEP (Mod to Sev) Title Change
A74: Social Studies K | B74: =LEN(A74) -> 16 | C74: SSEK01 | D74: 1 | F74: No Credit
A75: Social Studies 1 | B75: =LEN(A75) -> 16 | C75: SSEA01 | D75: 2 | F75: No Credit
A76: Social Studies 2 | B76: =LEN(A76) -> 16 | C76: SSEB01 | D76: 2 | F76: No Credit
A77: Social Studies 3 | B77: =LEN(A77) -> 16 | C77: SSEC01 | D77: 3 | F77: No Credit
...

Sheet IB Courses -Bahrain Only
A1: =' High School Courses'!$A$1 -> As of: 24 February 2003 @ 1:00 | H1: =' High School Courses'!$G$1 -> File Name 03-04COR.XLS
A2: NOTE: USE THE TABS AT THE BOTTOM OF THIS SHEET TO SWITCH BETWEEN GRADES 9-12, GRADES 5-8, IB COURSES & AFCENT
A3: COURSE TITLE | B3: TITLE LEN | C3: CODE | D3: GRADE | E3: LENGTH | F3: SUBJECT AREA | G3: REP | H3: COMMENT
A4: IB Art 1 High | B4: =LEN(A4) -> 13 | C4: ARS592 | D4: 11-12 | E4: 36 | F4: GF
A5: IB Art 2 High | B5: =LEN(A5) -> 13 | C5: ARS692 | D5: 12 | E5: 36 | F5: GF | H5: (Weighted)
A6: IB Art 1 Sub | B6: =LEN(A6) -> 12 | C6: ARS591 | D6: 11-12 | E6: 36 | F6: GF
A7: IB Art 2 Sub | B7: =LEN(A7) -> 12 | C7: ARS691 | D7: 12 | E7: 36 | F7: GF
A8: IB Computer 1 High | B8: =LEN(A8) -> 18 | C8: CSP592 | D8: 11-12 | E8: 36 | F8: GC
A9: IB Computer 2 High | B9: =LEN(A9) -> 18 | C9: CSP692 | D9: 12 | E9: 36 | F9: GC | H9: (Weighted)
A10: IB Computer 1 Sub | B10: =LEN(A10) -> 17 | C10: CSP591 | D10: 11-12 | E10: 36 | F10: GC
A11: IB Computer 2 Sub | B11: =LEN(A11) -> 17 | C11: CSP691 | D11: 12 | E11: 36 | F11: GC
A12: IB Arabic 1 High | B12: =LEN(A12) -> 16 | C12: FLA592 | D12: 11-12 | E12: 36 | F12: GD
A13: IB Arabic 2 High | B13: =LEN(A13) -> 16 | C13: FLA692 | D13: 12 | E13: 36 | F13: GD | H13: (Weighted)
A14: IB Arabic 1 Sub | B14: =LEN(A14) -> 15 | C14: FLA591 | D14: 11-12 | E14: 36 | F14: GD
A15: IB Arabic 2 Sub | B15: =LEN(A15) -> 15 | C15: FLA691 | D15: 12 | E15: 36 | F15: GD
A16: IB French 1 High | B16: =LEN(A16) -> 16 | C16: FLF592 | D16: 11-12 | E16: 36 | F16: GD
A17: IB French 2 High | B17: =LEN(A17) -> 16 | C17: FLF692 | D17: 12 | E17: 36 | F17: GD | H17: (Weighted)
A18: IB French 1 Sub | B18: =LEN(A18) -> 15 | C18: FLF591 | D18: 11-12 | E18: 36 | F18: GD
A19: IB French 2 Sub | B19: =LEN(A19) -> 15 | C19: FLF691 | D19: 12 | E19: 36 | F19: GD
A20: IB German 1 High | B20: =LEN(A20) -> 16 | C20: FLG592 | D20: 11-12 | E20: 36 | F20: GD
A21: IB German 2 High | B21: =LEN(A21) -> 16 | C21: FLG692 | D21: 12 | E21: 36 | F21: GD | H21: (Weighted)
A22: IB German 1 Sub | B22: =LEN(A22) -> 15 | C22: FLG591 | D22: 11-12 | E22: 36 | F22: GD
A23: IB German 2 Sub | B23: =LEN(A23) -> 15 | C23: FLG691 | D23: 12 | E23: 36 | F23: GD
A24: IB English 1 High | B24: =LEN(A24) -> 17 | C24: LAE592 | D24: 11-12 | E24: 36 | F24: GL
A25: IB English 2 High | B25: =LEN(A25) -> 17 | C25: LAE692 | D25: 12 | E25: 36 | F25: GL | H25: (Weighted)
A26: IB English Sub | B26: =LEN(A26) -> 14 | C26: LAE591 | D26: 11-12 | E26: 36 | F26: GL
A27: IB World Lit 1 High | B27: =LEN(A27) -> 19 | C27: LAL592 | D27: 11-12 | E27: 36 | F27: GL
A28: IB World Lit 2 High | B28: =LEN(A28) -> 19 | C28: LAL692 | D28: 12 | E28: 36 | F28: GL | H28: (Weighted)
A29: IB World Lit 1 Sub | B29: =LEN(A29) -> 18 | C29: LAL591 | D29: 11-12 | E29: 36 | F29: GL
A30: IB World Lit 2 Sub | B30: =LEN(A30) -> 18 | C30: LAL691 | D30: 12 | E30: 36 | F30: GL
A31: IB Math 1 | B31: =LEN(A31) -> 9 | C31: MAA591 | D31: 11 | E31: 36 | F31: GM
A32: IB Math 2 High | B32: =LEN(A32) -> 14 | C32: MAC691 | D32: 12 | E32: 36 | F32: GM | H32: (Weighted)
A33: IB Math 3 | B33: =LEN(A33) -> 9 | C33: MAC692 | D33: 12 | E33: 36 | F33: GM
A34: IB Math 2 Sub | B34: =LEN(A34) -> 13 | C34: MAD691 | D34: 12 | E34: 36 | F34: GM
A35: IB Biology 1 High | B35: =LEN(A35) -> 17 | C35: SCB592 | D35: 11-12 | E35: 36 | F35: GS
A36: IB Biology 2 High | B36: =LEN(A36) -> 17 | C36: SCB692 | D36: 12 | E36: 36 | F36: GS | H36: (Weighted)
A37: IB Biology 1 Sub | B37: =LEN(A37) -> 16 | C37: SCB591 | D37: 11-12 | E37: 36 | F37: GS
A38: IB Biology 2 Sub | B38: =LEN(A38) -> 16 | C38: SCB691 | D38: 12 | E38: 36 | F38: GS
A39: IB Chemistry1 High | B39: =LEN(A39) -> 19 | C39: SCC592 | D39: 11-12 | E39: 36 | F39: GS
A40: IB Chemistry 2 High | B40: =LEN(A40) -> 19 | C40: SCC692 | D40: 12 | E40: 36 | F40: GS | H40: (Weighted)
...

Sheet Special Courses - AFNORTH Only
A1: =' High School Courses'!$A$1 -> As of: 24 February 2003 @ 1:00 | H1: =' High School Courses'!$G$1 -> File Name 03-04COR.XLS
A2: NOTE: USE THE TABS AT THE BOTTOM OF THIS SHEET TO SWITCH BETWEEN GRADES 9-12, GRADES 5-8, IB COURSES & AFCENT
A4: COURSE TITLE | B4: TITLE LEN | C4: CODE | D4: GRADE | E4: LENGTH | F4: SUBJECT AREA | G4: REP | H4: COMMENT
A5: French First Lang 7 | B5: =LEN(A5) -> 19 | C5: FFL101 | D5: 7 | E5: 36 | F5: No Credit
A6: French First Lang 8 | B6: =LEN(A6) -> 19 | C6: FFL201 | D6: 8 | E6: 36 | F6: No Credit
A7: French First Lang 9 | B7: =LEN(A7) -> 19 | C7: FFL301 | D7: 9 | E7: 36 | F7: Elective
A8: French First Lang 10 | B8: =LEN(A8) -> 20 | C8: FFL401 | D8: 10 | E8: 36 | F8: Elective
A9: English 9 C | B9: =LEN(A9) -> 11 | C9: LAE301C | D9: 9 | E9: 36 | F9: GL - English 9
A10: English 10 C | B10: =LEN(A10) -> 12 | C10: LAE401C | D10: 10 | E10: 36 | F10: GL - English 10
A11: English 11 C | B11: =LEN(A11) -> 12 | C11: LAE501C | D11: 11 | E11: 36 | F11: GL - English 11
A12: English 12 C | B12: =LEN(A12) -> 12 | C12: LAE601C | D12: 12 | E12: 36 | F12: GL - English 12
A13: Principles Math 9 | B13: =LEN(A13) -> 17 | C13: MAZ301C | D13: 9 | E13: 36 | F13: GM - Algebra I
A14: Principles Math 10 | B14: =LEN(A14) -> 18 | C14: MAZ401C | D14: 10 | E14: 36 | F14: GM - Geometry
A15: Functions &Relations | B15: =LEN(A15) -> 20 | C15: MAZ501C | D15: 11 | E15: 36 | F15: Elective
A16: Math Everyday Life | B16: =LEN(A16) -> 18 | C16: MAZ502C | D16: 11-12 | E16: 36 | F16: Elective
A17: Science 10, Academic | B17: =LEN(A17) -> 20 | C17: SCG401C | D17: 10 | E17: 36 | F17: GS - Biology | H17: Cannot receive credit for Science 10 Academic and Biology
A18: French World Geog 7 | B18: =LEN(A18) -> 19 | C18: SSC101F | D18: 7 | E18: 36 | F18: No Credit
A19: French Canadian Geog | B19: =LEN(A19) -> 20 | C19: SSC301F | D19: 9-12 | E19: 36 | F19: Elective
A20: Geography of Canada | B20: =LEN(A20) -> 19 | C20: SSC302C | D20: 9 | E20: 36 | F20: Elective
A21: Civics | B21: =LEN(A21) -> 6 | C21: SSG401C | D21: 10 | E21: 36 | F21: Elective
A22: French World Hist 8 | B22: =LEN(A22) -> 19 | C22: SSW201F | D22: 8 | E22: 36 | F22: No Credit
A23: Fr Canadian Hist | B23: =LEN(A23) -> 16 | C23: SSW303F | D23: 9-12 | E23: 36 | F23: Elective
