Workbook

Sheet Read me first!
B2: User Warning
C3: This database was assembled largely from information received from all the air districts in California except the Bay Area AQMD, with supplemental information supplied by the California Department of Corrections, The Office of Energy Assessments of the California Department of General Services, PG&E, Silicon Valley Power, and a major telecommunications company operating in the state. The user of this inventory needs to be aware of several assumptions made in assembling elements of the database, as well as several known limitations. These include:
C4: • Only BUGs with generating capacities greater than 300 kW are included in the inventory database.
C5: • Data on BUGs in the Bay Area AQMD (BAAQMD) is limited to that supplied by PG&E, Silicon Valley Power, and the major telecommunications company. The inventory most certainly does not include all BUGs in the jurisdiction of the BAAQMD. Although the BAAQMD provided a database of permitted engines in August 2003, it did not contain information on equipment location needed for this database. Therefore, no information provided by BAAQMD is included in this database.
C6: • Facility name, address, and contact information in the data supplied by PG&E are not included in this database as PG&E considers this customer information to be sensitive and privileged.
C7: • The top 14 district sources supplied data generally current though October 2003. The exceptions include the San Diego County APCD data which reflect applications through August 2003, and the Sacramento Metropolitan AQMD and El Dorado County AQMD data which reflect applications through September 2003. The table in the sheet tabbed "How Current" summarizes the timing of the most recent updates from the various data sources.
C8: • NOx and PM emissions factors were taken from the ARB OFFROAD model, and represent average emission factors for corresponding engine ratings and year of manufacture. Emission factors are noted only for diesel-fueled BUGs with known permit application years. The permit application year was assumed to be the BUG year of manufacture.
C9: • Missing numbers in sequence within a data source are the result of cancellations and deletions
B11: Database Structure
C12: The database is contained in the sheet tabbed "Inventory." Each BUG record contains the following information, when available from the data source, arranged in columns:
C13: • Record Number: A number assigned by TIAX/NCI for tracking purposes
C14: • Data Source: A 2 or 3 letter code that corresponds to the source of the data; the table below indicates data sources corresponding to each code
C15: • Facility Name: The BUG owner and facility name
C16: • Permit Application Number: The air district application number for the BUG's air permit
C17: • Permit Application Year: The year the initial air permit application was submitted
C18: • Permit Number: The air district number of the air permit issued
C19: • Engine Description: All information describing the BUG's engine received from the data source
C20: • Primary Fuel: The BUG's primary fuel
C21: • Manufacturer: The manufacturer of the BUG's engine
C22: • Model: The model number of the BUG's engine
C23: • Generator Capacity: The stated or estimated BUG generation capacity (kW); if the capacity was stated by the data source, this is the value used; if the data source only gave the BUG engine's hp or bhp rating, then the generator capacity is calculated from the stated hp or bhp rating using a conversion factor of 0.67 kW/hp
... C33: • PM Emission Factor: Estimated particulate (PM) emission factor (g/bhp-hr); see last item under User Warning above
B35: Data Source Codes
B37: Code | C37: Data Source
B38: AMA | C38: Amador County APCD
B39: AV | C39: Antelope Valley APCD
B40: BTT | C40: Butte County AQMD
B41: CLS | C41: Colusa County APCD
B42: CSC | C42: Silicon Valley Power (City of Santa Clara)
B43: DOC | C43: California Department of Corrections
B44: DWP | C44: Los Angeles Department of Water and Power
B45: EDC | C45: El Dorado County APCD
B46: FRV | C46: Feather River AQMD
B47: GB | C47: Great Basin Unified APCD
B48: GLN | C48: Glenn County APCD
... B70: YS | C70: Yolo Solano AQMD

Sheet How Current
B2: Source | C2: Number of BUGs | D2: Total MW | E2: Database Current Through:
B3: Air Districts
B4: South Coast AQMD | C4: =COUNT(Inventory!K2:K2234) -> 2233 | D4: =SUM(Inventory!K2:K2234)/1000 -> 1844.8673 | E4: October 2003
B5: San Diego County APCD | C5: =COUNT(Inventory!K2762:K3378) -> 617 | D5: =SUM(Inventory!K2762:K3378)/1000 -> 433.19867 | E5: August 2003
B6: San Joaquin Valley Unified APCD | C6: =COUNT(Inventory!K2235:K2761) -> 527 | D6: =SUM(Inventory!K2235:K2761)/1000 -> 402.31967 | E6: October 2003
B7: Sacramento Metropolitan AQMD | C7: =COUNT(Inventory!K3513:K3871) -> 359 | D7: =SUM(Inventory!K3513:K3871)/1000 -> 298.19267 | E7: September 2003
B8: Monterey Bay Unified APCD | C8: =COUNT(Inventory!K3379:K3512) -> 134 | D8: =SUM(Inventory!K3379:K3512)/1000 -> 88.134 | E8: October 2003
B9: Yolo/Solano AQMD | C9: =COUNT(Inventory!K3949:K4038) -> 90 | D9: =SUM(Inventory!K3949:K4038)/1000 -> 74.947333 | E9: October 2003
B10: Ventura County APCD | C10: =COUNT(Inventory!K4208:K4273) -> 66 | D10: =SUM(Inventory!K4208:K4273)/1000 -> 60.324333 | E10: October 2003
B11: Mojave Desert AQMD | C11: =COUNT(Inventory!K3872:K3948) -> 77 | D11: =SUM(Inventory!K3872:K3948)/1000 -> 46.193333 | E11: October 2003
B12: Placer County APCD | C12: =COUNT(Inventory!K4341:K4380) -> 40 | D12: =SUM(Inventory!K4341:K4380)/1000 -> 44.865667 | E12: October 2003
B13: San Luis Obispo County APCD | C13: =COUNT(Inventory!K4139:K4177) -> 39 | D13: =SUM(Inventory!K4139:K4177)/1000 -> 30.523333 | E13: October 2003
B14: Antelope Valley APCD | C14: =COUNT(Inventory!K4039:K4083) -> 45 | D14: =SUM(Inventory!K4039:K4083)/1000 -> 27.451333 | E14: October 2003
B15: Kern County APCD | C15: =COUNT(Inventory!K4287:K4325) -> 39 | D15: =SUM(Inventory!K4287:K4325)/1000 -> 18.102667 | E15: October 2003
B16: El Dorado County AQMD | C16: =COUNT(Inventory!K4084:K4117) -> 34 | D16: =SUM(Inventory!K4084:K4117)/1000 -> 22.215333 | E16: September 2003
B17: Feather River AQMD | C17: =COUNT(Inventory!K4178:K4198) -> 21 | D17: =SUM(Inventory!K4178:K4198)/1000 -> 14.6 | E17: October 2003
B18: Imperial County APCD | C18: =COUNT(Inventory!K4202:K4207) -> 6 | D18: =SUM(Inventory!K4202:K4207)/1000 -> 9.6513333 | E18: April 2001
B19: Butte County AQMD | C19: =COUNT(Inventory!K4393:K4405) -> 13 | D19: =SUM(Inventory!K4393:K4405)/1000 -> 9.1493333 | E19: April 2001
B20: Great Basin Unified APCD | C20: =COUNT(Inventory!K4118:K4128) -> 11 | D20: =SUM(Inventory!K4118:K4128)/1000 -> 7.9853333 | E20: March 2001
B21: Santa Barbara County APCD | C21: =COUNT(Inventory!K4274:K4286) -> 13 | D21: =SUM(Inventory!K4274:K4286)/1000 -> 7.8 | E21: March 2001, poor recordkeeping prior to 2001
B22: Amador County APCD | C22: =COUNT(Inventory!K4129:K4136) -> 8 | D22: =SUM(Inventory!K4129:K4136)/1000 -> 6.949 | E22: April 2001
B23: Shasta County AQMD | C23: =COUNT(Inventory!K4381:K4389) -> 9 | D23: =SUM(Inventory!K4381:K4389)/1000 -> 6.4096667 | E23: April 2001
B24: Lake County AQMD | C24: =COUNT(Inventory!K4326:K4333) -> 8 | D24: =SUM(Inventory!K4326:K4333)/1000 -> 3.87 | E24: April 2001
B25: Mendocino County AQMD | C25: =COUNT(Inventory!K4337:K4339) -> 3 | D25: =SUM(Inventory!K4337:K4339)/1000 -> 2.25 | E25: April 2001
B26: Glenn County APCD | C26: =COUNT(Inventory!K4199:K4201) -> 3 | D26: =SUM(Inventory!K4199:K4201)/1000 -> 1.529 | E26: April 2001
B27: Mariposa County APCD | C27: =COUNT(Inventory!K4334:K4336) -> 3 | D27: =SUM(Inventory!K4334:K4336)/1000 -> 1.12 | E27: April 2001
B28: Tehama County APCD | C28: =COUNT(Inventory!K4390:K4392) -> 3 | D28: =SUM(Inventory!K4390:K4392)/1000 -> 0.98333333 | E28: April 2001
B29: North Coast Unified AQMD | C29: =COUNT(Inventory!K4340) -> 1 | D29: =SUM(Inventory!K4340)/1000 -> 0.75 | E29: April 2001
B30: Colusa County APCD | C30: =COUNT(Inventory!K4137:K4138) -> 2 | D30: =SUM(Inventory!K4137:K4138)/1000 -> 0.7 | E30: April 2001
B32: Other Sources
B33: Pacific Gas & Electric | C33: =COUNT(Inventory!K4448:K4803) -> 356 | D33: =SUM(Inventory!K4448:K4803)/1000 -> 295.1772 | E33: March 2003
B34: California Department of Corrections | C34: =COUNT(Inventory!K4818:K4847) -> 30 | D34: =SUM(Inventory!K4818:K4847)/1000 -> 36.9 | E34: May 2000
B35: Silicon Valley Power | C35: =COUNT(Inventory!K4406:K4447) -> 42 | D35: =SUM(Inventory!K4406:K4447)/1000 -> 35.725 | E35: April 2001
B36: Major Telecommunications Company | C36: =COUNT(Inventory!K4848:K4907) -> 60 | D36: =SUM(Inventory!K4848:K4907)/1000 -> 33.215 | E36: April 2001
B37: Office of Energy Assessments-California Department of General Services | C37: =COUNT(Inventory!K4811:K4817) -> 7 | D37: =SUM(Inventory!K4811:K4817)/1000 -> 8.3733333 | E37: March 2001
B38: Los Angeles Dept. of Water and Power | C38: =COUNT(Inventory!K4804:K4810) -> 7 | D38: =SUM(Inventory!K4804:K4810)/1000 -> 5.76 | E38: April 2001
B39: Totals | C39: =SUM(C4:C38) -> 4906 | D39: =SUM(D4:D38) -> 3880.2332

Sheet Inventory
A1: Record Number | B1: Data Source | C1: Facility Name | D1: Permit Application Number | E1: Permit Application Year | F1: Permit Number | G1: Engine Description | H1: Primary Fuel | I1: Manufacturer | J1: Model | K1: Generator Capacity (kW) | L1: Stated Generator Capacity (kW) | M1: Stated Engine Rating (hp) | N1: Stated Engine Rating (bhp) | O1: Facility Address | P1: City | Q1: Zip Code | R1: Contact Person | S1: Contact Phone Number | T1: NOx Emission Factor (g/bhp-hr) | U1: PM Emission Factor (g/bhp-hr)
A2: 1 | B2: SC | C2: 1875/1925 CENTURY PARK EAST CO | D2: 296382 | E2: 1994 | F2: D85615 | G2: ICE, CATERPILLAR, DIESEL, EMR, MODEL 3412, SN 3857846, TURBOCHARGED, AFTERCOOLED, 12 CYL, 755 BHP | H2: Diesel | I2: Caterpillar | J2: 3412 | K2: =L2+M2*(2/3)+N2*(2/3) -> 503.33333 | N2: 755 | O2: 1875 CENTURY PARK E | P2: LOS ANGELES | Q2: 90067 | R2: DIEHR STEVE | S2: (310) 2030330 | T2: 8.17 | U2: 0.38
A3: 4 | B3: SC | C3: 20TH CENTURY FOX FILM CORP | D3: 330888 | E3: 1997 | F3: F8683 | G3: ICE, CUMMINS, DIESEL, EMR, MODEL QST30-G2, TURBOCHARGED, AFTERCOOLED, 12 CYL, 800 KW, EMR | H3: Diesel | I3: Cummins | J3: QST30-G2 | K3: =L3+M3*(2/3)+N3*(2/3) -> 800 | L3: 800 | O3: 10201 W PICO BLVD BLDG 99 | P3: LOS ANGELES | Q3: 90064-2651 | R3: CANDLER TREVOR | S3: (310) 3696623 | T3: 8.17 | U3: 0.38
A4: 5 | B4: SC | C4: 20TH CENTURY INSURANCE CO | D4: 361864 | E4: 1999 | F4: F23017 | G4: ICE, CUMMINS, DIESEL, EMR, MODEL KTA50-G9, EMR TURBOCHARGED, AFTERCOOLED, 16 CYL, 1500 KW | H4: Diesel | I4: Cummins | J4: KTA50-G9 | K4: =L4+M4*(2/3)+N4*(2/3) -> 1500 | L4: 1500 | O4: 6301 OWENSMOUTH AVE | P4: WOODLAND HILLS | Q4: 91367-2286 | R4: LANDGRAF BERNARD | S4: (818) 7043091 | T4: 8.17 | U4: 0.38
A5: 7 | B5: SC | C5: 360 NETWORKS (USA) INC | D5: 377563 | E5: 2000 | F5: F35656 | G5: ICE, CATERPILLAR, DIESEL, 12 CYL, TURBOCHARGED, AFTERCOOLED, MODEL 3512B DITA, SN 8RM00626, 1500 KW, EMR | H5: Diesel | I5: Caterpillar | J5: 3512B DITA | K5: =L5+M5*(2/3)+N5*(2/3) -> 1500 | L5: 1500 | O5: 600 W 7 TH ST | P5: LOS ANGELES | Q5: 90017 | R5: WALKER RICHARD | S5: (541) 3187392 | T5: 6.9 | U5: 0.4
A6: 8 | B6: SC | C6: 360 NETWORKS (USA) INC | D6: 377564 | E6: 2000 | F6: F35657 | G6: ICE, CATERPILLAR, DIESEL, 12 CYL, TURBOCHARGED, AFTERCOOLED, MODEL 3512B DITA, SN 8RM00627, 1500 KW, EMR | H6: Diesel | I6: Caterpillar | J6: 3512B DITA | K6: =L6+M6*(2/3)+N6*(2/3) -> 1500 | L6: 1500 | O6: 600 W 7 TH ST | P6: LOS ANGELES | Q6: 90017 | R6: WALKER RICHARD | S6: (541) 3187392 | T6: 6.9 | U6: 0.4
A7: 9 | B7: SC | C7: 360 NETWORKS (USA) INC | D7: 377566 | E7: 2000 | F7: F35661 | G7: ICE, CATERPILLAR, DIESEL, 12 CYL, TURBOCHARGED, AFTERCOOLED, MODEL 3512B DITA, SN 8RM00628, 1500 KW, EMR | H7: Diesel | I7: Caterpillar | J7: 3512B DITA | K7: =L7+M7*(2/3)+N7*(2/3) -> 1500 | L7: 1500 | O7: 600 W 7 TH ST | P7: LOS ANGELES | Q7: 90017 | R7: WALKER RICHARD | S7: (541) 3187392 | T7: 6.9 | U7: 0.4
A8: 10 | B8: SC | C8: 450 NORTH BRAND LLC | D8: 363450 | E8: 1999 | F8: F23702 | G8: ICE, DETROIT DIESEL, 12 CYL, TURBOCHARGED, AFTERCOOLED, MODEL 12V-92TA, SN 12VF013933, 830 BHP, EMR | H8: Diesel | I8: Detroit Diesel | J8: 12V-92TA | K8: =L8+M8*(2/3)+N8*(2/3) -> 553.33333 | N8: 830 | O8: 450 N BRAND BLVD | P8: GLENDALE | Q8: 91209 | R8: TEEGARDEN CATHY | S8: (818) 2422152 | T8: 8.17 | U8: 0.38
A9: 12 | B9: SC | C9: 4MC-BURBANK, INC. | D9: 357595 | E9: 1999 | F9: F21411 | G9: ICE, CATERPILLAR, 12 CYL, TURBOCHARGED, AFTERCOOLED, MODEL 3512 DITA, 1250 KW, DIESEL, EMR | H9: Diesel | I9: Caterpillar | J9: 3512 DITA | K9: =L9+M9*(2/3)+N9*(2/3) -> 1250 | L9: 1250 | O9: 2901 W ALAMEDA AVE | P9: BURBANK | Q9: 91505 | R9: TABB JOHN | S9: (818) 8407207 | T9: 8.17 | U9: 0.38
A10: 13 | B10: SC | C10: 550 NORTH BRAND OWNER'S CORP | D10: 286105 | E10: 1993 | F10: D77793 | G10: ICE, CATERPILLAR, 12 CYL, TURBOCHARGED, AFTERCOOLED, MODEL 3412, SN 81205336, 558 BHP, DIESEL, EMR | H10: Diesel | I10: Caterpillar | J10: 3412 | K10: =L10+M10*(2/3)+N10*(2/3) -> 372 | N10: 558 | O10: 550 N BRAND BLVD | P10: GLENDALE | Q10: 91203 | R10: ROSS JUNE | S10: (818) 2426550 | T10: 8.17 | U10: 0.38
A11: 14 | B11: SC | C11: 600 ANTON BLV ASSOC,SO COAST PLZ TWN CTR | D11: 260878 | E11: 1991 | F11: D51286 | G11: ICE, CATERPILLAR, 8 CYL, DIESEL, EMR, MODEL 3508/750, SN 23203472, TURBOCHARGED, AFTERCOOLED, 1098 BHP | H11: Diesel | I11: Caterpillar | J11: 3508 | K11: =L11+M11*(2/3)+N11*(2/3) -> 732 | N11: 1098 | O11: 600 ANTON BLVD | P11: COSTA MESA | Q11: 92626 | R11: SUTTON DON | S11: (714) 4352133 | T11: 8.17 | U11: 0.38
A12: 15 | B12: SC | C12: 611 W 6TH ST ASSOC LLC/METCOM MGMT LLC | D12: 368199 | E12: 2000 | F12: F33277 | G12: ICE, CATERPILLAR, 12 CYL, DIESEL, EMR, MODEL 3412DIT, SN 81Z02794, TURBOCHARGED, AFTERCOOLED, 755 BHP | H12: Diesel | I12: Caterpillar | J12: 3412 DIT | K12: =L12+M12*(2/3)+N12*(2/3) -> 503.33333 | N12: 755 | O12: 611 W 6TH ST | P12: LOS ANGELES | Q12: 90017 | R12: KOILE STEPHEN | S12: (213) 6239989 | T12: 6.9 | U12: 0.4
A13: 16 | B13: SC | C13: 611 W 6TH ST ASSOC LLC/METCOM MGMT LLC | D13: 368200 | E13: 2000 | F13: F33278 | G13: ICE, DETROIT DIESEL, 16 CYL, TURBOCHARGED, AFTERCOOLED, MODEL 7163-7400, SN 16V3328, 700 BHP, EMR, DIESEL | H13: Diesel | I13: Detroit Diesel | J13: 7163-7400 | K13: =L13+M13*(2/3)+N13*(2/3) -> 466.66667 | N13: 700 | O13: 611 W 6TH ST | P13: LOS ANGELES | Q13: 90017 | R13: KOILE STEPHEN | S13: (213) 6239989 | T13: 6.9 | U13: 0.4
A14: 17 | B14: SC | C14: 6300 WILSHIRE ASSOCIATES | D14: 261846 | E14: 1992 | F14: D48429 | G14: ICE, DETROIT DIESEL, 12 CYL, TURBOCHARGED, AFTERCOOLED, MODEL 8123-7405, SN 12VF013933, 830 BHP, EMR, DIESEL | H14: Diesel | I14: Detroit Diesel | J14: 8123-7405 | K14: =L14+M14*(2/3)+N14*(2/3) -> 553.33333 | N14: 830 | O14: 6300 WILSHIRE BLVD #1115 | P14: LOS ANGELES | Q14: 90048-5213 | R14: O'KEEFE KEN | S14: (323) 6555443 | T14: 8.17 | U14: 0.38
A15: 18 | B15: SC | C15: AT & T WIRELESS | D15: 366410 | E15: 2000 | F15: F31366 | G15: ICE, CUMMINS, DIESEL, MODEL KTA19-G4, TURBOCHARGED, AFTERCOOLED, EMERGENCY ELECTRICAL GENERATION, 755 BHP | H15: Diesel | I15: Cummins | J15: KTA19-G4 | K15: =L15+M15*(2/3)+N15*(2/3) -> 503.33333 | N15: 755 | O15: 301 N CRESCENT WAY | P15: ANAHEIM | Q15: 92805 | R15: WALDEN BARBARA | S15: (925) 2241488 | T15: 6.9 | U15: 0.4
A16: 19 | B16: SC | C16: AB CELLULAR HOLDING/AT&T WIRELESS | D16: 374313 | E16: 2000 | F16: F34169 | G16: ICE, CUMMINS, MODEL N14 G2, SN 12004341, DIESEL, 6 CYL, TURBOCHARGED, AFTERCOOLED, 535 BHP, EMR | H16: Diesel | I16: Cummins | J16: N14-G2 | K16: =L16+M16*(2/3)+N16*(2/3) -> 356.66667 | N16: 535 | O16: 4135 GARNER RD | P16: RIVERSIDE | Q16: 92501 | R16: WALDEN BARBARA | S16: (925) 2241488 | T16: 6.9 | U16: 0.4
A17: 20 | B17: SC | C17: AB CELLULAR HOLDING/AT&T WIRELESS | D17: 374315 | E17: 2000 | F17: F34172 | G17: ICE, CUMMINS, MODEL N14 G2, SN 12004388, DIESEL, 6 CYL, TURBOCHARGED, AFTERCOOLED, 535 BHP, EMR | H17: Diesel | I17: Cummins | J17: N14-G2 | K17: =L17+M17*(2/3)+N17*(2/3) -> 356.66667 | N17: 535 | O17: 4135 GARNER RD | P17: RIVERSIDE | Q17: 92501 | R17: WALDEN BARBARA | S17: (925) 2241488 | T17: 6.9 | U17: 0.4
A18: 21 | B18: SC | C18: AB CELLULAR HOLDING/AT&T WIRELESS | D18: 374317 | E18: 2000 | F18: F34174 | G18: ICE, CUMMINS, MODEL QSX15-G9, SN 14009139, DIESEL, 6 CYL, TURBOCHARGED, AFTERCOOLED, 765 BHP, EMR | H18: Diesel | I18: Cummins | J18: QSX15-G9 | K18: =L18+M18*(2/3)+N18*(2/3) -> 510 | N18: 765 | O18: 4135 GARNER RD | P18: RIVERSIDE | Q18: 92501 | R18: WALDEN BARBARA | S18: (925) 2241488 | T18: 6.9 | U18: 0.4
A19: 22 | B19: SC | C19: ABLESTIK LABORATORIES | D19: 379682 | E19: 2001 | F19: F37050 | G19: ICE, DETROIT DIESEL, 12 CYL, TURBOCHARGED, AFTERCOOLED, MODEL T123-7K36 (12V-4000), 2200 BHP, DIESEL, EMR | H19: Diesel | I19: Detroit Diesel | J19: T123-7K36 | K19: =L19+M19*(2/3)+N19*(2/3) -> 1466.6667 | N19: 2200 | O19: 20021 SUSANA RD | P19: RANCHO DOMINGUEZ | Q19: 90221 | R19: GEBREYESUS YARED | S19: (310) 6055764 | T19: 6.9 | U19: 0.4
A20: 32 | B20: SC | C20: ACADEMY MOTION PICTURES OF ARTS &SCIENCE | D20: 340677 | E20: 1998 | F20: F14027 | G20: ICE, CUMMINS, 6 CYL, TURBOCHARGED, AFTERCOOLED, MODEL NTA855-G3, 535 BHP, DIESEL, EMR | H20: Diesel | I20: Cummins | J20: NTA855-G3 | K20: =L20+M20*(2/3)+N20*(2/3) -> 356.66667 | N20: 535 | O20: 8949 WILSHIRE BLVD | P20: BEVERLY HILLS | Q20: 90210 | R20: EDWARDS DOUG | S20: (213) 2788990 | T20: 6.9 | U20: 0.4
A21: 33 | B21: SC | C21: AETNA LIFE INSURANCE CO . | D21: 345974 | E21: 1998 | F21: F16616 | G21: ICE, CUMMINS, 6 CYL, TURBOCHARGED, AFTERCOOLED, MODEL NTA855-G3, 535 BHP, DIESEL, EMR | H21: Diesel | I21: Cummins | J21: NTA855-G3 | K21: =L21+M21*(2/3)+N21*(2/3) -> 356.66667 | N21: 535 | O21: 251 S LAKE AVE | P21: PASADENA | Q21: 91125 | R21: ALVARADO ARMAND V | S21: (626) 7925161 | T21: 6.9 | U21: 0.4
A22: 34 | B22: SC | C22: AETNA LIFE INSURANCE COMPANY | D22: 290657 | E22: 1994 | F22: D81346 | G22: ICE, CATERPILLAR, MODEL D348PCTA, SN JO3053, 600KW, DIESEL, 12 CYL, AFTERCOOLED, EMR, | H22: Diesel | I22: Caterpillar | J22: D348 PCTA | K22: =L22+M22*(2/3)+N22*(2/3) -> 600 | L22: 600 | O22: 225 S LAKE AVE | P22: PASADENA | Q22: 91101 | R22: ALVARADO ARMAND | S22: (626) 7925161 | T22: 8.17 | U22: 0.38
A23: 35 | B23: SC | C23: AGGREKO INC | D23: 168559 | E23: 1988 | F23: D37004 | G23: ICE, CUMMINS, 6 CYL, TURBOCHARGED, AFTERCOOLED, MODEL KTTA-19-G, 620 BHP, DIESEL. | H23: Diesel | I23: Cummins | J23: KTTA19-G | K23: =L23+M23*(2/3)+N23*(2/3) -> 413.33333 | N23: 620 | O23: VARIOUS LOCATIONS IN SCAQMD | P23: SANTA FE SPRINGS | Q23: 90670-4995 | R23: ONEILL PETER | S23: (310) 8027972 | T23: 8.17 | U23: 0.38
A24: 36 | B24: SC | C24: AGGREKO INC | D24: 168560 | E24: 1988 | F24: D37005 | G24: ICE, CUMMINS, 6 CYL, TURBOCHARGED, AFTERCOOLED, MODEL KTTA-19-G, 620 BHP, DIESEL. | H24: Diesel | I24: Cummins | J24: KTTA19-G | K24: =L24+M24*(2/3)+N24*(2/3) -> 413.33333 | N24: 620 | O24: VARIOUS LOCATIONS IN SCAQMD | P24: SANTA FE SPRINGS | Q24: 90670-4995 | R24: ONEILL PETER | S24: (310) 8027972 | T24: 8.17 | U24: 0.38
A25: 37 | B25: SC | C25: AGGREKO INC | D25: 168561 | E25: 1988 | F25: D37006 | G25: ICE, CUMMINS, 6 CYL, TURBOCHARGED, AFTERCOOLED, MODEL KTTA-19-G, 620 BHP, DIESEL. | H25: Diesel | I25: Cummins | J25: KTTA19-G | K25: =L25+M25*(2/3)+N25*(2/3) -> 413.33333 | N25: 620 | O25: VARIOUS LOCATIONS IN SCAQMD | P25: SANTA FE SPRINGS | Q25: 90670-4995 | R25: ONEILL PETER | S25: (310) 8027972 | T25: 8.17 | U25: 0.38
A26: 40 | B26: SC | C26: AGGREKO INC | D26: 299501 | E26: 1995 | F26: D96673 | G26: ICE, CUMMINS, PORTABLE, MODEL P 6558, SN 37140831, DIESEL, 6 CYL, TURBOCHARGED, AFTERCOOLED, 620 BHP | H26: Diesel | I26: Cummins | J26: P 6558 | K26: =L26+M26*(2/3)+N26*(2/3) -> 413.33333 | N26: 620 | O26: VARIOUS LOCATIONS IN SCAQMD | P26: SANTA FE SPRINGS | Q26: 90670-4995 | R26: ONEILL PETER | S26: (310) 8027972 | T26: 8.17 | U26: 0.38
A27: 49 | B27: SC | C27: AGL INVESTMENTS #5 | D27: 363379 | E27: 1999 | F27: F32814 | G27: ICE, CATERPILLAR, MODEL 3412, SN 81Z06828, 724 BHP, DIESEL, 12 CYL, TURBOCHARGED, AFTERCOOLED, EMR, | H27: Diesel | I27: Caterpillar | J27: 3412 | K27: =L27+M27*(2/3)+N27*(2/3) -> 482.66667 | N27: 724 | O27: 555 ANTON BLVD | P27: COSTA MESA | Q27: 92626 | R27: HUNTER JAMES | S27: (714) 7084350 | T27: 6.9 | U27: 0.4
A28: 50 | B28: SC | C28: AGUINAGA FERTILIZER CO INC | D28: 378015 | E28: 2000 | F28: F36126 | G28: ICE, PORTABLE, CATERPILLAR, MODEL 3412E DITA, SN 4CR00600, TURBOCHARGED, AFTERCOOLED, DIESEL, 750 BHP, TUB GRINDER DRIVER | H28: Diesel | I28: Caterpillar | J28: 3412E DITA | K28: =L28+M28*(2/3)+N28*(2/3) -> 500 | N28: 750 | O28: 7992 IRVINE BLVD | P28: IRVINE | Q28: 92718 | R28: AGUINAGA ROGER | S28: (949) 7869558 | T28: 6.9 | U28: 0.4
A29: 54 | B29: SC | C29: VERIZON WIRELESS/TUSTIN MTSO | D29: 288928 | E29: 1994 | F29: D79916 | G29: ICE, CUMMINS, 6 CYL, TURBOCHARGED, AFTERCOOLED, MODEL KTA19-G2, 600 BHP, DIESEL, EMERGENCY ELECTRICAL GENERATION | H29: Diesel | I29: Cummins | J29: KTA19-G2 | K29: =L29+M29*(2/3)+N29*(2/3) -> 400 | N29: 600 | O29: 2792 WALNUT AVE | P29: TUSTIN | Q29: 92782 | R29: CARR WILLIAM | S29: (714) 6733182 | T29: 8.17 | U29: 0.38
A30: 55 | B30: SC | C30: ALCATEL INDUSTRIES | D30: 371907 | E30: 2000 | F30: F32665 | G30: ICE, CATERPILLAR, 12 CYL, TURBOCHARGED, AFTERCOOLED, MODEL 3412 DITA, 600 KW, DIESEL, EMR | H30: Diesel | I30: Caterpillar | J30: 3412 DITA | K30: =L30+M30*(2/3)+N30*(2/3) -> 600 | L30: 600 | O30: 26801 W AGOURA | P30: CALABASAS | Q30: 91301 | R30: CHRISTIE BRIAN | S30: (818) 8785123 | T30: 6.9 | U30: 0.4
A31: 56 | B31: SC | C31: ALCON SURGICAL INC | D31: 378534 | E31: 2000 | F31: F36552 | G31: ICE, CUMMINS,16 CYL, TURBOCHARGED, AFTERCOOLED, MODEL KTA50-G9, 2220 BHP, DIESEL, EMR | H31: Diesel | I31: Cummins | J31: KTA50-G9 | K31: =L31+M31*(2/3)+N31*(2/3) -> 1480 | N31: 2220 | O31: 15800 ALTON PKY | P31: IRVINE | Q31: 92718 | R31: BRUNDAGE BRANDON | S31: (949) 7536495 | T31: 6.9 | U31: 0.4
A32: 57 | B32: SC | C32: ALISO WATER MGMT AGENCY | D32: 10680A | E32: 1981 | F32: M30351 | G32: ICE, DETROIT DIESEL, TWO-CYCLE, WATER COOLED, 12 CYL, MODEL 7123 7305, 350KW, SN 12VA060486, EMR | H32: Diesel | I32: Detroit Diesel | J32: 7123-7305 | K32: =L32+M32*(2/3)+N32*(2/3) -> 350 | L32: 350 | O32: 515 FOREST AVE | P32: LAGUNA BEACH | Q32: 92653 | T32: 12 | U32: 0.53
A33: 58 | B33: SC | C33: ALL STATE INSURANCE CO | D33: 376547 | E33: 2000 | F33: F36888 | G33: ICE, CATERPILLAR, MODEL 3512BDITA, 1500 KW, DIESEL, 12 CYL, TURBOCHARGED, AFTERCOOLED, EMR | H33: Diesel | I33: Caterpillar | J33: 3512B DITA | K33: =L33+M33*(2/3)+N33*(2/3) -> 1500 | L33: 1500 | O33: 21950 E COPLEY DR | P33: DIAMOND BAR | Q33: 91765 | R33: SCOTT HELEN | S33: (909) 6126794 | T33: 6.9 | U33: 0.4
A34: 59 | B34: SC | C34: ALLEGIANCE HEALTHCARE CORPORATION | D34: 325847 | E34: 1997 | F34: F6087 | G34: ICE, CATERPILLAR, MODEL 3412TA, 749 BHP, DIESEL, 12 CYL, FOUR CYCLE, TURBOCHARGED, AFTERCOOLED, EMR, | H34: Diesel | I34: Caterpillar | J34: 3412 TA | K34: =L34+M34*(2/3)+N34*(2/3) -> 499.33333 | N34: 749 | O34: 4551 E PHILADELPHIA ST | P34: ONTARIO | Q34: 91761 | R34: VU KENNETH | S34: (909) 9743648 | T34: 6.9 | U34: 0.4
A35: 60 | B35: SC | C35: ALLEGIANCE TELECOM INC | D35: 362791 | E35: 1999 | F35: F24498 | G35: ICE, KOHLER, MODEL 750ROZD, DIESEL, TURBOCHARGED, AFTERCOOLED, 1170 BHP, EMR | H35: Diesel | I35: Kohler | J35: 750 ROZD | K35: =L35+M35*(2/3)+N35*(2/3) -> 780 | N35: 1170 | O35: 818 W 7TH ST STE 320 | P35: LOS ANGELES | Q35: 90017 | R35: CHING TED | S35: (213) 8910600 | T35: 8.17 | U35: 0.38
A36: 61 | B36: SC | C36: ALLERGAN INC UNIT #1 | D36: 263600 | E36: 1992 | F36: D60073 | G36: ICE, CATERPILLAR, MODEL 3412 DT, SN 38506732, DIESEL, EMR, 12 CYL, 545 BHP, TURBOCHARGED, AFTERCOOLED | H36: Diesel | I36: Caterpillar | J36: 3412 DT | K36: =L36+M36*(2/3)+N36*(2/3) -> 363.33333 | N36: 545 | O36: 18600 VON KARMAN | P36: IRVINE | Q36: 92715-1513 | R36: REED JON | S36: (714) 9556785 | T36: 8.17 | U36: 0.38
A37: 62 | B37: SC | C37: ALLERGAN INC UNIT #1 | D37: 263601 | E37: 1992 | F37: D60074 | G37: ICE, DETROIT DIESEL, MODEL 12V92T, SN 12VF002698, DIESEL, EMR, 8 CYL, 741 BHP, TURBOCHARGED, AFTERCOOLED | H37: Diesel | I37: Detroit Diesel | J37: 12V-92T | K37: =L37+M37*(2/3)+N37*(2/3) -> 494 | N37: 741 | O37: 18600 VON KARMAN | P37: IRVINE | Q37: 92715 | R37: REED JON | S37: (714) 9556785 | T37: 8.17 | U37: 0.38
A38: 63 | B38: SC | C38: ALPHA THERAPEUTIC CORP | D38: 292033 | E38: 1994 | F38: D82426 | G38: ICE, CUMMINS, 16 CYL, TURBOCHARGED, AFTERCOOLED, MODEL KTTA-50-G2, SN K930526551, 2220 BHP, DIESEL, EMR | H38: Diesel | I38: Cummins | J38: KTTA50-G2 | K38: =L38+M38*(2/3)+N38*(2/3) -> 1480 | N38: 2220 | O38: 5555 VALLEY BLVD | P38: LOS ANGELES | Q38: 90032-3548 | R38: ENRIQUEZ MATHILDE | S38: (213) 2277644 | T38: 8.17 | U38: 0.38
A39: 64 | B39: SC | C39: ALPHA THERAPEUTIC CORP | D39: 292034 | E39: 1994 | F39: D82427 | G39: ICE, CUMMINS, 16 CYL, TURBOCHARGED, AFTERCOOLED, MODEL KTTA50-G2, SN K930525356, 2220 BHP, DIESEL, EMR | H39: Diesel | I39: Cummins | J39: KTTA50-G2 | K39: =L39+M39*(2/3)+N39*(2/3) -> 1480 | N39: 2220 | O39: 5555 VALLEY BLVD | P39: LOS ANGELES | Q39: 90032-3548 | R39: ENRIQUEZ MATHILDE | S39: (213) 2277644 | T39: 8.17 | U39: 0.38
A40: 65 | B40: SC | C40: ALPHA THERAPEUTIC CORP | D40: 317427 | E40: 1996 | F40: F00711 | G40: ICE, CATERPILLAR,MODEL 3516 DITA, TURBOCHARGED, AFTERCOOLED, 16 CYL, 2000 KW, EMR, DIESEL | H40: Diesel | I40: Caterpillar | J40: 3516 DITA | K40: =L40+M40*(2/3)+N40*(2/3) -> 2000 | L40: 2000 | O40: 5555 VALLEY BLVD | P40: LOS ANGELES | Q40: 90032 | R40: ENRIQUEZ MATHILDE | S40: (213) 2277644 | T40: 8.17 | U40: 0.38
...
