Workbook
Name Print_Area_MI: Spring2004!#REF!

Sheet student
C1: GRADE CALCULATOR
A3: Your Student ID # ---> | B3: 0 | C3: <----Type your ID# and then hit enter.
B5: Your Grade | F5: Class Average
A6: Current income | B6: =VLOOKUP($B$3,Spring2004!$T$25:'Spring2004'!AI402,2,FALSE) -> #N/A | F6: =Spring2004!U402 -> 319307.1
A7: Current grade | B7: =VLOOKUP(B6,Spring2004!$T$1:'Spring2004'!$U$9, 2) -> #N/A | F7: =VLOOKUP(F6,Spring2004!$T$1:'Spring2004'!$U$9, 2) -> B+
B9: Multiple Choice | C9: Essay | D9: Total | F9: Multiple Choice | G9: Essay | H9: Total
A10: Exam #1 | B10: =VLOOKUP($B$3,Spring2004!$T$25:'Spring2004'!AI402,5,FALSE) -> #N/A | C10: =VLOOKUP($B$3,Spring2004!$T$25:'Spring2004'!AI402,6,FALSE) -> #N/A | D10: =VLOOKUP($B$3,Spring2004!$T$25:'Spring2004'!AI402,7,FALSE) -> #N/A | F10: =Spring2004!X402 -> 147073.17 | G10: =Spring2004!Y402 -> 14816.25 | H10: =Spring2004!Z402 -> 150285.37
A11: Exam #2 | B11: =VLOOKUP($B$3,Spring2004!$T$25:'Spring2004'!AI402,9,FALSE) -> #N/A | C11: =VLOOKUP($B$3,Spring2004!$T$25:'Spring2004'!AI402,10,FALSE) -> #N/A | D11: =VLOOKUP($B$3,Spring2004!$T$25:'Spring2004'!AI402,11,FALSE) -> #N/A | F11: =Spring2004!AB402 -> 140144.04 | G11: =Spring2004!AC402 -> 17506.557 | H11: =Spring2004!AD402 -> 145949.44
A12: Exam #3 | B12: =VLOOKUP($B$3,Spring2004!$T$25:'Spring2004'!AI402,15,FALSE) -> #N/A | C12: =VLOOKUP($B$3,Spring2004!$T$25:'Spring2004'!AI402,14,FALSE) -> #N/A | D12: =VLOOKUP($B$3,Spring2004!$T$25:'Spring2004'!AI402,12,FALSE) -> #N/A | F12: =Spring2004!AE402 -> 0 | G12: =Spring2004!AF402 -> 0 | H12: =Spring2004!AG402 -> 0
A13: Final Exam | B13: =VLOOKUP($B$3,Spring2004!$T$25:'Spring2004'!AI402,13,FALSE) -> #N/A | F13: =Spring2004!AH402 -> 0
A15: Project #1 | B15: =VLOOKUP($B$3,Spring2004!$T$25:'Spring2004'!AI402,14,FALSE) -> #N/A | E15: Project #1 | F15: =Spring2004!AI402 -> 0
A17: Total Extra Credit | B17: =VLOOKUP($B$3,Spring2004!$T$25:'Spring2004'!AI402,3,FALSE) -> #N/A | E17: Total Extra Credit | F17: =Spring2004!V402 -> 23072.29
A19: * Note - If you would like to protect the privacy of your grade please submit a new ID of your choosing to the TA.
A20: ** - The spreasheet calculates your current letter grade based on all relevant exams/assignments. If you have missed an exam your income is correct but NOT your letter grade.

Sheet Spring2004
T1: 0 | U1: F
T2: =0.58*AE3 -> 208800 | U2: D
T3: =0.68*AE3 -> 244800 | U3: C | AE3: 360000
T4: =0.76*AE3 -> 273600 | U4: C+
T5: =0.8*AE3 -> 288000 | U5: B-
T6: =0.82*AE3 -> 295200 | U6: B
T7: =0.86*AE3 -> 309600 | U7: B+
T8: =0.9*AE3 -> 324000 | U8: A-
T9: =0.93*AE3 -> 334800 | U9: A
B23: Homeworks | F23: Games | M23: Drawings | S23: Movie | U23: CLASS | V23: Total | X23: Exam 1 | Y23: Exam 1 | Z23: Exam 1 | AB23: Exam 2 | AC23: Exam 2 | AD23: Exam 2 | AE23: Exam 3 | AF23: Exam 3 | AG23: Exam 3 | AI23: Project
A24: 1 | B24: 2 | C24: 3 | D24: 4 | E24: 1 | F24: 2 | G24: 3 | H24: 4 | I24: 5 | J24: 6 | K24: 7 | L24: 1 | M24: 2 | N24: 3 | O24: 4 | P24: 5 | Q24: 6 | R24: 7 | S24: Project | T24: Student ID | U24: INCOME | V24: Extra | X24: M/C | Y24: Essay | Z24: Total | AB24: M/C | AC24: Essay | AD24: Total | AE24: M/C | AF24: Essay | AG24: Total | AH24: Final | AI24: #1
A25: 3550 | B25: 0 | C25: 0 | D25: 0 | E25: 6000 | F25: 2700 | G25: 1500 | H25: 1450 | I25: 0 | J25: 0 | K25: 0 | L25: 1500 | M25: 2000 | N25: 1500 | O25: 3000 | P25: 0 | Q25: 0 | R25: 0 | S25: 0 | T25: 211809639 | U25: =SUM(V25, Z25, AD25, AG25, AH25, AI25) -> 311200 | V25: =SUM(A25:S25) -> 23200 | X25: 144000 | Z25: 144000 | AA25: 126000 | AB25: =AA25+18000 -> 144000 | AD25: =SUM(AB25:AC25) -> 144000 | AE25: 0 | AF25: 0 | AG25: =SUM(AE25:AF25) -> 0 | AH25: 0 | AI25: 0 | AX25: =(AB25+18000) -> 162000
A26: 5000 | B26: 5000 | C26: 0 | D26: 0 | E26: 6000 | F26: 2700 | G26: 1000 | H26: 1200 | I26: 0 | J26: 0 | K26: 0 | L26: 1500 | M26: 2000 | N26: 1500 | O26: 3000 | P26: 0 | Q26: 0 | R26: 0 | S26: 0 | T26: 208640915 | U26: =SUM(V26, Z26, AD26, AG26, AH26, AI26) -> 394900 | V26: =SUM(A26:S26) -> 28900 | W26: 168000 | X26: =W26+3*6000 -> 186000 | Z26: =SUM(X26:Y26) -> 186000 | AA26: 162000 | AB26: =AA26+18000 -> 180000 | AD26: =SUM(AB26:AC26) -> 180000 | AE26: 0 | AF26: 0 | AG26: =SUM(AE26:AF26) -> 0 | AH26: 0 | AI26: 0 | AX26: =(AB26+18000) -> 198000
A27: 3500 | B27: 5000 | C27: 0 | D27: 0 | E27: 6000 | F27: 2700 | G27: 1500 | H27: 1450 | I27: 0 | J27: 0 | K27: 0 | L27: 1500 | M27: 2000 | N27: 1500 | O27: 0 | P27: 0 | Q27: 0 | R27: 0 | S27: 0 | T27: 196700350 | U27: =SUM(V27, Z27, AD27, AG27, AH27, AI27) -> 283150 | V27: =SUM(A27:S27) -> 25150 | W27: 114000 | X27: =W27+3*6000 -> 132000 | Z27: =SUM(X27:Y27) -> 132000 | AA27: 108000 | AB27: =AA27+18000 -> 126000 | AD27: =SUM(AB27:AC27) -> 126000 | AE27: 0 | AF27: 0 | AG27: =SUM(AE27:AF27) -> 0 | AH27: 0 | AI27: 0 | AX27: =(AB27+18000) -> 144000
A28: 4350 | B28: 5000 | C28: 0 | D28: 0 | E28: 6000 | F28: 2700 | G28: 1500 | H28: 1450 | I28: 0 | J28: 0 | K28: 0 | L28: 1500 | M28: 2000 | N28: 1500 | O28: 0 | P28: 0 | Q28: 0 | R28: 0 | S28: 0 | T28: 205669687 | U28: =SUM(V28, Z28, AD28, AG28, AH28, AI28) -> 416000 | V28: =SUM(A28:S28) -> 26000 | W28: 162000 | X28: =W28+3*6000 -> 180000 | Y28: 18000 | Z28: =SUM(X28:Y28) -> 198000 | AA28: 156000 | AB28: =AA28+18000 -> 174000 | AC28: 18000 | AD28: =SUM(AB28:AC28) -> 192000 | AE28: 0 | AF28: 0 | AG28: =SUM(AE28:AF28) -> 0 | AH28: 0 | AI28: 0 | AX28: =(AB28+18000) -> 192000
A29: 0 | B29: 0 | C29: 0 | D29: 0 | E29: 6000 | F29: 2700 | G29: 1500 | H29: 0 | I29: 0 | J29: 0 | K29: 0 | L29: 1500 | M29: 2000 | N29: 0 | O29: 3000 | P29: 0 | Q29: 0 | R29: 0 | S29: 0 | T29: 129749410 | U29: =SUM(V29, Z29, AD29, AG29, AH29, AI29) -> 316700 | V29: =SUM(A29:S29) -> 16700 | W29: 132000 | X29: =W29+3*6000 -> 150000 | Z29: =SUM(X29:Y29) -> 150000 | AA29: 132000 | AB29: =AA29+18000 -> 150000 | AD29: =SUM(AB29:AC29) -> 150000 | AE29: 0 | AF29: 0 | AG29: =SUM(AE29:AF29) -> 0 | AH29: 0 | AI29: 0 | AX29: =(AB29+18000) -> 168000
A30: 0 | B30: 5000 | C30: 0 | D30: 0 | E30: 6000 | F30: 2700 | G30: 1000 | H30: 1450 | I30: 0 | J30: 0 | K30: 0 | L30: 0 | M30: 2000 | N30: 1500 | O30: 3000 | P30: 0 | Q30: 0 | R30: 0 | S30: 0 | T30: 152785217 | U30: =SUM(V30, Z30, AD30, AG30, AH30, AI30) -> 310650 | V30: =SUM(A30:S30) -> 22650 | W30: 138000 | X30: =W30+3*6000 -> 156000 | Z30: =SUM(X30:Y30) -> 156000 | AA30: 114000 | AB30: =AA30+18000 -> 132000 | AD30: =SUM(AB30:AC30) -> 132000 | AE30: 0 | AF30: 0 | AG30: =SUM(AE30:AF30) -> 0 | AH30: 0 | AI30: 0 | AX30: =(AB30+18000) -> 150000
A31: 0 | B31: 0 | C31: 0 | D31: 0 | E31: 6000 | F31: 2700 | G31: 3500 | H31: 1700 | I31: 0 | J31: 0 | K31: 0 | L31: 1500 | M31: 2000 | N31: 1500 | O31: 0 | P31: 0 | Q31: 0 | R31: 0 | S31: 0 | T31: 211688367 | U31: =SUM(V31, Z31, AD31, AG31, AH31, AI31) -> 288900 | V31: =SUM(A31:S31) -> 18900 | W31: 102000 | X31: =W31+3*6000 -> 120000 | Z31: =SUM(X31:Y31) -> 120000 | AA31: 114000 | AB31: =AA31+18000 -> 132000 | AC31: 18000 | AD31: =SUM(AB31:AC31) -> 150000 | AE31: 0 | AF31: 0 | AG31: =SUM(AE31:AF31) -> 0 | AH31: 0 | AI31: 0 | AX31: =(AB31+18000) -> 150000
A32: 3750 | B32: 5000 | C32: 0 | D32: 0 | E32: 6000 | F32: 2700 | G32: 1500 | H32: 1450 | I32: 0 | J32: 0 | K32: 0 | L32: 1500 | M32: 2000 | N32: 1500 | O32: 3000 | P32: 0 | Q32: 0 | R32: 0 | S32: 0 | T32: 168626361 | U32: =SUM(V32, Z32, AD32, AG32, AH32, AI32) -> 370400 | V32: =SUM(A32:S32) -> 28400 | W32: 156000 | X32: =W32+3*6000 -> 174000 | Z32: =SUM(X32:Y32) -> 174000 | AA32: 150000 | AB32: =AA32+18000 -> 168000 | AD32: =SUM(AB32:AC32) -> 168000 | AE32: 0 | AF32: 0 | AG32: =SUM(AE32:AF32) -> 0 | AH32: 0 | AI32: 0 | AX32: =(AB32+18000) -> 186000
A33: 3600 | B33: 5000 | C33: 0 | D33: 0 | E33: 6000 | F33: 2700 | G33: 1500 | H33: 1450 | I33: 0 | J33: 0 | K33: 0 | L33: 0 | M33: 2000 | N33: 1500 | O33: 3000 | P33: 0 | Q33: 0 | R33: 0 | S33: 0 | T33: 160660768 | U33: =SUM(V33, Z33, AD33, AG33, AH33, AI33) -> 290750 | V33: =SUM(A33:S33) -> 26750 | W33: 114000 | X33: =W33+3*6000 -> 132000 | Z33: =SUM(X33:Y33) -> 132000 | AA33: 114000 | AB33: =AA33+18000 -> 132000 | AD33: =SUM(AB33:AC33) -> 132000 | AE33: 0 | AF33: 0 | AG33: =SUM(AE33:AF33) -> 0 | AH33: 0 | AI33: 0 | AX33: =(AB33+18000) -> 150000
A34: 4750 | B34: 0 | C34: 0 | D34: 0 | E34: 6000 | F34: 2700 | G34: 0 | H34: 0 | I34: 0 | J34: 0 | K34: 0 | L34: 1500 | M34: 2000 | N34: 1500 | O34: 0 | P34: 0 | Q34: 0 | R34: 0 | S34: 0 | T34: 173661902 | U34: =SUM(V34, Z34, AD34, AG34, AH34, AI34) -> 300450 | V34: =SUM(A34:S34) -> 18450 | W34: 114000 | X34: =W34+3*6000 -> 132000 | Z34: =SUM(X34:Y34) -> 132000 | AA34: 132000 | AB34: =AA34+18000 -> 150000 | AD34: =SUM(AB34:AC34) -> 150000 | AE34: 0 | AF34: 0 | AG34: =SUM(AE34:AF34) -> 0 | AH34: 0 | AI34: 0 | AX34: =(AB34+18000) -> 168000
A35: 3250 | B35: 0 | C35: 0 | D35: 0 | E35: 6000 | F35: 2700 | G35: 0 | H35: 0 | I35: 0 | J35: 0 | K35: 0 | L35: 1500 | M35: 2000 | N35: 1500 | O35: 0 | P35: 0 | Q35: 0 | R35: 0 | S35: 0 | T35: 117742264 | AE35: 0 | AF35: 0 | AG35: =SUM(AE35:AF35) -> 0 | AH35: 0 | AI35: 0
A36: 0 | B36: 5000 | C36: 0 | D36: 0 | E36: 6000 | F36: 2700 | G36: 0 | H36: 650 | I36: 0 | J36: 0 | K36: 0 | L36: 1500 | M36: 2000 | N36: 1500 | O36: 3000 | P36: 0 | Q36: 0 | R36: 0 | S36: 0 | T36: 178665412 | U36: =SUM(V36, Z36, AD36, AG36, AH36, AI36) -> 172350 | V36: =SUM(A36:S36) -> 22350 | W36: 42000 | X36: =W36+3*6000 -> 60000 | Z36: =SUM(X36:Y36) -> 60000 | AA36: 54000 | AB36: =AA36+18000 -> 72000 | AC36: 18000 | AD36: =SUM(AB36:AC36) -> 90000 | AE36: 0 | AF36: 0 | AG36: =SUM(AE36:AF36) -> 0 | AH36: 0 | AI36: 0
A37: 4050 | B37: 4000 | C37: 0 | D37: 0 | E37: 6000 | F37: 2700 | G37: 1000 | H37: 1200 | I37: 0 | J37: 0 | K37: 0 | L37: 1500 | M37: 2000 | N37: 1500 | O37: 3000 | P37: 0 | Q37: 0 | R37: 0 | S37: 0 | T37: 164709696 | U37: =SUM(V37, Z37, AD37, AG37, AH37, AI37) -> 302950 | V37: =SUM(A37:S37) -> 26950 | W37: 96000 | X37: =W37+3*6000 -> 114000 | Z37: =SUM(X37:Y37) -> 114000 | AA37: 126000 | AB37: =AA37+18000 -> 144000 | AC37: 18000 | AD37: =SUM(AB37:AC37) -> 162000 | AE37: 0 | AF37: 0 | AG37: =SUM(AE37:AF37) -> 0 | AH37: 0 | AI37: 0
A38: 0 | B38: 4000 | C38: 0 | D38: 0 | E38: 6000 | F38: 2700 | G38: 2000 | H38: 1450 | I38: 0 | J38: 0 | K38: 0 | L38: 1500 | M38: 2000 | N38: 1500 | O38: 3000 | P38: 0 | Q38: 0 | R38: 0 | S38: 0 | T38: 170668270 | U38: =SUM(V38, Z38, AD38, AG38, AH38, AI38) -> 258150 | V38: =SUM(A38:S38) -> 24150 | W38: 96000 | X38: =W38+3*6000 -> 114000 | Z38: =SUM(X38:Y38) -> 114000 | AA38: 102000 | AB38: =AA38+18000 -> 120000 | AD38: =SUM(AB38:AC38) -> 120000 | AE38: 0 | AF38: 0 | AG38: =SUM(AE38:AF38) -> 0 | AH38: 0 | AI38: 0
A39: 0 | B39: 0 | C39: 0 | D39: 0 | E39: 6000 | F39: 2700 | G39: 1000 | I39: 0 | J39: 0 | K39: 0 | L39: 1500 | M39: 2000 | N39: 1500 | O39: 0 | P39: 0 | Q39: 0 | R39: 0 | S39: 0 | T39: 592907444 | U39: =SUM(V39, Z39, AD39, AG39, AH39, AI39) -> 342900 | V39: =SUM(A39:S39) -> 14700 | W39: 144000 | X39: =W39+3*6000 -> 162000 | Y39: 16200 | Z39: =SUM(X39:Y39) -> 178200 | AA39: 114000 | AB39: =AA39+18000 -> 132000 | AC39: 18000 | AD39: =SUM(AB39:AC39) -> 150000 | AE39: 0 | AF39: 0 | AG39: =SUM(AE39:AF39) -> 0 | AH39: 0 | AI39: 0
A40: 4300 | B40: 0 | C40: 0 | D40: 0 | E40: 6000 | F40: 2700 | G40: 1500 | H40: 0 | I40: 0 | J40: 0 | K40: 0 | L40: 1500 | M40: 2000 | N40: 1500 | O40: 3000 | P40: 0 | Q40: 0 | R40: 0 | S40: 0 | T40: 164682035 | U40: =SUM(V40, Z40, AD40, AG40, AH40, AI40) -> 340500 | V40: =SUM(A40:S40) -> 22500 | W40: 150000 | X40: =W40+3*6000 -> 168000 | Z40: =SUM(X40:Y40) -> 168000 | AA40: 132000 | AB40: =AA40+18000 -> 150000 | AD40: =SUM(AB40:AC40) -> 150000 | AE40: 0 | AF40: 0 | AG40: =SUM(AE40:AF40) -> 0 | AH40: 0 | AI40: 0
A41: 5000 | B41: 4500 | C41: 0 | D41: 0 | E41: 6000 | F41: 2700 | G41: 1000 | H41: 1450 | I41: 0 | J41: 0 | K41: 0 | L41: 1500 | M41: 2000 | N41: 0 | O41: 3000 | P41: 0 | Q41: 0 | R41: 0 | S41: 0 | T41: 200667452 | U41: =SUM(V41, Z41, AD41, AG41, AH41, AI41) -> 285150 | V41: =SUM(A41:S41) -> 27150 | W41: 108000 | X41: =W41+3*6000 -> 126000 | Z41: =SUM(X41:Y41) -> 126000 | AA41: 96000 | AB41: =AA41+18000 -> 114000 | AC41: 18000 | AD41: =SUM(AB41:AC41) -> 132000 | AE41: 0 | AF41: 0 | AG41: =SUM(AE41:AF41) -> 0 | AH41: 0 | AI41: 0
A42: 3500 | B42: 5000 | C42: 0 | D42: 0 | E42: 6000 | F42: 2700 | G42: 1000 | H42: 1450 | I42: 0 | J42: 0 | K42: 0 | L42: 1500 | M42: 2000 | N42: 1500 | O42: 3000 | P42: 0 | Q42: 0 | R42: 0 | S42: 0 | T42: 203644670 | U42: =SUM(V42, Z42, AD42, AG42, AH42, AI42) -> 391850 | V42: =SUM(A42:S42) -> 27650 | W42: 180000 | X42: =W42+3*6000 -> 198000 | Z42: =SUM(X42:Y42) -> 198000 | AA42: 132000 | AB42: =AA42+18000 -> 150000 | AC42: 16200 | AD42: =SUM(AB42:AC42) -> 166200 | AE42: 0 | AF42: 0 | AG42: =SUM(AE42:AF42) -> 0 | AH42: 0 | AI42: 0
A43: 3550 | B43: 4500 | C43: 0 | D43: 0 | E43: 6000 | F43: 2700 | G43: 1000 | H43: 0 | I43: 0 | J43: 0 | K43: 0 | L43: 1500 | M43: 2000 | N43: 1500 | O43: 0 | P43: 0 | Q43: 0 | R43: 0 | S43: 0 | T43: 560775299 | U43: =SUM(V43, Z43, AD43, AG43, AH43, AI43) -> 310750 | V43: =SUM(A43:S43) -> 22750 | W43: 132000 | X43: =W43+3*6000 -> 150000 | Z43: =SUM(X43:Y43) -> 150000 | AA43: 120000 | AB43: =AA43+18000 -> 138000 | AD43: =SUM(AB43:AC43) -> 138000 | AE43: 0 | AF43: 0 | AG43: =SUM(AE43:AF43) -> 0 | AH43: 0 | AI43: 0
A44: 4550 | B44: 5000 | C44: 0 | D44: 0 | E44: 6000 | F44: 1275 | G44: 2000 | H44: 1450 | I44: 0 | J44: 0 | K44: 0 | L44: 1500 | M44: 2000 | N44: 1500 | O44: 3000 | P44: 0 | Q44: 0 | R44: 0 | S44: 0 | T44: 186665782 | U44: =SUM(V44, Z44, AD44, AG44, AH44, AI44) -> 358275 | V44: =SUM(A44:S44) -> 28275 | W44: 150000 | X44: =W44+3*6000 -> 168000 | Z44: =SUM(X44:Y44) -> 168000 | AA44: 144000 | AB44: =AA44+18000 -> 162000 | AD44: =SUM(AB44:AC44) -> 162000 | AE44: 0 | AF44: 0 | AG44: =SUM(AE44:AF44) -> 0 | AH44: 0 | AI44: 0
A45: 0 | B45: 0 | C45: 0 | D45: 0 | E45: 6000 | F45: 0 | G45: 0 | H45: 0 | I45: 0 | J45: 0 | K45: 0 | L45: 1500 | M45: 2000 | N45: 1500 | O45: 0 | P45: 0 | Q45: 0 | R45: 0 | S45: 0 | T45: 187644085 | U45: =SUM(V45, Z45, AD45, AG45, AH45, AI45) -> 335000 | V45: =SUM(A45:S45) -> 11000 | W45: 144000 | X45: =W45+3*6000 -> 162000 | Z45: =SUM(X45:Y45) -> 162000 | AA45: 144000 | AB45: =AA45+18000 -> 162000 | AD45: =SUM(AB45:AC45) -> 162000 | AE45: 0 | AF45: 0 | AG45: =SUM(AE45:AF45) -> 0 | AH45: 0 | AI45: 0
A46: 0 | B46: 0 | C46: 0 | D46: 0 | E46: 6000 | F46: 2700 | G46: 1500 | H46: 1450 | I46: 0 | J46: 0 | K46: 0 | L46: 1500 | M46: 2000 | N46: 1500 | O46: 3000 | P46: 0 | Q46: 0 | R46: 0 | S46: 0 | T46: 228352008 | U46: =SUM(V46, Z46, AD46, AG46, AH46, AI46) -> 319650 | V46: =SUM(A46:S46) -> 19650 | X46: 150000 | Z46: 150000 | AA46: 132000 | AB46: =AA46+18000 -> 150000 | AD46: =SUM(AB46:AC46) -> 150000 | AE46: 0 | AF46: 0 | AG46: =SUM(AE46:AF46) -> 0 | AH46: 0 | AI46: 0
A47: 0 | B47: 0 | C47: 0 | D47: 0 | E47: 6000 | F47: 2700 | G47: 2000 | H47: 1450 | I47: 0 | J47: 0 | K47: 0 | L47: 1500 | M47: 2000 | N47: 1500 | O47: 3000 | P47: 0 | Q47: 0 | R47: 0 | S47: 0 | T47: 181681578 | U47: =SUM(V47, Z47, AD47, AG47, AH47, AI47) -> 266150 | V47: =SUM(A47:S47) -> 20150 | W47: 120000 | X47: =W47+3*6000 -> 138000 | Z47: =SUM(X47:Y47) -> 138000 | AA47: 90000 | AB47: =AA47+18000 -> 108000 | AD47: =SUM(AB47:AC47) -> 108000 | AE47: 0 | AF47: 0 | AG47: =SUM(AE47:AF47) -> 0 | AH47: 0 | AI47: 0
A48: 3800 | B48: 5000 | C48: 0 | D48: 0 | E48: 6000 | F48: 0 | G48: 1500 | H48: 0 | I48: 0 | J48: 0 | K48: 0 | L48: 1500 | M48: 2000 | N48: 0 | O48: 0 | P48: 0 | Q48: 0 | R48: 0 | S48: 0 | T48: 194646235 | U48: =SUM(V48, Z48, AD48, AG48, AH48, AI48) -> 354600 | V48: =SUM(A48:S48) -> 19800 | W48: 156000 | X48: =W48+3*6000 -> 174000 | Y48: 10800 | Z48: =SUM(X48:Y48) -> 184800 | AB48: 150000 | AD48: =SUM(AB48:AC48) -> 150000 | AE48: 0 | AF48: 0 | AG48: =SUM(AE48:AF48) -> 0 | AH48: 0 | AI48: 0
A49: 4350 | B49: 4000 | C49: 0 | D49: 0 | E49: 6000 | F49: 0 | G49: 1500 | H49: 1700 | I49: 0 | J49: 0 | K49: 0 | L49: 1500 | M49: 2000 | N49: 1500 | O49: 3000 | P49: 0 | Q49: 0 | R49: 0 | S49: 0 | T49: 8668755 | U49: =SUM(V49, Z49, AD49, AG49, AH49, AI49) -> 307550 | V49: =SUM(A49:S49) -> 25550 | W49: 126000 | X49: =W49+3*6000 -> 144000 | Z49: =SUM(X49:Y49) -> 144000 | AA49: 120000 | AB49: =AA49+18000 -> 138000 | AD49: =SUM(AB49:AC49) -> 138000 | AE49: 0 | AF49: 0 | AG49: =SUM(AE49:AF49) -> 0 | AH49: 0 | AI49: 0
A50: 4250 | B50: 4500 | C50: 0 | D50: 0 | E50: 6000 | F50: 2700 | G50: 2500 | H50: 1450 | I50: 0 | J50: 0 | K50: 0 | L50: 1500 | M50: 2000 | N50: 1500 | O50: 3000 | P50: 0 | Q50: 0 | R50: 0 | S50: 0 | T50: 164646182 | U50: =SUM(V50, Z50, AD50, AG50, AH50, AI50) -> 263400 | V50: =SUM(A50:S50) -> 29400 | W50: 102000 | X50: =W50+3*6000 -> 120000 | Z50: =SUM(X50:Y50) -> 120000 | AA50: 96000 | AB50: =AA50+18000 -> 114000 | AD50: =SUM(AB50:AC50) -> 114000 | AE50: 0 | AF50: 0 | AG50: =SUM(AE50:AF50) -> 0 | AH50: 0 | AI50: 0
A51: 3550 | B51: 0 | C51: 0 | D51: 0 | E51: 6000 | F51: 2700 | G51: 0 | H51: 1450 | I51: 0 | J51: 0 | K51: 0 | L51: 1500 | M51: 2000 | N51: 1500 | O51: 0 | P51: 0 | Q51: 0 | R51: 0 | S51: 0 | T51: 195741470 | U51: =SUM(V51, Z51, AD51, AG51, AH51, AI51) -> 264700 | V51: =SUM(A51:S51) -> 18700 | W51: 114000 | X51: =W51+3*6000 -> 132000 | Z51: =SUM(X51:Y51) -> 132000 | AA51: 96000 | AB51: =AA51+18000 -> 114000 | AD51: =SUM(AB51:AC51) -> 114000 | AE51: 0 | AF51: 0 | AG51: =SUM(AE51:AF51) -> 0 | AH51: 0 | AI51: 0
A52: 3550 | B52: 4500 | C52: 0 | D52: 0 | E52: 6000 | F52: 2700 | G52: 1500 | H52: 0 | I52: 0 | J52: 0 | K52: 0 | L52: 1500 | M52: 2000 | N52: 1500 | O52: 3000 | P52: 0 | Q52: 0 | R52: 0 | S52: 0 | T52: 3689537 | U52: =SUM(V52, Z52, AD52, AG52, AH52, AI52) -> 356250 | V52: =SUM(A52:S52) -> 26250 | W52: 144000 | X52: =W52+3*6000 -> 162000 | Z52: =SUM(X52:Y52) -> 162000 | AA52: 150000 | AB52: =AA52+18000 -> 168000 | AD52: =SUM(AB52:AC52) -> 168000 | AE52: 0 | AF52: 0 | AG52: =SUM(AE52:AF52) -> 0 | AH52: 0 | AI52: 0
A53: 4100 | B53: 5000 | C53: 0 | D53: 0 | E53: 6000 | F53: 2700 | G53: 0 | H53: 1450 | I53: 0 | J53: 0 | K53: 0 | L53: 1500 | M53: 2000 | N53: 1500 | O53: 3000 | P53: 0 | Q53: 0 | R53: 0 | S53: 0 | T53: 169665771 | U53: =SUM(V53, Z53, AD53, AG53, AH53, AI53) -> 227650 | V53: =SUM(A53:S53) -> 27250 | W53: 90000 | X53: =W53+3*6000 -> 108000 | Y53: 14400 | Z53: =SUM(X53:Y53) -> 122400 | AA53: 60000 | AB53: =AA53+18000 -> 78000 | AD53: =SUM(AB53:AC53) -> 78000 | AE53: 0 | AF53: 0 | AG53: =SUM(AE53:AF53) -> 0 | AH53: 0 | AI53: 0
...
