Workbook

Sheet Industry Statistics
A1: Technology Industry Name:
B2: Industry
B3: Mean | C3: ='Company 1'!A1 -> Company 1 | D3: ='Company 2'!A1 -> Company 2 | E3: ='Company 3'!A1 -> Company 3 | F3: ='Company 4'!A1 -> Company 4 | G3: ='Company 5'!A1 -> Company 5 | H3: ='Company 6'!A1 -> Company 6
A4: Growth:
A5: Revenues (past 5 yrs) | B5: =AVERAGE(C5:H5) -> 0 | C5: ='Company 1'!B7 -> 0 | D5: ='Company 2'!B7 -> 0 | E5: ='Company 3'!B7 -> 0 | F5: ='Company 4'!B7 -> 0 | G5: ='Company 5'!B7 -> 0 | H5: ='Company 6'!B7 -> 0
A6: Revenues (fore. 5 yrs) | B6: =AVERAGE(C6:H6) -> 0 | C6: ='Company 1'!B8 -> 0 | D6: ='Company 2'!B8 -> 0 | E6: ='Company 3'!B8 -> 0 | F6: ='Company 4'!B8 -> 0 | G6: ='Company 5'!B8 -> 0 | H6: ='Company 6'!B8 -> 0
A7: Earnings (past 5 yrs) | B7: =AVERAGE(C7:H7) -> 0 | C7: ='Company 1'!B9 -> 0 | D7: ='Company 2'!B9 -> 0 | E7: ='Company 3'!B9 -> 0 | F7: ='Company 4'!B9 -> 0 | G7: ='Company 5'!B9 -> 0 | H7: ='Company 6'!B9 -> 0
A8: Earnings (fore. 5 yrs) | B8: =AVERAGE(C8:H8) -> 0 | C8: ='Company 1'!B10 -> 0 | D8: ='Company 2'!B10 -> 0 | E8: ='Company 3'!B10 -> 0 | F8: ='Company 4'!B10 -> 0 | G8: ='Company 5'!B10 -> 0 | H8: ='Company 6'!B10 -> 0
A10: Profitability:
A11: Gross margin (current) | B11: =AVERAGE(C11:H11) -> #DIV/0! | C11: ='Company 1'!B52 -> #DIV/0! | D11: ='Company 2'!B52 -> #DIV/0! | E11: ='Company 3'!B52 -> #DIV/0! | F11: ='Company 4'!B52 -> #DIV/0! | G11: ='Company 5'!B52 -> #DIV/0! | H11: ='Company 6'!B52 -> #DIV/0!
A12: Oper. margin (current) | B12: =AVERAGE(C12:H12) -> #DIV/0! | C12: ='Company 1'!B53 -> #DIV/0! | D12: ='Company 2'!B53 -> #DIV/0! | E12: ='Company 3'!B53 -> #DIV/0! | F12: ='Company 4'!B53 -> #DIV/0! | G12: ='Company 5'!B53 -> #DIV/0! | H12: ='Company 6'!B53 -> #DIV/0!
A13: Oper. margin (fore. 5 yrs) | B13: =AVERAGE(C13:H13) -> 0 | C13: ='Company 1'!B11 -> 0 | D13: ='Company 2'!B11 -> 0 | E13: ='Company 3'!B11 -> 0 | F13: ='Company 4'!B11 -> 0 | G13: ='Company 5'!B11 -> 0 | H13: ='Company 6'!B11 -> 0
A14: Net margin (current) | B14: =AVERAGE(C14:H14) -> #DIV/0! | C14: ='Company 1'!B54 -> #DIV/0! | D14: ='Company 2'!B54 -> #DIV/0! | E14: ='Company 3'!B54 -> #DIV/0! | F14: ='Company 4'!B54 -> #DIV/0! | G14: ='Company 5'!B54 -> #DIV/0! | H14: ='Company 6'!B54 -> #DIV/0!
A15: Net margin (fore. 5 yrs) | B15: =AVERAGE(C15:H15) -> 0 | C15: ='Company 1'!B12 -> 0 | D15: ='Company 2'!B12 -> 0 | E15: ='Company 3'!B12 -> 0 | F15: ='Company 4'!B12 -> 0 | G15: ='Company 5'!B12 -> 0 | H15: ='Company 6'!B12 -> 0
A16: ROE (current) | B16: =AVERAGE(C16:H16) -> #DIV/0! | C16: ='Company 1'!B56 -> #DIV/0! | D16: ='Company 2'!B56 -> #DIV/0! | E16: ='Company 3'!B56 -> #DIV/0! | F16: ='Company 4'!B56 -> #DIV/0! | G16: ='Company 5'!B56 -> #DIV/0! | H16: ='Company 6'!B56 -> #DIV/0!
A17: ROE (fore. 5 yrs) | B17: =AVERAGE(C17:H17) -> 0 | C17: ='Company 1'!B13 -> 0 | D17: ='Company 2'!B13 -> 0 | E17: ='Company 3'!B13 -> 0 | F17: ='Company 4'!B13 -> 0 | G17: ='Company 5'!B13 -> 0 | H17: ='Company 6'!B13 -> 0
A18: R & D% of sales | B18: =AVERAGE(C18:H18) -> #DIV/0! | C18: ='Company 1'!B57 -> #DIV/0! | D18: ='Company 2'!B57 -> #DIV/0! | E18: ='Company 3'!B57 -> #DIV/0! | F18: ='Company 4'!B57 -> #DIV/0! | G18: ='Company 5'!B57 -> #DIV/0! | H18: ='Company 6'!B57 -> #DIV/0!
A19: SGA% of sales | B19: =AVERAGE(C19:H19) -> #DIV/0! | C19: ='Company 1'!B58 -> #DIV/0! | D19: ='Company 2'!B58 -> #DIV/0! | E19: ='Company 3'!B58 -> #DIV/0! | F19: ='Company 4'!B58 -> #DIV/0! | G19: ='Company 5'!B58 -> #DIV/0! | H19: ='Company 6'!B58 -> #DIV/0!
A20: Pretax Nonrecurr% of sales | B20: =AVERAGE(C20:H20) -> #DIV/0! | C20: ='Company 1'!B59 -> #DIV/0! | D20: ='Company 2'!B59 -> #DIV/0! | E20: ='Company 3'!B59 -> #DIV/0! | F20: ='Company 4'!B59 -> #DIV/0! | G20: ='Company 5'!B59 -> #DIV/0! | H20: ='Company 6'!B59 -> #DIV/0!
A21: Fixed assets-Avg W/O yrs | B21: =AVERAGE(C21:H21) -> #DIV/0! | C21: ='Company 1'!B60 -> #DIV/0! | D21: ='Company 2'!B60 -> #DIV/0! | E21: ='Company 3'!B60 -> #DIV/0! | F21: ='Company 4'!B60 -> #DIV/0! | G21: ='Company 5'!B60 -> #DIV/0! | H21: ='Company 6'!B60 -> #DIV/0!
A23: Activity:
A24: Revenue per employee | B24: =AVERAGE(C24:H24) -> #DIV/0! | C24: ='Company 1'!B64 -> #DIV/0! | D24: ='Company 2'!B64 -> #DIV/0! | E24: ='Company 3'!B64 -> #DIV/0! | F24: ='Company 4'!B64 -> #DIV/0! | G24: ='Company 5'!B64 -> #DIV/0! | H24: ='Company 6'!B64 -> #DIV/0!
A25: Receivables turnover | B25: =AVERAGE(C25:H25) -> #DIV/0! | C25: ='Company 1'!B65 -> #DIV/0! | D25: ='Company 2'!B65 -> #DIV/0! | E25: ='Company 3'!B65 -> #DIV/0! | F25: ='Company 4'!B65 -> #DIV/0! | G25: ='Company 5'!B65 -> #DIV/0! | H25: ='Company 6'!B65 -> #DIV/0!
A26: Days receivables | B26: =AVERAGE(C26:H26) -> #DIV/0! | C26: ='Company 1'!B66 -> #DIV/0! | D26: ='Company 2'!B66 -> #DIV/0! | E26: ='Company 3'!B66 -> #DIV/0! | F26: ='Company 4'!B66 -> #DIV/0! | G26: ='Company 5'!B66 -> #DIV/0! | H26: ='Company 6'!B66 -> #DIV/0!
A27: Inventory turnover | B27: =AVERAGE(C27:H27) -> #DIV/0! | C27: ='Company 1'!B67 -> #DIV/0! | D27: ='Company 2'!B67 -> #DIV/0! | E27: ='Company 3'!B67 -> #DIV/0! | F27: ='Company 4'!B67 -> #DIV/0! | G27: ='Company 5'!B67 -> #DIV/0! | H27: ='Company 6'!B67 -> #DIV/0!
A28: Days inventory | B28: =AVERAGE(C28:H28) -> #DIV/0! | C28: ='Company 1'!B68 -> #DIV/0! | D28: ='Company 2'!B68 -> #DIV/0! | E28: ='Company 3'!B68 -> #DIV/0! | F28: ='Company 4'!B68 -> #DIV/0! | G28: ='Company 5'!B68 -> #DIV/0! | H28: ='Company 6'!B68 -> #DIV/0!
A29: Payables turnover | B29: =AVERAGE(C29:H29) -> #DIV/0! | C29: ='Company 1'!B69 -> #DIV/0! | D29: ='Company 2'!B69 -> #DIV/0! | E29: ='Company 3'!B69 -> #DIV/0! | F29: ='Company 4'!B69 -> #DIV/0! | G29: ='Company 5'!B69 -> #DIV/0! | H29: ='Company 6'!B69 -> #DIV/0!
A30: Days payables | B30: =AVERAGE(C30:H30) -> #DIV/0! | C30: ='Company 1'!B70 -> #DIV/0! | D30: ='Company 2'!B70 -> #DIV/0! | E30: ='Company 3'!B70 -> #DIV/0! | F30: ='Company 4'!B70 -> #DIV/0! | G30: ='Company 5'!B70 -> #DIV/0! | H30: ='Company 6'!B70 -> #DIV/0!
A31: Cash Cycle | B31: =AVERAGE(C31:H31) -> #DIV/0! | C31: ='Company 1'!B66+'Company 1'!B68-'Company 1'!B70 -> #DIV/0! | D31: ='Company 2'!B66+'Company 2'!B68-'Company 2'!B70 -> #DIV/0! | E31: ='Company 3'!B66+'Company 3'!B68-'Company 3'!B70 -> #DIV/0! | F31: ='Company 4'!B66+'Company 4'!B68-'Company 4'!B70 -> #DIV/0! | G31: ='Company 5'!B66+'Company 5'!B68-'Company 5'!B70 -> #DIV/0! | H31: ='Company 6'!B66+'Company 6'!B68-'Company 6'!B70 -> #DIV/0!
A32: Total assets turnover | B32: =AVERAGE(C32:H32) -> #DIV/0! | C32: ='Company 1'!B71 -> #DIV/0! | D32: ='Company 2'!B71 -> #DIV/0! | E32: ='Company 3'!B71 -> #DIV/0! | F32: ='Company 4'!B71 -> #DIV/0! | G32: ='Company 5'!B71 -> #DIV/0! | H32: ='Company 6'!B71 -> #DIV/0!
A33: Days total assets | B33: =AVERAGE(C33:H33) -> #DIV/0! | C33: ='Company 1'!B72 -> #DIV/0! | D33: ='Company 2'!B72 -> #DIV/0! | E33: ='Company 3'!B72 -> #DIV/0! | F33: ='Company 4'!B72 -> #DIV/0! | G33: ='Company 5'!B72 -> #DIV/0! | H33: ='Company 6'!B72 -> #DIV/0!
A35: Liquidity & Leverage:
A36: Current ratio | B36: =AVERAGE(C36:H36) -> #DIV/0! | C36: ='Company 1'!B75 -> #DIV/0! | D36: ='Company 2'!B75 -> #DIV/0! | E36: ='Company 3'!B75 -> #DIV/0! | F36: ='Company 4'!B75 -> #DIV/0! | G36: ='Company 5'!B75 -> #DIV/0! | H36: ='Company 6'!B75 -> #DIV/0!
A37: Fin leverage (TA/Equity) | B37: =AVERAGE(C37:H37) -> #DIV/0! | C37: ='Company 1'!B76 -> #DIV/0! | D37: ='Company 2'!B76 -> #DIV/0! | E37: ='Company 3'!B76 -> #DIV/0! | F37: ='Company 4'!B76 -> #DIV/0! | G37: ='Company 5'!B76 -> #DIV/0! | H37: ='Company 6'!B76 -> #DIV/0!
A38: Op leases / Total Capital | B38: =AVERAGE(C38:H38) -> #DIV/0! | C38: ='Company 1'!B77 -> #DIV/0! | D38: ='Company 2'!B77 -> #DIV/0! | E38: ='Company 3'!B77 -> #DIV/0! | F38: ='Company 4'!B77 -> #DIV/0! | G38: ='Company 5'!B77 -> #DIV/0! | H38: ='Company 6'!B77 -> #DIV/0!
A40: DuPont Analysis:
A41: ROE (current) | B41: =AVERAGE(C41:H41) -> #DIV/0! | C41: ='Company 1'!B56 -> #DIV/0! | D41: ='Company 2'!B56 -> #DIV/0! | E41: ='Company 3'!B56 -> #DIV/0! | F41: ='Company 4'!B56 -> #DIV/0! | G41: ='Company 5'!B56 -> #DIV/0! | H41: ='Company 6'!B56 -> #DIV/0!
A42: Net margin | B42: =AVERAGE(C42:H42) -> #DIV/0! | C42: ='Company 1'!B54 -> #DIV/0! | D42: ='Company 2'!B54 -> #DIV/0! | E42: ='Company 3'!B54 -> #DIV/0! | F42: ='Company 4'!B54 -> #DIV/0! | G42: ='Company 5'!B54 -> #DIV/0! | H42: ='Company 6'!B54 -> #DIV/0!
A43: Asset turnover | B43: =AVERAGE(C43:H43) -> #DIV/0! | C43: ='Company 1'!B71 -> #DIV/0! | D43: ='Company 2'!B71 -> #DIV/0! | E43: ='Company 3'!B71 -> #DIV/0! | F43: ='Company 4'!B71 -> #DIV/0! | G43: ='Company 5'!B71 -> #DIV/0! | H43: ='Company 6'!B71 -> #DIV/0!
A44: Financial leverage | B44: =AVERAGE(C44:H44) -> #DIV/0! | C44: ='Company 1'!B76 -> #DIV/0! | D44: ='Company 2'!B76 -> #DIV/0! | E44: ='Company 3'!B76 -> #DIV/0! | F44: ='Company 4'!B76 -> #DIV/0! | G44: ='Company 5'!B76 -> #DIV/0! | H44: ='Company 6'!B76 -> #DIV/0!
...

Sheet Company 1
A1: Company 1
B2: Current Year | C2: 1 Yr Prior | D2: 2 Yrs Prior
A3: VL = Value Line is source:
A4: VL Price
A5: VL P/E
A6: VL Inv. Method (1Fifo, 2Lifo,3Avg, 4Sp ID)
A7: VL Rev. Gr (Past 5 years)
A8: VL Rev. Gr. (Forecast 5 years)
A9: VL EPS Gr. (Past 5 years)
A10: VL EPS Gr. (Forecast 5 years)
A11: VL Op. Margin (Forecast 5 years)
A12: VL Net Margin (Forecast 5 years)
A13: VL ROE (Forecast 5 years)
A14: VL Div. Payout (Forecast 5 years)
... A51: Profitability Ratios (All ratios are automatically calculated):
A52: Gross Margin | B52: =(B18-B19)/B18 -> #DIV/0! | C52: =(C18-C19)/C18 -> #DIV/0! | D52: =(D18-D19)/D18 -> #DIV/0!
A53: Operating Margin | B53: =B24/B18 -> #DIV/0! | C53: =C24/C18 -> #DIV/0! | D53: =D24/D18 -> #DIV/0!
A54: Net Margin (Sustainable) | B54: =B28/B18 -> #DIV/0! | C54: =C28/C18 -> #DIV/0! | D54: =D28/D18 -> #DIV/0!
A55: Return on total assets | B55: =B28/B38 -> #DIV/0!
A56: Return on equity | B56: =B28/B41 -> #DIV/0!
A57: R & D% of Sales | B57: =B20/B18 -> #DIV/0! | C57: =C20/C18 -> #DIV/0! | D57: =D20/D18 -> #DIV/0!
A58: SGA% of Sales | B58: =B21/B18 -> #DIV/0! | C58: =C21/C18 -> #DIV/0! | D58: =D21/D18 -> #DIV/0!
A59: Pretax nonrecurr% of Sales | B59: =B22/B18 -> #DIV/0! | C59: =C22/C18 -> #DIV/0! | D59: =D22/D18 -> #DIV/0!
A60: Avg. Writeoff Period Fixed Assets | B60: =1/(B30/((B35+C35-B37-C37)/2)) -> #DIV/0!
A61: Effective Tax Rate | B61: =B26/B25 -> #DIV/0! | C61: =C26/C25 -> #DIV/0! | D61: =D26/D25 -> #DIV/0!
A63: Activity Ratios:
A64: Revenue per employee | B64: =B18/(B15) -> #DIV/0!
A65: Receivables turnover | B65: =B18/B32 -> #DIV/0!
A66: Days Receivables | B66: =B32/(B18/365) -> #DIV/0!
A67: Inventory turnover | B67: =B19/B33 -> #DIV/0!
A68: Days Inventory | B68: =B33/(B19/365) -> #DIV/0!
A69: Payables turnover | B69: =B19/B39 -> #DIV/0!
A70: Days Payables | B70: =B39/(B19/365) -> #DIV/0!
A71: Total Assets Turnover | B71: =B18/B38 -> #DIV/0!
A72: Days Total Assets | B72: =365/B71 -> #DIV/0!
A74: Liquidity & Leverage Ratios:
A75: Current ratio | B75: =B34/B40 -> #DIV/0!
A76: Fin Leverage (TA/Equity) | B76: =B38/B41 -> #DIV/0!
A77: Op leases % of Tot Cap. | B77: =B45/B38 -> #DIV/0!
A79: Valuation Ratios:
...

Sheet Company 2
A1: Company 2
B2: Current Year | C2: 1 Yr Prior | D2: 2 Yrs Prior
A3: VL = Value Line is source:
A4: VL Price
A5: VL P/E
A6: VL Inv. Method (1Fifo, 2Lifo,3Avg, 4Sp ID)
A7: VL Rev. Gr (Past 5 years)
A8: VL Rev. Gr. (Forecast 5 years)
A9: VL EPS Gr. (Past 5 years)
A10: VL EPS Gr. (Forecast 5 years)
A11: VL Op. Margin (Forecast 5 years)
A12: VL Net Margin (Forecast 5 years)
A13: VL ROE (Forecast 5 years)
A14: VL Div. Payout (Forecast 5 years)
... A51: Profitability Ratios (All ratios are automatically calculated):
A52: Gross Margin | B52: =(B18-B19)/B18 -> #DIV/0! | C52: =(C18-C19)/C18 -> #DIV/0! | D52: =(D18-D19)/D18 -> #DIV/0!
A53: Operating Margin | B53: =B24/B18 -> #DIV/0! | C53: =C24/C18 -> #DIV/0! | D53: =D24/D18 -> #DIV/0!
A54: Net Margin (Sustainable) | B54: =B28/B18 -> #DIV/0! | C54: =C28/C18 -> #DIV/0! | D54: =D28/D18 -> #DIV/0!
A55: Return on total assets | B55: =B28/B38 -> #DIV/0!
A56: Return on equity | B56: =B28/B41 -> #DIV/0!
A57: R & D% of Sales | B57: =B20/B18 -> #DIV/0! | C57: =C20/C18 -> #DIV/0! | D57: =D20/D18 -> #DIV/0!
A58: SGA% of Sales | B58: =B21/B18 -> #DIV/0! | C58: =C21/C18 -> #DIV/0! | D58: =D21/D18 -> #DIV/0!
A59: Pretax nonrecurr% of Sales | B59: =B22/B18 -> #DIV/0! | C59: =C22/C18 -> #DIV/0! | D59: =D22/D18 -> #DIV/0!
A60: Avg. Writeoff Period Fixed Assets | B60: =1/(B30/((B35+C35-B37-C37)/2)) -> #DIV/0!
A61: Effective Tax Rate | B61: =B26/B25 -> #DIV/0! | C61: =C26/C25 -> #DIV/0! | D61: =D26/D25 -> #DIV/0!
A63: Activity Ratios:
A64: Revenue per employee | B64: =B18/(B15) -> #DIV/0!
A65: Receivables turnover | B65: =B18/B32 -> #DIV/0!
A66: Days Receivables | B66: =B32/(B18/365) -> #DIV/0!
A67: Inventory turnover | B67: =B19/B33 -> #DIV/0!
A68: Days Inventory | B68: =B33/(B19/365) -> #DIV/0!
A69: Payables turnover | B69: =B19/B39 -> #DIV/0!
A70: Days Payables | B70: =B39/(B19/365) -> #DIV/0!
A71: Total Assets Turnover | B71: =B18/B38 -> #DIV/0!
A72: Days Total Assets | B72: =365/B71 -> #DIV/0!
A74: Liquidity & Leverage Ratios:
A75: Current ratio | B75: =B34/B40 -> #DIV/0!
A76: Fin Leverage (TA/Equity) | B76: =B38/B41 -> #DIV/0!
A77: Op leases % of Tot Cap. | B77: =B45/B38 -> #DIV/0!
A79: Valuation Ratios:
...

Sheet Company 3
A1: Company 3
B2: Current Year | C2: 1 Yr Prior | D2: 2 Yrs Prior
A3: VL = Value Line is source:
A4: VL Price
A5: VL P/E
A6: VL Inv. Method (1Fifo, 2Lifo,3Avg, 4Sp ID)
A7: VL Rev. Gr (Past 5 years)
A8: VL Rev. Gr. (Forecast 5 years)
A9: VL EPS Gr. (Past 5 years)
A10: VL EPS Gr. (Forecast 5 years)
A11: VL Op. Margin (Forecast 5 years)
A12: VL Net Margin (Forecast 5 years)
A13: VL ROE (Forecast 5 years)
A14: VL Div. Payout (Forecast 5 years)
... A51: Profitability Ratios (All ratios are automatically calculated):
A52: Gross Margin | B52: =(B18-B19)/B18 -> #DIV/0! | C52: =(C18-C19)/C18 -> #DIV/0! | D52: =(D18-D19)/D18 -> #DIV/0!
A53: Operating Margin | B53: =B24/B18 -> #DIV/0! | C53: =C24/C18 -> #DIV/0! | D53: =D24/D18 -> #DIV/0!
A54: Net Margin (Sustainable) | B54: =B28/B18 -> #DIV/0! | C54: =C28/C18 -> #DIV/0! | D54: =D28/D18 -> #DIV/0!
A55: Return on total assets | B55: =B28/B38 -> #DIV/0!
A56: Return on equity | B56: =B28/B41 -> #DIV/0!
A57: R & D% of Sales | B57: =B20/B18 -> #DIV/0! | C57: =C20/C18 -> #DIV/0! | D57: =D20/D18 -> #DIV/0!
A58: SGA% of Sales | B58: =B21/B18 -> #DIV/0! | C58: =C21/C18 -> #DIV/0! | D58: =D21/D18 -> #DIV/0!
A59: Pretax nonrecurr% of Sales | B59: =B22/B18 -> #DIV/0! | C59: =C22/C18 -> #DIV/0! | D59: =D22/D18 -> #DIV/0!
A60: Avg. Writeoff Period Fixed Assets | B60: =1/(B30/((B35+C35-B37-C37)/2)) -> #DIV/0!
A61: Effective Tax Rate | B61: =B26/B25 -> #DIV/0! | C61: =C26/C25 -> #DIV/0! | D61: =D26/D25 -> #DIV/0!
A63: Activity Ratios:
A64: Revenue per employee | B64: =B18/(B15) -> #DIV/0!
A65: Receivables turnover | B65: =B18/B32 -> #DIV/0!
A66: Days Receivables | B66: =B32/(B18/365) -> #DIV/0!
A67: Inventory turnover | B67: =B19/B33 -> #DIV/0!
A68: Days Inventory | B68: =B33/(B19/365) -> #DIV/0!
A69: Payables turnover | B69: =B19/B39 -> #DIV/0!
A70: Days Payables | B70: =B39/(B19/365) -> #DIV/0!
A71: Total Assets Turnover | B71: =B18/B38 -> #DIV/0!
A72: Days Total Assets | B72: =365/B71 -> #DIV/0!
A74: Liquidity & Leverage Ratios:
A75: Current ratio | B75: =B34/B40 -> #DIV/0!
A76: Fin Leverage (TA/Equity) | B76: =B38/B41 -> #DIV/0!
A77: Op leases % of Tot Cap. | B77: =B45/B38 -> #DIV/0!
A79: Valuation Ratios:
...

Sheet Company 4
A1: Company 4
B2: Current Year | C2: 1 Yr Prior | D2: 2 Yrs Prior
A3: VL = Value Line is source:
A4: VL Price
A5: VL P/E
A6: VL Inv. Method (1Fifo, 2Lifo,3Avg, 4Sp ID)
A7: VL Rev. Gr (Past 5 years)
A8: VL Rev. Gr. (Forecast 5 years)
A9: VL EPS Gr. (Past 5 years)
A10: VL EPS Gr. (Forecast 5 years)
A11: VL Op. Margin (Forecast 5 years)
A12: VL Net Margin (Forecast 5 years)
A13: VL ROE (Forecast 5 years)
A14: VL Div. Payout (Forecast 5 years)
... A51: Profitability Ratios (All ratios are automatically calculated):
A52: Gross Margin | B52: =(B18-B19)/B18 -> #DIV/0! | C52: =(C18-C19)/C18 -> #DIV/0! | D52: =(D18-D19)/D18 -> #DIV/0!
A53: Operating Margin | B53: =B24/B18 -> #DIV/0! | C53: =C24/C18 -> #DIV/0! | D53: =D24/D18 -> #DIV/0!
A54: Net Margin (Sustainable) | B54: =B28/B18 -> #DIV/0! | C54: =C28/C18 -> #DIV/0! | D54: =D28/D18 -> #DIV/0!
A55: Return on total assets | B55: =B28/B38 -> #DIV/0!
A56: Return on equity | B56: =B28/B41 -> #DIV/0!
A57: R & D% of Sales | B57: =B20/B18 -> #DIV/0! | C57: =C20/C18 -> #DIV/0! | D57: =D20/D18 -> #DIV/0!
A58: SGA% of Sales | B58: =B21/B18 -> #DIV/0! | C58: =C21/C18 -> #DIV/0! | D58: =D21/D18 -> #DIV/0!
A59: Pretax nonrecurr% of Sales | B59: =B22/B18 -> #DIV/0! | C59: =C22/C18 -> #DIV/0! | D59: =D22/D18 -> #DIV/0!
A60: Avg. Writeoff Period Fixed Assets | B60: =1/(B30/((B35+C35-B37-C37)/2)) -> #DIV/0!
A61: Effective Tax Rate | B61: =B26/B25 -> #DIV/0! | C61: =C26/C25 -> #DIV/0! | D61: =D26/D25 -> #DIV/0!
A63: Activity Ratios:
A64: Revenue per employee | B64: =B18/(B15) -> #DIV/0!
A65: Receivables turnover | B65: =B18/B32 -> #DIV/0!
A66: Days Receivables | B66: =B32/(B18/365) -> #DIV/0!
A67: Inventory turnover | B67: =B19/B33 -> #DIV/0!
A68: Days Inventory | B68: =B33/(B19/365) -> #DIV/0!
A69: Payables turnover | B69: =B19/B39 -> #DIV/0!
A70: Days Payables | B70: =B39/(B19/365) -> #DIV/0!
A71: Total Assets Turnover | B71: =B18/B38 -> #DIV/0!
A72: Days Total Assets | B72: =365/B71 -> #DIV/0!
A74: Liquidity & Leverage Ratios:
A75: Current ratio | B75: =B34/B40 -> #DIV/0!
A76: Fin Leverage (TA/Equity) | B76: =B38/B41 -> #DIV/0!
A77: Op leases % of Tot Cap. | B77: =B45/B38 -> #DIV/0!
A79: Valuation Ratios:
...

Sheet Company 5
A1: Company 5
B2: Current Year | C2: 1 Yr Prior | D2: 2 Yrs Prior
A3: VL = Value Line is source:
A4: VL Price
A5: VL P/E
A6: VL Inv. Method (1Fifo, 2Lifo,3Avg, 4Sp ID)
A7: VL Rev. Gr (Past 5 years)
A8: VL Rev. Gr. (Forecast 5 years)
A9: VL EPS Gr. (Past 5 years)
A10: VL EPS Gr. (Forecast 5 years)
A11: VL Op. Margin (Forecast 5 years)
A12: VL Net Margin (Forecast 5 years)
A13: VL ROE (Forecast 5 years)
A14: VL Div. Payout (Forecast 5 years)
... A51: Profitability Ratios (All ratios are automatically calculated):
A52: Gross Margin | B52: =(B18-B19)/B18 -> #DIV/0! | C52: =(C18-C19)/C18 -> #DIV/0! | D52: =(D18-D19)/D18 -> #DIV/0!
A53: Operating Margin | B53: =B24/B18 -> #DIV/0! | C53: =C24/C18 -> #DIV/0! | D53: =D24/D18 -> #DIV/0!
A54: Net Margin (Sustainable) | B54: =B28/B18 -> #DIV/0! | C54: =C28/C18 -> #DIV/0! | D54: =D28/D18 -> #DIV/0!
A55: Return on total assets | B55: =B28/B38 -> #DIV/0!
A56: Return on equity | B56: =B28/B41 -> #DIV/0!
A57: R & D% of Sales | B57: =B20/B18 -> #DIV/0! | C57: =C20/C18 -> #DIV/0! | D57: =D20/D18 -> #DIV/0!
A58: SGA% of Sales | B58: =B21/B18 -> #DIV/0! | C58: =C21/C18 -> #DIV/0! | D58: =D21/D18 -> #DIV/0!
A59: Pretax nonrecurr% of Sales | B59: =B22/B18 -> #DIV/0! | C59: =C22/C18 -> #DIV/0! | D59: =D22/D18 -> #DIV/0!
A60: Avg. Writeoff Period Fixed Assets | B60: =1/(B30/((B35+C35-B37-C37)/2)) -> #DIV/0!
A61: Effective Tax Rate | B61: =B26/B25 -> #DIV/0! | C61: =C26/C25 -> #DIV/0! | D61: =D26/D25 -> #DIV/0!
A63: Activity Ratios:
A64: Revenue per employee | B64: =B18/(B15) -> #DIV/0!
A65: Receivables turnover | B65: =B18/B32 -> #DIV/0!
A66: Days Receivables | B66: =B32/(B18/365) -> #DIV/0!
A67: Inventory turnover | B67: =B19/B33 -> #DIV/0!
A68: Days Inventory | B68: =B33/(B19/365) -> #DIV/0!
A69: Payables turnover | B69: =B19/B39 -> #DIV/0!
A70: Days Payables | B70: =B39/(B19/365) -> #DIV/0!
A71: Total Assets Turnover | B71: =B18/B38 -> #DIV/0!
A72: Days Total Assets | B72: =365/B71 -> #DIV/0!
A74: Liquidity & Leverage Ratios:
A75: Current ratio | B75: =B34/B40 -> #DIV/0!
A76: Fin Leverage (TA/Equity) | B76: =B38/B41 -> #DIV/0!
A77: Op leases % of Tot Cap. | B77: =B45/B38 -> #DIV/0!
A79: Valuation Ratios:
...

Sheet Company 6
A1: Company 6
B2: Current Year | C2: 1 Yr Prior | D2: 2 Yrs Prior
A3: VL = Value Line is source:
A4: VL Price
A5: VL P/E
A6: VL Inv. Method (1Fifo, 2Lifo,3Avg, 4Sp ID)
A7: VL Rev. Gr (Past 5 years)
A8: VL Rev. Gr. (Forecast 5 years)
A9: VL EPS Gr. (Past 5 years)
A10: VL EPS Gr. (Forecast 5 years)
A11: VL Op. Margin (Forecast 5 years)
A12: VL Net Margin (Forecast 5 years)
A13: VL ROE (Forecast 5 years)
A14: VL Div. Payout (Forecast 5 years)
... A51: Profitability Ratios (All ratios are automatically calculated):
A52: Gross Margin | B52: =(B18-B19)/B18 -> #DIV/0! | C52: =(C18-C19)/C18 -> #DIV/0! | D52: =(D18-D19)/D18 -> #DIV/0!
A53: Operating Margin | B53: =B24/B18 -> #DIV/0! | C53: =C24/C18 -> #DIV/0! | D53: =D24/D18 -> #DIV/0!
A54: Net Margin (Sustainable) | B54: =B28/B18 -> #DIV/0! | C54: =C28/C18 -> #DIV/0! | D54: =D28/D18 -> #DIV/0!
A55: Return on total assets | B55: =B28/B38 -> #DIV/0!
A56: Return on equity | B56: =B28/B41 -> #DIV/0!
A57: R & D% of Sales | B57: =B20/B18 -> #DIV/0! | C57: =C20/C18 -> #DIV/0! | D57: =D20/D18 -> #DIV/0!
A58: SGA% of Sales | B58: =B21/B18 -> #DIV/0! | C58: =C21/C18 -> #DIV/0! | D58: =D21/D18 -> #DIV/0!
A59: Pretax nonrecurr% of Sales | B59: =B22/B18 -> #DIV/0! | C59: =C22/C18 -> #DIV/0! | D59: =D22/D18 -> #DIV/0!
A60: Avg. Writeoff Period Fixed Assets | B60: =1/(B30/((B35+C35-B37-C37)/2)) -> #DIV/0!
A61: Effective Tax Rate | B61: =B26/B25 -> #DIV/0! | C61: =C26/C25 -> #DIV/0! | D61: =D26/D25 -> #DIV/0!
A63: Activity Ratios:
A64: Revenue per employee | B64: =B18/(B15) -> #DIV/0!
A65: Receivables turnover | B65: =B18/B32 -> #DIV/0!
A66: Days Receivables | B66: =B32/(B18/365) -> #DIV/0!
A67: Inventory turnover | B67: =B19/B33 -> #DIV/0!
A68: Days Inventory | B68: =B33/(B19/365) -> #DIV/0!
A69: Payables turnover | B69: =B19/B39 -> #DIV/0!
A70: Days Payables | B70: =B39/(B19/365) -> #DIV/0!
A71: Total Assets Turnover | B71: =B18/B38 -> #DIV/0!
A72: Days Total Assets | B72: =365/B71 -> #DIV/0!
A74: Liquidity & Leverage Ratios:
A75: Current ratio | B75: =B34/B40 -> #DIV/0!
A76: Fin Leverage (TA/Equity) | B76: =B38/B41 -> #DIV/0!
A77: Op leases % of Tot Cap. | B77: =B45/B38 -> #DIV/0!
A79: Valuation Ratios:
...
