Workbook
Name Maturity: 'Financial Model'!$D$153:$E$162
Name Maturity: #REF!
Name MaturitySchedule: 'Financial Model'!$D$153:$D$162
Name MaturitySchedule: #REF!
Name Retention: 'Financial Model'!$D$153:$F$162
Name Retention: #REF!
Name Statement_Date: #REF!

Sheet Begin Model

Sheet Model Assumptions
A1: Exhibit 1 Model Assumptions
A3: ASSUMPTIONS | B3: Lo | C3: Med | D3: Hi
A4: Duration of average loan (years) | B4: 0.5 | C4: 1.5 | D4: 2
A5: Amount of average loan | B5: 5 | C5: 10 | D5: 30
A6: Interest rate of average loan (excluding inflation) | B6: 0.35 | C6: 0.485 | D6: 0.65
A7: Default rate | B7: 0.05 | C7: 0.1 | D7: 0.15
A8: Required deposits by borrowers | B8: 0.05 | C8: 0.1 | D8: 0.2
A9: Loan advisors per office | B9: 2 | C9: 6 | D9: 7
A10: Loan advisor annual salary | B10: 12 | C10: 15 | D10: 20
A11: Growth Rate | B11: 0.05 | C11: 0.1 | D11: 0.15
A12: Tax Rate | B12: 0.05 | C12: 0.15 | D12: 0.3
A13: Discount Rate | B13: 0.15 | C13: 0.296 | D13: 0.35
A14: Growth in Terminal Value | B14: 0 | C14: 0.05 | D14: 0.1
A15: Application fee | B15: 15 | C15: 35 | D15: 50
... A33: Accounts payable (% SGA & Operating Expense) | B33: 0.04 | C33: 0.05 | D33: 0.06
A34: Interest on Debt from Ukrainian Investor | C34: 0
A36: Equipment | B36: Life | C36: Cost
A37: Computer (1 per staff member) | B37: 5 | C37: 1.5
A38: Office fixtures ($50,000 per branch) | B38: same | C38: 25
A39: Photocopier (1 per branch) | B39: same | C39: 10
A40: Automobile (1 per branch) | B40: 5 | C40: 5

Sheet Financial Model
A1: Exhibit 2 Financial Model
A3: NEWBANK PRO FORMA FINANCIAL INFORMATION
A4: (All dollar figures stated in '000USD 2001)
D6: 2001 | E6: 2002 | F6: 2003 | G6: 2004 | H6: 2005 | I6: 2006 | J6: 2007 | K6: 2008 | L6: 2009 | M6: 2010
D7: 1 | E7: 2 | F7: 3 | G7: 4 | H7: 5 | I7: 6 | J7: 7 | K7: 8 | L7: 9 | M7: 10
A9: LOAN PORTFOLIO DETAILS
B10: Beginning portfolio value | D10: 0 | E10: =D14 -> 1000 | F10: =E14 -> 3000 | G10: =F14 -> 5500 | H10: =G14 -> 9625 | I10: =H14 -> 13781.25 | J10: =I14 -> 17226.562 | K10: =J14 -> 20097.656 | L10: =K14 -> 22107.422 | M10: =L14 -> 24318.164
B11: Loans issued during period | D11: 1000 | E11: =D11*(1+E12) -> 2000 | F11: =E11*(1+F12) -> 3500 | G11: =F11*(1+G12) -> 6125 | H11: =G11*(1+H12) -> 7656.25 | I11: =H11*(1+I12) -> 9570.3125 | J11: =I11*(1+J12) -> 10527.344 | K11: =J11*(1+K12) -> 11580.078 | L11: =K11*(1+L12) -> 12738.086 | M11: =L11*(1+M12) -> 14011.895
B12: Growth in total value of loans issued | E12: 1 | F12: 0.75 | G12: 0.75 | H12: 0.25 | I12: 0.25 | J12: 0.1 | K12: 0.1 | L12: 0.1 | M12: 0.1
B13: Loans matured during period | D13: =-IF(ISERROR(VLOOKUP(D7,Maturity,2)),0,VLOOKUP(D7,Maturity,2)) -> 0 | E13: =-IF(ISERROR(VLOOKUP(E7,Maturity,2)),0,VLOOKUP(E7,Maturity,2)) -> 0 | F13: =-IF(ISERROR(VLOOKUP(F7,Maturity,2)),0,VLOOKUP(F7,Maturity,2)) -> -1000 | G13: =-IF(ISERROR(VLOOKUP(G7,Maturity,2)),0,VLOOKUP(G7,Maturity,2)) -> -2000 | H13: =-IF(ISERROR(VLOOKUP(H7,Maturity,2)),0,VLOOKUP(H7,Maturity,2)) -> -3500 | I13: =-IF(ISERROR(VLOOKUP(I7,Maturity,2)),0,VLOOKUP(I7,Maturity,2)) -> -6125 | J13: =-IF(ISERROR(VLOOKUP(J7,Maturity,2)),0,VLOOKUP(J7,Maturity,2)) -> -7656.25 | K13: =-IF(ISERROR(VLOOKUP(K7,Maturity,2)),0,VLOOKUP(K7,Maturity,2)) -> -9570.3125 | ... M13: =-IF(ISERROR(VLOOKUP(M7,Maturity,2)),0,VLOOKUP(M7,Maturity,2)) -> -11580.078
B14: End-of-year portfolio value | D14: =D10+D11 -> 1000 | E14: =E10+E11 -> 3000 | F14: =F10+F11+F13 -> 5500 | G14: =G10+G11+G13 -> 9625 | H14: =H10+H11+H13 -> 13781.25 | I14: =I10+I11+I13 -> 17226.562 | J14: =J10+J11+J13 -> 20097.656 | K14: =K10+K11+K13 -> 22107.422 | L14: =L10+L11+L13 -> 24318.164 | M14: =M10+M11+M13 -> 26749.98
B15: Average loan portfolio value | D15: =(D10+D14)/2 -> 500 | E15: =(E10+E14)/2 -> 2000 | F15: =(F10+F14)/2 -> 4250 | G15: =(G10+G14)/2 -> 7562.5 | H15: =(H10+H14)/2 -> 11703.125 | I15: =(I10+I14)/2 -> 15503.906 | J15: =(J10+J14)/2 -> 18662.109 | K15: =(K10+K14)/2 -> 21102.539 | ... M15: =(M10+M14)/2 -> 25534.072
A18: BORROWER DETAILS
B19: Creditors with loans outstanding from prior period | D19: 0 | E19: =D24 -> 100 | F19: =E24 -> 200 | G19: =F24 -> 350 | H19: =G24 -> 612.5 | I19: =H24 -> 765.625 | J19: =I24 -> 957.03125 | K19: =J24 -> 1052.7344 | L19: =K24 -> 1158.0078 | M19: =L24 -> 1273.8086
B20: Returning creditors (2nd or 3rd loan) | D20: ='Model Assumptions'!$C$29*-1*'Financial Model'!C23 -> 0 | E20: ='Model Assumptions'!$C$29*-1*'Financial Model'!D23 -> 0 | F20: ='Model Assumptions'!$C$29*-1*'Financial Model'!E23 -> 0 | G20: ='Model Assumptions'!$C$29*-1*'Financial Model'!F23 -> 50 | H20: ='Model Assumptions'!$C$29*-1*'Financial Model'!G23 -> 100 | I20: ='Model Assumptions'!$C$29*-1*'Financial Model'!H23 -> 175 | J20: ='Model Assumptions'!$C$29*-1*'Financial Model'!I23 -> 306.25 | K20: ='Model Assumptions'!$C$29*-1*'Financial Model'!J23 -> 382.8125 | ... M20: ='Model Assumptions'!$C$29*-1*'Financial Model'!L23 -> 526.36719
B21: First-time creditors added during period | D21: =D24-C24-D23-D20 -> 100 | E21: =E24-D24-E23-E20 -> 100 | F21: =F24-E24-F23-F20 -> 250 | G21: =G24-F24-G23-G20 -> 412.5 | H21: =H24-G24-H23-H20 -> 403.125 | I21: =I24-H24-I23-I20 -> 628.90625 | J21: =J24-I24-J23-J20 -> 555.07812 | K21: =K24-J24-K23-K20 -> 679.49219 | ... M21: =M24-L24-M23-M20 -> 759.02148
B22: Creditors defaulting during period
B23: Creditors with loans maturing during period | D23: =-1*IF(ISERROR(VLOOKUP(D7,Retention,3)),0,VLOOKUP(D7,Retention,3)) -> 0 | E23: =-1*IF(ISERROR(VLOOKUP(E7,Retention,3)),0,VLOOKUP(E7,Retention,3)) -> 0 | F23: =-1*IF(ISERROR(VLOOKUP(F7,Retention,3)),0,VLOOKUP(F7,Retention,3)) -> -100 | G23: =-1*IF(ISERROR(VLOOKUP(G7,Retention,3)),0,VLOOKUP(G7,Retention,3)) -> -200 | H23: =-1*IF(ISERROR(VLOOKUP(H7,Retention,3)),0,VLOOKUP(H7,Retention,3)) -> -350 | I23: =-1*IF(ISERROR(VLOOKUP(I7,Retention,3)),0,VLOOKUP(I7,Retention,3)) -> -612.5 | J23: =-1*IF(ISERROR(VLOOKUP(J7,Retention,3)),0,VLOOKUP(J7,Retention,3)) -> -765.625 | K23: =-1*IF(ISERROR(VLOOKUP(K7,Retention,3)),0,VLOOKUP(K7,Retention,3)) -> -957.03125 | ... M23: =-1*IF(ISERROR(VLOOKUP(M7,Retention,3)),0,VLOOKUP(M7,Retention,3)) -> -1158.0078
B24: Total current borrowers | D24: =D11/'Model Assumptions'!$C$5 -> 100 | E24: =E11/'Model Assumptions'!$C$5 -> 200 | F24: =F11/'Model Assumptions'!$C$5 -> 350 | G24: =G11/'Model Assumptions'!$C$5 -> 612.5 | H24: =H11/'Model Assumptions'!$C$5 -> 765.625 | I24: =I11/'Model Assumptions'!$C$5 -> 957.03125 | J24: =J11/'Model Assumptions'!$C$5 -> 1052.7344 | K24: =K11/'Model Assumptions'!$C$5 -> 1158.0078 | ... M24: =M11/'Model Assumptions'!$C$5 -> 1401.1895
A26: OPERATIONAL DETAILS
B27: Number of Branches | D27: 1 | E27: 3 | F27: 4 | G27: 7 | H27: 10 | I27: 13 | J27: 15 | K27: 17 | L27: 20 | M27: 24
B28: Staffing
B29: Senior Executives | D29: ='Model Assumptions'!$C$22 -> 1 | E29: ='Model Assumptions'!$C$22 -> 1 | F29: ='Model Assumptions'!$C$22 -> 1 | G29: ='Model Assumptions'!$C$22 -> 1 | H29: ='Model Assumptions'!$C$22 -> 1 | I29: ='Model Assumptions'!$C$22 -> 1 | J29: ='Model Assumptions'!$C$22 -> 1 | K29: ='Model Assumptions'!$C$22 -> 1 | ... M29: ='Model Assumptions'!$C$22 -> 1
B30: Branch Directors | D30: ='Model Assumptions'!$C$20*D27 -> 1 | E30: ='Model Assumptions'!$C$20*E27 -> 3 | F30: ='Model Assumptions'!$C$20*F27 -> 4 | G30: ='Model Assumptions'!$C$20*G27 -> 7 | H30: ='Model Assumptions'!$C$20*H27 -> 10 | I30: ='Model Assumptions'!$C$20*I27 -> 13 | J30: ='Model Assumptions'!$C$20*J27 -> 15 | K30: ='Model Assumptions'!$C$20*K27 -> 17 | ... M30: ='Model Assumptions'!$C$20*M27 -> 24
B31: Loan Advisors | D31: 4 | E31: =E27*'Model Assumptions'!$C$9 -> 18 | F31: =F27*'Model Assumptions'!$C$9 -> 24 | G31: =G27*'Model Assumptions'!$C$9 -> 42 | H31: =H27*'Model Assumptions'!$C$9 -> 60 | I31: =I27*'Model Assumptions'!$C$9 -> 78 | J31: =J27*'Model Assumptions'!$C$9 -> 90 | K31: =K27*'Model Assumptions'!$C$9 -> 102 | L31: =L27*'Model Assumptions'!$C$9 -> 120 | M31: =M27*'Model Assumptions'!$C$9 -> 144
B32: Loan advisor turnover | D32: =ROUNDDOWN(D31*'Model Assumptions'!$C$24,0) -> 0 | E32: =ROUNDDOWN(E31*'Model Assumptions'!$C$24,0) -> 2 | F32: =ROUNDDOWN(F31*'Model Assumptions'!$C$24,0) -> 3 | G32: =ROUNDDOWN(G31*'Model Assumptions'!$C$24,0) -> 6 | H32: =ROUNDDOWN(H31*'Model Assumptions'!$C$24,0) -> 9 | I32: =ROUNDDOWN(I31*'Model Assumptions'!$C$24,0) -> 11 | J32: =ROUNDDOWN(J31*'Model Assumptions'!$C$24,0) -> 13 | K32: =ROUNDDOWN(K31*'Model Assumptions'!$C$24,0) -> 15 | ... M32: =ROUNDDOWN(M31*'Model Assumptions'!$C$24,0) -> 21
B33: New loan advisors hired during period | D33: =D31-C31+D32 -> 4 | E33: =E31-D31+E32 -> 16 | F33: =F31-E31+F32 -> 9 | G33: =G31-F31+G32 -> 24 | H33: =H31-G31+H32 -> 27 | I33: =I31-H31+I32 -> 29 | J33: =J31-I31+J32 -> 25 | K33: =K31-J31+K32 -> 27 | ... M33: =M31-L31+M32 -> 45
B34: Total professional staff | D34: =D31+D30+D29 -> 6 | E34: =E31+E30+E29 -> 22 | F34: =F31+F30+F29 -> 29 | G34: =G31+G30+G29 -> 50 | H34: =H31+H30+H29 -> 71 | I34: =I31+I30+I29 -> 92 | J34: =J31+J30+J29 -> 106 | K34: =K31+K30+K29 -> 120 | ... M34: =M31+M30+M29 -> 169
C35: Administrative Coordinators | D35: =D34/'Model Assumptions'!$C$25 -> 2 | E35: =E34/'Model Assumptions'!$C$25 -> 7.3333333 | F35: =F34/'Model Assumptions'!$C$25 -> 9.6666667 | G35: =G34/'Model Assumptions'!$C$25 -> 16.666667 | H35: =H34/'Model Assumptions'!$C$25 -> 23.666667 | I35: =I34/'Model Assumptions'!$C$25 -> 30.666667 | J35: =J34/'Model Assumptions'!$C$25 -> 35.333333 | K35: =K34/'Model Assumptions'!$C$25 -> 40 | ... M35: =M34/'Model Assumptions'!$C$25 -> 56.333333
B36: Total employees | D36: =D35+D31+D30+D29 -> 8 | E36: =E35+E31+E30+E29 -> 29.333333 | F36: =F35+F31+F30+F29 -> 38.666667 | G36: =G35+G31+G30+G29 -> 66.666667 | H36: =H35+H31+H30+H29 -> 94.666667 | I36: =I35+I31+I30+I29 -> 122.66667 | J36: =J35+J31+J30+J29 -> 141.33333 | K36: =K35+K31+K30+K29 -> 160 | ... M36: =M35+M31+M30+M29 -> 225.33333
B38: New Creditors Per Advisor | D38: =D21/D31 -> 25 | E38: =E21/E31 -> 5.5555556 | F38: =F21/F31 -> 10.416667 | G38: =G21/G31 -> 9.8214286 | H38: =H21/H31 -> 6.71875 | I38: =I21/I31 -> 8.0629006 | J38: =J21/J31 -> 6.1675347 | K38: =K21/K31 -> 6.6616881 | ... M38: =M21/M31 -> 5.2709825
A40: NEWBANK PRO FORMA INCOME STATEMENT
A41: (All dollar figures stated in '000USD 2001)
D43: 2001 | E43: 2002 | F43: 2003 | G43: 2004 | H43: 2005 | I43: 2006 | J43: 2007 | K43: 2008 | L43: 2009 | M43: 2010
B44: Interest Income
C45: Application Fees | D45: =D21*'Model Assumptions'!$C$15*'Model Assumptions'!$C$16/1000 -> 10.5 | E45: =E21*'Model Assumptions'!$C$15*'Model Assumptions'!$C$16/1000 -> 10.5 | F45: =F21*'Model Assumptions'!$C$15*'Model Assumptions'!$C$16/1000 -> 26.25 | G45: =G21*'Model Assumptions'!$C$15*'Model Assumptions'!$C$16/1000 -> 43.3125 | H45: =H21*'Model Assumptions'!$C$15*'Model Assumptions'!$C$16/1000 -> 42.328125 | I45: =I21*'Model Assumptions'!$C$15*'Model Assumptions'!$C$16/1000 -> 66.035156 | J45: =J21*'Model Assumptions'!$C$15*'Model Assumptions'!$C$16/1000 -> 58.283203 | K45: =K21*'Model Assumptions'!$C$15*'Model Assumptions'!$C$16/1000 -> 71.34668 | ... M45: =M21*'Model Assumptions'!$C$15*'Model Assumptions'!$C$16/1000 -> 79.697256
C46: Interest Income on Short Term Investments | D46: =D82*'Model Assumptions'!$C$32 -> 2.3074782 | E46: =((D82+E82)/2)*'Model Assumptions'!$C$32 -> 12.632184 | F46: =((E82+F82)/2)*'Model Assumptions'!$C$32 -> 45.612639 | G46: =((F82+G82)/2)*'Model Assumptions'!$C$32 -> 38.040882 | H46: =((G82+H82)/2)*'Model Assumptions'!$C$32 -> 6.2382826 | I46: =((H82+I82)/2)*'Model Assumptions'!$C$32 -> 25.932497 | J46: =((I82+J82)/2)*'Model Assumptions'!$C$32 -> 180.50665 | K46: =((J82+K82)/2)*'Model Assumptions'!$C$32 -> 586.96797 | L46: =((K82+L82)/2)*'Model Assumptions'!$C$32 -> 1172.729 | M46: =((L82+M82)/2)*'Model Assumptions'!$C$32 -> 1836.427
C47: Interest Income on loans | D47: =((D10+D14)/2)*'Model Assumptions'!$C$6 -> 242.5 | E47: =((E10+E14)/2)*'Model Assumptions'!$C$6 -> 970 | F47: =((F10+F14)/2)*'Model Assumptions'!$C$6 -> 2061.25 | G47: =((G10+G14)/2)*'Model Assumptions'!$C$6 -> 3667.8125 | H47: =((H10+H14)/2)*'Model Assumptions'!$C$6 -> 5676.0156 | I47: =((I10+I14)/2)*'Model Assumptions'!$C$6 -> 7519.3945 | J47: =((J10+J14)/2)*'Model Assumptions'!$C$6 -> 9051.123 | K47: =((K10+K14)/2)*'Model Assumptions'!$C$6 -> 10234.731 | ... M47: =((M10+M14)/2)*'Model Assumptions'!$C$6 -> 12384.025
B48: Total Interest Income | D48: =SUM(D45:D47) -> 255.30748 | E48: =SUM(E45:E47) -> 993.13218 | F48: =SUM(F45:F47) -> 2133.1126 | G48: =SUM(G45:G47) -> 3749.1659 | H48: =SUM(H45:H47) -> 5724.582 | I48: =SUM(I45:I47) -> 7611.3622 | J48: =SUM(J45:J47) -> 9289.9129 | K48: =SUM(K45:K47) -> 10893.046 | ... M48: =SUM(M45:M47) -> 14300.149
B50: Interest Expense
...

Sheet NPV Calculation
A1: Exhibit 3 NPV Calculation
A3: NEWBANK NET PRESENT VALUE OF CASH FLOWS CALCULATION
A4: (All dollar figures stated in '000USD 2001)
O5: Terminal
D6: 2000 | E6: 2001 | F6: 2002 | G6: 2003 | H6: 2004 | I6: 2005 | J6: 2006 | K6: 2007 | L6: 2008 | M6: 2009 | N6: 2010 | O6: Value
B7: Net Income | E7: ='Financial Model'!D73 -> -242.39252 | F7: ='Financial Model'!E73 -> -19.967816 | G7: ='Financial Model'!F73 -> 882.41423 | H7: ='Financial Model'!G73 -> 1785.5442 | I7: ='Financial Model'!H73 -> 3246.5749 | J7: ='Financial Model'!I73 -> 4706.8966 | K7: ='Financial Model'!J73 -> 6186.2148 | L7: ='Financial Model'!K73 -> 7618.5058 | ... N7: ='Financial Model'!M73 -> 9865.1526
A8: Add Non Cash Expenses:
B9: Depreciation | E9: ='Financial Model'!D62 -> 5.7 | F9: ='Financial Model'!E62 -> 21.6 | G9: ='Financial Model'!F62 -> 35.7 | H9: ='Financial Model'!G62 -> 57.3 | I9: ='Financial Model'!H62 -> 86.7 | J9: ='Financial Model'!I62 -> 116.1 | K9: ='Financial Model'!J62 -> 125.5 | L9: ='Financial Model'!K62 -> 123.9 | ... N9: ='Financial Model'!M62 -> 28.7
B10: Provision for Loan Losses | E10: ='Financial Model'!D56 -> 100 | F10: ='Financial Model'!E56 -> 200 | G10: ='Financial Model'!F56 -> 250 | H10: ='Financial Model'!G56 -> 412.5 | I10: ='Financial Model'!H56 -> 415.625 | J10: ='Financial Model'!I56 -> 344.53125 | K10: ='Financial Model'!J56 -> 287.10938 | L10: ='Financial Model'!K56 -> 200.97656 | ... N10: ='Financial Model'!M56 -> 243.18164
A11: Less Change in Net Working Capital: | E11: ='Financial Model'!D131+'Financial Model'!D132+'Financial Model'!D134+'Financial Model'!D135 -> -885.66883 | F11: ='Financial Model'!E131+'Financial Model'!E132+'Financial Model'!E134+'Financial Model'!E135 -> -1760.1943 | G11: ='Financial Model'!F131+'Financial Model'!F132+'Financial Model'!F134+'Financial Model'!F135 -> -2210.6531 | H11: ='Financial Model'!G131+'Financial Model'!G132+'Financial Model'!G134+'Financial Model'!G135 -> -3665.0666 | I11: ='Financial Model'!H131+'Financial Model'!H132+'Financial Model'!H134+'Financial Model'!H135 -> -3671.902 | J11: ='Financial Model'!I131+'Financial Model'!I132+'Financial Model'!I134+'Financial Model'!I135 -> -3032.8766 | K11: ='Financial Model'!J131+'Financial Model'!J132+'Financial Model'!J134+'Financial Model'!J135 -> -2528.4943 | L11: ='Financial Model'!K131+'Financial Model'!K132+'Financial Model'!K134+'Financial Model'!K135 -> -1765.2386 | ... N11: ='Financial Model'!M131+'Financial Model'!M132+'Financial Model'!M134+'Financial Model'!M135 -> -2118.9565
A12: Less Capital Expenditures: | E12: ='Financial Model'!D139 -> -52 | F12: ='Financial Model'!E139 -> -112 | G12: ='Financial Model'!F139 -> -54 | H12: ='Financial Model'!G139 -> -162 | I12: ='Financial Model'!H139 -> -162 | J12: ='Financial Model'!I139 -> -162 | K12: ='Financial Model'!J139 -> -108 | L12: ='Financial Model'!K139 -> -108 | ... N12: ='Financial Model'!M139 -> -216
B13: Free Cash Flows | E13: =SUM(E7:E12) -> -1074.3614 | F13: =SUM(F7:F12) -> -1670.5621 | G13: =SUM(G7:G12) -> -1096.5389 | H13: =SUM(H7:H12) -> -1571.7224 | I13: =SUM(I7:I12) -> -85.002069 | J13: =SUM(J7:J12) -> 1972.6513 | K13: =SUM(K7:K12) -> 3962.3299 | L13: =SUM(L7:L12) -> 6070.1438 | ... N13: =SUM(N7:N12) -> 7802.0777 | O13: =N13*(1+'Model Assumptions'!C11)/('Model Assumptions'!C13-'Model Assumptions'!C11) -> 43787.171
A15: Present Value of Free Cash Flows | E15: =E13/(1+'Model Assumptions'!$C$13)^('NPV Calculation'!E6-'NPV Calculation'!$D$6) -> -828.98253 | F15: =F13/(1+'Model Assumptions'!$C$13)^('NPV Calculation'!F6-'NPV Calculation'!$D$6) -> -994.60954 | G15: =G13/(1+'Model Assumptions'!$C$13)^('NPV Calculation'!G6-'NPV Calculation'!$D$6) -> -503.74302 | H15: =H13/(1+'Model Assumptions'!$C$13)^('NPV Calculation'!H6-'NPV Calculation'!$D$6) -> -557.12908 | I15: =I13/(1+'Model Assumptions'!$C$13)^('NPV Calculation'!I6-'NPV Calculation'!$D$6) -> -23.249011 | J15: =J13/(1+'Model Assumptions'!$C$13)^('NPV Calculation'!J6-'NPV Calculation'!$D$6) -> 416.31332 | K15: =K13/(1+'Model Assumptions'!$C$13)^('NPV Calculation'!K6-'NPV Calculation'!$D$6) -> 645.23158 | L15: =L13/(1+'Model Assumptions'!$C$13)^('NPV Calculation'!L6-'NPV Calculation'!$D$6) -> 762.70917 | ... N15: =N13/(1+'Model Assumptions'!$C$13)^('NPV Calculation'!N6-'NPV Calculation'!$D$6) -> 583.66044 | O15: =O13/(1+'Model Assumptions'!$C$13-'Model Assumptions'!$C$14)^('NPV Calculation'!N6-'NPV Calculation'!$D$6) -> 4854.7455
A16: Sum of PV Cash Flows | D16: =SUM(E15:O15) -> 5028.4471
A18: Cost of Project - Debt | E18: =IF(-'Financial Model'!D143<0,-'Financial Model'!D143,0) -> -1100 | F18: =IF(-'Financial Model'!E143<0,-'Financial Model'!E143,0) -> -1400 | G18: =IF(-'Financial Model'!F143<0,-'Financial Model'!F143,0) -> 0 | H18: =IF(-'Financial Model'!G143<0,-'Financial Model'!G143,0) -> 0 | I18: =IF(-'Financial Model'!H143<0,-'Financial Model'!H143,0) -> 0 | J18: =IF(-'Financial Model'!I143<0,-'Financial Model'!I143,0) -> 0 | K18: =IF(-'Financial Model'!J143<0,-'Financial Model'!J143,0) -> 0 | L18: =IF(-'Financial Model'!K143<0,-'Financial Model'!K143,0) -> 0 | ... N18: =IF(-'Financial Model'!M143<0,-'Financial Model'!M143,0) -> 0
A19: Cost of Project - Equity | E19: =IF(-'Financial Model'!D144<0,-'Financial Model'!D144,0) -> 0 | F19: =IF(-'Financial Model'!E144<0,-'Financial Model'!E144,0) -> -500 | G19: =IF(-'Financial Model'!F144<0,-'Financial Model'!F144,0) -> -1600 | H19: =IF(-'Financial Model'!G144<0,-'Financial Model'!G144,0) -> -900 | I19: =IF(-'Financial Model'!H144<0,-'Financial Model'!H144,0) -> -50 | J19: =IF(-'Financial Model'!I144<0,-'Financial Model'!I144,0) -> 0 | K19: =IF(-'Financial Model'!J144<0,-'Financial Model'!J144,0) -> 0 | L19: =IF(-'Financial Model'!K144<0,-'Financial Model'!K144,0) -> 0 | ... N19: =IF(-'Financial Model'!M144<0,-'Financial Model'!M144,0) -> 0
B20: Total Capital Expenditures | E20: =IF(-'Financial Model'!D145<0,-'Financial Model'!D145,0) -> -1100 | F20: =IF(-'Financial Model'!E145<0,-'Financial Model'!E145,0) -> -1900 | G20: =IF(-'Financial Model'!F145<0,-'Financial Model'!F145,0) -> -1600 | H20: =IF(-'Financial Model'!G145<0,-'Financial Model'!G145,0) -> -900 | I20: =IF(-'Financial Model'!H145<0,-'Financial Model'!H145,0) -> -50 | J20: =IF(-'Financial Model'!I145<0,-'Financial Model'!I145,0) -> 0 | K20: =IF(-'Financial Model'!J145<0,-'Financial Model'!J145,0) -> 0 | L20: =IF(-'Financial Model'!K145<0,-'Financial Model'!K145,0) -> 0 | ... N20: =IF(-'Financial Model'!M145<0,-'Financial Model'!M145,0) -> 0
A22: Present Value of Project Costs | E22: =E20/(1+$H$28)^(E6-$D$6) -> -1043.8909 | F22: =F20/(1+$H$28)^(F6-$D$6) -> -1711.112 | G22: =G20/(1+$H$28)^(G6-$D$6) -> -1367.4367 | H22: =H20/(1+$H$28)^(H6-$D$6) -> -729.9484 | I22: =I20/(1+$H$28)^(I6-$D$6) -> -38.484165 | J22: =J20/(1+$H$28)^(J6-$D$6) -> 0 | K22: =K20/(1+$H$28)^(K6-$D$6) -> 0 | L22: =L20/(1+$H$28)^(L6-$D$6) -> 0 | ... N22: =N20/(1+$H$28)^(N6-$D$6) -> 0
A23: Sum of PV Project Costs | D23: =SUM(E22:N22) -> -4890.872
A25: NPV | D25: =D16+D23 -> 137.57504
E26: =E16 -> 0
A28: (1) | B28: Discounted at 30 year US T Bond rate. | H28: 0.05375

Sheet End Model

Sheet Goldman Integrated Model
A1: Exhibit 4 Goldman Integrated Model
A3: Sovereign Yield Spread | H3: New Bank Cost of Capital
B4: Ukraine | C4: US | D4: Sovereign | E4: Date of Ukrainian Issue
A5: 98 day/90 day | B5: 0.175 | C5: 0.0483 | D5: =B5-C5 -> 0.1267 | E5: 36942 | H5: Beta x Risk Premium | K5: =D22*C24 -> 0.0578
A6: 126-day/4 mo. | B6: 0.1698 | C6: 0.0475 | D6: =B6-C6 -> 0.1223 | E6: 36950 | H6: +
A7: 182 day/180 day | B7: 0.189 | C7: 0.0469 | D7: =B7-C7 -> 0.1421 | E7: 36942 | H7: Risk free Rate | K7: =B11 -> 0.045
A8: 217-day/7 mo. | B8: 0.1797 | C8: 0.0467 | D8: =B8-C8 -> 0.133 | E8: 36950 | H8: +
D9: =AVERAGE(D5:D8) -> 0.131025 | H9: Sovereign Yield Spread | K9: =D9 -> 0.131025
H10: Total CoC | K10: =SUM(K5:K9) -> 0.233825
A11: Risk-free Rate | B11: 0.045 | C11: Based on 1 year Treasury Bond
A14: Estimated Market Beta
A15: Regional Banks | D15: 0.67 | E15: Yardville National Bank
D16: 0.75 | E16: Bank of the Ozarks
D17: 0.31 | E17: Farquier Bankshares Inc
D18: 0.72 | E18: Belmont Bancorp
D19: 0.44 | E19: Acadiana BancShares, Inc.
A20: Ave. Reg. Bank Beta | D20: =AVERAGE(D15:D19) -> 0.578
A21: Premium for Microfinancing | D21: x 2 | E21: Accounts for elevated risk of microfinancing
A22: Overall Estimated Beta | D22: =D20*2 -> 1.156
A24: Historical US Risk Premium | C24: 0.05 | D24: Approximation
