Workbook

Sheet Cash Flow
A1: Cash Flow Statement
B2: Start-Up | C2: 1 | D2: 2 | E2: 3 | F2: 4 | G2: 5 | H2: 6 | I2: 7 | J2: 8 | K2: 9 | L2: 10 | M2: 11 | N2: 12
A3: Cash on Hand
A4: Sales-Cash
A6: Other Sources of Cash:
A7: Loan Proceeds
A8: Owner's Cash Injection
A10: Total Cash Available | B10: =SUM(B3:B8) -> 0 | C10: =SUM(C3:C8) -> 0 | D10: =SUM(D3:D8) -> 0 | E10: =SUM(E3:E8) -> 0 | F10: =SUM(F3:F8) -> 0 | G10: =SUM(G3:G8) -> 0 | H10: =SUM(H3:H8) -> 0 | I10: =SUM(I3:I8) -> 0 | ... N10: =SUM(N3:N8) -> 0
A12: Operating Expenses
A13: Purchases (Merchandise)
A14: Salaries & wages (Excludes withdrawals)
A15: Payroll Expenses (Taxes etc.)
A16: Outside Services
A17: Supplies
A18: Repairs and Maintenance
A19: Advertising
A20: Car Delivery and Travel
A21: Accounting and Legal Fees
A22: Rent
A23: Telephone
... A29: Other
A30: Total Operating Expenses | B30: =SUM(B13:B29) -> 0 | C30: =SUM(C13:C29) -> 0 | D30: =SUM(D13:D29) -> 0 | E30: =SUM(E13:E29) -> 0 | F30: =SUM(F13:F29) -> 0 | G30: =SUM(G13:G29) -> 0 | H30: =SUM(H13:H29) -> 0 | I30: =SUM(I13:I29) -> 0 | ... N30: =SUM(N13:N29) -> 0
A32: Other Start-up costs:
A33: Miscellaneous
A34: Owner's Withdrawal
A35: Total Other Start-up costs | B35: =SUM(B33:B34) -> 0 | C35: =SUM(C33:C34) -> 0 | D35: =SUM(D33:D34) -> 0 | E35: =SUM(E33:E34) -> 0 | F35: =SUM(F33:F34) -> 0 | G35: =SUM(G33:G34) -> 0 | H35: =SUM(H33:H34) -> 0 | I35: =SUM(I33:I34) -> 0 | ... N35: =SUM(N33:N34) -> 0
A38: Total Cash Paid Out | B38: =B30+B35 -> 0 | C38: =C30+C35 -> 0 | D38: =D30+D35 -> 0 | E38: =E30+E35 -> 0 | F38: =F30+F35 -> 0 | G38: =G30+G35 -> 0 | H38: =H30+H35 -> 0 | I38: =I30+I35 -> 0 | ... N38: =N30+N35 -> 0
A40: Cash Position | B40: =B10-B38 -> 0 | C40: =C10-C38 -> 0 | D40: =D10-D38 -> 0 | E40: =E10-E38 -> 0 | F40: =F10-F38 -> 0 | G40: =G10-G38 -> 0 | H40: =H10-H38 -> 0 | I40: =I10-I38 -> 0 | ... N40: =N10-N38 -> 0
A42: *Still need to calculate principal and interest

Sheet Income Statement
B1: ABC Company
B2: Statement of Income
B3: Period of to
C4: 2001 | D4: 2002 | E4: 2003 | F4: 2004 | G4: 2005
A5: Revenues
B6: Sales-Cash
B7: Sales-Credit
B8: Less Returns and Allowances
B9: Net Sales | C9: =C6+C7-C8 -> 0 | D9: =D6+D7-D8 -> 0 | E9: =E6+E7-E8 -> 0 | F9: =F6+F7-F8 -> 0 | G9: =G6+G7-G8 -> 0
A11: Cost of Goods Sold
B12: Beginning Inventory
B13: Add: Purchases
B14: Direct Labor
B15: Outside Services
B16: Cost of Goods Available | C16: =C12+SUM(C13:C15) -> 0 | D16: =D12+SUM(D13:D15) -> 0 | E16: =E12+SUM(E13:E15) -> 0 | F16: =F12+SUM(F13:F15) -> 0 | G16: =G12+SUM(G13:G15) -> 0
B17: Less: Ending Inventory
B18: Total Cost of Goods Sold | C18: =C16-C17 -> 0 | D18: =D16-D17 -> 0 | E18: =E16-E17 -> 0 | F18: =F16-F17 -> 0 | G18: =G16-G17 -> 0
A20: Gross Profit | C20: =C9-C18 -> 0 | D20: =D9-D18 -> 0 | E20: =E9-E18 -> 0 | F20: =F9-F18 -> 0 | G20: =G9-G18 -> 0
A22: Operating Expenses
B23: Selling expenses:
B24: Advertising
B25: Commissions
B26: Total Selling Expenses | C26: =SUM(C24:C25) -> 0 | D26: =SUM(D24:D25) -> 0 | E26: =SUM(E24:E25) -> 0 | F26: =SUM(F24:F25) -> 0 | G26: =SUM(G24:G25) -> 0
B27: General and Administrative expenses:
B28: Officers' Salaries
B29: Employees' wages
B30: Supplies
B31: Repairs and Maintenance
B32: Car Delivery and Travel
B33: Accounting and Legal Fees
B34: Rent
B35: Telephone
B36: Utilities
B37: Insurance
B38: Total General and Administrative expenses | C38: =SUM(C28:C37) -> 0 | D38: =SUM(D28:D37) -> 0 | E38: =SUM(E28:E37) -> 0 | F38: =SUM(F28:F37) -> 0 | G38: =SUM(G28:G37) -> 0
B39: Total Operating Expenses | C39: =C26+C38 -> 0 | D39: =D26+D38 -> 0 | E39: =E26+E38 -> 0 | F39: =F26+F38 -> 0 | G39: =G26+G38 -> 0
B40: Operating Income | C40: =C20-C39 -> 0 | D40: =D20-D39 -> 0 | E40: =E20-E39 -> 0 | F40: =F20-F39 -> 0 | G40: =G20-G39 -> 0
A42: Other Income and Expenses
B43: Interest income
B44: Interest expense
...

Sheet Balance Sheet
A1: ABC Company
A2: Balance Sheet
A3: as of
C4: 2001 | D4: 2002 | E4: 2003 | F4: 2004 | G4: 2005
A5: Assets
A6: Current Assets:
B7: Cash and Cash equivalents
B8: Accounts receivable (less AFDA)*
B9: Inventory
B10: Prepaid expenses
A11: Total Current Assets | C11: =SUM(C7:C10) -> 0 | D11: =SUM(D7:D10) -> 0 | E11: =SUM(E7:E10) -> 0 | F11: =SUM(F7:F10) -> 0 | G11: =SUM(G7:G10) -> 0
A13: Property and Equipment:
B14: Land
A15: Capital Purchases:
B16: Buildings
B17: Equipment
B18: Less Accumulated depreciation
A19: Total Property and Equipment | C19: =SUM(C14:C17)-C18 -> 0 | D19: =SUM(D14:D17)-D18 -> 0 | E19: =SUM(E14:E17)-E18 -> 0 | F19: =SUM(F14:F17)-F18 -> 0 | G19: =SUM(G14:G17)-G18 -> 0
A21: Investments
A22: Restricted Assets
A23: Other Assets
A24: Total Assets | C24: =C11+C19+C21+C23 -> 0 | D24: =D11+D19+D21+D23 -> 0 | E24: =E11+E19+E21+E23 -> 0 | F24: =F11+F19+F21+F23 -> 0 | G24: =G11+G19+G21+G23 -> 0
A27: Liabilities and Equity
A28: Current liabilities:
B29: Accounts payable
B30: Current Portion of Long Term Debt
B31: Salary and Wages Payable
B32: Rent Payable
B33: Taxes Payable
A34: Total Current Liabilities | C34: =SUM(C29:C33) -> 0 | D34: =SUM(D29:D33) -> 0 | E34: =SUM(E29:E33) -> 0 | F34: =SUM(F29:F33) -> 0 | G34: =SUM(G29:G33) -> 0
A36: Long-term Liabilities:
B37: Long-term debt
B38: Other
A39: Total Long-term Liabilities: | C39: =C37+C38 -> 0 | D39: =D37+D38 -> 0 | E39: =E37+E38 -> 0 | F39: =F37+F38 -> 0 | G39: =G37+G38 -> 0
A41: Equity:
B42: Owner's Capital** | C42: ='Statement of Capital'!B13 -> 0 | D42: ='Statement of Capital'!C13 -> 0 | E42: ='Statement of Capital'!D13 -> 0 | F42: ='Statement of Capital'!E13 -> 0 | G42: ='Statement of Capital'!F13 -> 0
B43: Restricted Capital
A44: Total Equity | C44: =SUM(C42:C43) -> 0 | D44: =SUM(D42:D43) -> 0 | E44: =SUM(E42:E43) -> 0 | F44: =SUM(F42:F43) -> 0 | G44: =SUM(G42:G43) -> 0
A46: Total Liabilities and Equity | C46: =C34+C39+C44 -> 0 | D46: =D34+D39+D44 -> 0 | E46: =E34+E39+E44 -> 0 | F46: =F34+F39+F44 -> 0 | G46: =G34+G39+G44 -> 0
A48: * Note: | B48: AFDA stands for Allowance for Doubtful Accounts
...

Sheet Statement of Capital
A1: ABC Company
A2: Statement of Capital
A3: for the period ending
B6: 2001 | C6: 2002 | D6: 2003 | E6: 2004 | F6: 2005
A7: Beginning Capital
A9: Add: Net Income of the Current Period | B9: ='Income Statement'!C49 -> 0 | C9: ='Income Statement'!D49 -> 0 | D9: ='Income Statement'!E49 -> 0 | E9: ='Income Statement'!F49 -> 0 | F9: ='Income Statement'!G49 -> 0
A10: Add: Owner's Injections
A11: Less: Owner's Withdrawals
A13: Ending Capital | B13: =B7+B9+B10-B11 -> 0 | C13: =C7+C9+C10-C11 -> 0 | D13: =D7+D9+D10-D11 -> 0 | E13: =E7+E9+E10-E11 -> 0 | F13: =F7+F9+F10-F11 -> 0
A15: Statement of Capital is used for proprietorships and partnerships, corporations would use
A16: the Statement of Retained Earnings.

Sheet Breakeven
A1: Breakeven Analysis
A3: Breakeven Point in Units = Monthly Fixed Costs/(Selling Price - Variable Costs)
D4: 2001 | E4: 2002 | F4: 2003 | G4: 2004 | H4: 2005
A5: Monthly Fixed Costs:
B6: Rent
B7: Telephone
B8: Utilities
B9: Loan
B10: Advertising
B11: Other
A12: Total Fixed Costs | D12: =SUM(D6:D11) -> 0 | E12: =SUM(E6:E11) -> 0 | F12: =SUM(F6:F11) -> 0 | G12: =SUM(G6:G11) -> 0 | H12: =SUM(H6:H11) -> 0
B13: Selling Price
A14: Less | B14: Variable Costs:
B17: Total Variable Costs | D17: =SUM(D15:D16) -> 0 | E17: =SUM(E15:E16) -> 0 | F17: =SUM(F15:F16) -> 0 | G17: =SUM(G15:G16) -> 0 | H17: =SUM(H15:H16) -> 0
D18: =D13-D17 -> 0 | E18: =E13-E17 -> 0 | F18: =F13-F17 -> 0 | G18: =G13-G17 -> 0 | H18: =H13-H17 -> 0
A19: Breakeven Point in Units | D19: =D12/D18 -> #DIV/0! | E19: =E12/E18 -> #DIV/0! | F19: =F12/F18 -> #DIV/0! | G19: =G12/G18 -> #DIV/0! | H19: =H12/H18 -> #DIV/0!
A21: Type of Business:
A22: Manufacturing | D22: Retail | F22: Service
A23: Fixed Costs | C23: Variable Costs | D23: Fixed Costs | E23: Variable Costs | F23: Fixed Costs | G23: Variable Costs
A24: Rent | C24: Direct Materials | D24: Rent | E24: Cost of Goods Sold | F24: Rent | G24: Employees' Billable Hours
A25: Telephone | C25: Direct Labor | D25: Telephone | F25: Telephone
A26: Utilities | C26: Manufacturing Overhead | D26: Utilities | F26: Utilities
A27: Loan | D27: Loan | F27: Loan
A28: Advertising | D28: Advertising | F28: Advertising
A29: Other | D29: Other | F29: Other
A35: Target Profit = Monthly Fixed Costs + Profit / (Selling Price - Variable Costs)
D36: 2001 | E36: 2002 | F36: 2003 | G36: 2004 | H36: 2005
A37: Monthly Fixed Costs:
B38: Rent
B39: Telephone
B40: Utilities
B41: Loan
B42: Advertising
B43: Other
A44: Total Fixed Costs | D44: =SUM(D38:D43) -> 0 | E44: =SUM(E38:E43) -> 0 | F44: =SUM(F38:F43) -> 0 | G44: =SUM(G38:G43) -> 0 | H44: =SUM(H38:H43) -> 0
A45: Add | B45: Profit
A46: Total Fixed Costs and Profit | D46: =D44+D45 -> 0 | E46: =E44+E45 -> 0 | F46: =F44+F45 -> 0 | G46: =G44+G45 -> 0 | H46: =H44+H45 -> 0
B48: Selling Price
A49: Less | B49: Variable Costs:
B52: Total Variable Costs | D52: =SUM(D50:D51) -> 0 | E52: =SUM(E50:E51) -> 0 | F52: =SUM(F50:F51) -> 0 | G52: =SUM(G50:G51) -> 0 | H52: =SUM(H50:H51) -> 0
...

Sheet Acual Rate
A1: Actual Growth Rate = Current Years Sales / Prior Years Sales - 1
A3: Formula | B3: 2001 | C3: 2002 | D3: 2003 | E3: 2004 | F3: 2005
A4: Current Years Sales | B4: ='Income Statement'!C9 -> 0 | C4: ='Income Statement'!D9 -> 0 | D4: ='Income Statement'!E9 -> 0 | E4: ='Income Statement'!F9 -> 0 | F4: ='Income Statement'!G9 -> 0
A5: Prior Years Sales | C5: ='Income Statement'!C9 -> 0 | D5: ='Income Statement'!D9 -> 0 | E5: ='Income Statement'!E9 -> 0 | F5: ='Income Statement'!F9 -> 0
B6: =B4/B5 -> #DIV/0! | C6: =C4/C5 -> #DIV/0! | D6: =D4/D5 -> #DIV/0! | E6: =E4/E5 -> #DIV/0! | F6: =F4/F5 -> #DIV/0!
A7: Subtract by 1 | B7: =B6-1 -> #DIV/0! | C7: =C6-1 -> #DIV/0! | D7: =D6-1 -> #DIV/0! | E7: =E6-1 -> #DIV/0! | F7: =F6-1 -> #DIV/0!
A9: Actual Growth Rate % | B9: =B7 -> #DIV/0! | C9: =C7 -> #DIV/0! | D9: =D7 -> #DIV/0! | E9: =E7 -> #DIV/0! | F9: =F7 -> #DIV/0!
A11: Actual Growth Rate determines the rate of growth of your company
A13: To determine if your growth rate is at a favorable percentage, compare your rate with the
A14: Industry Average.
A16: To determine if your growth rate can be sustained in the future, compare with the Sustainable
A17: Growth Rate.

Sheet Calculations
A1: Calculations for Sustainable Growth Rate
A3: Formulas | C3: 2001 | D3: 2002 | E3: 2003 | F3: 2004 | G3: 2005
A4: Profit Margin
B5: Net Income | C5: ='Income Statement'!C49 -> 0 | D5: ='Income Statement'!D49 -> 0 | E5: ='Income Statement'!E49 -> 0 | F5: ='Income Statement'!F49 -> 0 | G5: ='Income Statement'!G49 -> 0
B6: Net Sales | C6: ='Income Statement'!C9 -> 0 | D6: ='Income Statement'!D9 -> 0 | E6: ='Income Statement'!E9 -> 0 | F6: ='Income Statement'!F9 -> 0 | G6: ='Income Statement'!G9 -> 0
C7: =C5/C6 -> #DIV/0! | D7: =D5/D6 -> #DIV/0! | E7: =E5/E6 -> #DIV/0! | F7: =F5/F6 -> #DIV/0! | G7: =G5/G6 -> #DIV/0!
A9: Retention rate | C9: 1 | D9: 1 | E9: 1 | F9: 1 | G9: 1
A11: Asset turnover Ratio
B12: Net Sales | C12: ='Income Statement'!C9 -> 0 | D12: ='Income Statement'!D9 -> 0 | E12: ='Income Statement'!E9 -> 0 | F12: ='Income Statement'!F9 -> 0 | G12: ='Income Statement'!G9 -> 0
B13: Average Total Assets | C13: ='Balance Sheet'!C24 -> 0 | D13: ='Balance Sheet'!D24 -> 0 | E13: ='Balance Sheet'!E24 -> 0 | F13: ='Balance Sheet'!F24 -> 0 | G13: ='Balance Sheet'!G24 -> 0
C14: =C12/C13 -> #DIV/0! | D14: =D12/D13 -> #DIV/0! | E14: =E12/E13 -> #DIV/0! | F14: =F12/F13 -> #DIV/0! | G14: =G12/G13 -> #DIV/0!
A15: Asset-to-equity ratio
B16: Total Assets | C16: ='Balance Sheet'!C24 -> 0 | D16: ='Balance Sheet'!D24 -> 0 | E16: ='Balance Sheet'!E24 -> 0 | F16: ='Balance Sheet'!F24 -> 0 | G16: ='Balance Sheet'!G24 -> 0
B17: Equity | C17: ='Balance Sheet'!C44 -> 0 | D17: ='Balance Sheet'!D44 -> 0 | E17: ='Balance Sheet'!E44 -> 0 | F17: ='Balance Sheet'!F44 -> 0 | G17: ='Balance Sheet'!G44 -> 0
C18: =C16/C17 -> #DIV/0! | D18: =D16/D17 -> #DIV/0! | E18: =E16/E17 -> #DIV/0! | F18: =F16/F17 -> #DIV/0! | G18: =G16/G17 -> #DIV/0!
A20: Sustainable Growth Rate determines your company's growth rate potential.
A22: This growth rate can be compared with your Acutal Growth Rate to determine if your
A23: company is achieving its growth rate potential.

Sheet Sustainable Rate
A1: Sustainable Growth Rate = (Retention rate x Asset to equity ratio) x (Profit margin x Asset Turnover Ratio)
A3: Formula | B3: 2001 | C3: 2002 | D3: 2003 | E3: 2004 | F3: 2005
A4: Retention rate* | B4: =Calculations!C9 -> 1 | C4: 1 | D4: 1 | E4: 1 | F4: =Calculations!G9 -> 1
A5: Asset to equity Ratio | B5: =Calculations!C18 -> #DIV/0! | C5: =Calculations!D18 -> #DIV/0! | D5: =Calculations!E18 -> #DIV/0! | E5: =Calculations!F18 -> #DIV/0! | F5: =Calculations!G18 -> #DIV/0!
B6: =B4*B5 -> #DIV/0! | C6: =C4*C5 -> #DIV/0! | D6: =D4*D5 -> #DIV/0! | E6: =E4*E5 -> #DIV/0! | F6: =F4*F5 -> #DIV/0!
A8: Profit Margin | B8: =Calculations!C7 -> #DIV/0! | C8: =Calculations!D7 -> #DIV/0! | D8: =Calculations!E7 -> #DIV/0! | E8: =Calculations!F7 -> #DIV/0! | F8: =Calculations!G7 -> #DIV/0!
A9: Asset Turnover Ratio | B9: =Calculations!C14 -> #DIV/0! | C9: =Calculations!D14 -> #DIV/0! | D9: =Calculations!E14 -> #DIV/0! | E9: =Calculations!F14 -> #DIV/0! | F9: =Calculations!G14 -> #DIV/0!
B10: =B8*B9 -> #DIV/0! | C10: =C8*C9 -> #DIV/0! | D10: =D8*D9 -> #DIV/0! | E10: =E8*E9 -> #DIV/0! | F10: =F8*F9 -> #DIV/0!
A12: Sustainable Growth Rate | B12: =B6*B10 -> #DIV/0! | C12: =C6*C10 -> #DIV/0! | D12: =D6*D10 -> #DIV/0! | E12: =E6*E10 -> #DIV/0! | F12: =F6*F10 -> #DIV/0!
B13: =B12 -> #DIV/0! | C13: =C12 -> #DIV/0! | D13: =D12 -> #DIV/0! | E13: =E12 -> #DIV/0! | F13: =F12 -> #DIV/0!
A15: Retention rate = 100% with the expectation that 100% of the beginning retained earnings will be retained
A16: and carried over to the following year.
A17: Retention rate, profit margin, and sustainable growth rate values are in decimal form where (1.00 = 100%)

Sheet AR vs SR
A1: Comparison of Actual Growth Rate and Sustainable Growth Rate
B3: 2001 | C3: 2002 | D3: 2003 | E3: 2004 | F3: 2005
A4: Actual Growth Rate | B4: ='Acual Rate'!B9 -> #DIV/0! | C4: ='Acual Rate'!C9 -> #DIV/0! | D4: ='Acual Rate'!D9 -> #DIV/0! | E4: ='Acual Rate'!E9 -> #DIV/0! | F4: ='Acual Rate'!F9 -> #DIV/0!
A5: Sustainable Growth Rate | B5: ='Sustainable Rate'!B13 -> #DIV/0! | C5: ='Sustainable Rate'!C13 -> #DIV/0! | D5: ='Sustainable Rate'!D13 -> #DIV/0! | E5: ='Sustainable Rate'!E13 -> #DIV/0! | F5: ='Sustainable Rate'!F13 -> #DIV/0!
A7: In comparing the Actual Growth Rate to the Sustainable Growth Rate you can determine how your company
A8: is growing in comparision with the rate of how it should be growing
A11: If your Actual Growth Rate is higher than your Sustainable Growth Rate, then your company could grow
A12: at a faster rate then it is currently.
A14: If your Actual Growth Rate is lower than your Sustainable Growth Rate, then your company is growing at a faster rate
A15: than it should be. This might be an indicator that you could run out of money if your company continues to grow too fast.
