Workbook

Sheet September
G1: Appendix 4.1
A3: Medical Staff as @ 30th September 2002 (Month 6) - West Division
C5: Budget | D5: Budget to date | E5: Spend | F5: Spend | G5: %
C6: WTE | D6: £ | F6: Variance | G6: Variance
B8: Consultants - Permanent | C8: 37 | D8: =1616750+8287+2081+365+6465+61681+20103+14219+12587 -> 1742538 | E8: 1437812 | F8: =D8-E8 -> 304726
B9: Consultants - Locum vacancies | C9: 0 | D9: 0 | E9: =8285+89681+60114+6619+97727-2200+9160+15362+78540+4243 -> 367531 | F9: =D9-E9 -> -367531
B10: Sub total Consultants | D10: =SUM(D8:D9) -> 1742538 | E10: =SUM(E8:E9) -> 1805343 | F10: =D8-E10 -> -62805 | G10: =F10/D8 -> -0.036042256
B12: Registrars / Staff Grades - Permanent | C12: =7+5.5 -> 12.5 | D12: =301305+25119 -> 326424 | E12: 152297 | F12: =D12-E12 -> 174127
B13: Registrars / Staff Grades - Locum vacancies | C13: 0 | D13: 0 | E13: =21119+63241-3835+39912+2734+38841+9622+64315+4043+48681+49418+19777+58274 -> 416142 | F13: =D13-E13 -> -416142
B14: Sub total Registrars / Staff Grades | D14: =SUM(D12:D13) -> 326424 | E14: =SUM(E12:E13) -> 568439 | F14: =D12-E14 -> -242015 | G14: =F14/D12 -> -0.74141301
B16: SHO''s - Permanent | C16: 27.24 | D16: =685122+23678+58764+3407+8517 -> 779488 | E16: 432608 | F16: =D16-E16 -> 346880
B17: SHO''s - Locum vacancies | C17: 0 | D17: 0 | E17: =271+271+36054+1146+30499+116956+45780+11885+50913+1864+40829+5000+30493 -> 371961 | F17: =D17-E17 -> -371961
B18: Sub total SHO's | D18: =SUM(D16:D17) -> 779488 | E18: =SUM(E16:E17) -> 804569 | F18: =D16-E18 -> -25081 | G18: =F18/D16 -> -0.032176249
B20: Associate Specialists - Permanent | C20: 2.9 | D20: =79059+1723+20515 -> 101297 | E20: 40331 | F20: =D20-E20 -> 60966
B21: Associate Specialists - Locum vacancies | C21: 0 | D21: 0 | E21: =83844 -> 83844 | F21: =D21-E21 -> -83844
B22: Sub total Associate Specialists | D22: =SUM(D20:D21) -> 101297 | E22: =SUM(E20:E21) -> 124175 | F22: =D20-E22 -> -22878 | G22: =F22/D20 -> -0.22585072
B24: Clinical Assistants - Permanent | C24: 2.71 | D24: =49707+18665 -> 68372 | E24: 8156 | F24: =D24-E24 -> 60216
B25: Clinical Assistants - Locum vacancies | C25: 0 | D25: 0 | E25: =4542+15570+18555+11465 -> 50132 | F25: =D25-E25 -> -50132
B26: Sub total Clinical Assistants | D26: =SUM(D24:D25) -> 68372 | E26: =SUM(E24:E25) -> 58288 | F26: =D24-E26 -> 10084 | G26: =F26/D24 -> 0.14748728
B28: Grand Total | C28: =SUM(C7:C27) -> 82.35 | D28: =SUM(D7:D27)/2 -> 3018119 | E28: =E10+E14+E18+E22+E26 -> 3360814 | F28: =F10+F14+F18+F22+F26 -> -342695 | G28: =F28/D28 -> -0.11354589

Sheet October
G1: Appendix 4.1
A3: Medical Staff as @ 31st October 2002 (Month 7) - West Division
C5: Budget | D5: Budget to date | E5: Spend | F5: Spend | G5: %
C6: WTE | D6: £ | F6: Variance | G6: Variance
I7: 1544536 | J7: 335255
B8: Consultants - Permanent | C8: 37 | D8: =1903728+11049+2428+426+7543+71961+23454+16588+14685 -> 2051862 | E8: 1669516 | F8: =D8-E8 -> 382346 | I8: 1669516 | J8: 1903728
B9: Consultants - Locum vacancies | C9: 0 | D9: 0 | E9: =14500+98569+71814+7722+113504-2200+9856+36091+84612+4243 -> 438711 | F9: =D9-E9 -> -438711
B10: Sub total Consultants | D10: =SUM(D8:D9) -> 2051862 | E10: =SUM(E8:E9) -> 2108227 | F10: =D8-E10 -> -56365 | G10: =F10/D8 -> -0.027470171
B12: Registrars / Staff Grades - Permanent | C12: =7+5.5 -> 12.5 | D12: =351529+29306 -> 380835 | E12: 183554 | F12: =D12-E12 -> 197281 | I12: 183554 | J12: 351529
B13: Registrars / Staff Grades - Locum vacancies | C13: 0 | D13: 0 | E13: =21119+79712-3835+46447+2734+68278+11846+79680+17504+4043+56409+58264+36379+69494 -> 548074 | F13: =D13-E13 -> -548074
B14: Sub total Registrars / Staff Grades | D14: =SUM(D12:D13) -> 380835 | E14: =SUM(E12:E13) -> 731628 | F14: =D12-E14 -> -350793 | G14: =F14/D12 -> -0.92111544
B16: SHO''s - Permanent | C16: 27.24 | D16: =799305+27625+68559+3975+9937 -> 909401 | E16: 506395 | F16: =D16-E16 -> 403006 | I16: 506395 | J16: 799305
B17: SHO''s - Locum vacancies | C17: 0 | D17: 0 | E17: =2229+1007+38708+4717+30499+127206+48381+8775+40939+1864+40829+266+5534+1790+33603 -> 386347 | F17: =D17-E17 -> -386347
B18: Sub total SHO's | D18: =SUM(D16:D17) -> 909401 | E18: =SUM(E16:E17) -> 892742 | F18: =D16-E18 -> 16659 | G18: =F18/D16 -> 0.018318652
B20: Associate Specialists - Permanent | C20: 2.9 | D20: =92236+2010+23934 -> 118180 | E20: 47390 | F20: =D20-E20 -> 70790
B21: Associate Specialists - Locum vacancies | C21: 0 | D21: 0 | E21: =110805 -> 110805 | F21: =D21-E21 -> -110805 | I21: 47390 | J21: 92236
B22: Sub total Associate Specialists | D22: =SUM(D20:D21) -> 118180 | E22: =SUM(E20:E21) -> 158195 | F22: =D20-E22 -> -40015 | G22: =F22/D20 -> -0.33859367
B24: Clinical Assistants - Permanent | C24: 2.71 | D24: =57992+21775 -> 79767 | E24: 9087 | F24: =D24-E24 -> 70680 | I24: 9087 | J24: 57992
B25: Clinical Assistants - Locum vacancies | C25: 0 | D25: 0 | E25: =5229+18172+23968+13229 -> 60598 | F25: =D25-E25 -> -60598
B26: Sub total Clinical Assistants | D26: =SUM(D24:D25) -> 79767 | E26: =SUM(E24:E25) -> 69685 | F26: =D24-E26 -> 10082 | G26: =F26/D24 -> 0.12639312
B28: Grand Total | C28: =SUM(C7:C27) -> 82.35 | D28: =SUM(D7:D27)/2 -> 3540045 | E28: =E10+E14+E18+E22+E26 -> 3960477 | F28: =F10+F14+F18+F22+F26 -> -420432 | G28: =F28/D28 -> -0.11876459 | I28: =SUM(I7:I27) -> 3960478 | J28: =SUM(J7:J27) -> 3540045
I29: =SUM(I28-E28) -> 1

Sheet November
I1: Appendix 4.1
A3: Medical Staff as @ 30th November 2002 (Month 8) - West Division
C5: Budget | D5: Budget to November | E5: Spend to November | F5: Variance to Nov (M 8) | G5: % Variance | H5: Variance as @ Oct (M 7) | I5: Monthly Movement
C6: WTE | D6: £ | E6: £ | F6: under / (over) £ | H6: under / (over) £ | I6: under / (over) £
B9: Consultants - Permanent | C9: 37 | D9: 2214161 | E9: 1955381 | F9: =D9-E9 -> 258780
B10: Consultants - Locum vacancies | C10: 0 | D10: 156670 | E10: 486764 | F10: =D10-E10 -> -330094
B11: Sub total Consultants | D11: =SUM(D9:D10) -> 2370831 | E11: =SUM(E9:E10) -> 2442145 | F11: =D11-E11 -> -71314 | G11: =F11/D9 -> -0.032208137 | H11: -56365 | I11: =F11-H11 -> -14949
B13: Registrars / Staff Grades - Permanent | C13: =7+5.5 -> 12.5 | D13: =243846+157896 -> 401742 | E13: =114715+94602 -> 209317 | F13: =D13-E13 -> 192425
B14: Registrars / Staff Grades - Locum vacancies | C14: 0 | D14: 33492 | E14: =417152-1101+137664+89975 -> 643690 | F14: =D14-E14 -> -610198
B15: Sub total Registrars / Staff Grades | D15: =SUM(D13:D14) -> 435234 | E15: =SUM(E13:E14) -> 853007 | F15: =D15-E15 -> -417773 | G15: =F15/D13 -> -1.0399037 | H15: -350793 | I15: =F15-H15 -> -66980
B17: SHO''s - Permanent | C17: 27.24 | D17: =913495 -> 913495 | E17: 574430 | F17: =D17-E17 -> 339065
B18: SHO''s - Locum vacancies | C18: 0 | D18: 125824 | E18: 433122 | F18: =D18-E18 -> -307298
B19: Sub total SHO's | D19: =SUM(D17:D18) -> 1039319 | E19: =SUM(E17:E18) -> 1007552 | F19: =D19-E19 -> 31767 | G19: =F19/D17 -> 0.034775231 | H19: 16659 | I19: =F19-H19 -> 15108
B21: Associate Specialists - Permanent | C21: 2.9 | D21: 105412 | E21: 54448 | F21: =D21-E21 -> 50964
B22: Associate Specialists - Locum vacancies | C22: 0 | D22: 29650 | E22: 127719 | F22: =D22-E22 -> -98069
B23: Sub total Associate Specialists | D23: =SUM(D21:D22) -> 135062 | E23: =SUM(E21:E22) -> 182167 | F23: =D23-E23 -> -47105 | G23: =F23/D21 -> -0.44686563 | H23: -40015 | I23: =F23-H23 -> -7090
B25: Clinical Assistants - Permanent | C25: 2.71 | D25: =60335+3 -> 60338 | E25: 10019 | F25: =D25-E25 -> 50319
B26: Clinical Assistants - Locum vacancies | C26: 0 | D26: =24886 -> 24886 | E26: =59735+5916 -> 65651 | F26: =D26-E26 -> -40765
B27: Sub total Clinical Assistants | D27: =SUM(D25:D26) -> 85224 | E27: =SUM(E25:E26) -> 75670 | F27: =D27-E27 -> 9554 | G27: =F27/D25 -> 0.15834134 | H27: 10082 | I27: =F27-H27 -> -528
B29: Grand Total | C29: =SUM(C8:C28) -> 82.35 | D29: =SUM(D8:D28)/2 -> 4065670 | E29: =E11+E15+E19+E23+E27 -> 4560541 | F29: =F11+F15+F19+F23+F27 -> -494871 | G29: =F29/D29 -> -0.12171942 | H29: =H11+H15+H19+H23+H27 -> -420432 | I29: =I11+I15+I19+I23+I27 -> -74439

Sheet December
I1: Appendix 4.1
A3: Medical Staff as @ 31 December 2002 (Month 9) - West Division
C5: Budget | D5: Budget to December | E5: Spend to December | F5: Variance to Dec (M 9) | G5: % Variance | H5: Variance as @ Dec (M 9) | I5: Monthly Movement
C6: WTE | D6: £ | E6: £ | F6: under / (over) £ | H6: under / (over) £ | I6: under / (over) £
B9: Consultants - Permanent | C9: 37 | D9: =2479033+16573+3122+548+9698+92521+30155+21328+18881 -> 2671859 | E9: 2193280 | F9: =D9-E9 -> 478579
B10: Consultants - Locum vacancies | C10: 0 | D10: 0 | E10: =18540+111761+5593+95472+9928+145057-2200+9856+34122+25011+86988+3770+5859 -> 549757 | F10: =D10-E10 -> -549757
B11: Sub total Consultants | D11: =SUM(D9:D10) -> 2671859 | E11: =SUM(E9:E10) -> 2743037 | F11: =D11-E11 -> -71178 | G11: =F11/D9 -> -0.026639879 | H11: -71314 | I11: =F11-H11 -> 136
B13: Registrars / Staff Grades - Permanent | C13: =7+5.5 -> 12.5 | D13: =274326+177637+37679 -> 489642 | E13: =139100+117616 -> 256716 | F13: =D13-E13 -> 232926
B14: Registrars / Staff Grades - Locum vacancies | C14: 0 | D14: 0 | E14: =21119+107270-3835+65007+2734+135281+24788+101254+38406+4083+66817+56627+54509+83237+1732-25000 -> 734029 | F14: =D14-E14 -> -734029
B15: Sub total Registrars / Staff Grades | D15: =SUM(D13:D14) -> 489642 | E15: =SUM(E13:E14) -> 990745 | F15: =D15-E15 -> -501103 | G15: =F15/D13 -> -1.0234069 | H15: -417773 | I15: =F15-H15 -> -83330
B17: SHO''s - Permanent | C17: 27.24 | D17: =1027678+35518+88147+5110+12776 -> 1169229 | E17: 648500 | F17: =D17-E17 -> 520729
B18: SHO''s - Locum vacancies | C18: 0 | D18: 0 | E18: =2557+2937+39319+5150+30499+147674+56670+20012+42586+1864+40829+3714+14830+2540+36106+25000 -> 472287 | F18: =D18-E18 -> -472287
B19: Sub total SHO's | D19: =SUM(D17:D18) -> 1169229 | E19: =SUM(E17:E18) -> 1120787 | F19: =D19-E19 -> 48442 | G19: =F19/D17 -> 0.041430721 | H19: 31767 | I19: =F19-H19 -> 16675
B21: Associate Specialists - Permanent | C21: 2.9 | D21: =118590+2584+30772 -> 151946 | E21: 61507 | F21: =D21-E21 -> 90439
B22: Associate Specialists - Locum vacancies | C22: 0 | D22: 0 | E22: =145774 -> 145774 | F22: =D22-E22 -> -145774
B23: Sub total Associate Specialists | D23: =SUM(D21:D22) -> 151946 | E23: =SUM(E21:E22) -> 207281 | F23: =D23-E23 -> -55335 | G23: =F23/D21 -> -0.36417543 | H23: -47105 | I23: =F23-H23 -> -8230
B25: Clinical Assistants - Permanent | C25: 2.71 | D25: =67877+27997 -> 95874 | E25: 10951 | F25: =D25-E25 -> 84923
B26: Clinical Assistants - Locum vacancies | C26: 0 | D26: 0 | E26: =6774+23968+23376+17198 -> 71316 | F26: =D26-E26 -> -71316
B27: Sub total Clinical Assistants | D27: =SUM(D25:D26) -> 95874 | E27: =SUM(E25:E26) -> 82267 | F27: =D27-E27 -> 13607 | G27: =F27/D25 -> 0.14192586 | H27: 9554 | I27: =F27-H27 -> 4053
B29: Grand Total | C29: =SUM(C8:C28) -> 82.35 | D29: =SUM(D8:D28)/2 -> 4578550 | E29: =E11+E15+E19+E23+E27 -> 5144117 | F29: =F11+F15+F19+F23+F27 -> -565567 | G29: =F29/D29 -> -0.12352535 | H29: =H11+H15+H19+H23+H27 -> -494871 | I29: =I11+I15+I19+I23+I27 -> -70696

Sheet January
J1: Appendix 4.1
A3: Medical Staff as @ 31 January 2003 (Month 10) - West Division
C5: Budget | D5: Budget to January | E5: Spend to January | F5: Variance to Jan (M 10) | G5: % Variance | I5: Variance as @ Dec (M 9) | J5: Monthly Movement
C6: WTE | D6: £ | E6: £ | F6: under / (over) £ | I6: under / (over) £ | J6: under / (over) £
B9: Consultants - Permanent | C9: 37 | D9: =2757728+19336+3469+608+10776+102801+33506+23698+20979 -> 2972901 | E9: =2443232 -> 2443232 | F9: =D9-E9 -> 529669
B10: Consultants - Locum vacancies | C10: 0 | D10: 0 | E10: =21958+119160+11186+107122+11031+169599-2200+9856+34122+25171+91884+3770+4243 -> 606902 | F10: =D10-E10 -> -606902
B11: Sub total Consultants | D11: =SUM(D9:D10) -> 2972901 | E11: =SUM(E9:E10) -> 3050134 | F11: =D11-E11 -> -77233 | G11: =F11/D9 -> -0.025979002 | I11: -71178 | J11: =F11-I11 -> -6055
B13: Registrars / Staff Grades - Permanent | C13: =7+5.5 -> 12.5 | D13: =304807+197376+41865 -> 544048 | E13: =157496+133464 -> 290960 | F13: =D13-E13 -> 253088
B14: Registrars / Staff Grades - Locum vacancies | C14: 0 | D14: 0 | E14: =21119+117175+73447+2734+195640+24535+112534+34840+4083+74265+56627+61071+88237 -> 866307 | F14: =D14-E14 -> -866307
B15: Sub total Registrars / Staff Grades | D15: =SUM(D13:D14) -> 544048 | E15: =SUM(E13:E14) -> 1157267 | F15: =D15-E15 -> -613219 | G15: =F15/D13 -> -1.1271414 | I15: -501103 | J15: =F15-I15 -> -112116
B17: SHO''s - Permanent | C17: 27.24 | D17: =1141869+39464+97941+5678+14196 -> 1299148 | E17: 727782 | F17: =D17-E17 -> 571366
B18: SHO''s - Locum vacancies | C18: 0 | D18: 0 | E18: =2557+2937+39319+7061+30499+145167+59383+20012+48986+1864+40829+3714+19737+2540+36106 -> 460711 | F18: =D18-E18 -> -460711
B19: Sub total SHO's | D19: =SUM(D17:D18) -> 1299148 | E19: =SUM(E17:E18) -> 1188493 | F19: =D19-E19 -> 110655 | G19: =F19/D17 -> 0.085175053 | I19: 48442 | J19: =F19-I19 -> 62213
B21: Associate Specialists - Permanent | C21: 2.9 | D21: =131765+2872+34192 -> 168829 | E21: =68565 -> 68565 | F21: =D21-E21 -> 100264
B22: Associate Specialists - Locum vacancies | C22: 0 | D22: 0 | E22: =162620 -> 162620 | F22: =D22-E22 -> -162620
B23: Sub total Associate Specialists | D23: =SUM(D21:D22) -> 168829 | E23: =SUM(E21:E22) -> 231185 | F23: =D23-E23 -> -62356 | G23: =F23/D21 -> -0.36934413 | I23: -55335 | J23: =F23-I23 -> -7021
B25: Clinical Assistants - Permanent | C25: 2.71 | D25: =75418+31108 -> 106526 | E25: =11882 -> 11882 | F25: =D25-E25 -> 94644
B26: Clinical Assistants - Locum vacancies | C26: 0 | D26: 0 | E26: =25978+23968+26422 -> 76368 | F26: =D26-E26 -> -76368
B27: Sub total Clinical Assistants | D27: =SUM(D25:D26) -> 106526 | E27: =SUM(E25:E26) -> 88250 | F27: =D27-E27 -> 18276 | G27: =F27/D25 -> 0.17156375 | I27: 13607 | J27: =F27-I27 -> 4669
B29: Grand Total | C29: =SUM(C8:C28) -> 82.35 | D29: =SUM(D8:D28)/2 -> 5091452 | E29: =E11+E15+E19+E23+E27 -> 5715329 | F29: =F11+F15+F19+F23+F27 -> -623877 | G29: =F29/D29 -> -0.1225342 | I29: =I11+I15+I19+I23+I27 -> -565567 | J29: =J11+J15+J19+J23+J27 -> -58310

Sheet Nov
O1: Appendix 3.1
A3: Medical Staff as @ 30 November 2003 (Month 8) - Operations Division (JH)
C5: Budget | D5: Actual | F5: Budget to November | G5: Spend to November | H5: Variance to November (M8) | I5: % Variance | L5: 2003/04 forecast outturn | N5: 2004/05 forecast outturn Worst case | P5: Variance
C6: WTE | D6: WTE | F6: £ | G6: £ | H6: under / (over) £
B9: Consultants - Permanent | C9: =Sheet1!H20 -> 34.75 | D9: =Sheet1!I20 -> 32.01 | F9: =Sheet1!E20 -> 2274328 | G9: =Sheet1!F20 -> 2146285 | H9: =F9-G9 -> 128043 | K9: =G9/8*12 -> 3219427.5 | L9: ='TOTAL (2)'!K58 -> 2989845.5 | N9: ='TOTAL (2)'!M58 -> 3248322.5 | P9: =L9-N9 -> -258477
B10: Consultants - Locum vacancies | C10: =Sheet1!H79 -> 1.73 | D10: =Sheet1!I79 -> 1.73 | F10: =Sheet1!E79 -> 306901 | G10: =Sheet1!F79 -> 720854 | H10: =F10-G10 -> -413953 | K10: =G10/8*12 -> 1081281 | L10: ='TOTAL (2)'!K75 -> 1168132.4 | N10: ='TOTAL (2)'!M75 -> 1230432.4 | P10: =L10-N10 -> -62300
B11: Sub total Consultants | C11: =SUM(C9:C10) -> 36.48 | D11: =SUM(D9:D10) -> 33.74 | F11: =SUM(F9:F10) -> 2581229 | G11: =SUM(G9:G10) -> 2867139 | H11: =F11-G11 -> -285910 | I11: =H11/F9 -> -0.12571186 | K11: =SUM(K9:K10) -> 4300708.5 | L11: =SUM(L9:L10) -> 4157977.9 | N11: =SUM(N9:N10) -> 4478754.9 | P11: =SUM(P9:P10) -> -320777 | Q11: Note 1
B13: Registrars / Staff Grades - Permanent | C13: =Sheet1!H18 -> 13.5 | D13: =Sheet1!I18 -> 12.22 | F13: =Sheet1!E18 -> 668433 | G13: =Sheet1!F18 -> 374507 | H13: =F13-G13 -> 293926 | K13: =G13/8*12 -> 561760.5 | L13: ='TOTAL (2)'!K118 -> 843241 | N13: ='TOTAL (2)'!M118 -> 843241 | P13: =L13-N13 -> 0
B14: Registrars / Staff Grades - Locum vacancies | C14: 0 | D14: 1 | F14: =Sheet1!E97+Sheet1!E110+Sheet1!E114 -> 258602 | G14: =Sheet1!F97+Sheet1!F110+Sheet1!F114 -> 1015241 | H14: =F14-G14 -> -756639 | K14: =G14/8*12 -> 1522861.5 | L14: ='TOTAL (2)'!K131 -> 1161821 | N14: ='TOTAL (2)'!M131 -> 1220496 | P14: =L14-N14 -> -58675
B15: Sub total Registrars / Staff Grades | C15: =SUM(C13:C14) -> 13.5 | D15: =SUM(D13:D14) -> 13.22 | F15: =SUM(F13:F14) -> 927035 | G15: =SUM(G13:G14) -> 1389748 | H15: =F15-G15 -> -462713 | I15: =H15/F13 -> -0.69223542 | K15: =SUM(K13:K14) -> 2084622 | L15: =SUM(L13:L14) -> 2005062 | N15: =SUM(N13:N14) -> 2063737 | P15: =SUM(P13:P14) -> -58675 | Q15: Note 2
B17: SHO''s - Permanent | C17: =Sheet1!H19 -> 22 | D17: =Sheet1!I19 -> 18.8 | F17: =Sheet1!E19 -> 851385 | G17: =Sheet1!F19 -> 798604 | H17: =F17-G17 -> 52781 | K17: =G17/8*12 -> 1197906 | L17: ='TOTAL (2)'!K98 -> 977210 | N17: ='TOTAL (2)'!M98 -> 985123 | P17: =L17-N17 -> -7913
B18: SHO''s - Locum vacancies | C18: 0 | D18: 0 | F18: =Sheet1!E56+Sheet1!E124 -> 63777 | G18: =Sheet1!F56+Sheet1!F124 -> 210168 | H18: =F18-G18 -> -146391 | K18: =G18/8*12 -> 315252 | L18: ='TOTAL (2)'!K105 -> 547311 | N18: ='TOTAL (2)'!M105 -> 486587 | P18: =L18-N18 -> 60724
B19: Sub total SHO's | C19: =SUM(C17:C18) -> 22 | D19: =SUM(D17:D18) -> 18.8 | F19: =SUM(F17:F18) -> 915162 | G19: =SUM(G17:G18) -> 1008772 | H19: =F19-G19 -> -93610 | I19: =H19/F17 -> -0.10995026 | K19: =SUM(K17:K18) -> 1513158 | L19: =SUM(L17:L18) -> 1524521 | N19: =SUM(N17:N18) -> 1471710 | P19: =SUM(P17:P18) -> 52811 | Q19: Note 3
B21: Associate Specialists - Permanent | C21: =Sheet1!H22 -> 2.27 | D21: =Sheet1!I22 -> 0.27 | F21: =Sheet1!E22 -> 109870 | G21: =Sheet1!F22 -> 11903 | H21: =F21-G21 -> 97967 | K21: =G21/8*12 -> 17854.5 | L21: ='TOTAL (2)'!K7 -> 164393 | N21: ='TOTAL (2)'!M7 -> 97478.824 | P21: =L21-N21 -> 66914.176
B22: Associate Specialists - Locum vacancies | C22: =Sheet1!H103 -> 0.63 | D22: =Sheet1!I103 -> 0 | F22: =Sheet1!E103 -> 152324 | G22: =Sheet1!F103 -> 130172 | H22: =F22-G22 -> 22152 | K22: =G22/8*12 -> 195258 | L22: ='TOTAL (2)'!K9 -> 160597 | N22: ='TOTAL (2)'!M9 -> 160597 | P22: =L22-N22 -> 0
B23: Sub total Associate Specialists | C23: =SUM(C21:C22) -> 2.9 | D23: =SUM(D21:D22) -> 0.27 | F23: =SUM(F21:F22) -> 262194 | G23: =SUM(G21:G22) -> 142075 | H23: =F23-G23 -> 120119 | I23: =H23/F21 -> 1.093283 | K23: =SUM(K21:K22) -> 213112.5 | L23: =SUM(L21:L22) -> 324990 | N23: =SUM(N21:N22) -> 258075.82 | P23: =SUM(P21:P22) -> 66914.176 | Q23: Note4
B25: Clinical Assistants - Permanent | C25: =Sheet1!H21 -> 1.17 | D25: =Sheet1!I21 -> 0.18 | F25: =Sheet1!E21 -> 36720 | G25: =Sheet1!F21 -> 7695 | H25: =F25-G25 -> 29025 | K25: =G25/8*12 -> 11542.5 | L25: ='TOTAL (2)'!K12 -> 74107 | N25: ='TOTAL (2)'!M12 -> 74107 | P25: =L25-N25 -> 0
B26: Clinical Assistants - Locum vacancies | C26: 0 | D26: 1 | F26: =Sheet1!E38 -> 48585 | G26: =Sheet1!F38 -> 72974 | H26: =F26-G26 -> -24389 | K26: =G26/8*12 -> 109461 | L26: ='TOTAL (2)'!K16 -> 100013 | N26: ='TOTAL (2)'!M16 -> 100013 | P26: =L26-N26 -> 0
B27: Sub total Clinical Assistants | C27: =SUM(C25:C26) -> 1.17 | D27: =SUM(D25:D26) -> 1.18 | F27: =SUM(F25:F26) -> 85305 | G27: =SUM(G25:G26) -> 80669 | H27: =F27-G27 -> 4636 | I27: =H27/F25 -> 0.12625272 | K27: =SUM(K25:K26) -> 121003.5 | L27: =SUM(L25:L26) -> 174120 | N27: =SUM(N25:N26) -> 174120 | P27: =SUM(P25:P26) -> 0
B29: Grand Total | C29: =C27+C23+C19+C15+C11 -> 76.05 | D29: =D27+D23+D19+D15+D11 -> 67.21 | F29: =F27+F23+F19+F15+F11 -> 4770925 | G29: =G11+G15+G19+G23+G27 -> 5488403 | H29: =H11+H15+H19+H23+H27 -> -717478 | I29: =H29/F29 -> -0.15038551 | K29: =K11+K15+K19+K23+K27 -> 8232604.5 | L29: =L11+L15+L19+L23+L27 -> 8186670.9 | N29: =N11+N15+N19+N23+N27 -> 8446397.8 | P29: =P11+P15+P19+P23+P27 -> -259726.82
B31: Budget 2003/04 | K31: =1183291+5922356 -> 7105647 | L31: =1183291+5922356 -> 7105647 | N31: =1183291+5922356 -> 7105647
K33: =K31-K29 -> -1126957.5 | L33: =L31-L29 -> -1081023.9 | N33: =N31-N29 -> -1340750.8
B35: Note 1
B36: Variance is due to JH committing to 2 consultants to be recruited by December 04
B37: An addittional .8 of a consultant needs to be included in East Camhs to bring up consultants to 2 in each borough
B39: Note 2
B40: Variance due to JH committing to two post being recruited by July 04 and thus locum budget need to be re allocated to fill substantive posts
B42: Note 3
B44: SHO in CAMHS has been filled substantively and has reduced the outturn, but this is also based on JH Scenario 1
B46: Note 4
B48: Based on JH paper that all Associate Specialist Vacancy are at locum rate.
B49: Reduction in next forecast due a post been filled this year.
B51: Note 5
B53: No change
... B57: Next year figure exclude Parential leave for Medical and therefore need to be include with High level of assumption

Sheet TOTAL (2)
B1: MEDICAL STAFFING
A3: des | B3: POST | C3: NAME | D3: GRADE | E3: START DATE | F3: COMMENT | G3: ACTIVITY | H3: BUDGET | I3: YTD MTH 7 | J3: MTH 8-12 | K3: ACTUAL | L3: OUTTURN VARIANCE | M3: 04/05 out turn worst case
A4: as | B4: ASS SPEC | H4: 79048 | I4: 11869 | K4: =J4+I4 -> 11869 | L4: =H4-K4 -> 67179 | M4: 0
A5: as | B5: Assoc Spec (0.27 wte) | C5: Dr Thomas | D5: Staff Grade (0.2 wte) | E5: Ongoing | F5: Need to check post and sessions | H5: 18641 | I5: 10415 | J5: =1488*5 -> 7440 | K5: =J5+I5 -> 17855 | L5: =H5-K5 -> 786 | M5: =K5*1.03225 -> 18430.824
A6: as | B6: Assoc Spec | C6: Dr Umaipalan | D6: Substantive to commence 1st January | F6: Presently covered by Locum Staff Grade | H6: 67115 | I6: 81459 | J6: =10642*5 -> 53210 | K6: =J6+I6 -> 134669 | L6: =H6-K6 -> -67554 | M6: =79048 -> 79048
A7: as Total | H7: =SUBTOTAL(9,H4:H6) -> 164804 | I7: =SUBTOTAL(9,I4:I6) -> 103743 | J7: =SUBTOTAL(9,J4:J6) -> 60650 | K7: =SUBTOTAL(9,K4:K6) -> 164393 | L7: =SUBTOTAL(9,L4:L6) -> 411 | M7: =SUBTOTAL(9,M4:M6) -> 97478.824
A8: asl | B8: Assoc. Spec (0.63 wte) | C8: Dr Pietromartire | D8: Locum Ass. Spec | E8: ongoing | F8: Ass specialist JD sent to Region | H8: 228485 | I8: =99817+4700 -> 104517 | J8: =11216*5 -> 56080 | K8: =J8+I8 -> 160597 | L8: =H8-K8 -> 67888 | M8: =K8 -> 160597
A9: asl Total | H9: =SUBTOTAL(9,H8:H8) -> 228485 | I9: =SUBTOTAL(9,I8:I8) -> 104517 | J9: =SUBTOTAL(9,J8:J8) -> 56080 | K9: =SUBTOTAL(9,K8:K8) -> 160597 | L9: =SUBTOTAL(9,L8:L8) -> 67888 | M9: =SUBTOTAL(9,M8:M8) -> 160597
A10: clin | B10: Clin Ass. (0.63 wte) | C10: Dr Kanagasandra | D10: Substantive 0.2 wte | E10: NA | F10: NA | H10: 33366 | I10: 18922 | J10: =2547*52/12*5 -> 55185 | K10: =J10+I10 -> 74107 | L10: =H10-K10 -> -40741 | M10: =K10 -> 74107
A11: clin | B11: Clin Ass. (0.63 wte) | C11: Dr Mathukia | D11: Substantive 0.2 wte | L11: =H11-K11 -> 0 | M11: 0
A12: clin Total | H12: =SUBTOTAL(9,H10:H11) -> 33366 | I12: =SUBTOTAL(9,I10:I11) -> 18922 | J12: =SUBTOTAL(9,J10:J11) -> 55185 | K12: =SUBTOTAL(9,K10:K11) -> 74107 | L12: =SUBTOTAL(9,L10:L11) -> -40741 | M12: =SUBTOTAL(9,M10:M11) -> 74107
A13: clinl | B13: Clin Ass (0.64 wte) | C13: Dr Trivedi | D13: NHS Locum Clin Ass (0.9 wte) | E13: Ongoing | F13: JD back from Region for further comments. | H13: 33979 | I13: 25205 | J13: =2708*5 -> 13540 | K13: =J13+I13 -> 38745 | L13: =H13-K13 -> -4766 | M13: =K13 -> 38745
A14: clinl | B14: Psychotherapy Clinical Assistant (0.18 wte) | C14: Dr Garwood | D14: NHS Locum Clinical Assistant | E14: Ongoing | H14: 11641 | I14: 6733 | J14: =962*5 -> 4810 | K14: =J14+I14 -> 11543 | L14: =H14-K14 -> 98 | M14: =K14 -> 11543
A15: clinl | B15: Clin Ass. (0.73 wte) | C15: Dr Saleem | D15: Substantive Staff Grade 1.0 wte | E15: NA | F15: NA | H15: 38898 | I15: 22955 | J15: =5354*5 -> 26770 | K15: =J15+I15 -> 49725 | L15: =H15-K15 -> -10827 | M15: =K15 -> 49725
A16: clinl Total | H16: =SUBTOTAL(9,H13:H15) -> 84518 | I16: =SUBTOTAL(9,I13:I15) -> 54893 | J16: =SUBTOTAL(9,J13:J15) -> 45120 | K16: =SUBTOTAL(9,K13:K15) -> 100013 | L16: =SUBTOTAL(9,L13:L15) -> -15495 | M16: =SUBTOTAL(9,M13:M15) -> 100013
A17: con | B17: Consultant | C17: Dr Magner | D17: Substantive | E17: 38322 | F17: NA | H17: 101244 | I17: =69513-7934 -> 61579 | J17: =7933*3 -> 23799 | K17: =J17+I17 -> 85378 | L17: =H17-K17 -> 15866 | M17: =7933*4 -> 31732
A18: con | B18: Consultant | C18: Dr Duffett | D18: Substantive | E18: NA | F18: NA | H18: 99307 | I18: =68963-7586 -> 61377 | J18: =7586*5 -> 37930 | K18: =J18+I18 -> 99307 | L18: =H18-K18 -> 0 | M18: =K18 -> 99307
A19: con | B19: Consultant | C19: Vacancy | D19: Substantive | E19: NA | F19: NA | H19: 95517 | I19: 16443 | K19: =J19+I19 -> 16443 | L19: =H19-K19 -> 79074 | M19: =7422*5 -> 37110
A20: con | B20: Consultant | C20: Dr Margo | D20: Substantive | E20: NA | F20: NA | H20: =116250*1.03225 -> 119999.06 | I20: 70067 | J20: =9915*5 -> 49575 | K20: =J20+I20 -> 119642 | L20: =H20-K20 -> 357.0625 | M20: =K20 -> 119642
A21: con | B21: Consultant | C21: Dr Walsh | D21: Substantive | E21: NA | F21: NA | H21: =103883*1.03225 -> 107233.23 | I21: =72815-7614 -> 65201 | J21: =10306*5 -> 51530 | K21: =J21+I21 -> 116731 | L21: =H21-K21 -> -9497.7733 | M21: =K21 -> 116731
A22: con | B22: Consultant | C22: Dr Evenson | D22: Substantive | E22: NA | F22: NA | H22: 90325 | I22: 58934 | J22: =7588*5 -> 37940 | K22: =J22+I22 -> 96874 | L22: =H22-K22 -> -6549 | M22: =K22 -> 96874
A23: con | B23: Consultant | C23: Dr Wildgrube | D23: Substantive | E23: NA | F23: NA | H23: 87346 | I23: 62621 | J23: =7422*5 -> 37110 | K23: =J23+I23 -> 99731 | L23: =H23-K23 -> -12385 | M23: =K23 -> 99731
A24: con | B24: Consultant (0.45 wte) | C24: Vacant | F24: Available funding | H24: 40345 | K24: =J24+I24 -> 0 | L24: =H24-K24 -> 40345 | M24: =K24 -> 0
A25: con | B25: Consultant | C25: Dr Fagin | D25: Substantive | E25: NA | F25: NA | H25: =132974*1.05+3705 -> 143327.7 | I25: 75975 | J25: =11326*5 -> 56630 | K25: =J25+I25 -> 132605 | L25: =H25-K25 -> 10722.7 | M25: =K25 -> 132605
A26: con | B26: Consultant | C26: Dr Williams | D26: Substantive | E26: NA | F26: NA | H26: =78405*1.05+3705 -> 86030.25 | I26: =59509-7220 -> 52289 | J26: =7220*5 -> 36100 | K26: =J26+I26 -> 88389 | L26: =H26-K26 -> -2358.75 | M26: =K26 -> 88389
A27: con | B27: Consultant | C27: Dr Travers | D27: Substantive | E27: NA | F27: NA | H27: 92523 | I27: =72388-8752 -> 63636 | J27: =8752*5 -> 43760 | K27: =J27+I27 -> 107396 | L27: =H27-K27 -> -14873 | M27: =K27 -> 107396
A28: con | B28: Consultant | C28: Dr Gadhvi | D28: Substantive | E28: NA | F28: NA | H28: =84722*1.04 -> 88110.88 | I28: =59909-7337 -> 52572 | J28: =7337*5 -> 36685 | K28: =J28+I28 -> 89257 | L28: =H28-K28 -> -1146.12 | M28: =K28 -> 89257
A29: con | B29: Consultant | C29: Dr Lawrence | D29: Substantive | E29: NA | F29: NA | H29: =78568*1.04 -> 81710.72 | I29: =56769-7987 -> 48782 | J29: =7987*5 -> 39935 | K29: =J29+I29 -> 88717 | L29: =H29-K29 -> -7006.28 | M29: =K29 -> 88717
A30: con | B30: Consultant | C30: Dr Borrell | D30: Substantive 0.7 wte | E30: NA | F30: NA | H30: =49518*1.04 -> 51498.72 | I30: 37575 | J30: =4176*5 -> 20880 | K30: =J30+I30 -> 58455 | L30: =H30-K30 -> -6956.28 | M30: =K30 -> 58455
A31: con | B31: Consultant | C31: Dr Papanastiou | D31: 0.7 wte | H31: 48084 | I31: =13735-4578 -> 9157 | J31: =4578*5 -> 22890 | K31: =J31+I31 -> 32047 | L31: =H31-K31 -> 16037 | M31: =K31 -> 32047
A32: con | B32: Consultant (0.27 wte) | C32: Vacant | F32: Available funding | H32: 0 | K32: =J32+I32 -> 0 | L32: =H32-K32 -> 0 | M32: =K32 -> 0
A33: con | B33: Consultant | C33: Dr Mirza | D33: Substantive | E33: NA | F33: NA | H33: 85479 | I33: =51064+15138 -> 66202 | J33: =7136*5 -> 35680 | K33: =J33+I33 -> 101882 | L33: =H33-K33 -> -16403 | M33: =K33 -> 101882
A34: con | B34: Consultant | C34: D Cleary | D34: Substantive 0.5 wte | E34: NA | F34: NA | H34: 96160 | I34: =61184+12055 -> 73239 | J34: =8720*5 -> 43600 | K34: =J34+I34 -> 116839 | L34: =H34-K34 -> -20679 | M34: =K34 -> 116839
A35: con | B35: Consultant | C35: Dr Petterson | D35: Substantive 0.5 wte | M35: =K35 -> 0
A36: con | B36: Consultant | C36: Dr Luyombia | D36: Substantive | E36: NA | F36: NA | H36: 88675 | I36: 51321 | J36: =7332*5 -> 36660 | K36: =J36+I36 -> 87981 | L36: =H36-K36 -> 694 | M36: =K36 -> 87981
A37: con | B37: Consultant | C37: Dr Rossouw | D37: Substantive | E37: NA | F37: NA | H37: 47052 | I37: =4203*7 -> 29421 | J37: =4203*5 -> 21015 | K37: =J37+I37 -> 50436 | L37: =H37-K37 -> -3384 | M37: =K37 -> 50436
A38: con | B38: Consultant | C38: DrLittlejohn | D38: Substantive | E38: NA | F38: NA | H38: 85717 | I38: 50457 | J38: =7414*5 -> 37070 | K38: =J38+I38 -> 87527 | L38: =H38-K38 -> -1810 | M38: =K38 -> 87527
A39: con | B39: Consultant (0.54wte) | C39: Dr Lau | D39: Substantive 0.4 wte | E39: NA | F39: NA | H39: 86270 | I39: =7314*7 -> 51198 | J39: =7314*5 -> 36570 | K39: =J39+I39 -> 87768 | L39: =H39-K39 -> -1498 | M39: =K39 -> 87768
A40: con | B40: Consultant | C40: Dr Caviston | D40: Substantive | E40: NA | F40: NA | H40: 91295 | I40: =7609*7 -> 53263 | J40: =7609*5 -> 38045 | K40: =J40+I40 -> 91308 | L40: =H40-K40 -> -13 | M40: =K40 -> 91308
A41: con | B41: Consultant | C41: Dr El Hadi | D41: Trainee | E41: NA | F41: NA | H41: =84955*1.04 -> 88353.2 | I41: =7341*7 -> 51387 | J41: =7341*5 -> 36705 | K41: =J41+I41 -> 88092 | L41: =H41-K41 -> 261.2 | M41: =K41 -> 88092
...

Sheet Sheet1
B3: ET6 | C3: Description | D3: 2002/03
B4: Budget
B5: 5645155 | C5: Budget
B6: to Date
B7: 940868 | C7: Spend
B8: to Date
B9: 814159 | C9: Variance
B10: Under/(Over)
B11: 126709 | C11: wte
B12: ccb
B13: 74.51 | C13: wte
B14: Worked
B15: 65.57 | C15: WTE
B16: CBB
B17: 78.51 | E17: Budget | F17: Spend | G17: Variance | H17: wte | I17: wte | M17: CONSULTANT | O17: =70*50*4.35 -> 15225
B18: REGISTRARS | C18: REGISTRARS | D18: 1014988 | E18: 668433 | F18: 374507 | G18: 293926 | H18: 13.5 | I18: 12.22 | J18: 14.5 | M18: SHO | O18: =41*4.35*46 -> 8204.1
B19: BEZZ | C19: SNR HOUSE OFFICERS | D19: 1275993 | E19: 851385 | F19: 798604 | G19: 52781 | H19: 22 | I19: 18.8 | J19: 24 | M19: STAFF GRADE | O19: =51*4.35*40 -> 8874
B20: BAZZ | C20: CONSULTANTS | D20: 3411492 | E20: 2274328 | F20: 2146285 | G20: 128043 | H20: 34.75 | I20: 32.01 | J20: 36.57 | M20: ASSOC SPECIALIST | O20: =49.95*4.35*40 -> 8691.3
B21: BHZZ | C21: CLINICAL ASSTS & BTS SESSIONS | D21: 55079 | E21: 36720 | F21: 7695 | G21: 29025 | H21: 1.17 | I21: 0.18 | J21: 1.17 | M21: CLINICAL ASSISTANT | O21: =49*4.35*40 -> 8526
B22: BBZZ | C22: ASSOCIATE SPECIALIST | D22: 164804 | E22: 109870 | F22: 11903 | G22: 97967 | H22: 2.27 | I22: 0.27 | J22: 2.27
E24: =SUM(E18:E22) -> 3940736 | F24: =SUM(F18:F22) -> 3338994 | G24: =SUM(G18:G22) -> 601742
A31: =MID(B31,9,4) -> PA01 | B31: MD-GCPT/PA01-000000 | C31: C & A WOODWARD AGENCY-MEDICAL | D31: =VLOOKUP($B31,Sheet2!$B$4:$J$1501,3,0) -> 0 | E31: =VLOOKUP($B31,Sheet2!$B$4:$J$1501,4,0) -> 0 | F31: =VLOOKUP($B31,Sheet2!$B$4:$J$1501,5,0) -> 0 | G31: =VLOOKUP($B31,Sheet2!$B$4:$J$1501,6,0) -> 0 | H31: =VLOOKUP($B31,Sheet2!$B$4:$J$1501,7,0) -> 0 | I31: =VLOOKUP($B31,Sheet2!$B$4:$J$1501,8,0) -> 0 | J31: =VLOOKUP($B31,Sheet2!$B$4:$J$1501,9,0) -> 0
A32: =MID(B32,9,4) -> PA01 | B32: ML-SWMA/PA01-000000 | C32: CHILD PSYCHIAT AGENCY-MEDICAL | D32: =VLOOKUP($B32,Sheet2!$B$4:$J$1501,3,0) -> 0 | E32: =VLOOKUP($B32,Sheet2!$B$4:$J$1501,4,0) -> 0 | F32: =VLOOKUP($B32,Sheet2!$B$4:$J$1501,5,0) -> 0 | G32: =VLOOKUP($B32,Sheet2!$B$4:$J$1501,6,0) -> 0 | H32: =VLOOKUP($B32,Sheet2!$B$4:$J$1501,7,0) -> 0 | I32: =VLOOKUP($B32,Sheet2!$B$4:$J$1501,8,0) -> 0 | J32: =VLOOKUP($B32,Sheet2!$B$4:$J$1501,9,0) -> 0
A33: PA01 Total | D33: =SUM(D31:D32) -> 0 | E33: =SUM(E31:E32) -> 0 | F33: =SUM(F31:F32) -> 0 | G33: =SUM(G31:G32) -> 0 | H33: =SUM(H31:H32) -> 0 | I33: =SUM(I31:I32) -> 0 | J33: =SUM(J31:J32) -> 0
A34: =MID(B34,9,4) -> PA02 | B34: MR-GMMS/PA02-000000 | C34: STH SEC MED CLIN ASSIS LOC | D34: =VLOOKUP($B34,Sheet2!$B$4:$J$1501,3,0) -> 0 | E34: =VLOOKUP($B34,Sheet2!$B$4:$J$1501,4,0) -> 0 | F34: =VLOOKUP($B34,Sheet2!$B$4:$J$1501,5,0) -> 0 | G34: =VLOOKUP($B34,Sheet2!$B$4:$J$1501,6,0) -> 0 | H34: =VLOOKUP($B34,Sheet2!$B$4:$J$1501,7,0) -> 0 | I34: =VLOOKUP($B34,Sheet2!$B$4:$J$1501,8,0) -> 0 | J34: =VLOOKUP($B34,Sheet2!$B$4:$J$1501,9,0) -> 0
A35: =MID(B35,9,4) -> PA02 | B35: MR-GMMT/PA02-000000 | C35: NTH SEC MED CLIN ASSIS LOC | D35: =VLOOKUP($B35,Sheet2!$B$4:$J$1501,3,0) -> 33979 | E35: =VLOOKUP($B35,Sheet2!$B$4:$J$1501,4,0) -> 22653 | F35: =VLOOKUP($B35,Sheet2!$B$4:$J$1501,5,0) -> 27913 | G35: =VLOOKUP($B35,Sheet2!$B$4:$J$1501,6,0) -> -5260 | H35: =VLOOKUP($B35,Sheet2!$B$4:$J$1501,7,0) -> 0.64 | I35: =VLOOKUP($B35,Sheet2!$B$4:$J$1501,8,0) -> 0.64 | J35: =VLOOKUP($B35,Sheet2!$B$4:$J$1501,9,0) -> 0.64
A36: =MID(B36,9,4) -> PA02 | B36: MR-GMMW/PA02-000000 | C36: WST SEC MED CLIN ASSIS LOC | D36: =VLOOKUP($B36,Sheet2!$B$4:$J$1501,3,0) -> 38898 | E36: =VLOOKUP($B36,Sheet2!$B$4:$J$1501,4,0) -> 25932 | F36: =VLOOKUP($B36,Sheet2!$B$4:$J$1501,5,0) -> 22955 | G36: =VLOOKUP($B36,Sheet2!$B$4:$J$1501,6,0) -> 2977 | H36: =VLOOKUP($B36,Sheet2!$B$4:$J$1501,7,0) -> 0.73 | I36: =VLOOKUP($B36,Sheet2!$B$4:$J$1501,8,0) -> 0 | J36: =VLOOKUP($B36,Sheet2!$B$4:$J$1501,9,0) -> 0.73
A37: =MID(B37,9,4) -> PA02 | B37: MR-GMML/PA02-000000 | C37: REHAB MED CLIN ASSIS LOC | D37: =VLOOKUP($B37,Sheet2!$B$4:$J$1501,3,0) -> 0 | E37: =VLOOKUP($B37,Sheet2!$B$4:$J$1501,4,0) -> 0 | F37: =VLOOKUP($B37,Sheet2!$B$4:$J$1501,5,0) -> 22106 | G37: =VLOOKUP($B37,Sheet2!$B$4:$J$1501,6,0) -> -22106 | H37: =VLOOKUP($B37,Sheet2!$B$4:$J$1501,7,0) -> 0 | I37: =VLOOKUP($B37,Sheet2!$B$4:$J$1501,8,0) -> 0.65 | J37: =VLOOKUP($B37,Sheet2!$B$4:$J$1501,9,0) -> 0
A38: PA02 Total | C38: REHAB MED CLIN ASSIS LOC | D38: =SUM(D34:D37) -> 72877 | E38: =SUM(E34:E37) -> 48585 | F38: =SUM(F34:F37) -> 72974 | G38: =SUM(G34:G37) -> -24389 | H38: =SUM(H34:H37) -> 1.37 | I38: =SUM(I34:I37) -> 1.29 | J38: =SUM(J34:J37) -> 1.37 | L38: =F38/5/O21 -> 1.7117992
A39: =MID(B39,9,4) -> PA03 | B39: MF-WFMC/PA03-000000 | C39: MEDI COVER SHO LOCUM | D39: =VLOOKUP($B39,Sheet2!$B$4:$J$1501,3,0) -> 8441 | E39: =VLOOKUP($B39,Sheet2!$B$4:$J$1501,4,0) -> 5628 | F39: =VLOOKUP($B39,Sheet2!$B$4:$J$1501,5,0) -> 13344 | G39: =VLOOKUP($B39,Sheet2!$B$4:$J$1501,6,0) -> -7716 | H39: =VLOOKUP($B39,Sheet2!$B$4:$J$1501,7,0) -> 0 | I39: =VLOOKUP($B39,Sheet2!$B$4:$J$1501,8,0) -> 0 | J39: =VLOOKUP($B39,Sheet2!$B$4:$J$1501,9,0) -> 0
A40: =MID(B40,9,4) -> PA03 | B40: MF-WFME/PA03-000000 | C40: E FOREST UNIT SHO LOCUM | D40: =VLOOKUP($B40,Sheet2!$B$4:$J$1501,3,0) -> 0 | E40: =VLOOKUP($B40,Sheet2!$B$4:$J$1501,4,0) -> 0 | F40: =VLOOKUP($B40,Sheet2!$B$4:$J$1501,5,0) -> 3666 | G40: =VLOOKUP($B40,Sheet2!$B$4:$J$1501,6,0) -> -3666 | H40: =VLOOKUP($B40,Sheet2!$B$4:$J$1501,7,0) -> 0 | I40: =VLOOKUP($B40,Sheet2!$B$4:$J$1501,8,0) -> 0 | J40: =VLOOKUP($B40,Sheet2!$B$4:$J$1501,9,0) -> 0
A41: =MID(B41,9,4) -> PA03 | B41: MF-WFMS/PA03-000000 | C41: MEDI STH CMHT SHO LOCUM | D41: =VLOOKUP($B41,Sheet2!$B$4:$J$1501,3,0) -> 0 | E41: =VLOOKUP($B41,Sheet2!$B$4:$J$1501,4,0) -> 0 | F41: =VLOOKUP($B41,Sheet2!$B$4:$J$1501,5,0) -> 2057 | G41: =VLOOKUP($B41,Sheet2!$B$4:$J$1501,6,0) -> -2057 | H41: =VLOOKUP($B41,Sheet2!$B$4:$J$1501,7,0) -> 0 | I41: =VLOOKUP($B41,Sheet2!$B$4:$J$1501,8,0) -> 0 | J41: =VLOOKUP($B41,Sheet2!$B$4:$J$1501,9,0) -> 0
A42: =MID(B42,9,4) -> PA03 | B42: MR-GDBP/PA03-000000 | C42: BED PRESSURE SHO LOCUM | D42: =VLOOKUP($B42,Sheet2!$B$4:$J$1501,3,0) -> 0 | E42: =VLOOKUP($B42,Sheet2!$B$4:$J$1501,4,0) -> 0 | F42: =VLOOKUP($B42,Sheet2!$B$4:$J$1501,5,0) -> 15090 | G42: =VLOOKUP($B42,Sheet2!$B$4:$J$1501,6,0) -> -15090 | H42: =VLOOKUP($B42,Sheet2!$B$4:$J$1501,7,0) -> 0 | I42: =VLOOKUP($B42,Sheet2!$B$4:$J$1501,8,0) -> 0 | J42: =VLOOKUP($B42,Sheet2!$B$4:$J$1501,9,0) -> 0
A43: =MID(B43,9,4) -> PA03 | B43: MR-GMGK/PA03-000000 | C43: CLIN DIR MGMT SHO LOCUM | D43: =VLOOKUP($B43,Sheet2!$B$4:$J$1501,3,0) -> 0 | E43: =VLOOKUP($B43,Sheet2!$B$4:$J$1501,4,0) -> 0 | F43: =VLOOKUP($B43,Sheet2!$B$4:$J$1501,5,0) -> 4513 | G43: =VLOOKUP($B43,Sheet2!$B$4:$J$1501,6,0) -> -4513 | H43: =VLOOKUP($B43,Sheet2!$B$4:$J$1501,7,0) -> 0 | I43: =VLOOKUP($B43,Sheet2!$B$4:$J$1501,8,0) -> 0 | J43: =VLOOKUP($B43,Sheet2!$B$4:$J$1501,9,0) -> 0
A44: =MID(B44,9,4) -> PA03 | B44: MR-GMMF/PA03-000000 | C44: GM DR FELDMAN SHO LOCUM | D44: =VLOOKUP($B44,Sheet2!$B$4:$J$1501,3,0) -> 0 | E44: =VLOOKUP($B44,Sheet2!$B$4:$J$1501,4,0) -> 0 | F44: =VLOOKUP($B44,Sheet2!$B$4:$J$1501,5,0) -> 0 | G44: =VLOOKUP($B44,Sheet2!$B$4:$J$1501,6,0) -> 0 | H44: =VLOOKUP($B44,Sheet2!$B$4:$J$1501,7,0) -> 0 | I44: =VLOOKUP($B44,Sheet2!$B$4:$J$1501,8,0) -> 0 | J44: =VLOOKUP($B44,Sheet2!$B$4:$J$1501,9,0) -> 0
A45: =MID(B45,9,4) -> PA03 | B45: MR-GMMS/PA03-000000 | C45: STH SEC MED SHO LOCUM | D45: =VLOOKUP($B45,Sheet2!$B$4:$J$1501,3,0) -> 0 | E45: =VLOOKUP($B45,Sheet2!$B$4:$J$1501,4,0) -> 0 | F45: =VLOOKUP($B45,Sheet2!$B$4:$J$1501,5,0) -> 52316 | G45: =VLOOKUP($B45,Sheet2!$B$4:$J$1501,6,0) -> -52316 | H45: =VLOOKUP($B45,Sheet2!$B$4:$J$1501,7,0) -> 0 | I45: =VLOOKUP($B45,Sheet2!$B$4:$J$1501,8,0) -> 0 | J45: =VLOOKUP($B45,Sheet2!$B$4:$J$1501,9,0) -> 0
A46: =MID(B46,9,4) -> PA03 | B46: MR-GMMT/PA03-000000 | C46: NTH SEC MED SHO LOCUM | D46: =VLOOKUP($B46,Sheet2!$B$4:$J$1501,3,0) -> 0 | E46: =VLOOKUP($B46,Sheet2!$B$4:$J$1501,4,0) -> 0 | F46: =VLOOKUP($B46,Sheet2!$B$4:$J$1501,5,0) -> 14909 | G46: =VLOOKUP($B46,Sheet2!$B$4:$J$1501,6,0) -> -14909 | H46: =VLOOKUP($B46,Sheet2!$B$4:$J$1501,7,0) -> 0 | I46: =VLOOKUP($B46,Sheet2!$B$4:$J$1501,8,0) -> 0 | J46: =VLOOKUP($B46,Sheet2!$B$4:$J$1501,9,0) -> 0
A47: =MID(B47,9,4) -> PA03 | B47: MR-GWCU/PA03-000000 | C47: KAHLIL GIBRAN SHO LOCUM | D47: =VLOOKUP($B47,Sheet2!$B$4:$J$1501,3,0) -> 0 | E47: =VLOOKUP($B47,Sheet2!$B$4:$J$1501,4,0) -> 0 | F47: =VLOOKUP($B47,Sheet2!$B$4:$J$1501,5,0) -> 549 | G47: =VLOOKUP($B47,Sheet2!$B$4:$J$1501,6,0) -> -549 | H47: =VLOOKUP($B47,Sheet2!$B$4:$J$1501,7,0) -> 0 | I47: =VLOOKUP($B47,Sheet2!$B$4:$J$1501,8,0) -> 0 | J47: =VLOOKUP($B47,Sheet2!$B$4:$J$1501,9,0) -> 0
A48: =MID(B48,9,4) -> PA03 | B48: MR-GWIC/PA03-000000 | C48: PATH ON TAGORE SHO LOCUM | D48: =VLOOKUP($B48,Sheet2!$B$4:$J$1501,3,0) -> 0 | E48: =VLOOKUP($B48,Sheet2!$B$4:$J$1501,4,0) -> 0 | F48: =VLOOKUP($B48,Sheet2!$B$4:$J$1501,5,0) -> 7179 | G48: =VLOOKUP($B48,Sheet2!$B$4:$J$1501,6,0) -> -7179 | H48: =VLOOKUP($B48,Sheet2!$B$4:$J$1501,7,0) -> 0 | I48: =VLOOKUP($B48,Sheet2!$B$4:$J$1501,8,0) -> 0 | J48: =VLOOKUP($B48,Sheet2!$B$4:$J$1501,9,0) -> 0
A49: =MID(B49,9,4) -> PA03 | B49: MR-JDBR/PA03-000000 | C49: BROOKSIDE UNIT SHO LOCUM | D49: =VLOOKUP($B49,Sheet2!$B$4:$J$1501,3,0) -> 0 | E49: =VLOOKUP($B49,Sheet2!$B$4:$J$1501,4,0) -> 0 | F49: =VLOOKUP($B49,Sheet2!$B$4:$J$1501,5,0) -> 15298 | G49: =VLOOKUP($B49,Sheet2!$B$4:$J$1501,6,0) -> -15298 | H49: =VLOOKUP($B49,Sheet2!$B$4:$J$1501,7,0) -> 0 | I49: =VLOOKUP($B49,Sheet2!$B$4:$J$1501,8,0) -> 0 | J49: =VLOOKUP($B49,Sheet2!$B$4:$J$1501,9,0) -> 0
...

Sheet Sheet2
A2: ET6 | B2: Description | C2: 2003/04 Budget 5,922,356 | D2: Budget to Date 3,940,736 | E2: Spend to Date 3,338,994 | F2: Variance Under/(Over) 601,742 | G2: wte ccb 73.69 | H2: wte Worked 63.48 | I2: WTE CBB 78.51
A3: REGISTRARS | B3: REGISTRARS | C3: 1014988 | D3: 668433 | E3: 374507 | F3: 293926 | G3: 13.5 | H3: 12.22 | I3: 14.5
A4: BEZZ | B4: SNR HOUSE OFFICERS | C4: 1275993 | D4: 851385 | E4: 798604 | F4: 52781 | G4: 22 | H4: 18.8 | I4: 24
A5: BAZZ | B5: CONSULTANTS | C5: 3411492 | D5: 2274328 | E5: 2146285 | F5: 128043 | G5: 34.75 | H5: 32.01 | I5: 36.57
A6: BHZZ | B6: CLINICAL ASSTS & BTS SESSIONS | C6: 55079 | D6: 36720 | E6: 7695 | F6: 29025 | G6: 1.17 | H6: 0.18 | I6: 1.17
A7: BBZZ | B7: ASSOCIATE SPECIALIST | C7: 164804 | D7: 109870 | E7: 11903 | F7: 97967 | G7: 2.27 | H7: 0.27 | I7: 2.27
A10: =MID(B10,9,4)
A11: =MID(B11,9,4) -> PA01 | B11: MD-GCPT/PA01-000000 | C11: C & A WOODWARD AGENCY-MEDICAL
A12: =MID(B12,9,4) -> PA01 | B12: ML-SWMA/PA01-000000 | C12: CHILD PSYCHIAT AGENCY-MEDICAL
A13: =MID(B13,9,4) -> PA02 | B13: MR-GMML/PA02-000000 | C13: REHAB MED CLIN ASSIS LOC | F13: 22106 | G13: -22106 | I13: 0.65
A14: =MID(B14,9,4) -> PA02 | B14: MR-GMMS/PA02-000000 | C14: STH SEC MED CLIN ASSIS LOC
A15: =MID(B15,9,4) -> PA02 | B15: MR-GMMT/PA02-000000 | C15: NTH SEC MED CLIN ASSIS LOC | D15: 33979 | E15: 22653 | F15: 27913 | G15: -5260 | H15: 0.64 | I15: 0.64 | J15: 0.64
A16: =MID(B16,9,4) -> PA02 | B16: MR-GMMW/PA02-000000 | C16: WST SEC MED CLIN ASSIS LOC | D16: 38898 | E16: 25932 | F16: 22955 | G16: 2977 | H16: 0.73 | J16: 0.73
A17: =MID(B17,9,4) -> PA03 | B17: MF-WFLS/PA03-000000 | C17: MED LIASON SHO LOCUM | D17: 62821 | E17: 41881 | F17: 0 | G17: 41881
A18: =MID(B18,9,4) -> PA03 | B18: MF-WFMC/PA03-000000 | C18: MEDI COVER SHO LOCUM | D18: 8441 | E18: 5628 | F18: 13344 | G18: -7716
A19: =MID(B19,9,4) -> PA03 | B19: MF-WFME/PA03-000000 | C19: E FOREST UNIT SHO LOCUM | F19: 3666 | G19: -3666
A20: =MID(B20,9,4) -> PA03 | B20: MF-WFMJ/PA03-000000 | C20: FOREST PGME SHO LOCUM | D20: 17690 | E20: 11794 | F20: 34959 | G20: -23165
A21: =MID(B21,9,4) -> PA03 | B21: MF-WFML/PA03-000000 | C21: MEDI REHAB SHO LOCUM | F21: 3873 | G21: -3873
A22: =MID(B22,9,4) -> PA03 | B22: MF-WFMS/PA03-000000 | C22: MEDI STH CMHT SHO LOCUM | F22: 2057 | G22: -2057
A23: =MID(B23,9,4) -> PA03 | B23: MF-WFMT/PA03-000000 | C23: MEDI MTH CMHT SHO LOCUM | F23: 2057 | G23: -2057
A24: =MID(B24,9,4) -> PA03 | B24: MR-GDBP/PA03-000000 | C24: BED PRESSURE SHO LOCUM | F24: 15090 | G24: -15090
A25: =MID(B25,9,4) -> PA03 | B25: MR-GDPG/PA03-000000 | C25: GM POSTGRAD SHO LOCUM | F25: 5521 | G25: -5521
A26: =MID(B26,9,4) -> PA03 | B26: MR-GMGK/PA03-000000 | C26: CLIN DIR MGMT SHO LOCUM | F26: 4513 | G26: -4513
A27: =MID(B27,9,4) -> PA03 | B27: MR-GMMF/PA03-000000 | C27: GM DR FELDMAN SHO LOCUM
A28: =MID(B28,9,4) -> PA03 | B28: MR-GMML/PA03-000000 | C28: REHAB MED SHO LOCUM | F28: 29361 | G28: -29361
A29: =MID(B29,9,4) -> PA03 | B29: MR-GMMS/PA03-000000 | C29: STH SEC MED SHO LOCUM | F29: 52316 | G29: -52316
A30: =MID(B30,9,4) -> PA03 | B30: MR-GMMT/PA03-000000 | C30: NTH SEC MED SHO LOCUM | F30: 14909 | G30: -14909
A31: =MID(B31,9,4) -> PA03 | B31: MR-GWCU/PA03-000000 | C31: KAHLIL GIBRAN SHO LOCUM | F31: 549 | G31: -549
A32: =MID(B32,9,4) -> PA03 | B32: MR-GWIC/PA03-000000 | C32: PATH ON TAGORE SHO LOCUM | F32: 7179 | G32: -7179
A33: =MID(B33,9,4) -> PA03 | B33: MR-JDBR/PA03-000000 | C33: BROOKSIDE UNIT SHO LOCUM | F33: 15298 | G33: -15298
A34: =MID(B34,9,4) -> PA04 | B34: MF-WFHT/PA04-000000 | C34: HOME TREAT CONSULT LOC | F34: 0 | G34: 0
A35: =MID(B35,9,4) -> PA04 | B35: MF-WFLS/PA04-000000 | C35: MED LIASON CONSULT LOC | F35: 11278 | G35: -11278
A36: =MID(B36,9,4) -> PA04 | B36: MF-WFMA/PA04-000000 | C36: CHILD MED CONSULT LOC | F36: 69324 | G36: -69324 | I36: 1
A37: =MID(B37,9,4) -> PA04 | B37: MF-WFMC/PA04-000000 | C37: MEDI COVER CONSULT LOC
A38: =MID(B38,9,4) -> PA04 | B38: MF-WFME/PA04-000000 | C38: E FOREST UNIT CONSULT LOC | F38: 15138 | G38: -15138
A39: =MID(B39,9,4) -> PA04 | B39: MF-WFMJ/PA04-000000 | C39: FOREST PGME CONSULT LOC
A40: =MID(B40,9,4) -> PA04 | B40: MF-WFMK/PA04-000000 | C40: FOR SNR DR TR CONSULT LOC
A41: =MID(B41,9,4) -> PA04 | B41: MF-WFML/PA04-000000 | C41: MEDI REHAB CONSULT LOC
A42: =MID(B42,9,4) -> PA04 | B42: MF-WFMR/PA04-000000 | C42: WALT MED CONSULT LOC | D42: 8805 | E42: 5870 | F42: 22604 | G42: -16734
A43: =MID(B43,9,4) -> PA04 | B43: MF-WFMT/PA04-000000 | C43: MEDI MTH CMHT CONSULT LOC | F43: 69904 | G43: -69904
...

Sheet Sheet3
B1: REGISTRARS | C1: REGISTRARS | D1: 980451 | E1: 490230 | F1: 266291 | G1: 223939 | H1: 13.5 | I1: 9 | J1: 14.5
B2: BEZZ | C2: SNR HOUSE OFFICERS | D2: 1273829 | E2: 636917 | F2: 618424 | G2: 18493 | H2: 22 | I2: 22.1 | J2: 24
B3: BAZZ | C3: CONSULTANTS | D3: 3411492 | E3: 1705747 | F3: 1613829 | G3: 91918 | H3: 34.75 | I3: 31.23 | J3: 36.57
B5: BHZZ | C5: CLINICAL ASSTS & BTS SESSIONS | D5: 55079 | E5: 27540 | F5: 5771 | G5: 21769 | H5: 1.17 | I5: 0.18 | J5: 1.17
B6: BBZZ | C6: ASSOCIATE SPECIALIST | D6: 164804 | E6: 82402 | F6: 8928 | G6: 73474 | H6: 2.27 | I6: 0.27 | J6: 2.27
B8: MD-GCPT/PA01-000000 | C8: C & A WOODWARD AGENCY-MEDICAL
B9: MF-WFAS/PA10-000000 | C9: STONELEA SHO O/C COVER | F9: 686 | G9: -686
B10: MF-WFHT/PA04-000000 | C10: HOME TREAT CONSULT LOC | F10: 0 | G10: 0
B11: MF-WFHT/PA06-000000 | C11: HOME TREAT STAFF GRADE LO | F11: 70818 | G11: -70818
B12: MF-WFHT/PA07-000000 | C12: HOME TREAT ASSOC SPEC LOC | F12: 0 | G12: 0
B13: MF-WFMA/PA04-000000 | C13: CHILD MED CONSULT LOC | F13: 45279 | G13: -45279 | I13: 1
B14: MF-WFMA/PA10-000000 | C14: CHILD MED SHO O/C COVER
B15: MF-WFMC/PA03-000000 | C15: MEDI COVER SHO LOCUM | D15: 8441 | E15: 4221 | F15: 13344 | G15: -9123
B16: MF-WFMC/PA04-000000 | C16: MEDI COVER CONSULT LOC
B17: MF-WFMC/PA06-000000 | C17: MEDI COVER STAFF GRADE LO
B18: MF-WFMC/PA10-000000 | C18: MEDI COVER SHO O/C COVER | F18: 686 | G18: -686
B19: MF-WFME/PA03-000000 | C19: E FOREST UNIT SHO LOCUM | F19: 3666 | G19: -3666
B20: MF-WFME/PA04-000000 | C20: E FOREST UNIT CONSULT LOC | F20: 15138 | G20: -15138
B21: MF-WFPS/PA04-000000 | C21: PSYCHOTHERAPY CONSULT LOC | D21: 13781 | E21: 6891 | F21: 6879 | G21: 12 | H21: 0.18 | I21: 0.18 | J21: 0.18
B22: MF-WFPS/PA10-000000 | C22: PSYCHOTHERAPY SHO O/C COVER
B23: ML-SWMA/PA01-000000 | C23: CHILD PSYCHIAT AGENCY-MEDICAL
B24: ML-SWMA/PA04-000000 | C24: CHILD PSYCHIAT CONSULT LOC
B25: MR-GDAO/PA06-000000 | C25: ASSERTIVE OUT STAFF GRADE LO | D25: 59207 | E25: 29603 | F25: 37526 | G25: -7923 | H25: 1
B26: MR-GDHR/PA07-000000 | C26: 24 HR ACCESS ASSOC SPEC LOC
B27: MR-GMGK/PA03-000000 | C27: CLIN DIR MGMT SHO LOCUM | F27: 1674 | G27: -1674
B28: MR-GMGK/PA06-000000 | C28: CLIN DIR MGMT STAFF GRADE LO | F28: 44539 | G28: -44539
B29: MR-GMMF/PA03-000000 | C29: GM DR FELDMAN SHO LOCUM
B30: MR-GMMS/PA02-000000 | C30: STH SEC MED CLIN ASSIS LOC
B31: MR-GMMS/PA03-000000 | C31: STH SEC MED SHO LOCUM | F31: 48424 | G31: -48424
B32: MR-GMMS/PA04-000000 | C32: STH SEC MED CONSULT LOC | D32: 61629 | E32: 30813 | F32: 55339 | G32: -24526
B33: MR-GMMS/PA06-000000 | C33: STH SEC MED STAFF GRADE LO | F33: 131470 | G33: -131470 | I33: 2
B34: MR-GMMS/PA07-000000 | C34: STH SEC MED ASSOC SPEC LOC | D34: 228485 | E34: 114243 | F34: 97078 | G34: 17165 | H34: 0.63 | J34: 0.63
B35: MR-GMMS/PA09-000000 | C35: STH SEC MED REGISTRAR LOCU
B36: MR-GMMT/PA02-000000 | C36: NTH SEC MED CLIN ASSIS LOC | D36: 33979 | E36: 16990 | F36: 22497 | G36: -5507 | H36: 0.64 | I36: 0.64 | J36: 0.64
B37: MR-GMMT/PA03-000000 | C37: NTH SEC MED SHO LOCUM | F37: 9612 | G37: -9612
B38: MR-GMMT/PA04-000000 | C38: NTH SEC MED CONSULT LOC | F38: 15272 | G38: -15272
B39: MR-GMMT/PA06-000000 | C39: NTH SEC MED STAFF GRADE LO | F39: 48991 | G39: -48991
B40: MR-GMMT/PA08-000000 | C40: NTH SEC MED SPEC REG LOC | F40: 13506 | G40: -13506
B41: MR-GMMW/PA02-000000 | C41: WST SEC MED CLIN ASSIS LOC | D41: 38898 | E41: 19450 | F41: 22955 | G41: -3505 | H41: 0.73 | J41: 0.73
B42: MR-GMMW/PA06-000000 | C42: WST SEC MED STAFF GRADE LO | F42: 17190 | G42: -17190 | I42: 1
...
