Workbook

Sheet Introduction
A1: Excel-based non-linear Armington CGE model
B3: This notebook presents a sector-focused 2 import-source Armington CGE model.
B4: The model is specified as a non-linear system of equations. Welfare
B5: analytics involve calculation of equivalent variation, based on Cobb-Douglas
B6: preferences. This involves solving a set of non-linear equations
B7: (given in cells A40..45) for zero values, where the variables
B8: in the system are reported in cells I40..45.
B10: The system of equations are solved using the Excel add-in Solver,
B11: with one of the equation cells specified as the target cell, and the others
B12: as constraints. All are to be solved for zero values (most are excess demand
B13: equations). You may need to adjust the solver options settings (convergence
B14: tolerance etc.) if you have trouble obtaining a solution. Default values for the
B15: solver have already been set. Use the "Calibrate" macro to reset intial solver values
... B26: and Office97 versions of Excel.

Sheet Results Chart
A2: Real Income Effects | E2: Imports in focus sector
A14: benchmark | B14: counterfactual | E14: benchmark | F14: counterfactual
A15: ='The Model'!H44/'The Model'!A36 -> 2008000 | B15: =A15+'The Model'!I50 -> 2013463 | E15: =SUM('The Model'!B5:B6)/SUM('The Model'!B5:B6)*100 -> 100 | F15: =('The Model'!I52+'The Model'!I53)/SUM('The Model'!B5:B6)*100 -> 162.01657
A18: Domestic production in focus sector
A31: benchmark | B31: counterfactual
A32: ='The Model'!H51/'The Model'!H51*100 -> 100 | B32: ='The Model'!I51/'The Model'!H51*100 -> 67.73141

Sheet The Model
B1: Inputs | D1: A sector-focused Armington CGE model
B2: note: use "solver", under the "Tools" menu. Solver settings have been set.
R3: {Optimizer.Reset}
B4: 20000 | C4: Benchmark sales of X1 (i.e. domestic) industry | P4: =$A$41=0 -> FALSE | R4: {Optimizer.Solution_Cell A42}
B5: 20000 | C5: Benchmark sales of country 2 imports (targeted by policy change) | I5: NOTE: sales at internal prices! | P5: =COUNT($I$40:$I$44) -> 5 | R5: {Optimizer.Solution_Goal "Target Value:"}
B6: 20000 | C6: Benchmark sales of country 3 imports | P6: =$A$40=0 -> FALSE | R6: {Optimizer.Variable_Cells I39..I43}
B7: =SUM(B4:B6) -> 60000 | C7: Benchmark total sales (domestic origin and imported) | P7: =$A$42=0 -> FALSE | R7: {Optimizer.Add 1,"A39..A39","=","0"}
P8: =$A$43=0 -> FALSE | R8: {Optimizer.Add 2,"A40..A40","=","0"}
B9: 2000000 | C9: GDP: Total value added in the benchmark data | P9: =$A$44=0 -> FALSE | R9: {Optimizer.Add 3,"A41..A41","=","0"}
B10: 3 | C10: Es1: Elasticity of domestic supply | P10: ={600,1000,0.00001,0.1,FALSE,FALSE,FALSE,2,1,1,0.001,FALSE} -> 600 | R10: {Optimizer.Add 4,"A43..A43","=","0"}
B11: 15 | C11: Es2: Elasticity of country 2 import supply | R11: {Optimizer.Solve}
B12: 15 | C12: Es3: Elasticity of country 3 import supply | R12: {Optimizer.Reset}
B13: 5 | C13: s: | D13: Armington elasticity of substitution | R13: {Optimizer.Solution_Cell C42}
R14: {Optimizer.Solution_Goal "Target Value:"}
B15: 0.25 | C15: t2,0: Initial tariff on country 2 imports | R15: {Optimizer.Variable_Cells H39..H43}
B16: 0.25 | C16: t3,0: Initial tariff on country 3 imports | R16: {Optimizer.Add 1,"C39..C39","=","0"}
B17: 0 | C17: t2,1: Final tariff on country 2 imports | R17: {Optimizer.Add 2,"C40..C40","=","0"}
B18: 0 | C18: t3,1: Final tariff on country 3 imports | R18: {Optimizer.Add 3,"C41..C41","=","0"}
R19: {Optimizer.Add 4,"C43..C43","=","0"}
B20: 0.15 | C20: w2,0: Initial export tax/quota price wedge on country 2 imports | R20: {Optimizer.Solve}
B21: 0.15 | C21: w3,0: Initial export tax/quota price wedge on country 3 imports | R21: {SelectBlock A1..A1}
B22: 0 | C22: w2,1: Final export tax/quota price wedge on country 2 imports
B23: 0 | C23: w3,1: Final export tax/quota price wedge on country 3 imports
B26: Calibrated values
A28: =(B4) -> 20000 | B28: Ks1 : domestic supply constant term | G28: 1 | H28: P1: calibrated domestic product market
A29: =(B5)*(((1+B15+B20))^(B11)) -> 3111361.9 | B29: Ks2 : country 2 import supply constant term | G29: =(1+B15+B20)*G31 -> 1 | H29: P2: calibrated internal price for good 2
A30: =(B6)*(((1+B16+B21))^(B12)) -> 3111361.9 | B30: Ks3 : country 3 import supply constant term | G30: =(1+B16+B21)*G32 -> 1 | H30: P3: calibrated internal price for good 3
A31: =(B7) -> 60000 | B31: KD : composite demand constant term | G31: =(1/((1+B15+B20))) -> 0.71428571 | H31: P2*: calibrated country 2 border price | X31: rho | Y31: 1.1
A32: =(B4/A$31)^(1/B$13) -> 0.80274156 | B32: w1: | C32: CES weight for domestic good | G32: =(1/((1+B16+B21))) -> 0.71428571 | H32: P3*: calibrated country 3 border price | X32: omega | Y32: =1/(1-Y31) -> -10
A33: =(B5/A$31)^(1/B$13) -> 0.80274156 | B33: w2: | C33: CES weight for country 2 import | G33: =(((A32)^B13)+((A33)^B13)+((A34)^B13))^(-1/(B13-1)) -> 1 | H33: PA: calibrated composite good price
A34: =(B6/A$31)^(1/B$13) -> 0.80274156 | B34: w3: | C34: CES weight for country 3 import | G34: =1/B10+1 -> 1.3333333 | H34: y: calibrated CET exponential parameter | M34: =M35/A35 -> 1 | N34: =(1-M34)*100 -> 2.220446e-13
A35: =B9 -> 2000000 | B35: Z: CET constant | G35: =(B4/B9)^(-1/B10) -> 4.6415888 | H35: g1: calibrated CET weight for X1 | M35: =(G35*(B4^G34)+G36*((B9-B4)^G34))^(1/G34) -> 2000000
A36: =B7/(B9+B5*(B15/(1+B15))+B6*(B16/(1+B16))) -> 0.029880478 | B36: q: Income expenditure share | G36: =((B9-B4)/B9)^(-1/B10) -> 1.0033557 | H36: g2: calibrated CET weight for G
B37: Solution values
A38: counterfactual | C38: non-linear problem calculated values | H38: variables in | I38: variables in the | J38: relative
A39: implicit functions | H39: the benchmark | I39: counterfactual | J39: values
A40: =(((A32/I40)^(B$13))*(I$44)*(I$43^(B$13-1)))-(A28*(I40^B10)) -> 0.00030118658 | C40: P1: internal price for the focus sector home good | H40: 1 | I40: 0.87820662 | J40: =I40/H40 -> 0.87820662
A41: =(((A33/I41)^(B$13))*(I$44)*(I$43^(B$13-1)))-(A29*(((I41/((1+B17+B22)))^B11))) -> 0.093242872 | C41: P2: internal price for the focus sector country 2 good | H41: 1 | I41: 0.73763683 | J41: =I41/H41 -> 0.73763683
A42: =(((A34/I42)^(B$13))*(I$44)*(I$43^(B$13-1)))-(A30*(((I42/((1+B18+B23)))^B12))) -> 0.093242874 | C42: P3: internal price for the focus sector country 3 good | H42: 1 | I42: 0.73763683 | J42: =I42/H42 -> 0.73763683
A43: =(((A32)^(B$13))*(I40^(1-B$13))+((A33)^(B$13))*(I41^(1-B$13))+((A34)^(B$13))*(I42^(1-B$13)))^(1/(1-B13))-I43 -> 2.3173605e-09 | C43: PA: focus sector composite good price | H43: 1 | I43: 0.77221289 | J43: =I43/H43 -> 0.77221289
...

Sheet Armington elasticities
B2: Appendix Table 5A.3
B4: Estimated Elasticities of Substitution between Imports
B5: and Domestic Competing Goods (based on U.S. imports)
B8: Sector No. | C8: Elasticity | D8: t-statistic | F8: Sector Name
B10: 1 | C10: 1.22 | D10: 1.63 | F10: Iron and ferroalloy ores mining
B11: 4 | C11: 0.16 | D11: 0.23 | F11: Coal mining
B12: 5 | C12: 0.31 | D12: 2.3 | E12: * | F12: Crude petroleum and natural gas
B13: 6 | C13: 0.97 | D13: 17.84 | E13: * | F13: Stone, sand, and gravel
B14: 8 | C14: 1.13 | D14: 1.78 | F14: Chemical and fertilizer mineral mining
B15: 9 | C15: 1.68 | D15: 3.3 | E15: * | F15: Meat packing plants and prepared meats
B16: 11 | C16: 1 | D16: 33.92 | E16: * | F16: Creamery butter
B17: 12 | C17: 1.99 | D17: 6.74 | E17: * | F17: Cheese, natural and processed
B18: 15 | C18: 0.67 | D18: 3.1 | E18: * | F18: Fluid milk
B19: 17 | C19: 1.16 | D19: 2.84 | E19: * | F19: Flour and other grain mill products
B20: 18 | C20: 0.35 | D20: 8.04 | E20: * | F20: Cereals and flour
B21: 19 | C21: 1.88 | D21: 7.9 | E21: * | F21: Dog, cat, and other pet food
B22: 20 | C22: 1.26 | D22: 6.24 | E22: * | F22: Prepared feeds, n.e.c.
B23: 21 | C23: 0.59 | D23: 1.67 | F23: Wet corn milling
B24: 22 | C24: 1.11 | D24: 7.68 | E24: * | F24: Bread, cake, cookies, and crackers
B25: 24 | C25: 0.13 | D25: 6.57 | E25: * | F25: Chocolate and other confectionary products
B26: 25 | C26: 0.02 | D26: 0.8 | F26: Malt and malt beverages
B27: 26 | C27: 3.49 | D27: 6.95 | E27: * | F27: Wine, brandy, and brandy spirits
B28: 27 | C28: 0.15 | D28: 8.46 | E28: * | F28: Distilled liquor, except brandy
B29: 28 | C29: 1.49 | D29: 4.75 | E29: * | F29: Soft drinks, flavorings, and syrups
B30: 29 | C30: 0.93 | D30: 2.82 | E30: * | F30: Vegetable oil mills
B31: 30 | C31: 0.06 | D31: 0.14 | F31: Animinal and marine fats and oils
B32: 32 | C32: 1.85 | D32: 4.12 | E32: * | F32: Shortening and cooking oils
B33: 33 | C33: 0.27 | D33: 5.16 | E33: * | F33: Sea foods, ice, and pasta
B34: 34 | C34: 0.69 | D34: 1.52 | F34: Cigarettes
B35: 35 | C35: 0.15 | D35: 3.28 | E35: * | F35: Cigars
B36: 36 | C36: 0.99 | D36: 6.21 | E36: * | F36: Tobacco
B37: 37 | C37: 0.54 | D37: 3.96 | E37: * | F37: Yarn, thread, and broadwoven fabric mills
B38: 38 | C38: 0.82 | D38: 7.41 | E38: * | F38: Narrow fabric mills
B39: 39 | C39: 1.21 | D39: 2.55 | E39: * | F39: Floor coverings
B40: 40 | C40: 0.57 | D40: 1.91 | F40: Felt, lace and other textile goods
B41: 41 | C41: 2.53 | D41: 9.8 | E41: * | F41: Hosiery
B42: 43 | C42: 0.45 | D42: 3.55 | E42: * | F42: Apparel made from purchased materials
B43: 44 | C43: 2.18 | D43: 3.74 | E43: * | F43: Housefurnish., textile bags, canvas
B44: 45 | C44: 0.64 | D44: 2.6 | E44: * | F44: Logging camps and logging contractors
B45: 46 | C45: 0.58 | D45: 0.64 | F45: Sawmills
...
