Workbook

Sheet Introduction
A1: Excel-based non-linear Armington model
B3: This notebook presents a simple, 2 import-source Armington model.
B4: The model is specified as a non-linear system of equations. Welfare
B5: analytics involve comparison of both the status quo and the counterfactual to
B6: a free-trade equilibria. This involves solving a set of non-linear equations
B7: (given in cells A39..43 and C39..43) for zero values, where the variables
B8: in the system are reported in cells H39..43 and I39..43.
B10: The system of equations can be solved using the Excel add-in Solver,
B11: with one of the equation cells specified as the target cell, and the others
B12: as constraints. All are to be solved for zero values (as they are excess demand
B13: equations). You may need to adjust the solver options settings (convergence
B14: tolerance etc.) if you have trouble obtaining a solution. Default values for the
B15: solver have already been set. Use the "Calibrate" macro to calibrate the model first.
... B23: and Office97 versions of Excel. Modified June 1998.

Sheet Results Chart
A1: Welfare effects
B2: Old regime | C2: New Regime
A3: welfare triangle | B3: ='imperfect substutes model'!G50 -> -226.67627 | C3: ='imperfect substutes model'!H50 -> -421.88847
A4: terms-of-trade effects | B4: ='imperfect substutes model'!G51 -> 54.120012 | C4: ='imperfect substutes model'!H51 -> 74.069605
A5: quota rent transfers | B5: ='imperfect substutes model'!G52 -> 0 | C5: ='imperfect substutes model'!H52 -> -141.90699
A6: secondary effects | B6: ='imperfect substutes model'!G53 -> * | C6: ='imperfect substutes model'!H53 -> 7.4050485
A7: Total | B7: =SUM(B3:B6) -> -172.55626 | C7: =SUM(C3:C6) -> -482.32081

Sheet imperfect substutes model
B1: Inputs | D1: Non-linear Armington model
B2: note: use "solver", under the "Tools" menu. Solver settings have been set.
R3: {Optimizer.Reset}
B4: 200 | C4: Benchmark sales of X1 (i.e. domestic) industry | P4: =$A$41=0 -> FALSE | R4: {Optimizer.Solution_Cell A42}
B5: 1000 | C5: Benchmark sales of country 2 imports (targeted by policy change) | I5: NOTE: sales at internal prices! | P5: =COUNT($I$40:$I$44) -> 5 | R5: {Optimizer.Solution_Goal "Target Value:"}
B6: 200 | C6: Benchmark sales of country 3 imports | P6: =$A$40=0 -> FALSE | R6: {Optimizer.Variable_Cells I39..I43}
B7: =SUM(B4:B6) -> 1400 | C7: Benchmark total sales (domestic origin and imported) | P7: =$A$42=0 -> FALSE | R7: {Optimizer.Add 1,"A39..A39","=","0"}
P8: =$A$43=0 -> FALSE | R8: {Optimizer.Add 2,"A40..A40","=","0"}
B9: 1.5 | C9: NA: Composite elasticity of demand | P9: =$A$44=0 -> FALSE | R9: {Optimizer.Add 3,"A41..A41","=","0"}
B10: 3 | C10: Es1: Elasticity of domestic supply | P10: ={600,1000,0.00001,0.1,FALSE,FALSE,FALSE,2,1,1,0.001,FALSE} -> 600 | R10: {Optimizer.Add 4,"A43..A43","=","0"}
B11: 5 | C11: Es2: Elasticity of country 2 import supply | R11: {Optimizer.Solve}
B12: 5 | C12: Es3: Elasticity of country 3 import supply | R12: {Optimizer.Reset}
B13: 5 | C13: s: | D13: Elasticity of substitution | R13: {Optimizer.Solution_Cell C42}
R14: {Optimizer.Solution_Goal "Target Value:"}
B15: 0.25 | C15: t2,0: Initial tariff on country 2 imports | R15: {Optimizer.Variable_Cells H39..H43}
B16: 0.25 | C16: t3,0: Initial tariff on country 3 imports | R16: {Optimizer.Add 1,"C39..C39","=","0"}
B17: 0.25 | C17: t2,1: Final tariff on country 2 imports | R17: {Optimizer.Add 2,"C40..C40","=","0"}
B18: 0.25 | C18: t3,1: Final tariff on country 3 imports | R18: {Optimizer.Add 3,"C41..C41","=","0"}
R19: {Optimizer.Add 4,"C43..C43","=","0"}
B20: 0 | C20: w2,0: Initial export tax/quota price wedge on country 2 imports | R20: {Optimizer.Solve}
B21: 0 | C21: w3,0: Initial export tax/quota price wedge on country 3 imports | R21: {SelectBlock A1..A1}
B22: 0.25 | C22: w2,1: Final export tax/quota price wedge on country 2 imports
B23: 0 | C23: w3,1: Final export tax/quota price wedge on country 3 imports
B26: Calibrated values
A28: =(B4) -> 200 | B28: Ks1 : domestic supply constant term | G28: 1 | H28: P1: calibrated domestic product market
A29: =(B5)*(((1+B15+B20))^(B11)) -> 3051.7578 | B29: Ks2 : country 2 import supply constant term | G29: =(1+B15+B20)*G31 -> 1 | H29: P2: calibrated internal price for good 2
A30: =(B6)*(((1+B16+B21))^(B12)) -> 610.35156 | B30: Ks3 : country 3 import supply constant term | G30: =(1+B16+B21)*G32 -> 1 | H30: P3: calibrated internal price for good 3
A31: =(B7) -> 1400 | B31: KD : composite demand constant term | G31: =(1/((1+B15+B20))) -> 0.8 | H31: P2*: calibrated country 2 border price
A32: =(B4/A$31)^(1/B$13) -> 0.67761091 | B32: w1: | C32: CES weight for domestic good | G32: =(1/((1+B16+B21))) -> 0.8 | H32: P3*: calibrated country 3 border price
A33: =(B5/A$31)^(1/B$13) -> 0.93491988 | B33: w2: | C33: CES weight for country 2 import | G33: =(((A32)^B13)+((A33)^B13)+((A34)^B13))^(-1/(B13-1)) -> 1 | H33: PA: calibrated composite good price
A34: =(B6/A$31)^(1/B$13) -> 0.67761091 | B34: w3: | C34: CES weight for country 3 import
B37: Counterfactual solution values
A38: counterfactual | C38: free-trade in X2 | H38: internal prices and Y
A39: Excess demands | C39: excess demands | H39: free trade in X2 | I39: counterfactual
A40: =(((A32/I40)^(B$13))*(I$44)*(I$43^(B$13-1)))-(A28*(I40^B10)) -> -9.1820908e-08 | C40: =(((A32/H40)^(B$13))*(H$44)*(H$43^(B$13-1)))-(A28*(H40^B10)) -> 0 | E40: P1: domestic product market | H40: 0.94398997 | I40: 1.0433767 | N40: 1
A41: =(((A33/I41)^(B$13))*(I$44)*(I$43^(B$13-1)))-(A29*(((I41/((1+B17+B22)))^B11))) -> -8.3927171e-07 | C41: =(((A33/H41)^(B$13))*(H$44)*(H$43^(B$13-1)))-(A29*(((H41/((1)*(1)))^B11))) -> 2.2737368e-13 | E41: P2: good 2 market | H41: 0.85412001 | I41: 1.1332965 | N41: 1
A42: =(((A34/I42)^(B$13))*(I$44)*(I$43^(B$13-1)))-(A30*(((I42/((1+B18+B23)))^B12))) -> -1.6414859e-07 | C42: =(((A34/H42)^(B$13))*(H$44)*(H$43^(B$13-1)))-(A30*(((H42/((1+B18+B23)))^B12))) -> -5.6843419e-14 | E42: P3: good 3 market | H42: 0.9549352 | I42: 1.0345534 | N42: 1
A43: =(((A32)^(B$13))*(I40^(1-B$13))+((A33)^(B$13))*(I41^(1-B$13))+((A34)^(B$13))*(I42^(1-B$13)))^(1/(1-B13))-I43 -> -2.6128211e-11 | C43: =(((A32)^(B$13))*(H40^(1-B$13))+((A33)^(B$13))*(H41^(1-B$13))+((A34)^(B$13))*(H42^(1-B$13)))^(1/(1-B13))-H43 -> 0 | E43: PA: composite good price | H43: 0.87656189 | I43: 1.1019229 | N43: 1
A44: =(A31)*(I43^(-B9+1))-I44 -> 8.6279215e-08 | C44: =(A31)*(H43^(-B9+1))-H44 -> 0 | E44: Y: total expenditure | H44: 1495.329 | I44: 1333.6824 | N44: =(B7) -> 1400
B46: Results
...

Sheet Armington elasticities
B2: Appendix Table 5A.3
B4: Estimated Elasticities of Substitution between Imports
B5: and Domestic Competing Goods (based on U.S. imports)
B8: Sector No. | C8: Elasticity | D8: t-statistic | F8: Sector Name
B10: 1 | C10: 1.22 | D10: 1.63 | F10: Iron and ferroalloy ores mining
B11: 4 | C11: 0.16 | D11: 0.23 | F11: Coal mining
B12: 5 | C12: 0.31 | D12: 2.3 | E12: * | F12: Crude petroleum and natural gas
B13: 6 | C13: 0.97 | D13: 17.84 | E13: * | F13: Stone, sand, and gravel
B14: 8 | C14: 1.13 | D14: 1.78 | F14: Chemical and fertilizer mineral mining
B15: 9 | C15: 1.68 | D15: 3.3 | E15: * | F15: Meat packing plants and prepared meats
B16: 11 | C16: 1 | D16: 33.92 | E16: * | F16: Creamery butter
B17: 12 | C17: 1.99 | D17: 6.74 | E17: * | F17: Cheese, natural and processed
B18: 15 | C18: 0.67 | D18: 3.1 | E18: * | F18: Fluid milk
B19: 17 | C19: 1.16 | D19: 2.84 | E19: * | F19: Flour and other grain mill products
B20: 18 | C20: 0.35 | D20: 8.04 | E20: * | F20: Cereals and flour
B21: 19 | C21: 1.88 | D21: 7.9 | E21: * | F21: Dog, cat, and other pet food
B22: 20 | C22: 1.26 | D22: 6.24 | E22: * | F22: Prepared feeds, n.e.c.
B23: 21 | C23: 0.59 | D23: 1.67 | F23: Wet corn milling
B24: 22 | C24: 1.11 | D24: 7.68 | E24: * | F24: Bread, cake, cookies, and crackers
B25: 24 | C25: 0.13 | D25: 6.57 | E25: * | F25: Chocolate and other confectionary products
B26: 25 | C26: 0.02 | D26: 0.8 | F26: Malt and malt beverages
B27: 26 | C27: 3.49 | D27: 6.95 | E27: * | F27: Wine, brandy, and brandy spirits
B28: 27 | C28: 0.15 | D28: 8.46 | E28: * | F28: Distilled liquor, except brandy
B29: 28 | C29: 1.49 | D29: 4.75 | E29: * | F29: Soft drinks, flavorings, and syrups
B30: 29 | C30: 0.93 | D30: 2.82 | E30: * | F30: Vegetable oil mills
B31: 30 | C31: 0.06 | D31: 0.14 | F31: Animinal and marine fats and oils
B32: 32 | C32: 1.85 | D32: 4.12 | E32: * | F32: Shortening and cooking oils
B33: 33 | C33: 0.27 | D33: 5.16 | E33: * | F33: Sea foods, ice, and pasta
B34: 34 | C34: 0.69 | D34: 1.52 | F34: Cigarettes
B35: 35 | C35: 0.15 | D35: 3.28 | E35: * | F35: Cigars
B36: 36 | C36: 0.99 | D36: 6.21 | E36: * | F36: Tobacco
B37: 37 | C37: 0.54 | D37: 3.96 | E37: * | F37: Yarn, thread, and broadwoven fabric mills
B38: 38 | C38: 0.82 | D38: 7.41 | E38: * | F38: Narrow fabric mills
B39: 39 | C39: 1.21 | D39: 2.55 | E39: * | F39: Floor coverings
B40: 40 | C40: 0.57 | D40: 1.91 | F40: Felt, lace and other textile goods
B41: 41 | C41: 2.53 | D41: 9.8 | E41: * | F41: Hosiery
B42: 43 | C42: 0.45 | D42: 3.55 | E42: * | F42: Apparel made from purchased materials
B43: 44 | C43: 2.18 | D43: 3.74 | E43: * | F43: Housefurnish., textile bags, canvas
B44: 45 | C44: 0.64 | D44: 2.6 | E44: * | F44: Logging camps and logging contractors
B45: 46 | C45: 0.58 | D45: 0.64 | F45: Sawmills
...
