Workbook

Sheet Class 1
C3: Social Science
C4: 0.1 | D4: 0.1 | E4: 0.15 | F4: 0.2 | G4: 0.1 | H4: 0.15 | I4: 0.2 | K4: Spelling | S4: Math
A5: Last Name | B5: First Name | C5: Pre-Test | D5: Quiz 1 | E5: Writen Report | F5: Mid-Term | G5: Quiz 2 | H5: Oral Report | I5: Final | K5: Week 1 | L5: Week 2 | M5: Week 3 | N5: Week 4 | O5: Week 5 | P5: Week 6 | Q5: Week 7 | S5: Week 1 | T5: Week 2 | U5: Week 3 | V5: Week 4 | W5: Week 5 | X5: Week 6 | Y5: Week 7
A6: Aarons | B6: Karly | C6: 90 | D6: 90 | E6: 95 | F6: 100 | G6: 100 | H6: 100 | I6: 100 | K6: 95 | L6: 98 | M6: 100 | N6: 100 | O6: 100 | P6: 98 | Q6: 99 | S6: =C6-7 -> 83 | T6: =D6-7 -> 83 | U6: =E6-7 -> 88 | V6: =F6-7 -> 93 | W6: =G6-7 -> 93 | X6: =H6-7 -> 93 | Y6: =I6-7 -> 93
A7: Benjamin | B7: Darwin | C7: 91 | D7: 67 | E7: 72 | F7: 75 | G7: 78 | H7: 82 | I7: 90 | K7: =C7-3 -> 88 | L7: =D7-3 -> 64 | M7: =E7-3 -> 69 | N7: =F7-3 -> 72 | O7: =G7-3 -> 75 | P7: =H7-3 -> 79 | Q7: =I7-3 -> 87 | S7: =C7-7 -> 84 | T7: =D7-7 -> 60 | U7: =E7-7 -> 65 | V7: =F7-7 -> 68 | W7: =G7-7 -> 71 | X7: =H7-7 -> 75 | Y7: =I7-7 -> 83
A8: Donegal | B8: Micheal | C8: 87 | D8: 58 | E8: 65 | F8: 72 | G8: 78 | H8: 82 | I8: 85 | K8: =C8-3 -> 84 | L8: =D8-3 -> 55 | M8: =E8-3 -> 62 | N8: =F8-3 -> 69 | O8: =G8-3 -> 75 | P8: =H8-3 -> 79 | Q8: =I8-3 -> 82 | S8: =C8-7 -> 80 | T8: =D8-7 -> 51 | U8: =E8-7 -> 58 | V8: =F8-7 -> 65 | W8: =G8-7 -> 71 | X8: =H8-7 -> 75 | Y8: =I8-7 -> 78
A9: Darwin | B9: Dameon | C9: 78 | D9: 65 | E9: 68 | F9: 75 | G9: 81 | H9: 86 | I9: 92 | K9: =C9-3 -> 75 | L9: =D9-3 -> 62 | M9: =E9-3 -> 65 | N9: =F9-3 -> 72 | O9: =G9-3 -> 78 | P9: =H9-3 -> 83 | Q9: =I9-3 -> 89 | S9: =C9-7 -> 71 | T9: =D9-7 -> 58 | U9: =E9-7 -> 61 | V9: =F9-7 -> 68 | W9: =G9-7 -> 74 | X9: =H9-7 -> 79 | Y9: =I9-7 -> 85
A10: Farmer | B10: Jessica | C10: 85 | D10: 87 | E10: 89 | F10: 91 | G10: 90 | H10: 95 | I10: 97 | K10: =C10-3 -> 82 | L10: =D10-3 -> 84 | M10: =E10-3 -> 86 | N10: =F10-3 -> 88 | O10: =G10-3 -> 87 | P10: =H10-3 -> 92 | Q10: =I10-3 -> 94 | S10: =C10-7 -> 78 | T10: =D10-7 -> 80 | U10: =E10-7 -> 82 | V10: =F10-7 -> 84 | W10: =G10-7 -> 83 | X10: =H10-7 -> 88 | Y10: =I10-7 -> 90
A11: Green | B11: Rachel | C11: 89 | D11: 95 | E11: 78 | F11: 89 | G11: 94 | H11: 88 | I11: 95 | K11: =C11-3 -> 86 | L11: =D11-3 -> 92 | M11: =E11-3 -> 75 | N11: =F11-3 -> 86 | O11: =G11-3 -> 91 | P11: =H11-3 -> 85 | Q11: =I11-3 -> 92 | S11: =C11-7 -> 82 | T11: =D11-7 -> 88 | U11: =E11-7 -> 71 | V11: =F11-7 -> 82 | W11: =G11-7 -> 87 | X11: =H11-7 -> 81 | Y11: =I11-7 -> 88
A12: Holiday | B12: Tiffany | C12: 75 | D12: 83 | E12: 89 | F12: 85 | G12: 83 | H12: 87 | I12: 91 | K12: =C12-3 -> 72 | L12: =D12-3 -> 80 | M12: =E12-3 -> 86 | N12: =F12-3 -> 82 | O12: =G12-3 -> 80 | P12: =H12-3 -> 84 | Q12: =I12-3 -> 88 | S12: =C12-7 -> 68 | T12: =D12-7 -> 76 | U12: =E12-7 -> 82 | V12: =F12-7 -> 78 | W12: =G12-7 -> 76 | X12: =H12-7 -> 80 | Y12: =I12-7 -> 84
A13: Jones | B13: Kaci Lynn | C13: 81 | D13: 96 | E13: 97 | F13: 99 | G13: 96 | H13: 99 | I13: 100 | K13: =C13-3 -> 78 | L13: =D13-3 -> 93 | M13: =E13-3 -> 94 | N13: =F13-3 -> 96 | O13: =G13-3 -> 93 | P13: =H13-3 -> 96 | Q13: =I13-3 -> 97 | S13: =C13-7 -> 74 | T13: =D13-7 -> 89 | U13: =E13-7 -> 90 | V13: =F13-7 -> 92 | W13: =G13-7 -> 89 | X13: =H13-7 -> 92 | Y13: =I13-7 -> 93
A14: Jones | B14: Staci Lee | C14: 85 | D14: 95 | E14: 96 | F14: 98 | G14: 97 | H14: 98 | I14: 99 | K14: =C14-3 -> 82 | L14: =D14-3 -> 92 | M14: =E14-3 -> 93 | N14: =F14-3 -> 95 | O14: =G14-3 -> 94 | P14: =H14-3 -> 95 | Q14: =I14-3 -> 96 | S14: =C14-7 -> 78 | T14: =D14-7 -> 88 | U14: =E14-7 -> 89 | V14: =F14-7 -> 91 | W14: =G14-7 -> 90 | X14: =H14-7 -> 91 | Y14: =I14-7 -> 92
A15: Konston | B15: Heidi | C15: 89 | D15: 72 | E15: 74 | F15: 75 | G15: 74 | H15: 76 | I15: 81 | K15: =C15-3 -> 86 | L15: =D15-3 -> 69 | M15: =E15-3 -> 71 | N15: =F15-3 -> 72 | O15: =G15-3 -> 71 | P15: =H15-3 -> 73 | Q15: =I15-3 -> 78 | S15: =C15-7 -> 82 | T15: =D15-7 -> 65 | U15: =E15-7 -> 67 | V15: =F15-7 -> 68 | W15: =G15-7 -> 67 | X15: =H15-7 -> 69 | Y15: =I15-7 -> 74
A16: Klass | B16: Renee | C16: 58 | D16: 55 | E16: 54 | F16: 57 | G16: 58 | H16: 60 | I16: 59 | K16: 40 | L16: 42 | M16: 45 | N16: =F16-3 -> 54 | O16: 44 | P16: 43 | Q16: =I16-3 -> 56 | S16: 60 | T16: 45 | U16: 65 | V16: =F16-7 -> 50 | W16: =G16-7 -> 51 | X16: =H16-7 -> 53 | Y16: =I16-7 -> 52
A17: Lamb | B17: Brooke | C17: 64 | D17: 97 | E17: 89 | F17: 95 | G17: 88 | H17: 87 | I17: 91 | K17: =C17-3 -> 61 | L17: =D17-3 -> 94 | M17: =E17-3 -> 86 | N17: =F17-3 -> 92 | O17: =G17-3 -> 85 | P17: =H17-3 -> 84 | Q17: =I17-3 -> 88 | S17: =C17-7 -> 57 | T17: =D17-7 -> 90 | U17: =E17-7 -> 82 | V17: =F17-7 -> 88 | W17: =G17-7 -> 81 | X17: =H17-7 -> 80 | Y17: =I17-7 -> 84
A18: Marcus | B18: Kevin | C18: 63 | D18: 83 | E18: 85 | F18: 89 | G18: 88 | H18: 87 | I18: 91 | K18: =C18-3 -> 60 | L18: =D18-3 -> 80 | M18: =E18-3 -> 82 | N18: =F18-3 -> 86 | O18: =G18-3 -> 85 | P18: =H18-3 -> 84 | Q18: =I18-3 -> 88 | S18: =C18-7 -> 56 | T18: =D18-7 -> 76 | U18: =E18-7 -> 78 | V18: =F18-7 -> 82 | W18: =G18-7 -> 81 | X18: =H18-7 -> 80 | Y18: =I18-7 -> 84
A19: Matthews | B19: Cory | C19: 88 | D19: 88 | E19: 87 | F19: 95 | G19: 84 | H19: 85 | I19: 96 | K19: =C19-3 -> 85 | L19: =D19-3 -> 85 | M19: =E19-3 -> 84 | N19: =F19-3 -> 92 | O19: =G19-3 -> 81 | P19: =H19-3 -> 82 | Q19: =I19-3 -> 93 | S19: =C19-7 -> 81 | T19: =D19-7 -> 81 | U19: =E19-7 -> 80 | V19: =F19-7 -> 88 | W19: =G19-7 -> 77 | X19: =H19-7 -> 78 | Y19: =I19-7 -> 89
A20: Parker | B20: William | C20: 75 | D20: 88 | E20: 91 | F20: 82 | G20: 73 | H20: 74 | I20: 91 | K20: 83 | L20: 85 | M20: 81 | N20: 84 | O20: 88 | P20: 85 | Q20: 83 | S20: 78 | T20: 79 | U20: 69 | V20: 72 | W20: =G20-7 -> 66 | X20: 80 | Y20: =I20-7 -> 84
A21: Russo | B21: Nicholas | C21: 80 | D21: 82 | E21: 86 | F21: 92 | G21: 80 | H21: 75 | I21: 63 | K21: =C21-3 -> 77 | L21: =D21-3 -> 79 | M21: =E21-3 -> 83 | N21: =F21-3 -> 89 | O21: =G21-3 -> 77 | P21: =H21-3 -> 72 | Q21: =I21-3 -> 60 | S21: =C21-7 -> 73 | T21: =D21-7 -> 75 | U21: =E21-7 -> 79 | V21: =F21-7 -> 85 | W21: =G21-7 -> 73 | X21: =H21-7 -> 68 | Y21: =I21-7 -> 56
A22: Sanders | B22: Seth | C22: 89 | D22: 82 | E22: 65 | F22: 95 | G22: 92 | H22: 95 | I22: 96 | K22: =C22-3 -> 86 | L22: =D22-3 -> 79 | M22: =E22-3 -> 62 | N22: =F22-3 -> 92 | O22: =G22-3 -> 89 | P22: =H22-3 -> 92 | Q22: =I22-3 -> 93 | S22: =C22-7 -> 82 | T22: =D22-7 -> 75 | U22: =E22-7 -> 58 | V22: =F22-7 -> 88 | W22: =G22-7 -> 85 | X22: =H22-7 -> 88 | Y22: =I22-7 -> 89
A23: Shafer | B23: Anastacia | C23: 86 | D23: 87 | E23: 78 | F23: 75 | G23: 80 | H23: 79 | I23: 81 | K23: =C23-3 -> 83 | L23: =D23-3 -> 84 | M23: =E23-3 -> 75 | N23: =F23-3 -> 72 | O23: =G23-3 -> 77 | P23: =H23-3 -> 76 | Q23: =I23-3 -> 78 | S23: =C23-7 -> 79 | T23: =D23-7 -> 80 | U23: =E23-7 -> 71 | V23: =F23-7 -> 68 | W23: =G23-7 -> 73 | X23: =H23-7 -> 72 | Y23: =I23-7 -> 74
A24: Walker | B24: Xavier | C24: 89 | D24: 93 | E24: 92 | F24: 92 | G24: 94 | H24: 92 | I24: 95 | K24: =C24-3 -> 86 | L24: =D24-3 -> 90 | M24: =E24-3 -> 89 | N24: =F24-3 -> 89 | O24: =G24-3 -> 91 | P24: =H24-3 -> 89 | Q24: =I24-3 -> 92 | S24: =C24-7 -> 82 | T24: =D24-7 -> 86 | U24: =E24-7 -> 85 | V24: =F24-7 -> 85 | W24: =G24-7 -> 87 | X24: =H24-7 -> 85 | Y24: =I24-7 -> 88
A25: Williams | B25: Janey | C25: 82 | D25: 82 | E25: 86 | F25: 85 | G25: 87 | H25: 88 | I25: 91 | K25: =C25-3 -> 79 | L25: =D25-3 -> 79 | M25: =E25-3 -> 83 | N25: =F25-3 -> 82 | O25: =G25-3 -> 84 | P25: =H25-3 -> 85 | Q25: =I25-3 -> 88 | S25: =C25-7 -> 75 | T25: =D25-7 -> 75 | U25: =E25-7 -> 79 | V25: =F25-7 -> 78 | W25: =G25-7 -> 80 | X25: =H25-7 -> 81 | Y25: =I25-7 -> 84
A26: Zanders | B26: Cassandra | C26: 75 | D26: 63 | E26: 62 | F26: 70 | G26: 73 | H26: 76 | I26: 79 | K26: =C26-3 -> 72 | L26: =D26-3 -> 60 | M26: =E26-3 -> 59 | N26: =F26-3 -> 67 | O26: =G26-3 -> 70 | P26: =H26-3 -> 73 | Q26: =I26-3 -> 76 | S26: =C26-7 -> 68 | T26: =D26-7 -> 56 | U26: =E26-7 -> 55 | V26: =F26-7 -> 63 | W26: =G26-7 -> 66 | X26: =H26-7 -> 69 | Y26: =I26-7 -> 72
A38: Students | C38: Grade
A39: Last Name | B39: First Name | C39: 1
A40: Aarons | B40: Karly | C40: =C6*0.1+D6*0.1+E6*0.15+F6*0.2+G6*0.1+H6*0.15+I6*0.2 -> 97.25 | D40: A+
A41: Benjamin | B41: Darwin | C41: =C7*0.1+D7*0.1+E7*0.15+F7*0.2+G7*0.1+H7*0.15+I7*0.2 -> 79.7 | D41: B- | F41: Scale
A42: Donegal | B42: Micheal | C42: =C8*0.1+D8*0.1+E8*0.15+F8*0.2+G8*0.1+H8*0.15+I8*0.2 -> 75.75 | D42: C | F42: 97-100 | G42: A+
A43: Darwin | B43: Dameon | C43: =C9*0.1+D9*0.1+E9*0.15+F9*0.2+G9*0.1+H9*0.15+I9*0.2 -> 78.9 | D43: C+ | F43: 94-96 | G43: A
A44: Farmer | B44: Jessica | C44: =C10*0.1+D10*0.1+E10*0.15+F10*0.2+G10*0.1+H10*0.15+I10*0.2 -> 91.4 | D44: A- | F44: 90-93 | G44: A-
A45: Green | B45: Rachel | C45: =C11*0.1+D11*0.1+E11*0.15+F11*0.2+G11*0.1+H11*0.15+I11*0.2 -> 89.5 | D45: A- | F45: 87-89 | G45: B+
A46: Holiday | B46: Tiffany | C46: =C12*0.1+D12*0.1+E12*0.15+F12*0.2+G12*0.1+H12*0.15+I12*0.2 -> 85.7 | D46: B | F46: 84-86 | G46: B
A47: Jones | B47: Kaci Lynn | C47: =C13*0.1+D13*0.1+E13*0.15+F13*0.2+G13*0.1+H13*0.15+I13*0.2 -> 96.5 | D47: A+ | F47: 80-83 | G47: B-
A48: Jones | B48: Staci Lee | C48: =C14*0.1+D14*0.1+E14*0.15+F14*0.2+G14*0.1+H14*0.15+I14*0.2 -> 96.2 | D48: A+ | F48: 77-79 | G48: C+
A49: Konston | B49: Heidi | C49: =C15*0.1+D15*0.1+E15*0.15+F15*0.2+G15*0.1+H15*0.15+I15*0.2 -> 77.2 | D49: C | F49: 74-76 | G49: C
A50: Klass | B50: Renee | C50: =C16*0.1+D16*0.1+E16*0.15+F16*0.2+G16*0.1+H16*0.15+I16*0.2 -> 57.4 | D50: D | F50: 70-73 | G50: C-
A51: Lamb | B51: Brooke | C51: =C17*0.1+D17*0.1+E17*0.15+F17*0.2+G17*0.1+H17*0.15+I17*0.2 -> 88.5 | D51: A- | F51: 67-69 | G51: D+
A52: Marcus | B52: Kevin | C52: =C18*0.1+D18*0.1+E18*0.15+F18*0.2+G18*0.1+H18*0.15+I18*0.2 -> 85.2 | D52: B+ | F52: 64-66 | G52: D
A53: Matthews | B53: Cory | C53: =C19*0.1+D19*0.1+E19*0.15+F19*0.2+G19*0.1+H19*0.15+I19*0.2 -> 90 | D53: A- | F53: 60-63 | G53: D-
...

Sheet Class 2
C3: ='Class 1'!C3 -> Social Science
C4: ='Class 1'!C4 -> 0.1 | D4: ='Class 1'!D4 -> 0.1 | E4: ='Class 1'!E4 -> 0.15 | F4: ='Class 1'!F4 -> 0.2 | G4: ='Class 1'!G4 -> 0.1 | H4: ='Class 1'!H4 -> 0.15 | I4: ='Class 1'!I4 -> 0.2
A5: ='Class 1'!A5 -> Last Name | B5: ='Class 1'!B5 -> First Name | C5: ='Class 1'!C5 -> Pre-Test | D5: ='Class 1'!D5 -> Quiz 1 | E5: ='Class 1'!E5 -> Writen Report | F5: ='Class 1'!F5 -> Mid-Term | G5: ='Class 1'!G5 -> Quiz 2 | H5: ='Class 1'!H5 -> Oral Report | I5: ='Class 1'!I5 -> Final
A6: ='Class 1'!A6 -> Aarons | B6: ='Class 1'!B6 -> Karly | C6: ='Class 1'!C6 -> 90 | D6: ='Class 1'!D6 -> 90 | E6: ='Class 1'!E6 -> 95 | F6: ='Class 1'!F6 -> 100 | G6: ='Class 1'!G6 -> 100 | H6: ='Class 1'!H6-3 -> 97 | I6: ='Class 1'!I6 -> 100
A7: ='Class 1'!A7 -> Benjamin | B7: ='Class 1'!B7 -> Darwin | C7: ='Class 1'!C7-15 -> 76 | D7: ='Class 1'!D7-20 -> 47 | E7: ='Class 1'!E7-30 -> 42 | F7: ='Class 1'!F7-40 -> 35 | G7: ='Class 1'!G7-50 -> 28 | H7: ='Class 1'!H7-50 -> 32 | I7: ='Class 1'!I7-50 -> 40
A8: ='Class 1'!A8 -> Donegal | B8: ='Class 1'!B8 -> Micheal | C8: ='Class 1'!C8-15 -> 72 | D8: ='Class 1'!D8-20 -> 38 | E8: ='Class 1'!E8-30 -> 35 | F8: ='Class 1'!F8-40 -> 32 | G8: ='Class 1'!G8-50 -> 28 | H8: ='Class 1'!H8-50 -> 32 | I8: ='Class 1'!I8-50 -> 35
A9: ='Class 1'!A9 -> Darwin | B9: ='Class 1'!B9 -> Dameon | C9: ='Class 1'!C9-15 -> 63 | D9: ='Class 1'!D9-20 -> 45 | E9: ='Class 1'!E9-30 -> 38 | F9: ='Class 1'!F9-40 -> 35 | G9: ='Class 1'!G9-50 -> 31 | H9: ='Class 1'!H9-50 -> 36 | I9: ='Class 1'!I9-50 -> 42
A10: ='Class 1'!A10 -> Farmer | B10: ='Class 1'!B10 -> Jessica | C10: ='Class 1'!C10-15 -> 70 | D10: ='Class 1'!D10-20 -> 67 | E10: ='Class 1'!E10-30 -> 59 | F10: ='Class 1'!F10-40 -> 51 | G10: ='Class 1'!G10-50 -> 40 | H10: ='Class 1'!H10-50 -> 45 | I10: ='Class 1'!I10-50 -> 47
A11: ='Class 1'!A11 -> Green | B11: ='Class 1'!B11 -> Rachel | C11: ='Class 1'!C11-15 -> 74 | D11: ='Class 1'!D11-20 -> 75 | E11: ='Class 1'!E11-30 -> 48 | F11: ='Class 1'!F11-40 -> 49 | G11: ='Class 1'!G11-50 -> 44 | H11: ='Class 1'!H11-50 -> 38 | I11: ='Class 1'!I11-50 -> 45
A12: ='Class 1'!A12 -> Holiday | B12: ='Class 1'!B12 -> Tiffany | C12: ='Class 1'!C12-15 -> 60 | D12: ='Class 1'!D12-20 -> 63 | E12: ='Class 1'!E12-30 -> 59 | F12: ='Class 1'!F12-40 -> 45 | G12: ='Class 1'!G12-50 -> 33 | H12: ='Class 1'!H12-50 -> 37 | I12: ='Class 1'!I12-50 -> 41
A13: ='Class 1'!A13 -> Jones | B13: ='Class 1'!B13 -> Kaci Lynn | C13: ='Class 1'!C13-15 -> 66 | D13: ='Class 1'!D13-20 -> 76 | E13: 78 | F13: 79 | G13: 81 | H13: 82 | I13: 83
A14: ='Class 1'!A14 -> Jones | B14: ='Class 1'!B14 -> Staci Lee | C14: ='Class 1'!C14-10 -> 75 | D14: ='Class 1'!D14-10 -> 85 | E14: ='Class 1'!E14-10 -> 86 | F14: ='Class 1'!F14-10 -> 88 | G14: ='Class 1'!G14-10 -> 87 | H14: ='Class 1'!H14-10 -> 88 | I14: ='Class 1'!I14-10 -> 89
A15: ='Class 1'!A15 -> Konston | B15: ='Class 1'!B15 -> Heidi | C15: ='Class 1'!C15-15 -> 74 | D15: ='Class 1'!D15-20 -> 52 | E15: ='Class 1'!E15-30 -> 44 | F15: ='Class 1'!F15-40 -> 35 | G15: ='Class 1'!G15-50 -> 24 | H15: ='Class 1'!H15-50 -> 26 | I15: ='Class 1'!I15-50 -> 31
A16: ='Class 1'!A16 -> Klass | B16: ='Class 1'!B16 -> Renee | C16: ='Class 1'!C16-15 -> 43 | D16: ='Class 1'!D16-20 -> 35 | E16: ='Class 1'!E16-30 -> 24 | F16: ='Class 1'!F16-40 -> 17 | G16: ='Class 1'!G16-40 -> 18 | H16: ='Class 1'!H16-40 -> 20 | I16: ='Class 1'!I16-40 -> 19
A17: ='Class 1'!A17 -> Lamb | B17: ='Class 1'!B17 -> Brooke | C17: ='Class 1'!C17-15 -> 49 | D17: ='Class 1'!D17-20 -> 77 | E17: 77 | F17: 80 | G17: 75 | H17: 72 | I17: 70
A18: ='Class 1'!A18 -> Marcus | B18: ='Class 1'!B18 -> Kevin | C18: ='Class 1'!C18-15 -> 48 | D18: ='Class 1'!D18-20 -> 63 | E18: ='Class 1'!E18-30 -> 55 | F18: ='Class 1'!F18-40 -> 49 | G18: ='Class 1'!G18-50 -> 38 | H18: ='Class 1'!H18-50 -> 37 | I18: ='Class 1'!I18-50 -> 41
A19: ='Class 1'!A19 -> Matthews | B19: ='Class 1'!B19 -> Cory | C19: ='Class 1'!C19-15 -> 73 | D19: ='Class 1'!D19-20 -> 68 | E19: ='Class 1'!E19-30 -> 57 | F19: ='Class 1'!F19-40 -> 55 | G19: ='Class 1'!G19-50 -> 34 | H19: ='Class 1'!H19-50 -> 35 | I19: ='Class 1'!I19-50 -> 46
A20: ='Class 1'!A20 -> Parker | B20: ='Class 1'!B20 -> William | C20: ='Class 1'!C20-15 -> 60 | D20: ='Class 1'!D20-20 -> 68 | E20: ='Class 1'!E20-30 -> 61 | F20: ='Class 1'!F20-40 -> 42 | G20: ='Class 1'!G20-50 -> 23 | H20: ='Class 1'!H20-50 -> 24 | I20: ='Class 1'!I20-50 -> 41
A21: ='Class 1'!A21 -> Russo | B21: ='Class 1'!B21 -> Nicholas | C21: ='Class 1'!C21 -> 80 | D21: ='Class 1'!D21 -> 82 | E21: ='Class 1'!E21 -> 86 | F21: ='Class 1'!F21 -> 92 | G21: ='Class 1'!G21 -> 80 | H21: ='Class 1'!H21 -> 75 | I21: ='Class 1'!I21 -> 63
A22: ='Class 1'!A22 -> Sanders | B22: ='Class 1'!B22 -> Seth | C22: ='Class 1'!C22-15 -> 74 | D22: ='Class 1'!D22-20 -> 62 | E22: ='Class 1'!E22-30 -> 35 | F22: ='Class 1'!F22-40 -> 55 | G22: ='Class 1'!G22-50 -> 42 | H22: ='Class 1'!H22-50 -> 45 | I22: ='Class 1'!I22-50 -> 46
A23: ='Class 1'!A23 -> Shafer | B23: ='Class 1'!B23 -> Anastacia | C23: ='Class 1'!C23-15 -> 71 | D23: ='Class 1'!D23-20 -> 67 | E23: ='Class 1'!E23-30 -> 48 | F23: ='Class 1'!F23-40 -> 35 | G23: ='Class 1'!G23-50 -> 30 | H23: ='Class 1'!H23-50 -> 29 | I23: ='Class 1'!I23-50 -> 31
A24: ='Class 1'!A24 -> Walker | B24: ='Class 1'!B24 -> Xavier | C24: ='Class 1'!C24-15 -> 74 | D24: ='Class 1'!D24-20 -> 73 | E24: ='Class 1'!E24-30 -> 62 | F24: ='Class 1'!F24-40 -> 52 | G24: ='Class 1'!G24-50 -> 44 | H24: ='Class 1'!H24-50 -> 42 | I24: ='Class 1'!I24-50 -> 45
A25: ='Class 1'!A25 -> Williams | B25: ='Class 1'!B25 -> Janey | C25: ='Class 1'!C25-15 -> 67 | D25: ='Class 1'!D25-20 -> 62 | E25: ='Class 1'!E25-30 -> 56 | F25: ='Class 1'!F25-40 -> 45 | G25: ='Class 1'!G25-50 -> 37 | H25: ='Class 1'!H25-50 -> 38 | I25: ='Class 1'!I25-50 -> 41
A26: ='Class 1'!A26 -> Zanders | B26: ='Class 1'!B26 -> Cassandra | C26: ='Class 1'!C26-15 -> 60 | D26: ='Class 1'!D26-20 -> 43 | E26: ='Class 1'!E26-30 -> 32 | F26: ='Class 1'!F26-40 -> 30 | G26: ='Class 1'!G26-50 -> 23 | H26: ='Class 1'!H26-50 -> 26 | I26: ='Class 1'!I26-50 -> 29

Sheet Class 3
C3: Social Science
C4: ='Class 1'!C4 -> 0.1 | D4: ='Class 1'!D4 -> 0.1 | E4: ='Class 1'!E4 -> 0.15 | F4: ='Class 1'!F4 -> 0.2 | G4: ='Class 1'!G4 -> 0.1 | H4: ='Class 1'!H4 -> 0.15 | I4: ='Class 1'!I4 -> 0.2
A5: ='Class 1'!A5 -> Last Name | B5: ='Class 1'!B5 -> First Name | C5: ='Class 1'!C5 -> Pre-Test | D5: ='Class 1'!D5 -> Quiz 1 | E5: ='Class 1'!E5 -> Writen Report | F5: ='Class 1'!F5 -> Mid-Term | G5: ='Class 1'!G5 -> Quiz 2 | H5: ='Class 1'!H5 -> Oral Report | I5: ='Class 1'!I5 -> Final
A6: ='Class 1'!A6 -> Aarons | B6: ='Class 1'!B6 -> Karly | C6: ='Class 1'!C6-10 -> 80 | D6: ='Class 1'!D6 -> 90 | E6: ='Class 1'!E6 -> 95 | F6: ='Class 1'!F6 -> 100 | G6: ='Class 1'!G6-5 -> 95 | H6: ='Class 1'!H6-5 -> 95 | I6: ='Class 1'!I6 -> 100
A7: ='Class 1'!A7 -> Benjamin | B7: ='Class 1'!B7 -> Darwin | C7: ='Class 1'!C7-10 -> 81 | D7: ='Class 1'!D7 -> 67 | E7: ='Class 1'!E7+10 -> 82 | F7: ='Class 1'!F7+10 -> 85 | G7: ='Class 1'!G7-15 -> 63 | H7: ='Class 1'!H7-15 -> 67 | I7: ='Class 1'!I7+5 -> 95
A8: ='Class 1'!A8 -> Donegal | B8: ='Class 1'!B8 -> Micheal | C8: ='Class 1'!C8-10 -> 77 | D8: ='Class 1'!D8 -> 58 | E8: ='Class 1'!E8+10 -> 75 | F8: ='Class 1'!F8+10 -> 82 | G8: ='Class 1'!G8-15 -> 63 | H8: ='Class 1'!H8-15 -> 67 | I8: ='Class 1'!I8+5 -> 90
A9: ='Class 1'!A9 -> Darwin | B9: ='Class 1'!B9 -> Dameon | C9: ='Class 1'!C9-10 -> 68 | D9: ='Class 1'!D9 -> 65 | E9: ='Class 1'!E9+10 -> 78 | F9: ='Class 1'!F9+10 -> 85 | G9: ='Class 1'!G9-15 -> 66 | H9: ='Class 1'!H9-15 -> 71 | I9: ='Class 1'!I9+5 -> 97
A10: ='Class 1'!A10 -> Farmer | B10: ='Class 1'!B10 -> Jessica | C10: ='Class 1'!C10-10 -> 75 | D10: ='Class 1'!D10 -> 87 | E10: ='Class 1'!E10+10 -> 99 | F10: ='Class 1'!F10 -> 91 | G10: ='Class 1'!G10-15 -> 75 | H10: ='Class 1'!H10-15 -> 80 | I10: ='Class 1'!I10 -> 97
A11: ='Class 1'!A11 -> Green | B11: ='Class 1'!B11 -> Rachel | C11: ='Class 1'!C11-10 -> 79 | D11: ='Class 1'!D11 -> 95 | E11: ='Class 1'!E11+10 -> 88 | F11: ='Class 1'!F11+10 -> 99 | G11: ='Class 1'!G11-15 -> 79 | H11: ='Class 1'!H11-15 -> 73 | I11: ='Class 1'!I11 -> 95
A12: ='Class 1'!A12 -> Holiday | B12: ='Class 1'!B12 -> Tiffany | C12: ='Class 1'!C12-10 -> 65 | D12: ='Class 1'!D12 -> 83 | E12: ='Class 1'!E12+10 -> 99 | F12: ='Class 1'!F12+10 -> 95 | G12: ='Class 1'!G12-15 -> 68 | H12: ='Class 1'!H12-15 -> 72 | I12: ='Class 1'!I12+5 -> 96
A13: ='Class 1'!A13 -> Jones | B13: ='Class 1'!B13 -> Kaci Lynn | C13: ='Class 1'!C13-10 -> 71 | D13: ='Class 1'!D13 -> 96 | E13: ='Class 1'!E13 -> 97 | F13: ='Class 1'!F13 -> 99 | G13: ='Class 1'!G13-15 -> 81 | H13: ='Class 1'!H13-15 -> 84 | I13: ='Class 1'!I13+5 -> 105
A14: ='Class 1'!A14 -> Jones | B14: ='Class 1'!B14 -> Staci Lee | C14: ='Class 1'!C14-10 -> 75 | D14: ='Class 1'!D14 -> 95 | E14: ='Class 1'!E14 -> 96 | F14: ='Class 1'!F14 -> 98 | G14: ='Class 1'!G14-15 -> 82 | H14: ='Class 1'!H14-15 -> 83 | I14: ='Class 1'!I14+5 -> 104
A15: ='Class 1'!A15 -> Konston | B15: ='Class 1'!B15 -> Heidi | C15: ='Class 1'!C15-10 -> 79 | D15: ='Class 1'!D15 -> 72 | E15: ='Class 1'!E15+10 -> 84 | F15: ='Class 1'!F15+10 -> 85 | G15: ='Class 1'!G15-15 -> 59 | H15: ='Class 1'!H15-15 -> 61 | I15: ='Class 1'!I15+5 -> 86
A16: ='Class 1'!A16 -> Klass | B16: ='Class 1'!B16 -> Renee | C16: ='Class 1'!C16-10 -> 48 | D16: ='Class 1'!D16 -> 55 | E16: ='Class 1'!E16+10 -> 64 | F16: ='Class 1'!F16+10 -> 67 | G16: ='Class 1'!G16-15 -> 43 | H16: ='Class 1'!H16-15 -> 45 | I16: ='Class 1'!I16+5 -> 64
A17: ='Class 1'!A17 -> Lamb | B17: ='Class 1'!B17 -> Brooke | C17: ='Class 1'!C17-10 -> 54 | D17: ='Class 1'!D17 -> 97 | E17: ='Class 1'!E17+10 -> 99 | F17: ='Class 1'!F17 -> 95 | G17: ='Class 1'!G17-15 -> 73 | H17: ='Class 1'!H17-15 -> 72 | I17: ='Class 1'!I17+5 -> 96
A18: ='Class 1'!A18 -> Marcus | B18: ='Class 1'!B18 -> Kevin | C18: ='Class 1'!C18-10 -> 53 | D18: ='Class 1'!D18 -> 83 | E18: ='Class 1'!E18+10 -> 95 | F18: ='Class 1'!F18+10 -> 99 | G18: ='Class 1'!G18-15 -> 73 | H18: ='Class 1'!H18-15 -> 72 | I18: ='Class 1'!I18+5 -> 96
A19: ='Class 1'!A19 -> Matthews | B19: ='Class 1'!B19 -> Cory | C19: ='Class 1'!C19-10 -> 78 | D19: ='Class 1'!D19 -> 88 | E19: ='Class 1'!E19+10 -> 97 | F19: ='Class 1'!F19 -> 95 | G19: ='Class 1'!G19-15 -> 69 | H19: ='Class 1'!H19-15 -> 70 | I19: ='Class 1'!I19+5 -> 101
A20: ='Class 1'!A20 -> Parker | B20: ='Class 1'!B20 -> William | C20: ='Class 1'!C20-10 -> 65 | D20: ='Class 1'!D20 -> 88 | E20: ='Class 1'!E20+10 -> 101 | F20: ='Class 1'!F20+10 -> 92 | G20: ='Class 1'!G20-15 -> 58 | H20: ='Class 1'!H20-15 -> 59 | I20: ='Class 1'!I20+5 -> 96
A21: ='Class 1'!A21 -> Russo | B21: ='Class 1'!B21 -> Nicholas | C21: ='Class 1'!C21 -> 80 | D21: ='Class 1'!D21 -> 82 | E21: ='Class 1'!E21 -> 86 | F21: ='Class 1'!F21 -> 92 | G21: ='Class 1'!G21 -> 80 | H21: ='Class 1'!H21 -> 75 | I21: ='Class 1'!I21 -> 63
A22: ='Class 1'!A22 -> Sanders | B22: ='Class 1'!B22 -> Seth | C22: ='Class 1'!C22-10 -> 79 | D22: ='Class 1'!D22 -> 82 | E22: ='Class 1'!E22+10 -> 75 | F22: ='Class 1'!F22 -> 95 | G22: ='Class 1'!G22-15 -> 77 | H22: ='Class 1'!H22-15 -> 80 | I22: ='Class 1'!I22+5 -> 101
A23: ='Class 1'!A23 -> Shafer | B23: ='Class 1'!B23 -> Anastacia | C23: ='Class 1'!C23-10 -> 76 | D23: ='Class 1'!D23 -> 87 | E23: ='Class 1'!E23+10 -> 88 | F23: ='Class 1'!F23+10 -> 85 | G23: ='Class 1'!G23-15 -> 65 | H23: ='Class 1'!H23-15 -> 64 | I23: ='Class 1'!I23+5 -> 86
A24: ='Class 1'!A24 -> Walker | B24: ='Class 1'!B24 -> Xavier | C24: ='Class 1'!C24-10 -> 79 | D24: ='Class 1'!D24 -> 93 | E24: ='Class 1'!E24 -> 92 | F24: ='Class 1'!F24 -> 92 | G24: ='Class 1'!G24-15 -> 79 | H24: ='Class 1'!H24-15 -> 77 | I24: ='Class 1'!I24+5 -> 100
A25: ='Class 1'!A25 -> Williams | B25: ='Class 1'!B25 -> Janey | C25: ='Class 1'!C25-10 -> 72 | D25: ='Class 1'!D25 -> 82 | E25: ='Class 1'!E25+10 -> 96 | F25: ='Class 1'!F25+10 -> 95 | G25: ='Class 1'!G25-15 -> 72 | H25: ='Class 1'!H25-15 -> 73 | I25: ='Class 1'!I25+5 -> 96
A26: ='Class 1'!A26 -> Zanders | B26: ='Class 1'!B26 -> Cassandra | C26: ='Class 1'!C26-10 -> 65 | D26: ='Class 1'!D26 -> 63 | E26: ='Class 1'!E26+10 -> 72 | F26: ='Class 1'!F26+10 -> 80 | G26: ='Class 1'!G26-15 -> 58 | H26: ='Class 1'!H26-15 -> 61 | I26: ='Class 1'!I26+5 -> 84

Sheet Compare Grades

Sheet Grade Charts

Sheet Chart Data
B2: Homework | C2: Quiz 1 | D2: Book Report 1 | E2: Mid-Term | F2: Quiz 2 | G2: Book Report 2 | H2: Final
A3: Karly | B3: 100 | C3: 100 | D3: 100 | E3: 100 | F3: 100 | G3: 100 | H3: 100
B5: Homework | C5: Quiz 1 | D5: Book Report 1 | E5: Mid-Term | F5: Quiz 2 | G5: Book Report 2 | H5: Final
A6: Micheal | B6: 99 | C6: 58 | D6: 65 | E6: 72 | F6: 78 | G6: 82 | H6: 85
B8: Homework | C8: Quiz 1 | D8: Book Report 1 | E8: Mid-Term | F8: Quiz 2 | G8: Book Report 2 | H8: Final
A9: Dameon | B9: 65 | C9: 65 | D9: 68 | E9: 75 | F9: 81 | G9: 86 | H9: 92
B11: Homework | C11: Quiz 1 | D11: Book Report 1 | E11: Mid-Term | F11: Quiz 2 | G11: Book Report 2 | H11: Final
A12: Rachel | B12: 95 | C12: 95 | D12: 78 | E12: 89 | F12: 94 | G12: 88 | H12: 95
B14: Homework | C14: Quiz 1 | D14: Book Report 1 | E14: Mid-Term | F14: Quiz 2 | G14: Book Report 2 | H14: Final
A15: Renee | B15: 58 | C15: 55 | D15: 54 | E15: 68 | F15: 72 | G15: 73 | H15: 76
B17: Homework | C17: Quiz 1 | D17: Book Report 1 | E17: Mid-Term | F17: Quiz 2 | G17: Book Report 2 | H17: Final
A18: Brooke | B18: 87 | C18: 97 | D18: 89 | E18: 95 | F18: 88 | G18: 87 | H18: 91
B20: Homework | C20: Quiz 1 | D20: Book Report 1 | E20: Mid-Term | F20: Quiz 2 | G20: Book Report 2 | H20: Final
A21: Nicholas | B21: 80 | C21: 82 | D21: 86 | E21: 92 | F21: 80 | G21: 75 | H21: 63
B23: Homework | C23: Quiz 1 | D23: Book Report 1 | E23: Mid-Term | F23: Quiz 2 | G23: Book Report 2 | H23: Final
A24: Seth | B24: 89 | C24: 82 | D24: 65 | E24: 95 | F24: 92 | G24: 95 | H24: 96
B26: Homework | C26: Quiz 1 | D26: Book Report 1 | E26: Mid-Term | F26: Quiz 2 | G26: Book Report 2 | H26: Final
A27: Anastacia | B27: 86 | C27: 87 | D27: 78 | E27: 75 | F27: 80 | G27: 79 | H27: 81
B29: Homework | C29: Quiz 1 | D29: Book Report 1 | E29: Mid-Term | F29: Quiz 2 | G29: Book Report 2 | H29: Final
A30: Cassandra | B30: 64 | C30: 63 | D30: 62 | E30: 70 | F30: 73 | G30: 76 | H30: 79
