Workbook
Name Annual_interest_rate: SourceFunds!#REF!
Name bill1: bill2/bill3
Name bill10: Amortization!$C$16
Name bill11: Amortization!$G$16
Name bill12: IF(Amortization!XFD1<>"",DATE(YEAR(bill13),MONTH(bill13)+(Amortization!XFD1-1)*12/bill3,DAY(bill13)),"")
Name bill13: Amortization!$C$11
Name bill14: IF(Amortization!XFB1<>"",Amortization!XFD1*bill1,"")
Name bill15: IF(Amortization!XFA1<>"",MIN(Amortization!XFC1,bill10-Amortization!XFD1),"")
Name bill16: IF(Amortization!XEZ1<>"",Amortization!XFB1-Amortization!XFD1,"")
Name bill17: Amortization!$G$17
Name bill2: Amortization!$C$8
Name bill3: Amortization!$C$10
Name bill4: bill3*bill5
Name bill5: Amortization!$C$9
Name bill6: Amortization!$C$7
Name bill7: Amortization!$C$13
Name bill8: Amortization!$C$14
Name bill9: Amortization!$C$17
Name Calculated_payment: SourceFunds!$C$14
Name Ending.Balance: IF([1]cutupproforma!XEZ1<>"",[1]cutupproforma!XFB1-[1]cutupproforma!XFD1,"")
Name Entered_payment: SourceFunds!$C$13
Name First_payment_due: SourceFunds!$C$11
Name First_payment_no: SourceFunds!$C$17
Name Interest: IF([1]cutupproforma!XFB1<>"",[1]cutupproforma!XFD1*BeginInv!Periodic_rate,"")
Name Interest: IF([1]cutupproforma!XFB1<>"",[1]cutupproforma!XFD1*Bizbalsht!Periodic_rate,"")
Name Interest: IF([1]cutupproforma!XFB1<>"",[1]cutupproforma!XFD1*CapEquip!Periodic_rate,"")
Name Interest: IF([1]cutupproforma!XFB1<>"",[1]cutupproforma!XFD1*CashFlow!Periodic_rate,"")
Name Interest: IF([1]cutupproforma!XFB1<>"",[1]cutupproforma!XFD1*IncomeStatement!Periodic_rate,"")
Name Interest: IF([1]cutupproforma!XFB1<>"",[1]cutupproforma!XFD1*KeyRatios!Periodic_rate,"")
Name Interest: IF([1]cutupproforma!XFB1<>"",[1]cutupproforma!XFD1*Payroll!Periodic_rate,"")
Name Interest: IF([1]cutupproforma!XFB1<>"",[1]cutupproforma!XFD1*Perbalsht!Periodic_rate,"")
Name Interest: IF([1]cutupproforma!XFB1<>"",[1]cutupproforma!XFD1*Startupcosts!Periodic_rate,"")
Name Interest: IF([1]cutupproforma!XFB1<>"",[1]cutupproforma!XFD1*WorkCap!Periodic_rate,"")
Name Interest: IF([1]cutupproforma!XFB1<>"",[1]cutupproforma!XFD1*Periodic_rate,"")
Name Loan_amount: SourceFunds!#REF!
Name Payments_per_year: SourceFunds!$C$9
Name Periodic_rate: Annual_interest_rate/Payments_per_year
Name Periodic_rate: Annual_interest_rate/Payments_per_year
Name Periodic_rate: Annual_interest_rate/Payments_per_year
Name Periodic_rate: Annual_interest_rate/Payments_per_year
Name Periodic_rate: Annual_interest_rate/Payments_per_year
Name Periodic_rate: Annual_interest_rate/Payments_per_year
Name Periodic_rate: Annual_interest_rate/Payments_per_year
Name Periodic_rate: Annual_interest_rate/Payments_per_year
Name Periodic_rate: Annual_interest_rate/Payments_per_year
Name Periodic_rate: Annual_interest_rate/Payments_per_year
Name Periodic_rate: Annual_interest_rate/Payments_per_year
Name Pmt_to_use: SourceFunds!$C$16
Name Principal: IF([1]cutupproforma!XFA1<>"",MIN([1]cutupproforma!XFC1,Pmt_to_use-[1]cutupproforma!XFD1),"")
Name Principal: IF([1]cutupproforma!XFA1<>"",MIN([1]cutupproforma!XFC1,Pmt_to_use-[1]cutupproforma!XFD1),"")
Name Principal: IF([1]cutupproforma!XFA1<>"",MIN([1]cutupproforma!XFC1,Pmt_to_use-[1]cutupproforma!XFD1),"")
Name Principal: IF([1]cutupproforma!XFA1<>"",MIN([1]cutupproforma!XFC1,Pmt_to_use-[1]cutupproforma!XFD1),"")
Name Principal: IF([1]cutupproforma!XFA1<>"",MIN([1]cutupproforma!XFC1,Pmt_to_use-[1]cutupproforma!XFD1),"")
Name Principal: IF([1]cutupproforma!XFA1<>"",MIN([1]cutupproforma!XFC1,Pmt_to_use-[1]cutupproforma!XFD1),"")
Name Principal: IF([1]cutupproforma!XFA1<>"",MIN([1]cutupproforma!XFC1,Pmt_to_use-[1]cutupproforma!XFD1),"")
Name Principal: IF([1]cutupproforma!XFA1<>"",MIN([1]cutupproforma!XFC1,Pmt_to_use-[1]cutupproforma!XFD1),"")
Name Principal: IF([1]cutupproforma!XFA1<>"",MIN([1]cutupproforma!XFC1,Pmt_to_use-[1]cutupproforma!XFD1),"")
Name Principal: IF([1]cutupproforma!XFA1<>"",MIN([1]cutupproforma!XFC1,Pmt_to_use-[1]cutupproforma!XFD1),"")
Name Principal: IF([1]cutupproforma!XFA1<>"",MIN([1]cutupproforma!XFC1,Pmt_to_use-[1]cutupproforma!XFD1),"")
Name Show.Date: IF([1]cutupproforma!XFD1<>"",DATE(YEAR(First_payment_due),MONTH(First_payment_due)+([1]cutupproforma!XFD1-1)*12/Payments_per_year,DAY(First_payment_due)),"")

Sheet SourceFunds
A1: SUMMARY OF SOURCES AND USES OF FUNDS
A3: SOURCES OF FUNDS
A5: Owner(s) Investment
A7: Cash | B7: 0
A8: Other
A9: Other
A11: Total Owners Investment | B11: =SUM(B7:B9) -> 0
A13: Requested Bank Loans | B13: 0
A15: Other Source | B15: 0
A16: Other Source | B16: 0
A18: TOTAL FUNDS | B18: =SUM(B11,B13,B15,B16) -> 0
A20: USES OF FUNDS
A22: * Complete Worksheet
A24: Capital Equipment * | B24: =SUM(CapEquip!C24) -> 0
A26: Beginning Inventory * | B26: =SUM(BeginInv!D28) -> 0
A28: Start-up Costs * | B28: =SUM(Startupcosts!B37) -> 0
A30: Working Capital * | B30: =SUM(WorkCap!B38) -> 0
A32: Land | B32: 0
A34: Building(s) | B34: 0
A36: TOTAL USES OF FUNDS | B36: =SUM(B24,B26,B28,B30,B32,B34) -> 0
A38: SECURITY
A40: Collateral
A42: * * Equipment | B42: 0
A43: * * Inventory | B43: 0
A44: 3rd Item | B44: 0
A45: 4th Item | B45: 0
A47: TOTAL SECURITY OFFERED | B47: =SUM(B42:B45) -> 0
A49: SIGNER(S)
A53: GUARANTOR(S)
A56: * * banks will only use partial value of equipment and no inventory

Sheet CapEquip
A1: CAPITAL EQUIPMENT
A3: EQUIPMENT
A5: NAME | B5: MODEL # | C5: COST *
A7: Pickup truck | C7: 0
C8: 0
C9: 0
C10: 0
C11: 0
C12: 0
A24: TOTAL EQUIPMENT COST | C24: =SUM(C6:C23) -> 0
A26: * Include sales tax and shipping in cost

Sheet BeginInv
A1: BEGINNING INVENTORY
A3: PRODUCTS or RAW MATERIALS
A5: ITEM | B5: QTY | C5: COST * | D5: TOTAL
A7: Electric Washers | B7: 0 | C7: 0 | D7: =B7*C7 -> 0
B8: 0 | C8: 0 | D8: =B8*C8 -> 0
B9: 0 | C9: 0 | D9: =B9*C9 -> 0
D10: =B10*C10 -> 0
D11: =B11*C11 -> 0
D12: =B12*C12 -> 0
D13: =B13*C13 -> 0
D14: =B14*C14 -> 0
D15: =B15*C15 -> 0
D16: =B16*C16 -> 0
D17: =B17*C17 -> 0
D18: =B18*C18 -> 0
D19: =B19*C19 -> 0
D20: =B20*C20 -> 0
D21: =B21*C21 -> 0
... D27: =B27*C27 -> 0
A28: TOTAL COST | D28: =SUM(D6:D26) -> 0
A30: * include sales tax and shipping in cost

Sheet Startupcosts
A1: START-UP COSTS
A3: ITEM | B3: COST
A5: Remodeling and Decorating | B5: 0
A7: Interior and Exterior Signs | B7: 0
A9: Installation of Fixtures and Equipment
A11: Telephone Installation | B11: 0
A13: Rent Deposits | B13: 0
A15: Utility Deposits | B15: 0
A17: Licenses | B17: 0
A19: Permits | B19: 0
A21: Professional Fees | B21: 0
A23: Advertising and Promotions | B23: 0
A25: Office Supplies (initial) | B25: 0
A27: Other Supplies (initial) | B27: 0
A29: Training | B29: 0
A31: Other
A33: Other
A35: Other
A37: TOTAL START-UP COSTS | B37: =SUM(B5:B35) -> 0

Sheet WorkCap
A1: WORKING CAPITAL
A3: NOTE: Complete the Income Statement worksheet
A4: first, numbers automatically posted to sheet
B5: ENTER MONTHS
A6: ITEM | B6: 3
A8: =IncomeStatement!$A$29 -> Payroll (includes bus share of taxes) | B8: =IF($B$6=1,IncomeStatement!C29,IF($B$6=2,IncomeStatement!C29+IncomeStatement!D29,IF($B$6=3,IncomeStatement!C29+IncomeStatement!D29+IncomeStatement!E29,IF($B$6=4,IncomeStatement!C29+IncomeStatement!D29+IncomeStatement!E29+IncomeStatement!F29,IF($B$6=5,IncomeStatement!C29+IncomeStatement!D29+IncomeStatement!E29+IncomeStatement!F29+IncomeStatement!G29,IF($B$6=6,IncomeStatement!C29+IncomeStatement!D29+IncomeStatement!E29+IncomeStatement!F29+IncomeStatement!G29+IncomeStatement!H29,IF($B$6=7,IncomeStatement!C29+IncomeStatement!D29+IncomeStatement!E29+IncomeStatement!F29+IncomeStatement!G29+IncomeStatement!H29+IncomeStatement!I29,IF($B$6=8,IncomeStatement!C29+IncomeStatement!D29+IncomeStatement!E29+IncomeStatement!F29+IncomeStatement!G29+IncomeStatement!H29+IncomeStatement!I29+IncomeStatement!J29,C8)))))))) -> 0 | C8: =IF($B$6=9,IncomeStatement!C29+IncomeStatement!D29+IncomeStatement!E29+IncomeStatement!F29+IncomeStatement!G29+IncomeStatement!H29+IncomeStatement!I29+IncomeStatement!J29+IncomeStatement!K29,IF($B$6=10,IncomeStatement!C29+IncomeStatement!D29+IncomeStatement!E29+IncomeStatement!F29+IncomeStatement!G29+IncomeStatement!H29+IncomeStatement!I29+IncomeStatement!J29+IncomeStatement!K29+IncomeStatement!L29,IF($B$6=11,IncomeStatement!C29+IncomeStatement!D29+IncomeStatement!E29+IncomeStatement!F29+IncomeStatement!G29+IncomeStatement!H29+IncomeStatement!I29+IncomeStatement!J29+IncomeStatement!K29+IncomeStatement!L29+IncomeStatement!M29,IF($B$6=12,IncomeStatement!C29+IncomeStatement!D29+IncomeStatement!E29+IncomeStatement!F29+IncomeStatement!G29+IncomeStatement!H29+IncomeStatement!I29+IncomeStatement!J29+IncomeStatement!K29+IncomeStatement!L29+IncomeStatement!M29+IncomeStatement!N29)))) -> FALSE
A9: =IncomeStatement!A30 -> Commissions | B9: =IF($B$6=1,IncomeStatement!C30,IF($B$6=2,IncomeStatement!C30+IncomeStatement!D30,IF($B$6=3,IncomeStatement!C30+IncomeStatement!D30+IncomeStatement!E30,IF($B$6=4,IncomeStatement!C30+IncomeStatement!D30+IncomeStatement!E30+IncomeStatement!F30,IF($B$6=5,IncomeStatement!C30+IncomeStatement!D30+IncomeStatement!E30+IncomeStatement!F30+IncomeStatement!G30,IF($B$6=6,IncomeStatement!C30+IncomeStatement!D30+IncomeStatement!E30+IncomeStatement!F30+IncomeStatement!G30+IncomeStatement!H30,IF($B$6=7,IncomeStatement!C30+IncomeStatement!D30+IncomeStatement!E30+IncomeStatement!F30+IncomeStatement!G30+IncomeStatement!H30+IncomeStatement!I30,IF($B$6=8,IncomeStatement!C30+IncomeStatement!D30+IncomeStatement!E30+IncomeStatement!F30+IncomeStatement!G30+IncomeStatement!H30+IncomeStatement!I30+IncomeStatement!J30,C9)))))))) -> 0 | C9: =IF($B$6=9,IncomeStatement!C30+IncomeStatement!D30+IncomeStatement!E30+IncomeStatement!F30+IncomeStatement!G30+IncomeStatement!H30+IncomeStatement!I30+IncomeStatement!J30+IncomeStatement!K30,IF($B$6=10,IncomeStatement!C30+IncomeStatement!D30+IncomeStatement!E30+IncomeStatement!F30+IncomeStatement!G30+IncomeStatement!H30+IncomeStatement!I30+IncomeStatement!J30+IncomeStatement!K30+IncomeStatement!L30,IF($B$6=11,IncomeStatement!C30+IncomeStatement!D30+IncomeStatement!E30+IncomeStatement!F30+IncomeStatement!G30+IncomeStatement!H30+IncomeStatement!I30+IncomeStatement!J30+IncomeStatement!K30+IncomeStatement!L30+IncomeStatement!M30,IF($B$6=12,IncomeStatement!C30+IncomeStatement!D30+IncomeStatement!E30+IncomeStatement!F30+IncomeStatement!G30+IncomeStatement!H30+IncomeStatement!I30+IncomeStatement!J30+IncomeStatement!K30+IncomeStatement!L30+IncomeStatement!M30+IncomeStatement!N30)))) -> FALSE
A10: =IncomeStatement!A31 -> Lease | B10: =IF($B$6=1,IncomeStatement!C31,IF($B$6=2,IncomeStatement!C31+IncomeStatement!D31,IF($B$6=3,IncomeStatement!C31+IncomeStatement!D31+IncomeStatement!E31,IF($B$6=4,IncomeStatement!C31+IncomeStatement!D31+IncomeStatement!E31+IncomeStatement!F31,IF($B$6=5,IncomeStatement!C31+IncomeStatement!D31+IncomeStatement!E31+IncomeStatement!F31+IncomeStatement!G31,IF($B$6=6,IncomeStatement!C31+IncomeStatement!D31+IncomeStatement!E31+IncomeStatement!F31+IncomeStatement!G31+IncomeStatement!H31,IF($B$6=7,IncomeStatement!C31+IncomeStatement!D31+IncomeStatement!E31+IncomeStatement!F31+IncomeStatement!G31+IncomeStatement!H31+IncomeStatement!I31,IF($B$6=8,IncomeStatement!C31+IncomeStatement!D31+IncomeStatement!E31+IncomeStatement!F31+IncomeStatement!G31+IncomeStatement!H31+IncomeStatement!I31+IncomeStatement!J31,C10)))))))) -> 0 | C10: =IF($B$6=9,IncomeStatement!C31+IncomeStatement!D31+IncomeStatement!E31+IncomeStatement!F31+IncomeStatement!G31+IncomeStatement!H31+IncomeStatement!I31+IncomeStatement!J31+IncomeStatement!K31,IF($B$6=10,IncomeStatement!C31+IncomeStatement!D31+IncomeStatement!E31+IncomeStatement!F31+IncomeStatement!G31+IncomeStatement!H31+IncomeStatement!I31+IncomeStatement!J31+IncomeStatement!K31+IncomeStatement!L31,IF($B$6=11,IncomeStatement!C31+IncomeStatement!D31+IncomeStatement!E31+IncomeStatement!F31+IncomeStatement!G31+IncomeStatement!H31+IncomeStatement!I31+IncomeStatement!J31+IncomeStatement!K31+IncomeStatement!L31+IncomeStatement!M31,IF($B$6=12,IncomeStatement!C31+IncomeStatement!D31+IncomeStatement!E31+IncomeStatement!F31+IncomeStatement!G31+IncomeStatement!H31+IncomeStatement!I31+IncomeStatement!J31+IncomeStatement!K31+IncomeStatement!L31+IncomeStatement!M31+IncomeStatement!N31)))) -> FALSE
A11: =IncomeStatement!A32 -> Building Maintenance | B11: =IF($B$6=1,IncomeStatement!C32,IF($B$6=2,IncomeStatement!C32+IncomeStatement!D32,IF($B$6=3,IncomeStatement!C32+IncomeStatement!D32+IncomeStatement!E32,IF($B$6=4,IncomeStatement!C32+IncomeStatement!D32+IncomeStatement!E32+IncomeStatement!F32,IF($B$6=5,IncomeStatement!C32+IncomeStatement!D32+IncomeStatement!E32+IncomeStatement!F32+IncomeStatement!G32,IF($B$6=6,IncomeStatement!C32+IncomeStatement!D32+IncomeStatement!E32+IncomeStatement!F32+IncomeStatement!G32+IncomeStatement!H32,IF($B$6=7,IncomeStatement!C32+IncomeStatement!D32+IncomeStatement!E32+IncomeStatement!F32+IncomeStatement!G32+IncomeStatement!H32+IncomeStatement!I32,IF($B$6=8,IncomeStatement!C32+IncomeStatement!D32+IncomeStatement!E32+IncomeStatement!F32+IncomeStatement!G32+IncomeStatement!H32+IncomeStatement!I32+IncomeStatement!J32,C11)))))))) -> 0 | C11: =IF($B$6=9,IncomeStatement!C32+IncomeStatement!D32+IncomeStatement!E32+IncomeStatement!F32+IncomeStatement!G32+IncomeStatement!H32+IncomeStatement!I32+IncomeStatement!J32+IncomeStatement!K32,IF($B$6=10,IncomeStatement!C32+IncomeStatement!D32+IncomeStatement!E32+IncomeStatement!F32+IncomeStatement!G32+IncomeStatement!H32+IncomeStatement!I32+IncomeStatement!J32+IncomeStatement!K32+IncomeStatement!L32,IF($B$6=11,IncomeStatement!C32+IncomeStatement!D32+IncomeStatement!E32+IncomeStatement!F32+IncomeStatement!G32+IncomeStatement!H32+IncomeStatement!I32+IncomeStatement!J32+IncomeStatement!K32+IncomeStatement!L32+IncomeStatement!M32,IF($B$6=12,IncomeStatement!C32+IncomeStatement!D32+IncomeStatement!E32+IncomeStatement!F32+IncomeStatement!G32+IncomeStatement!H32+IncomeStatement!I32+IncomeStatement!J32+IncomeStatement!K32+IncomeStatement!L32+IncomeStatement!M32+IncomeStatement!N32)))) -> FALSE
A12: =IncomeStatement!A33 -> Advertising | B12: =IF($B$6=1,IncomeStatement!C33,IF($B$6=2,IncomeStatement!C33+IncomeStatement!D33,IF($B$6=3,IncomeStatement!C33+IncomeStatement!D33+IncomeStatement!E33,IF($B$6=4,IncomeStatement!C33+IncomeStatement!D33+IncomeStatement!E33+IncomeStatement!F33,IF($B$6=5,IncomeStatement!C33+IncomeStatement!D33+IncomeStatement!E33+IncomeStatement!F33+IncomeStatement!G33,IF($B$6=6,IncomeStatement!C33+IncomeStatement!D33+IncomeStatement!E33+IncomeStatement!F33+IncomeStatement!G33+IncomeStatement!H33,IF($B$6=7,IncomeStatement!C33+IncomeStatement!D33+IncomeStatement!E33+IncomeStatement!F33+IncomeStatement!G33+IncomeStatement!H33+IncomeStatement!I33,IF($B$6=8,IncomeStatement!C33+IncomeStatement!D33+IncomeStatement!E33+IncomeStatement!F33+IncomeStatement!G33+IncomeStatement!H33+IncomeStatement!I33+IncomeStatement!J33,C12)))))))) -> 0 | C12: =IF($B$6=9,IncomeStatement!C33+IncomeStatement!D33+IncomeStatement!E33+IncomeStatement!F33+IncomeStatement!G33+IncomeStatement!H33+IncomeStatement!I33+IncomeStatement!J33+IncomeStatement!K33,IF($B$6=10,IncomeStatement!C33+IncomeStatement!D33+IncomeStatement!E33+IncomeStatement!F33+IncomeStatement!G33+IncomeStatement!H33+IncomeStatement!I33+IncomeStatement!J33+IncomeStatement!K33+IncomeStatement!L33,IF($B$6=11,IncomeStatement!C33+IncomeStatement!D33+IncomeStatement!E33+IncomeStatement!F33+IncomeStatement!G33+IncomeStatement!H33+IncomeStatement!I33+IncomeStatement!J33+IncomeStatement!K33+IncomeStatement!L33+IncomeStatement!M33,IF($B$6=12,IncomeStatement!C33+IncomeStatement!D33+IncomeStatement!E33+IncomeStatement!F33+IncomeStatement!G33+IncomeStatement!H33+IncomeStatement!I33+IncomeStatement!J33+IncomeStatement!K33+IncomeStatement!L33+IncomeStatement!M33+IncomeStatement!N33)))) -> FALSE
A13: =IncomeStatement!A34 -> Office Equipment | B13: =IF($B$6=1,IncomeStatement!C34,IF($B$6=2,IncomeStatement!C34+IncomeStatement!D34,IF($B$6=3,IncomeStatement!C34+IncomeStatement!D34+IncomeStatement!E34,IF($B$6=4,IncomeStatement!C34+IncomeStatement!D34+IncomeStatement!E34+IncomeStatement!F34,IF($B$6=5,IncomeStatement!C34+IncomeStatement!D34+IncomeStatement!E34+IncomeStatement!F34+IncomeStatement!G34,IF($B$6=6,IncomeStatement!C34+IncomeStatement!D34+IncomeStatement!E34+IncomeStatement!F34+IncomeStatement!G34+IncomeStatement!H34,IF($B$6=7,IncomeStatement!C34+IncomeStatement!D34+IncomeStatement!E34+IncomeStatement!F34+IncomeStatement!G34+IncomeStatement!H34+IncomeStatement!I34,IF($B$6=8,IncomeStatement!C34+IncomeStatement!D34+IncomeStatement!E34+IncomeStatement!F34+IncomeStatement!G34+IncomeStatement!H34+IncomeStatement!I34+IncomeStatement!J34,C13)))))))) -> 0 | C13: =IF($B$6=9,IncomeStatement!C34+IncomeStatement!D34+IncomeStatement!E34+IncomeStatement!F34+IncomeStatement!G34+IncomeStatement!H34+IncomeStatement!I34+IncomeStatement!J34+IncomeStatement!K34,IF($B$6=10,IncomeStatement!C34+IncomeStatement!D34+IncomeStatement!E34+IncomeStatement!F34+IncomeStatement!G34+IncomeStatement!H34+IncomeStatement!I34+IncomeStatement!J34+IncomeStatement!K34+IncomeStatement!L34,IF($B$6=11,IncomeStatement!C34+IncomeStatement!D34+IncomeStatement!E34+IncomeStatement!F34+IncomeStatement!G34+IncomeStatement!H34+IncomeStatement!I34+IncomeStatement!J34+IncomeStatement!K34+IncomeStatement!L34+IncomeStatement!M34,IF($B$6=12,IncomeStatement!C34+IncomeStatement!D34+IncomeStatement!E34+IncomeStatement!F34+IncomeStatement!G34+IncomeStatement!H34+IncomeStatement!I34+IncomeStatement!J34+IncomeStatement!K34+IncomeStatement!L34+IncomeStatement!M34+IncomeStatement!N34)))) -> FALSE
A14: =IncomeStatement!A35 -> Other Leases | B14: =IF($B$6=1,IncomeStatement!C35,IF($B$6=2,IncomeStatement!C35+IncomeStatement!D35,IF($B$6=3,IncomeStatement!C35+IncomeStatement!D35+IncomeStatement!E35,IF($B$6=4,IncomeStatement!C35+IncomeStatement!D35+IncomeStatement!E35+IncomeStatement!F35,IF($B$6=5,IncomeStatement!C35+IncomeStatement!D35+IncomeStatement!E35+IncomeStatement!F35+IncomeStatement!G35,IF($B$6=6,IncomeStatement!C35+IncomeStatement!D35+IncomeStatement!E35+IncomeStatement!F35+IncomeStatement!G35+IncomeStatement!H35,IF($B$6=7,IncomeStatement!C35+IncomeStatement!D35+IncomeStatement!E35+IncomeStatement!F35+IncomeStatement!G35+IncomeStatement!H35+IncomeStatement!I35,IF($B$6=8,IncomeStatement!C35+IncomeStatement!D35+IncomeStatement!E35+IncomeStatement!F35+IncomeStatement!G35+IncomeStatement!H35+IncomeStatement!I35+IncomeStatement!J35,C14)))))))) -> 0 | C14: =IF($B$6=9,IncomeStatement!C35+IncomeStatement!D35+IncomeStatement!E35+IncomeStatement!F35+IncomeStatement!G35+IncomeStatement!H35+IncomeStatement!I35+IncomeStatement!J35+IncomeStatement!K35,IF($B$6=10,IncomeStatement!C35+IncomeStatement!D35+IncomeStatement!E35+IncomeStatement!F35+IncomeStatement!G35+IncomeStatement!H35+IncomeStatement!I35+IncomeStatement!J35+IncomeStatement!K35+IncomeStatement!L35,IF($B$6=11,IncomeStatement!C35+IncomeStatement!D35+IncomeStatement!E35+IncomeStatement!F35+IncomeStatement!G35+IncomeStatement!H35+IncomeStatement!I35+IncomeStatement!J35+IncomeStatement!K35+IncomeStatement!L35+IncomeStatement!M35,IF($B$6=12,IncomeStatement!C35+IncomeStatement!D35+IncomeStatement!E35+IncomeStatement!F35+IncomeStatement!G35+IncomeStatement!H35+IncomeStatement!I35+IncomeStatement!J35+IncomeStatement!K35+IncomeStatement!L35+IncomeStatement!M35+IncomeStatement!N35)))) -> FALSE
A15: =IncomeStatement!A36 -> Office Supplies | B15: =IF($B$6=1,IncomeStatement!C36,IF($B$6=2,IncomeStatement!C36+IncomeStatement!D36,IF($B$6=3,IncomeStatement!C36+IncomeStatement!D36+IncomeStatement!E36,IF($B$6=4,IncomeStatement!C36+IncomeStatement!D36+IncomeStatement!E36+IncomeStatement!F36,IF($B$6=5,IncomeStatement!C36+IncomeStatement!D36+IncomeStatement!E36+IncomeStatement!F36+IncomeStatement!G36,IF($B$6=6,IncomeStatement!C36+IncomeStatement!D36+IncomeStatement!E36+IncomeStatement!F36+IncomeStatement!G36+IncomeStatement!H36,IF($B$6=7,IncomeStatement!C36+IncomeStatement!D36+IncomeStatement!E36+IncomeStatement!F36+IncomeStatement!G36+IncomeStatement!H36+IncomeStatement!I36,IF($B$6=8,IncomeStatement!C36+IncomeStatement!D36+IncomeStatement!E36+IncomeStatement!F36+IncomeStatement!G36+IncomeStatement!H36+IncomeStatement!I36+IncomeStatement!J36,C15)))))))) -> 0 | C15: =IF($B$6=9,IncomeStatement!C36+IncomeStatement!D36+IncomeStatement!E36+IncomeStatement!F36+IncomeStatement!G36+IncomeStatement!H36+IncomeStatement!I36+IncomeStatement!J36+IncomeStatement!K36,IF($B$6=10,IncomeStatement!C36+IncomeStatement!D36+IncomeStatement!E36+IncomeStatement!F36+IncomeStatement!G36+IncomeStatement!H36+IncomeStatement!I36+IncomeStatement!J36+IncomeStatement!K36+IncomeStatement!L36,IF($B$6=11,IncomeStatement!C36+IncomeStatement!D36+IncomeStatement!E36+IncomeStatement!F36+IncomeStatement!G36+IncomeStatement!H36+IncomeStatement!I36+IncomeStatement!J36+IncomeStatement!K36+IncomeStatement!L36+IncomeStatement!M36,IF($B$6=12,IncomeStatement!C36+IncomeStatement!D36+IncomeStatement!E36+IncomeStatement!F36+IncomeStatement!G36+IncomeStatement!H36+IncomeStatement!I36+IncomeStatement!J36+IncomeStatement!K36+IncomeStatement!L36+IncomeStatement!M36+IncomeStatement!N36)))) -> FALSE
A16: =IncomeStatement!A37 -> Professional Fees | B16: =IF($B$6=1,IncomeStatement!C37,IF($B$6=2,IncomeStatement!C37+IncomeStatement!D37,IF($B$6=3,IncomeStatement!C37+IncomeStatement!D37+IncomeStatement!E37,IF($B$6=4,IncomeStatement!C37+IncomeStatement!D37+IncomeStatement!E37+IncomeStatement!F37,IF($B$6=5,IncomeStatement!C37+IncomeStatement!D37+IncomeStatement!E37+IncomeStatement!F37+IncomeStatement!G37,IF($B$6=6,IncomeStatement!C37+IncomeStatement!D37+IncomeStatement!E37+IncomeStatement!F37+IncomeStatement!G37+IncomeStatement!H37,IF($B$6=7,IncomeStatement!C37+IncomeStatement!D37+IncomeStatement!E37+IncomeStatement!F37+IncomeStatement!G37+IncomeStatement!H37+IncomeStatement!I37,IF($B$6=8,IncomeStatement!C37+IncomeStatement!D37+IncomeStatement!E37+IncomeStatement!F37+IncomeStatement!G37+IncomeStatement!H37+IncomeStatement!I37+IncomeStatement!J37,C16)))))))) -> 0 | C16: =IF($B$6=9,IncomeStatement!C37+IncomeStatement!D37+IncomeStatement!E37+IncomeStatement!F37+IncomeStatement!G37+IncomeStatement!H37+IncomeStatement!I37+IncomeStatement!J37+IncomeStatement!K37,IF($B$6=10,IncomeStatement!C37+IncomeStatement!D37+IncomeStatement!E37+IncomeStatement!F37+IncomeStatement!G37+IncomeStatement!H37+IncomeStatement!I37+IncomeStatement!J37+IncomeStatement!K37+IncomeStatement!L37,IF($B$6=11,IncomeStatement!C37+IncomeStatement!D37+IncomeStatement!E37+IncomeStatement!F37+IncomeStatement!G37+IncomeStatement!H37+IncomeStatement!I37+IncomeStatement!J37+IncomeStatement!K37+IncomeStatement!L37+IncomeStatement!M37,IF($B$6=12,IncomeStatement!C37+IncomeStatement!D37+IncomeStatement!E37+IncomeStatement!F37+IncomeStatement!G37+IncomeStatement!H37+IncomeStatement!I37+IncomeStatement!J37+IncomeStatement!K37+IncomeStatement!L37+IncomeStatement!M37+IncomeStatement!N37)))) -> FALSE
A17: =IncomeStatement!A38 -> Electric | B17: =IF($B$6=1,IncomeStatement!C38,IF($B$6=2,IncomeStatement!C38+IncomeStatement!D38,IF($B$6=3,IncomeStatement!C38+IncomeStatement!D38+IncomeStatement!E38,IF($B$6=4,IncomeStatement!C38+IncomeStatement!D38+IncomeStatement!E38+IncomeStatement!F38,IF($B$6=5,IncomeStatement!C38+IncomeStatement!D38+IncomeStatement!E38+IncomeStatement!F38+IncomeStatement!G38,IF($B$6=6,IncomeStatement!C38+IncomeStatement!D38+IncomeStatement!E38+IncomeStatement!F38+IncomeStatement!G38+IncomeStatement!H38,IF($B$6=7,IncomeStatement!C38+IncomeStatement!D38+IncomeStatement!E38+IncomeStatement!F38+IncomeStatement!G38+IncomeStatement!H38+IncomeStatement!I38,IF($B$6=8,IncomeStatement!C38+IncomeStatement!D38+IncomeStatement!E38+IncomeStatement!F38+IncomeStatement!G38+IncomeStatement!H38+IncomeStatement!I38+IncomeStatement!J38,C17)))))))) -> 0 | C17: =IF($B$6=9,IncomeStatement!C38+IncomeStatement!D38+IncomeStatement!E38+IncomeStatement!F38+IncomeStatement!G38+IncomeStatement!H38+IncomeStatement!I38+IncomeStatement!J38+IncomeStatement!K38,IF($B$6=10,IncomeStatement!C38+IncomeStatement!D38+IncomeStatement!E38+IncomeStatement!F38+IncomeStatement!G38+IncomeStatement!H38+IncomeStatement!I38+IncomeStatement!J38+IncomeStatement!K38+IncomeStatement!L38,IF($B$6=11,IncomeStatement!C38+IncomeStatement!D38+IncomeStatement!E38+IncomeStatement!F38+IncomeStatement!G38+IncomeStatement!H38+IncomeStatement!I38+IncomeStatement!J38+IncomeStatement!K38+IncomeStatement!L38+IncomeStatement!M38,IF($B$6=12,IncomeStatement!C38+IncomeStatement!D38+IncomeStatement!E38+IncomeStatement!F38+IncomeStatement!G38+IncomeStatement!H38+IncomeStatement!I38+IncomeStatement!J38+IncomeStatement!K38+IncomeStatement!L38+IncomeStatement!M38+IncomeStatement!N38)))) -> FALSE
A18: =IncomeStatement!A39 -> Water | B18: =IF($B$6=1,IncomeStatement!C39,IF($B$6=2,IncomeStatement!C39+IncomeStatement!D39,IF($B$6=3,IncomeStatement!C39+IncomeStatement!D39+IncomeStatement!E39,IF($B$6=4,IncomeStatement!C39+IncomeStatement!D39+IncomeStatement!E39+IncomeStatement!F39,IF($B$6=5,IncomeStatement!C39+IncomeStatement!D39+IncomeStatement!E39+IncomeStatement!F39+IncomeStatement!G39,IF($B$6=6,IncomeStatement!C39+IncomeStatement!D39+IncomeStatement!E39+IncomeStatement!F39+IncomeStatement!G39+IncomeStatement!H39,IF($B$6=7,IncomeStatement!C39+IncomeStatement!D39+IncomeStatement!E39+IncomeStatement!F39+IncomeStatement!G39+IncomeStatement!H39+IncomeStatement!I39,IF($B$6=8,IncomeStatement!C39+IncomeStatement!D39+IncomeStatement!E39+IncomeStatement!F39+IncomeStatement!G39+IncomeStatement!H39+IncomeStatement!I39+IncomeStatement!J39,C18)))))))) -> 0 | C18: =IF($B$6=9,IncomeStatement!C39+IncomeStatement!D39+IncomeStatement!E39+IncomeStatement!F39+IncomeStatement!G39+IncomeStatement!H39+IncomeStatement!I39+IncomeStatement!J39+IncomeStatement!K39,IF($B$6=10,IncomeStatement!C39+IncomeStatement!D39+IncomeStatement!E39+IncomeStatement!F39+IncomeStatement!G39+IncomeStatement!H39+IncomeStatement!I39+IncomeStatement!J39+IncomeStatement!K39+IncomeStatement!L39,IF($B$6=11,IncomeStatement!C39+IncomeStatement!D39+IncomeStatement!E39+IncomeStatement!F39+IncomeStatement!G39+IncomeStatement!H39+IncomeStatement!I39+IncomeStatement!J39+IncomeStatement!K39+IncomeStatement!L39+IncomeStatement!M39,IF($B$6=12,IncomeStatement!C39+IncomeStatement!D39+IncomeStatement!E39+IncomeStatement!F39+IncomeStatement!G39+IncomeStatement!H39+IncomeStatement!I39+IncomeStatement!J39+IncomeStatement!K39+IncomeStatement!L39+IncomeStatement!M39+IncomeStatement!N39)))) -> FALSE
A19: =IncomeStatement!A40 -> Gas | B19: =IF($B$6=1,IncomeStatement!C40,IF($B$6=2,IncomeStatement!C40+IncomeStatement!D40,IF($B$6=3,IncomeStatement!C40+IncomeStatement!D40+IncomeStatement!E40,IF($B$6=4,IncomeStatement!C40+IncomeStatement!D40+IncomeStatement!E40+IncomeStatement!F40,IF($B$6=5,IncomeStatement!C40+IncomeStatement!D40+IncomeStatement!E40+IncomeStatement!F40+IncomeStatement!G40,IF($B$6=6,IncomeStatement!C40+IncomeStatement!D40+IncomeStatement!E40+IncomeStatement!F40+IncomeStatement!G40+IncomeStatement!H40,IF($B$6=7,IncomeStatement!C40+IncomeStatement!D40+IncomeStatement!E40+IncomeStatement!F40+IncomeStatement!G40+IncomeStatement!H40+IncomeStatement!I40,IF($B$6=8,IncomeStatement!C40+IncomeStatement!D40+IncomeStatement!E40+IncomeStatement!F40+IncomeStatement!G40+IncomeStatement!H40+IncomeStatement!I40+IncomeStatement!J40,C19)))))))) -> 0 | C19: =IF($B$6=9,IncomeStatement!C40+IncomeStatement!D40+IncomeStatement!E40+IncomeStatement!F40+IncomeStatement!G40+IncomeStatement!H40+IncomeStatement!I40+IncomeStatement!J40+IncomeStatement!K40,IF($B$6=10,IncomeStatement!C40+IncomeStatement!D40+IncomeStatement!E40+IncomeStatement!F40+IncomeStatement!G40+IncomeStatement!H40+IncomeStatement!I40+IncomeStatement!J40+IncomeStatement!K40+IncomeStatement!L40,IF($B$6=11,IncomeStatement!C40+IncomeStatement!D40+IncomeStatement!E40+IncomeStatement!F40+IncomeStatement!G40+IncomeStatement!H40+IncomeStatement!I40+IncomeStatement!J40+IncomeStatement!K40+IncomeStatement!L40+IncomeStatement!M40,IF($B$6=12,IncomeStatement!C40+IncomeStatement!D40+IncomeStatement!E40+IncomeStatement!F40+IncomeStatement!G40+IncomeStatement!H40+IncomeStatement!I40+IncomeStatement!J40+IncomeStatement!K40+IncomeStatement!L40+IncomeStatement!M40+IncomeStatement!N40)))) -> FALSE
A20: =IncomeStatement!A41 -> Web/Internet | B20: =IF($B$6=1,IncomeStatement!C41,IF($B$6=2,IncomeStatement!C41+IncomeStatement!D41,IF($B$6=3,IncomeStatement!C41+IncomeStatement!D41+IncomeStatement!E41,IF($B$6=4,IncomeStatement!C41+IncomeStatement!D41+IncomeStatement!E41+IncomeStatement!F41,IF($B$6=5,IncomeStatement!C41+IncomeStatement!D41+IncomeStatement!E41+IncomeStatement!F41+IncomeStatement!G41,IF($B$6=6,IncomeStatement!C41+IncomeStatement!D41+IncomeStatement!E41+IncomeStatement!F41+IncomeStatement!G41+IncomeStatement!H41,IF($B$6=7,IncomeStatement!C41+IncomeStatement!D41+IncomeStatement!E41+IncomeStatement!F41+IncomeStatement!G41+IncomeStatement!H41+IncomeStatement!I41,IF($B$6=8,IncomeStatement!C41+IncomeStatement!D41+IncomeStatement!E41+IncomeStatement!F41+IncomeStatement!G41+IncomeStatement!H41+IncomeStatement!I41+IncomeStatement!J41,C20)))))))) -> 0 | C20: =IF($B$6=9,IncomeStatement!C41+IncomeStatement!D41+IncomeStatement!E41+IncomeStatement!F41+IncomeStatement!G41+IncomeStatement!H41+IncomeStatement!I41+IncomeStatement!J41+IncomeStatement!K41,IF($B$6=10,IncomeStatement!C41+IncomeStatement!D41+IncomeStatement!E41+IncomeStatement!F41+IncomeStatement!G41+IncomeStatement!H41+IncomeStatement!I41+IncomeStatement!J41+IncomeStatement!K41+IncomeStatement!L41,IF($B$6=11,IncomeStatement!C41+IncomeStatement!D41+IncomeStatement!E41+IncomeStatement!F41+IncomeStatement!G41+IncomeStatement!H41+IncomeStatement!I41+IncomeStatement!J41+IncomeStatement!K41+IncomeStatement!L41+IncomeStatement!M41,IF($B$6=12,IncomeStatement!C41+IncomeStatement!D41+IncomeStatement!E41+IncomeStatement!F41+IncomeStatement!G41+IncomeStatement!H41+IncomeStatement!I41+IncomeStatement!J41+IncomeStatement!K41+IncomeStatement!L41+IncomeStatement!M41+IncomeStatement!N41)))) -> FALSE
... A35: =IncomeStatement!A56 -> Supplies | B35: =IF($B$6=1,IncomeStatement!C56,IF($B$6=2,IncomeStatement!C56+IncomeStatement!D56,IF($B$6=3,IncomeStatement!C56+IncomeStatement!D56+IncomeStatement!E56,IF($B$6=4,IncomeStatement!C56+IncomeStatement!D56+IncomeStatement!E56+IncomeStatement!F56,IF($B$6=5,IncomeStatement!C56+IncomeStatement!D56+IncomeStatement!E56+IncomeStatement!F56+IncomeStatement!G56,IF($B$6=6,IncomeStatement!C56+IncomeStatement!D56+IncomeStatement!E56+IncomeStatement!F56+IncomeStatement!G56+IncomeStatement!H56,IF($B$6=7,IncomeStatement!C56+IncomeStatement!D56+IncomeStatement!E56+IncomeStatement!F56+IncomeStatement!G56+IncomeStatement!H56+IncomeStatement!I56,IF($B$6=8,IncomeStatement!C56+IncomeStatement!D56+IncomeStatement!E56+IncomeStatement!F56+IncomeStatement!G56+IncomeStatement!H56+IncomeStatement!I56+IncomeStatement!J56,C35)))))))) -> 0 | C35: =IF($B$6=9,IncomeStatement!C56+IncomeStatement!D56+IncomeStatement!E56+IncomeStatement!F56+IncomeStatement!G56+IncomeStatement!H56+IncomeStatement!I56+IncomeStatement!J56+IncomeStatement!K56,IF($B$6=10,IncomeStatement!C56+IncomeStatement!D56+IncomeStatement!E56+IncomeStatement!F56+IncomeStatement!G56+IncomeStatement!H56+IncomeStatement!I56+IncomeStatement!J56+IncomeStatement!K56+IncomeStatement!L56,IF($B$6=11,IncomeStatement!C56+IncomeStatement!D56+IncomeStatement!E56+IncomeStatement!F56+IncomeStatement!G56+IncomeStatement!H56+IncomeStatement!I56+IncomeStatement!J56+IncomeStatement!K56+IncomeStatement!L56+IncomeStatement!M56,IF($B$6=12,IncomeStatement!C56+IncomeStatement!D56+IncomeStatement!E56+IncomeStatement!F56+IncomeStatement!G56+IncomeStatement!H56+IncomeStatement!I56+IncomeStatement!J56+IncomeStatement!K56+IncomeStatement!L56+IncomeStatement!M56+IncomeStatement!N56)))) -> FALSE
A36: =IncomeStatement!$A$58 -> Miscellaneous | B36: =IF($B$6=1,IncomeStatement!C58,IF($B$6=2,IncomeStatement!C58+IncomeStatement!D58,IF($B$6=3,IncomeStatement!C58+IncomeStatement!D58+IncomeStatement!E58,IF($B$6=4,IncomeStatement!C58+IncomeStatement!D58+IncomeStatement!E58+IncomeStatement!F58,IF($B$6=5,IncomeStatement!C58+IncomeStatement!D58+IncomeStatement!E58+IncomeStatement!F58+IncomeStatement!G58,IF($B$6=6,IncomeStatement!C58+IncomeStatement!D58+IncomeStatement!E58+IncomeStatement!F58+IncomeStatement!G58+IncomeStatement!H58,IF($B$6=7,IncomeStatement!C58+IncomeStatement!D58+IncomeStatement!E58+IncomeStatement!F58+IncomeStatement!G58+IncomeStatement!H58+IncomeStatement!I58,IF($B$6=8,IncomeStatement!C58+IncomeStatement!D58+IncomeStatement!E58+IncomeStatement!F58+IncomeStatement!G58+IncomeStatement!H58+IncomeStatement!I58+IncomeStatement!J58,C36)))))))) -> 0 | C36: =IF($B$6=9,IncomeStatement!C58+IncomeStatement!D58+IncomeStatement!E58+IncomeStatement!F58+IncomeStatement!G58+IncomeStatement!H58+IncomeStatement!I58+IncomeStatement!J58+IncomeStatement!K58,IF($B$6=10,IncomeStatement!C58+IncomeStatement!D58+IncomeStatement!E58+IncomeStatement!F58+IncomeStatement!G58+IncomeStatement!H58+IncomeStatement!I58+IncomeStatement!J58+IncomeStatement!K58+IncomeStatement!L58,IF($B$6=11,IncomeStatement!C58+IncomeStatement!D58+IncomeStatement!E58+IncomeStatement!F58+IncomeStatement!G58+IncomeStatement!H58+IncomeStatement!I58+IncomeStatement!J58+IncomeStatement!K58+IncomeStatement!L58+IncomeStatement!M58,IF($B$6=12,IncomeStatement!C58+IncomeStatement!D58+IncomeStatement!E58+IncomeStatement!F58+IncomeStatement!G58+IncomeStatement!H58+IncomeStatement!I58+IncomeStatement!J58+IncomeStatement!K58+IncomeStatement!L58+IncomeStatement!M58+IncomeStatement!N58)))) -> FALSE
A38: TOTAL WORKING CAPITAL | B38: =SUM(B8:B36) -> 0

Sheet Payroll
A1: PAYROLL WORK SHEET
A3: Enter all job positions with pay rate or salary, number of hours per week,
A4: overtime hours per week (hours over 40 in one week) and weeks per year.
A6: Social Security Tax (FICA) | B6: 0.062
A7: Medicare Tax (FICA-MED) | B7: 0.0145
A8: Federal and State Unemployment Tax (F/SUTA) | B8: 0.062 | C8: on first $7,000 of wages
A10: Workers Compensation Insurance (WC) | B10: 0.027 | C10: Varies by industry, enter industry rate if different
H12: EMPLOYER CONTRIBUTIONS
A13: JOB POSITION | B13: PAY RATE | C13: SALARY | D13: HOURS/WK | E13: OT HRS/WK | F13: WEEKS/YR | G13: TOTAL | H13: FICA | I13: FICA MED | J13: F/SUTA | K13: TOTAL | L13: WC
A14: Joe Delivery | B14: 0 | C14: 0 | D14: 40 | E14: 0 | F14: 52 | G14: =(((B14*D14)+((B14*1.5))*E14)*F14+C14) -> 0 | H14: =G14*$B$6 -> 0 | I14: =G14*$B$7 -> 0 | J14: =IF(G14>7000,7000*$B$8,G14*$B$8) -> 0 | K14: =SUM(H14:J14) -> 0 | L14: =G14*$B$10 -> 0
B15: 0 | C15: 0 | D15: 0 | E15: 0 | F15: 52 | G15: =(((B15*D15)+((B15*1.5))*E15)*F15+C15) -> 0 | H15: =G15*$B$6 -> 0 | I15: =G15*$B$7 -> 0 | J15: =IF(G15>7000,7000*$B$8,G15*$B$8) -> 0 | K15: =SUM(H15:J15) -> 0 | L15: =G15*$B$10 -> 0
B16: 0 | C16: 0 | D16: 0 | E16: 0 | F16: 52 | G16: =(((B16*D16)+((B16*1.5))*E16)*F16+C16) -> 0 | H16: =G16*$B$6 -> 0 | I16: =G16*$B$7 -> 0 | J16: =IF(G16>7000,7000*$B$8,G16*$B$8) -> 0 | K16: =SUM(H16:J16) -> 0 | L16: =G16*$B$10 -> 0
B17: 0 | C17: 0 | D17: 0 | E17: 0 | F17: 52 | G17: =(((B17*D17)+((B17*1.5))*E17)*F17+C17) -> 0 | H17: =G17*$B$6 -> 0 | I17: =G17*$B$7 -> 0 | J17: =IF(G17>7000,7000*$B$8,G17*$B$8) -> 0 | K17: =SUM(H17:J17) -> 0 | L17: =G17*$B$10 -> 0
B18: 0 | C18: 0 | D18: 0 | E18: 0 | F18: 52 | G18: =(((B18*D18)+((B18*1.5))*E18)*F18+C18) -> 0 | H18: =G18*$B$6 -> 0 | I18: =G18*$B$7 -> 0 | J18: =IF(G18>7000,7000*$B$8,G18*$B$8) -> 0 | K18: =SUM(H18:J18) -> 0 | L18: =G18*$B$10 -> 0
G19: =(((B19*D19)+((B19*1.5))*E19)*F19+C19) -> 0 | H19: =G19*$B$6 -> 0 | I19: =G19*$B$7 -> 0 | J19: =IF(G19>7000,7000*$B$8,G19*$B$8) -> 0 | K19: =SUM(H19:J19) -> 0 | L19: =G19*$B$10 -> 0
G20: =(((B20*D20)+((B20*1.5))*E20)*F20+C20) -> 0 | H20: =G20*$B$6 -> 0 | I20: =G20*$B$7 -> 0 | J20: =IF(G20>7000,7000*$B$8,G20*$B$8) -> 0 | K20: =SUM(H20:J20) -> 0 | L20: =G20*$B$10 -> 0
G21: =(((B21*D21)+((B21*1.5))*E21)*F21+C21) -> 0 | H21: =G21*$B$6 -> 0 | I21: =G21*$B$7 -> 0 | J21: =IF(G21>7000,7000*$B$8,G21*$B$8) -> 0 | K21: =SUM(H21:J21) -> 0 | L21: =G21*$B$10 -> 0
G22: =(((B22*D22)+((B22*1.5))*E22)*F22+C22) -> 0 | H22: =G22*$B$6 -> 0 | I22: =G22*$B$7 -> 0 | J22: =IF(G22>7000,7000*$B$8,G22*$B$8) -> 0 | K22: =SUM(H22:J22) -> 0 | L22: =G22*$B$10 -> 0
G23: =(((B23*D23)+((B23*1.5))*E23)*F23+C23) -> 0 | H23: =G23*$B$6 -> 0 | I23: =G23*$B$7 -> 0 | J23: =IF(G23>7000,7000*$B$8,G23*$B$8) -> 0 | K23: =SUM(H23:J23) -> 0 | L23: =G23*$B$10 -> 0
G24: =(((B24*D24)+((B24*1.5))*E24)*F24+C24) -> 0 | H24: =G24*$B$6 -> 0 | I24: =G24*$B$7 -> 0 | J24: =IF(G24>7000,7000*$B$8,G24*$B$8) -> 0 | K24: =SUM(H24:J24) -> 0 | L24: =G24*$B$10 -> 0
A25: TOTALS | G25: =SUM(G14:G24) -> 0 | H25: =SUM(H14:H24) -> 0 | I25: =SUM(I14:I24) -> 0 | J25: =SUM(J14:J24) -> 0 | K25: =SUM(K14:K24) -> 0 | L25: =SUM(L14:L24) -> 0
A27: TOTAL ESTIMATED PAYROLL EXPENSE | B27: =SUM(G25,K25) -> 0
A28: Includes Business' share of tax
A29: Do not overwrite this number !!!!
A31: WORKERS COMPENSATION EXPENSE | B31: =L25 -> 0

Sheet IncomeStatement
A1: Enter Expected Cash Sales 1st Year | C1: 0
A2: Enter Expected Credit Sales 1st Year | C2: 0
A3: Enter Expected Cost of Goods Sold % | C3: 0.45
A4: Enter % of Expected Growth 2nd Year | C4: 0.15
A5: Enter % of Expected Growth 3rd Year | C5: 0.1
A7: Enter your Monthly Sales Percentages | C7: 0.11 | D7: 0.09 | E7: 0.08 | F7: 0.05 | G7: 0.05 | H7: 0.05 | I7: 0.05 | J7: 0.05 | K7: 0.07 | L7: 0.12 | M7: 0.13 | N7: 0.15 | P7: =SUM(C7:O7) -> 1
A8: INCOME AND EXPENSE STATEMENT
A9: (PROJECTED INCOME AND EXPENSE STATEMENT)
A11: SALES | C11: Month 1 | D11: Month 2 | E11: Month 3 | F11: Month 4 | G11: Month 5 | H11: Month 6 | I11: Month 7 | J11: Month 8 | K11: Month 9 | L11: Month 10 | M11: Month 11 | N11: Month 12 | P11: Year 1 | Q11: % Net Sales | R11: Year 2 | S11: % Net Sales | T11: Year 3 | U11: % Net Sales
A13: Cash Sales | C13: =$C$1*C7 -> 0 | D13: =$C$1*D7 -> 0 | E13: =$C$1*E7 -> 0 | F13: =$C$1*F7 -> 0 | G13: =$C$1*G7 -> 0 | H13: =$C$1*H7 -> 0 | I13: =$C$1*I7 -> 0 | J13: =$C$1*J7 -> 0 | ... N13: =$C$1*N7 -> 0 | P13: =SUM(C13:O13) -> 0 | Q13: =P13/(P13+P14) -> #DIV/0! | R13: =P13+(P13*$C$4) -> 0 | S13: =R13/(R13+R14) -> #DIV/0! | T13: =R13+(R13*$C$5) -> 0 | U13: =T13/(T13+T14) -> #DIV/0!
A14: Credit Sales | C14: =$C$2*C7 -> 0 | D14: =$C$2*D7 -> 0 | E14: =$C$2*E7 -> 0 | F14: =$C$2*F7 -> 0 | G14: =$C$2*G7 -> 0 | H14: =$C$2*H7 -> 0 | I14: =$C$2*I7 -> 0 | J14: =$C$2*J7 -> 0 | ... N14: =$C$2*N7 -> 0 | P14: =SUM(C14:O14) -> 0 | Q14: =P14/(P13+P14) -> #DIV/0! | R14: =P14+(P14*$C$4) -> 0 | S14: =R14/(R13+R14) -> #DIV/0! | T14: =R14+(R14*$C$5) -> 0 | U14: =T14/(T13+T14) -> #DIV/0!
A15: (less Returns and Discounts) | C15: 0 | D15: 0 | E15: 0 | F15: 0 | G15: 0 | H15: 0 | I15: 0 | J15: 0 | K15: 0 | L15: 0 | M15: 0 | N15: 0 | P15: =SUM(C15:O15) -> 0 | Q15: =P15/(P13+P14) -> #DIV/0! | R15: =(R13+R14)*Q15 -> #DIV/0! | S15: =R15/(R13+R14) -> #DIV/0! | T15: =(T13+T14)*S15 -> #DIV/0! | U15: =T15/(T13+T14) -> #DIV/0!
A17: TOTAL NET SALES | C17: =SUM(C13:C14)-C15 -> 0 | D17: =SUM(D13:D14)-D15 -> 0 | E17: =SUM(E13:E14)-E15 -> 0 | F17: =SUM(F13:F14)-F15 -> 0 | G17: =SUM(G13:G14)-G15 -> 0 | H17: =SUM(H13:H14)-H15 -> 0 | I17: =SUM(I13:I14)-I15 -> 0 | J17: =SUM(J13:J14)-J15 -> 0 | ... N17: =SUM(N13:N14)-N15 -> 0 | P17: =SUM(P13:P14)-P15 -> 0 | Q17: =P17/$P$17 -> #DIV/0! | R17: =SUM(R13:R14)-R15 -> #DIV/0! | S17: =R17/$R$17 -> #DIV/0! | T17: =SUM(T13:T14)-T15 -> #DIV/0! | U17: =T17/$T$17 -> #DIV/0!
A19: COST OF GOODS SOLD
A21: Purchases for resale | C21: =C17*$C$3 -> 0 | D21: =D17*$C$3 -> 0 | E21: =E17*$C$3 -> 0 | F21: =F17*$C$3 -> 0 | G21: =G17*$C$3 -> 0 | H21: =H17*$C$3 -> 0 | I21: =I17*$C$3 -> 0 | J21: =J17*$C$3 -> 0 | ... N21: =N17*$C$3 -> 0 | P21: =SUM(C21:O21) -> 0 | Q21: =P21/$P$17 -> #DIV/0! | R21: =R17*$C$3 -> #DIV/0! | S21: =R21/$R$17 -> #DIV/0! | T21: =T17*$C$3 -> #DIV/0! | U21: =T21/$T$17 -> #DIV/0!
A23: TOTAL COST OF GOODS SOLD | C23: =SUM(C21:C22) -> 0 | D23: =SUM(D21:D22) -> 0 | E23: =SUM(E21:E22) -> 0 | F23: =SUM(F21:F22) -> 0 | G23: =SUM(G21:G22) -> 0 | H23: =SUM(H21:H22) -> 0 | I23: =SUM(I21:I22) -> 0 | J23: =SUM(J21:J22) -> 0 | ... N23: =SUM(N21:N22) -> 0 | P23: =SUM(C23:O23) -> 0 | Q23: =P23/$P$17 -> #DIV/0! | R23: =SUM(R21:R22) -> #DIV/0! | S23: =R23/$R$17 -> #DIV/0! | T23: =SUM(T21:T22) -> #DIV/0! | U23: =T23/$T$17 -> #DIV/0!
A25: GROSS PROFIT | C25: =C17-C21 -> 0 | D25: =D17-D21 -> 0 | E25: =E17-E21 -> 0 | F25: =F17-F21 -> 0 | G25: =G17-G21 -> 0 | H25: =H17-H21 -> 0 | I25: =I17-I21 -> 0 | J25: =J17-J21 -> 0 | ... N25: =N17-N21 -> 0 | P25: =SUM(C25:O25) -> 0 | Q25: =P25/$P$17 -> #DIV/0! | R25: =R17-R21 -> #DIV/0! | S25: =R25/$R$17 -> #DIV/0! | T25: =T17-T21 -> #DIV/0! | U25: =T25/$T$17 -> #DIV/0!
A27: EXPENSES
A29: Payroll (includes bus share of taxes) | C29: =Payroll!$B$27/12 -> 0 | D29: =Payroll!$B$27/12 -> 0 | E29: =Payroll!$B$27/12 -> 0 | F29: =Payroll!$B$27/12 -> 0 | G29: =Payroll!$B$27/12 -> 0 | H29: =Payroll!$B$27/12 -> 0 | I29: =Payroll!$B$27/12 -> 0 | J29: =Payroll!$B$27/12 -> 0 | ... N29: =Payroll!$B$27/12 -> 0 | P29: =SUM(C29:O29) -> 0 | Q29: =P29/$P$17 -> #DIV/0! | R29: =P29*1.03 -> 0 | S29: =R29/$R$17 -> #DIV/0! | T29: =R29*1.03 -> 0 | U29: =T29/$T$17 -> #DIV/0!
A30: Commissions | C30: 0 | D30: 0 | E30: 0 | F30: 0 | G30: 0 | H30: 0 | I30: 0 | J30: 0 | K30: 0 | L30: 0 | M30: 0 | N30: 0 | P30: =SUM(C30:O30) -> 0 | Q30: =P30/$P$17 -> #DIV/0! | R30: =P30*1.03 -> 0 | S30: =R30/$R$17 -> #DIV/0! | T30: =R30*1.03 -> 0
A31: Lease | C31: 0 | D31: 0 | E31: 0 | F31: 0 | G31: 0 | H31: 0 | I31: 0 | J31: 0 | K31: 0 | L31: 0 | M31: 0 | N31: 0 | P31: =SUM(C31:O31) -> 0 | Q31: =P31/$P$17 -> #DIV/0! | R31: =P31*1.03 -> 0 | S31: =R31/$R$17 -> #DIV/0! | T31: =R31*1.03 -> 0 | U31: =T31/$T$17 -> #DIV/0!
A32: Building Maintenance | C32: 0 | D32: 0 | E32: 0 | F32: 0 | G32: 0 | H32: 0 | I32: 0 | J32: 0 | K32: 0 | L32: 0 | M32: 0 | N32: 0 | P32: =SUM(C32:O32) -> 0 | Q32: =P32/$P$17 -> #DIV/0! | R32: =P32*1.03 -> 0 | S32: =R32/$R$17 -> #DIV/0! | T32: =R32*1.03 -> 0 | U32: =T32/$T$17 -> #DIV/0!
A33: Advertising | C33: 0 | D33: 0 | E33: 0 | F33: 0 | G33: 0 | H33: 0 | I33: 0 | J33: 0 | K33: 0 | L33: 0 | M33: 0 | N33: 0 | P33: =SUM(C33:O33) -> 0 | Q33: =P33/$P$17 -> #DIV/0! | R33: =P33*1.03 -> 0 | S33: =R33/$R$17 -> #DIV/0! | T33: =R33*1.03 -> 0 | U33: =T33/$T$17 -> #DIV/0!
A34: Office Equipment | C34: 0 | D34: 0 | E34: 0 | F34: 0 | G34: 0 | H34: 0 | I34: 0 | J34: 0 | K34: 0 | L34: 0 | M34: 0 | N34: 0 | P34: =SUM(C34:O34) -> 0 | Q34: =P34/$P$17 -> #DIV/0! | R34: =P34*1.03 -> 0 | S34: =R34/$R$17 -> #DIV/0! | T34: =R34*1.03 -> 0 | U34: =T34/$T$17 -> #DIV/0!
A35: Other Leases | C35: 0 | D35: 0 | E35: 0 | F35: 0 | G35: 0 | H35: 0 | I35: 0 | J35: 0 | K35: 0 | L35: 0 | M35: 0 | N35: 0 | P35: =SUM(C35:O35) -> 0 | Q35: =P35/$P$17 -> #DIV/0! | R35: =P35*1.03 -> 0 | S35: =R35/$R$17 -> #DIV/0! | T35: =R35*1.03 -> 0 | U35: =T35/$T$17 -> #DIV/0!
A36: Office Supplies | C36: 0 | D36: 0 | E36: 0 | F36: 0 | G36: 0 | H36: 0 | I36: 0 | J36: 0 | K36: 0 | L36: 0 | M36: 0 | N36: 0 | P36: =SUM(C36:O36) -> 0 | Q36: =P36/$P$17 -> #DIV/0! | R36: =P36*1.03 -> 0 | S36: =R36/$R$17 -> #DIV/0! | T36: =R36*1.03 -> 0 | U36: =T36/$T$17 -> #DIV/0!
A37: Professional Fees | C37: 0 | D37: 0 | E37: 0 | F37: 0 | G37: 0 | H37: 0 | I37: 0 | J37: 0 | K37: 0 | L37: 0 | M37: 0 | N37: 0 | P37: =SUM(C37:O37) -> 0 | Q37: =P37/$P$17 -> #DIV/0! | R37: =P37*1.03 -> 0 | S37: =R37/$R$17 -> #DIV/0! | T37: =R37*1.03 -> 0 | U37: =T37/$T$17 -> #DIV/0!
A38: Electric | C38: 0 | D38: 0 | E38: 0 | F38: 0 | G38: 0 | H38: 0 | I38: 0 | J38: 0 | K38: 0 | L38: 0 | M38: 0 | N38: 0 | P38: =SUM(C38:O38) -> 0 | Q38: =P38/$P$17 -> #DIV/0! | R38: =P38*1.03 -> 0 | S38: =R38/$R$17 -> #DIV/0! | T38: =R38*1.03 -> 0 | U38: =T38/$T$17 -> #DIV/0!
A39: Water | C39: 0 | D39: 0 | E39: 0 | F39: 0 | G39: 0 | H39: 0 | I39: 0 | J39: 0 | K39: 0 | L39: 0 | M39: 0 | N39: 0 | P39: =SUM(C39:O39) -> 0 | Q39: =P39/$P$17 -> #DIV/0! | R39: =P39*1.03 -> 0 | S39: =R39/$R$17 -> #DIV/0! | T39: =R39*1.03 -> 0 | U39: =T39/$T$17 -> #DIV/0!
A40: Gas | C40: 0 | D40: 0 | E40: 0 | F40: 0 | G40: 0 | H40: 0 | I40: 0 | J40: 0 | K40: 0 | L40: 0 | M40: 0 | N40: 0 | P40: =SUM(C40:O40) -> 0 | Q40: =P40/$P$17 -> #DIV/0! | R40: =P40*1.03 -> 0 | S40: =R40/$R$17 -> #DIV/0! | T40: =R40*1.03 -> 0 | U40: =T40/$T$17 -> #DIV/0!
A41: Web/Internet | C41: 0 | D41: 0 | E41: 0 | F41: 0 | G41: 0 | H41: 0 | I41: 0 | J41: 0 | K41: 0 | L41: 0 | M41: 0 | N41: 0 | P41: =SUM(C41:O41) -> 0 | Q41: =P41/$P$17 -> #DIV/0! | R41: =P41*1.03 -> 0 | S41: =R41/$R$17 -> #DIV/0! | T41: =R41*1.03 -> 0 | U41: =T41/$T$17 -> #DIV/0!
A42: Telephone | C42: 0 | D42: 0 | E42: 0 | F42: 0 | G42: 0 | H42: 0 | I42: 0 | J42: 0 | K42: 0 | L42: 0 | M42: 0 | N42: 0 | P42: =SUM(C42:O42) -> 0 | Q42: =P42/$P$17 -> #DIV/0! | R42: =P42*1.03 -> 0 | S42: =R42/$R$17 -> #DIV/0! | T42: =R42*1.03 -> 0 | U42: =T42/$T$17 -> #DIV/0!
... A47: Vehicle Insurance | C47: 0 | D47: 0 | E47: 0 | F47: 0 | G47: 0 | H47: 0 | I47: 0 | J47: 0 | K47: 0 | L47: 0 | M47: 0 | N47: 0 | P47: =SUM(C47:O47) -> 0 | Q47: =P47/$P$17 -> #DIV/0! | R47: =P47*1.03 -> 0 | S47: =R47/$R$17 -> #DIV/0! | T47: =R47*1.03 -> 0 | U47: =T47/$T$17 -> #DIV/0!
A48: Workers Comp Insurance | C48: =Payroll!$L$25/12 -> 0 | D48: =Payroll!$L$25/12 -> 0 | E48: =Payroll!$L$25/12 -> 0 | F48: =Payroll!$L$25/12 -> 0 | G48: =Payroll!$L$25/12 -> 0 | H48: =Payroll!$L$25/12 -> 0 | I48: =Payroll!$L$25/12 -> 0 | J48: =Payroll!$L$25/12 -> 0 | ... N48: =Payroll!$L$25/12 -> 0 | P48: =SUM(C48:O48) -> 0 | Q48: =P48/$P$17 -> #DIV/0! | R48: =P48*1.03 -> 0 | S48: =R48/$R$17 -> #DIV/0! | T48: =R48*1.03 -> 0 | U48: =T48/$T$17 -> #DIV/0!
A49: Vehicle Fuel & Maintenance | C49: 0 | D49: 0 | E49: 0 | F49: 0 | G49: 0 | H49: 0 | I49: 0 | J49: 0 | K49: 0 | L49: 0 | M49: 0 | N49: 0 | P49: =SUM(C49:O49) -> 0 | Q49: =P49/$P$17 -> #DIV/0! | R49: =P49*1.03 -> 0 | S49: =R49/$R$17 -> #DIV/0! | T49: =R49*1.03 -> 0 | U49: =T49/$T$17 -> #DIV/0!
A50: Equipment Maintenance and Repair | C50: 0 | D50: 0 | E50: 0 | F50: 0 | G50: 0 | H50: 0 | I50: 0 | J50: 0 | K50: 0 | L50: 0 | M50: 0 | N50: 0 | P50: =SUM(C50:O50) -> 0 | Q50: =P50/$P$17 -> #DIV/0! | R50: =P50*1.03 -> 0 | S50: =R50/$R$17 -> #DIV/0! | T50: =R50*1.03 -> 0 | U50: =T50/$T$17 -> #DIV/0!
A51: Credit Card Fees | C51: 0 | D51: 0 | E51: 0 | F51: 0 | G51: 0 | H51: 0 | I51: 0 | J51: 0 | K51: 0 | L51: 0 | M51: 0 | N51: 0 | P51: =SUM(C51:O51) -> 0 | Q51: =P51/$P$17 -> #DIV/0! | R51: =P51*1.03 -> 0 | S51: =R51/$R$17 -> #DIV/0! | T51: =R51*1.03 -> 0 | U51: =T51/$T$17 -> #DIV/0!
A52: Interest | C52: =Amortization!D22 -> 0 | D52: =Amortization!D23 -> 0 | E52: =Amortization!D24 -> 0 | F52: =Amortization!D25 -> 0 | G52: =Amortization!D26 -> 0 | H52: =Amortization!D27 -> 0 | I52: =Amortization!D28 -> 0 | J52: =Amortization!D29 -> 0 | K52: =Amortization!D30 -> 0 | L52: =Amortization!D31 -> 0 | M52: =Amortization!D32 -> 0 | N52: =Amortization!D33 -> 0 | P52: =SUM(C52:O52) -> 0 | Q52: =P52/$P$17 -> #DIV/0! | R52: =P52*1.03 -> 0 | S52: =R52/$R$17 -> #DIV/0! | T52: =R52*1.03 -> 0 | U52: =T52/$T$17 -> #DIV/0!
A53: Bank Fees | C53: 0 | D53: 0 | E53: 0 | F53: 0 | G53: 0 | H53: 0 | I53: 0 | J53: 0 | K53: 0 | L53: 0 | M53: 0 | N53: 0 | P53: =SUM(C53:O53) -> 0 | Q53: =P53/$P$17 -> #DIV/0! | R53: =P53*1.03 -> 0 | S53: =R53/$R$17 -> #DIV/0! | T53: =R53*1.03 -> 0 | U53: =T53/$T$17 -> #DIV/0!
A54: Training | C54: 0 | D54: 0 | E54: 0 | F54: 0 | G54: 0 | H54: 0 | I54: 0 | J54: 0 | K54: 0 | L54: 0 | M54: 0 | N54: 0 | P54: =SUM(C54:O54) -> 0 | Q54: =P54/$P$17 -> #DIV/0! | R54: =P54*1.03 -> 0 | S54: =R54/$R$17 -> #DIV/0! | T54: =R54*1.03 -> 0 | U54: =T54/$T$17 -> #DIV/0!
...

Sheet CashFlow
A1: CASH FLOW STATEMENT
B3: Start Up | C3: =IncomeStatement!C11 -> Month 1 | D3: =IncomeStatement!D11 -> Month 2 | E3: =IncomeStatement!E11 -> Month 3 | F3: =IncomeStatement!F11 -> Month 4 | G3: =IncomeStatement!G11 -> Month 5 | H3: =IncomeStatement!H11 -> Month 6 | I3: =IncomeStatement!I11 -> Month 7 | J3: =IncomeStatement!J11 -> Month 8 | ... N3: =IncomeStatement!N11 -> Month 12
A5: BEGINNING CASH | B5: =SourceFunds!$B$7 -> 0 | C5: =B60 -> 0 | D5: =C60 -> 0 | E5: =D60 -> 0 | F5: =E60 -> 0 | G5: =F60 -> 0 | H5: =G60 -> 0 | I5: =H60 -> 0 | J5: =I60 -> 0 | ... N5: =M60 -> 0
A6: (Enter beginning cash)
A8: ADD:
A9: Cash Sales | C9: =SUM(IncomeStatement!C13) -> 0 | D9: =SUM(IncomeStatement!D13) -> 0 | E9: =SUM(IncomeStatement!E13) -> 0 | F9: =SUM(IncomeStatement!F13) -> 0 | G9: =SUM(IncomeStatement!G13) -> 0 | H9: =SUM(IncomeStatement!H13) -> 0 | I9: =SUM(IncomeStatement!I13) -> 0 | J9: =SUM(IncomeStatement!J13) -> 0 | ... N9: =SUM(IncomeStatement!N13) -> 0
A10: Collection on Receivables *note | C10: 0 | D10: =IncomeStatement!C14*0.5 -> 0 | E10: =(IncomeStatement!D14*0.5)+IncomeStatement!C14*0.5 -> 0 | F10: =(IncomeStatement!E14*0.5)+IncomeStatement!D14*0.5 -> 0 | G10: =(IncomeStatement!F14*0.5)+IncomeStatement!E14*0.5 -> 0 | H10: =(IncomeStatement!G14*0.5)+IncomeStatement!F14*0.5 -> 0 | I10: =(IncomeStatement!H14*0.5)+IncomeStatement!G14*0.5 -> 0 | J10: =(IncomeStatement!I14*0.5)+IncomeStatement!H14*0.5 -> 0 | K10: =(IncomeStatement!J14*0.5)+IncomeStatement!I14*0.5 -> 0 | L10: =(IncomeStatement!K14*0.5)+IncomeStatement!J14*0.5 -> 0 | ... N10: =(IncomeStatement!M14*0.5)+IncomeStatement!L14*0.5 -> 0
A11: Loan or other Cash Injection | B11: =+Amortization!C7 -> 0
A12: Other | B12: 0 | C12: 0 | D12: 0
A14: TOTAL CASH AVAILABLE | B14: =SUM(B12,B11,B10,B9,B5) -> 0 | C14: =SUM(C12,C11,C10,C9,C5) -> 0 | D14: =SUM(D12,D11,D10,D9,D5) -> 0 | E14: =SUM(E12,E11,E10,E9,E5) -> 0 | F14: =SUM(F12,F11,F10,F9,F5) -> 0 | G14: =SUM(G12,G11,G10,G9,G5) -> 0 | H14: =SUM(H12,H11,H10,H9,H5) -> 0 | I14: =SUM(I12,I11,I10,I9,I5) -> 0 | ... N14: =SUM(N12,N11,N10,N9,N5) -> 0
A16: EXPENSES
A18: =IncomeStatement!$A$29 -> Payroll (includes bus share of taxes) | C18: =SUM(IncomeStatement!C29) -> 0 | D18: =SUM(IncomeStatement!D29) -> 0 | E18: =SUM(IncomeStatement!E29) -> 0 | F18: =SUM(IncomeStatement!F29) -> 0 | G18: =SUM(IncomeStatement!G29) -> 0 | H18: =SUM(IncomeStatement!H29) -> 0 | I18: =SUM(IncomeStatement!I29) -> 0 | J18: =SUM(IncomeStatement!J29) -> 0 | ... N18: =SUM(IncomeStatement!N29) -> 0
A19: =IncomeStatement!A30 -> Commissions | C19: =SUM(IncomeStatement!C30) -> 0 | D19: =SUM(IncomeStatement!D30) -> 0 | E19: =SUM(IncomeStatement!E30) -> 0 | F19: =SUM(IncomeStatement!F30) -> 0 | G19: =SUM(IncomeStatement!G30) -> 0 | H19: =SUM(IncomeStatement!H30) -> 0 | I19: =SUM(IncomeStatement!I30) -> 0 | J19: =SUM(IncomeStatement!J30) -> 0 | ... N19: =SUM(IncomeStatement!N30) -> 0
A20: =IncomeStatement!A31 -> Lease | C20: =SUM(IncomeStatement!C31) -> 0 | D20: =SUM(IncomeStatement!D31) -> 0 | E20: =SUM(IncomeStatement!E31) -> 0 | F20: =SUM(IncomeStatement!F31) -> 0 | G20: =SUM(IncomeStatement!G31) -> 0 | H20: =SUM(IncomeStatement!H31) -> 0 | I20: =SUM(IncomeStatement!I31) -> 0 | J20: =SUM(IncomeStatement!J31) -> 0 | ... N20: =SUM(IncomeStatement!N31) -> 0
A21: =IncomeStatement!A32 -> Building Maintenance | C21: =SUM(IncomeStatement!C32) -> 0 | D21: =SUM(IncomeStatement!D32) -> 0 | E21: =SUM(IncomeStatement!E32) -> 0 | F21: =SUM(IncomeStatement!F32) -> 0 | G21: =SUM(IncomeStatement!G32) -> 0 | H21: =SUM(IncomeStatement!H32) -> 0 | I21: =SUM(IncomeStatement!I32) -> 0 | J21: =SUM(IncomeStatement!J32) -> 0 | ... N21: =SUM(IncomeStatement!N32) -> 0
A22: =IncomeStatement!A33 -> Advertising | C22: =SUM(IncomeStatement!C33) -> 0 | D22: =SUM(IncomeStatement!D33) -> 0 | E22: =SUM(IncomeStatement!E33) -> 0 | F22: =SUM(IncomeStatement!F33) -> 0 | G22: =SUM(IncomeStatement!G33) -> 0 | H22: =SUM(IncomeStatement!H33) -> 0 | I22: =SUM(IncomeStatement!I33) -> 0 | J22: =SUM(IncomeStatement!J33) -> 0 | ... N22: =SUM(IncomeStatement!N33) -> 0
A23: =IncomeStatement!A34 -> Office Equipment | C23: =SUM(IncomeStatement!C34) -> 0 | D23: =SUM(IncomeStatement!D34) -> 0 | E23: =SUM(IncomeStatement!E34) -> 0 | F23: =SUM(IncomeStatement!F34) -> 0 | G23: =SUM(IncomeStatement!G34) -> 0 | H23: =SUM(IncomeStatement!H34) -> 0 | I23: =SUM(IncomeStatement!I34) -> 0 | J23: =SUM(IncomeStatement!J34) -> 0 | ... N23: =SUM(IncomeStatement!N34) -> 0
A24: =IncomeStatement!A35 -> Other Leases | C24: =SUM(IncomeStatement!C35) -> 0 | D24: =SUM(IncomeStatement!D35) -> 0 | E24: =SUM(IncomeStatement!E35) -> 0 | F24: =SUM(IncomeStatement!F35) -> 0 | G24: =SUM(IncomeStatement!G35) -> 0 | H24: =SUM(IncomeStatement!H35) -> 0 | I24: =SUM(IncomeStatement!I35) -> 0 | J24: =SUM(IncomeStatement!J35) -> 0 | ... N24: =SUM(IncomeStatement!N35) -> 0
A25: =IncomeStatement!A36 -> Office Supplies | C25: =SUM(IncomeStatement!C36) -> 0 | D25: =SUM(IncomeStatement!D36) -> 0 | E25: =SUM(IncomeStatement!E36) -> 0 | F25: =SUM(IncomeStatement!F36) -> 0 | G25: =SUM(IncomeStatement!G36) -> 0 | H25: =SUM(IncomeStatement!H36) -> 0 | I25: =SUM(IncomeStatement!I36) -> 0 | J25: =SUM(IncomeStatement!J36) -> 0 | ... N25: =SUM(IncomeStatement!N36) -> 0
A26: =IncomeStatement!A37 -> Professional Fees | C26: =SUM(IncomeStatement!C37) -> 0 | D26: =SUM(IncomeStatement!D37) -> 0 | E26: =SUM(IncomeStatement!E37) -> 0 | F26: =SUM(IncomeStatement!F37) -> 0 | G26: =SUM(IncomeStatement!G37) -> 0 | H26: =SUM(IncomeStatement!H37) -> 0 | I26: =SUM(IncomeStatement!I37) -> 0 | J26: =SUM(IncomeStatement!J37) -> 0 | ... N26: =SUM(IncomeStatement!N37) -> 0
A27: =IncomeStatement!A38 -> Electric | C27: =SUM(IncomeStatement!C38) -> 0 | D27: =SUM(IncomeStatement!D38) -> 0 | E27: =SUM(IncomeStatement!E38) -> 0 | F27: =SUM(IncomeStatement!F38) -> 0 | G27: =SUM(IncomeStatement!G38) -> 0 | H27: =SUM(IncomeStatement!H38) -> 0 | I27: =SUM(IncomeStatement!I38) -> 0 | J27: =SUM(IncomeStatement!J38) -> 0 | ... N27: =SUM(IncomeStatement!N38) -> 0
A28: =IncomeStatement!A39 -> Water | C28: =SUM(IncomeStatement!C39) -> 0 | D28: =SUM(IncomeStatement!D39) -> 0 | E28: =SUM(IncomeStatement!E39) -> 0 | F28: =SUM(IncomeStatement!F39) -> 0 | G28: =SUM(IncomeStatement!G39) -> 0 | H28: =SUM(IncomeStatement!H39) -> 0 | I28: =SUM(IncomeStatement!I39) -> 0 | J28: =SUM(IncomeStatement!J39) -> 0 | ... N28: =SUM(IncomeStatement!N39) -> 0
A29: =IncomeStatement!A40 -> Gas | C29: =SUM(IncomeStatement!C40) -> 0 | D29: =SUM(IncomeStatement!D40) -> 0 | E29: =SUM(IncomeStatement!E40) -> 0 | F29: =SUM(IncomeStatement!F40) -> 0 | G29: =SUM(IncomeStatement!G40) -> 0 | H29: =SUM(IncomeStatement!H40) -> 0 | I29: =SUM(IncomeStatement!I40) -> 0 | J29: =SUM(IncomeStatement!J40) -> 0 | ... N29: =SUM(IncomeStatement!N40) -> 0
A30: =IncomeStatement!A41 -> Web/Internet | C30: =SUM(IncomeStatement!C41) -> 0 | D30: =SUM(IncomeStatement!D41) -> 0 | E30: =SUM(IncomeStatement!E41) -> 0 | F30: =SUM(IncomeStatement!F41) -> 0 | G30: =SUM(IncomeStatement!G41) -> 0 | H30: =SUM(IncomeStatement!H41) -> 0 | I30: =SUM(IncomeStatement!I41) -> 0 | J30: =SUM(IncomeStatement!J41) -> 0 | ... N30: =SUM(IncomeStatement!N41) -> 0
... A40: =IncomeStatement!A51 -> Credit Card Fees | C40: =SUM(IncomeStatement!C51) -> 0 | D40: =SUM(IncomeStatement!D51) -> 0 | E40: =SUM(IncomeStatement!E51) -> 0 | F40: =SUM(IncomeStatement!F51) -> 0 | G40: =SUM(IncomeStatement!G51) -> 0 | H40: =SUM(IncomeStatement!H51) -> 0 | I40: =SUM(IncomeStatement!I51) -> 0 | J40: =SUM(IncomeStatement!J51) -> 0 | ... N40: =SUM(IncomeStatement!N51) -> 0
A41: =IncomeStatement!A52 -> Interest | C41: =IncomeStatement!C52 -> 0 | D41: =IncomeStatement!D52 -> 0 | E41: =IncomeStatement!E52 -> 0 | F41: =IncomeStatement!F52 -> 0 | G41: =IncomeStatement!G52 -> 0 | H41: =IncomeStatement!H52 -> 0 | I41: =IncomeStatement!I52 -> 0 | J41: =IncomeStatement!J52 -> 0 | ... N41: =IncomeStatement!N52 -> 0
A42: =IncomeStatement!A53 -> Bank Fees | C42: =SUM(IncomeStatement!C53) -> 0 | D42: =SUM(IncomeStatement!D53) -> 0 | E42: =SUM(IncomeStatement!E53) -> 0 | F42: =SUM(IncomeStatement!F53) -> 0 | G42: =SUM(IncomeStatement!G53) -> 0 | H42: =SUM(IncomeStatement!H53) -> 0 | I42: =SUM(IncomeStatement!I53) -> 0 | J42: =SUM(IncomeStatement!J53) -> 0 | ... N42: =SUM(IncomeStatement!N53) -> 0
A43: =IncomeStatement!A54 -> Training | C43: =SUM(IncomeStatement!C54) -> 0 | D43: =SUM(IncomeStatement!D54) -> 0 | E43: =SUM(IncomeStatement!E54) -> 0 | F43: =SUM(IncomeStatement!F54) -> 0 | G43: =SUM(IncomeStatement!G54) -> 0 | H43: =SUM(IncomeStatement!H54) -> 0 | I43: =SUM(IncomeStatement!I54) -> 0 | J43: =SUM(IncomeStatement!J54) -> 0 | ... N43: =SUM(IncomeStatement!N54) -> 0
A44: =IncomeStatement!A55 -> Travel | C44: =SUM(IncomeStatement!C55) -> 0 | D44: =SUM(IncomeStatement!D55) -> 0 | E44: =SUM(IncomeStatement!E55) -> 0 | F44: =SUM(IncomeStatement!F55) -> 0 | G44: =SUM(IncomeStatement!G55) -> 0 | H44: =SUM(IncomeStatement!H55) -> 0 | I44: =SUM(IncomeStatement!I55) -> 0 | J44: =SUM(IncomeStatement!J55) -> 0 | ... N44: =SUM(IncomeStatement!N55) -> 0
A45: =IncomeStatement!A56 -> Supplies | C45: =SUM(IncomeStatement!C56) -> 0 | D45: =SUM(IncomeStatement!D56) -> 0 | E45: =SUM(IncomeStatement!E56) -> 0 | F45: =SUM(IncomeStatement!F56) -> 0 | G45: =SUM(IncomeStatement!G56) -> 0 | H45: =SUM(IncomeStatement!H56) -> 0 | I45: =SUM(IncomeStatement!I56) -> 0 | J45: =SUM(IncomeStatement!J56) -> 0 | ... N45: =SUM(IncomeStatement!N56) -> 0
A46: =IncomeStatement!$A$58 -> Miscellaneous | C46: =SUM(IncomeStatement!C58) -> 0 | D46: =SUM(IncomeStatement!D58) -> 0 | E46: =SUM(IncomeStatement!E58) -> 0 | F46: =SUM(IncomeStatement!F58) -> 0 | G46: =SUM(IncomeStatement!G58) -> 0 | H46: =SUM(IncomeStatement!H58) -> 0 | I46: =SUM(IncomeStatement!I58) -> 0 | J46: =SUM(IncomeStatement!J58) -> 0 | ... N46: =SUM(IncomeStatement!N58) -> 0
A48: TOTAL OPERATING EXPENSES | B48: =SUM(B18:B47) -> 0 | C48: =SUM(C18:C47) -> 0 | D48: =SUM(D18:D47) -> 0 | E48: =SUM(E18:E47) -> 0 | F48: =SUM(F18:F47) -> 0 | G48: =SUM(G18:G47) -> 0 | H48: =SUM(H18:H47) -> 0 | I48: =SUM(I18:I47) -> 0 | ... N48: =SUM(N18:N47) -> 0
A50: OTHER EXPENDITURES
A52: Inventory Purchases/CoGS | B52: =+BeginInv!D28 -> 0 | C52: =SUM(IncomeStatement!C21) -> 0 | D52: =SUM(IncomeStatement!D21) -> 0 | E52: =SUM(IncomeStatement!E21) -> 0 | F52: =SUM(IncomeStatement!F21) -> 0 | G52: =SUM(IncomeStatement!G21) -> 0 | H52: =SUM(IncomeStatement!H21) -> 0 | I52: =SUM(IncomeStatement!I21) -> 0 | J52: =SUM(IncomeStatement!J21) -> 0 | ... N52: =SUM(IncomeStatement!N21) -> 0
A53: Loan Principal Payments | C53: =Amortization!E22 -> 0 | D53: =Amortization!E23 -> 0 | E53: =Amortization!E24 -> 0 | F53: =Amortization!E25 -> 0 | G53: =Amortization!E26 -> 0 | H53: =Amortization!E27 -> 0 | I53: =Amortization!E28 -> 0 | J53: =Amortization!E29 -> 0 | K53: =Amortization!E30 -> 0 | L53: =Amortization!E31 -> 0 | M53: =Amortization!E32 -> 0 | N53: =Amortization!E33 -> 0
A54: Start Up Costs | B54: =+Startupcosts!B37 -> 0
A55: ** Capital Expenditures | B55: =SourceFunds!B24+SourceFunds!B32+SourceFunds!B34 -> 0
A56: Owners Draw's | B56: 0 | C56: 0 | D56: 0 | E56: 0 | F56: 0 | G56: 0 | H56: 0 | I56: 0 | J56: 0 | K56: 0 | L56: 0 | M56: 0 | N56: 0
A58: TOTAL CASH PAID OUT | B58: =SUM(B56,B55,B53,B54,B52,B48) -> 0 | C58: =SUM(C56,C55,C53,C52,C48) -> 0 | D58: =SUM(D56,D55,D53,D52,D48) -> 0 | E58: =SUM(E56,E55,E53,E52,E48) -> 0 | F58: =SUM(F56,F55,F53,F52,F48) -> 0 | G58: =SUM(G56,G55,G53,G52,G48) -> 0 | H58: =SUM(H56,H55,H53,H52,H48) -> 0 | I58: =SUM(I56,I55,I53,I52,I48) -> 0 | J58: =SUM(J56,J55,J53,J52,J48) -> 0 | ... N58: =SUM(N56,N55,N53,N52,N48) -> 0
A60: NET CASH AVAILABLE | B60: =B14-B58 -> 0 | C60: =C14-C58 -> 0 | D60: =D14-D58 -> 0 | E60: =E14-E58 -> 0 | F60: =F14-F58 -> 0 | G60: =G14-G58 -> 0 | H60: =H14-H58 -> 0 | I60: =I14-I58 -> 0 | ... N60: =N14-N58 -> 0
...

Sheet Bizbalsht
A1: BUSINESS BALANCE SHEET
A4: ASSETS | B4: Start Up | C4: YEAR 1 | D4: YEAR 2 | E4: YEAR 3
A6: Current Assets
A8: Cash | B8: =CashFlow!B5 -> 0 | C8: =CashFlow!$N$60 -> 0 | D8: 0 | E8: 0
A9: Accounts Receivable | B9: 0 | C9: 0 | D9: 0 | E9: 0
A10: Inventory | B10: =BeginInv!D28 -> 0 | C10: 0 | D10: 0 | E10: 0
A11: Prepaid Expenses | B11: =Startupcosts!B13+Startupcosts!B15 -> 0 | C11: =Startupcosts!C13+Startupcosts!C15 -> 0 | D11: 0 | E11: 0
A13: Total Current Assets | B13: =SUM(B8:B12) -> 0 | C13: =SUM(C8:C12) -> 0 | D13: =SUM(D8:D12) -> 0 | E13: =SUM(E8:E12) -> 0
A15: Fixed Assets
A17: Land | B17: =SourceFunds!B32 -> 0 | C17: =SourceFunds!B32 -> 0 | D17: 0 | E17: 0
A18: Buildings | B18: =SourceFunds!B34 -> 0 | C18: =SourceFunds!B34 -> 0 | D18: 0 | E18: 0
