Workbook

Sheet Instructions
A2: This is an analysis tool, not a specific answer. It provides a framework for modeling different business models so that Cisco customers
A3: and partners can better understand the opportunity available with in-building network applications in hotels.
A5: The initial assumptions provided represent a strongly validated starting point. The cost numbers are based on extensive direct experience
A6: as well as workshops and validations by service providers, systems integrators and hotel properties and chains. The revenue numbers
A7: are highly conservative and are based on what we see as a minimal penetration rate for guest room and meeting room Internet access.
A9: To use the model, you'll need to first set the assumptions at the top of the Summary worksheet. Click on the Summary tab below and it will
A10: take you to that worksheet. The items that can be adjusted include:
B11: Number of rooms
B12: Number of meeting rooms (default is 1 meeting room per 25 guest rooms)
B13: Cost of the T1 and average hourly installation labor cost
B14: The type of infrastructure being deployed to the guest rooms - can set to LRE, Ethernet, Cable
B15: Buy vs lease
B16: Property owner vs service provider - A service provider's costs to provide circuits, NOC,a nd end user support will be lower than a property's
A18: Video numbers are included as a placeholder and a starting point. There currently are no known vednors providing commercially supported in-room
A19: video on demand systems. However, Cisco believes that several vendors will enter this market soon, and we think the initial assumptions shown in this

Sheet Summary
A1: Property Assumptions | G1: Infrastructure / Installation Assumptions
A2: Number of Rooms | D2: 300 | G2: LRE, Cable, or Ethernet? | K2: lre | L2: drives guest room equipment and install numbers
A3: Number of Meeting Rooms | D3: =0.04*D2 -> 12 | E3: 4% of guest rooms | K3: =IF(K2="lre",'Equipment - LRE'!F20,IF(K2="cable",'Equipment - Cable'!F13,IF(K2="ethernet",Ethernet!F18,0))) -> 136942.05 | L3: Guest room equipment cost
A4: Assume entire hotel is installed | K4: =IF(K2="lre",'Equipment - LRE'!F30,IF(K2="cable",'Equipment - Cable'!F22,IF(K2="ethernet",Ethernet!F26,0))) -> 25603.75 | L4: Meeting room equipment cost
A5: Occupancy rate | D5: 0.8 | G5: Cisco Equipment Discount | K5: 0.35
A6: Meeting room occupancy rate | D6: 0.5 | G6: Enter "Lease" or "Buy" - no quotes | K6: lease
A7: Price per night for guestroom Internet access | D7: 10 | G7: Who is Providing the Service? | K7: prop | L7: Enter "SP" for Service Provider, "Prop" for Property
A8: Price per day for meeting room Internet access | D8: 600 | L8: Drives operating cost assumptions
A9: Revenue Share for guest rooms | D9: 0 | G9: Note: Video numbers are representative of future targets and dcan not be validated
A10: Installation Labor Cost per Hour | D10: 90 | G10: Include Video? | K10: no
A11: Monthly cost per T1 including ISP | D11: 650 | H11: Number of owned movies | K11: 10
H12: Percent of First run viewing vs owned | K12: 0.25
H13: Cost per owned movie | K13: 1000 | L13: range from 300-1800
H14: Charge per movie | K14: 8.95
A16: Pro Forma Income Model for Hotels
A18: =Revenue!A19 -> Annual Revenue | C18: Install | D18: Year 1 | E18: Year 2 | F18: Year 3 | G18: Year 4 | H18: Year 5
A19: =Revenue!A20 -> Guest Room Revenue | D19: =Revenue!C20 -> 18144 | E19: =Revenue!D20 -> 36288 | F19: =Revenue!E20 -> 54432 | G19: =Revenue!F20 -> 72576 | H19: =Revenue!G20 -> 90720
A20: =Revenue!A21 -> Revenue share | D20: =Revenue!C21 -> 0 | E20: =Revenue!D21 -> 0 | F20: =Revenue!E21 -> 0 | G20: =Revenue!F21 -> 0 | H20: =Revenue!G21 -> 0
A21: =Revenue!A22 -> Meeting Revenue | D21: =Revenue!C22 -> 27216 | E21: =Revenue!D22 -> 54432 | F21: =Revenue!E22 -> 81648 | G21: =Revenue!F22 -> 108864 | H21: =Revenue!G22 -> 136080
A22: Video Revenue | D22: =IF($K$10="Yes",Revenue!C32,0) -> 0 | E22: =IF($K$10="Yes",Revenue!D32,0) -> 0 | F22: =IF($K$10="Yes",Revenue!E32,0) -> 0 | G22: =IF($K$10="Yes",Revenue!F32,0) -> 0 | H22: =IF($K$10="Yes",Revenue!G32,0) -> 0
A23: Total Revenue | D23: =SUM(D19:D22) -> 45360 | E23: =SUM(E19:E22) -> 90720 | F23: =SUM(F19:F22) -> 136080 | G23: =SUM(G19:G22) -> 181440 | H23: =SUM(H19:H22) -> 226800
A25: Cost | I25: Lease rates
A26: Guest room hardware | C26: =IF($K$6="Buy",K3,0) -> 0 | D26: =IF($K$6="Buy",0,IF($K$6="Lease",IF($K$2="LRE",$K3*$I$26*12,$K3*$I$26*12),0)) -> 49299.138 | E26: =IF($K$6="Buy",0,IF($K$6="Lease",IF($K$2="LRE",$K3*$I$26*12,$K3*$I$26*12),0)) -> 49299.138 | F26: =IF($K$6="Buy",0,IF($K$6="Lease",IF($K$2="LRE",$K3*$I$26*12,$K3*$I$26*12),0)) -> 49299.138 | G26: =IF($K$6="Buy",0,IF($K$6="Lease",IF($K$2="LRE",$K3*$I$26*12,$K3*$I$26*12),0))*0.4 -> 19719.655 | H26: =IF($K$6="Buy",0,IF($K$6="Lease",IF($K$2="LRE",$K3*$I$26*12,$K3*$I$26*12),0))*0.4 -> 19719.655 | I26: 0.03 | J26: Using discounted costs
A27: Meeting room hardware | C27: =IF($K$6="Buy",'Equipment - LRE'!F30,0) -> 0 | D27: =IF($K$6="Buy",0,IF($K$6="Lease",'Equipment - LRE'!$F$30*$I$27*12,0)) -> 9217.35 | E27: =IF($K$6="Buy",0,IF($K$6="Lease",'Equipment - LRE'!$F$30*$I$27*12,0)) -> 9217.35 | F27: =IF($K$6="Buy",0,IF($K$6="Lease",'Equipment - LRE'!$F$30*$I$27*12,0)) -> 9217.35 | G27: =IF($K$6="Buy",0,IF($K$6="Lease",'Equipment - LRE'!$F$30*$I$27*12,0))*0.4 -> 3686.94 | H27: =IF($K$6="Buy",0,IF($K$6="Lease",'Equipment - LRE'!$F$30*$I$27*12,0))*0.4 -> 3686.94 | I27: 0.03 | J27: Using discounted costs
A28: Video equipment costs | C28: =IF(K10="Yes",IF($K$6="Buy",'Equipment - LRE'!F38,0),0) -> 0 | D28: =IF($K$10="Yes",IF($K$6="Buy",0,IF($K$6="Lease",'Equipment - LRE'!$F$38*$I$27*12,0)),0) -> 0 | E28: =IF($K$10="Yes",IF($K$6="Buy",0,IF($K$6="Lease",'Equipment - LRE'!$F$38*$I$27*12,0)),0) -> 0 | F28: =IF($K$10="Yes",IF($K$6="Buy",0,IF($K$6="Lease",'Equipment - LRE'!$F$38*$I$27*12,0)),0) -> 0 | G28: =IF($K$10="Yes",IF($K$6="Buy",0,IF($K$6="Lease",'Equipment - LRE'!$F$38*$I$27*12,0)),0)*0.5 -> 0 | H28: =IF($K$10="Yes",IF($K$6="Buy",0,IF($K$6="Lease",'Equipment - LRE'!$F$38*$I$27*12,0)),0)*0.5 -> 0 | I28: 0.03 | J28: Using discounted costs
A29: Installation labor costs | C29: =IF($K$6="Buy",IF($K$2="lre",'Install Labor Costs'!$D$31,IF($K$2="cable",'Install Labor Costs'!$F$31,IF($K$2="ethernet",'Install Labor Costs'!$F$31,0))),0) -> 0 | D29: =IF($K$6="Buy",0,IF($K$6="Lease",IF($K$2="lre",'Install Labor Costs'!$D$31*$I$29*12,IF($K$2="cable",'Install Labor Costs'!$F$31*$I$29*12,IF($K$2="ethernet",'Install Labor Costs'!$F$31*$I$29*12,0))),0)) -> 8278.2 | E29: =IF($K$6="Buy",0,IF($K$6="Lease",IF($K$2="lre",'Install Labor Costs'!$D$31*$I$29*12,IF($K$2="cable",'Install Labor Costs'!$F$31*$I$29*12,IF($K$2="ethernet",'Install Labor Costs'!$F$31*$I$29*12,0))),0)) -> 8278.2 | F29: =IF($K$6="Buy",0,IF($K$6="Lease",IF($K$2="lre",'Install Labor Costs'!$D$31*$I$29*12,IF($K$2="cable",'Install Labor Costs'!$F$31*$I$29*12,IF($K$2="ethernet",'Install Labor Costs'!$F$31*$I$29*12,0))),0)) -> 8278.2 | I29: 0.035 | J29: Assuming trained crews using BBSM processes
A30: Circuit | B30: =K$7 -> prop | D30: ='SG&A and Service & Support'!D14*IF($K$7="SP",0.8,IF($K$7="PROP",1,0)) -> 7800 | E30: =D30*0.9 -> 7020 | F30: =E30*0.9 -> 6318 | G30: =F30*0.9 -> 5686.2 | H30: =G30*0.9 -> 5117.58 | J30: 10% annual decline, both transport and bandwidth, 50% off if service provider
A31: Help Desk | B31: =K$7 -> prop | D31: ='SG&A and Service & Support'!$D19*IF($K$7="SP",0.7,IF($K$7="PROP",1,0)) -> 5400 | E31: ='SG&A and Service & Support'!$D19*IF($K$7="SP",0.7,IF($K$7="PROP",1,0)) -> 5400 | F31: ='SG&A and Service & Support'!$D19*IF($K$7="SP",0.7,IF($K$7="PROP",1,0)) -> 5400 | G31: ='SG&A and Service & Support'!$D19*IF($K$7="SP",0.7,IF($K$7="PROP",1,0)) -> 5400 | H31: ='SG&A and Service & Support'!$D19*IF($K$7="SP",0.7,IF($K$7="PROP",1,0)) -> 5400 | J31: Based on pro-forma quotes, less if a SP
A32: NOC | B32: =K$7 -> prop | D32: ='SG&A and Service & Support'!$D20*IF($K$7="SP",0.6,IF($K$7="PROP",1,0)) -> 14400 | E32: ='SG&A and Service & Support'!$D20*IF($K$7="SP",0.6,IF($K$7="PROP",1,0)) -> 14400 | F32: ='SG&A and Service & Support'!$D20*IF($K$7="SP",0.6,IF($K$7="PROP",1,0)) -> 14400 | G32: ='SG&A and Service & Support'!$D20*IF($K$7="SP",0.6,IF($K$7="PROP",1,0)) -> 14400 | H32: ='SG&A and Service & Support'!$D20*IF($K$7="SP",0.6,IF($K$7="PROP",1,0)) -> 14400 | J32: Based on pro-forma quotes
A33: SmartNet - Break Fix | D33: ='SG&A and Service & Support'!$D23 -> 8635.664 | E33: ='SG&A and Service & Support'!$D23 -> 8635.664 | F33: ='SG&A and Service & Support'!$D23 -> 8635.664 | G33: ='SG&A and Service & Support'!$D23 -> 8635.664 | H33: ='SG&A and Service & Support'!$D23 -> 8635.664 | J33: based on | K33: 0.08 | L33: SmartNet fee
A34: SG&A | D34: ='SG&A and Service & Support'!D28*IF($K$7="SP",0.5,IF($K$7="PROP",1,0)) -> 4600 | E34: ='SG&A and Service & Support'!E28*IF($K$7="SP",0.5,IF($K$7="PROP",1,0)) -> 3400 | F34: =0.9*E34 -> 3060 | G34: =0.9*F34 -> 2754 | H34: =0.9*G34 -> 2478.6 | J34: Buffer number for overhead costs,includes marketing.
A35: Video costs | D35: =IF($K$10="Yes",'SG&A and Service & Support'!$D37,0) -> 0 | E35: =IF($K$10="Yes",'SG&A and Service & Support'!$D37,0) -> 0 | F35: =IF($K$10="Yes",'SG&A and Service & Support'!$D37,0) -> 0 | G35: =IF($K$10="Yes",'SG&A and Service & Support'!$D37,0) -> 0 | H35: =IF($K$10="Yes",'SG&A and Service & Support'!$D37,0) -> 0
B36: Total Cost | C36: =SUM(C26:C32) -> 0 | D36: =SUM(D26:D35) -> 107630.35 | E36: =SUM(E26:E35) -> 105650.35 | F36: =SUM(F26:F35) -> 104608.35 | G36: =SUM(G26:G35) -> 60282.459 | H36: =SUM(H26:H35) -> 59438.439
A38: Cash Flow | C38: =C23-C36 -> 0 | D38: =D23-D36 -> -62270.352 | E38: =E23-E36 -> -14930.352 | F38: =F23-F36 -> 31471.648 | G38: =G23-G36 -> 121157.54 | H38: =H23-H36 -> 167361.56
B39: IRR - 5 years | D39: =IRR(C38:H38) -> 0.56887084
D40: Year 1 | E40: Year 2 | F40: Year 3 | G40: Year 4 | H40: Year 5
C41: Total cost per day | D41: =-D36/(365*($D$2+$D$3)) -> -0.94512076 | E41: =-E36/(365*($D$2+$D$3)) -> -0.92773404 | F41: =-F36/(365*($D$2+$D$3)) -> -0.91858405 | G41: =-G36/(365*($D$2+$D$3)) -> -0.52935071 | H41: =-H36/(365*($D$2+$D$3)) -> -0.52193923 | J41: Includes all services
C42: Cost per day - net of meeting room revenue | D42: =-(D36-D21-D22)/(365*($D$2+$D$3)) -> -0.70613235 | E42: =-(E36-E21-E22)/(365*($D$2+$D$3)) -> -0.44975722 | F42: =-(F36-F21-F22)/(365*($D$2+$D$3)) -> -0.20161883 | G42: =-(G36-G21-G22)/(365*($D$2+$D$3)) -> 0.42660292 | H42: =-(H36-H21-H22)/(365*($D$2+$D$3)) -> 0.67300282 | J42: If video offered
C43: Cost per day - net of meeting room and in-room revenue | D43: =-(D36-D23)/(365*($D$2+$D$3)) -> -0.54680674 | E43: =-(E36-E23)/(365*($D$2+$D$3)) -> -0.13110601 | F43: =-(F36-F23)/(365*($D$2+$D$3)) -> 0.27635799 | G43: =-(G36-G23)/(365*($D$2+$D$3)) -> 1.0639053 | H43: =-(H36-H23)/(365*($D$2+$D$3)) -> 1.4696308 | J43: Includes all services
B47: The property-owned model includes full, outsourced incremental costs for circuits, support, NOC and maintenance
...

Sheet Revenue
C2: Year 1 | D2: Year 2 | E2: Year 3 | F2: Year 4 | G2: Year 5
A3: Jacks Installed | C3: =Summary!$D2 -> 300 | D3: =Summary!$D2 -> 300 | E3: =Summary!$D2 -> 300 | F3: =Summary!$D2 -> 300 | G3: =Summary!$D2 -> 300
A4: Meeting Rooms Installed | C4: =Summary!$D3 -> 12 | D4: =Summary!$D3 -> 12 | E4: =Summary!$D3 -> 12 | F4: =Summary!$D3 -> 12 | G4: =Summary!$D3 -> 12
A6: Usage Forecast
A7: # of available business nights/year | C7: =C3*Summary!$D5*252 -> 60480 | D7: =D3*Summary!$D5*252 -> 60480 | E7: =E3*Summary!$D5*252 -> 60480 | F7: =F3*Summary!$D5*252 -> 60480 | G7: =G3*Summary!$D5*252 -> 60480 | H7: Using assumed occupancy and 21 business nights/month
A8: Guest Room Take Rate | C8: 0.03 | D8: 0.06 | E8: 0.09 | F8: 0.12 | G8: 0.15 | H8: Driven by awareness and VPN penetration
A9: BBSM Uses/Year | C9: =C8*C7 -> 1814.4 | D9: =D8*D7 -> 3628.8 | E9: =E8*E7 -> 5443.2 | F9: =F8*F7 -> 7257.6 | G9: =G8*G7 -> 9072
A11: # of available meetings/year | C11: =C4*Summary!$D6*252 -> 1512 | D11: =D4*Summary!$D6*252 -> 1512 | E11: =E4*Summary!$D6*252 -> 1512 | F11: =F4*Summary!$D6*252 -> 1512 | G11: =G4*Summary!$D6*252 -> 1512 | H11: Using assumed occupancy and 21 business days/month
A12: Meeting Room Take Rate | C12: 0.03 | D12: 0.06 | E12: 0.09 | F12: 0.12 | G12: 0.15
A13: M.R. Rentals/Year | C13: =C12*C11 -> 45.36 | D13: =D12*D11 -> 90.72 | E13: =E12*E11 -> 136.08 | F13: =F12*F11 -> 181.44 | G13: =G12*G11 -> 226.8
A15: Price
A16: BBSM Rental | C16: =Summary!$D7 -> 10 | D16: =Summary!$D7 -> 10 | E16: =Summary!$D7 -> 10 | F16: =Summary!$D7 -> 10 | G16: =Summary!$D7 -> 10 | H16: From assumption on Summary page
A17: Meeting Room | C17: =Summary!$D8 -> 600 | D17: =Summary!$D8 -> 600 | E17: =Summary!$D8 -> 600 | F17: =Summary!$D8 -> 600 | G17: =Summary!$D8 -> 600 | H17: From assumption on Summary page
A19: Annual Revenue
A20: Guest Room Revenue | C20: =C16*C9 -> 18144 | D20: =D16*D9 -> 36288 | E20: =E16*E9 -> 54432 | F20: =F16*F9 -> 72576 | G20: =G16*G9 -> 90720
A21: Revenue share | C21: =-Summary!$D9*C20 -> 0 | D21: =-Summary!$D9*D20 -> 0 | E21: =-Summary!$D9*E20 -> 0 | F21: =-Summary!$D9*F20 -> 0 | G21: =-Summary!$D9*G20 -> 0 | H21: From assumption on Summary page
A22: Meeting Revenue | C22: =C17*C13 -> 27216 | D22: =D17*D13 -> 54432 | E22: =E17*E13 -> 81648 | F22: =F17*F13 -> 108864 | G22: =G17*G13 -> 136080
A23: Total Access Revenue | C23: =C20+C22+C21 -> 45360 | D23: =D20+D22+D21 -> 90720 | E23: =E20+E22+E21 -> 136080 | F23: =F20+F22+F21 -> 181440 | G23: =G20+G22+G21 -> 226800
A25: Video Revenue
A26: Penetration | C26: 0.12 | D26: 0.12 | E26: 0.12 | F26: 0.12 | G26: 0.12 | H26: Based on OnCommand and lodgeNet results
A27: % First Run | C27: =Summary!$K12 -> 0.25 | D27: =Summary!$K12 -> 0.25 | E27: =Summary!$K12 -> 0.25 | F27: =Summary!$K12 -> 0.25 | G27: =Summary!$K12 -> 0.25 | H27: From assumption on Summary page
A28: First run viewers/year | C28: =C7*C26*C27 -> 1814.4 | D28: =D7*D26*D27 -> 1814.4 | E28: =E7*E26*E27 -> 1814.4 | F28: =F7*F26*F27 -> 1814.4 | G28: =G7*G26*G27 -> 1814.4 | H28: calculated
A29: Owned movie viewers per year | C29: =C7*C26*(1-C27) -> 5443.2 | D29: =D7*D26*(1-D27) -> 5443.2 | E29: =E7*E26*(1-E27) -> 5443.2 | F29: =F7*F26*(1-F27) -> 5443.2 | G29: =G7*G26*(1-G27) -> 5443.2 | H29: calculated
A30: Total Video Users | C30: =C28+C29 -> 7257.6 | D30: =D28+D29 -> 7257.6 | E30: =E28+E29 -> 7257.6 | F30: =F28+F29 -> 7257.6 | G30: =G28+G29 -> 7257.6
A31: Revenue per use | C31: =Summary!$K14 -> 8.95 | D31: =Summary!$K14 -> 8.95 | E31: =Summary!$K14 -> 8.95 | F31: =Summary!$K14 -> 8.95 | G31: =Summary!$K14 -> 8.95
A32: Total Video Revenue | C32: =C30*C31 -> 64955.52 | D32: =D30*D31 -> 64955.52 | E32: =E30*E31 -> 64955.52 | F32: =F30*F31 -> 64955.52 | G32: =G30*G31 -> 64955.52
A35: Data points for guest room usage
B36: current averages are 3-4% usage for properties installed over 6 months, trending upwards as more travellers expect hi speed access
B37: - Increased penetration of VPNs for Enterprise networks will greatly increase usage
B38: - On average, it costs a company $13 for an employee to dial-in from a hotel for email, including 800 line, modem banks, and hotel charges
B39: - In room broadband access costs only $10
B40: 60% of business travellers check their email/access the Internet on the road
B42: Meeting room usage is still unpredictable, but is viewed as the most profitable part of the hotel network
B44: ** By far the most important criteria is deploying into an "A" or "B" property that attracts business travellers
A46: Data points for meeting room access
B47: Primarily applies to large, business oriented hotels, especially in tech centers
B48: Can achieve more than $20,000 in revenue over a single multi-day event
B49: Can charge from $100 - 200/per person for a connection. More if connecting a booth/exhibit
A51: Data points for Video
B52: Both OnCommand and LodgeNet average 12-13% penetration. A new VoD service would be superior to these, but face similar usage
...

Sheet Ethernet
A3: Guestroom and Core Hardware Components | B3: Qty. | C3: Unit Price | D3: Ext. Price | E3: Discount | F3: Total
A4: Catalyst 2924 Distribution Switches | B4: =INT(Summary!D2/24)+1 -> 13 | C4: 1995 | D4: =B4*C4 -> 25935 | E4: =Summary!$K$5 -> 0.35 | F4: =D4*(1-E4) -> 16857.75 | G4: 24 port switches
A5: In-Room Ethernet Cables | B5: =Summary!D$2 -> 300 | C5: 1.5 | D5: =B5*C5 -> 450 | E5: 0 | F5: =D5*(1-E5) -> 450
A6: RJ-21 Cross Connect Cables | B6: =2*B4 -> 26 | C6: 50 | D6: =B6*C6 -> 1300 | E6: 0 | F6: =D6*(1-E6) -> 1300
A7: Block, 66 TELCO(w/Amphenol Connector) | B7: =2*B4 -> 26 | C7: 33 | D7: =B7*C7 -> 858 | E7: 0 | F7: =D7*(1-E7) -> 858
A8: Ethernet Patch Cables | B8: 17 | C8: 3.15 | D8: =B8*C8 -> 53.55 | E8: 0 | F8: =D8*(1-E8) -> 53.55
A9: Catalyst 2924 Base Switches | B9: =IF(Summary!D2<200,0,1) -> 1 | C9: 1995 | D9: =B9*C9 -> 1995 | E9: =Summary!$K$5 -> 0.35 | F9: =D9*(1-E9) -> 1296.75
A10: 15" Monitor | B10: 1 | C10: 157 | D10: =B10*C10 -> 157 | E10: 0 | F10: =D10*(1-E10) -> 157
A11: Rack, Component 7' x 19" | B11: 1 | C11: 120 | D11: =B11*C11 -> 120 | E11: 0 | F11: =D11*(1-E11) -> 120
A12: Cisco Building Broadband Service Manager | B12: 1 | C12: 11500 | D12: =B12*C12 -> 11500 | E12: =Summary!$K$5 -> 0.35 | F12: =D12*(1-E12) -> 7475
A13: Incremental port licenses | B13: =IF((INT(((Summary!D2+Summary!D3)-96)/24)+1)>0,(INT(((Summary!D2+Summary!D3)-96)/24)+1),0) -> 10 | C13: 600 | D13: =B13*C13 -> 6000 | E13: =Summary!$K$5 -> 0.35 | F13: =D13*(1-E13) -> 3900
A14: APC UPS for BBSM Server, Router, Base Switch | B14: 1 | C14: 900 | D14: =B14*C14 -> 900 | E14: 0 | F14: =D14*(1-E14) -> 900
A15: PMS Connection Cable | B15: 1 | C15: 120 | D15: =B15*C15 -> 120 | E15: 0 | F15: =D15*(1-E15) -> 120
A16: Cisco 2611 Router | B16: 1 | C16: 5895 | D16: =B16*C16 -> 5895 | E16: =Summary!$K$5 -> 0.35 | F16: =D16*(1-E16) -> 3831.75 | G16: Includes firewall feature set
A17: Cisco CE 507 Content Engine, AC Power, Cache SW | B17: =IF(Summary!D2>150,1,0) -> 1 | C17: 5500 | D17: =B17*C17 -> 5500 | E17: =Summary!$K$5 -> 0.35 | F17: =D17*(1-E17) -> 3575 | G17: Only in hotels with over 150 rooms
A18: Total Guestroom and Core Hardware Costs | D18: =SUM(D4:D16) -> 55283.55 | F18: =SUM(F4:F16) -> 37319.8
A19: Hardware Cost per Room | D19: =D18/Summary!$D2 -> 184.2785 | F19: =F18/Summary!$D2 -> 124.39933
A21: Meeting Room Solution (Use Aironet Wireless) | B21: Qty. | C21: Unit Price | D21: Ext. Price | E21: Discount | F21: Total | G21: * Assumes non-fixed deployment of gear
A22: Wireless Access Points | B22: =IF(Summary!D3=0,0,INT((Summary!$D$3+3)/3)) -> 5 | C22: 1499 | D22: =B22*C22 -> 7495 | E22: =Summary!$K$5 -> 0.35 | F22: =D22*(1-E22) -> 4871.75 | G22: Includes 75' cables and best antenna
A23: Wireless Bridges | B23: =2*B22 -> 10 | C23: 1499 | D23: =B23*C23 -> 14990 | E23: =Summary!$K$5 -> 0.35 | F23: =D23*(1-E23) -> 9743.5
A24: Hubs for Meeting Room Use | B24: =B23 -> 10 | C24: 495 | D24: =B24*C24 -> 4950 | E24: 0 | F24: =D24*(1-E24) -> 4950
A25: Catalyst 2924 Distribution Switches | B25: =IF(Summary!$D$3<5,0,1) -> 1 | C25: 1995 | D25: =B25*C25 -> 1995 | E25: =Summary!$K$5 -> 0.35 | F25: =D25*(1-E25) -> 1296.75 | G25: Optionally the 3500XL PWR for $3,995
A26: Total Meeting Room Hardware Costs | D26: =SUM(D22:D25) -> 29430 | F26: =SUM(F22:F25) -> 20862
A28: Estimated Total Project Equipment Cost | D28: =D18+D26 -> 84713.55 | F28: =F18+F26 -> 58181.8
A30: Video
A31: Video Server | B31: =INT(Summary!D2/600)+1 -> 1 | C31: 12000 | D31: =B31*C31 -> 12000 | E31: =Summary!$K$5 -> 0.35 | F31: =D31*(1-E31) -> 7800 | G31: Estimate for a server capable of 40 users
A32: Video Management Server | B32: 1 | C32: 5000 | D32: =B32*C32 -> 5000 | E32: 0 | F32: =D32*(1-E32) -> 5000 | G32: Estimate
A33: Set Top Box | B33: =Summary!D2 -> 300 | C33: 200 | D33: =B33*C33 -> 60000 | E33: 0 | F33: =D33*(1-E33) -> 60000 | G33: Estimated incremental cost assuming LRE CPE is rotated to another site
A34: Total Video Hardware Costs | D34: =SUM(D31:D33) -> 77000 | F34: =SUM(F31:F33) -> 72800 | H34: hope to achieve sub-200 in volume

Sheet Equipment - LRE
A3: Guestroom and Core Hardware Components | B3: Qty. | C3: Unit Price | D3: Ext. Price | E3: Discount | F3: Total
A4: Catalyst 2924 LRE Switches | B4: =INT(Summary!D2/24)+1 -> 13 | C4: 6495 | D4: =B4*C4 -> 84435 | E4: =Summary!$K$5 -> 0.35 | F4: =D4*(1-E4) -> 54882.75 | G4: 24 port switches
A5: POTs Splitters | B5: =INT(Summary!D$2/48)+1 -> 7 | C5: 1395 | D5: =B5*C5 -> 9765 | E5: =Summary!$K$5 -> 0.35 | F5: =D5*(1-E5) -> 6347.25 | G5: 48 port POTS splitters
A6: Catalyst 575 LRE CPE Modems | B6: =Summary!D$2 -> 300 | C6: 280 | D6: =B6*C6 -> 84000 | E6: =Summary!$K$5 -> 0.35 | F6: =D6*(1-E6) -> 54600
A7: In-Room Ethernet Cables | B7: =Summary!D$2 -> 300 | C7: 1.5 | D7: =B7*C7 -> 450 | E7: 0 | F7: =D7*(1-E7) -> 450
A8: RJ-21 Cables LRE Switch to POTs Splitters | B8: =B4 -> 13 | C8: 50 | D8: =B8*C8 -> 650 | E8: 0 | F8: =D8*(1-E8) -> 650
A9: RJ-21 Cross Connect Cables | B9: =2*B8 -> 26 | C9: 50 | D9: =B9*C9 -> 1300 | E9: 0 | F9: =D9*(1-E9) -> 1300
A10: Block, 66 TELCO(w/Amphenol Connector) | B10: =2*B8 -> 26 | C10: 33 | D10: =B10*C10 -> 858 | E10: 0 | F10: =D10*(1-E10) -> 858
A11: Ethernet Patch Cables | B11: 17 | C11: 3.15 | D11: =B11*C11 -> 53.55 | E11: 0 | F11: =D11*(1-E11) -> 53.55
A12: Catalyst 2924 Base Switches | B12: =IF(Summary!D2<200,0,1) -> 1 | C12: 1995 | D12: =B12*C12 -> 1995 | E12: =Summary!$K$5 -> 0.35 | F12: =D12*(1-E12) -> 1296.75
A13: 15" Monitor | B13: 1 | C13: 157 | D13: =B13*C13 -> 157 | E13: 0 | F13: =D13*(1-E13) -> 157
A14: Rack, Component 7' x 19" | B14: 1 | C14: 120 | D14: =B14*C14 -> 120 | E14: 0 | F14: =D14*(1-E14) -> 120
A15: Cisco Building Broadband Service Manager | B15: 1 | C15: 11500 | D15: =B15*C15 -> 11500 | E15: =Summary!$K$5 -> 0.35 | F15: =D15*(1-E15) -> 7475
A16: Incremental port licenses | B16: =IF((INT(((Summary!D2+Summary!D3)-96)/24)+1)>0,(INT(((Summary!D2+Summary!D3)-96)/24)+1),0) -> 10 | C16: 600 | D16: =B16*C16 -> 6000 | E16: =Summary!$K$5 -> 0.35 | F16: =D16*(1-E16) -> 3900
A17: APC UPS for BBSM Server, Router, Base Switch | B17: 1 | C17: 900 | D17: =B17*C17 -> 900 | E17: 0 | F17: =D17*(1-E17) -> 900
A18: PMS Connection Cable | B18: 1 | C18: 120 | D18: =B18*C18 -> 120 | E18: 0 | F18: =D18*(1-E18) -> 120
A19: Cisco 2611 Router | B19: 1 | C19: 5895 | D19: =B19*C19 -> 5895 | E19: =Summary!$K$5 -> 0.35 | F19: =D19*(1-E19) -> 3831.75 | G19: Includes firewall feature set
A20: Total Guestroom and Core Hardware Costs | D20: =SUM(D4:D19) -> 208198.55 | F20: =SUM(F4:F19) -> 136942.05
A21: Hardware Cost per Room | D21: =D20/Summary!D2 -> 693.99517 | F21: =F20/Summary!D2 -> 456.4735
A23: Meeting Room Solution (Use Aironet Wireless) | B23: Qty. | C23: Unit Price | D23: Ext. Price | E23: Discount | F23: Total | G23: * Assumes non-fixed deployment of gear
A24: Wireless Access Points | B24: =IF(Summary!D3=0,0,INT((Summary!$D$3+3)/3)) -> 5 | C24: 1499 | D24: =B24*C24 -> 7495 | E24: =Summary!$K$5 -> 0.35 | F24: =D24*(1-E24) -> 4871.75 | G24: Includes 75' cables and best antenna
A25: Wireless Bridges | B25: =2*B24 -> 10 | C25: 1499 | D25: =B25*C25 -> 14990 | E25: =Summary!$K$5 -> 0.35 | F25: =D25*(1-E25) -> 9743.5
A26: Hubs for Meeting Room Use | B26: =B25 -> 10 | C26: 495 | D26: =B26*C26 -> 4950 | E26: 0 | F26: =D26*(1-E26) -> 4950
A27: Catalyst 2924 LRE Switches | B27: =IF(Summary!$D$3<5,0,1) -> 1 | C27: 6495 | D27: =B27*C27 -> 6495 | E27: =Summary!$K$5 -> 0.35 | F27: =D27*(1-E27) -> 4221.75 | G27: Optionally the 3500XL PWR for $3,995
A28: POTs Splitters | B28: =IF(B27=0,0,1) -> 1 | C28: 1395 | D28: =B28*C28 -> 1395 | E28: =Summary!$K$5 -> 0.35 | F28: =D28*(1-E28) -> 906.75 | G28: enough to cover meeting rooms
A29: LRE Modem for Connection to MDF | B29: =B24 -> 5 | C29: 280 | D29: =B29*C29 -> 1400 | E29: =Summary!$K$5 -> 0.35 | F29: =D29*(1-E29) -> 910
A30: Total Meeting Room Hardware Costs | D30: =SUM(D24:D29) -> 36725 | F30: =SUM(F24:F29) -> 25603.75
A32: Estimated Total Project Equipment Cost | D32: =D20+D30 -> 244923.55 | F32: =F20+F30 -> 162545.8
A34: Video
A35: Video Server | B35: =INT(Summary!D2/600)+1 -> 1 | C35: 12000 | D35: =B35*C35 -> 12000 | E35: =Summary!$K$5 -> 0.35 | F35: =D35*(1-E35) -> 7800 | G35: Estimate for a server capable of 40 users
A36: Video Management Server | B36: 1 | C36: 5000 | D36: =B36*C36 -> 5000 | E36: 0 | F36: =D36*(1-E36) -> 5000 | G36: Estimate
A37: Set Top Box | B37: =Summary!D2 -> 300 | C37: 200 | D37: =B37*C37 -> 60000 | E37: 0 | F37: =D37*(1-E37) -> 60000 | G37: Estimated incremental cost assuming LRE CPE is rotated to another site
A38: Total Video Hardware Costs | D38: =SUM(D35:D37) -> 77000 | F38: =SUM(F35:F37) -> 72800 | H38: hope to achieve sub-200 in volume

Sheet Equipment - Cable
A1: Data service only
A3: Guestroom and Core Hardware Components | B3: Qty. | C3: Unit Price | D3: Ext. Price | E3: Discount | F3: Total
A4: Cable router uBR7114 | B4: 1 | C4: 25000 | D4: =B4*C4 -> 25000 | E4: =Summary!K$5 -> 0.35 | F4: =D4*(1-E4) -> 16250
A5: DOCSIS Modems (data only, non Cisco) | B5: =Summary!D2 -> 300 | C5: 150 | D5: =B5*C5 -> 45000 | E5: =Summary!K$5 -> 0.35 | F5: =D5*(1-E5) -> 29250
A6: In-Room Ethernet Cables | B6: =Summary!D2 -> 300 | C6: 2 | D6: =B6*C6 -> 600 | E6: 0 | F6: =D6*(1-E6) -> 600
A7: 15" Monitor | B7: 1 | C7: 157 | D7: =B7*C7 -> 157 | E7: 0 | F7: =D7*(1-E7) -> 157
A8: Rack, Component 7' x 19" | B8: 1 | C8: 120 | D8: =B8*C8 -> 120 | E8: 0 | F8: =D8*(1-E8) -> 120
A9: Cisco Building Broadband Service Manager | B9: 1 | C9: 11500 | D9: =B9*C9 -> 11500 | E9: =Summary!K$5 -> 0.35 | F9: =D9*(1-E9) -> 7475
A10: Incremental port licenses | B10: =IF((INT(((Summary!D2+Summary!D3)-96)/24)+1)>0,(INT(((Summary!D2+Summary!D3)-96)/24)+1),0) -> 10 | C10: 600 | D10: =B10*C10 -> 6000 | E10: =Summary!K$5 -> 0.35 | F10: =D10*(1-E10) -> 3900
A11: APC UPS for BBSM Server, Router, Base Switch | B11: 1 | C11: 900 | D11: =B11*C11 -> 900 | E11: 0 | F11: =D11*(1-E11) -> 900
A12: PMS Connection Cable | B12: 1 | C12: 120 | D12: =B12*C12 -> 120 | E12: 0 | F12: =D12*(1-E12) -> 120
A13: Total Guestroom and Core Hardware Costs | D13: =SUM(D4:D12) -> 89397 | F13: =SUM(F4:F12) -> 58772
A14: Hardware Cost per Room | D14: =D13/Summary!D2 -> 297.99 | F14: =F13/Summary!D2 -> 195.90667
A17: Meeting Room Solution (Use Aironet Wireless) | B17: Qty. | C17: Unit Price | D17: Ext. Price | E17: Discount | F17: Total | G17: * Assumes non-fixed deployment of gear
A18: Wireless Access Points | B18: =IF(Summary!D3=0,0,INT((Summary!$D$3+3)/3)) -> 5 | C18: 1877 | D18: =B18*C18 -> 9385 | E18: =Summary!K$5 -> 0.35 | F18: =D18*(1-E18) -> 6100.25 | G18: Includes 75' cables and best antenna
A19: Wireless Bridges | B19: =2*B18 -> 10 | C19: 1695 | D19: =B19*C19 -> 16950 | E19: =Summary!K$5 -> 0.35 | F19: =D19*(1-E19) -> 11017.5
A20: Hubs for Meeting Room Use | B20: =B19 -> 10 | C20: 400 | D20: =B20*C20 -> 4000 | E20: 0 | F20: =D20*(1-E20) -> 4000
A21: Cable Router for connection to coax uplink | B21: =B18 -> 5 | C21: 900 | D21: =B21*C21 -> 4500 | E21: =Summary!K$5 -> 0.35 | F21: =D21*(1-E21) -> 2925
A22: Total Meeting Room Hardware Costs | D22: =SUM(D18:D21) -> 34835 | F22: =SUM(F18:F21) -> 24042.75
A24: Estimated Total Data Equipment Cost | D24: =D22+D13 -> 124232 | F24: =F22+F13 -> 82814.75
A26: Video
A27: Video Server | B27: =INT(Summary!D2/600)+1 -> 1 | C27: 12000 | D27: =B27*C27 -> 12000 | E27: 0 | F27: =D27*(1-E27) -> 12000 | G27: Estimate for a server capable of 40 users
A28: Video Management Server | B28: 1 | C28: 5000 | D28: =B28*C28 -> 5000 | E28: 0 | F28: =D28*(1-E28) -> 5000 | G28: Estimate
A29: Set Top Box | B29: =Summary!D2 -> 300 | C29: 0 | D29: =B29*C29 -> 0 | E29: 0 | F29: =D29*(1-E29) -> 0 | G29: Assumes no incremental cost for set top box on cable infrastructure
A30: Total Video Hardware Costs | D30: =SUM(D27:D29) -> 17000 | F30: =SUM(F27:F29) -> 17000

Sheet Install Labor Costs
C1: Resp | D1: TIP Program Standards (LRE / Wireless) | F1: COAX cable and Cat 5 Ethernet installations
A3: Pre-Installation | D3: Hours | F3: Hours
B4: Site Survey | D4: =IF(Summary!D2>299,8,IF(Summary!D2>150,6,4)) -> 8 | F4: 5
B5: Site Preparations | C5: Property
B6: Network Design | D6: 1 | F6: 1
B7: TCP/IP Schemateic | D7: 1 | F7: 1
B8: Create Bill of Materials | D8: 1 | F8: 1
B9: Allocate/Pick Eqiupment | D9: 1 | F9: 1
B10: Configure Equipment | D10: 4 | F10: 2
B11: Ship to Site | D11: 1 | F11: 1
B12: Receive and store equipment on site | C12: Property
A14: Installation
B15: Site Meeting/Equipment Inventory/Shortages | D15: 4 | F15: 4
B16: Test Local Access Circuit | D16: 2 | F16: 2
B17: Install MDF - Cross Connects | D17: =0.1*Summary!D2 -> 30 | F17: 0
B18: Install MDF - Hardware Installation | D18: =Summary!D2/24 -> 12.5 | F18: 2
B19: Install Guest Rooms - Jack on Desk | D19: =0.2*Summary!D2 -> 60 | F19: =0.1*Summary!D2 -> 30
B20: Install meeting rooms - Create IDF | D20: =1.5*Summary!$D$3 -> 18 | F20: =1.5*Summary!$D$3 -> 18
B21: Install meeting rooms - Hardware and testing | D21: =2.25*Summary!$D$3 -> 27 | F21: =2.25*Summary!$D$3 -> 27
B22: PMS Integration | C22: Varies
B23: Acceptance Test and Certification | D23: 4 | F23: 4
B24: On-site training and collateral | D24: =IF(Summary!D2>299,8,IF(Summary!D2>150,6,4)) -> 8 | F24: =IF(Summary!D2>299,8,IF(Summary!D2>150,6,4)) -> 8
B25: Total direct install | D25: =SUM(D4:D24) -> 182.5 | F25: =SUM(F4:F24) -> 107
B27: Project management | C27: 0.2 | D27: =D25*C27 -> 36.5 | F27: =F25*C27 -> 21.4
B28: Total Install Hours | D28: =D25+D27 -> 219 | F28: =F25+F27 -> 128.4
B30: Labor cost / hour | D30: =Summary!D10 -> 90 | F30: =Summary!D10 -> 90
B31: Total Install Labor Cost | D31: =D28*D30 -> 19710 | F31: =F28*F30 -> 11556
B32: Cost per room | D32: =D31/Summary!D2 -> 65.7 | F32: =F31/Summary!D2 -> 38.52

Sheet SG&A and Service & Support
D1: Annual Cost Estimates
A3: Corporate Relationship Development
B4: Proposal | D4: All these vary significantly based on strategy, exisitng businesses, etc…
B5: Create Master Agreement Package | D5: The model just applies a % of revenue that drops over time as the business matures
B6: New Contract Launch
B7: Master Plan: 0 to 120+ days
B8: Master Schedule
B9: MRP
B10: Procurement
B11: Asset management
B12: Marketing collateral and program development
C13: Number of Circuits | D13: Annual Cost
A14: Circuit | C14: =INT((Summary!D2/1000)+1) -> 1 | D14: =C14*12*Summary!D11 -> 7800
A16: Service and Support
A18: Ongoing Support - central
B19: End User help Desk | D19: =18*Summary!D2 -> 5400
B20: NOC - Level 3 | D20: =48*Summary!D2 -> 14400
A22: Ongoing Support - onsite
B23: Field technical support | D23: =E23*IF(Summary!K2="lre",('Equipment - LRE'!F20+'Equipment - LRE'!F30-'Equipment - LRE'!F6),IF(Summary!K2="cable",('Equipment - Cable'!F13+'Equipment - Cable'!F22-'Equipment - Cable'!F5),IF(Summary!K2="ethernet",(Ethernet!F18+Ethernet!F26),0))) -> 8635.664 | E23: =Summary!K33 -> 0.08
A25: SG&A | D25: Year 1 | E25: Years 2+
B26: Recurring training / events | D26: =12*Summary!D2 -> 3600 | E26: =8*Summary!D2 -> 2400 | F26: $12 and $8 per room
B27: Portal/Connect screen maint | D27: =IF(Summary!D2>199,1000,IF(Summary!D2>99,500,250)) -> 1000 | E27: =D27 -> 1000 | F27: varies based on size of hotel
B28: Total SG&A | D28: =SUM(D26:D27) -> 4600 | E28: =SUM(E26:E27) -> 3400
B31: Total Annual Service & Support | D31: =SUM(D19:D23) -> 28435.664
A33: Ongoing Support - Video
B34: Refresh content | D34: 3600 | E34: $300/month for either extra bandwidth or fedexing videos
B35: Owned content | D35: =Summary!K11*Summary!K13*2 -> 20000 | E35: From variables on page 1, times 2 since refreshed 2 times/year
B36: First run content | C36: 0.5 | D36: =C36*Revenue!C28*Revenue!C31 -> 8119.44 | E36: Percent of revenue goes to studio
B37: Video Operating Costs | D37: =SUM(D34:D36) -> 31719.44
A40: Video Assumptions
B41: First run movies as % of total is a variable
B42: Owned movies can be purchased for a 1 time cost and can be shown for 6 months
B43: Number of First run and owned videos is a variable
