Workbook

Sheet Overall Grade
A1: Grade Summary | B1: Assuming your Homework and Quiz average stays the same, and your Exam average stays the same
A2: CE EN 203-2
A3: Winter 2001 | B3: Updated | C3: 37006
B4: 35 | C4: 20 | D4: 20 | E4: 20 | F4: 25 | G4: (Final Weights with lowest of 20 weight removed)
B5: 35 | C5: 20 | D5: 20 | E5: 20 | F5: 25 | G5: (Current Weights-Lowest Quiz, Exam1, Exam2 dropped)
A6: Code | B6: HW | C6: Quizes | D6: Exam 1 | E6: Exam 2 | F6: Final | G6: Total | H6: Grade | I6: GPA | K6: BreakPts | L6: Grade | M6: GPA | S6: Score Bin | T6: Score Freq | V6: Grades | W6: Grade Bin | X6: Grade Freq
A7: 7148 | B7: =' Homework'!AN10 -> 0.71681416 | C7: =Quizes!M5 -> 0.85 | D7: 0.715 | E7: 0.9 | F7: 0.455 | G7: =B7*$B$5+C7*$C$5+0*$D$5+E7*E5+F7*F5 -> 71.463496 | H7: =VLOOKUP(G7,$K$7:$L$18,2,TRUE) -> C | I7: =VLOOKUP(H7,$L$7:$M$18,2,FALSE) -> 2 | K7: 0 | L7: F | M7: 0 | S7: 100 | T7: =FREQUENCY($G$7:$G$48,S7:S8) -> 0 | V7: A | W7: 4 | X7: =FREQUENCY($I$7:$I$48,W7:W8) -> 12
A8: 8311 | B8: =' Homework'!AN11 -> 0.64424779 | C8: =Quizes!M6 -> 0.71428571 | D8: 0.48 | E8: 0.875 | F8: 0.785 | G8: =B8*$B$5+C8*$C$5+0*$D$5+E8*E5+F8*F5 -> 73.959387 | H8: =VLOOKUP(G8,$K$7:$L$18,2,TRUE) -> C | I8: =VLOOKUP(H8,$L$7:$M$18,2,FALSE) -> 2 | K8: 50 | L8: D- | M8: 0.7 | S8: 99 | T8: =FREQUENCY($G$7:$G$48,S8:S9) -> 1 | V8: A- | W8: 3.7 | X8: =FREQUENCY($I$7:$I$48,W8:W9) -> 4
A9: 5045 | B9: =' Homework'!AN12 -> 0.9840708 | C9: =Quizes!M7 -> 0.92857143 | D9: 0.895 | E9: 0.96 | F9: 0.95 | G9: =B9*$B$5+C9*$C$5+0*$D$5+E9*E5+F9*F5 -> 95.963906 | H9: =VLOOKUP(G9,$K$7:$L$18,2,TRUE) -> A | I9: =VLOOKUP(H9,$L$7:$M$18,2,FALSE) -> 4 | K9: 57 | L9: D | M9: 1 | S9: 98 | T9: =FREQUENCY($G$7:$G$48,S9:S10) -> 1 | V9: B+ | W9: 3.4 | X9: =FREQUENCY($I$7:$I$48,W9:W10) -> 8
A10: 7827 | B10: =' Homework'!AN13 -> 0.24424779 | C10: =Quizes!M8 -> 0.2 | D10: 0.575 | E10: 0.075 | F10: 0.045 | G10: =B10*$B$5+C10*$C$5+D10*$D$5+0*E5+F10*F5 -> 25.173673 | H10: =VLOOKUP(G10,$K$7:$L$18,2,TRUE) -> F | I10: =VLOOKUP(H10,$L$7:$M$18,2,FALSE) -> 0 | K10: 64 | L10: D+ | M10: 1.4 | S10: 97 | T10: =FREQUENCY($G$7:$G$48,S10:S11) -> 2 | V10: B | W10: 3 | X10: =FREQUENCY($I$7:$I$48,W10:W11) -> 1
A11: 6462 | B11: =' Homework'!AN14 -> 0.9539823 | C11: =Quizes!M9 -> 0.34285714 | D11: 0.7 | E11: 0.875 | F11: 0.465 | G11: =B11*$B$5+0*$C$5+D11*$D$5+E11*E5+F11*F5 -> 76.514381 | H11: =VLOOKUP(G11,$K$7:$L$18,2,TRUE) -> C+ | I11: =VLOOKUP(H11,$L$7:$M$18,2,FALSE) -> 2.4 | K11: 67 | L11: C- | M11: 1.7 | S11: 96 | T11: =FREQUENCY($G$7:$G$48,S11:S12) -> 3 | V11: B- | W11: 2.7 | X11: =FREQUENCY($I$7:$I$48,W11:W12) -> 3
A12: 1282 | B12: =' Homework'!AN15 -> 0.76548673 | C12: =Quizes!M10 -> 0.34285714 | D12: 0.935 | E12: 0.99 | F12: 0.91 | G12: =B12*$B$5+0*$C$5+D12*$D$5+E12*E5+F12*F5 -> 88.042035 | H12: =VLOOKUP(G12,$K$7:$L$18,2,TRUE) -> B+ | I12: =VLOOKUP(H12,$L$7:$M$18,2,FALSE) -> 3.4 | K12: 71 | L12: C | M12: 2 | S12: 95 | T12: =FREQUENCY($G$7:$G$48,S12:S13) -> 5 | V12: C+ | W12: 2.4 | X12: =FREQUENCY($I$7:$I$48,W12:W13) -> 1
A13: 9009 | B13: =' Homework'!AN16 -> 0.98053097 | C13: =Quizes!M11 -> 0.91428571 | D13: 1 | E13: 0.985 | F13: 0.98 | G13: =B13*$B$5+0*$C$5+D13*$D$5+E13*E5+F13*F5 -> 98.518584 | H13: =VLOOKUP(G13,$K$7:$L$18,2,TRUE) -> A | I13: =VLOOKUP(H13,$L$7:$M$18,2,FALSE) -> 4 | K13: 76 | L13: C+ | M13: 2.4 | S13: 94 | T13: =FREQUENCY($G$7:$G$48,S13:S14) -> 0 | V13: C | W13: 2 | X13: =FREQUENCY($I$7:$I$48,W13:W14) -> 7
A14: O594 | B14: =' Homework'!AN17 -> 0.93628319 | C14: =Quizes!M12 -> 0.88571429 | D14: =1 -> 1 | E14: 1 | F14: 0.935 | G14: =B14*$B$5+0*$C$5+D14*$D$5+E14*E5+F14*F5 -> 96.144912 | H14: =VLOOKUP(G14,$K$7:$L$18,2,TRUE) -> A | I14: =VLOOKUP(H14,$L$7:$M$18,2,FALSE) -> 4 | K14: 80 | L14: B- | M14: 2.7 | S14: 93 | T14: =FREQUENCY($G$7:$G$48,S14:S15) -> 3 | V14: C- | W14: 1.7 | X14: =FREQUENCY($I$7:$I$48,W14:W15) -> 2
A15: 8380 | B15: =' Homework'!AN18 -> 0.95221239 | C15: =Quizes!M13 -> 0.95714286 | D15: 0.96 | E15: 0.99 | F15: 0.9 | G15: =B15*$B$5+0*$C$5+D15*$D$5+E15*E5+F15*F5 -> 94.827434 | H15: =VLOOKUP(G15,$K$7:$L$18,2,TRUE) -> A | I15: =VLOOKUP(H15,$L$7:$M$18,2,FALSE) -> 4 | K15: 85 | L15: B | M15: 3 | S15: 92 | T15: =FREQUENCY($G$7:$G$48,S15:S16) -> 0 | V15: D+ | W15: 1.4 | X15: =FREQUENCY($I$7:$I$48,W15:W16) -> 0
A16: 9983 | B16: =' Homework'!AN19 -> 0.83451327 | C16: =Quizes!M14 -> 0.65714286 | D16: 0.79 | E16: 0.75 | F16: 0.535 | G16: =B16*$B$5+0*$C$5+D16*$D$5+E16*E5+F16*F5 -> 73.382965 | H16: =VLOOKUP(G16,$K$7:$L$18,2,TRUE) -> C | I16: =VLOOKUP(H16,$L$7:$M$18,2,FALSE) -> 2 | K16: 87 | L16: B+ | M16: 3.4 | S16: 91 | T16: =FREQUENCY($G$7:$G$48,S16:S17) -> 1 | V16: D | W16: 1 | X16: =FREQUENCY($I$7:$I$48,W16:W17) -> 2
A17: 5717 | B17: =' Homework'!AN20 -> 0.9460177 | C17: =Quizes!M15 -> 0.31428571 | D17: 0.86 | E17: 0.86 | G17: =B17*$B$5+0*$C$5+D17*$D$5+E17*E5+F17*F5 -> 67.510619 | H17: =VLOOKUP(G17,$K$7:$L$18,2,TRUE) -> C- | I17: =VLOOKUP(H17,$L$7:$M$18,2,FALSE) -> 1.7 | K17: 90 | L17: A- | M17: 3.7 | S17: 90 | T17: =FREQUENCY($G$7:$G$48,S17:S18) -> 0 | V17: D- | W17: 0.7 | X17: =FREQUENCY($I$7:$I$48,W17:W18) -> 0
A18: 3947 | B18: =' Homework'!AN21 -> 0.93362832 | C18: =Quizes!M16 -> 0.34285714 | D18: 0.845 | E18: 0.865 | F18: 0.805 | G18: =B18*$B$5+0*$C$5+D18*$D$5+E18*E5+F18*F5 -> 87.001991 | H18: =VLOOKUP(G18,$K$7:$L$18,2,TRUE) -> B+ | I18: =VLOOKUP(H18,$L$7:$M$18,2,FALSE) -> 3.4 | K18: 94 | L18: A | M18: 4 | S18: 89 | T18: =FREQUENCY($G$7:$G$48,S18:S19) -> 6 | V18: F | W18: 0 | X18: =FREQUENCY($I$7:$I$48,V18:V20) -> 1
A19: 7688 | B19: =' Homework'!AN22 -> 0.98230088 | C19: =Quizes!M17 -> 0.97142857 | D19: 0.985 | E19: 0.915 | F19: 0.875 | G19: =B19*$B$5+C19*$C$5+D19*$D$5+0*E5+F19*F5 -> 95.384102 | H19: =VLOOKUP(G19,$K$7:$L$18,2,TRUE) -> A | I19: =VLOOKUP(H19,$L$7:$M$18,2,FALSE) -> 4 | S19: 88 | T19: =FREQUENCY($G$7:$G$48,S19:S20) -> 2
A20: 8378 | B20: =' Homework'!AN23 -> 0.9699115 | C20: =Quizes!M18 -> 0.73571429 | D20: 0.62 | E20: 0.975 | F20: 0.805 | G20: =B20*$B$5+C20*$C$5+0*$D$5+E20*E5+F20*F5 -> 88.286188 | H20: =VLOOKUP(G20,$K$7:$L$18,2,TRUE) -> B+ | I20: =VLOOKUP(H20,$L$7:$M$18,2,FALSE) -> 3.4 | S20: 87 | T20: =FREQUENCY($G$7:$G$48,S20:S21) -> 0
A21: 7585 | B21: =' Homework'!AN24 -> 0.80530973 | C21: =Quizes!M19 -> 0.53571429 | D21: 0.635 | E21: 0.55 | F21: 0.385 | G21: =B21*$B$5+0*$C$5+D21*$D$5+E21*E5+F21*F5 -> 61.510841 | H21: =VLOOKUP(G21,$K$7:$L$18,2,TRUE) -> D | I21: =VLOOKUP(H21,$L$7:$M$18,2,FALSE) -> 1 | K21: Ave GPA: | L21: =AVERAGE(I7:I48) -> 2.997561 | S21: 86 | T21: =FREQUENCY($G$7:$G$48,S21:S22) -> 1 | W21: Total = | X21: =SUM(X7:X18) -> 41
A22: 3738 | B22: =' Homework'!AN25 -> 0.54513274 | C22: =Quizes!M20 -> 0.38571429 | D22: 0.95 | E22: 0.91 | F22: 0.475 | G22: =B22*$B$5+0*$C$5+D22*$D$5+E22*E5+F22*F5 -> 68.154646 | H22: =VLOOKUP(G22,$K$7:$L$18,2,TRUE) -> C- | I22: =VLOOKUP(H22,$L$7:$M$18,2,FALSE) -> 1.7 | S22: 85 | T22: =FREQUENCY($G$7:$G$48,S22:S23) -> 0
A23: 3668 | B23: =' Homework'!AN26 -> 0.77079646 | C23: =Quizes!M21 -> 0.67857143 | D23: 0.595 | E23: 0.8 | F23: 0.695 | G23: =B23*$B$5+C23*$C$5+0*$D$5+E23*E5+F23*F5 -> 73.924305 | H23: =VLOOKUP(G23,$K$7:$L$18,2,TRUE) -> C | I23: =VLOOKUP(H23,$L$7:$M$18,2,FALSE) -> 2 | S23: 84 | T23: =FREQUENCY($G$7:$G$48,S23:S24) -> 1
A24: 8537 | B24: =' Homework'!AN27 -> 0.9380531 | C24: =Quizes!M22 -> 0.85714286 | D24: 0.945 | E24: 1 | F24: 0.925 | G24: =B24*B5+0*C5+D24*D5+E24*E5+F24*F5 -> 94.856858 | H24: =VLOOKUP(G24,$K$7:$L$18,2,TRUE) -> A | I24: =VLOOKUP(H24,$L$7:$M$18,2,FALSE) -> 4 | S24: 83 | T24: =FREQUENCY($G$7:$G$48,S24:S25) -> 1
A25: 1245 | B25: =' Homework'!AN28 -> 0.94867257 | C25: =Quizes!M23 -> 0.98571429 | D25: 0.92 | E25: 0.87 | F25: 0.845 | G25: =B25*B5+C25*C5+D24*D5+0*E5+F25*F5 -> 92.942826 | H25: =VLOOKUP(G25,$K$7:$L$18,2,TRUE) -> A- | I25: =VLOOKUP(H25,$L$7:$M$18,2,FALSE) -> 3.7 | S25: 82 | T25: =FREQUENCY($G$7:$G$48,S25:S26) -> 1
A26: 4092 | B26: =' Homework'!AN29 -> 0.84247788 | C26: =Quizes!M24 -> 0.52857143 | D26: 0.825 | E26: 0.94 | F26: 0.715 | G26: =B26*$B$5+0*$C$5+D26*$D$5+E26*E5+F26*F5 -> 82.661726 | H26: =VLOOKUP(G26,$K$7:$L$18,2,TRUE) -> B- | I26: =VLOOKUP(H26,$L$7:$M$18,2,FALSE) -> 2.7 | S26: 81 | T26: =FREQUENCY($G$7:$G$48,S26:S27) -> 0
A27: 5688 | B27: =' Homework'!AN30 -> 0.98230088 | C27: =Quizes!M25 -> 0.25714286 | D27: 0.905 | E27: 0.915 | F27: 0.72 | G27: =B27*$B$5+0*$C$5+D27*$D$5+E27*E5+F27*F5 -> 88.780531 | H27: =VLOOKUP(G27,$K$7:$L$18,2,TRUE) -> B+ | I27: =VLOOKUP(H27,$L$7:$M$18,2,FALSE) -> 3.4 | S27: 80 | T27: =FREQUENCY($G$7:$G$48,S27:S28) -> 0
A28: -9564 | B28: =' Homework'!AN31 -> 0.93274336 | C28: =Quizes!M26 -> 0.77142857 | D28: 0.955 | E28: 0.95 | F28: 0.89 | G28: =B28*B5+D28*D5+E28*E5+F28*F5 -> 92.996018 | H28: =VLOOKUP(G28,$K$7:$L$18,2,TRUE) -> A- | I28: =VLOOKUP(H28,$L$7:$M$18,2,FALSE) -> 3.7 | S28: 79 | T28: =FREQUENCY($G$7:$G$48,S28:S29) -> 0
A29: 5951 | B29: =' Homework'!AN32 -> 0.90619469 | C29: =Quizes!M27 -> 0.85714286 | D29: 0.845 | E29: 0.785 | F29: 0.63 | G29: =B29*$B$5+C29*$C$5+D29*$D$5+0*E5+F29*F5 -> 81.509671 | H29: =VLOOKUP(G29,$K$7:$L$18,2,TRUE) -> B- | I29: =VLOOKUP(H29,$L$7:$M$18,2,FALSE) -> 2.7 | S29: 78 | T29: =FREQUENCY($G$7:$G$48,S29:S30) -> 0
A30: 7032 | B30: =' Homework'!AN33 -> 0.93097345 | C30: =Quizes!M28 -> 0.77857143 | D30: 0.89 | E30: 0.9 | F30: 0.8 | G30: =B30*$B$5+0*$C$5+D30*$D$5+E30*E5+F30*F5 -> 88.384071 | H30: =VLOOKUP(G30,$K$7:$L$18,2,TRUE) -> B+ | I30: =VLOOKUP(H30,$L$7:$M$18,2,FALSE) -> 3.4 | S30: 77 | T30: =FREQUENCY($G$7:$G$48,S30:S31) -> 1
A31: 5234 | B31: =' Homework'!AN34 -> 0.9699115 | C31: =Quizes!M29 -> 0.92142857 | D31: 0.93 | E31: 0.9 | F31: 0.8 | G31: =B31*$B$5+C31*$C$5+D31*$D$5+0*E5+F31*F5 -> 90.975474 | H31: =VLOOKUP(G31,$K$7:$L$18,2,TRUE) -> A- | I31: =VLOOKUP(H31,$L$7:$M$18,2,FALSE) -> 3.7 | S31: 76 | T31: =FREQUENCY($G$7:$G$48,S31:S32) -> 0
A32: 4402 | B32: =' Homework'!AN35 -> 0.9300885 | C32: =Quizes!M30 -> 0.93571429 | D32: 0.985 | E32: 0.89 | F32: 0.925 | G32: =B32*$B$5+C32*$C$5+D32*$D$5+0*E5+F32*F5 -> 94.092383 | H32: =VLOOKUP(G32,$K$7:$L$18,2,TRUE) -> A | I32: =VLOOKUP(H32,$L$7:$M$18,2,FALSE) -> 4 | S32: 75 | T32: =FREQUENCY($G$7:$G$48,S32:S33) -> 0
A33: 7527 | B33: =' Homework'!AN36 -> 0.99292035 | C33: =Quizes!M31 -> 0.78571429 | D33: 0.955 | E33: 0.975 | F33: 0.975 | G33: =B33*$B$5+0*$C$5+D33*$D$5+E33*E5+F33*F5 -> 97.727212 | H33: =VLOOKUP(G33,$K$7:$L$18,2,TRUE) -> A | I33: =VLOOKUP(H33,$L$7:$M$18,2,FALSE) -> 4 | S33: 74 | T33: =FREQUENCY($G$7:$G$48,S33:S34) -> 3
A34: 2654 | B34: =' Homework'!AN37 -> 0.78230088 | C34: =Quizes!M32 -> 0.73571429 | D34: 0.86 | E34: 0.895 | F34: 0.85 | G34: =B34*$B$5+0*$C$5+D34*$D$5+E34*E5+F34*F5 -> 83.730531 | H34: =VLOOKUP(G34,$K$7:$L$18,2,TRUE) -> B- | I34: =VLOOKUP(H34,$L$7:$M$18,2,FALSE) -> 2.7 | S34: 73 | T34: =FREQUENCY($G$7:$G$48,S34:S35) -> 2
A35: -6682 | B35: =' Homework'!AN38 -> 0.74336283 | C35: =Quizes!M33 -> 0.82857143 | D35: 0.76 | E35: 0.775 | F35: 0.555 | G35: =B35*$B$5+C35*$C$5+0*$D$5+E35*E5+F35*F5 -> 71.964128 | H35: =VLOOKUP(G35,$K$7:$L$18,2,TRUE) -> C | I35: =VLOOKUP(H35,$L$7:$M$18,2,FALSE) -> 2 | S35: 72 | T35: =FREQUENCY($G$7:$G$48,S35:S36) -> 2
A36: 7935 | B36: =' Homework'!AN39 -> 0.89115044 | C36: =Quizes!M34 -> 0.89285714 | D36: 0.93 | E36: 0.955 | F36: 0.785 | G36: =B36*$B$5+0*$C$5+D36*$D$5+E36*E5+F36*F5 -> 88.515265 | H36: =VLOOKUP(G36,$K$7:$L$18,2,TRUE) -> B+ | I36: =VLOOKUP(H36,$L$7:$M$18,2,FALSE) -> 3.4 | S36: 71 | T36: =FREQUENCY($G$7:$G$48,S36:S37) -> 0
A37: -9400 | B37: =' Homework'!AN40 -> 0.93982301 | C37: =Quizes!M35 -> 0.73571429 | D37: 0.79 | E37: 0.975 | F37: 0.805 | G37: =B37*$B$5+0*$C$5+D37*$D$5+E37*E5+F37*F5 -> 88.318805 | H37: =VLOOKUP(G37,$K$7:$L$18,2,TRUE) -> B+ | I37: =VLOOKUP(H37,$L$7:$M$18,2,FALSE) -> 3.4 | S37: 70 | T37: =FREQUENCY($G$7:$G$48,S37:S38) -> 0
A38: O046 | B38: =' Homework'!AN41 -> 0.99646018 | C38: =Quizes!M36 -> 0.87142857 | D38: 0.99 | E38: 0.95 | F38: 0.92 | G38: =B38*$B$5+0*$C$5+D38*$D$5+E38*E5+F38*F5 -> 96.676106 | H38: =VLOOKUP(G38,$K$7:$L$18,2,TRUE) -> A | I38: =VLOOKUP(H38,$L$7:$M$18,2,FALSE) -> 4 | S38: 69 | T38: =FREQUENCY($G$7:$G$48,S38:S39) -> 1
A39: 4805 | B39: =' Homework'!AN42 -> 0.93628319 | C39: =Quizes!M37 -> 0.91428571 | D39: 0.975 | E39: 0.95 | F39: 0.86 | G39: =B39*$B$5+0*$C$5+D39*$D$5+E39*E5+F39*F5 -> 92.769912 | H39: =VLOOKUP(G39,$K$7:$L$18,2,TRUE) -> A- | I39: =VLOOKUP(H39,$L$7:$M$18,2,FALSE) -> 3.7 | S39: 68 | T39: =FREQUENCY($G$7:$G$48,S39:S40) -> 1
A40: 2311 | B40: =' Homework'!AN43 -> 0.93893805 | C40: =Quizes!M38 -> 0.77857143 | D40: 0.745 | E40: 0.895 | F40: 0.83 | G40: =B40*$B$5+C40*$C$5+0*$D$5+E40*E5+F40*F5 -> 87.08426 | H40: =VLOOKUP(G40,$K$7:$L$18,2,TRUE) -> B+ | I40: =VLOOKUP(H40,$L$7:$M$18,2,FALSE) -> 3.4 | S40: 67 | T40: =FREQUENCY($G$7:$G$48,S40:S41) -> 0
...

Sheet  Homework
A1: Homework Grades
A3: CE EN 203-2
A4: Winter 2001
A5: Update 4/25/2001 | AE5: dropped homework
B6: CE 203-002 Dr. Benzley 2/12/01
A7: Assignment | B7: 12.2-4,3-5 | C7: 12.4-3,4-8 | D7: 12.5-3,5-7 | E7: 1.2-2,2-5,3-5 | F7: 1.4-2,5-3 | G7: 1.6-2,7-2,8-6 | H7: 2.2-2,2-9 | I7: 2.3-5,4-6,4-9 | J7: 2.5-9,6-3 | K7: 3.2-3,3-1 | L7: 3.4-3,5-4 | M7: 3.7-1,8-3 | N7: 3.9-8,10-5 | O7: 4.3-2,3-5 | P7: 4.3-10,3-12 | Q7: 4.5-1,5-20,5-29 | R7: 5.4-3,4-6 | S7: 5.5-5,5-7,5-12 | T7: 5.6-1,6-8 | U7: 5.8-2,9-2,10-7 | V7: 5.11-5,12-2 | W7: 7.2-3,3-4 | X7: 7.4-3,4-9,4-18 | Y7: 7.5-1,5-7 | Z7: 7.6-2,7-5 | AA7: 8.2-9,3-7 | AB7: 8.4-4,5-18 | AC7: 9.3-3,3-11,3-13 | AD7: 9.4-2,4-6 | AE7: 9.5-3,5-6 | AF7: 9.6-3,6-9,6-10 | AG7: 9.7-1,8-1 | AH7: 9.9-2,9-5 | AI7: 10.3-3,3-7 | AJ7: 10.5-5,5-9 | AK7: 11.2-3,3-4 | AL7: 11.4-2,5-5
B8: SLC | C8: SLC | D8: R | E8: N | F8: SLC | G8: R | H8: SLC | I8: N | J8: SLC | K8: SLC | L8: SLC | M8: SLC | N8: R | O8: SLC | P8: R | Q8: R | R8: SLC | T8: SLC | U8: N | V8: SC | W8: SLC | X8: SC | Y8: SC | Z8: SLC | AA8: SLC | AB8: R | AC8: SLC | AD8: SLC | AM8: TOTALS
B9: 15 | C9: 15 | D9: 15 | E9: 20 | F9: 15 | G9: 20 | H9: 15 | I9: 20 | J9: 15 | K9: 15 | L9: 15 | M9: 15 | N9: 15 | O9: 15 | P9: 15 | Q9: 20 | R9: 15 | S9: 20 | T9: 15 | U9: 20 | V9: 15 | W9: 15 | X9: 20 | Y9: 15 | Z9: 15 | AA9: 15 | AB9: 15 | AC9: 20 | AD9: 15 | AE9: 15 | AF9: 20 | AG9: 15 | AH9: 15 | AI9: 15 | AJ9: 15 | AK9: 15 | AL9: 15 | AM9: =SUM(B9:AL9)-15-20 -> 565
A10: 7148 | B10: 15 | C10: 15 | D10: 13 | E10: 19 | F10: 15 | G10: 17 | H10: 15 | I10: 11 | J10: 12 | K10: 15 | L10: 15 | M10: 8 | N10: 14 | O10: 15 | P10: 5 | Q10: 16 | R10: 15 | S10: 12 | T10: 10 | U10: 2 | V10: 13 | W10: 7 | X10: 8 | Y10: 14 | Z10: 13 | AA10: 10 | AB10: 8 | AE10: 12 | AF10: 12 | AG10: 5 | AH10: 7 | AJ10: 10 | AK10: 12 | AL10: 15 | AM10: =SUM(B10:AL10) -> 405 | AN10: =AM10/AM9 -> 0.71681416
A11: 8311 | B11: 15 | C11: 15 | D11: 14 | E11: 20 | F11: 14 | G11: 20 | H11: 15 | I11: 18 | J11: 15 | K11: 15 | L11: 15 | M11: 15 | N11: 15 | O11: 14 | P11: 14 | Q11: 10 | R11: 7.5 | S11: 7.5 | T11: 7.5 | U11: 18 | W11: 12 | AB11: 12 | AI11: 15 | AJ11: 15 | AK11: 15 | AL11: 10.5 | AM11: =SUM(B11:AL11) -> 364 | AN11: =AM11/AM9 -> 0.64424779
A12: 5045 | B12: 15 | C12: 15 | D12: 14 | E12: 20 | F12: 15 | G12: 20 | H12: 15 | I12: 18 | J12: 15 | K12: 15 | L12: 15 | M12: 15 | N12: 15 | O12: 15 | P12: 15 | Q12: 20 | R12: 15 | S12: 15 | T12: 15 | U12: 18 | V12: 15 | W12: 11 | X12: 12 | Y12: 15 | Z12: 11 | AA12: 14 | AB12: 10 | AC12: 19 | AD12: 11 | AE12: 15 | AF12: 19 | AG12: 13 | AH12: 15 | AI12: 15 | AJ12: 11 | AK12: 15 | AL12: 15 | AM12: =SUM(B12:AL12) -> 556 | AN12: =AM12/AM9 -> 0.9840708
A13: 7827 | B13: 4 | F13: 14 | G13: 18 | I13: 10 | K13: 15 | L13: 8 | M13: 15 | N13: 11 | O13: 9 | R13: 7.5 | V13: 15 | W13: 7.5 | AG13: 4 | AM13: =SUM(B13:AL13) -> 138 | AN13: =AM13/AM9 -> 0.24424779
A14: 6462 | B14: 15 | C14: 15 | D14: 15 | E14: 19 | F14: 15 | G14: 17 | H14: 15 | I14: 0 | J14: 15 | K14: 14 | L14: 15 | M14: 15 | N14: 12 | O14: 15 | P14: 14 | Q14: 19 | R14: 15 | S14: 15 | T14: 15 | U14: 20 | V14: 15 | W14: 14 | X14: 16 | Y14: 15 | Z14: 12 | AA14: 15 | AB14: 15 | AC14: 20 | AD14: 15 | AE14: 13 | AF14: 20 | AG14: 14 | AH14: 15 | AI14: 15 | AJ14: 0 | AK14: 15 | AL14: 15 | AM14: =SUM(B14:AL14) -> 539 | AN14: =AM14/AM9 -> 0.9539823
A15: 1282 | B15: 15 | C15: 14 | D15: 15 | E15: 20 | F15: 12 | G15: 18 | H15: 15 | I15: 20 | J15: 7.5 | K15: 7.5 | L15: 7.5 | M15: 14 | N15: 14 | O15: 15 | P15: 15 | Q15: 14 | R15: 15 | S15: 20 | T15: 15 | U15: 10 | V15: 7.5 | W15: 10.5 | X15: 14 | Y15: 7.5 | Z15: 7.5 | AA15: 7.5 | AB15: 7.5 | AC15: 10 | AD15: 7.5 | AE15: 0 | AF15: 0 | AG15: 7.5 | AH15: 15 | AI15: 9.5 | AJ15: 12 | AK15: 10.5 | AL15: 15 | AM15: =SUM(B15:AL15) -> 432.5 | AN15: =AM15/AM9 -> 0.76548673
A16: 9009 | B16: 15 | C16: 15 | D16: 15 | E16: 20 | F16: 15 | G16: 0 | H16: 15 | I16: 20 | J16: 15 | K16: 15 | L16: 14 | M16: 15 | N16: 13 | O16: 15 | P16: 15 | Q16: 19 | R16: 14 | S16: 20 | T16: 15 | U16: 20 | V16: 15 | W16: 0 | X16: 20 | Y16: 15 | Z16: 15 | AA16: 14 | AB16: 15 | AC16: 20 | AD16: 15 | AE16: 15 | AF16: 18 | AG16: 14 | AH16: 15 | AI16: 13 | AJ16: 15 | AK16: 15 | AL16: 15 | AM16: =SUM(B16:AL16) -> 554 | AN16: =AM16/AM9 -> 0.98053097
A17: O594 | B17: 15 | C17: 15 | D17: 15 | E17: 19 | F17: 15 | G17: 20 | H17: 15 | I17: 19 | J17: 15 | K17: 15 | L17: 15 | M17: 15 | N17: 12 | O17: 15 | P17: 14 | Q17: 20 | R17: 15 | S17: 12 | T17: 15 | U17: 14 | V17: 15 | W17: 13 | X17: 0 | Y17: 15 | Z17: 0 | AA17: 15 | AB17: 12 | AC17: 12 | AD17: 15 | AE17: 15 | AF17: 19 | AG17: 14 | AH17: 15 | AI17: 14 | AJ17: 15 | AK17: 15 | AL17: 15 | AM17: =SUM(B17:AL17) -> 529 | AN17: =AM17/AM9 -> 0.93628319
A18: 8380 | B18: 15 | C18: 15 | D18: 0 | E18: 18 | F18: 15 | G18: 20 | H18: 15 | I18: 0 | J18: 14 | K18: 15 | L18: 15 | M18: 15 | N18: 15 | O18: 15 | P18: 15 | Q18: 17 | R18: 15 | S18: 20 | T18: 12 | U18: 20 | V18: 15 | W18: 13 | X18: 20 | Y18: 15 | Z18: 15 | AA18: 15 | AB18: 15 | AC18: 12 | AD18: 14 | AE18: 15 | AF18: 19 | AG18: 12 | AH18: 15 | AI18: 12 | AJ18: 15 | AK18: 15 | AL18: 15 | AM18: =SUM(B18:AL18) -> 538 | AN18: =AM18/AM9 -> 0.95221239
A19: 9983 | B19: 15 | C19: 15 | D19: 15 | E19: 20 | F19: 15 | G19: 18 | H19: 15 | I19: 20 | J19: 14 | K19: 15 | L19: 12 | M19: 15 | N19: 15 | O19: 14 | P19: 8 | Q19: 17 | R19: 7.5 | S19: 8 | T19: 10 | U19: 18 | V19: 11 | W19: 6.5 | X19: 16 | Y19: 14 | AA19: 15 | AC19: 19 | AD19: 14 | AE19: 15 | AF19: 17 | AH19: 7.5 | AI19: 9 | AJ19: 11 | AK19: 15 | AL19: 15 | AM19: =SUM(B19:AL19) -> 471.5 | AN19: =AM19/AM9 -> 0.83451327
A20: 5617 | B20: 15 | C20: 15 | D20: 14 | E20: 20 | F20: 15 | G20: 13 | H20: 15 | I20: 20 | J20: 15 | K20: 15 | L20: 15 | M20: 15 | N20: 15 | O20: 15 | P20: 12 | Q20: 20 | R20: 15 | S20: 20 | T20: 14 | U20: 20 | V20: 15 | W20: 0 | X20: 18 | Y20: 15 | Z20: 15 | AA20: 15 | AB20: 12 | AD20: 15 | AE20: 15 | AF20: 20 | AG20: 15 | AH20: 15 | AI20: 10.5 | AJ20: 10.5 | AK20: 10.5 | AL20: 15 | AM20: =SUM(B20:AL20) -> 534.5 | AN20: =AM20/AM9 -> 0.9460177
A21: 3947 | B21: 15 | C21: 15 | D21: 15 | E21: 15 | F21: 14 | G21: 20 | H21: 15 | I21: 18 | J21: 14 | K21: 15 | L21: 15 | M21: 15 | N21: 15 | O21: 15 | P21: 10 | Q21: 20 | R21: 15 | S21: 20 | T21: 15 | U21: 10 | V21: 15 | W21: 13 | X21: 20 | Y21: 15 | Z21: 14 | AA21: 15 | AB21: 12 | AC21: 20 | AD21: 13 | AE21: 15 | AF21: 0 | AG21: 0 | AH21: 15 | AI21: 14 | AJ21: 10.5 | AK21: 15 | AL21: 15 | AM21: =SUM(B21:AL21) -> 527.5 | AN21: =AM21/AM9 -> 0.93362832
A22: 7688 | B22: 15 | C22: 15 | D22: 14 | E22: 20 | F22: 15 | G22: 20 | H22: 15 | I22: 0 | J22: 14 | K22: 15 | L22: 15 | M22: 15 | N22: 15 | O22: 15 | P22: 15 | Q22: 20 | R22: 15 | S22: 20 | T22: 15 | U22: 20 | V22: 15 | W22: 13 | X22: 20 | Y22: 15 | Z22: 15 | AA22: 13 | AB22: 0 | AC22: 20 | AD22: 15 | AE22: 15 | AF22: 19 | AG22: 15 | AH22: 15 | AI22: 15 | AJ22: 15 | AK22: 12 | AL22: 15 | AM22: =SUM(B22:AL22) -> 555 | AN22: =AM22/AM9 -> 0.98230088
A23: 8378 | B23: 15 | C23: 15 | D23: 15 | E23: 20 | F23: 15 | G23: 20 | H23: 15 | I23: 0 | J23: 13 | K23: 15 | L23: 15 | M23: 15 | N23: 14 | O23: 15 | P23: 15 | Q23: 19 | R23: 15 | S23: 0 | T23: 15 | U23: 20 | V23: 15 | W23: 12 | X23: 20 | Y23: 15 | Z23: 14 | AA23: 15 | AB23: 15 | AC23: 18 | AD23: 15 | AE23: 15 | AF23: 20 | AG23: 14 | AH23: 15 | AI23: 14 | AJ23: 15 | AK23: 15 | AL23: 15 | AM23: =SUM(B23:AL23) -> 548 | AN23: =AM23/AM9 -> 0.9699115
A24: 7585 | E24: 16 | F24: 15 | G24: 17 | H24: 15 | I24: 16 | J24: 13 | K24: 15 | L24: 15 | M24: 15 | N24: 15 | O24: 9 | Q24: 18 | R24: 15 | S24: 10 | T24: 15 | U24: 14 | V24: 15 | W24: 10 | X24: 14 | Y24: 15 | Z24: 15 | AA24: 15 | AB24: 12 | AC24: 9 | AD24: 14 | AE24: 15 | AF24: 15 | AG24: 13 | AH24: 15 | AJ24: 15 | AK24: 15 | AL24: 15 | AM24: =SUM(B24:AL24) -> 455 | AN24: =AM24/AM9 -> 0.80530973
A25: 3738 | B25: 15 | C25: 9 | D25: 5 | E25: 20 | F25: 12 | G25: 20 | H25: 15 | I25: 4 | J25: 9.5 | K25: 9.5 | L25: 9 | M25: 8 | N25: 15 | P25: 13 | Q25: 16 | R25: 15 | T25: 7.5 | U25: 10 | V25: 7.5 | W25: 7.5 | AC25: 10 | AD25: 7.5 | AE25: 7.5 | AF25: 4 | AG25: 10.5 | AH25: 10.5 | AI25: 9.5 | AK25: 10.5 | AL25: 10.5 | AM25: =SUM(B25:AL25) -> 308 | AN25: =AM25/AM9 -> 0.54513274
A26: 3668 | B26: 14 | C26: 9 | D26: 13 | E26: 15 | F26: 15 | G26: 20 | H26: 15 | I26: 8 | J26: 10.5 | K26: 7.5 | L26: 10.5 | M26: 9.5 | N26: 15 | O26: 15 | P26: 7.5 | Q26: 15 | R26: 14 | S26: 19 | T26: 14 | U26: 20 | V26: 9.5 | W26: 9 | X26: 13 | Y26: 15 | Z26: 11 | AA26: 14 | AB26: 12 | AC26: 10 | AD26: 7.5 | AE26: 13 | AF26: 0 | AG26: 0 | AH26: 7.5 | AI26: 10 | AJ26: 13 | AK26: 9.5 | AL26: 15 | AM26: =SUM(B26:AL26) -> 435.5 | AN26: =AM26/AM9 -> 0.77079646
A27: 8537 | B27: 15 | C27: 15 | D27: 15 | E27: 19 | F27: 15 | G27: 20 | H27: 15 | I27: 15 | J27: 13 | K27: 15 | L27: 15 | M27: 15 | N27: 14 | O27: 15 | P27: 15 | Q27: 19 | R27: 15 | S27: 11 | T27: 13 | U27: 20 | V27: 15 | W27: 14 | X27: 17 | Y27: 15 | Z27: 14 | AA27: 15 | AB27: 14 | AC27: 15 | AD27: 12 | AE27: 15 | AF27: 0 | AG27: 0 | AH27: 15 | AI27: 15 | AJ27: 15 | AK27: 15 | AL27: 15 | AM27: =SUM(B27:AL27) -> 530 | AN27: =AM27/AM9 -> 0.9380531
A28: 1245 | B28: 15 | C28: 15 | D28: 14 | E28: 18 | F28: 14 | G28: 18 | H28: 15 | I28: 20 | J28: 15 | K28: 15 | L28: 15 | M28: 13 | N28: 15 | O28: 13 | P28: 14 | Q28: 20 | R28: 15 | S28: 0 | T28: 15 | U28: 19 | V28: 15 | W28: 0 | X28: 16 | Y28: 14 | Z28: 11 | AA28: 15 | AB28: 12 | AC28: 18 | AD28: 13 | AE28: 15 | AF28: 20 | AG28: 15 | AH28: 14 | AI28: 15 | AJ28: 15 | AK28: 15 | AL28: 15 | AM28: =SUM(B28:AL28) -> 536 | AN28: =AM28/AM9 -> 0.94867257
A29: 4092 | B29: 15 | C29: 15 | D29: 15 | E29: 11 | G29: 19 | H29: 14 | I29: 20 | J29: 15 | K29: 13 | L29: 12 | M29: 15 | N29: 15 | O29: 15 | P29: 10.5 | Q29: 12 | R29: 9.5 | S29: 0 | T29: 15 | V29: 14 | W29: 14 | X29: 18 | Y29: 15 | Z29: 14 | AA29: 15 | AB29: 10 | AC29: 19 | AD29: 15 | AE29: 15 | AF29: 19 | AG29: 6.5 | AH29: 15 | AI29: 10.5 | AJ29: 15 | AK29: 10.5 | AL29: 9.5 | AM29: =SUM(B29:AL29) -> 476 | AN29: =AM29/AM9 -> 0.84247788
A30: 5688 | B30: 15 | C30: 14 | D30: 14 | E30: 20 | F30: 15 | G30: 20 | H30: 15 | I30: 20 | J30: 15 | K30: 15 | L30: 15 | M30: 14 | N30: 15 | O30: 15 | P30: 15 | Q30: 20 | R30: 15 | S30: 20 | T30: 15 | U30: 20 | V30: 15 | W30: 14 | X30: 0 | Y30: 15 | Z30: 15 | AA30: 15 | AB30: 15 | AC30: 20 | AD30: 15 | AE30: 15 | AF30: 14 | AG30: 0 | AH30: 15 | AI30: 15 | AJ30: 15 | AK30: 15 | AL30: 15 | AM30: =SUM(B30:AL30) -> 555 | AN30: =AM30/AM9 -> 0.98230088
A31: 9564 | B31: 15 | C31: 15 | D31: 14 | E31: 20 | F31: 14 | G31: 18 | H31: 15 | I31: 20 | J31: 15 | K31: 15 | L31: 15 | M31: 14 | N31: 15 | O31: 15 | P31: 13 | Q31: 20 | R31: 15 | S31: 7 | T31: 15 | U31: 20 | V31: 15 | W31: 10 | X31: 20 | Y31: 15 | Z31: 14 | AA31: 14 | AB31: 12 | AC31: 20 | AD31: 12 | AE31: 15 | AF31: 0 | AG31: 14 | AH31: 15 | AJ31: 11 | AK31: 15 | AL31: 15 | AM31: =SUM(B31:AL31) -> 527 | AN31: =AM31/AM9 -> 0.93274336
A32: 5951 | B32: 15 | C32: 15 | D32: 15 | E32: 15 | F32: 15 | G32: 17 | H32: 15 | I32: 18 | J32: 14 | K32: 15 | L32: 15 | M32: 15 | N32: 15 | O32: 14 | P32: 6.5 | Q32: 18 | R32: 15 | S32: 20 | T32: 15 | U32: 20 | V32: 15 | W32: 11 | Y32: 15 | Z32: 15 | AB32: 12 | AC32: 19 | AD32: 7.5 | AE32: 15 | AF32: 20 | AG32: 12 | AH32: 8.5 | AI32: 15 | AJ32: 15 | AK32: 15 | AL32: 9.5 | AM32: =SUM(B32:AL32) -> 512 | AN32: =AM32/AM9 -> 0.90619469
A33: 7032 | B33: 15 | C33: 14 | D33: 14 | E33: 11 | F33: 15 | G33: 20 | H33: 15 | I33: 0 | J33: 14 | K33: 15 | L33: 15 | M33: 15 | N33: 15 | O33: 15 | P33: 12 | Q33: 20 | R33: 15 | S33: 13 | T33: 15 | U33: 19 | V33: 15 | W33: 15 | X33: 17 | Y33: 15 | Z33: 15 | AA33: 15 | AB33: 0 | AC33: 19 | AD33: 12 | AE33: 15 | AF33: 18 | AG33: 13 | AH33: 13 | AI33: 13 | AJ33: 15 | AK33: 15 | AL33: 14 | AM33: =SUM(B33:AL33) -> 526 | AN33: =AM33/AM9 -> 0.93097345
A34: 5234 | B34: 15 | C34: 15 | D34: 14 | E34: 20 | F34: 15 | G34: 0 | H34: 15 | I34: 20 | J34: 15 | K34: 15 | L34: 15 | M34: 15 | N34: 15 | O34: 15 | P34: 15 | Q34: 19 | R34: 15 | S34: 13 | T34: 15 | U34: 20 | V34: 15 | W34: 14 | X34: 19 | Y34: 15 | Z34: 14 | AA34: 15 | AB34: 12 | AC34: 19 | AD34: 15 | AE34: 15 | AF34: 19 | AH34: 15 | AI34: 15 | AJ34: 15 | AK34: 15 | AL34: 15 | AM34: =SUM(B34:AL34) -> 548 | AN34: =AM34/AM9 -> 0.9699115
A35: 4402 | B35: 15 | C35: 13 | D35: 15 | E35: 19 | F35: 14 | G35: 18 | H35: 15 | I35: 20 | J35: 15 | K35: 10.5 | L35: 15 | M35: 15 | N35: 15 | O35: 14 | Q35: 20 | R35: 15 | T35: 15 | U35: 20 | V35: 15 | W35: 13 | X35: 19 | Y35: 15 | Z35: 9.5 | AA35: 15 | AB35: 15 | AC35: 19 | AD35: 15 | AE35: 15 | AF35: 10 | AG35: 7.5 | AH35: 14 | AI35: 15 | AJ35: 15 | AK35: 15 | AL35: 15 | AM35: =SUM(B35:AL35) -> 525.5 | AN35: =AM35/AM9 -> 0.9300885
A36: 7527 | B36: 15 | C36: 15 | D36: 15 | E36: 20 | F36: 14 | G36: 20 | H36: 15 | I36: 18 | J36: 15 | K36: 15 | L36: 15 | M36: 15 | N36: 15 | O36: 15 | P36: 15 | Q36: 20 | R36: 15 | S36: 20 | T36: 15 | U36: 20 | V36: 15 | W36: 14 | X36: 20 | Y36: 15 | Z36: 15 | AA36: 15 | AB36: 15 | AC36: 0 | AD36: 15 | AE36: 15 | AF36: 20 | AG36: 15 | AH36: 15 | AI36: 0 | AJ36: 15 | AK36: 15 | AL36: 15 | AM36: =SUM(B36:AL36) -> 561 | AN36: =AM36/AM9 -> 0.99292035
A37: 2654 | B37: 12 | C37: 9 | D37: 10 | E37: 12 | F37: 12 | G37: 17 | H37: 14 | I37: 0 | J37: 12 | K37: 13 | L37: 13 | M37: 14 | N37: 13 | O37: 11 | P37: 11 | Q37: 17 | R37: 0 | S37: 8 | T37: 15 | U37: 18 | V37: 6.5 | W37: 11 | X37: 15 | Y37: 15 | Z37: 11 | AA37: 13 | AB37: 9 | AC37: 14 | AD37: 10 | AE37: 15 | AF37: 15 | AG37: 13 | AH37: 15 | AI37: 8 | AJ37: 10.5 | AK37: 15 | AL37: 15 | AM37: =SUM(B37:AL37) -> 442 | AN37: =AM37/AM9 -> 0.78230088
A38: 6682 | B38: 15 | C38: 7.5 | D38: 15 | E38: 10 | F38: 7.5 | G38: 18 | H38: 15 | I38: 15 | J38: 13 | K38: 15 | L38: 15 | M38: 15 | N38: 13 | O38: 14 | P38: 0 | Q38: 10 | R38: 6.5 | S38: 10 | T38: 11 | U38: 19 | V38: 15 | W38: 9 | X38: 13 | Y38: 15 | Z38: 11 | AA38: 11 | AB38: 9 | AC38: 14 | AD38: 14 | AE38: 12 | AF38: 0 | AG38: 7.5 | AH38: 7.5 | AI38: 7.5 | AJ38: 7.5 | AK38: 15 | AL38: 7.5 | AM38: =SUM(B38:AL38) -> 420 | AN38: =AM38/AM9 -> 0.74336283
A39: 7935 | B39: 13 | C39: 13 | D39: 12 | E39: 12 | F39: 11 | H39: 15 | I39: 14 | J39: 7.5 | K39: 15 | M39: 15 | N39: 13 | O39: 15 | P39: 15 | Q39: 20 | R39: 15 | S39: 18 | T39: 15 | U39: 20 | V39: 15 | W39: 9.5 | X39: 16 | Y39: 15 | Z39: 14 | AA39: 15 | AB39: 15 | AC39: 17 | AD39: 15 | AE39: 15 | AF39: 19 | AG39: 12 | AH39: 9.5 | AI39: 14 | AJ39: 14 | AK39: 15 | AL39: 15 | AM39: =SUM(B39:AL39) -> 503.5 | AN39: =AM39/AM9 -> 0.89115044
A40: 9400 | B40: 14 | C40: 15 | D40: 15 | E40: 16 | F40: 14 | G40: 20 | H40: 14 | I40: 0 | J40: 13 | K40: 15 | L40: 15 | M40: 15 | N40: 15 | O40: 14 | P40: 0 | Q40: 16 | R40: 15 | S40: 13 | T40: 15 | U40: 20 | V40: 15 | W40: 15 | X40: 20 | Y40: 15 | Z40: 15 | AA40: 15 | AB40: 12 | AC40: 18 | AD40: 10 | AE40: 15 | AF40: 18 | AG40: 14 | AH40: 15 | AI40: 15 | AJ40: 15 | AK40: 15 | AL40: 15 | AM40: =SUM(B40:AL40) -> 531 | AN40: =AM40/AM9 -> 0.93982301
A41: O046 | B41: 15 | C41: 15 | D41: 15 | E41: 20 | F41: 15 | G41: 0 | H41: 15 | I41: 20 | J41: 15 | K41: 15 | L41: 15 | M41: 15 | N41: 15 | O41: 15 | P41: 15 | Q41: 20 | R41: 15 | S41: 20 | T41: 15 | U41: 20 | V41: 15 | W41: 0 | X41: 20 | Y41: 15 | Z41: 15 | AA41: 15 | AB41: 15 | AC41: 19 | AD41: 15 | AE41: 15 | AF41: 20 | AG41: 14 | AH41: 15 | AI41: 15 | AJ41: 15 | AK41: 15 | AL41: 15 | AM41: =SUM(B41:AL41) -> 563 | AN41: =AM41/AM9 -> 0.99646018
...

Sheet Quizes
A1: CE 203-2
A2: Winter 2001 | B2: Updated | C2: 37006
A3: Code | B3: 1 | C3: 2 | D3: 3 | E3: 4 | F3: 5 | G3: 6 | H3: 7 | I3: 8 | J3: 9 | K3: 10 | L3: Total Points | M3: Percent
A4: Max. Points | B4: 20 | C4: 20 | D4: 20 | E4: 20 | F4: 20 | G4: 20 | H4: 20 | L4: =SUM(B4:H4) -> 140 | M4: =L4/$L$4 -> 1
A5: 7148 | B5: 20 | C5: 14 | D5: 20 | E5: 16 | F5: 15 | G5: 14 | H5: 20 | L5: =SUM(B5:H5) -> 119 | M5: =L5/$L$4 -> 0.85
A6: 8311 | B6: 8 | C6: 16 | D6: 0 | E6: 18 | F6: 18 | G6: 20 | H6: 20 | L6: =SUM(B6:H6) -> 100 | M6: =L6/$L$4 -> 0.71428571
A7: 5045 | B7: 16 | C7: 18 | D7: 20 | E7: 18 | F7: 18 | G7: 20 | H7: 20 | L7: =SUM(B7:H7) -> 130 | M7: =L7/$L$4 -> 0.92857143
A8: 7827 | B8: 0 | C8: 10 | D8: 4 | E8: 14 | L8: =SUM(B8:H8) -> 28 | M8: =L8/$L$4 -> 0.2
B9: 0 | C9: 12 | D9: 0 | F9: 16 | H9: 20 | L9: =SUM(B9:H9) -> 48 | M9: =L9/$L$4 -> 0.34285714
A10: 1282 | B10: 16 | C10: 0 | D10: 20 | E10: 12 | L10: =SUM(B10:H10) -> 48 | M10: =L10/$L$4 -> 0.34285714
A11: 9009 | B11: 16 | C11: 16 | D11: 20 | E11: 16 | F11: 20 | G11: 20 | H11: 20 | L11: =SUM(B11:H11) -> 128 | M11: =L11/$L$4 -> 0.91428571
A12: O594 | B12: 16 | C12: 12 | D12: 20 | E12: 18 | F12: 18 | G12: 20 | H12: 20 | L12: =SUM(B12:H12) -> 124 | M12: =L12/$L$4 -> 0.88571429
A13: 8380 | B13: 16 | C13: 20 | D13: 20 | E13: 18 | F13: 20 | G13: 20 | H13: 20 | L13: =SUM(B13:H13) -> 134 | M13: =L13/$L$4 -> 0.95714286
A14: 9983 | B14: 16 | C14: 0 | D14: 10 | E14: 18 | F14: 18 | G14: 14 | H14: 16 | L14: =SUM(B14:H14) -> 92 | M14: =L14/$L$4 -> 0.65714286
A15: 5717 | B15: 12 | C15: 10 | D15: 12 | E15: 10 | L15: =SUM(B15:H15) -> 44 | M15: =L15/$L$4 -> 0.31428571
A16: 3947 | B16: 6 | C16: 0 | D16: 16 | E16: 8 | F16: 18 | L16: =SUM(B16:H16) -> 48 | M16: =L16/$L$4 -> 0.34285714
A17: 7688 | B17: 16 | C17: 20 | D17: 20 | E17: 20 | F17: 20 | G17: 20 | H17: 20 | L17: =SUM(B17:H17) -> 136 | M17: =L17/$L$4 -> 0.97142857
A18: 8378 | B18: 12 | C18: 14 | D18: 16 | E18: 16 | F18: 5 | G18: 20 | H18: 20 | L18: =SUM(B18:H18) -> 103 | M18: =L18/$L$4 -> 0.73571429
A19: 7585 | B19: 6 | C19: 14 | D19: 12 | E19: 18 | F19: 5 | H19: 20 | L19: =SUM(B19:H19) -> 75 | M19: =L19/$L$4 -> 0.53571429
A20: 3738 | B20: 20 | C20: 14 | D20: 20 | L20: =SUM(B20:H20) -> 54 | M20: =L20/$L$4 -> 0.38571429
A21: 3668 | B21: 8 | C21: 14 | D21: 20 | E21: 18 | F21: 3 | G21: 16 | H21: 16 | L21: =SUM(B21:H21) -> 95 | M21: =L21/$L$4 -> 0.67857143
A22: 8537 | B22: 14 | C22: 18 | D22: 16 | E22: 14 | F22: 18 | G22: 20 | H22: 20 | L22: =SUM(B22:H22) -> 120 | M22: =L22/$L$4 -> 0.85714286
A23: 1245 | B23: 20 | C23: 20 | D23: 20 | E23: 20 | F23: 18 | G23: 20 | H23: 20 | L23: =SUM(B23:H23) -> 138 | M23: =L23/$L$4 -> 0.98571429
A24: 4092 | B24: 10 | C24: 14 | D24: 14 | E24: 14 | G24: 6 | H24: 16 | L24: =SUM(B24:H24) -> 74 | M24: =L24/$L$4 -> 0.52857143
A25: 5688 | B25: 20 | C25: 16 | D25: 0 | L25: =SUM(B25:H25) -> 36 | M25: =L25/$L$4 -> 0.25714286
A26: -9564 | B26: 20 | C26: 14 | D26: 0 | E26: 20 | F26: 18 | G26: 20 | H26: 16 | L26: =SUM(B26:H26) -> 108 | M26: =L26/$L$4 -> 0.77142857
A27: 5951 | B27: 8 | C27: 18 | D27: 20 | E27: 16 | F27: 18 | G27: 20 | H27: 20 | L27: =SUM(B27:H27) -> 120 | M27: =L27/$L$4 -> 0.85714286
A28: 7032 | B28: 10 | C28: 12 | D28: 20 | E28: 12 | F28: 15 | G28: 20 | H28: 20 | L28: =SUM(B28:H28) -> 109 | M28: =L28/$L$4 -> 0.77857143
A29: 5234 | B29: 20 | C29: 18 | D29: 20 | E29: 18 | F29: 17 | G29: 16 | H29: 20 | L29: =SUM(B29:H29) -> 129 | M29: =L29/$L$4 -> 0.92142857
A30: 4402 | B30: 20 | C30: 18 | D30: 20 | E30: 14 | F30: 19 | G30: 20 | H30: 20 | L30: =SUM(B30:H30) -> 131 | M30: =L30/$L$4 -> 0.93571429
A31: 7527 | B31: 20 | C31: 16 | D31: 20 | E31: 20 | F31: 20 | G31: 14 | L31: =SUM(B31:H31) -> 110 | M31: =L31/$L$4 -> 0.78571429
A32: 2654 | B32: 16 | C32: 16 | D32: 20 | E32: 16 | F32: 15 | G32: 20 | L32: =SUM(B32:H32) -> 103 | M32: =L32/$L$4 -> 0.73571429
A33: -6682 | B33: 14 | C33: 16 | D33: 16 | E33: 14 | F33: 16 | G33: 20 | H33: 20 | L33: =SUM(B33:H33) -> 116 | M33: =L33/$L$4 -> 0.82857143
A34: 7935 | B34: 12 | C34: 18 | D34: 20 | E34: 18 | F34: 17 | G34: 20 | H34: 20 | L34: =SUM(B34:H34) -> 125 | M34: =L34/$L$4 -> 0.89285714
A35: -9400 | B35: 8 | C35: 18 | D35: 16 | E35: 10 | F35: 15 | G35: 16 | H35: 20 | L35: =SUM(B35:H35) -> 103 | M35: =L35/$L$4 -> 0.73571429
A36: O046 | B36: 12 | C36: 20 | D36: 20 | E36: 16 | F36: 18 | G36: 16 | H36: 20 | L36: =SUM(B36:H36) -> 122 | M36: =L36/$L$4 -> 0.87142857
A37: 4805 | B37: 16 | C37: 18 | D37: 16 | E37: 18 | F37: 20 | G37: 20 | H37: 20 | L37: =SUM(B37:H37) -> 128 | M37: =L37/$L$4 -> 0.91428571
A38: 2311 | B38: 6 | C38: 16 | D38: 16 | E38: 16 | F38: 15 | G38: 20 | H38: 20 | L38: =SUM(B38:H38) -> 109 | M38: =L38/$L$4 -> 0.77857143
A39: 8419 | B39: 20 | C39: 20 | D39: 20 | E39: 20 | F39: 20 | G39: 20 | H39: 20 | L39: =SUM(B39:H39) -> 140 | M39: =L39/$L$4 -> 1
A40: 1714 | B40: 12 | C40: 16 | D40: 8 | E40: 20 | G40: 20 | H40: 20 | L40: =SUM(B40:H40) -> 96 | M40: =L40/$L$4 -> 0.68571429
...
