Workbook

Sheet Dairy Description
A1: Key Code:
A2: Dairy Business Analysis Project
A3: Dairy Business Summary
A4: 2000
A5: Inputs - Dairy Description
A6: Livestock & Business Description | C6: Prod. Recording System | E6: Milking System | G6: Milking Frequency
A7: Pounds milk sold | B7: 0 | C7: 0 | D7: DHI | E7: 0 | F7: Number | G7: 0 | H7: Seasonal
A8: Avg. milk plant %BF | B8: 0 | C8: 0 | D8: DHI ID# | E8: 0 | F8: Parlor | G8: 0 | H8: 2x/day
C9: 0 | D9: Other | E9: 0 | F9: Size | G9: 0 | H9: 3x/day
A10: Livestock | B10: Avg. for Year | C10: 0 | D10: None | E10: 0 | F10: FI barn | G10: 0 | H10: Other
A11: Cows owned | B11: 0
A12: Cows leased | B12: 0 | C12: Business type: | E12: Housing | G12: Manure System
A13: Heifers + calves | B13: 0 | C13: 0 | D13: Sole prop. | E13: 0 | F13: Freestall | G13: 0 | H13: Lagoon
A14: Bulls | B14: 0 | C14: 0 | D14: Partnership | E14: 0 | F14: Fdg/Shg | G14: 0 | H14: Spray fields
A15: Other | B15: 0 | C15: 0 | D15: Corporation | E15: 0 | F15: None | G15: 0 | H15: Compost
C16: 0 | D16: LLP | G16: 0 | H16: None
A18: BST Use: | B18: 0 | C18: % of herd | D18: 0 | E18: # of doses
A20: Labor Inventory-Yearly average F/T months(1) | D20: Labor Turnover | E20: Full-time Equivalents (1)
A21: Operator -1 | B21: 0 | E21: Operators | F21: Managers | G21: Support staff | H21: Total
A22: -2 | B22: 0 | D22: Beg. of year inventory | E22: 0 | F22: 0 | G22: 0 | H22: =SUM(E22:G22) -> 0
A23: -3 | B23: 0 | D23: -layoffs | E23: 0 | F23: 0 | G23: 0 | H23: =SUM(E23:G23) -> 0
A24: -4 | B24: 0 | D24: -termination/resignation | E24: 0 | F24: 0 | G24: 0 | H24: =SUM(E24:G24) -> 0
A25: Family (paid) | B25: 0 | D25: +new hires | E25: 0 | F25: 0 | G25: 0 | H25: =SUM(E25:G25) -> 0
A26: Family (unpaid) | B26: 0 | D26: =End of year inventory | E26: =E22-E23-E24+E25 -> 0 | F26: =F22-F23-F24+F25 -> 0 | G26: =G22-G23-G24+G25 -> 0 | H26: =SUM(E26:G26) -> 0
A27: Hired (reg. & seas.) | B27: 0
A28: Total | B28: =SUM(B21:B27) -> 0 | D28: Number of positions replaced | E28: 0 | F28: 0 | G28: 0 | H28: =SUM(E28:G28) -> 0
A30: Land Inventory | B30: Acres owned | C30: Acres rented | D30: All Acres | F30: Feeding System | H30: Cooling System
A31: Cultivated land | B31: 0 | C31: 0 | D31: =B31+C31 -> 0 | E31: One-shot | F31: 0 | G31: Shade | H31: 0
A32: Improved pasture (2) | B32: 0 | C32: 0 | D32: =B32+C32 -> 0 | E32: TMR | F32: 0 | G32: Fans | H32: 0
A33: Non-improved pasture | B33: 0 | C33: 0 | D33: =B33+C33 -> 0 | E33: Grazing | F33: 0 | G33: Sprinklers | H33: 0
A34: Woods & other | B34: 0 | C34: 0 | D34: =B34+C34 -> 0 | E34: Other | F34: 0 | G34: Ponds | H34: 0
A35: Total | B35: =SUM(B31:B34) -> 0 | C35: =SUM(C31:C34) -> 0 | D35: =SUM(D31:D34) -> 0 | G35: None | H35: 0
A37: Harvested Crops | B37: Acres | C37: Total Prod (tons) | E37: % Dry Matter | G37: Tot. dry matter (tons)
A38: 0 | B38: 0 | C38: 0 | E38: 0 | G38: =C38*E38/100 -> 0
A39: 0 | B39: 0 | C39: 0 | E39: 0 | G39: =C39*E39/100 -> 0
A40: 0 | B40: 0 | C40: 0 | E40: 0 | G40: =C40*E40/100 -> 0
A41: 0 | B41: 0 | C41: 0 | E41: 0 | G41: =C41*E41/100 -> 0
A42: 0 | B42: 0 | C42: 0 | E42: 0 | G42: =C42*E42/100 -> 0
A43: 0 | B43: 0 | C43: 0 | E43: 0 | G43: =C43*E43/100 -> 0
A44: 0 | B44: 0 | C44: 0 | E44: 0 | G44: =C44*E44/100 -> 0
...

Sheet Livestock
A1: ='Dairy Description'!A1 -> Key Code: | B1: Dairy Business Analysis Project
A2: Dairy Business Summary
A3: 2000
A5: Livestock
B6: Beginning (Jan 1) | G6: | | H6: Ending (Dec 31)
D7: $ per | F7: Total | G7: | | J7: $ per | L7: Total
B8: No. | C8: x | D8: Head | E8: = | F8: Value | G8: | | H8: No. | I8: x | J8: Head | K8: = | L8: Value
A9: Cows: | G9: |
A10: Raised/expensed | B10: 0 | D10: 0 | F10: =B10*D10 -> 0 | G10: | | H10: 0 | J10: 0 | L10: =H10*J10 -> 0
A11: Capitalized | B11: 0 | D11: 0 | F11: =B11*D11 -> 0 | H11: 0 | J11: 0 | L11: =H11*J11 -> 0
A12: Leased | B12: 0 | D12: 0 | F12: =B12*D12 -> 0 | G12: | | H12: 0 | J12: 0 | L12: =H12*J12 -> 0
A13: Total dairy cows | B13: =SUM(B10:B12) -> 0 | F13: =SUM(F10:F12) -> 0 | G13: | | H13: =SUM(H10:H12) -> 0 | L13: =SUM(L10:L12) -> 0
G14: |
A15: Heifers: | G15: |
A16: Bred heifers | B16: 0 | D16: 0 | F16: =B16*D16 -> 0 | G16: | | H16: 0 | J16: 0 | L16: =H16*J16 -> 0
A17: Open (6 mo. - bred) | B17: 0 | D17: 0 | F17: =B17*D17 -> 0 | G17: | | H17: 0 | J17: 0 | L17: =H17*J17 -> 0
A18: Calves (< 6 mo.) | B18: 0 | D18: 0 | F18: =B18*D18 -> 0 | G18: | | H18: 0 | J18: 0 | L18: =H18*J18 -> 0
A19: Total heifers | B19: =SUM(B16:B18) -> 0 | F19: =SUM(F16:F18) -> 0 | G19: | | H19: =SUM(H16:H18) -> 0 | L19: =SUM(L16:L18) -> 0
G20: |
A21: Bulls & other livestock: | G21: |
A22: ________________ | B22: 0 | D22: 0 | F22: =B22*D22 -> 0 | G22: | | H22: 0 | J22: 0 | L22: =H22*J22 -> 0
A23: _________________ | B23: 0 | D23: 0 | F23: =B23*D23 -> 0 | G23: | | H23: 0 | J23: 0 | L23: =H23*J23 -> 0
A24: Total bulls & other | B24: =B22+B23 -> 0 | F24: =F22+F23 -> 0 | G24: | | H24: =H22+H23 -> 0 | L24: =L22+L23 -> 0
G25: |
A26: Total Livestock | B26: =B13+B19+B24 -> 0 | F26: =F13+F19+F24 -> 0 | G26: | | H26: =H13+H19+H24 -> 0 | L26: =L13+L19+L24 -> 0
G27: |
A29: Cow number check: | B29: 0 | C29: + | D29: 0 | E29: + | F29: 0 | G29: - | H29: 0 | I29: = | J29: =B29+D29+F29-H29 -> 0
B30: # cows | D30: # heifers | F30: # cows | H30: # sold,
B31: beg. yr. | D31: fresh | F31: purch | H31: died, etc.
A33: Capital livestock inventory worksheet (do not include leased, raised, or expensed livestock)
A34: Beginning of year inventory | F34: =F11 -> 0 | H34: End of year inventory | L34: =L11 -> 0
A35: Capital livestock purchased (1) | E35: + | F35: 0
A36: Capital livestock sold (2) | E36: - | F36: 0
A37: Noncash livestock transfer from dairy | E37: - | F37: 0
A38: Noncash livestock transfer to dairy | E38: + | F38: 0
A39: Tax depreciation | E39: - | F39: 0
D40: Net value of inventory | E40: = | H40: =F34+F35-F36-F37+F38-F39 -> 0
D41: Gain/loss on sale of capital livestock | H41: =L34-H40 -> 0
D42: (end less beginning after changes)
A43: (1) Only include purchases of capital livestock. Do not include purchases that were expensed. Enter expensed livestock
...

Sheet Feed and Supply
A1: ='Dairy Description'!A1 -> Key Code: | B1: Dairy Business Analysis Project
B2: Dairy Business Summary
A3: 2000
A5: Raised Feed and Supply Inventory
A6: Grown Feed Worksheet Beginning (Jan 1) | E6: | | F6: Ending (Dec 31)
C7: $ per | D7: Total | E7: | | G7: $ per | H7: Total
A8: Item | B8: Quant. x | C8: Unit | D8: = Value | E8: | | F8: Quant. x | G8: Unit | H8: = Value
A9: Grown feeds: | E9: |
A10: 0 | B10: 0 | C10: 0 | D10: =B10*C10 -> 0 | E10: | | F10: 0 | G10: 0 | H10: =F10*G10 -> 0
A11: 0 | B11: 0 | C11: 0 | D11: =B11*C11 -> 0 | E11: | | F11: 0 | G11: 0 | H11: =F11*G11 -> 0
A12: 0 | B12: 0 | C12: 0 | D12: =B12*C12 -> 0 | E12: | | F12: 0 | G12: 0 | H12: =F12*G12 -> 0
A13: 0 | B13: 0 | C13: 0 | D13: =B13*C13 -> 0 | E13: | | F13: 0 | G13: 0 | H13: =F13*G13 -> 0
A14: 0 | B14: 0 | C14: 0 | D14: =B14*C14 -> 0 | E14: | | F14: 0 | G14: 0 | H14: =F14*G14 -> 0
A15: 0 | B15: 0 | C15: 0 | D15: =B15*C15 -> 0 | E15: | | F15: 0 | G15: 0 | H15: =F15*G15 -> 0
A16: Total | D16: =SUM(D10:D15) -> 0 | E16: | | H16: =SUM(H10:H15) -> 0
A18: Purchased Feed & Supply Inventory
A19: Item | I19: Inv. Chng. (1)
A20: Total grown feeds (2) | B20: 0 | C20: 0 | D20: =B20*C20 -> 0 | E20: | | F20: 0 | G20: 0 | H20: =F20*G20 -> 0 | I20: =H20-D20 -> 0
A21: Purchased feeds:(3) | E21: |
A22: Grain & concentrate | B22: 0 | C22: 0 | D22: =B22*C22 -> 0 | E22: | | F22: 0 | G22: 0 | H22: =F22*G22 -> 0 | I22: =H22-D22 -> 0
A23: Forage | B23: 0 | C23: 0 | D23: =B23*C23 -> 0 | E23: | | F23: 0 | G23: 0 | H23: =F23*G23 -> 0 | I23: =H23-D23 -> 0
A24: Complete ration | B24: 0 | C24: 0 | D24: =B24*C24 -> 0 | E24: | | F24: 0 | G24: 0 | H24: =F24*G24 -> 0 | I24: =H24-D24 -> 0
A25: Other feed | B25: 0 | C25: 0 | D25: =B25*C25 -> 0 | E25: | | F25: 0 | G25: 0 | H25: =F25*G25 -> 0 | I25: =H25-D25 -> 0
A26: Supplies | E26: |
A27: Machine: parts | B27: 0 | C27: 0 | D27: =B27*C27 -> 0 | E27: | | F27: 0 | G27: 0 | H27: =F27*G27 -> 0 | I27: =H27-D27 -> 0
A28: Fuel, oil, grease | B28: 0 | C28: 0 | D28: =B28*C28 -> 0 | E28: | | F28: 0 | G28: 0 | H28: =F28*G28 -> 0 | I28: =H28-D28 -> 0
A29: Livestock: semen | B29: 0 | C29: 0 | D29: =B29*C29 -> 0 | E29: | | F29: 0 | G29: 0 | H29: =F29*G29 -> 0 | I29: =H29-D29 -> 0
A30: Vet. Supplies | B30: 0 | C30: 0 | D30: =B30*C30 -> 0 | E30: | | F30: 0 | G30: 0 | H30: =F30*G30 -> 0 | I30: =H30-D30 -> 0
A31: Bedding | B31: 0 | C31: 0 | D31: =B31*C31 -> 0 | E31: | | F31: 0 | G31: 0 | H31: =F31*G31 -> 0 | I31: =H31-D31 -> 0
A32: Dairy supplies | B32: 0 | C32: 0 | D32: =B32*C32 -> 0 | E32: | | F32: 0 | G32: 0 | H32: =F32*G32 -> 0 | I32: =H32-D32 -> 0
A33: Other lvstk supplies | B33: 0 | C33: 0 | D33: =B33*C33 -> 0 | E33: | | F33: 0 | G33: 0 | H33: =F33*G33 -> 0 | I33: =H33-D33 -> 0
A34: Crops: fertilizer | B34: 0 | C34: 0 | D34: =B34*C34 -> 0 | E34: | | F34: 0 | G34: 0 | H34: =F34*G34 -> 0 | I34: =H34-D34 -> 0
A35: Seed | B35: 0 | C35: 0 | D35: =B35*C35 -> 0 | E35: | | F35: 0 | G35: 0 | H35: =F35*G35 -> 0 | I35: =H35-D35 -> 0
A36: Pesticide/other | B36: 0 | C36: 0 | D36: =B36*C36 -> 0 | E36: | | F36: 0 | G36: 0 | H36: =F36*G36 -> 0 | I36: =H36-D36 -> 0
A37: Land/building/fence: | B37: 0 | C37: 0 | D37: =B37*C37 -> 0 | E37: | | F37: 0 | G37: 0 | H37: =F37*G37 -> 0 | I37: =H37-D37 -> 0
A38: Other: | B38: 0 | C38: 0 | D38: =B38*C38 -> 0 | E38: | | F38: 0 | G38: 0 | H38: =F38*G38 -> 0 | I38: =H38-D38 -> 0
A39: Total feed and supplies | D39: =SUM(D20:D38) -> 0 | E39: | | H39: =SUM(H20:H38) -> 0
A41: (1) All inventory changes are calculated: end year minus beginning year. Grown feed carries over to Dairy
A42: Receipts and purchased feed and supplies carry over to Dairy Expenses.
A43: (2) Copy directly from Total line in section above.
...

Sheet Receivables
A1: ='Dairy Description'!A1 -> Key Code: | C1: Dairy Business Analysis Project
C2: Dairy Business Summary
A3: 2000
A5: Changes in Operating Accounts Receivable
B6: Balance | C6: Balance | D6: Change in | E6: Allocation
A7: Account Number | B7: Beginning | C7: Ending | D7: Accounts | F7: Change in
A8: or Description (1) | B8: (Jan 1) | C8: (Dec 31) | D8: Receivable(2) | E8: Receipt Category | F8: Acct. Rec.
A10: Milk receipts | B10: 0 | C10: 0 | D10: =C10-B10 -> 0 | E10: Milk | F10: =D10 -> 0
A11: 0 | B11: 0 | C11: 0 | D11: =C11-B11 -> 0 | E11: Cows | F11: 0
A12: 0 | B12: 0 | C12: 0 | D12: =C12-B12 -> 0 | E12: Calves | F12: 0
A13: 0 | B13: 0 | C13: 0 | D13: =C13-B13 -> 0 | E13: Other Livestock | F13: 0
A14: 0 | B14: 0 | C14: 0 | D14: =C14-B14 -> 0 | E14: Crops | F14: 0
A15: 0 | B15: 0 | C15: 0 | D15: =C15-B15 -> 0 | E15: Gov't Receipts | F15: 0
A16: 0 | B16: 0 | C16: 0 | D16: =C16-B16 -> 0 | E16: Custom work | F16: 0
A17: 0 | B17: 0 | C17: 0 | D17: =C17-B17 -> 0 | E17: Gas tax refund | F17: 0
A18: 0 | B18: 0 | C18: 0 | D18: =C18-B18 -> 0 | E18: Other | F18: 0
A19: Total(3) | B19: =SUM(B10:B18) -> 0 | C19: =SUM(C10:C18) -> 0 | D19: =C19-B19 -> 0 | E19: Total(3) | F19: =SUM(F10:F18) -> 0
A21: 1. Identify changes in operating accounts receivable by taking inventory of beginning and ending account balances.
A22: 2. Assign and allocate the changes in accounts receivable to appropriate dairy receipts using worksheet.
A23: 3. The total of the "Change in Accounts Receivable" column above must equal the total allocation.

Sheet Income
A1: ='Dairy Description'!A1 -> Key Code: | B1: Dairy Business Analysis Project
A2: Dairy Business Summary
A3: 2000
A5: Dairy Receipts
D6: Changes in
B7: Cash | C7: Change in | D7: Accounts | E7: Accrual
A8: RECEIPTS | B8: Receipts | C8: + Inventory (1) | D8: + Receivable (2) | E8: = Receipts
A9: Milk sales (3) | B9: 0 | C9: xxxxxxxxxxxx | D9: =Receivables!F10 -> 0 | E9: =B9+D9 -> 0
A10: Cow Sales (4) | B10: 0 | C10: =(Livestock!L10-Livestock!F10)+(Livestock!L12-Livestock!F12) -> 0 | D10: =Receivables!F11 -> 0 | E10: =SUM(B10:D10) -> 0
A11: Heifer & calf sales | B11: 0 | C11: =(Livestock!L19-Livestock!F19) -> 0 | D11: =Receivables!F12 -> 0 | E11: =B11+C11+D11 -> 0
A12: Other livestock (5) | B12: 0 | C12: =Livestock!L24-Livestock!F24 -> 0 | D12: =Receivables!F13 -> 0 | E12: =B12+C12+D12 -> 0
A13: Crops (6) | B13: 0 | C13: ='Feed and Supply'!I20 -> 0 | D13: =Receivables!F14 -> 0 | E13: =B13+C13+D13 -> 0
A14: Gov't receipts | B14: 0 | C14: xxxxxxxxxxxxx | D14: =Receivables!F15 -> 0 | E14: =B14+D14 -> 0
A15: Custom work | B15: 0 | C15: xxxxxxxxxxxxx | D15: =Receivables!F16 -> 0 | E15: =B15+D15 -> 0
A16: Gas tax refund | B16: 0 | C16: xxxxxxxxxxxxx | D16: =Receivables!F17 -> 0 | E16: =B16+D16 -> 0
A17: Other | B17: 0 | C17: 0 | D17: =Receivables!F18 -> 0 | E17: =B17+C17+D17 -> 0
A18: 0 | B18: 0 | C18: 0 | D18: 0 | E18: =B18+C18+D18 -> 0
A19: 0 | B19: 0 | C19: 0 | D19: 0 | E19: =B19+C19+D19 -> 0
A20: 0 | B20: 0 | C20: 0 | D20: 0 | E20: =B20+C20+D20 -> 0
A21: 0 | B21: 0 | C21: 0 | D21: 0 | E21: =B21+C21+D21 -> 0
A22: TOTAL | B22: =SUM(B9:B21) -> 0 | D22: =SUM(D9:D21) -> 0 | E22: =SUM(E9:E21) -> 0
A24: Nondairy Receipts
A25: Cash income (7) | E25: 0
A26: Other cash used (8) | E26: 0
A27: Noncash capital transfers (9) | E27: 0
A29: Notes
A30: (1) End of year minus beginning of year. Computed from data in other forms.
A31: (2) Use worksheets for accounts receivable (Screen 4).
A32: (3) Enter gross milk receipts. All marketing and co-op deductions are entered separately as expenses.
A33: (4) Gross receipts from cull cows and cows sold for dairy purposes. Cows are females that have calved.
A34: Do not include sales of capitalized livestock. Enter that information on Livestock page.
A35: (5) Receipts from sale of heifers, bulls, or other livestock not reported above. Do not enter sales of capital livestock.
A36: (6) Crop sales includes sales of standing and harvested crops and any crop insurance proceeds.
A37: Do not include sales of purchased feed.
A38: (7) If dairy accounts are not separate from personal accounts, or doing a Level 2 analysis, fill in this value.
A39: Nondairy cash income from nondairy work for self or spouse, tax refunds, principal and interest received
A40: from prior sale of dairy assets, other sales, income form public offices or other nondairy income that is
... A48: dairy assets.

Sheet Payables
A1: ='Dairy Description'!A1 -> Key Code: | C1: Dairy Business Analysis Project
A2: Dairy Business Summary
A3: 2000
A5: Changes in Accounts Payable Worksheet
B6: Balance | C6: Balance | D6: Change in | E6: Allocation (4)
A7: Account Number | B7: Beginning | C7: Ending | D7: Accounts | E7: (Totals entered on Expense form)
A8: or Description (1,2) | B8: (Jan 1) | C8: (Dec 31) | D8: Payable (3) | E8: Expense | F8: Change in Pay.
E9: Personnel
A10: _______________ | B10: 0 | C10: 0 | D10: =C10-B10 -> 0 | E10: Salaries/wages | F10: 0
A11: _______________ | B11: 0 | C11: 0 | D11: =C11-B11 -> 0 | E11: Related payroll costs | F11: 0
A12: _______________ | B12: 0 | C12: 0 | D12: =C12-B12 -> 0 | E12: Other | F12: 0
A13: _______________ | B13: 0 | C13: 0 | D13: =C13-B13 -> 0 | E13: Purchased Feed
A14: _______________ | B14: 0 | C14: 0 | D14: =C14-B14 -> 0 | E14: Grain & conc. | F14: 0
A15: _______________ | B15: 0 | C15: 0 | D15: =C15-B15 -> 0 | E15: Forage | F15: 0
A16: _______________ | B16: 0 | C16: 0 | D16: =C16-B16 -> 0 | E16: Complete ration | F16: 0
A17: _______________ | B17: 0 | C17: 0 | D17: =C17-B17 -> 0 | E17: Other feed | F17: 0
A18: _______________ | B18: 0 | C18: 0 | D18: =C18-B18 -> 0 | E18: Crops
A19: _______________ | B19: 0 | C19: 0 | D19: =C19-B19 -> 0 | E19: Fertilizer & lime | F19: 0
A20: _______________ | B20: 0 | C20: 0 | D20: =C20-B20 -> 0 | E20: Seeds & plants | F20: 0
A21: _______________ | B21: 0 | C21: 0 | D21: =C21-B21 -> 0 | E21: Spray & other exp. | F21: 0
A22: Total (6) | B22: =SUM(B10:B21) -> 0 | C22: =SUM(C10:C21) -> 0 | D22: =C22-B22 -> 0 | E22: Machinery
E23: Hire, rent, lease | F23: 0
A24: 1. Take inventory in open operating accounts payable at the beginning | E24: Repairs & other exp. | F24: 0
A25: and end of year. These accounts established when dairy inputs, such | E25: Fuel, oil, grease | F25: 0
A26: as feed, fertilizer, supplies, machinery, repairs, and veterinarian services | E26: Livestock
A27: were bought on credit. | E27: Replacements | F27: 0
A28: 2. If there is more than one account per vendor, list separately on left-hand | E28: Breeding | F28: 0
A29: portion of the worksheet to facilitate easier allocation to dairy expense | E29: Vet & medicine | F29: 0
A30: categories. | E30: Bedding | F30: 0
A31: 3. Assign and allocate changes in open operating accounts payable to | E31: Dairy supplies | F31: 0
A32: appropriate dairy expenses. | E32: Cattle lease/rent | F32: 0
A33: 4. When more than one type of dairy input is included in an open account, | E33: Other livestock exp. | F33: 0
A34: allocate to the expense categories using estimated ratio of dairy input | E34: Milk Marketing
A35: actually purchased from the account during the year. | E35: Hauling | F35: 0
A36: 5. If scheduled debt payments were not made, there is likely an | E36: Coop dues | F36: 0
A37: increase in accounts payable for "interest". However, if the loan was | E37: Advertising, mrkg. | F37: 0
A38: refinanced and the unpaid amount added to the principal, the interest is | E38: CCC/gov't asmts. | F38: 0
A39: considered paid and is reported elsewhere. | E39: Real Estate
A40: 6. The Total on the worksheet above must equal the Total on the allocation | E40: Land, bldg, fence repr. | F40: 0
A41: list on the right. | E41: Taxes | F41: 0
...

Sheet Prepaid Expenses
A1: ='Dairy Description'!A1 -> Key Code: | B1: Dairy Business Analysis Project
A2: Dairy Business Summary
A3: 2000
A5: Prepaid Expenses
B6: Prepaid Expenses for Year (1)
B8: Jan. 1 | C8: Dec. 31 | D8: Change (2)
A9: Personnel
A10: Salaries/wages | B10: 0 | C10: 0 | D10: =C10-B10 -> 0
A11: Related payroll costs | B11: 0 | C11: 0 | D11: =C11-B11 -> 0
A12: Other | B12: 0 | C12: 0 | D12: =C12-B12 -> 0
A13: Purchased Feed
A14: Grain & conc. | B14: 0 | C14: 0 | D14: =C14-B14 -> 0
A15: Forage | B15: 0 | C15: 0 | D15: =C15-B15 -> 0
A16: Complete ration | B16: 0 | C16: 0 | D16: =C16-B16 -> 0
A17: Other feed | B17: 0 | C17: 0 | D17: =C17-B17 -> 0
A18: Crops
A19: Fertilizer & lime | B19: 0 | C19: 0 | D19: =C19-B19 -> 0
A20: Seeds & plants | B20: 0 | C20: 0 | D20: =C20-B20 -> 0
A21: Spray & other exp. | B21: 0 | C21: 0 | D21: =C21-B21 -> 0
A22: Machinery
A23: Hire, rent, lease | B23: 0 | C23: 0 | D23: =C23-B23 -> 0
A24: Repairs & other exp. | B24: 0 | C24: 0 | D24: =C24-B24 -> 0
A25: Fuel, oil, grease | B25: 0 | C25: 0 | D25: =C25-B25 -> 0
A26: Livestock
A27: Expensed Purchases | B27: 0 | C27: 0 | D27: =C27-B27 -> 0
A28: Breeding | B28: 0 | C28: 0 | D28: =C28-B28 -> 0
A29: Vet & medicine | B29: 0 | C29: 0 | D29: =C29-B29 -> 0
A30: Bedding | B30: 0 | C30: 0 | D30: =C30-B30 -> 0
A31: Dairy supplies | B31: 0 | C31: 0 | D31: =C31-B31 -> 0
A32: Cattle lease/rent | B32: 0 | C32: 0 | D32: =C32-B32 -> 0
A33: Other livestock exp. | B33: 0 | C33: 0 | D33: =C33-B33 -> 0
A34: Milk Marketing
A35: Hauling | B35: 0 | C35: 0 | D35: =C35-B35 -> 0
A36: Coop dues | B36: 0 | C36: 0 | D36: =C36-B36 -> 0
A37: Advertising, mrkg. | B37: 0 | C37: 0 | D37: =C37-B37 -> 0
A38: CCC/gov't asmts. | B38: 0 | C38: 0 | D38: =C38-B38 -> 0
A39: Real Estate
A40: Land, bldg, fence repr. | B40: 0 | C40: 0 | D40: =C40-B40 -> 0
A41: Taxes | B41: 0 | C41: 0 | D41: =C41-B41 -> 0
A42: Rent & lease | B42: 0 | C42: 0 | D42: =C42-B42 -> 0
...

Sheet Expenses
A1: ='Dairy Description'!A1 -> Key Code: | B1: Dairy Business Analysis Project
A2: Dairy Business Summary
A3: 2000
A5: Dairy Expenses
B8: Cash | C8: Change in Inventory or | D8: Change in | E8: Accrual
A9: Expenses | B9: Amount Paid | C9: - Prepaid Expenses (1) | D9: + Acct. Payable (2) | E9: = Expenses
A10: Personnel
A11: Salaries/wages | B11: 0 | C11: ='Prepaid Expenses'!D10 -> 0 | D11: =Payables!F10 -> 0 | E11: =B11-C11+D11 -> 0
A12: Related payroll costs | B12: 0 | C12: ='Prepaid Expenses'!D11 -> 0 | D12: =Payables!F11 -> 0 | E12: =B12-C12+D12 -> 0
A13: Other | B13: 0 | C13: ='Prepaid Expenses'!D12 -> 0 | D13: =Payables!F12 -> 0 | E13: =B13-C13+D13 -> 0
A14: Purchased Feed
A15: Grain & concentrate | B15: 0 | C15: ='Feed and Supply'!I22+'Prepaid Expenses'!D14 -> 0 | D15: =Payables!F14 -> 0 | E15: =B15-C15+D15 -> 0
A16: Forage | B16: 0 | C16: ='Feed and Supply'!I23+'Prepaid Expenses'!D15 -> 0 | D16: =Payables!F15 -> 0 | E16: =B16-C16+D16 -> 0
A17: Complete ration | B17: 0 | C17: ='Feed and Supply'!I24+'Prepaid Expenses'!D16 -> 0 | D17: =Payables!F16 -> 0 | E17: =B17-C17+D17 -> 0
A18: Other feed | B18: 0 | C18: ='Feed and Supply'!I25+'Prepaid Expenses'!D17 -> 0 | D18: =Payables!F17 -> 0 | E18: =B18-C18+D18 -> 0
A19: Crops
A20: Fertilizer & lime | B20: 0 | C20: ='Feed and Supply'!I34+'Prepaid Expenses'!D19 -> 0 | D20: =Payables!F19 -> 0 | E20: =B20-C20+D20 -> 0
A21: Seeds & plants | B21: 0 | C21: ='Feed and Supply'!I35+'Prepaid Expenses'!D20 -> 0 | D21: =Payables!F20 -> 0 | E21: =B21-C21+D21 -> 0
A22: Spray & other exp. | B22: 0 | C22: ='Feed and Supply'!I36+'Prepaid Expenses'!D21 -> 0 | D22: =Payables!F21 -> 0 | E22: =B22-C22+D22 -> 0
A23: Machinery
A24: Hire, rent, lease | B24: 0 | C24: ='Prepaid Expenses'!D23 -> 0 | D24: =Payables!F23 -> 0 | E24: =B24-C24+D24 -> 0
A25: Repairs & other exp. | B25: 0 | C25: ='Feed and Supply'!I27+'Prepaid Expenses'!D24 -> 0 | D25: =Payables!F24 -> 0 | E25: =B25-C25+D25 -> 0
A26: Fuel, oil, grease | B26: 0 | C26: ='Feed and Supply'!I28+'Prepaid Expenses'!D25 -> 0 | D26: =Payables!F25 -> 0 | E26: =B26-C26+D26 -> 0
A27: Livestock
A28: Expensed purchases (3) | B28: 0 | C28: ='Prepaid Expenses'!D27 -> 0 | D28: =Payables!F27 -> 0 | E28: =B28-C28+D28 -> 0
A29: Breeding | B29: 0 | C29: ='Feed and Supply'!I29+'Prepaid Expenses'!D28 -> 0 | D29: =Payables!F28 -> 0 | E29: =B29-C29+D29 -> 0
A30: Vet & medicine | B30: 0 | C30: ='Feed and Supply'!I30+'Prepaid Expenses'!D29 -> 0 | D30: =Payables!F29 -> 0 | E30: =B30-C30+D30 -> 0
A31: Bedding | B31: 0 | C31: ='Feed and Supply'!I31+'Prepaid Expenses'!D30 -> 0 | D31: =Payables!F30 -> 0 | E31: =B31-C31+D31 -> 0
A32: Dairy supplies | B32: 0 | C32: ='Feed and Supply'!I32+'Prepaid Expenses'!D31 -> 0 | D32: =Payables!F31 -> 0 | E32: =B32-C32+D32 -> 0
A33: Cattle lease/rent | B33: 0 | C33: ='Prepaid Expenses'!D32 -> 0 | D33: =Payables!F32 -> 0 | E33: =B33-C33+D33 -> 0
A34: Other livestock exp. (4) | B34: 0 | C34: ='Feed and Supply'!I33+'Prepaid Expenses'!D33 -> 0 | D34: =Payables!F33 -> 0 | E34: =B34-C34+D34 -> 0
A35: Milk Marketing
A36: Hauling | B36: 0 | C36: ='Prepaid Expenses'!D35 -> 0 | D36: =Payables!F35 -> 0 | E36: =B36-C36+D36 -> 0
A37: Coop dues | B37: 0 | C37: ='Prepaid Expenses'!D36 -> 0 | D37: =Payables!F36 -> 0 | E37: =B37-C37+D37 -> 0
A38: Advertising, mrkg. | B38: 0 | C38: ='Prepaid Expenses'!D37 -> 0 | D38: =Payables!F37 -> 0 | E38: =B38-C38+D38 -> 0
A39: CCC/gov't asmts. | B39: 0 | C39: ='Prepaid Expenses'!D38 -> 0 | D39: =Payables!F38 -> 0 | E39: =B39-C39+D39 -> 0
A40: Real Estate
A41: Land, bldg, fence repr. | B41: 0 | C41: ='Feed and Supply'!I37+'Prepaid Expenses'!D40 -> 0 | D41: =Payables!F40 -> 0 | E41: =B41-C41+D41 -> 0
A42: Taxes | B42: 0 | C42: ='Feed and Supply'!I38+'Prepaid Expenses'!D41 -> 0 | D42: =Payables!F41 -> 0 | E42: =B42-C42+D42 -> 0
A43: Rent & lease | B43: 0 | C43: ='Feed and Supply'!I39+'Prepaid Expenses'!D42 -> 0 | D43: =Payables!F42 -> 0 | E43: =B43-C43+D43 -> 0
...

Sheet Machinery and Equipment
A1: ='Dairy Description'!A1 -> Key Code: | B1: Dairy Business Analysis Project
A2: Dairy Business Summary
A3: 2000
A5: Note: If the business maintains complete and accurate records on machinery and equipment, only the
A6: bottom section needs be filled out. The top two sections are worksheets to compute values
A7: for total machinery and equipment purchased and sold, which are used in the bottom section.
A9: Machinery, Equipment Inventory & Depreciation | F9: Worksheet
A10: Machinery and Equipment Purchased Worksheet
D11: Market | E11: Market
B12: Cash | D12: Value of | E12: Value of
A13: Description | B13: Paid | C13: + | D13: Trade-in | E13: = New Item (1)
A14: _________________________ | B14: 0 | D14: 0 | E14: =B14+D14 -> 0
A15: _________________________ | B15: 0 | D15: 0 | E15: =B15+D15 -> 0
A16: _________________________ | B16: 0 | D16: 0 | E16: =B16+D16 -> 0
A17: _________________________ | B17: 0 | D17: 0 | E17: =B17+D17 -> 0
A18: _________________________ | B18: 0 | D18: 0 | E18: 0
A19: _________________________ | B19: 0 | D19: 0 | E19: =B19+D19 -> 0
A20: Total Mach. & Equip. Purchased | B20: =SUM(B14:B19) -> 0
A22: (1) Loss in market value may occur from date of purchase to end of year. Adjust year end value
A23: recorded in inventory to represent year end market values of machinery and equipment purchased.
F24: Worksheet
A25: Machinery and Equipment Sold or Destroyed (not trade-ins) Worksheet
A26: Description | B26: Sale | D26: Insurance
B27: Amount | D27: Received
A28: _________________________ | B28: 0 | D28: 0
A29: _________________________ | B29: 0 | D29: 0
A30: _________________________ | B30: 0 | D30: 0
A31: Total Mach. & Equipment Sold | B31: =SUM(B28:B30) -> 0 | D31: =SUM(D28:D30) -> 0 | E31: =SUM(B31:D31) -> 0
A34: Machinery and Equipment Inventory & Depreciation (do not include leased items)
A35: Beginning of Year Inventory | D35: 0 | E35: End of Year Inventory | F35: 0
A36: Machinery and Equipment Purchased | C36: + | D36: 0
A37: Noncash Mach. Transfer to Dairy | C37: + | D37: 0
A38: (e.g. gifts/inheritances)
A39: Machinery and Equipment Sold | C39: - | D39: 0
A40: Tax Depreciation (2) | C40: - | D40: 0
B41: Total Beginning Inventory After Changes | F41: =D35+D36+D37-D39-D40 -> 0
B42: Machinery Appreciation | F42: =F35-F41 -> 0
B43: (end less beginning after changes)
A44: (2) Depreciation for year, exclude buildings and cattle from depreciation.

Sheet Buildings
A1: ='Dairy Description'!A1 -> Key Code: | B1: Dairy Business Analysis Project
A2: Dairy Business Summary
A3: 2000
A5: Building Purchases & Sales | J5: Worksheet
A6: New Purchases & Capital Improvements | J6: Sale Price
F7: Lost | J7: or Amount
A8: Description | D8: Cost | F8: Capital | H8: Description | J8: Received
A9: Buildings and Land Improvements (1)
A10: _______________________________ | D10: 0 | F10: 0 | H10: Capital Sales:
A11: _______________________________ | D11: 0 | F11: 0 | H11: ___________________ | J11: 0
A12: _______________________________ | D12: 0 | F12: 0 | H12: ___________________ | J12: 0
A13: _______________________________ | D13: 0 | F13: 0 | H13: ___________________ | J13: 0
A14: _______________________________ | D14: 0 | F14: 0 | H14: Losses:
A15: _______________________________ | D15: 0 | F15: 0 | H15: ___________________ | J15: 0
A16: _______________________________ | D16: 0 | F16: 0 | H16: ___________________ | J16: 0
A17: Total Buildings | G17: Total Capital Sales
A18: & Lost Capital | D18: =SUM(D10:D16) -> 0 | F18: =SUM(F10:F16) -> 0 | H18: & Losses | J18: =SUM(J11:J16) -> 0
A20: (1) e.g., new fences, drainage tile, farm ponds.
A22: Building/Improvement Inventory Balance
G23: (Jan 1) | I23: (Dec 31)
E24: Building Market Value: | G24: Beginning | H24: 0 | I24: Ending | J24: 0
A25: New buildings/improvements
A26: Purchased: | D26: 0 | E26: - | F26: 0 | G26: = + | H26: =D26-F26 -> 0
D27: bldgs./land imp. | F27: lost capital | H27: value added
F28: Noncash Transfer to Farm (e.g. gifts/inherit.) | G28: + | H28: 0
F29: =B29*D29 -> 0
F30: Depreciation: from income tax (including buildings) | G30: - | H30: 0
F31: =B31*D31 -> 0
A33: Buildings Sold: | B33: Total sale price | F33: 0
B34: Sale expenses | E34: - | F34: 0
B35: Net Sale Price | G35: - | H35: =F33-F34 -> 0
B36: Note/lien held by seller | E36: - | F36: 0
B37: Net cash amount received (2) | E37: = | F37: =F33-F34-F36 -> 0
A38: Total beginning value after changes | F38: 0 | J38: =H24+H26+H28-H30-H35 -> 0
A40: Building Appreciation | J40: =J24-J38 -> 0
A42: (2) Calculated value is a cash inflow to the farm. If part or all of this was converted to nonfarm,
A43: This must be noted.

Sheet Real Estate
A1: ='Dairy Description'!A1 -> Key Code:
A2: Dairy Business Analysis Project
A3: Dairy Business Summary
A4: 2000
A5: Real Estate Inventory
D6: '1 January | G6: | | I6: '31 December
A7: Parcel Description | C7: # acres | D7: $ per acre | F7: value | G7: | | H7: # acres | I7: $ per acre | J7: value
A8: 0 | C8: 0 | D8: 0 | F8: =C8*D8 -> 0 | G8: | | H8: 0 | I8: 0 | J8: =H8*I8 -> 0
A9: 0 | C9: 0 | D9: 0 | F9: =C9*D9 -> 0 | G9: | | H9: 0 | I9: 0 | J9: =H9*I9 -> 0
A10: 0 | C10: 0 | D10: 0 | F10: =C10*D10 -> 0 | G10: | | H10: 0 | I10: 0 | J10: =H10*I10 -> 0
A11: 0 | C11: 0 | D11: 0 | F11: =C11*D11 -> 0 | G11: | | H11: 0 | I11: 0 | J11: =H11*I11 -> 0
A12: 0 | C12: 0 | D12: 0 | F12: =C12*D12 -> 0 | G12: | | H12: 0 | I12: 0 | J12: =H12*I12 -> 0
A13: 0 | C13: 0 | D13: 0 | F13: =C13*D13 -> 0 | G13: | | H13: 0 | I13: 0 | J13: =H13*I13 -> 0
A14: 0 | C14: 0 | D14: 0 | F14: =C14*D14 -> 0 | G14: | | H14: 0 | I14: 0 | J14: =H14*I14 -> 0
A15: 0 | C15: 0 | D15: 0 | F15: =C15*D15 -> 0 | G15: | | H15: 0 | I15: 0 | J15: =H15*I15 -> 0
A16: 0 | C16: 0 | D16: 0 | F16: =C16*D16 -> 0 | G16: | | H16: 0 | I16: 0 | J16: =H16*I16 -> 0
A17: 0 | C17: 0 | D17: 0 | F17: =C17*D17 -> 0 | G17: | | H17: 0 | I17: 0 | J17: =H17*I17 -> 0
A18: 0 | C18: 0 | D18: 0 | F18: =C18*D18 -> 0 | G18: | | H18: 0 | I18: 0 | J18: =H18*I18 -> 0
A19: 0 | C19: 0 | D19: 0 | F19: =C19*D19 -> 0 | G19: | | H19: 0 | I19: 0 | J19: =H19*I19 -> 0
... A22: 0 | C22: 0 | D22: 0 | F22: =C22*D22 -> 0 | G22: | | H22: 0 | I22: 0 | J22: =H22*I22 -> 0
G23: |
A24: Total | C24: =SUM(C8:C22) -> 0 | D24: =SUM(D8:D22) -> 0 | F24: =SUM(F8:F22) -> 0 | G24: | | H24: =SUM(H8:H22) -> 0 | I24: =SUM(I8:I22) -> 0 | J24: =SUM(J8:J22) -> 0
A27: Real Estate Transactions
G28: (Jan 1) | I28: (Dec 31)
E29: Real Estate Market Value: | G29: Beginning | H29: =F24 -> 0 | I29: Ending | J29: =J24 -> 0
A30: New Real Estate
A31: Purchased: | D31: 0 | E31: - | F31: 0 | G31: = | H31: =D31-F31 -> 0
D32: Land | F32: lost capital | H32: value added
F33: Noncash Real Estate Transfer to Farm (e.g. gifts/inherit.) | G33: + | H33: 0
A36: Real Estate Sold: | D36: Total sale price | F36: 0
D37: Sale expenses | E37: - | F37: 0
D38: Net Sale Price | G38: - | H38: =F36-F37 -> 0
D39: Note/mortgage held by seller | E39: - | F39: 0
D40: Net cash amount received (1) | E40: = | F40: =F36-F37-F39 -> 0
A41: Total beginning value after changes | F41: 0 | J41: =H29+H31+H33-H38 -> 0
A43: Real Estate Appreciation | J43: =J29-J41 -> 0
A45: (1) Calculated value is a cash inflow to the farm. If part or all of this was converted to nonfarm, this must be noted.

Sheet Assets
A1: ='Dairy Description'!A1 -> Key Code:
C2: Dairy Business Analysis Project
A3: Dairy Business Summary
A4: 2000
A7: Other Assets, Paid-in-Capital
A8: Other assets | C8: Beginning (Jan 1) | E8: Ending (Dec 31)
A10: Machinery Leased | C10: 0 | E10: 0
A11: Buildings Leased | C11: 0 | E11: 0
A12: Real Estate Leased | C12: 0 | E12: 0
A13: Cash, checking & savings (1) | C13: 0 | E13: 0
A14: Farm Credit stock | C14: 0 | E14: 0
A15: Milk coop stock & certificates | C15: 0 | E15: 0
A16: Other | C16: 0 | E16: 0
A17: Non-dairy assets | C17: 0 | E17: 0
A19: Miscellaneous Inputs | C19: Amount
A20: Owner Withdrawals (2) | C20: 0
A21: Net Social Security and Income
A22: Taxes Paid (3) | C22: 0
A23: Capital Distributions Made (4) | C23: 0
A26: Paid-in-Capital
A27: Beginning Value | C27: 0 | D27: Ending Value | E27: 0
A28: Additional paid-in-capital | B28: + | C28: 0
A29: Additions/Reductions in retained earnings (5) | B29: + | C29: 0
A30: Net value of paid-in-capital | D30: =C27+C28+C29 -> 0
A31: Gain/Loss in value | D31: =E27-D30 -> 0
A34: Stocks and Certificates
A35: Beginning Value | C35: 0 | D35: Ending Value | E35: 0
A36: Additional capital investment | B36: + | C36: 0
A37: Additions/Reductions in principal | B37: + | C37: 0
A38: Net value of stocks/certificates | D38: =C35+C36+C37 -> 0
A39: Gain/Loss in value | D39: =E35-D38 -> 0
A41: (1) Beginning and Ending cash balances are essential for statement of cashflows to balance.
A42: (2) Only include if records indicate a withdrawal. If no draws taken, the value of management will be
A43: calculated using a fixed value.
A44: (3) Record any corporate or personal income taxes here. If a refund was issued, record as
A45: a negative value.
A46: (4) Only record a value if a gift or capital distribution was made from the business accounts.
A47: (5) Only record if changes in retained earnings directly affect the value of paid-in-capital.
A48: (6) Only record if adjustments were made to principal balance indicating an addition or reduction in
A49: principal value. Appreciation of stock value will be calculated.

Sheet Leases
A1: ='Dairy Description'!A1 -> Key Code: | D1: Dairy Business Analysis Project
A2: Dairy Business Summary
A3: 2000
A4: Lease Schedule
B5: Principal Balance | D5: Payments | G5: Next year's planned payments
A6: Lease type | B6: Jan. 1 | C6: Dec. 31 | D6: Interest | E6: Principal | F6: New Leases | G6: Amount | H6: Number/yr. | I6: Total
A7: Cattle
A8: 0 | B8: 0 | C8: 0 | D8: 0 | E8: 0 | F8: 0 | G8: 0 | H8: 0 | I8: =G8*H8 -> 0
A9: 0 | B9: 0 | C9: 0 | D9: 0 | E9: 0 | F9: 0 | G9: 0 | H9: 0 | I9: =G9*H9 -> 0
A10: 0 | B10: 0 | C10: 0 | D10: 0 | E10: 0 | F10: 0 | G10: 0 | H10: 0 | I10: =G10*H10 -> 0
A11: 0 | B11: 0 | C11: 0 | D11: 0 | E11: 0 | F11: 0 | G11: 0 | H11: 0 | I11: =G11*H11 -> 0
A12: Total cattle | B12: =SUM(B8:B11) -> 0 | C12: =SUM(C8:C11) -> 0 | D12: =SUM(D8:D11) -> 0 | E12: =SUM(E8:E11) -> 0 | F12: =SUM(F8:F11) -> 0 | I12: =SUM(I8:I11) -> 0
A14: Machinery and Equipment
A15: 0 | B15: 0 | C15: 0 | D15: 0 | E15: 0 | F15: 0 | G15: 0 | H15: 0 | I15: =G15*H15 -> 0
A16: 0 | B16: 0 | C16: 0 | D16: 0 | E16: 0 | F16: 0 | G16: 0 | H16: 0 | I16: =G16*H16 -> 0
A17: 0 | B17: 0 | C17: 0 | D17: 0 | E17: 0 | F17: 0 | G17: 0 | H17: 0 | I17: =G17*H17 -> 0
A18: 0 | B18: 0 | C18: 0 | D18: 0 | E18: 0 | F18: 0 | G18: 0 | H18: 0 | I18: =G18*H18 -> 0
A19: Total mach. and equip. | B19: =SUM(B15:B18) -> 0 | C19: =SUM(C15:C18) -> 0 | D19: =SUM(D15:D18) -> 0 | E19: =SUM(E15:E18) -> 0 | F19: =SUM(F15:F18) -> 0 | I19: =SUM(I15:I18) -> 0
A21: Buildings
A22: 0 | B22: 0 | C22: 0 | D22: 0 | E22: 0 | F22: 0 | G22: 0 | H22: 0 | I22: =G22*H22 -> 0
A23: 0 | B23: 0 | C23: 0 | D23: 0 | E23: 0 | F23: 0 | G23: 0 | H23: 0 | I23: =G23*H23 -> 0
A24: 0 | B24: 0 | C24: 0 | D24: 0 | E24: 0 | F24: 0 | G24: 0 | H24: 0 | I24: =G24*H24 -> 0
A25: 0 | B25: 0 | C25: 0 | D25: 0 | E25: 0 | F25: 0 | G25: 0 | H25: 0 | I25: =G25*H25 -> 0
A26: Total buildings | B26: =SUM(B22:B25) -> 0 | C26: =SUM(C22:C25) -> 0 | D26: =SUM(D22:D25) -> 0 | E26: =SUM(E22:E25) -> 0 | F26: =SUM(F22:F25) -> 0 | I26: =SUM(I22:I25) -> 0
A28: Real estate
A29: 0 | B29: 0 | C29: 0 | D29: 0 | E29: 0 | F29: 0 | G29: 0 | H29: 0 | I29: =G29*H29 -> 0
A30: 0 | B30: 0 | C30: 0 | D30: 0 | E30: 0 | F30: 0 | G30: 0 | H30: 0 | I30: =G30*H30 -> 0
A31: 0 | B31: 0 | C31: 0 | D31: 0 | E31: 0 | F31: 0 | G31: 0 | H31: 0 | I31: =G31*H31 -> 0
A32: 0 | B32: 0 | C32: 0 | D32: 0 | E32: 0 | F32: 0 | G32: 0 | H32: 0 | I32: =G32*H32 -> 0
A33: Total real estate | B33: =SUM(B29:B32) -> 0 | C33: =SUM(C29:C32) -> 0 | D33: =SUM(D29:D32) -> 0 | E33: =SUM(E29:E32) -> 0 | F33: =SUM(F29:F32) -> 0 | I33: =SUM(I29:I32) -> 0
A35: Whole farm
A36: 0 | B36: 0 | C36: 0 | D36: 0 | E36: 0 | F36: 0 | G36: 0 | H36: 0 | I36: =G36*H36 -> 0
A37: 0 | B37: 0 | C37: 0 | D37: 0 | E37: 0 | F37: 0 | G37: 0 | H37: 0 | I37: =G37*H37 -> 0
A38: 0 | B38: 0 | C38: 0 | D38: 0 | E38: 0 | F38: 0 | G38: 0 | H38: 0 | I38: =G38*H38 -> 0
A39: 0 | B39: 0 | C39: 0 | D39: 0 | E39: 0 | F39: 0 | G39: 0 | H39: 0 | I39: =G39*H39 -> 0
A40: Total whole farm | B40: =SUM(B36:B39) -> 0 | C40: =SUM(C36:C39) -> 0 | D40: =SUM(D36:D39) -> 0 | E40: =SUM(E36:E39) -> 0 | F40: =SUM(F36:F39) -> 0 | I40: =SUM(I36:I39) -> 0
A42: Total--all dairy leases | B42: =B12+B19+B26+B33+B40 -> 0 | C42: =C12+C19+C26+C33+C40 -> 0 | D42: =D12+D19+D26+D33+D40 -> 0 | E42: =E12+E19+E26+E33+E40 -> 0 | F42: =F12+F19+F26+F33+F40 -> 0
A44: Non-dairy leases | B44: 0 | C44: 0 | D44: 0 | E44: 0 | F44: 0 | G44: 0 | H44: 0 | I44: =G44*H44 -> 0
A46: Grand total--all leases | B46: =B42+B44 -> 0 | C46: =C42+C44 -> 0 | D46: =D42+D44 -> 0 | E46: =E42+E44 -> 0 | F46: =F42+F44 -> 0

Sheet Liabilities
A1: ='Dairy Description'!A1 -> Key Code: | D1: Dairy Business Analysis Project
A2: Dairy Business Summary
A3: 2000
A4: Debt Schedule
B5: Principal Balance | D5: Payments | G5: Next year's planned payments
A6: Loan Description | B6: Jan. 1 | C6: Dec. 31 | D6: Interest | E6: Principal | F6: New Borrowings | G6: Amount | H6: Number/yr. | I6: Total
A7: Term debt (>1 year)
A8: 0 | B8: 0 | C8: 0 | D8: 0 | E8: 0 | F8: 0 | G8: 0 | H8: 0 | I8: =G8*H8 -> 0
A9: 0 | B9: 0 | C9: 0 | D9: 0 | E9: 0 | F9: 0 | G9: 0 | H9: 0 | I9: =G9*H9 -> 0
A10: 0 | B10: 0 | C10: 0 | D10: 0 | E10: 0 | F10: 0 | G10: 0 | H10: 0 | I10: =G10*H10 -> 0
A11: 0 | B11: 0 | C11: 0 | D11: 0 | E11: 0 | F11: 0 | G11: 0 | H11: 0 | I11: =G11*H11 -> 0
A12: 0 | B12: 0 | C12: 0 | D12: 0 | E12: 0 | F12: 0 | G12: 0 | H12: 0 | I12: =G12*H12 -> 0
A13: 0 | B13: 0 | C13: 0 | D13: 0 | E13: 0 | F13: 0 | G13: 0 | H13: 0 | I13: =G13*H13 -> 0
A14: 0 | B14: 0 | C14: 0 | D14: 0 | E14: 0 | F14: 0 | G14: 0 | H14: 0 | I14: =G14*H14 -> 0
A15: 0 | B15: 0 | C15: 0 | D15: 0 | E15: 0 | F15: 0 | G15: 0 | H15: 0 | I15: =G15*H15 -> 0
A16: 0 | B16: 0 | C16: 0 | D16: 0 | E16: 0 | F16: 0 | G16: 0 | H16: 0 | I16: =G16*H16 -> 0
A17: 0 | B17: 0 | C17: 0 | D17: 0 | E17: 0 | F17: 0 | G17: 0 | H17: 0 | I17: =G17*H17 -> 0
A18: 0 | B18: 0 | C18: 0 | D18: 0 | E18: 0 | F18: 0 | G18: 0 | H18: 0 | I18: =G18*H18 -> 0
A19: 0 | B19: 0 | C19: 0 | D19: 0 | E19: 0 | F19: 0 | G19: 0 | H19: 0 | I19: =G19*H19 -> 0
A20: 0 | B20: 0 | C20: 0 | D20: 0 | E20: 0 | F20: 0 | G20: 0 | H20: 0 | I20: =G20*H20 -> 0
A21: Total term debt | B21: =SUM(B8:B20) -> 0 | C21: =SUM(C8:C20) -> 0 | D21: =SUM(D8:D20) -> 0 | E21: =SUM(E8:E20) -> 0 | F21: =SUM(F8:F20) -> 0 | I21: =SUM(I8:I20) -> 0
A23: Short term debt (< 1 year,
A24: borrowed to buy capital items.)
A25: 0 | B25: 0 | C25: 0 | D25: 0 | E25: 0 | F25: 0
A26: 0 | B26: 0 | C26: 0 | D26: 0 | E26: 0 | F26: 0
A27: 0 | B27: 0 | C27: 0 | D27: 0 | E27: 0 | F27: 0
A28: 0 | B28: 0 | C28: 0 | D28: 0 | E28: 0 | F28: 0
A29: 0 | B29: 0 | C29: 0 | D29: 0 | E29: 0 | F29: 0
A30: 0 | B30: 0 | C30: 0 | D30: 0 | E30: 0 | F30: 0
A31: Total short term debt | B31: =SUM(B25:B30) -> 0 | C31: =SUM(C25:C30) -> 0 | D31: =SUM(D25:D30) -> 0 | E31: =SUM(E25:E30) -> 0 | F31: =SUM(F25:F30) -> 0
A33: Operating debt (borrowed to buy items
A34: entered as expenses on screen 7)
A35: 0 | B35: 0 | C35: 0 | D35: 0 | E35: 0 | F35: 0
A36: 0 | B36: 0 | C36: 0 | D36: 0 | E36: 0 | F36: 0
A37: 0 | B37: 0 | C37: 0 | D37: 0 | E37: 0 | F37: 0
A38: 0 | B38: 0 | C38: 0 | D38: 0 | E38: 0 | F38: 0
A39: 0 | B39: 0 | C39: 0 | D39: 0 | E39: 0 | F39: 0
A40: Total operating debt | B40: =SUM(B35:B39) -> 0 | C40: =SUM(C35:C39) -> 0 | D40: =SUM(D35:D39) -> 0 | E40: =SUM(E35:E39) -> 0 | F40: =SUM(F35:F39) -> 0
A42: Total--all dairy debt | B42: =B21+B31+B40 -> 0 | C42: =C21+C31+C40 -> 0 | D42: =D21+D31+D40 -> 0 | E42: =E21+E31+E40 -> 0 | F42: =F21+F31+F40 -> 0
A44: Non-dairy Liabilities | B44: 0 | C44: 0 | D44: 0 | E44: 0 | F44: 0 | G44: 0 | H44: 0 | I44: =G44*H44 -> 0
...

Sheet Receipt Summary
A1: ='Dairy Description'!A1 -> Key Code:
A2: Dairy Business Analysis Project
A3: Dairy Business Summary
A4: 2000
A5: Dairy Revenues
A7: Labels | C7: Totals | D7: Per Cow | E7: Per Cwt | F7: Percent
A8: Milk sales | C8: =Income!E9 -> 0 | D8: =IF(AND('Dairy Description'!B$11>0),C8/'Dairy Description'!B$11,0) -> 0 | E8: =IF(AND('Dairy Description'!B$7>0),C8/('Dairy Description'!B$7/100),0) -> 0 | F8: =IF(AND($C$18>0),C8/($C$18),0) -> 0
A9: Cow sales | C9: =Income!E10 -> 0 | D9: =IF(AND('Dairy Description'!B$11>0),C9/'Dairy Description'!B$11,0) -> 0 | E9: =IF(AND('Dairy Description'!B$7>0),C9/('Dairy Description'!B$7/100),0) -> 0 | F9: =IF(AND($C$18>0),C9/($C$18),0) -> 0
A10: Calf and heifer sales | C10: =Income!E11 -> 0 | D10: =IF(AND('Dairy Description'!B$11>0),C10/'Dairy Description'!B$11,0) -> 0 | E10: =IF(AND('Dairy Description'!B$7>0),C10/('Dairy Description'!B$7/100),0) -> 0 | F10: =IF(AND($C$18>0),C10/($C$18),0) -> 0
A11: Other livestock | C11: =Income!E12 -> 0 | D11: =IF(AND('Dairy Description'!B$11>0),C11/'Dairy Description'!B$11,0) -> 0 | E11: =IF(AND('Dairy Description'!B$7>0),C11/('Dairy Description'!B$7/100),0) -> 0 | F11: =IF(AND($C$18>0),C11/($C$18),0) -> 0
A12: Crops | C12: =Income!E13 -> 0 | D12: =IF(AND('Dairy Description'!B$11>0),C12/'Dairy Description'!B$11,0) -> 0 | E12: =IF(AND('Dairy Description'!B$7>0),C12/('Dairy Description'!B$7/100),0) -> 0 | F12: =IF(AND($C$18>0),C12/($C$18),0) -> 0
A13: Gov't receipts | C13: =Income!E14 -> 0 | D13: =IF(AND('Dairy Description'!B$11>0),C13/'Dairy Description'!B$11,0) -> 0 | E13: =IF(AND('Dairy Description'!B$7>0),C13/('Dairy Description'!B$7/100),0) -> 0 | F13: =IF(AND($C$18>0),C13/($C$18),0) -> 0
A14: Custom work | C14: =Income!E15 -> 0 | D14: =IF(AND('Dairy Description'!B$11>0),C14/'Dairy Description'!B$11,0) -> 0 | E14: =IF(AND('Dairy Description'!B$7>0),C14/('Dairy Description'!B$7/100),0) -> 0 | F14: =IF(AND($C$18>0),C14/($C$18),0) -> 0
A15: Gas tax refund | C15: =Income!E16 -> 0 | D15: =IF(AND('Dairy Description'!B$11>0),C15/'Dairy Description'!B$11,0) -> 0 | E15: =IF(AND('Dairy Description'!B$7>0),C15/('Dairy Description'!B$7/100),0) -> 0 | F15: =IF(AND($C$18>0),C15/($C$18),0) -> 0
A16: Other | C16: =Income!E17+Income!E18+Income!E19+Income!E20+Income!E21 -> 0 | D16: =IF(AND('Dairy Description'!B$11>0),C16/'Dairy Description'!B$11,0) -> 0 | E16: =IF(AND('Dairy Description'!B$7>0),C16/('Dairy Description'!B$7/100),0) -> 0 | F16: =IF(AND($C$18>0),C16/($C$18),0) -> 0
A17: Gain (loss) on capital livestock sales | C17: =Livestock!H41 -> 0 | D17: =IF(AND('Dairy Description'!B$11>0),C17/'Dairy Description'!B$11,0) -> 0 | E17: =IF(AND('Dairy Description'!B$7>0),C17/('Dairy Description'!B$7/100),0) -> 0 | F17: =IF(AND($C$18>0),C17/($C$18),0) -> 0
A18: TOTAL | C18: =SUM(C8:C17) -> 0 | D18: =SUM(D8:D17) -> 0 | E18: =SUM(E8:E17) -> 0 | F18: =SUM(F8:F17) -> 0

Sheet Expense Summary
A1: ='Dairy Description'!A1 -> Key Code: | B1: Dairy Business Analysis Project
A2: Dairy Business Summary
A3: 2000
A5: Dairy Expenses
A7: Labels | C7: Totals | D7: Per Cow | E7: Per Cwt | F7: Percent (1)
A8: Personnel
A9: Salaries/wages | C9: =Expenses!E11 -> 0 | D9: =IF(AND('Dairy Description'!B$11>0),C9/'Dairy Description'!B$11,0) -> 0 | E9: =IF(AND('Dairy Description'!B$7>0),C9/('Dairy Description'!B$7/100),0) -> 0 | F9: =IF(AND('Receipt Summary'!$C$18>0),C9/('Receipt Summary'!$C$18),0) -> 0
A10: Other payroll costs | C10: =Expenses!E12 -> 0 | D10: =IF(AND('Dairy Description'!B$11>0),C10/'Dairy Description'!B$11,0) -> 0 | E10: =IF(AND('Dairy Description'!B$7>0),C10/('Dairy Description'!B$7/100),0) -> 0 | F10: =IF(AND('Receipt Summary'!$C$18>0),C10/('Receipt Summary'!$C$18),0) -> 0
A11: Other | C11: =Expenses!E13 -> 0 | D11: =IF(AND('Dairy Description'!B$11>0),C11/'Dairy Description'!B$11,0) -> 0 | E11: =IF(AND('Dairy Description'!B$7>0),C11/('Dairy Description'!B$7/100),0) -> 0 | F11: =IF(AND('Receipt Summary'!$C$18>0),C11/('Receipt Summary'!$C$18),0) -> 0
A12: Purchased Feed
A13: Grain & concentrate | C13: =Expenses!E15 -> 0 | D13: =IF(AND('Dairy Description'!B$11>0),C13/'Dairy Description'!B$11,0) -> 0 | E13: =IF(AND('Dairy Description'!B$7>0),C13/('Dairy Description'!B$7/100),0) -> 0 | F13: =IF(AND('Receipt Summary'!$C$18>0),C13/('Receipt Summary'!$C$18),0) -> 0
A14: Forage | C14: =Expenses!E16 -> 0 | D14: =IF(AND('Dairy Description'!B$11>0),C14/'Dairy Description'!B$11,0) -> 0 | E14: =IF(AND('Dairy Description'!B$7>0),C14/('Dairy Description'!B$7/100),0) -> 0 | F14: =IF(AND('Receipt Summary'!$C$18>0),C14/('Receipt Summary'!$C$18),0) -> 0
A15: Complete ration | C15: =Expenses!E17 -> 0 | D15: =IF(AND('Dairy Description'!B$11>0),C15/'Dairy Description'!B$11,0) -> 0 | E15: =IF(AND('Dairy Description'!B$7>0),C15/('Dairy Description'!B$7/100),0) -> 0 | F15: =IF(AND('Receipt Summary'!$C$18>0),C15/('Receipt Summary'!$C$18),0) -> 0
A16: Other feed | C16: =Expenses!E18 -> 0 | D16: =IF(AND('Dairy Description'!B$11>0),C16/'Dairy Description'!B$11,0) -> 0 | E16: =IF(AND('Dairy Description'!B$7>0),C16/('Dairy Description'!B$7/100),0) -> 0 | F16: =IF(AND('Receipt Summary'!$C$18>0),C16/('Receipt Summary'!$C$18),0) -> 0
E17: =SUM(E13:E16) -> 0
A18: Crops
A19: Fertilizer & lime | C19: =Expenses!E20 -> 0 | D19: =IF(AND('Dairy Description'!B$11>0),C19/'Dairy Description'!B$11,0) -> 0 | E19: =IF(AND('Dairy Description'!B$7>0),C19/('Dairy Description'!B$7/100),0) -> 0 | F19: =IF(AND('Receipt Summary'!$C$18>0),C19/('Receipt Summary'!$C$18),0) -> 0
A20: Seeds & plants | C20: =Expenses!E21 -> 0 | D20: =IF(AND('Dairy Description'!B$11>0),C20/'Dairy Description'!B$11,0) -> 0 | E20: =IF(AND('Dairy Description'!B$7>0),C20/('Dairy Description'!B$7/100),0) -> 0 | F20: =IF(AND('Receipt Summary'!$C$18>0),C20/('Receipt Summary'!$C$18),0) -> 0
A21: Spray & other exp. | C21: =Expenses!E22 -> 0 | D21: =IF(AND('Dairy Description'!B$11>0),C21/'Dairy Description'!B$11,0) -> 0 | E21: =IF(AND('Dairy Description'!B$7>0),C21/('Dairy Description'!B$7/100),0) -> 0 | F21: =IF(AND('Receipt Summary'!$C$18>0),C21/('Receipt Summary'!$C$18),0) -> 0
A22: Machinery
A23: Hire, rent, lease | C23: =Expenses!E24 -> 0 | D23: =IF(AND('Dairy Description'!B$11>0),C23/'Dairy Description'!B$11,0) -> 0 | E23: =IF(AND('Dairy Description'!B$7>0),C23/('Dairy Description'!B$7/100),0) -> 0 | F23: =IF(AND('Receipt Summary'!$C$18>0),C23/('Receipt Summary'!$C$18),0) -> 0
A24: Repairs & other exp. | C24: =Expenses!E25 -> 0 | D24: =IF(AND('Dairy Description'!B$11>0),C24/'Dairy Description'!B$11,0) -> 0 | E24: =IF(AND('Dairy Description'!B$7>0),C24/('Dairy Description'!B$7/100),0) -> 0 | F24: =IF(AND('Receipt Summary'!$C$18>0),C24/('Receipt Summary'!$C$18),0) -> 0
A25: Fuel, oil, grease | C25: =Expenses!E26 -> 0 | D25: =IF(AND('Dairy Description'!B$11>0),C25/'Dairy Description'!B$11,0) -> 0 | E25: =IF(AND('Dairy Description'!B$7>0),C25/('Dairy Description'!B$7/100),0) -> 0 | F25: =IF(AND('Receipt Summary'!$C$18>0),C25/('Receipt Summary'!$C$18),0) -> 0
A26: Livestock
A27: Expensed Purchased Livestock | C27: =Expenses!E28 -> 0 | D27: =IF(AND('Dairy Description'!B$11>0),C27/'Dairy Description'!B$11,0) -> 0 | E27: =IF(AND('Dairy Description'!B$7>0),C27/('Dairy Description'!B$7/100),0) -> 0 | F27: =IF(AND('Receipt Summary'!$C$18>0),C27/('Receipt Summary'!$C$18),0) -> 0
A28: Breeding | C28: =Expenses!E29 -> 0 | D28: =IF(AND('Dairy Description'!B$11>0),C28/'Dairy Description'!B$11,0) -> 0 | E28: =IF(AND('Dairy Description'!B$7>0),C28/('Dairy Description'!B$7/100),0) -> 0 | F28: =IF(AND('Receipt Summary'!$C$18>0),C28/('Receipt Summary'!$C$18),0) -> 0
A29: Vet & medicine | C29: =Expenses!E30 -> 0 | D29: =IF(AND('Dairy Description'!B$11>0),C29/'Dairy Description'!B$11,0) -> 0 | E29: =IF(AND('Dairy Description'!B$7>0),C29/('Dairy Description'!B$7/100),0) -> 0 | F29: =IF(AND('Receipt Summary'!$C$18>0),C29/('Receipt Summary'!$C$18),0) -> 0
A30: Bedding | C30: =Expenses!E31 -> 0 | D30: =IF(AND('Dairy Description'!B$11>0),C30/'Dairy Description'!B$11,0) -> 0 | E30: =IF(AND('Dairy Description'!B$7>0),C30/('Dairy Description'!B$7/100),0) -> 0 | F30: =IF(AND('Receipt Summary'!$C$18>0),C30/('Receipt Summary'!$C$18),0) -> 0
A31: Dairy supplies | C31: =Expenses!E32 -> 0 | D31: =IF(AND('Dairy Description'!B$11>0),C31/'Dairy Description'!B$11,0) -> 0 | E31: =IF(AND('Dairy Description'!B$7>0),C31/('Dairy Description'!B$7/100),0) -> 0 | F31: =IF(AND('Receipt Summary'!$C$18>0),C31/('Receipt Summary'!$C$18),0) -> 0
A32: Cattle lease/rent | C32: =Expenses!E33 -> 0 | D32: =IF(AND('Dairy Description'!B$11>0),C32/'Dairy Description'!B$11,0) -> 0 | E32: =IF(AND('Dairy Description'!B$7>0),C32/('Dairy Description'!B$7/100),0) -> 0 | F32: =IF(AND('Receipt Summary'!$C$18>0),C32/('Receipt Summary'!$C$18),0) -> 0
A33: Other livestock exp. | C33: =Expenses!E34 -> 0 | D33: =IF(AND('Dairy Description'!B$11>0),C33/'Dairy Description'!B$11,0) -> 0 | E33: =IF(AND('Dairy Description'!B$7>0),C33/('Dairy Description'!B$7/100),0) -> 0 | F33: =IF(AND('Receipt Summary'!$C$18>0),C33/('Receipt Summary'!$C$18),0) -> 0
A34: Milk Marketing
A35: Hauling | C35: =Expenses!E36 -> 0 | D35: =IF(AND('Dairy Description'!B$11>0),C35/'Dairy Description'!B$11,0) -> 0 | E35: =IF(AND('Dairy Description'!B$7>0),C35/('Dairy Description'!B$7/100),0) -> 0 | F35: =IF(AND('Receipt Summary'!$C$18>0),C35/('Receipt Summary'!$C$18),0) -> 0
A36: Coop dues | C36: =Expenses!E37 -> 0 | D36: =IF(AND('Dairy Description'!B$11>0),C36/'Dairy Description'!B$11,0) -> 0 | E36: =IF(AND('Dairy Description'!B$7>0),C36/('Dairy Description'!B$7/100),0) -> 0 | F36: =IF(AND('Receipt Summary'!$C$18>0),C36/('Receipt Summary'!$C$18),0) -> 0
A37: Advertising, mrkg. | C37: =Expenses!E38 -> 0 | D37: =IF(AND('Dairy Description'!B$11>0),C37/'Dairy Description'!B$11,0) -> 0 | E37: =IF(AND('Dairy Description'!B$7>0),C37/('Dairy Description'!B$7/100),0) -> 0 | F37: =IF(AND('Receipt Summary'!$C$18>0),C37/('Receipt Summary'!$C$18),0) -> 0
A38: CCC/gov't asmts. | C38: =Expenses!E39 -> 0 | D38: =IF(AND('Dairy Description'!B$11>0),C38/'Dairy Description'!B$11,0) -> 0 | E38: =IF(AND('Dairy Description'!B$7>0),C38/('Dairy Description'!B$7/100),0) -> 0 | F38: =IF(AND('Receipt Summary'!$C$18>0),C38/('Receipt Summary'!$C$18),0) -> 0
A39: Real Estate
A40: Land, bldg, fence repr. | C40: =Expenses!E41 -> 0 | D40: =IF(AND('Dairy Description'!B$11>0),C40/'Dairy Description'!B$11,0) -> 0 | E40: =IF(AND('Dairy Description'!B$7>0),C40/('Dairy Description'!B$7/100),0) -> 0 | F40: =IF(AND('Receipt Summary'!$C$18>0),C40/('Receipt Summary'!$C$18),0) -> 0
A41: Taxes | C41: =Expenses!E42 -> 0 | D41: =IF(AND('Dairy Description'!B$11>0),C41/'Dairy Description'!B$11,0) -> 0 | E41: =IF(AND('Dairy Description'!B$7>0),C41/('Dairy Description'!B$7/100),0) -> 0 | F41: =IF(AND('Receipt Summary'!$C$18>0),C41/('Receipt Summary'!$C$18),0) -> 0
A42: Rent & lease | C42: =Expenses!E43 -> 0 | D42: =IF(AND('Dairy Description'!B$11>0),C42/'Dairy Description'!B$11,0) -> 0 | E42: =IF(AND('Dairy Description'!B$7>0),C42/('Dairy Description'!B$7/100),0) -> 0 | F42: =IF(AND('Receipt Summary'!$C$18>0),C42/('Receipt Summary'!$C$18),0) -> 0
...

Sheet Balance
A1: ='Dairy Description'!A1 -> Key Code: | B1: Dairy Business Analysis Project
A2: Dairy Business Summary
A3: 2000
A5: Balance Sheet
D6: Liabilities
A7: Assets | B7: Jan 1 | C7: Dec 31 | D7: & Net Worth | E7: Jan 1 | F7: Dec 31
A9: Current | D9: Current
A10: Farm cash, | B10: =Assets!C13 -> 0 | C10: =Assets!E13 -> 0 | D10: Accounts payable | E10: =Payables!B22 -> 0 | F10: =Payables!C22 -> 0
A11: checking & savings | D11: Operating debt | E11: =Liabilities!B40 -> 0 | F11: =Liabilities!C40 -> 0
A12: Feed & supplies | B12: ='Feed and Supply'!D39 -> 0 | C12: ='Feed and Supply'!H39 -> 0 | D12: Short term debt | E12: =Liabilities!B31 -> 0 | F12: =Liabilities!C31 -> 0
A13: Accounts receivable | B13: =Receivables!B19 -> 0 | C13: =Receivables!C19 -> 0 | D13: Current portion-Notes Payable | E13: =Liabilities!E21 -> 0 | F13: =Liabilities!I21 -> 0
A14: Prepaid expenses | B14: ='Prepaid Expenses'!B52 -> 0 | C14: ='Prepaid Expenses'!C52 -> 0 | D14: Current portion-Leases | E14: =Leases!E42 -> 0 | F14: =Leases!I12+Leases!I19+Leases!I26+Leases!I33+Leases!I40 -> 0
A16: Total Current Assets | B16: =B10+B12+B13+B14 -> 0 | C16: =C10+C12+C13+C14 -> 0 | D16: Total Current Liabilities | E16: =SUM(E10:E14) -> 0 | F16: =SUM(F10:F14) -> 0
A18: Non Current | D18: Non Current
A19: Dairy cows: | D19: Non Current Portion-
A20: Raised/expensed | B20: =Livestock!F10 -> 0 | C20: =Livestock!L10 -> 0 | D20: Notes Payable | E20: =Liabilities!B21-Liabilities!E21 -> 0 | F20: =Liabilities!C21-Liabilities!I21 -> 0
A21: Capitalized | B21: =Livestock!F11 -> 0 | C21: =Livestock!L11 -> 0 | D21: Non current portion-leases
A22: Leased | B22: =Livestock!F12 -> 0 | C22: =Livestock!L12 -> 0 | D22: Cattle | E22: =Leases!B12-Leases!E12 -> 0 | F22: =Leases!C12-Leases!I12 -> 0
A23: Heifers | B23: =Livestock!F19 -> 0 | C23: =Livestock!L19 -> 0 | D23: Machinery and equipment | E23: =Leases!B19-Leases!E19 -> 0 | F23: =Leases!C19-Leases!I19 -> 0
A24: Bull and other livestock | B24: =Livestock!F24 -> 0 | C24: =Livestock!L24 -> 0 | D24: Buildings | E24: =Leases!B26-Leases!E26 -> 0 | F24: =Leases!C26-Leases!I26 -> 0
A25: Machinery owned | B25: ='Machinery and Equipment'!D35 -> 0 | C25: ='Machinery and Equipment'!F35 -> 0 | D25: Real estate | E25: =Leases!B33-Leases!E33 -> 0 | F25: =Leases!C33-Leases!I33 -> 0
A26: leased | B26: =Assets!C10 -> 0 | C26: =Assets!E10 -> 0 | D26: Whole farm | E26: =Leases!B40-Leases!E40 -> 0 | F26: =Leases!C40-Leases!I40 -> 0
A27: Farm Credit stock | B27: =Assets!C14 -> 0 | C27: =Assets!E14 -> 0
A28: Other stocks & | D28: Total Non Current Liabilities | E28: =SUM(E20:E26) -> 0 | F28: =SUM(F20:F26) -> 0
A29: certificates | B29: =Assets!C15+Assets!C16+Assets!C35 -> 0 | C29: =Assets!E15+Assets!E16+Assets!E35 -> 0
A30: Buildings
A31: owned | B31: =Buildings!H24 -> 0 | C31: =Buildings!J24 -> 0
A32: leased | B32: =Assets!C11 -> 0 | C32: =Assets!E11 -> 0
A33: Real estate
A34: owned | B34: ='Real Estate'!H29 -> 0 | C34: ='Real Estate'!J29 -> 0
A35: leased | B35: =Assets!C12 -> 0 | C35: =Assets!E12 -> 0
A37: Total Non Current Assets | B37: =SUM(B20:B35) -> 0 | C37: =SUM(C20:C35) -> 0
A39: Total Dairy Assets | B39: =B16+B37 -> 0 | C39: =C16+C37 -> 0 | D39: Total Dairy Liabilities | E39: =E16+E28 -> 0 | F39: =F16+F28 -> 0
A41: Non-dairy assets | B41: =Assets!C17 -> 0 | C41: =Assets!E17 -> 0 | D41: Non-dairy liabilities and leases | E41: =Leases!B44+Liabilities!B44 -> 0 | F41: =Leases!C44+Liabilities!C44 -> 0
D43: Paid-in-capital | E43: =Assets!C27 -> 0 | F43: =Assets!E27 -> 0
D44: Net Worth | E44: =B47-E39-E41-E43 -> 0 | F44: =C47-F39-F41-F43 -> 0
D46: Total Liabilities &
A47: Total Assets | B47: =B16+B37+B41 -> 0 | C47: =C16+C37+C41 -> 0 | D47: Owners' Equity | E47: =SUM(E39:E44) -> 0 | F47: =SUM(F39:F44) -> 0

Sheet Income Statement
A1: ='Dairy Description'!A1 -> Key Code: | B1: Dairy Business Analysis Project
A2: Dairy Business Summary
A3: 2000
A5: Income Statement
A7: Revenues
A8: Cash Milk Sales | E8: =Income!B9 -> 0
A9: Cow Revenues: | B9: Cash Receipts | D9: =Income!B10 -> 0
B10: Change in Inventory | D10: =Income!C10 -> 0
B11: Gross Cow Revenues | E11: =D9+D10 -> 0
A12: Heifer and Calf Revenues: | B12: Cash Receipts | D12: =Income!B11 -> 0
B13: Change in Inventory | D13: =Income!C11 -> 0
B14: Gross Heifer and Calf Revenues | E14: =D12+D13 -> 0
A15: Other Livestock Revenues: | B15: Cash Receipts | D15: =Income!B12 -> 0
B16: Change in Inventory | D16: =Income!C12 -> 0
B17: Gross Livestock Revenues | E17: =D15+D16 -> 0
A18: Crop Revenues: | B18: Cash Receipts | D18: =Income!B13 -> 0
B19: Change in Inventory | D19: =Income!C13 -> 0
B20: Gross Crop Revenues | E20: =D18+D19 -> 0
A21: Government Receipts | E21: =Income!B14 -> 0
A22: Custom Work | E22: =Income!B15 -> 0
A23: Gas Tax Refund | E23: =Income!B16 -> 0
A24: Other Farm Income | E24: =(Income!B17+Income!B18+Income!B19+Income!B20+Income!B21)+Income!C17+Income!C18+Income!C19+Income!C20+Income!C21 -> 0
A25: Change in Accounts Receivable | E25: =Income!D22 -> 0
A26: Gain/Loss on Sale of Capital Livestock | E26: =Livestock!H41 -> 0
B28: Total Revenues | E28: =E8+E11+E14+E17+E20+E21+E22+E23+E24+E25+E26 -> 0
A30: Expenses
A31: Cash Operating Expenses:
B32: Personnel | C32: =Expenses!B11+Expenses!B12+Expenses!B13 -> 0
B33: Purchased Feed | C33: =Expenses!B15+Expenses!B16+Expenses!B17+Expenses!B18 -> 0
B34: Crops | C34: =Expenses!B20+Expenses!B21+Expenses!B22 -> 0
B35: Machinery | C35: =Expenses!B24+Expenses!B25+Expenses!B26 -> 0
B36: Livestock | C36: =Expenses!B28+Expenses!B29+Expenses!B30+Expenses!B31+Expenses!B32+Expenses!B33+Expenses!B34 -> 0
B37: Milk Marketing | C37: =Expenses!B36+Expenses!B37+Expenses!B38+Expenses!B39 -> 0
B38: Real Estate | C38: =Expenses!B41+Expenses!B42+Expenses!B43 -> 0
B39: Other | C39: =Expenses!B45+Expenses!B46+Expenses!B48+Expenses!B49 -> 0
B40: Total Cash Operating Expenses | D40: =SUM(C32:C39) -> 0
A41: Change in Inventory/Prepaid Expenses | D41: =Expenses!C50 -> 0
A42: Change in Accounts Payable | D42: =Expenses!D50 -> 0
A43: Depreciation Expense | D43: ='Machinery and Equipment'!D40+Buildings!H30+Livestock!F39 -> 0
B44: Total Operating Expenses | E44: =D40-D41+D42+D43 -> 0
...

Sheet Ratios
A1: ='Dairy Description'!A1 -> Key Code: | B1: Dairy Business Analysis Project
A2: Dairy Business Summary
A3: 2000
A4: Standard Financial Ratio Analysis
A6: Measure | C6: Computation | D6: Jan. 1 | E6: Dec. 31 | F6: Change
A7: Liquidity
A8: Current Ratio | B8: = | C8: Current Assets/Current Liabilities | D8: =IF(AND(SUM(Balance!E16)),(Balance!B16/Balance!E16),0) -> 0 | E8: =IF(AND(SUM(Balance!F16)),(Balance!C16/Balance!F16),0) -> 0 | F8: =E8-D8 -> 0
A11: Working Capital | B11: = | C11: Total Current Assets-Total Current Liabilities | D11: =Balance!B16-Balance!E16 -> 0 | E11: =Balance!C16-Balance!F16 -> 0 | F11: =E11-D11 -> 0
A14: Solvency
A15: Debt to Asset Ratio | B15: = | C15: Total Liabilities/Total Assets | D15: =IF(AND(SUM(Balance!B47)),((Balance!E39+Balance!E41)/Balance!B47),0) -> 0 | E15: =IF(AND(SUM(Balance!C47)),((Balance!F39+Balance!F41)/Balance!C47),0) -> 0 | F15: =E15-D15 -> 0
A18: Equity to Asset | B18: = | C18: Net Worth/Total Assets | D18: =IF(AND(SUM(Balance!B47)),((Balance!E44+Balance!E43)/Balance!B47),0) -> 0 | E18: =IF(AND(SUM(Balance!C47)),((Balance!F44+Balance!F43)/Balance!C47),0) -> 0 | F18: =E18-D18 -> 0
A19: Ratio
A21: Debt to Equity Ratio | B21: = | C21: Total Liabilities/Net Worth | D21: =IF(AND(SUM(Balance!E44)),((Balance!E39+Balance!E41)/(Balance!E44+Balance!E43)),0) -> 0 | E21: =IF(AND(SUM(Balance!F44)),((Balance!F39+Balance!F41)/(Balance!F44+Balance!F43)),0) -> 0 | F21: =E21-D21 -> 0
A24: Profitability
A25: Rate of Return on | B25: = | C25: (NFIFO*+ Interest - Unpaid Mgt.)/Average Total Assets | D25: N/A | E25: =IF(AND(SUM(Balance!C39)),(('Income Statement'!E48+Expenses!B47-50000)/((Balance!B39+Balance!C39)/2)),0) -> 0 | F25: N/A
A26: Dairy Assets (1) (2)
A28: Rate of Return on | B28: = | C28: (NFIFO* - Unpaid Mgt.)/Average Equity | D28: N/A | E28: =IF(AND(SUM(Balance!F44)),(('Income Statement'!E48-50000)/(((Balance!E44+Balance!E43)+(Balance!F44+Balance!F43))/2)),0) -> 0 | F28: N/A
A29: Farm Equity (1)
A31: Operating Profit | B31: = | C31: (NFIFO* + Interest - Unpaid Mgt.)/Gross Revenues | D31: N/A | E31: =IF(AND(SUM('Income Statement'!E28)),(('Income Statement'!E48+Expenses!E47-50000)/'Income Statement'!E28),0) -> 0 | F31: N/A
A32: Margin Ratio (1)
A34: Financial Efficiency
A35: Asset Turnover | B35: = | C35: Gross Revenues/Average Total Assets | D35: N/A | E35: =IF(AND(SUM(Balance!C39)),('Income Statement'!E28/((Balance!B39+Balance!C39)/2)),0) -> 0 | F35: N/A
A36: Ratio (2)
A38: Operating Expense | B38: = | C38: (Total Operating Expenses - Depreciation Expense)/ | D38: N/A | E38: =IF(AND(SUM('Income Statement'!E28)),(('Income Statement'!E44-'Income Statement'!D43)/'Income Statement'!E28),0) -> 0 | F38: N/A
A39: Ratio | C39: Gross Revenues
A41: Depreciation | B41: = | C41: Depreciation Expense/Gross Revenues | D41: N/A | E41: =IF(AND(SUM('Income Statement'!E28)),('Income Statement'!D43/'Income Statement'!E28),0) -> 0 | F41: N/A
A42: Expense Ratio
A44: Interest Expense | B44: = | C44: Total Farm Interest Expense/Gross Revenues | D44: N/A | E44: =IF(AND(SUM('Income Statement'!E28)),('Income Statement'!E45/'Income Statement'!E28),0) -> 0 | F44: N/A
A45: Ratio
A47: Net Farm Income | B47: = | C47: NFIFO*/Gross Revenues | D47: N/A | E47: =IF(AND(SUM('Income Statement'!E28)),('Income Statement'!E48/'Income Statement'!E28),0) -> 0 | F47: N/A
A48: From Operations
A49: Ratio
A53: (1) An estimate of $50,000 is used for the value of unpaid management.
