Workbook

Sheet Infrastructure Description
A1: Application Infrastructure Description
A2: Server Configuration | B2: Server Function | C2: Disk & Capacity Requirements | D2: # of Servers Needed | E2: Environment (check all that apply)
A3: Describe the software needed to run on the server and any configuration requirements needed for proper operation of the software. | B3: Describe the function or purpose of the server (e.g., http server, middle-tier application server, failover, etc., ) | C3: Identify disk and capacity requirements for the server. | D3: For the configuration and purpose described, indicate the estimated number of servers needed for optimum performance | E3: Development | F3: Acceptance | G3: Education | H3: Production

Sheet Software
C1: Software
A2: Software Component | B2: Description | C2: License Restriction / Usage Metrics | D2: Cost | E2: Other Expense | F2: Total Cost | G2: Annual Maintenance
F3: =SUM(D3:E3) -> 0
F4: =SUM(D4:E4) -> 0
F5: =SUM(D5:E5) -> 0
F6: =SUM(D6:E6) -> 0
F7: =SUM(D7:E7) -> 0
F8: =SUM(D8:E8) -> 0
F9: =SUM(D9:E9) -> 0
F10: =SUM(D10:E10) -> 0
F11: =SUM(D11:E11) -> 0
F12: =SUM(D12:E12) -> 0
A13: Total Software Costs | D13: =SUM(D3:D12) -> 0 | E13: =SUM(E3:E12) -> 0 | F13: =SUM(F3:F12) -> 0 | G13: =SUM(G3:G12) -> 0

Sheet Not to Exceed
B1: Not to Exceed (NTE) Costs
A2: Skillset | B2: NTE Hours Phase 1 | C2: NTE Hours Phase 2 | D2: NTE Hours Phase 3 | E2: Total Hours | F2: Hourly Rate(1) | G2: Total Cost | I2: Phase 1 Percentage of Hours (work area) | J2: Phase 2 Percentage of Hours (work area) | K2: Phase 3 Percentage of Hours (work area) | L2: <--- this area is optional and used as work space
A4: Engagement Partner | E4: =SUM(B4:D4) -> 0 | G4: =E4*F4 -> 0
A5: Project Manager | E5: =SUM(B5:D5) -> 0 | G5: =E5*F5 -> 0
A6: Technical Architect | E6: =SUM(B6:D6) -> 0 | G6: =E6*F6 -> 0
A7: Lead Business Analyst | E7: =SUM(B7:D7) -> 0 | G7: =E7*F7 -> 0
A8: Business Analyst | E8: =SUM(B8:D8) -> 0 | G8: =E8*F8 -> 0
A9: Software Specialist | E9: =SUM(B9:D9) -> 0 | G9: =E9*F9 -> 0
A10: Product Quality Assurance Specialist | E10: =SUM(B10:D10) -> 0 | G10: =E10*F10 -> 0
A11: Process Audit Specialist | E11: =SUM(B11:D11) -> 0 | G11: =E11*F11 -> 0
A12: Training Specialist | E12: =SUM(B12:D12) -> 0 | G12: =E12*F12 -> 0
A13: Other: | E13: =SUM(B13:D13) -> 0 | G13: =E13*F13 -> 0
E14: =SUM(B14:D14) -> 0 | G14: =E14*F14 -> 0
E15: =SUM(B15:D15) -> 0 | G15: =E15*F15 -> 0
E16: =SUM(B16:D16) -> 0 | G16: =E16*F16 -> 0
A17: Total Hours: | B17: =SUM(B4:B15) -> 0 | E17: =SUM(E3:E16) -> 0 | G17: =SUM(G3:G16) -> 0 | I17: =SUM(I4:I16) -> 0 | J17: =SUM(J4:J16) -> 0 | K17: =SUM(K4:K16) -> 0
A19: Deliverable | B19: Total NTE Hours | C19: Integrator Percentage | D19: Integrator Hours | E19: DWD Hours
A20: Phase 1 – Planning
A21: Project Planning
A22: Create Project Plans | C22: 0.5 | D22: =B22*C22 -> 0 | E22: =B22*(1-C22) -> 0
A23: Project Office Documentation | C23: 0.5 | D23: =B23*C23 -> 0 | E23: =B23*(1-C23) -> 0
A24: Communications Plan | C24: 0 | D24: =B24*C24 -> 0 | E24: =B24*(1-C24) -> 0
A25: Risk Management Plan | C25: 0.5 | D25: =B25*C25 -> 0 | E25: =B25*(1-C25) -> 0
A26: Process Audit Plan | C26: 0.75 | D26: =B26*C26 -> 0 | E26: =B26*(1-C26) -> 0
A27: Acceptance Plan | C27: 0.5 | D27: =B27*C27 -> 0 | E27: =B27*(1-C27) -> 0
A28: Change Control Plan | C28: 0 | D28: =B28*C28 -> 0 | E28: =B28*(1-C28) -> 0
A29: Installation Planning
A30: Infrastructure Design Plan | C30: 0.4 | D30: =B30*C30 -> 0 | E30: =B30*(1-C30) -> 0
A31: Installation, Configuration, and Testing of the Software Plan | C31: 0.5 | D31: =B31*C31 -> 0 | E31: =B31*(1-C31) -> 0
A32: Knowledge Transfer / Staff Training Plan | C32: 0.5 | D32: =B32*C32 -> 0 | E32: =B32*(1-C32) -> 0
A33: Configuration Management Plan | C33: 0.5 | D33: =B33*C33 -> 0 | E33: =B33*(1-C33) -> 0
A34: Environmental Documentation | C34: 0.5 | D34: =B34*C34 -> 0 | E34: =B34*(1-C34) -> 0
A35: Database Conversion Plan | C35: 0.4 | D35: =B35*C35 -> 0 | E35: =B35*(1-C35) -> 0
A37: Phase 1 Totals | B37: =SUM(B22:B36) -> 0 | D37: =SUM(D22:D36) -> 0 | E37: =SUM(E22:E36) -> 0
A39: Phase 2 – System Enhancement Analysis
A40: Definition of System Enhancements (Gap Analysis) | C40: 0.5 | D40: =B40*C40 -> 0 | E40: =B40*(1-C40) -> 0
A41: Prioritization of Enhancements | C41: 0.1 | D41: =B41*C41 -> 0 | E41: =B41*(1-C41) -> 0
A42: Creation of the Enhancement Project Plan | C42: 0.5 | D42: =B42*C42 -> 0 | E42: =B42*(1-C42) -> 0
A43: Interface / Integration Design Analysis | C43: 0.6 | D43: =B43*C43 -> 0 | E43: =B43*(1-C43) -> 0
A44: Database Conversion Analysis | C44: 0.4 | D44: =B44*C44 -> 0 | E44: =B44*(1-C44) -> 0
...

Sheet Technical Support Staffing
A1: Technical Support Staffing Recommendations
A2: Provide an estimate for the staffing required for the installation, operational administration and infrastructure support of your proposed solution. Detail by skillset (eg. database administrator, system administrator, application support specialist, etc.). Vendors selected as candidates for the final round of this RFP process will be asked at that time to validate those estimates with a proposal from a third-party Application Service Provider if the proposed solution involves a development and runtime environment other than Microsoft (Visual Studio and/or .NET) or IBM WebSphere.
B4: Estimated Staff Time (Indicate in Percentage)
A5: Skillset | B5: Startup | C5: Annual
A13: Total technical support

Sheet Training
A1: Training Recommendations
A2: Provide an estimate of training required for the installation, operational administration, infrastructure support, application development and user training of your proposed solution. Detail by skillset (eg. database administrator, system administrator, analyst, developer, etc.).
E3: Training Supplied by: | H3: Estimated cost for training supplied by DWD for Non-standard toolsets**
A4: Skillset | B4: Training Description | C4: Training Hours | D4: Training Location | E4: Vendor* | F4: DWD | G4: Third Party
A8: Total technical support training | C8: =SUM(C5:C7) -> 0
A12: Total application development training | C12: =SUM(C9:C11) -> 0
A16: Total user training | C16: =SUM(C13:C15) -> 0
A20: *Costs associated with training that is provided by the vendor should be included as a "Not to Exceed" Cost
A21: **Training cost for DWD standard environments will be estimated by DWD

Sheet Customization & Implementation
B1: Phase 4 - Customization and Implementation Time and Cost Estimates
A2: Deliverable | B2: Total Estimated Hours | C2: Integrator Percentage | D2: Integrator Hours | E2: DWD Hours
D4: =B4*C4 -> 0 | E4: =B4*(1-C4) -> 0
D5: =B5*C5 -> 0 | E5: =B5*(1-C5) -> 0
D6: =B6*C6 -> 0 | E6: =B6*(1-C6) -> 0
D7: =B7*C7 -> 0 | E7: =B7*(1-C7) -> 0
D8: =B8*C8 -> 0 | E8: =B8*(1-C8) -> 0
D9: =B9*C9 -> 0 | E9: =B9*(1-C9) -> 0
D10: =B10*C10 -> 0 | E10: =B10*(1-C10) -> 0
D11: =B11*C11 -> 0 | E11: =B11*(1-C11) -> 0
D12: =B12*C12 -> 0 | E12: =B12*(1-C12) -> 0
D13: =B13*C13 -> 0 | E13: =B13*(1-C13) -> 0
D14: =B14*C14 -> 0 | E14: =B14*(1-C14) -> 0
D15: =B15*C15 -> 0 | E15: =B15*(1-C15) -> 0
... D21: =B21*C21 -> 0 | E21: =B21*(1-C21) -> 0
A24: Total Estimated Hours: | B24: =SUM(B4:B22) -> 0 | D24: =SUM(D4:D22) -> 0 | E24: =SUM(E4:E22) -> 0
A26: Integrator Skillset | B26: Estimated Hours through Implementation | C26: Rate | D26: Estimated Costs
A28: Engagement Partner | D28: =B28*C28 -> 0
A29: Project Manager | D29: =B29*C29 -> 0
A30: Technical Architect | D30: =B30*C30 -> 0
A31: Lead Business Analyst | D31: =B31*C31 -> 0
A32: Business Analyst | D32: =B32*C32 -> 0
A33: Software Specialist | D33: =B33*C33 -> 0
A34: Product Quality Assurance Specialist | D34: =B34*C34 -> 0
A35: Process Audit Specialist | D35: =B35*C35 -> 0
A36: Training Specialist | D36: =B36*C36 -> 0
A37: Other: | D37: =B37*C37 -> 0
D38: =B38*C38 -> 0
D39: =B39*C39 -> 0
D40: =B40*C40 -> 0
A41: Total Estimated Hours and Costs: | B41: =SUM(B28:B39) -> 0 | D41: =SUM(D28:D39) -> 0
A43: DWD Skillset (anticipated - please estimate) | B43: Estimated Hours through Implementation | C43: Rate* | D43: Estimated Costs
D45: =B45*C45 -> 0
D46: =B46*C46 -> 0
D47: =B47*C47 -> 0
D48: =B48*C48 -> 0
D49: =B49*C49 -> 0
D50: =B50*C50 -> 0
D51: =B51*C51 -> 0
D52: =B52*C52 -> 0
...

Sheet Total Costs 
B1: To Be Completed by DWD
A2: Integrator Costs
A3: Phase 1 | B3: ='Not to Exceed'!B4*'Not to Exceed'!F4+'Not to Exceed'!B5*'Not to Exceed'!F5+'Not to Exceed'!B6*'Not to Exceed'!F6+'Not to Exceed'!B7*'Not to Exceed'!F7+'Not to Exceed'!B8*'Not to Exceed'!F8+'Not to Exceed'!B9*'Not to Exceed'!F9+'Not to Exceed'!B10*'Not to Exceed'!F10+'Not to Exceed'!B11*'Not to Exceed'!F11+'Not to Exceed'!B12*'Not to Exceed'!F12 -> 0
A4: Phase 2 | B4: ='Not to Exceed'!C4*'Not to Exceed'!F4+'Not to Exceed'!C5*'Not to Exceed'!F5+'Not to Exceed'!C6*'Not to Exceed'!F6+'Not to Exceed'!C7*'Not to Exceed'!F7+'Not to Exceed'!C8*'Not to Exceed'!F8+'Not to Exceed'!C9*'Not to Exceed'!F9+'Not to Exceed'!C10*'Not to Exceed'!F10+'Not to Exceed'!C11*'Not to Exceed'!F11+'Not to Exceed'!C12*'Not to Exceed'!F12 -> 0
A5: Phase 3 | B5: ='Not to Exceed'!D4*'Not to Exceed'!F4+'Not to Exceed'!D5*'Not to Exceed'!F5+'Not to Exceed'!D6*'Not to Exceed'!F6+'Not to Exceed'!D7*'Not to Exceed'!F7+'Not to Exceed'!D8*'Not to Exceed'!F8+'Not to Exceed'!D9*'Not to Exceed'!F9+'Not to Exceed'!D10*'Not to Exceed'!F10+'Not to Exceed'!D11*'Not to Exceed'!F11+'Not to Exceed'!D12*'Not to Exceed'!F12 -> 0
A6: Phase 4 | B6: ='Customization & Implementation'!D41 -> 0
B7: =SUM(B2:B6) -> 0
A9: Software Costs | B9: =Software!F13 -> 0
A11: Infrastructure | B11: =#REF! -> #REF!
A13: DWD
B14: ='Customization & Implementation'!D46 -> 0
B15: ='Customization & Implementation'!D45 -> 0
B17: =SUM(B3:B15) -> #REF!
