Workbook
Name \0: Results!#REF!
Name \m: Results!#REF!
Name FORM: Results!#REF!
Name FORM1: 'Input Forms'!$A$1:$G$40
Name FORM2: 'Input Forms'!$A$41:$G$81
Name FORM3: 'Input Forms'!$A$83:$G$133
Name INPUT1A: Inputs!$A$1:$G$40
Name INPUT1B: Inputs!$A$41:$G$81
Name INPUTS: Results!#REF!
Name MENU: Results!#REF!
Name PRINT: Results!#REF!
Name Print_Area_MI: Percentages!$A$1:$H$51
Name RESULTS: Results!$A$1:$H$48
Name TABLE1: Percentages!$A$1:$H$51

Sheet Results
A1: Cost of Production per Equivalent Unit Produced | S1: Actual Dollars to ...
E2: T.D.M. = Tons Dry Matter | P2: Item: | Q2: =Inputs!$E$4 -> Milk | S2: =Inputs!$E$6 -> Corn | T2: =Inputs!$E$7 -> Corn Silage | U2: =Inputs!$E$8 -> Haylage | V2: =Inputs!$E$9 -> Hay | W2: =Inputs!$E$10 -> Other
A3: Unit Name: | B3: CWT EQ | C3: Head | D3: =Inputs!D57 -> Bushels | E3: =IF(Inputs!B29="tons","T.D.M.","unknown") -> T.D.M. | F3: =IF(Inputs!B30="tons","T.D.M.","unknown") -> T.D.M. | G3: =IF(Inputs!B31="tons","T.D.M.","unknown") -> T.D.M. | H3: =IF(Inputs!B32="tons","T.D.M.","unknown") -> T.D.M. | P3: Breeding Fees | Q3: =Inputs!$B66*Percentages!C3 -> 10398 | R3: =Inputs!$B66*Percentages!D3 -> 3466 | S3: =Inputs!$B66*Percentages!E3 -> 0 | T3: =Inputs!$B66*Percentages!F3 -> 0 | U3: =Inputs!$B66*Percentages!G3 -> 0 | V3: =Inputs!$B66*Percentages!H3 -> 0 | W3: =Inputs!$B66*Percentages!I3 -> 0 | Y3: =Inputs!C12 -> 0.085 | Z3: (interest only)
A4: Number Produced: | B4: =(Inputs!B43+Inputs!B44+Inputs!B45+Inputs!D46+Inputs!B54+Inputs!B23*Inputs!F38/2)/Inputs!F43 -> 89676.444 | C4: =Inputs!E36+Inputs!C54/Inputs!F39 -> 120 | D4: =Inputs!$C28*Inputs!$B$23+Inputs!$D28*Inputs!$C$24+Inputs!D58+Inputs!D59+Inputs!D54/Inputs!E28 -> 33526.4 | E4: =(Inputs!$C29*Inputs!$B$23+Inputs!$D29*Inputs!$C$24+Inputs!E58+Inputs!E59+Inputs!E54/Inputs!E29)*(1-Inputs!C38) -> 947.94 | F4: =(Inputs!$C30*Inputs!$B$23+Inputs!$D30*Inputs!$C$24+Inputs!F58+Inputs!F59+Inputs!F54/Inputs!E30)*(1-Inputs!C37) -> 1127.88 | G4: =(Inputs!$C31*Inputs!$B$23+Inputs!$D31*Inputs!$C$24+Inputs!G58+Inputs!G59+Inputs!G54/Inputs!E31)*(1-0.12) -> 476.96 | H4: =(Inputs!$C32*Inputs!$B$23+Inputs!$D32*Inputs!$C$24+Inputs!H58+Inputs!H59+Inputs!H54/Inputs!E32)*(1-Inputs!C39) -> 100 | P4: Car & Truck Expense | Q4: =Inputs!$B67*Percentages!C4 -> 334.8 | R4: =Inputs!$B67*Percentages!D4 -> 167.4 | S4: =Inputs!$B67*Percentages!E4 -> 585.9 | T4: =Inputs!$B67*Percentages!F4 -> 251.1 | U4: =Inputs!$B67*Percentages!G4 -> 301.32 | V4: =Inputs!$B67*Percentages!H4 -> 33.48 | W4: =Inputs!$B67*Percentages!I4 -> 0 | Y4: =Inputs!C12+1/10 -> 0.185
P5: Chemicals | Q5: =Inputs!$B68*Percentages!C5 -> 0 | R5: =Inputs!$B68*Percentages!D5 -> 0 | S5: =Inputs!$B68*Percentages!E5 -> 4501 | T5: =Inputs!$B68*Percentages!F5 -> 1929 | U5: =Inputs!$B68*Percentages!G5 -> 0 | V5: =Inputs!$B68*Percentages!H5 -> 0 | W5: =Inputs!$B68*Percentages!I5 -> 0 | Y5: =Inputs!C12+1/15 -> 0.15166667
A6: Enterprise: | B6: =Inputs!$E$4 -> Milk | C6: =Inputs!$E$5 -> Heifers | D6: =Inputs!$E$6 -> Corn | E6: =Inputs!$E$7 -> Corn Silage | F6: =Inputs!$E$8 -> Haylage | G6: =Inputs!$E$9 -> Hay | H6: =Inputs!$E$10 -> Other | P6: Conservation Expense | Q6: =Inputs!$B69*Percentages!C6 -> 0 | R6: =Inputs!$B69*Percentages!D6 -> 0 | S6: =Inputs!$B69*Percentages!E6 -> 0 | T6: =Inputs!$B69*Percentages!F6 -> 0 | U6: =Inputs!$B69*Percentages!G6 -> 0 | V6: =Inputs!$B69*Percentages!H6 -> 0 | W6: =Inputs!$B69*Percentages!I6 -> 0 | Y6: =Inputs!C12+1/20 -> 0.135
P7: Custom Hire | Q7: =Inputs!$B70*Percentages!C7 -> 0 | R7: =Inputs!$B70*Percentages!D7 -> 0 | S7: =Inputs!$B70*Percentages!E7 -> 26543 | T7: =Inputs!$B70*Percentages!F7 -> 0 | U7: =Inputs!$B70*Percentages!G7 -> 0 | V7: =Inputs!$B70*Percentages!H7 -> 0 | W7: =Inputs!$B70*Percentages!I7 -> 0 | Y7: =Inputs!C12-0.04 -> 0.045
A8: Total Costs | B8: =SUM(B14:B32) -> 12.140823 | C8: =SUM(C14:C32) -> 1199.508 | D8: =SUM(D14:D32) -> 2.1993492 | E8: =SUM(E14:E32) -> 49.853908 | F8: =SUM(F14:F32) -> 87.842868 | G8: =SUM(G14:G32) -> 24.779174 | H8: =SUM(H14:H32) -> 0
A9: (includes opportunity cost of capital and unpaid labor and management) | P9: Depreciation | Q9: =Inputs!$B71*Percentages!C9 -> 24860.4 | R9: =Inputs!$B71*Percentages!D9 -> 6215.1 | S9: =Inputs!$B71*Percentages!E9 -> 6215.1 | T9: =Inputs!$B71*Percentages!F9 -> 7768.875 | U9: =Inputs!$B71*Percentages!G9 -> 15537.75 | V9: =Inputs!$B71*Percentages!H9 -> 1553.775 | W9: =Inputs!$B71*Percentages!I9 -> 0
A10: Price charged to the dairy | B10: (per unit) | C10: =Inputs!F39 -> 1200 | D10: =Inputs!E28 -> 2.5 | E10: =Inputs!E29/(1-Inputs!C38) -> 57.142857 | F10: =Inputs!E30/(1-Inputs!C37) -> 100 | G10: =Inputs!E31/(1-0.12) -> 96.590909 | H10: =Inputs!E32/(1-Inputs!C39) -> 1 | P10: Employee Benefit Programs | Q10: =Inputs!$B72*Percentages!C10 -> 20967.7 | R10: =Inputs!$B72*Percentages!D10 -> 1612.9 | S10: =Inputs!$B72*Percentages!E10 -> 1290.32 | T10: =Inputs!$B72*Percentages!F10 -> 1935.48 | U10: =Inputs!$B72*Percentages!G10 -> 5806.44 | V10: =Inputs!$B72*Percentages!H10 -> 645.16 | W10: =Inputs!$B72*Percentages!I10 -> 0
O11: =Inputs!D60*Inputs!E28+Inputs!E60*Inputs!E29+Inputs!F60*Inputs!E30+Inputs!G60*Inputs!E31+Inputs!E32+Inputs!E61 -> -8099 | P11: Feed Purchased | Q11: =(Inputs!$B$73-$O$11)*Percentages!C11 -> 335977 | R11: =(Inputs!$B$73-$O$11)*Percentages!D11 -> 17683 | S11: =(Inputs!$B$73-$O$11)*Percentages!E11 -> 0 | T11: =(Inputs!$B$73-$O$11)*Percentages!F11 -> 0 | U11: =(Inputs!$B$73-$O$11)*Percentages!G11 -> 0 | V11: =(Inputs!$B$73-$O$11)*Percentages!H11 -> 0 | W11: =(Inputs!$B$73-$O$11)*Percentages!I11 -> 0
B12: Detailed Costs of Production per Unit | P12: Fertilizer | Q12: =Inputs!$B74*Percentages!C12 -> 0 | R12: =Inputs!$B74*Percentages!D12 -> 0 | S12: =Inputs!$B74*Percentages!E12 -> 2922.4 | T12: =Inputs!$B74*Percentages!F12 -> 1095.9 | U12: =Inputs!$B74*Percentages!G12 -> 3287.7 | V12: =Inputs!$B74*Percentages!H12 -> 0 | W12: =Inputs!$B74*Percentages!I12 -> 0
A13: Enterprise: | B13: =Inputs!$E$4 -> Milk | C13: Heifers | D13: =Inputs!$E$6 -> Corn | E13: =Inputs!$E$7 -> Corn Silage | F13: =Inputs!$E$8 -> Haylage | G13: =Inputs!$E$9 -> Hay | H13: =Inputs!$E$10 -> Other | P13: Freight | Q13: =Inputs!$B75*Percentages!C13 -> 1440 | R13: =Inputs!$B75*Percentages!D13 -> 0 | S13: =Inputs!$B75*Percentages!E13 -> 0 | T13: =Inputs!$B75*Percentages!F13 -> 0 | U13: =Inputs!$B75*Percentages!G13 -> 0 | V13: =Inputs!$B75*Percentages!H13 -> 0 | W13: =Inputs!$B75*Percentages!I13 -> 0
A14: Chemicals | B14: =Q5/B4 -> 0 | C14: =R5/C4 -> 0 | D14: =S5/D4 -> 0.13425241 | E14: =T5/E4 -> 2.0349389 | F14: =U5/F4 -> 0 | G14: =V5/G4 -> 0 | H14: =W5/H4 -> 0
A15: Custom Hire | B15: =Q7/B4 -> 0 | C15: =R7/C4 -> 0 | D15: =S7/D4 -> 0.79170445 | E15: =T7/E4 -> 0 | F15: =U7/F4 -> 0 | G15: =V7/G4 -> 0 | H15: =W7/H4 -> 0 | P15: Gasoline, Fuel | Q15: =Inputs!$B76*Percentages!C15 -> 917.64 | R15: =Inputs!$B76*Percentages!D15 -> 101.96 | S15: =Inputs!$B76*Percentages!E15 -> 1529.4 | T15: =Inputs!$B76*Percentages!F15 -> 2039.2 | U15: =Inputs!$B76*Percentages!G15 -> 5098 | V15: =Inputs!$B76*Percentages!H15 -> 509.8 | W15: =Inputs!$B76*Percentages!I15 -> 0
A16: Fertilizer | B16: =Q12/B4 -> 0 | C16: =R12/C4 -> 0 | D16: =S12/D4 -> 0.087167128 | E16: =T12/E4 -> 1.1560858 | F16: =U12/F4 -> 2.9149378 | G16: =V12/G4 -> 0 | H16: =W12/H4 -> 0 | P16: Insurance | Q16: =Inputs!$B77*Percentages!C16 -> 6266.4 | R16: =Inputs!$B77*Percentages!D16 -> 447.6 | S16: =Inputs!$B77*Percentages!E16 -> 1253.28 | T16: =Inputs!$B77*Percentages!F16 -> 537.12 | U16: =Inputs!$B77*Percentages!G16 -> 447.6 | V16: =Inputs!$B77*Percentages!H16 -> 0 | W16: =Inputs!$B77*Percentages!I16 -> 0
A17: Fuel & Utilities + Car & Truck Exp | B17: =(Q4+Q15+Q30)/B4 -> 0.14473411 | C17: =(R4+R15+R30)/C4 -> 4.302 | D17: =(S4+S15+S30)/D4 -> 0.066775437 | E17: =(T4+T15+T30)/E4 -> 2.5463004 | F17: =(U4+U15+U30)/F4 -> 4.8965847 | G17: =(V4+V15+V30)/G4 -> 1.1390473 | H17: =(W4+W15+W30)/H4 -> 0 | P17: Interest - Mortgage | Q17: =Inputs!$B78*Percentages!C17 -> 14688 | R17: =Inputs!$B78*Percentages!D17 -> 1632 | S17: =Inputs!$B78*Percentages!E17 -> 4080 | T17: =Inputs!$B78*Percentages!F17 -> 4080 | U17: =Inputs!$B78*Percentages!G17 -> 7344 | V17: =Inputs!$B78*Percentages!H17 -> 816 | W17: =Inputs!$B78*Percentages!I17 -> 0
A18: Repairs & Maintenance | B18: =Q24/B4 -> 0.16338293 | C18: =R24/C4 -> 15.262083 | D18: =S24/D4 -> 0.1092542 | E18: =T24/E4 -> 5.7960947 | F18: =U24/F4 -> 8.7685126 | G18: =V24/G4 -> 2.3039039 | H18: =W24/H4 -> 0 | P18: Interest - Other | Q18: =Inputs!$B79*Percentages!C18 -> 14871.15 | R18: =Inputs!$B79*Percentages!D18 -> 1652.35 | S18: =Inputs!$B79*Percentages!E18 -> 4130.875 | T18: =Inputs!$B79*Percentages!F18 -> 4130.875 | U18: =Inputs!$B79*Percentages!G18 -> 7435.575 | V18: =Inputs!$B79*Percentages!H18 -> 826.175 | W18: =Inputs!$B79*Percentages!I18 -> 0
A19: Plants & Seeds | B19: =Q25/B4 -> 0 | C19: =R25/C4 -> 0 | D19: =S25/D4 -> 0.10391811 | E19: =T25/E4 -> 1.8376691 | F19: =U25/F4 -> 1.3900415 | G19: =V25/G4 -> 0.36522979 | H19: =W25/H4 -> 0 | P19: Labor Hired | Q19: =Inputs!$B80*Percentages!C19 -> 151732.75 | R19: =Inputs!$B80*Percentages!D19 -> 11671.75 | S19: =Inputs!$B80*Percentages!E19 -> 9337.4 | T19: =Inputs!$B80*Percentages!F19 -> 14006.1 | U19: =Inputs!$B80*Percentages!G19 -> 42018.3 | V19: =Inputs!$B80*Percentages!H19 -> 4668.7 | W19: =Inputs!$B80*Percentages!I19 -> 0
A20: Property Taxes | B20: =Q29/B4 -> 0.01746278 | C20: =R29/C4 -> 0.45 | D20: =S29/D4 -> 0.03221342 | E20: =T29/E4 -> 0.56965631 | F20: =U29/F4 -> 1.7235876 | G20: =V29/G4 -> 0.45286817 | H20: =W29/H4 -> 0
A21: Rent | B21: =(Q22+Q23)/B4 -> 0.088211125 | C21: =(R22+R23)/C4 -> 3.4695 | D21: =(S22+S23)/D4 -> 0.12138196 | E21: =(T22+T23)/E4 -> 2.1960251 | F21: =(U22+U23)/F4 -> 0 | G21: =(V22+V23)/G4 -> 0 | H21: =(W22+W23)/H4 -> 0 | P21: Pension & Profit Sharing | Q21: =Inputs!$B81*Percentages!C21 -> 3900 | R21: =Inputs!$B81*Percentages!D21 -> 300 | S21: =Inputs!$B81*Percentages!E21 -> 300 | T21: =Inputs!$B81*Percentages!F21 -> 360 | U21: =Inputs!$B81*Percentages!G21 -> 1080 | V21: =Inputs!$B81*Percentages!H21 -> 60 | W21: =Inputs!$B81*Percentages!I21 -> 0
A22: Supplies Purchased | B22: =Q28/B4 -> 0.28116815 | C22: =R28/C4 -> 4.5186667 | D22: =S28/D4 -> 0 | E22: =T28/E4 -> 0 | F22: =U28/F4 -> 0 | G22: =V28/G4 -> 2.8421671 | H22: =W28/H4 -> 0 | P22: Rent - equipment | Q22: =Inputs!$F65*Percentages!C22 -> 0 | R22: =Inputs!$F65*Percentages!D22 -> 0 | S22: =Inputs!$F65*Percentages!E22 -> 600 | T22: =Inputs!$F65*Percentages!F22 -> 0 | U22: =Inputs!$F65*Percentages!G22 -> 0 | V22: =Inputs!$F65*Percentages!H22 -> 0 | W22: =Inputs!$F65*Percentages!I22 -> 0
A23: Veterinary & Breeding | B23: =(Q3+Q31)/B4 -> 0.37116771 | C23: =(R3+R31)/C4 -> 50.075 | D23: =(S3+S31)/D4 -> 0 | E23: =(T3+T31)/E4 -> 0 | F23: =(U3+U31)/F4 -> 0 | G23: =(V3+V31)/G4 -> 0 | H23: =(W3+W31)/H4 -> 0 | P23: Rent - other | Q23: =Inputs!$F66*Percentages!C23 -> 7910.46 | R23: =Inputs!$F66*Percentages!D23 -> 416.34 | S23: =Inputs!$F66*Percentages!E23 -> 3469.5 | T23: =Inputs!$F66*Percentages!F23 -> 2081.7 | U23: =Inputs!$F66*Percentages!G23 -> 0 | V23: =Inputs!$F66*Percentages!H23 -> 0 | W23: =Inputs!$F66*Percentages!I23 -> 0
A24: Other Variable Cost | B24: =(SUM(Q3:Q36)-Q3-Q4-Q5-Q7-Q9-Q10-Q11-Q12-Q15-Q17-Q18-Q19-Q21-Q22-Q23-Q24-Q25-Q28-Q29-Q30-Q31-Q37+Q38)/B4 -> 0.47124304 | C24: =(SUM(R3:R36)-R3-R4-R5-R7-R9-R10-R11-R12-R15-R17-R18-R19-R21-R22-R23-R24-R25-R28-R29-R30-R31-R37+R38)/C4 -> 3.73 | D24: =(SUM(S3:S36)-S3-S4-S5-S7-S9-S10-S11-S12-S15-S17-S18-S19-S21-S22-S23-S24-S25-S28-S29-S30-S31-S37+S38)/D4 -> 0.037381884 | E24: =(SUM(T3:T36)-T3-T4-T5-T7-T9-T10-T11-T12-T15-T17-T18-T19-T21-T22-T23-T24-T25-T28-T29-T30-T31-T37+T38)/E4 -> 0.56661814 | F24: =(SUM(U3:U36)-U3-U4-U5-U7-U9-U10-U11-U12-U15-U17-U18-U19-U21-U22-U23-U24-U25-U28-U29-U30-U31-U37+U38)/F4 -> 0.39685073 | G24: =(SUM(V3:V36)-V3-V4-V5-V7-V9-V10-V11-V12-V15-V17-V18-V19-V21-V22-V23-V24-V25-V28-V29-V30-V31-V37+V38)/G4 -> 3.8137148e-15 | H24: =(SUM(W3:W36)-W3-W4-W5-W7-W9-W10-W11-W12-W15-W17-W18-W19-W21-W22-W23-W24-W25-W28-W29-W30-W31-W37+W38)/H4 -> 0 | P24: Repairs and Maintenance | Q24: =Inputs!$F67*Percentages!C24 -> 14651.6 | R24: =Inputs!$F67*Percentages!D24 -> 1831.45 | S24: =Inputs!$F67*Percentages!E24 -> 3662.9 | T24: =Inputs!$F67*Percentages!F24 -> 5494.35 | U24: =Inputs!$F67*Percentages!G24 -> 9889.83 | V24: =Inputs!$F67*Percentages!H24 -> 1098.87 | W24: =Inputs!$F67*Percentages!I24 -> 0
A25: Purchased Feed | B25: =Q11/B4 -> 3.7465469 | C25: =R11/C4 -> 147.35833 | D25: =S11/D4 -> 0 | E25: =T11/E4 -> 0 | F25: =U11/F4 -> 0 | G25: =V11/G4 -> 0 | H25: =W11/H4 -> 0 | P25: Seed & Plants Purchased | Q25: =Inputs!$F68*Percentages!C25 -> 0 | R25: =Inputs!$F68*Percentages!D25 -> 0 | S25: =Inputs!$F68*Percentages!E25 -> 3484 | T25: =Inputs!$F68*Percentages!F25 -> 1742 | U25: =Inputs!$F68*Percentages!G25 -> 1567.8 | V25: =Inputs!$F68*Percentages!H25 -> 174.2 | W25: =Inputs!$F68*Percentages!I25 -> 0
A26: Home Grown Feeds | B26: =Q51/B4 -> 1.9871808 | C26: =R51/C4 -> 552.38913 | D26: =S51/D4 -> 0 | E26: =T51/E4 -> 0 | F26: =U51/F4 -> 0 | G26: =V51/G4 -> 0 | H26: =W51/H4 -> 0
A27: Hired Labor Costs | B27: =(Q10+Q19+Q21)/B4 -> 1.969307 | C27: =(R10+R19+R21)/C4 -> 113.20542 | D27: =(S10+S19+S21)/D4 -> 0.32594373 | E27: =(T10+T19+T21)/E4 -> 17.196848 | F27: =(U10+U19+U21)/F4 -> 43.359879 | G27: =(V10+V19+V21)/G4 -> 11.266899 | H27: =(W10+W19+W21)/H4 -> 0 | P27: Storage & Warehousing | Q27: =Inputs!$F69*Percentages!C27 -> 0 | R27: =Inputs!$F69*Percentages!D27 -> 0 | S27: =Inputs!$F69*Percentages!E27 -> 0 | T27: =Inputs!$F69*Percentages!F27 -> 0 | U27: =Inputs!$F69*Percentages!G27 -> 0 | V27: =Inputs!$F69*Percentages!H27 -> 0 | W27: =Inputs!$F69*Percentages!I27 -> 0
A28: Unpaid Labor & Management | B28: =(Q49+Q50)/B4 -> 0.1087242 | C28: =(R49+R50)/C4 -> 6.25 | D28: =(S49+S50)/D4 -> 0.02237043 | E28: =(T49+T50)/E4 -> 0.79118932 | F28: =(U49+U50)/F4 -> 2.3938717 | G28: =(V49+V50)/G4 -> 0.62898356 | H28: =(W49+W50)/H4 -> 0 | P28: Supplies Purchased | Q28: =Inputs!$F70*Percentages!C28 -> 25214.16 | R28: =Inputs!$F70*Percentages!D28 -> 542.24 | S28: =Inputs!$F70*Percentages!E28 -> 0 | T28: =Inputs!$F70*Percentages!F28 -> 0 | U28: =Inputs!$F70*Percentages!G28 -> 0 | V28: =Inputs!$F70*Percentages!H28 -> 1355.6 | W28: =Inputs!$F70*Percentages!I28 -> 0
A29: Internal Animal Purchases | B29: =(C4*Inputs!F39)/B4 -> 1.6057729 | C29: =Inputs!F38*Inputs!B23/2/C4 -> 137.5 | P29: Taxes | Q29: =Inputs!$F71*Percentages!C29 -> 1566 | R29: =Inputs!$F71*Percentages!D29 -> 54 | S29: =Inputs!$F71*Percentages!E29 -> 1080 | T29: =Inputs!$F71*Percentages!F29 -> 540 | U29: =Inputs!$F71*Percentages!G29 -> 1944 | V29: =Inputs!$F71*Percentages!H29 -> 216 | W29: =Inputs!$F71*Percentages!I29 -> 0
P30: Utilities | Q30: =Inputs!$F72*Percentages!C30 -> 11726.8 | R30: =Inputs!$F72*Percentages!D30 -> 246.88 | S30: =Inputs!$F72*Percentages!E30 -> 123.44 | T30: =Inputs!$F72*Percentages!F30 -> 123.44 | U30: =Inputs!$F72*Percentages!G30 -> 123.44 | V30: =Inputs!$F72*Percentages!H30 -> 0 | W30: =Inputs!$F72*Percentages!I30 -> 0
B31: Cost of Capital per Unit of Production | P31: Veterinary | Q31: =Inputs!$F73*Percentages!C31 -> 22887 | R31: =Inputs!$F73*Percentages!D31 -> 2543 | S31: =Inputs!$F73*Percentages!E31 -> 0 | T31: =Inputs!$F73*Percentages!F31 -> 0 | U31: =Inputs!$F73*Percentages!G31 -> 0 | V31: =Inputs!$F73*Percentages!H31 -> 0 | W31: =Inputs!$F73*Percentages!I31 -> 0
A32: Opportunity Cost | B32: =(+Q42+Q43+Q44+Q45+Q46+Q48)/B4 -> 1.1859216 | C32: =(+R42+R43+R44+R45+R46+R48)/C4 -> 160.99785 | D32: =(+S42+S43+S44+S45+S46+S48)/D4 -> 0.36698603 | E32: =(+T42+T43+T44+T45+T46+T48)/E4 -> 15.162482 | F32: =(+U42+U43+U44+U45+U46+U48)/F4 -> 21.998602 | G32: =(+V42+V43+V44+V45+V46+V48)/G4 -> 5.7800755 | H32: =(+W42+W43+W44+W45+W46+W48)/H4 -> 0
A33: Actual Cost | B33: =(+Q9+Q17+Q18)/B4 -> 0.60684331 | C33: =(+R9+R17+R18)/C4 -> 79.162083 | D33: =(+S9+S17+S18)/D4 -> 0.43028703 | E33: =(+T9+T17+T18)/E4 -> 16.857343 | F33: =(+U9+U17+U18)/F4 -> 26.879921 | G33: =(+V9+V17+V18)/G4 -> 6.7006667 | H33: =(+W9+W17+W18)/H4 -> 0 | P33: Other ... | Q33: =Inputs!$F74*Percentages!C33 -> 12445 | R33: =Inputs!$F74*Percentages!D33 -> 0 | S33: =Inputs!$F74*Percentages!E33 -> 0 | T33: =Inputs!$F74*Percentages!F33 -> 0 | U33: =Inputs!$F74*Percentages!G33 -> 0 | V33: =Inputs!$F74*Percentages!H33 -> 0 | W33: =Inputs!$F74*Percentages!I33 -> 0
P34: Other ... | Q34: =Inputs!$F75*Percentages!C34 -> 0 | R34: =Inputs!$F75*Percentages!D34 -> 0 | S34: =Inputs!$F75*Percentages!E34 -> 0 | T34: =Inputs!$F75*Percentages!F34 -> 0 | U34: =Inputs!$F75*Percentages!G34 -> 0 | V34: =Inputs!$F75*Percentages!H34 -> 0 | W34: =Inputs!$F75*Percentages!I34 -> 0
E35: Total Opportunity Cost Depreciation and Interest Used | F35: =Inputs!C9*Y7+Inputs!C7*Y5+Inputs!C6*Y4+Inputs!C8*Y6+Inputs!C5*Y3+Inputs!C4*Inputs!C12 -> 180813.9 | P35: Other ... | Q35: =Inputs!$F76*Percentages!C35 -> 0 | R35: =Inputs!$F76*Percentages!D35 -> 0 | S35: =Inputs!$F76*Percentages!E35 -> 0 | T35: =Inputs!$F76*Percentages!F35 -> 0 | U35: =Inputs!$F76*Percentages!G35 -> 0 | V35: =Inputs!$F76*Percentages!H35 -> 0 | W35: =Inputs!$F76*Percentages!I35 -> 0
E36: Total Actual Tax Depreciation and Interest Claimed | F36: =Inputs!B71+Inputs!B78+Inputs!B79 -> 127838 | P36: Other ... | Q36: =Inputs!$F77*Percentages!C36 -> 0 | R36: =Inputs!$F77*Percentages!D36 -> 0 | S36: =Inputs!$F77*Percentages!E36 -> 0 | T36: =Inputs!$F77*Percentages!F36 -> 0 | U36: =Inputs!$F77*Percentages!G36 -> 0 | V36: =Inputs!$F77*Percentages!H36 -> 0 | W36: =Inputs!$F77*Percentages!I36 -> 0
P37: Change in Prepaid Expenses | Q37: =Inputs!$F80*Percentages!C37 -> -15308 | R37: =Inputs!$F80*Percentages!D37 -> 0 | S37: =Inputs!$F80*Percentages!E37 -> 0 | T37: =Inputs!$F80*Percentages!F37 -> 0 | U37: =Inputs!$F80*Percentages!G37 -> 0 | V37: =Inputs!$F80*Percentages!H37 -> 0 | W37: =Inputs!$F80*Percentages!I37 -> 0
P38: Change in Accounts Payable | Q38: =Inputs!$F81*Percentages!C38 -> 6800 | R38: =Inputs!$F81*Percentages!D38 -> 0 | S38: =Inputs!$F81*Percentages!E38 -> 0 | T38: =Inputs!$F81*Percentages!F38 -> 0 | U38: =Inputs!$F81*Percentages!G38 -> 0 | V38: =Inputs!$F81*Percentages!H38 -> 0 | W38: =Inputs!$F81*Percentages!I38 -> 0
E39: Total Labor & Management Charges on This Farm | F39: =Inputs!C15+Inputs!C16+Inputs!B72+Inputs!B80+Inputs!B81 -> 286693
A41: Total Costs Charged to the Milk Production Enterprise | E41: =B4*B8 -> 1088745.8 | P41: Opportunity Costs
...

Sheet Inputs
A1: Step 1. List Value of Capital Items
C3: Value | D3: Enterprises on This Farm
B4: Inventory | C4: 180901 | E4: Milk
B5: Livestock | C5: 600250 | E5: Heifers
B6: Equipment | C6: 55000 | E6: Corn
B7: Machinery | C7: 146748 | E7: Corn Silage
B8: Buildings | C8: 580641 | E8: Haylage
B9: Land | C9: 79950 | E9: Hay
A10: Total Investment | C10: =C9+C7+C6+C8+C5+C4 -> 1643490 | E10: Other
A12: Opportunity Interest Rate | C12: 0.085
A14: Opportunity Cost of:
A15: Unpaid Labor | C15: 0
A16: Unpaid Management | C16: 15000
A21: Step 2. List Amount and Value of Feedstuffs Fed Annually
A23: Number of Cows | B23: 330
A24: Number of Other (Heifers) | C24: 250
A26: Amount of Home Grown Crops Fed: | C26: (per cow) | D26: (other) | E26: Value per
A27: (on an as is basis) | B27: Unit | C27: Quantity | D27: Quantity | E27: Unit | F27: Total | G27: Cows | H27: Heifers
A28: =E6 -> Corn | B28: Bushels | C28: 96 | D28: 10 | E28: 2.5 | F28: =(+C28+D28)*E28 -> 265 | G28: =C28*$E28 -> 240 | H28: =D28*$E28 -> 25
A29: =E7 -> Corn Silage | B29: Tons | C29: 2.9 | D29: 1 | E29: 20 | F29: =(+C29+D29)*E29 -> 78 | G29: =C29*$E29 -> 58 | H29: =D29*$E29 -> 20
A30: =E8 -> Haylage | B30: Tons | C30: 8 | D30: 0 | E30: 35 | F30: =(+C30+D30)*E30 -> 280 | G30: =C30*$E30 -> 280 | H30: =D30*$E30 -> 0
A31: =E9 -> Hay | B31: Tons | C31: 0 | D31: 2 | E31: 85 | F31: =(+C31+D31)*E31 -> 170 | G31: =C31*$E31 -> 0 | H31: =D31*$E31 -> 170
A32: =E10 -> Other | B32: Tons | C32: 0 | D32: 0 | E32: 1 | F32: =(+C32+D32)*E32 -> 0 | G32: =C32*$E32 -> 0 | H32: =D32*$E32 -> 0
E33: Total/Cow | F33: =SUM(F28:F32) -> 793 | G33: =SUM(G28:G32) -> 578 | H33: =SUM(H28:H32) -> 215
A35: Total Home Grown Feeds Fed | C35: =B23*G33+C24*H33 -> 244490 | D35: Number of Heifers that Freshened
D36: this year is | E36: 120
A37: Average Moisture in | B37: =A30 -> Haylage | C37: 0.65
A38: Average Moisture in | B38: =A29 -> Corn Silage | C38: 0.65 | D38: Price of a: | E38: Heifer Calf | F38: 100
A39: Average Moisture in | B39: =A32 -> Other | C39: 0 | E39: Replacement Heifer | F39: 1200
A41: Step 3. List Income
A43: Milk Sales | B43: 1111948 | D43: US All Milk Price | F43: 13.33
A44: Calf Sales | B44: 5464
A45: Cull Cow Sales | B45: 41227
C46: Change in Raised Dairy Herd's Value | D46: 11000
A48: Other Enterprise Incomes (excluding crop sales)
A49: Enterprise: | B49: =$E$4 -> Milk | C49: =$E$5 -> Heifers | D49: =$E$6 -> Corn | E49: =$E$7 -> Corn Silage | F49: =$E$8 -> Haylage | G49: =$E$9 -> Hay | H49: =$A$32 -> Other
A50: Coop Distributions | B50: 9248 | C50: 0 | D50: 0 | E50: 88 | F50: 88 | G50: 0 | H50: 0
A51: Crop Program Pymts | B51: 0 | C51: 0 | D51: 1366 | E51: 1000 | F51: 2450 | G51: 0 | H51: 0
A52: Tax Refunds | B52: 0 | C52: 0 | D52: 0 | E52: 0 | F52: 0 | G52: 0 | H52: 0
A53: Other | B53: 0 | C53: 0 | D53: 0 | E53: 0 | F53: 0 | G53: 0 | H53: 0
...

Sheet Percentages
A1: TABLE 1: Schedule F Costs | E1: Percent to ...
A2: Item: | B2: Unallocated | C2: =Inputs!$E$4 -> Milk | D2: Heifers | E2: =Inputs!$E$6 -> Corn | F2: =Inputs!$E$7 -> Corn Silage | G2: =Inputs!$E$8 -> Haylage | H2: =Inputs!$E$9 -> Hay | I2: =Inputs!$E$10 -> Other
A3: Breeding Fees | B3: =1-C3-D3-E3-F3-G3-H3-I3 -> 0 | C3: 0.75 | D3: 0.25 | E3: 0 | F3: 0 | G3: 0 | H3: 0 | I3: 0
A4: Car & Truck Expense | B4: =1-C4-D4-E4-F4-G4-H4-I4 -> 1.0061396e-16 | C4: 0.2 | D4: 0.1 | E4: 0.35 | F4: 0.15 | G4: 0.18 | H4: 0.02 | I4: 0
A5: Chemicals | B5: =1-C5-D5-E5-F5-G5-H5-I5 -> 5.5511151e-17 | C5: 0 | D5: 0 | E5: 0.7 | F5: 0.3 | G5: 0 | H5: 0 | I5: 0
A6: Conservation Expense | B6: =1-C6-D6-E6-F6-G6-H6-I6 -> -5.5511151e-17 | C6: 0 | D6: 0 | E6: 0.3 | F6: 0.3 | G6: 0.4 | H6: 0 | I6: 0
A7: Custom Hire | B7: =1-C7-D7-E7-F7-G7-H7-I7 -> 0 | C7: 0 | D7: 0 | E7: 1 | F7: 0 | G7: 0 | H7: 0 | I7: 0
A9: Depreciation | B9: =1-C9-D9-E9-F9-G9-H9-I9 -> 2.0816682e-17 | C9: 0.4 | D9: 0.1 | E9: 0.1 | F9: 0.125 | G9: 0.25 | H9: 0.025 | I9: 0
A10: Employee Benefit Programs | B10: =1-C10-D10-E10-F10-G10-H10-I10 -> 1.7347235e-17 | C10: 0.65 | D10: 0.05 | E10: 0.04 | F10: 0.06 | G10: 0.18 | H10: 0.02 | I10: 0
A11: Feed Purchased | B11: =1-C11-D11-E11-F11-G11-H11-I11 -> 4.1633363e-17 | C11: 0.95 | D11: 0.05 | E11: 0 | F11: 0 | G11: 0 | H11: 0 | I11: 0
A12: Fertilizer | B12: =1-C12-D12-E12-F12-G12-H12-I12 -> -5.5511151e-17 | C12: 0 | D12: 0 | E12: 0.4 | F12: 0.15 | G12: 0.45 | H12: 0 | I12: 0
A13: Freight | B13: =1-C13-D13-E13-F13-G13-H13-I13 -> 0 | C13: 1 | D13: 0 | E13: 0 | F13: 0 | G13: 0 | H13: 0 | I13: 0
A15: Gasoline, Fuel | B15: =1-C15-D15-E15-F15-G15-H15-I15 -> 4.1633363e-17 | C15: 0.09 | D15: 0.01 | E15: 0.15 | F15: 0.2 | G15: 0.5 | H15: 0.05 | I15: 0
A16: Insurance | B16: =1-C16-D16-E16-F16-G16-H16-I16 -> 4.1633363e-17 | C16: 0.7 | D16: 0.05 | E16: 0.14 | F16: 0.06 | G16: 0.05 | H16: 0 | I16: 0
... A38: Change Accounts Payable | B38: =1-C38-D38-E38-F38-G38-H38-I38 -> 0 | C38: 1 | D38: 0 | E38: 0 | F38: 0 | G38: 0 | H38: 0 | I38: 0
A40: TABLE 2: Opportunity Costs | F40: Percent to ...
A41: Item: | B41: Unallocated | C41: =Inputs!$E$4 -> Milk | D41: =D2 -> Heifers | E41: =Inputs!$E$6 -> Corn | F41: =Inputs!$E$7 -> Corn Silage | G41: =Inputs!$E$8 -> Haylage | H41: =Inputs!$E$9 -> Hay | I41: =Inputs!$E$10 -> Other
A42: Inventory | B42: =1-C42-D42-E42-F42-G42-H42-I42 -> -2.7755576e-17 | C42: 0.9 | D42: 0.1 | E42: 0 | F42: 0 | G42: 0 | H42: 0 | I42: 0
A43: Livestock | B43: =1-C43-D43-E43-F43-G43-H43-I43 -> 0 | C43: 0.75 | D43: 0.25 | E43: 0 | F43: 0 | G43: 0 | H43: 0 | I43: 0
A44: Equipment | B44: =1-C44-D44-E44-F44-G44-H44-I44 -> 3.6429193e-17 | C44: 0.7 | D44: 0.1 | E44: 0.04 | F44: 0.06 | G44: 0.09 | H44: 0.01 | I44: 0
A45: Machinery | B45: =1-C45-D45-E45-F45-G45-H45-I45 -> -5.5511151e-17 | C45: 0 | D45: 0 | E45: 0.15 | F45: 0.25 | G45: 0.54 | H45: 0.06 | I45: 0
A46: Buildings | B46: =1-C46-D46-E46-F46-G46-H46-I46 -> -1.3877788e-17 | C46: 0.6 | D46: 0.05 | E46: 0.1 | F46: 0.1 | G46: 0.135 | H46: 0.015 | I46: 0
A48: Land | B48: =1-C48-D48-E48-F48-G48-H48-I48 -> 0.25 | C48: 0.025 | D48: 0.025 | E48: 0.2 | F48: 0.1 | G48: 0.36 | H48: 0.04 | I48: 0
A49: Unpaid Labor | B49: =1-C49-D49-E49-F49-G49-H49-I49 -> 2.7755576e-17 | C49: 0.65 | D49: 0.05 | E49: 0.04 | F49: 0.05 | G49: 0.18 | H49: 0.03 | I49: 0
A50: Management | B50: =1-C50-D50-E50-F50-G50-H50-I50 -> 1.7347235e-17 | C50: 0.65 | D50: 0.05 | E50: 0.05 | F50: 0.05 | G50: 0.18 | H50: 0.02 | I50: 0
A51: Home Grown Feeds | B51: =1-C51-D51-E51-F51-G51-H51-I51 -> 0 | C51: =Inputs!G33/Inputs!F33 -> 0.72887768 | D51: =Inputs!H33/Inputs!F33 -> 0.27112232 | E51: 0 | F51: 0 | G51: 0 | H51: 0 | I51: 0

Sheet Input Forms
A1: Step 1. List Value of Capital Items
C3: Value | D3: Enterprises on This Farm
B4: Inventory | C4: $________ | E4: Milk
B5: Livestock | C5: $________ | E5: Heifers
B6: Equipment | C6: $________ | E6: ________
B7: Machinery | C7: $________ | E7: ________
B8: Buildings | C8: $________ | E8: ________
B9: Land | C9: $________ | E9: ________
E10: ________
A12: Opportunity Interest Rate | C12: ____%
A14: Opportunity Cost of:
A15: Unpaid Labor | C15: $________
A16: Unpaid Management | C16: $________
A21: Step 2. List Amount and Value of Feedstuffs Fed Annually
A23: Number of Cows | B23: ________
A24: Number of Other (Heifers) | C24: ________
A26: Amount of Home Grown Crops Fed: | C26: (per cow) | D26: (other) | E26: Value per
A27: (on an as is basis) | B27: Unit | C27: Quantity | D27: Quantity | E27: Unit
A28: =E6 -> ________ | B28: =$E$6 -> ________ | C28: _____.__ | D28: _____.__ | E28: $_____.__
A29: =E7 -> ________ | B29: =$E$6 -> ________ | C29: _____.__ | D29: _____.__ | E29: $_____.__
A30: =E8 -> ________ | B30: =$E$6 -> ________ | C30: _____.__ | D30: _____.__ | E30: $_____.__
A31: =E9 -> ________ | B31: =$E$6 -> ________ | C31: _____.__ | D31: _____.__ | E31: $_____.__
A32: =E10 -> ________ | B32: =$E$6 -> ________ | C32: _____.__ | D32: _____.__ | E32: $_____.__
C34: Number of heifers that freshened this year is | D34: ________
A37: Average Moisture in | B37: Haylage | C37: ____% | E37: Price of a: | F37: Heifer Calf | G37: $________
A38: Average Moisture in | B38: Corn Silage | C38: ____% | F38: Replacement Heifer | G38: $________
A39: Average Moisture in | B39: =A32 -> ________ | C39: ____%
A41: Step 3. List Income
A43: Milk Sales | B43: $__________ | D43: US All Milk Price | F43: $_____.__
A44: Calf Sales | B44: $________
A45: Cull Cow Sales | B45: $________
A46: Change in Raised Dairy Herd's Value | C46: $________
A47: (Animals that you raised or paid to have raised and have deducted as an expense those costs.)
A48: Other Enterprise Incomes (excluding crop sales)
A49: Enterprise: | B49: =$E$4 -> Milk | C49: =$E$5 -> Heifers | D49: =$E$6 -> ________ | E49: =$E$7 -> ________ | F49: =$E$8 -> ________ | G49: =$E$9 -> ________ | H49: =$A$32 -> ________
A50: Coop Distributions | B50: =$E$6 -> ________ | C50: =$E$6 -> ________ | D50: =$E$6 -> ________ | E50: =$E$6 -> ________ | F50: =$E$6 -> ________ | G50: =$E$6 -> ________ | H50: =$E$6 -> ________
A51: Crop Program Pymts | B51: =$E$6 -> ________ | C51: =$E$6 -> ________ | D51: =$E$6 -> ________ | E51: =$E$6 -> ________ | F51: =$E$6 -> ________ | G51: =$E$6 -> ________ | H51: =$E$6 -> ________
A52: Tax Refunds | B52: =$E$6 -> ________ | C52: =$E$6 -> ________ | D52: =$E$6 -> ________ | E52: =$E$6 -> ________ | F52: =$E$6 -> ________ | G52: =$E$6 -> ________ | H52: =$E$6 -> ________
A53: Other | B53: =$E$6 -> ________ | C53: =$E$6 -> ________ | D53: =$E$6 -> ________ | E53: =$E$6 -> ________ | F53: =$E$6 -> ________ | G53: =$E$6 -> ________ | H53: =$E$6 -> ________
A54: Total Other
...
