Workbook

Sheet Explanation
A1: =Report!A1 -> Summary of Data from CAS Professional Skills Survey 2002
A2: Explanation of Data/Report
A4: Specific Skills
A6: Importance
A7: Average Value of Survey Categories:
A8: 4 | B8: Critical
A9: 3 | B9: Important
A10: 2 | B10: Somewhat
A11: 1 | B11: Low
A12: 0 | B12: Not Important
A14: Where Should Be Taught
A15: % of Total Respondents (338)
A16: Did not show responses that were:
B17: Blank
B18: Not Familiar
B19: Data Error
A20: May not sum to 100% due to exclusion of Blank, Not Familiar, and Data Error.
A22: Use It
A23: Responses to "Have I used this?"
A24: Excluded responses that were:
B25: Blank
B26: Not Familiar
B27: Data Error
A28: Recalculated as % of "I use it" / ("I use it" + "I do not use it")
A31: General Questions
A33: May not sum to 100% due to exclusion of No Opinion, Blank, and Data Error.
A35: Question #4 - respondents were allowed to reply more than once.
B36: Percentages are to total number of replies (653).
B37: Does not sum to 100% due to those that were left blank.

Sheet Report
A1: Summary of Data from CAS Professional Skills Survey 2002
A3: Specific Skills
D5: Where Should Be Taught
A6: Item # | B6: Topic | C6: Importance | D6: Basic Ed | E6: Continuing Ed | F6: Non-CAS | G6: Use It
B8: Basic Mathematics
A9: 1A | B9: Basic Calculus - One Variable | C9: =(4*Data!B8+3*Data!C8+2*Data!D8+1*Data!E8)/(SUM(Data!B8:F8)) -> 2.8867925 | D9: =Data!H8/Data!$J$3 -> 0.48816568 | E9: =Data!I8/Data!$J$3 -> 0.0029585799 | F9: =Data!J8/Data!$J$3 -> 0.43195266 | G9: =Data!L8/(Data!L8+Data!M8) -> 0.7980456
A10: 1B | B10: Basic Calculus - Many Variables | C10: =(4*Data!B9+3*Data!C9+2*Data!D9+1*Data!E9)/(SUM(Data!B9:F9)) -> 2.5 | D10: =Data!H9/Data!$J$3 -> 0.46745562 | E10: =Data!I9/Data!$J$3 -> 0.020710059 | F10: =Data!J9/Data!$J$3 -> 0.43786982 | G10: =Data!L9/(Data!L9+Data!M9) -> 0.55409836
A11: 1C | B11: Basic Differential Equations | C11: =(4*Data!B10+3*Data!C10+2*Data!D10+1*Data!E10)/(SUM(Data!B10:F10)) -> 1.8360129 | D11: =Data!H10/Data!$J$3 -> 0.29585799 | E11: =Data!I10/Data!$J$3 -> 0.047337278 | F11: =Data!J10/Data!$J$3 -> 0.55325444 | G11: =Data!L10/(Data!L10+Data!M10) -> 0.27666667
A12: 1D | B12: Linear Algebra | C12: =(4*Data!B11+3*Data!C11+2*Data!D11+1*Data!E11)/(SUM(Data!B11:F11)) -> 2.5047619 | D12: =Data!H11/Data!$J$3 -> 0.43491124 | E12: =Data!I11/Data!$J$3 -> 0.017751479 | F12: =Data!J11/Data!$J$3 -> 0.4556213 | G12: =Data!L11/(Data!L11+Data!M11) -> 0.63815789
A13: 1E | B13: Algebraic Manipulation of Equations | C13: =(4*Data!B12+3*Data!C12+2*Data!D12+1*Data!E12)/(SUM(Data!B12:F12)) -> 3.5394322 | D13: =Data!H12/Data!$J$3 -> 0.4704142 | E13: =Data!I12/Data!$J$3 -> 0.0029585799 | F13: =Data!J12/Data!$J$3 -> 0.44674556 | G13: =Data!L12/(Data!L12+Data!M12) -> 0.96688742
B15: Probability
A16: 2A | B16: Bayes Theorem | C16: =(4*Data!B15+3*Data!C15+2*Data!D15+1*Data!E15)/(SUM(Data!B15:F15)) -> 3.168254 | D16: =Data!H15/Data!$J$3 -> 0.79289941 | E16: =Data!I15/Data!$J$3 -> 0.01183432 | F16: =Data!J15/Data!$J$3 -> 0.11538462 | G16: =Data!L15/(Data!L15+Data!M15) -> 0.82178218
A17: 2B | B17: Discrete Distributions | C17: =(4*Data!B16+3*Data!C16+2*Data!D16+1*Data!E16)/(SUM(Data!B16:F16)) -> 3.5362776 | D17: =Data!H16/Data!$J$3 -> 0.83136095 | E17: =Data!I16/Data!$J$3 -> 0.0029585799 | F17: =Data!J16/Data!$J$3 -> 0.088757396 | G17: =Data!L16/(Data!L16+Data!M16) -> 0.96052632
A18: 2C | B18: Continuous Univariate Distributions | C18: =(4*Data!B17+3*Data!C17+2*Data!D17+1*Data!E17)/(SUM(Data!B17:F17)) -> 3.4416404 | D18: =Data!H17/Data!$J$3 -> 0.83431953 | E18: =Data!I17/Data!$J$3 -> 0.0059171598 | F18: =Data!J17/Data!$J$3 -> 0.079881657 | G18: =Data!L17/(Data!L17+Data!M17) -> 0.92434211
A19: 2D | B19: Multi-variate Distributions | C19: =(4*Data!B18+3*Data!C18+2*Data!D18+1*Data!E18)/(SUM(Data!B18:F18)) -> 3.2397476 | D19: =Data!H18/Data!$J$3 -> 0.80473373 | E19: =Data!I18/Data!$J$3 -> 0.032544379 | F19: =Data!J18/Data!$J$3 -> 0.082840237 | G19: =Data!L18/(Data!L18+Data!M18) -> 0.77887789
B21: Microeconomics
A22: 3A | B22: Supply, Demand, Market Equilibrium | C22: =(4*Data!B21+3*Data!C21+2*Data!D21+1*Data!E21)/(SUM(Data!B21:F21)) -> 2.9905063 | D22: =Data!H21/Data!$J$3 -> 0.65680473 | E22: =Data!I21/Data!$J$3 -> 0.062130178 | F22: =Data!J21/Data!$J$3 -> 0.20118343 | G22: =Data!L21/(Data!L21+Data!M21) -> 0.69023569
A23: 3B | B23: Comparative Advantage & Trade Gains | C23: =(4*Data!B22+3*Data!C22+2*Data!D22+1*Data!E22)/(SUM(Data!B22:F22)) -> 2.5 | D23: =Data!H22/Data!$J$3 -> 0.48224852 | E23: =Data!I22/Data!$J$3 -> 0.11242604 | F23: =Data!J22/Data!$J$3 -> 0.21893491 | G23: =Data!L22/(Data!L22+Data!M22) -> 0.45864662
A24: 3C | B24: Consumer Behavior | C24: =(4*Data!B23+3*Data!C23+2*Data!D23+1*Data!E23)/(SUM(Data!B23:F23)) -> 2.724026 | D24: =Data!H23/Data!$J$3 -> 0.56804734 | E24: =Data!I23/Data!$J$3 -> 0.10059172 | F24: =Data!J23/Data!$J$3 -> 0.21893491 | G24: =Data!L23/(Data!L23+Data!M23) -> 0.58419244
A25: 3D | B25: Behavior of Firms | C25: =(4*Data!B24+3*Data!C24+2*Data!D24+1*Data!E24)/(SUM(Data!B24:F24)) -> 2.9775641 | D25: =Data!H24/Data!$J$3 -> 0.66272189 | E25: =Data!I24/Data!$J$3 -> 0.068047337 | F25: =Data!J24/Data!$J$3 -> 0.17455621 | G25: =Data!L24/(Data!L24+Data!M24) -> 0.67006803
A26: 3E | B26: Types of Markets | C26: =(4*Data!B25+3*Data!C25+2*Data!D25+1*Data!E25)/(SUM(Data!B25:F25)) -> 2.6805112 | D26: =Data!H25/Data!$J$3 -> 0.59763314 | E26: =Data!I25/Data!$J$3 -> 0.073964497 | F26: =Data!J25/Data!$J$3 -> 0.23372781 | G26: =Data!L25/(Data!L25+Data!M25) -> 0.53378378
A27: 3F | B27: Utility Theory | C27: =(4*Data!B26+3*Data!C26+2*Data!D26+1*Data!E26)/(SUM(Data!B26:F26)) -> 2.9041534 | D27: =Data!H26/Data!$J$3 -> 0.65680473 | E27: =Data!I26/Data!$J$3 -> 0.073964497 | F27: =Data!J26/Data!$J$3 -> 0.17455621 | G27: =Data!L26/(Data!L26+Data!M26) -> 0.62289562
A28: 3G | B28: Game Theory | C28: =(4*Data!B27+3*Data!C27+2*Data!D27+1*Data!E27)/(SUM(Data!B27:F27)) -> 2.3862069 | D28: =Data!H27/Data!$J$3 -> 0.42899408 | E28: =Data!I27/Data!$J$3 -> 0.17455621 | F28: =Data!J27/Data!$J$3 -> 0.23076923 | G28: =Data!L27/(Data!L27+Data!M27) -> 0.35869565
B30: Macroeconomics
A31: 4A | B31: National Income Accounting | C31: =(4*Data!B30+3*Data!C30+2*Data!D30+1*Data!E30)/(SUM(Data!B30:F30)) -> 2.2727273 | D31: =Data!H30/Data!$J$3 -> 0.4704142 | E31: =Data!I30/Data!$J$3 -> 0.085798817 | F31: =Data!J30/Data!$J$3 -> 0.34023669 | G31: =Data!L30/(Data!L30+Data!M30) -> 0.34576271
A32: 4B | B32: Aggregate Supply and Demand | C32: =(4*Data!B31+3*Data!C31+2*Data!D31+1*Data!E31)/(SUM(Data!B31:F31)) -> 2.4512987 | D32: =Data!H31/Data!$J$3 -> 0.52071006 | E32: =Data!I31/Data!$J$3 -> 0.082840237 | F32: =Data!J31/Data!$J$3 -> 0.28994083 | G32: =Data!L31/(Data!L31+Data!M31) -> 0.35958904
A33: 4C | B33: Inflation, Interest Rates, Federal Reserve | C33: =(4*Data!B32+3*Data!C32+2*Data!D32+1*Data!E32)/(SUM(Data!B32:F32)) -> 3.1785714 | D33: =Data!H32/Data!$J$3 -> 0.68047337 | E33: =Data!I32/Data!$J$3 -> 0.047337278 | F33: =Data!J32/Data!$J$3 -> 0.16863905 | G33: =Data!L32/(Data!L32+Data!M32) -> 0.82491582
A34: 4D | B34: Money Supply | C34: =(4*Data!B33+3*Data!C33+2*Data!D33+1*Data!E33)/(SUM(Data!B33:F33)) -> 2.3036304 | D34: =Data!H33/Data!$J$3 -> 0.44378698 | E34: =Data!I33/Data!$J$3 -> 0.1183432 | F34: =Data!J33/Data!$J$3 -> 0.31952663 | G34: =Data!L33/(Data!L33+Data!M33) -> 0.23529412
A35: 4E | B35: Keynesian Economics | C35: =(4*Data!B34+3*Data!C34+2*Data!D34+1*Data!E34)/(SUM(Data!B34:F34)) -> 2.0637584 | D35: =Data!H34/Data!$J$3 -> 0.3816568 | E35: =Data!I34/Data!$J$3 -> 0.13905325 | F35: =Data!J34/Data!$J$3 -> 0.34911243 | G35: =Data!L34/(Data!L34+Data!M34) -> 0.1443662
A36: 4F | B36: The Multiplier Effects | C36: =(4*Data!B35+3*Data!C35+2*Data!D35+1*Data!E35)/(SUM(Data!B35:F35)) -> 2.1653543 | D36: =Data!H35/Data!$J$3 -> 0.37278107 | E36: =Data!I35/Data!$J$3 -> 0.097633136 | F36: =Data!J35/Data!$J$3 -> 0.29289941 | G36: =Data!L35/(Data!L35+Data!M35) -> 0.19685039
B38: Interest Theory
A39: 5A | B39: Present Value, Future Value - Discrete | C39: =(4*Data!B38+3*Data!C38+2*Data!D38+1*Data!E38)/(SUM(Data!B38:F38)) -> 3.8673139 | D39: =Data!H38/Data!$J$3 -> 0.87869822 | E39: =Data!I38/Data!$J$3 -> 0.0059171598 | F39: =Data!J38/Data!$J$3 -> 0.017751479 | G39: =Data!L38/(Data!L38+Data!M38) -> 0.98996656
A40: 5B | B40: Present Value, Future Value - Continuous | C40: =(4*Data!B39+3*Data!C39+2*Data!D39+1*Data!E39)/(SUM(Data!B39:F39)) -> 3.6096774 | D40: =Data!H39/Data!$J$3 -> 0.85798817 | E40: =Data!I39/Data!$J$3 -> 0.020710059 | F40: =Data!J39/Data!$J$3 -> 0.023668639 | G40: =Data!L39/(Data!L39+Data!M39) -> 0.80808081
A41: 5C | B41: Bond Yields, Sinking Funds, Annuities | C41: =(4*Data!B40+3*Data!C40+2*Data!D40+1*Data!E40)/(SUM(Data!B40:F40)) -> 3.0844156 | D41: =Data!H40/Data!$J$3 -> 0.76627219 | E41: =Data!I40/Data!$J$3 -> 0.053254438 | F41: =Data!J40/Data!$J$3 -> 0.071005917 | G41: =Data!L40/(Data!L40+Data!M40) -> 0.60204082
A42: 5D | B42: Amortization & Depreciation | C42: =(4*Data!B41+3*Data!C41+2*Data!D41+1*Data!E41)/(SUM(Data!B41:F41)) -> 2.8762215 | D42: =Data!H41/Data!$J$3 -> 0.70710059 | E42: =Data!I41/Data!$J$3 -> 0.071005917 | F42: =Data!J41/Data!$J$3 -> 0.10650888 | G42: =Data!L41/(Data!L41+Data!M41) -> 0.57142857
B44: Basic Finance
A45: 6A | B45: NPV, Internal Rate of Return, etc. | C45: =(4*Data!B44+3*Data!C44+2*Data!D44+1*Data!E44)/(SUM(Data!B44:F44)) -> 3.7096774 | D45: =Data!H44/Data!$J$3 -> 0.85207101 | E45: =Data!I44/Data!$J$3 -> 0.014792899 | F45: =Data!J44/Data!$J$3 -> 0.026627219 | G45: =Data!L44/(Data!L44+Data!M44) -> 0.92929293
A46: 6B | B46: Risk vs. Return | C46: =(4*Data!B45+3*Data!C45+2*Data!D45+1*Data!E45)/(SUM(Data!B45:F45)) -> 3.3300971 | D46: =Data!H45/Data!$J$3 -> 0.79881657 | E46: =Data!I45/Data!$J$3 -> 0.062130178 | F46: =Data!J45/Data!$J$3 -> 0.035502959 | G46: =Data!L45/(Data!L45+Data!M45) -> 0.67918089
A47: 6C | B47: Capital Budgeting | C47: =(4*Data!B46+3*Data!C46+2*Data!D46+1*Data!E46)/(SUM(Data!B46:F46)) -> 3.0488599 | D47: =Data!H46/Data!$J$3 -> 0.69230769 | E47: =Data!I46/Data!$J$3 -> 0.12426036 | F47: =Data!J46/Data!$J$3 -> 0.073964497 | G47: =Data!L46/(Data!L46+Data!M46) -> 0.58843537
A48: 6D | B48: Efficient Markets | C48: =(4*Data!B47+3*Data!C47+2*Data!D47+1*Data!E47)/(SUM(Data!B47:F47)) -> 2.717608 | D48: =Data!H47/Data!$J$3 -> 0.63313609 | E48: =Data!I47/Data!$J$3 -> 0.13609467 | F48: =Data!J47/Data!$J$3 -> 0.10650888 | G48: =Data!L47/(Data!L47+Data!M47) -> 0.32068966
...

Sheet Data
A1: Summary of Data from CAS Professional Skills Survey 2002
H3: Total Taking Survey | J3: 338
A5: Item # | B5: Critical | C5: Important | D5: Somewhat | E5: Low | F5: Not Important | H5: Basic Ed | I5: Continuing Ed | J5: Non-CAS | L5: Use It | M5: Don't Use It
A8: 1A | B8: 107 | C8: 112 | D8: 62 | E8: 30 | F8: 7 | H8: 165 | I8: 1 | J8: 146 | L8: 245 | M8: 62
A9: 1B | B9: 67 | C9: 105 | D9: 79 | E9: 54 | F9: 13 | H9: 158 | I9: 7 | J9: 148 | L9: 169 | M9: 136
A10: 1C | B10: 27 | C10: 67 | D10: 81 | E10: 100 | F10: 36 | H10: 100 | I10: 16 | J10: 187 | L10: 83 | M10: 217
A11: 1D | B11: 75 | C11: 103 | D11: 66 | E11: 48 | F11: 23 | H11: 147 | I11: 6 | J11: 154 | L11: 194 | M11: 110
A12: 1E | B12: 213 | C12: 71 | D12: 24 | E12: 9 | F12: 0 | H12: 159 | I12: 1 | J12: 151 | L12: 292 | M12: 10
A15: 2A | B15: 135 | C15: 116 | D15: 48 | E15: 14 | F15: 2 | H15: 268 | I15: 4 | J15: 39 | L15: 249 | M15: 54
A16: 2B | B16: 197 | C16: 94 | D16: 25 | E16: 1 | F16: 0 | H16: 281 | I16: 1 | J16: 30 | L16: 292 | M16: 12
A17: 2C | B17: 175 | C17: 109 | D17: 31 | E17: 2 | F17: 0 | H17: 282 | I17: 2 | J17: 27 | L17: 281 | M17: 23
A18: 2D | B18: 146 | C18: 112 | D18: 48 | E18: 11 | F18: 0 | H18: 272 | I18: 11 | J18: 28 | L18: 236 | M18: 67
A21: 3A | B21: 94 | C21: 141 | D21: 66 | E21: 14 | F21: 1 | H21: 222 | I21: 21 | J21: 68 | L21: 205 | M21: 92
A22: 3B | B22: 39 | C22: 107 | D22: 96 | E22: 26 | F22: 10 | H22: 163 | I22: 38 | J22: 74 | L22: 122 | M22: 144
A23: 3C | B23: 63 | C23: 132 | D23: 84 | E23: 23 | F23: 6 | H23: 192 | I23: 34 | J23: 74 | L23: 170 | M23: 121
... A204: 18N | B204: 78 | C204: 117 | D204: 65 | E204: 16 | F204: 4 | H204: 12 | I204: 109 | J204: 158 | L204: 212 | M204: 46
A208: 1 | B208: Basic Subjects | C208: Keep on Syllabus | D208: Credit for University Courses | E208: Background Reading
B209: Calculus | C209: 110 | D209: 112 | E209: 67
B210: Probability | C210: 218 | D210: 59 | E210: 12
B211: Economics | C211: 160 | D211: 96 | E211: 33
B212: Regression | C212: 245 | D212: 31 | E212: 13
B213: Forecasting | C213: 228 | D213: 31 | E213: 29
B214: Time Series | C214: 195 | D214: 42 | E214: 47
B215: Interest Theory | C215: 249 | D215: 29 | E215: 10
B216: Finance | C216: 217 | D216: 56 | E216: 15
A218: 2 | B218: Would credit for university courses negatively affect the FCAS designation? | H218: Yes | I218: No
H219: 129 | I219: 141
A221: 3 | B221: How long should travel time be (based on first full-time casualty employment)?
C222: <4 | D222: 6
C223: 4 | D223: 7
C224: 5 | D224: 60
C225: 6 | D225: 47
C226: 7 | D226: 69
C227: 8 | D227: 48
C228: 9 | D228: 3
C229: 10 | D229: 22
C230: >10 | D230: =4+2 -> 6
A232: 4 | B232: Methods to reduce travel time:
B233: Reduce exams | E233: 66
B234: Reduce topics | E234: 110
...
