Workbook

Sheet Raw Data
A1: School Focused Youth Service Data
B3: 2000 - 16 projects
A4: Auspice | B4: issue | C4: Program | D4: children | E4: parents | F4: schools | G4: orgns | H4: hours | I4: $$ per child | J4: $$ per partic | K4: budget $ | L4: Sustained | M4: group work | N4: outings | O4: materials | P4: counselling | Q4: tutoring
A5: B'ton prim, sec | B5: Bullying | C5: Bentleigh/SFL dads | D5: 141 | E5: 200 | F5: 2 | G5: 2 | H5: 22 | I5: =J5 -> 10.26393 | J5: =K5/(D5+E5) -> 10.26393 | K5: 3500 | M5: y | N5: y | P5: y | R5: Dads involved SFL
A6: Mordi Chels Sec | B6: Anger mgt | C6: Kings/Comm health | D6: 7 | E6: 0 | F6: 1 | G6: 2 | H6: =1.5*11 -> 16.5 | I6: =J6 -> 290.02857 | J6: =K6/(D6+E6) -> 290.02857 | K6: 2030.2 | L6: Y | M6: y
A7: Gordon Homes | B7: school ret | C7: homework | D7: 4 | E7: 0 | F7: 3 | G7: 1 | H7: 100 | I7: =J7 -> 875 | J7: =K7/(D7+E7) -> 875 | K7: 3500 | L7: n | M7: y | O7: y | P7: y | Q7: y
A8: Bayside council | B8: Peer skills | C8: Kids Help Line | D8: 148 | E8: 0 | F8: 4 | G8: 2 | H8: =(14*6)+(4*6) -> 108 | I8: =J8 -> 26.216216 | J8: =K8/(D8+E8) -> 26.216216 | K8: 3880 | L8: y | M8: y | R8: BCC devel peer skills for 2ndry
A9: Kingston council | B9: culture | C9: Kingston | D9: 19 | E9: 0 | F9: 1 | G9: 1 | H9: =3*14 -> 42 | I9: =J9 -> 180.28632 | J9: =K9/(D9+E9) -> 180.28632 | K9: 3425.44 | L9: n | M9: y | N9: y
A10: Clarinda prim | B10: bullying | C10: REFS | D10: 66 | E10: 0 | F10: 1 | G10: 1 | H10: =(1 *5)+(4*3) -> 17 | I10: =J10 -> 45.454545 | J10: =K10/(D10+E10) -> 45.454545 | K10: 3000 | L10: y | M10: y | R10: Teacher prof devel - 1 day. Peer plus conf. Res.
A11: Bayside Youth Found | B11: body image | C11: JPET/BBCH | D11: 38 | E11: 0 | F11: 2 | G11: 6 | H11: 6 | I11: =J11 -> 92.105263 | J11: =K11/(D11+E11) -> 92.105263 | K11: 3500 | L11: y | M11: y | N11: y | O11: y | R11: SFL, LegalAid, BodyShop, etc
A12: CBCHS | B12: health, D/A | C12: Kingston | D12: 60 | E12: 0 | F12: 3 | G12: 3 | H12: 6 | I12: =J12 -> 27.5 | J12: =K12/(D12+E12) -> 27.5 | K12: 1650 | L12: y | M12: y
A13: Chelsea prim | B13: anger mgt | C13: REFS/SFL | D13: 92 | E13: 0 | F13: 1 | G13: 2 | H13: =3*(1*5)+(5*6) -> 45 | I13: =J13 -> 32.608696 | J13: =K13/(D13+E13) -> 32.608696 | K13: 3000 | M13: y | R13: SFL follows with counselling
A14: Kibreda | B14: school ret | C14: Kilb/SFL | D14: 30 | E14: 11 | F14: 1 | G14: 4 | H14: 10 | I14: =J14 -> 85.365854 | J14: =K14/(D14+E14) -> 85.365854 | K14: 3500 | L14: y | M14: y | P14: y
A15: Brighton Beach prim | B15: conflict res | C15: Schools Med | D15: 56 | E15: 54 | F15: 1 | G15: 2 | I15: =J15 -> 18.5 | J15: =K15/(D15+E15) -> 18.5 | K15: 2035 | L15: y | M15: y | N15: y | R15: envisage training other teachers
A16: CBCHS | B16: health, D/A | C16: Kingst/SFL | D16: 32 | E16: 0 | F16: 1 | G16: 3 | H16: 6 | I16: =J16 -> 31.03125 | J16: =K16/(D16+E16) -> 31.03125 | K16: 993 | L16: y | M16: y
A17: Chelt sec | B17: school ret | C17: Angli h/w | D17: 691 | E17: 0 | F17: 1 | G17: 1 | H17: =2*(2*16) -> 64 | I17: =J17 -> 2.1997106 | J17: =K17/(D17+E17) -> 2.1997106 | K17: 1520 | L17: y | Q17: y | R17: did not get full alloc
A18: St Finbars | B18: Bullying | C18: REFS | D18: 89 | E18: 0 | F18: 1 | G18: 1 | H18: =3*(1*5) -> 15 | I18: =J18 -> 16.853933 | J18: =K18/(D18+E18) -> 16.853933 | K18: 1500 | L18: y | M18: y
A19: Edithvale prim | B19: conflict res | C19: REFS | D19: 67 | E19: 0 | F19: 1 | G19: 1 | H19: =3*(45/60*6) -> 13.5 | I19: =J19 -> 20.149254 | J19: =K19/(D19+E19) -> 20.149254 | K19: 1350 | L19: y | M19: y
A20: Anglicare | B20: school ret | C20: homework | D20: 14 | H20: 30 | I20: =J20 -> 71.428571 | J20: =K20/(D20+E20) -> 71.428571 | K20: 1000 | Q20: y
A22: Totals | D22: =SUM(D5:D19) -> 1540 | E22: =SUM(E5:E15) -> 265 | F22: =SUM(F5:F19) -> 24 | G22: =SUM(G5:G19) -> 32 | H22: =SUM(H5:H20) -> 501 | K22: =SUM(K5:K20) -> 39383.64
B24: 2001 - 11 projects
A25: Auspice | B25: issue | C25: program | D25: children | E25: parents | F25: schools | G25: orgns | H25: hours | I25: $$ per child | J25: $$ per partic | K25: budget $ | L25: Sustained | M25: group work | N25: outings | O25: materials | P25: counselling | Q25: tutoring
A26: St Brigids | B26: peerskills | C26: REFS/SFL | D26: 42 | F26: 1 | G26: 2 | H26: 10 | I26: =K26/D26 -> 35.714286 | J26: =K26/(D26+E26) -> 35.714286 | K26: 1500 | M26: y | P26: y | R26: REFS = peer
A27: Aspendale prim | B27: peerskills | C27: REFS | D27: 90 | E27: 0 | F27: 1 | G27: 1 | H27: =(3*40/60)*5 -> 10 | I27: =K27/D27 -> 16.666667 | J27: =K27/(D27+E27) -> 16.666667 | K27: 1500 | L27: n | M27: y | R27: poor outcome
A28: Mentone Park pri | B28: peerskills | C28: REFS | D28: 30 | E28: 0 | F28: 1 | G28: 1 | H28: =(3*4) -> 12 | I28: =K28/D28 -> 47.666667 | J28: =K28/(D28+E28) -> 47.666667 | K28: 1430 | L28: y | M28: y | R28: Ok outcome. Teachers trained
A29: St Agnes | B29: dads | C29: SFL dads | D29: 102 | E29: 70 | F29: 1 | G29: 1 | H29: =(4*2) -> 8 | I29: =J29 -> 3.4883721 | J29: =K29/(D29+E29) -> 3.4883721 | K29: 600 | L29: y | M29: y
A30: Bayside Youthschool ret | C30: homework | D30: 0 | F30: 8 | G30: 3 | H30: =(2.5*16) -> 40 | I30: N/A | J30: N/A | K30: 1500 | M30: y | Q30: y
A31: Noah's Ark | B31: sibling camps | D31: 19 | E31: 21 | F31: 4 | G31: 3 | H31: =(19*3) -> 57 | I31: =J31 -> 400.12025 | J31: =K31/(D31+E31) -> 400.12025 | K31: 16004.81 | M31: y | N31: y
A32: Gardenvale pri | B32: life skills | C32: BCC/ Jugglers | D32: 54 | E32: 0 | F32: 1 | G32: 1 | H32: =(1*8) -> 8 | I32: =K32/D32 -> 26.703704 | J32: =K32/(D32+E32) -> 26.703704 | K32: 1442 | M32: y | R32: not much change seen
A33: Bayside council | B33: life skills | C33: BCC/ Jugglers | D33: 8 | E33: 0 | F33: 1 | G33: 2 | H33: =(1*8) -> 8 | I33: =K33/D33 -> 118.25 | J33: =K33/(D33+E33) -> 118.25 | K33: 946 | L33: n | R33: will run for other schools
A34: St Josephs | B34: peerskills | C34: REFS | D34: 23 | E34: 0 | F34: 1 | G34: 1 | H34: =(3*4) -> 12 | I34: =K34/D34 -> 62.173913 | J34: =K34/(D34+E34) -> 62.173913 | K34: 1430 | L34: y | M34: y
A35: St Patricks | B35: bullying | C35: SFL (NOV) | D35: 50 | E35: 0 | F35: 1 | G35: 1 | H35: =(4*7)+(2*4) -> 36 | I35: =K35/D35 -> 30 | J35: =K35/(D35+E35) -> 30 | K35: 1500 | L35: y | M35: y | R35: drama & discussion
A36: Moordialloc pri | B36: bullying | C36: SFL (NOV) | D36: 74 | E36: 0 | F36: 1 | G36: 1 | H36: 0 | I36: =K36/D36 -> 20.27027 | J36: =K36/(D36+E36) -> 20.27027 | K36: 1500 | L36: y | M36: y | R36: Knock out violence
A38: Totals | D38: =SUM(D26:D37) -> 492 | E38: =SUM(E27:E36) -> 91 | F38: =SUM(F26:F36) -> 21 | G38: =SUM(G26:G36) -> 17 | H38: =SUM(H26:H35) -> 201 | K38: =SUM(K26:K37) -> 29352.81
B40: Summary Information
B41: Program Type | F41: Issue Addressed
B42: Group work | C42: Outing | D42: Home work | E42: Other | F42: Bullying | G42: Peer skills | H42: Life skills | I42: Conflict /anger | K42: school ret | L42: culture | M42: Body image | N42: health | O42: dads | P42: siblings
A43: Kids involved | B43: =SUM(D5+D6+D7+D8+D9+D10+D11+D12+D13+D14+D15+D16+D18+D19+D26+D27+D28+D29+D30+D31+D32+D34+D35+D36) -> 1333 | C43: =SUM(D5+D9+D11+D15+D31) -> 273 | D43: =SUM(D7+D14+D17) -> 725 | F43: =SUM(D5+D10+D18+D35+D36) -> 420 | G43: =SUM(D8+D26+D27+D28+D34) -> 333 | H43: =SUM(D32+D33) -> 62 | I43: =SUM(D6+D13+D15+D19) -> 222 | K43: =SUM(D7+D14+D17) -> 725 | L43: 19 | M43: 38 | N43: =SUM(D12+D16) -> 92 | O43: 102 | P43: 19
A44: Parents | B44: =SUM(E5+E14+E15+E29+E31) -> 356 | C44: =SUM(E5+E15+E31) -> 275 | D44: 11 | F44: =SUM(E5) -> 200 | G44: 0 | H44: 0 | I44: =SUM(E15) -> 54 | K44: =SUM(E14) -> 11 | L44: 0 | M44: 0 | N44: 0 | O44: 70 | P44: 21
A45: Schools | B45: =SUM(F5+F6+F8+F9+F10+F11+F12+F13+F14+F15+F16+F18+F19+F26+F27+F28+F29+F30+F31+F32+F34+F35+F36) -> 40 | C45: =SUM(F5+F9+F11+F15+F31) -> 10 | D45: =SUM(F14+F30) -> 9 | F45: =SUM(F5+F10+F18+F35+F36) -> 6 | G45: =SUM(F8+F26+F27+F28+F34) -> 8 | H45: =SUM(F32+F33) -> 2 | I45: =SUM(F6+F13+F15+F19) -> 4 | K45: =SUM(F14+F17) -> 2 | L45: 1 | M45: 2 | N45: =SUM(F12+F16) -> 4 | O45: 1 | P45: 4
...

Sheet charts 2000
A1: ='Raw Data'!A4 -> Auspice | B1: ='Raw Data'!B4 -> issue | C1: Peer skills | D1: Culture | E1: School Retention | F1: Health | H1: ='Raw Data'!A4 -> Auspice | I1: ='Raw Data'!B4 -> issue | J1: ='Raw Data'!F4 -> schools | K1: ='Raw Data'!G4 -> orgns | L1: =C1 -> Peer skills | M1: =D1 -> Culture | N1: =E1 -> School Retention | O1: =F1 -> Health | P1: issue | Q1: children | R1: $$ per child | T1: Peer Skills | U1: Culture | V1: School Retention | W1: Health
A2: ='Raw Data'!A5 -> B'ton prim, sec | B2: ='Raw Data'!B5 -> Bullying | C2: 1 | H2: ='Raw Data'!A5 -> B'ton prim, sec | I2: ='Raw Data'!B5 -> Bullying | J2: ='Raw Data'!F5 -> 2 | K2: ='Raw Data'!G5 -> 2 | L2: =C2 -> 1 | M2: =D2 -> 0 | N2: =E2 -> 0 | O2: =F2 -> 0 | P2: Bullying | Q2: ='Raw Data'!D5 -> 141 | R2: ='Raw Data'!J5 -> 10.26393 | S2: =Q2*R2 -> 1447.2141 | T2: =SUM(J28+J29+J31+J33+J36+J38+J42) -> 577 | U2: 19 | V2: =SUM(J30+J37+J40+J43) -> 739 | W2: =SUM(J34+J35+J39) -> 130
A3: ='Raw Data'!A6 -> Mordi Chels Sec | B3: ='Raw Data'!B6 -> Anger mgt | C3: 1 | H3: ='Raw Data'!A6 -> Mordi Chels Sec | I3: ='Raw Data'!B6 -> Anger mgt | J3: ='Raw Data'!F6 -> 1 | K3: ='Raw Data'!G6 -> 2 | L3: =C3 -> 1 | M3: =D3 -> 0 | N3: =E3 -> 0 | O3: =F3 -> 0 | P3: Anger mgt | Q3: ='Raw Data'!D6 -> 7 | R3: ='Raw Data'!J6 -> 290.02857 | S3: =Q3*R3 -> 2030.2 | T3: =SUM(S2+S3+S5+S7+S10+S12+S15+S16) -> 17243.414 | U3: =SUM(S6) -> 3425.44 | V3: =SUM(S4+S11+S14+S17) -> 8580.9756 | W3: =SUM(S9+S13+S8) -> 6143
A4: ='Raw Data'!A7 -> Gordon Homes | B4: ='Raw Data'!B7 -> school ret | C4: =IF(B4="bullying",1,0) -> 0 | E4: 1 | H4: ='Raw Data'!A7 -> Gordon Homes | I4: ='Raw Data'!B7 -> school ret | J4: ='Raw Data'!F7 -> 3 | K4: ='Raw Data'!G7 -> 1 | L4: =C4 -> 0 | M4: =D4 -> 0 | N4: =E4 -> 1 | O4: =F4 -> 0 | P4: school ret | Q4: ='Raw Data'!D7 -> 4 | R4: ='Raw Data'!J7 -> 875 | S4: =Q4*R4 -> 3500 | T4: =T3/T2 -> 29.8846 | U4: =U3/U2 -> 180.28632 | V4: =V3/V2 -> 11.611604 | W4: =W3/W2 -> 47.253846
A5: ='Raw Data'!A8 -> Bayside council | B5: ='Raw Data'!B8 -> Peer skills | C5: 1 | H5: ='Raw Data'!A8 -> Bayside council | I5: ='Raw Data'!B8 -> Peer skills | J5: ='Raw Data'!F8 -> 4 | K5: ='Raw Data'!G8 -> 2 | L5: =C5 -> 1 | M5: =D5 -> 0 | N5: =E5 -> 0 | O5: =F5 -> 0 | P5: Peer skills | Q5: ='Raw Data'!D8 -> 148 | R5: ='Raw Data'!J8 -> 26.216216 | S5: =Q5*R5 -> 3880
A6: ='Raw Data'!A9 -> Kingston council | B6: ='Raw Data'!B9 -> culture | C6: =IF(B6="bullying",1,0) -> 0 | D6: 1 | H6: ='Raw Data'!A9 -> Kingston council | I6: ='Raw Data'!B9 -> culture | J6: ='Raw Data'!F9 -> 1 | K6: ='Raw Data'!G9 -> 1 | L6: =C6 -> 0 | M6: =D6 -> 1 | N6: =E6 -> 0 | O6: =F6 -> 0 | P6: culture | Q6: ='Raw Data'!D9 -> 19 | R6: ='Raw Data'!J9 -> 180.28632 | S6: =Q6*R6 -> 3425.44
A7: ='Raw Data'!A10 -> Clarinda prim | B7: ='Raw Data'!B10 -> bullying | C7: 1 | H7: ='Raw Data'!A10 -> Clarinda prim | I7: ='Raw Data'!B10 -> bullying | J7: ='Raw Data'!F10 -> 1 | K7: ='Raw Data'!G10 -> 1 | L7: =C7 -> 1 | M7: =D7 -> 0 | N7: =E7 -> 0 | O7: =F7 -> 0 | P7: bullying | Q7: ='Raw Data'!D10 -> 66 | R7: ='Raw Data'!J10 -> 45.454545 | S7: =Q7*R7 -> 3000
A8: ='Raw Data'!A11 -> Bayside Youth Found | B8: ='Raw Data'!B11 -> body image | C8: =IF(B8="bullying",1,0) -> 0 | F8: 1 | H8: ='Raw Data'!A11 -> Bayside Youth Found | I8: ='Raw Data'!B11 -> body image | J8: ='Raw Data'!F11 -> 2 | K8: ='Raw Data'!G11 -> 6 | L8: =C8 -> 0 | M8: =D8 -> 0 | N8: =E8 -> 0 | O8: =F8 -> 1 | P8: body image | Q8: ='Raw Data'!D11 -> 38 | R8: ='Raw Data'!J11 -> 92.105263 | S8: =Q8*R8 -> 3500
A9: ='Raw Data'!A12 -> CBCHS | B9: ='Raw Data'!B12 -> health, D/A | C9: =IF(B9="bullying",1,0) -> 0 | F9: 1 | H9: ='Raw Data'!A12 -> CBCHS | I9: ='Raw Data'!B12 -> health, D/A | J9: ='Raw Data'!F12 -> 3 | K9: ='Raw Data'!G12 -> 3 | L9: =C9 -> 0 | M9: =D9 -> 0 | N9: =E9 -> 0 | O9: =F9 -> 1 | P9: health, D/A | Q9: ='Raw Data'!D12 -> 60 | R9: ='Raw Data'!J12 -> 27.5 | S9: =Q9*R9 -> 1650
A10: ='Raw Data'!A13 -> Chelsea prim | B10: ='Raw Data'!B13 -> anger mgt | C10: 1 | H10: ='Raw Data'!A13 -> Chelsea prim | I10: ='Raw Data'!B13 -> anger mgt | J10: ='Raw Data'!F13 -> 1 | K10: ='Raw Data'!G13 -> 2 | L10: =C10 -> 1 | M10: =D10 -> 0 | N10: =E10 -> 0 | O10: =F10 -> 0 | P10: anger mgt | Q10: ='Raw Data'!D13 -> 92 | R10: ='Raw Data'!J13 -> 32.608696 | S10: =Q10*R10 -> 3000
A11: ='Raw Data'!A14 -> Kibreda | B11: ='Raw Data'!B14 -> school ret | C11: =IF(B11="bullying",1,0) -> 0 | E11: 1 | H11: ='Raw Data'!A14 -> Kibreda | I11: ='Raw Data'!B14 -> school ret | J11: ='Raw Data'!F14 -> 1 | K11: ='Raw Data'!G14 -> 4 | L11: =C11 -> 0 | M11: =D11 -> 0 | N11: =E11 -> 1 | O11: =F11 -> 0 | P11: school ret | Q11: ='Raw Data'!D14 -> 30 | R11: ='Raw Data'!J14 -> 85.365854 | S11: =Q11*R11 -> 2560.9756
A12: ='Raw Data'!A15 -> Brighton Beach prim | B12: ='Raw Data'!B15 -> conflict res | C12: 1 | H12: ='Raw Data'!A15 -> Brighton Beach prim | I12: ='Raw Data'!B15 -> conflict res | J12: ='Raw Data'!F15 -> 1 | K12: ='Raw Data'!G15 -> 2 | L12: =C12 -> 1 | M12: =D12 -> 0 | N12: =E12 -> 0 | O12: =F12 -> 0 | P12: conflict res | Q12: ='Raw Data'!D15 -> 56 | R12: ='Raw Data'!J15 -> 18.5 | S12: =Q12*R12 -> 1036
A13: ='Raw Data'!A16 -> CBCHS | B13: ='Raw Data'!B16 -> health, D/A | C13: =IF(B13="bullying",1,0) -> 0 | F13: 1 | H13: ='Raw Data'!A16 -> CBCHS | I13: ='Raw Data'!B16 -> health, D/A | J13: ='Raw Data'!F16 -> 1 | K13: ='Raw Data'!G16 -> 3 | L13: =C13 -> 0 | M13: =D13 -> 0 | N13: =E13 -> 0 | O13: =F13 -> 1 | P13: health, D/A | Q13: ='Raw Data'!D16 -> 32 | R13: ='Raw Data'!J16 -> 31.03125 | S13: =Q13*R13 -> 993
A14: ='Raw Data'!A17 -> Chelt sec | B14: ='Raw Data'!B17 -> school ret | C14: =IF(B14="bullying",1,0) -> 0 | E14: 1 | H14: ='Raw Data'!A17 -> Chelt sec | I14: ='Raw Data'!B17 -> school ret | J14: ='Raw Data'!F17 -> 1 | K14: ='Raw Data'!G17 -> 1 | L14: =C14 -> 0 | M14: =D14 -> 0 | N14: =E14 -> 1 | O14: =F14 -> 0 | P14: school ret | Q14: ='Raw Data'!D17 -> 691 | R14: ='Raw Data'!J17 -> 2.1997106 | S14: =Q14*R14 -> 1520
A15: ='Raw Data'!A18 -> St Finbars | B15: ='Raw Data'!B18 -> Bullying | C15: =IF(B15="bullying",1,0) -> 1 | H15: ='Raw Data'!A18 -> St Finbars | I15: ='Raw Data'!B18 -> Bullying | J15: ='Raw Data'!F18 -> 1 | K15: ='Raw Data'!G18 -> 1 | L15: =C15 -> 1 | M15: =D15 -> 0 | N15: =E15 -> 0 | O15: =F15 -> 0 | P15: Bullying | Q15: ='Raw Data'!D18 -> 89 | R15: ='Raw Data'!J18 -> 16.853933 | S15: =Q15*R15 -> 1500
A16: ='Raw Data'!A19 -> Edithvale prim | B16: ='Raw Data'!B19 -> conflict res | C16: 1 | H16: ='Raw Data'!A19 -> Edithvale prim | I16: ='Raw Data'!B19 -> conflict res | J16: ='Raw Data'!F19 -> 1 | K16: ='Raw Data'!G19 -> 1 | L16: =C16 -> 1 | M16: =D16 -> 0 | N16: =E16 -> 0 | O16: =F16 -> 0 | P16: conflict res | Q16: ='Raw Data'!D19 -> 67 | R16: ='Raw Data'!J19 -> 20.149254 | S16: =Q16*R16 -> 1350
A17: ='Raw Data'!A20 -> Anglicare | B17: ='Raw Data'!B20 -> school ret | C17: =IF(B17="bullying",1,0) -> 0 | E17: 1 | H17: ='Raw Data'!A20 -> Anglicare | I17: ='Raw Data'!B20 -> school ret | J17: ='Raw Data'!F20 -> 0 | K17: ='Raw Data'!G20 -> 0 | L17: =C17 -> 0 | M17: =D17 -> 0 | N17: =E17 -> 1 | O17: =F17 -> 0 | P17: school ret | Q17: ='Raw Data'!D20 -> 14 | R17: ='Raw Data'!J20 -> 71.428571 | S17: =Q17*R17 -> 1000
C18: =SUM(C2:C17) -> 8 | D18: =SUM(D2:D17) -> 1 | E18: =SUM(E2:E17) -> 4 | F18: =SUM(F2:F17) -> 3 | J18: =SUM(J2:J17) -> 24 | K18: =SUM(K2:K17) -> 32 | L18: =SUM(L2:L17) -> 8 | M18: =SUM(M2:M17) -> 1 | N18: =SUM(N2:N17) -> 4 | O18: =SUM(O2:O17) -> 3
C19: =C1 -> Peer skills | D19: =D1 -> Culture | E19: =E1 -> School Retention | F19: =F1 -> Health | K19: =J18+K18 -> 56
A21: ='Raw Data'!A4 -> Auspice | B21: ='Raw Data'!F4 -> schools | C21: ='Raw Data'!G4 -> orgns | J21: =C1 -> Peer skills | K21: =D1 -> Culture | L21: =E1 -> School Retention | M21: =F1 -> Health
A22: ='Raw Data'!A5 -> B'ton prim, sec | B22: ='Raw Data'!F5 -> 2 | C22: ='Raw Data'!G5 -> 2 | I22: Schools | J22: =SUM(J2+J3+J5+J7+J10+J12+J15+J16) -> 12 | K22: =SUM(J6) -> 1 | L22: =SUM(J4+J11+J14+J17) -> 5 | M22: =SUM(J8+J9+J13) -> 6
A23: ='Raw Data'!A6 -> Mordi Chels Sec | B23: ='Raw Data'!F6 -> 1 | C23: ='Raw Data'!G6 -> 2 | I23: Organisations | J23: =SUM(K2+K3+K5+K7+K10+K12+K15+K16) -> 13 | K23: =SUM(K6) -> 1 | L23: =SUM(K4+K11+K14+K17) -> 6 | M23: =SUM(K8+K9+K13) -> 12
A24: ='Raw Data'!A7 -> Gordon Homes | B24: ='Raw Data'!F7 -> 3 | C24: ='Raw Data'!G7 -> 1 | I24: programs | J24: =SUM(L18) -> 8 | K24: 1 | L24: 4 | M24: 3
A25: ='Raw Data'!A8 -> Bayside council | B25: ='Raw Data'!F8 -> 4 | C25: ='Raw Data'!G8 -> 2
A26: ='Raw Data'!A9 -> Kingston council | B26: ='Raw Data'!F9 -> 1 | C26: ='Raw Data'!G9 -> 1
A27: ='Raw Data'!A10 -> Clarinda prim | B27: ='Raw Data'!F10 -> 1 | C27: ='Raw Data'!G10 -> 1 | H27: issue | I27: Program | J27: children | K27: Peer skills | L27: Culture | M27: School Retention | N27: Health
A28: ='Raw Data'!A11 -> Bayside Youth Found | B28: ='Raw Data'!F11 -> 2 | C28: ='Raw Data'!G11 -> 6 | H28: Bullying | I28: Bentleigh/SFL dads | J28: =Q2 -> 141 | K28: 1
A29: ='Raw Data'!A12 -> CBCHS | B29: ='Raw Data'!F12 -> 3 | C29: ='Raw Data'!G12 -> 3 | H29: Anger mgt | I29: Kings/Comm health | J29: =Q3 -> 7 | K29: 1
A30: ='Raw Data'!A13 -> Chelsea prim | B30: ='Raw Data'!F13 -> 1 | C30: ='Raw Data'!G13 -> 2 | H30: school ret | I30: homework | J30: =Q4 -> 4 | K30: =IF(J30="bullying",1,0) -> 0 | M30: 1
A31: ='Raw Data'!A14 -> Kibreda | B31: ='Raw Data'!F14 -> 1 | C31: ='Raw Data'!G14 -> 4 | H31: Peer skills | I31: Kids Help Line | J31: =Q5 -> 148 | K31: 1
A32: ='Raw Data'!A15 -> Brighton Beach prim | B32: ='Raw Data'!F15 -> 1 | C32: ='Raw Data'!G15 -> 2 | H32: culture | I32: Kingston | J32: =Q6 -> 19 | K32: =IF(J32="bullying",1,0) -> 0 | L32: 1
A33: ='Raw Data'!A16 -> CBCHS | B33: ='Raw Data'!F16 -> 1 | C33: ='Raw Data'!G16 -> 3 | H33: bullying | I33: REFS | J33: =Q7 -> 66 | K33: 1
A34: ='Raw Data'!A17 -> Chelt sec | B34: ='Raw Data'!F17 -> 1 | C34: ='Raw Data'!G17 -> 1 | H34: body image | I34: JPET/BBCH | J34: =Q8 -> 38 | K34: =IF(J34="bullying",1,0) -> 0 | N34: 1
A35: ='Raw Data'!A18 -> St Finbars | B35: ='Raw Data'!F18 -> 1 | C35: ='Raw Data'!G18 -> 1 | H35: health, D/A | I35: Kingston | J35: =Q9 -> 60 | K35: =IF(J35="bullying",1,0) -> 0 | N35: 1
A36: ='Raw Data'!A19 -> Edithvale prim | B36: ='Raw Data'!F19 -> 1 | C36: ='Raw Data'!G19 -> 1 | H36: anger mgt | I36: REFS/SFL | J36: =Q10 -> 92 | K36: 1
A37: ='Raw Data'!A20 -> Anglicare | B37: ='Raw Data'!F20 -> 0 | C37: ='Raw Data'!G20 -> 0 | H37: school ret | I37: Kilb/SFL | J37: =Q11 -> 30 | K37: =IF(J37="bullying",1,0) -> 0 | M37: 1
H38: conflict res | I38: Schools Med | J38: =Q12 -> 56 | K38: 1
H39: health, D/A | I39: Kingst/SFL | J39: =Q13 -> 32 | K39: =IF(J39="bullying",1,0) -> 0 | N39: 1
H40: school ret | I40: Angli h/w | J40: =Q14 -> 691 | K40: =IF(J40="bullying",1,0) -> 0 | M40: 1
H41: Bullying | I41: REFS | J41: =Q15 -> 89 | K41: =IF(J41="bullying",1,0) -> 0
...

Sheet charts 2001 not printed
A1: Auspice | B1: issue | C1: Peer skills | D1: School retention | E1: Sibling camps
A2: St Brigids | B2: peerskills | C2: 1
A3: Aspendale prim | B3: peerskills | C3: 1
A4: Mentone Park pri | B4: peerskills | C4: 1
A5: St Agnes | B5: dads | C5: 1
A6: Bayside Youthschool ret | D6: 1
A7: Noah's Ark | B7: sibling camps | E7: 1 | AC7: 25/1/200225/1/2002
A8: Gardenvale pri | B8: life skills | C8: 1
A9: Bayside council | B9: life skills | C9: 1
A10: St Josephs | B10: peerskills | C10: 1
A11: St Patricks | B11: bullying | C11: 1
A12: Moordialloc pri | B12: bullying | C12: 1
C13: =SUM(C2:C12) -> 9 | D13: 1 | E13: 1
A15: Auspice | B15: schools | C15: orgns | D15: children | E15: $$ per child
A16: St Brigids | B16: 1 | C16: 2 | D16: 42 | E16: 35.714286 | F16: =E16*D16 -> 1500
A17: Aspendale prim | B17: 1 | C17: 1 | D17: 90 | E17: 16.666667 | F17: =E17*D17 -> 1500
A18: Mentone Park pri | B18: 1 | C18: 1 | D18: 30 | E18: 47.666667 | F18: =E18*D18 -> 1430
A19: St Agnes | B19: 1 | C19: 1 | D19: 102 | E19: 5.8823529 | F19: =E19*D19 -> 600
A20: Bayside Youth | B20: 8 | C20: 3 | D20: 0 | E20: N/A | F20: N/A
A21: Noah's Ark | B21: 4 | C21: 3 | D21: 19 | E21: 842.35842 | F21: =E21*D21 -> 16004.81
A22: Gardenvale pri | B22: 1 | C22: 1 | D22: 54 | E22: 26.703704 | F22: =E22*D22 -> 1442
A23: Bayside council | B23: 1 | C23: 2 | D23: 8 | E23: 118.25 | F23: =E23*D23 -> 946
A24: St Josephs | B24: 1 | C24: 1 | D24: 23 | E24: 62.173913 | F24: =E24*D24 -> 1430
A25: St Patricks | B25: 1 | C25: 1 | D25: 50 | E25: 30 | F25: =E25*D25 -> 1500
A26: Moordialloc pri | B26: 1 | C26: 1 | D26: 74 | E26: 20.27027 | F26: =E26*D26 -> 1500
B29: Peer skills | C29: School retention | D29: Sibling camps
A30: Children | B30: =SUM(D16+D17+D18+D19+D22+D23+D24+D25+D26) -> 473 | C30: 0 | D30: 19
A31: Dollars | B31: =SUM(F16+F17+F18+F19+F22+F23+F24+F25+F26) -> 11848 | C31: 0 | D31: 842.35842
A32: Dollars per Child | B32: =B31/B30 -> 25.048626 | C32: =C31/D13 -> 0 | D32: =D31/E13 -> 842.35842
B35: Peer skills | C35: School retention | D35: Sibling camps
A36: schools | B36: =SUM(B16+B17+B18+B19+B22+B23+B24+B25+B26) -> 9 | C36: =SUM(B20) -> 8 | D36: 4
A37: organisations | B37: =SUM(C16+C17+C18+C19+C22+C23+C24+C25+C26) -> 11 | C37: 3 | D37: 3

Sheet Age Data
A1: School Focused Youth Service Data
B2: 2000 - 16 projects | M2: Primary | Q2: Secondary
A3: Auspice | B3: issue | C3: Program | D3: Children | E3: Primary | F3: Secondary | G3: Peer skills | H3: Culture | I3: Health | J3: School Retention | K3: ='Raw Data'!I4 -> $$ per child | M3: =G3 -> Peer skills | N3: =H3 -> Culture | O3: =I3 -> Health | P3: =J3 -> School Retention | Q3: =M3 -> Peer skills | R3: =N3 -> Culture | S3: =O3 -> Health | T3: =P3 -> School Retention
A4: B'ton prim, sec | B4: Bullying | C4: Bentleigh/SFL dads | D4: 141 | E4: 141 | G4: 1 | K4: ='Raw Data'!I5 -> 10.26393 | L4: ='Raw Data'!K5 -> 3500 | M4: =IF(G4=1,$K4*$E4,0) -> 1447.2141 | N4: =IF(H4=1,$K4*$E4,0) -> 0 | O4: =IF(I4=1,$K4*$E4,0) -> 0 | P4: =IF(J4=1,$K4*$E4,0) -> 0 | Q4: =IF(G4=1,$K4*$F4,0) -> 0 | R4: =IF(H4=1,$K4*$F4,0) -> 0 | S4: =IF(I4=1,$K4*$F4,0) -> 0 | T4: =IF(J4=1,$K4*$F4,0) -> 0
A5: Mordi Chels Sec | B5: Anger mgt | C5: Kings/Comm health | D5: 7 | F5: 7 | G5: 1 | K5: ='Raw Data'!I6 -> 290.02857 | L5: ='Raw Data'!K6 -> 2030.2 | M5: =IF(G5=1,$K5*$E5,0) -> 0 | N5: =IF(H5=1,$K5*$E5,0) -> 0 | O5: =IF(I5=1,$K5*$E5,0) -> 0 | P5: =IF(J5=1,$K5*$E5,0) -> 0 | Q5: =IF(G5=1,$K5*$F5,0) -> 2030.2 | R5: =IF(H5=1,$K5*$F5,0) -> 0 | S5: =IF(I5=1,$K5*$F5,0) -> 0 | T5: =IF(J5=1,$K5*$F5,0) -> 0
A6: Gordon Homes | B6: school ret | C6: homework | D6: 4 | E6: 2 | F6: 2 | J6: 1 | K6: ='Raw Data'!I7 -> 875 | L6: ='Raw Data'!K7 -> 3500 | M6: =IF(G6=1,$K6*$E6,0) -> 0 | N6: =IF(H6=1,$K6*$E6,0) -> 0 | O6: =IF(I6=1,$K6*$E6,0) -> 0 | P6: =IF(J6=1,$K6*$E6,0) -> 1750 | Q6: =IF(G6=1,$K6*$F6,0) -> 0 | R6: =IF(H6=1,$K6*$F6,0) -> 0 | S6: =IF(I6=1,$K6*$F6,0) -> 0 | T6: =IF(J6=1,$K6*$F6,0) -> 1750
A7: Bayside council | B7: Peer skills | C7: Kids Help Line | D7: 148 | F7: 148 | G7: 1 | K7: ='Raw Data'!I8 -> 26.216216 | L7: ='Raw Data'!K8 -> 3880 | M7: =IF(G7=1,$K7*$E7,0) -> 0 | N7: =IF(H7=1,$K7*$E7,0) -> 0 | O7: =IF(I7=1,$K7*$E7,0) -> 0 | P7: =IF(J7=1,$K7*$E7,0) -> 0 | Q7: =IF(G7=1,$K7*$F7,0) -> 3880 | R7: =IF(H7=1,$K7*$F7,0) -> 0 | S7: =IF(I7=1,$K7*$F7,0) -> 0 | T7: =IF(J7=1,$K7*$F7,0) -> 0
A8: Kingston council | B8: culture | C8: Kingston | D8: 19 | F8: 19 | H8: 1 | K8: ='Raw Data'!I9 -> 180.28632 | L8: ='Raw Data'!K9 -> 3425.44 | M8: =IF(G8=1,$K8*$E8,0) -> 0 | N8: =IF(H8=1,$K8*$E8,0) -> 0 | O8: =IF(I8=1,$K8*$E8,0) -> 0 | P8: =IF(J8=1,$K8*$E8,0) -> 0 | Q8: =IF(G8=1,$K8*$F8,0) -> 0 | R8: =IF(H8=1,$K8*$F8,0) -> 3425.44 | S8: =IF(I8=1,$K8*$F8,0) -> 0 | T8: =IF(J8=1,$K8*$F8,0) -> 0
A9: Clarinda prim | B9: bullying | C9: REFS | D9: 66 | E9: 66 | G9: 1 | K9: ='Raw Data'!I10 -> 45.454545 | L9: ='Raw Data'!K10 -> 3000 | M9: =IF(G9=1,$K9*$E9,0) -> 3000 | N9: =IF(H9=1,$K9*$E9,0) -> 0 | O9: =IF(I9=1,$K9*$E9,0) -> 0 | P9: =IF(J9=1,$K9*$E9,0) -> 0 | Q9: =IF(G9=1,$K9*$F9,0) -> 0 | R9: =IF(H9=1,$K9*$F9,0) -> 0 | S9: =IF(I9=1,$K9*$F9,0) -> 0 | T9: =IF(J9=1,$K9*$F9,0) -> 0
A10: Bayside Youth Found | B10: body image | C10: JPET/BBCH | D10: 38 | E10: 1 | F10: 37 | I10: 1 | K10: ='Raw Data'!I11 -> 92.105263 | L10: ='Raw Data'!K11 -> 3500 | M10: =IF(G10=1,$K10*$E10,0) -> 0 | N10: =IF(H10=1,$K10*$E10,0) -> 0 | O10: =IF(I10=1,$K10*$E10,0) -> 92.105263 | P10: =IF(J10=1,$K10*$E10,0) -> 0 | Q10: =IF(G10=1,$K10*$F10,0) -> 0 | R10: =IF(H10=1,$K10*$F10,0) -> 0 | S10: =IF(I10=1,$K10*$F10,0) -> 3407.8947 | T10: =IF(J10=1,$K10*$F10,0) -> 0
A11: CBCHS | B11: health, D/A | C11: Kingston | D11: 60 | F11: 60 | I11: 1 | K11: ='Raw Data'!I12 -> 27.5 | L11: ='Raw Data'!K12 -> 1650 | M11: =IF(G11=1,$K11*$E11,0) -> 0 | N11: =IF(H11=1,$K11*$E11,0) -> 0 | O11: =IF(I11=1,$K11*$E11,0) -> 0 | P11: =IF(J11=1,$K11*$E11,0) -> 0 | Q11: =IF(G11=1,$K11*$F11,0) -> 0 | R11: =IF(H11=1,$K11*$F11,0) -> 0 | S11: =IF(I11=1,$K11*$F11,0) -> 1650 | T11: =IF(J11=1,$K11*$F11,0) -> 0
A12: Chelsea prim | B12: anger mgt | C12: REFS/SFL | D12: 92 | E12: 92 | G12: 1 | K12: ='Raw Data'!I13 -> 32.608696 | L12: ='Raw Data'!K13 -> 3000 | M12: =IF(G12=1,$K12*$E12,0) -> 3000 | N12: =IF(H12=1,$K12*$E12,0) -> 0 | O12: =IF(I12=1,$K12*$E12,0) -> 0 | P12: =IF(J12=1,$K12*$E12,0) -> 0 | Q12: =IF(G12=1,$K12*$F12,0) -> 0 | R12: =IF(H12=1,$K12*$F12,0) -> 0 | S12: =IF(I12=1,$K12*$F12,0) -> 0 | T12: =IF(J12=1,$K12*$F12,0) -> 0
A13: Kibreda | B13: school ret | C13: homework | D13: 30 | F13: 30 | J13: 1 | K13: ='Raw Data'!I14 -> 85.365854 | L13: ='Raw Data'!K14 -> 3500 | M13: =IF(G13=1,$K13*$E13,0) -> 0 | N13: =IF(H13=1,$K13*$E13,0) -> 0 | O13: =IF(I13=1,$K13*$E13,0) -> 0 | P13: =IF(J13=1,$K13*$E13,0) -> 0 | Q13: =IF(G13=1,$K13*$F13,0) -> 0 | R13: =IF(H13=1,$K13*$F13,0) -> 0 | S13: =IF(I13=1,$K13*$F13,0) -> 0 | T13: =IF(J13=1,$K13*$F13,0) -> 2560.9756
A14: Brighton Beach prim | B14: conflict res | C14: Schools Med | D14: 56 | E14: 56 | G14: 1 | K14: ='Raw Data'!I15 -> 18.5 | L14: ='Raw Data'!K15 -> 2035 | M14: =IF(G14=1,$K14*$E14,0) -> 1036 | N14: =IF(H14=1,$K14*$E14,0) -> 0 | O14: =IF(I14=1,$K14*$E14,0) -> 0 | P14: =IF(J14=1,$K14*$E14,0) -> 0 | Q14: =IF(G14=1,$K14*$F14,0) -> 0 | R14: =IF(H14=1,$K14*$F14,0) -> 0 | S14: =IF(I14=1,$K14*$F14,0) -> 0 | T14: =IF(J14=1,$K14*$F14,0) -> 0
A15: CBCHS | B15: health, D/A | C15: Kingst/SFL | D15: 32 | F15: 32 | I15: 1 | K15: ='Raw Data'!I16 -> 31.03125 | L15: ='Raw Data'!K16 -> 993 | M15: =IF(G15=1,$K15*$E15,0) -> 0 | N15: =IF(H15=1,$K15*$E15,0) -> 0 | O15: =IF(I15=1,$K15*$E15,0) -> 0 | P15: =IF(J15=1,$K15*$E15,0) -> 0 | Q15: =IF(G15=1,$K15*$F15,0) -> 0 | R15: =IF(H15=1,$K15*$F15,0) -> 0 | S15: =IF(I15=1,$K15*$F15,0) -> 993 | T15: =IF(J15=1,$K15*$F15,0) -> 0
A16: Chelt sec | B16: school ret | C16: Angli h/w | D16: 691 | F16: 691 | J16: 1 | K16: ='Raw Data'!I17 -> 2.1997106 | L16: ='Raw Data'!K17 -> 1520 | M16: =IF(G16=1,$K16*$E16,0) -> 0 | N16: =IF(H16=1,$K16*$E16,0) -> 0 | O16: =IF(I16=1,$K16*$E16,0) -> 0 | P16: =IF(J16=1,$K16*$E16,0) -> 0 | Q16: =IF(G16=1,$K16*$F16,0) -> 0 | R16: =IF(H16=1,$K16*$F16,0) -> 0 | S16: =IF(I16=1,$K16*$F16,0) -> 0 | T16: =IF(J16=1,$K16*$F16,0) -> 1520
A17: St Finbars | B17: Bullying | C17: REFS | D17: 89 | E17: 89 | G17: 1 | K17: ='Raw Data'!I18 -> 16.853933 | L17: ='Raw Data'!K18 -> 1500 | M17: =IF(G17=1,$K17*$E17,0) -> 1500 | N17: =IF(H17=1,$K17*$E17,0) -> 0 | O17: =IF(I17=1,$K17*$E17,0) -> 0 | P17: =IF(J17=1,$K17*$E17,0) -> 0 | Q17: =IF(G17=1,$K17*$F17,0) -> 0 | R17: =IF(H17=1,$K17*$F17,0) -> 0 | S17: =IF(I17=1,$K17*$F17,0) -> 0 | T17: =IF(J17=1,$K17*$F17,0) -> 0
A18: Edithvale prim | B18: conflict res | C18: REFS | D18: 67 | E18: 67 | G18: 1 | K18: ='Raw Data'!I19 -> 20.149254 | L18: ='Raw Data'!K19 -> 1350 | M18: =IF(G18=1,$K18*$E18,0) -> 1350 | N18: =IF(H18=1,$K18*$E18,0) -> 0 | O18: =IF(I18=1,$K18*$E18,0) -> 0 | P18: =IF(J18=1,$K18*$E18,0) -> 0 | Q18: =IF(G18=1,$K18*$F18,0) -> 0 | R18: =IF(H18=1,$K18*$F18,0) -> 0 | S18: =IF(I18=1,$K18*$F18,0) -> 0 | T18: =IF(J18=1,$K18*$F18,0) -> 0 | U18: 2000
A19: Anglicare | B19: school ret | C19: homework | D19: 14 | E19: 0 | F19: 14 | J19: 1 | K19: ='Raw Data'!I20 -> 71.428571 | L19: 0 | M19: =IF(G19=1,$K19*$E19,0) -> 0 | N19: =IF(H19=1,$K19*$E19,0) -> 0 | O19: =IF(I19=1,$K19*$E19,0) -> 0 | P19: 0 | Q19: =IF(G19=1,$K19*$F19,0) -> 0 | R19: =IF(H19=1,$K19*$F19,0) -> 0 | S19: =IF(I19=1,$K19*$F19,0) -> 0 | T19: 0 | U19: primary | V19: secondary
E20: =SUM(E4:E19) -> 514 | F20: =SUM(F5:F16) -> 1026 | G20: =SUM(G4:G18) -> 8 | H20: 1 | I20: 3 | J20: 4 | L20: =SUM(L4:L19) -> 38383.64 | M20: =SUM(M4:M19) -> 11333.214 | N20: =SUM(N4:N19) -> 0 | O20: =SUM(O4:O19) -> 92.105263 | P20: =SUM(P4:P19) -> 1750 | Q20: =SUM(Q4:Q19) -> 5910.2 | R20: =SUM(R4:R19) -> 3425.44 | S20: =SUM(S4:S19) -> 6050.8947 | T20: =SUM(T4:T19) -> 5830.9756 | U20: =SUM(M20:P20) -> 13175.319 | V20: =SUM(Q20:T20) -> 21217.51
M21: ='Age Charts'!B23 -> 511 | N21: ='Age Charts'!C23 -> 0 | O21: ='Age Charts'!D23 -> 1 | P21: ='Age Charts'!E23 -> 2 | Q21: ='Age Charts'!B24 -> 155 | R21: ='Age Charts'!C24 -> 19 | S21: ='Age Charts'!D24 -> 129 | T21: ='Age Charts'!E24 -> 723 | U21: =SUM(M21:P21) -> 514 | V21: =SUM(Q21:T21) -> 1026
B22: 2001 - 11 projects | M22: =M20/M21 -> 22.178501 | N22: 0 | O22: =O20/O21 -> 92.105263 | P22: =P20/P21 -> 875 | Q22: =Q20/Q21 -> 38.130323 | R22: =R20/R21 -> 180.28632 | S22: =S20/S21 -> 46.906161 | T22: =T20/T21 -> 8.0649732 | U22: =U20/U21 -> 25.632917 | V22: =S37 -> 39.036786
A23: Auspice | B23: issue | C23: program | D23: Children | E23: Primary | F23: Secondary | G23: Peer skills | H23: School Retention | I23: Sibling camps | K23: =K3 -> $$ per child | M23: Peer skills | N23: School Retention | O23: Sibling camps | P23: Peer skills | Q23: School Retention | R23: Sibling camps | U23: 2001
A24: St Brigids | B24: peerskills | C24: REFS/SFL | D24: 42 | E24: 42 | G24: 1 | K24: ='Raw Data'!I26 -> 35.714286 | M24: =IF(G24=1,$K24*$E24,0) -> 1500 | N24: =IF(H24=1,$K24*$E24,0) -> 0 | O24: =IF(I24=1,$K24*$E24,0) -> 0 | P24: =IF(G24=1,$K24*$F24,0) -> 0 | Q24: =IF(H24=1,$K24*$F24,0) -> 0 | R24: =IF(I24=1,$K24*$F24,0) -> 0 | U24: primary | V24: secondary
A25: Aspendale prim | B25: peerskills | C25: REFS | D25: 90 | E25: 90 | G25: 1 | K25: ='Raw Data'!I27 -> 16.666667 | M25: =IF(G25=1,$K25*$E25,0) -> 1500 | N25: =IF(H25=1,$K25*$E25,0) -> 0 | O25: =IF(I25=1,$K25*$E25,0) -> 0 | P25: =IF(G25=1,$K25*$F25,0) -> 0 | Q25: =IF(H25=1,$K25*$F25,0) -> 0 | R25: =IF(I25=1,$K25*$F25,0) -> 0 | U25: =SUM(M35:O35) -> 17605.618 | V25: =SUM(P35:R35) -> 1600.481
A26: Mentone Park pri | B26: peerskills | C26: REFS | D26: 30 | E26: 30 | G26: 1 | K26: ='Raw Data'!I28 -> 47.666667 | M26: =IF(G26=1,$K26*$E26,0) -> 1430 | N26: =IF(H26=1,$K26*$E26,0) -> 0 | O26: =IF(I26=1,$K26*$E26,0) -> 0 | P26: =IF(G26=1,$K26*$F26,0) -> 0 | Q26: =IF(H26=1,$K26*$F26,0) -> 0 | R26: =IF(I26=1,$K26*$F26,0) -> 0 | U26: =SUM(M36:O36) -> 488 | V26: 4
A27: St Agnes | B27: dads | C27: SFL dads | D27: 102 | E27: 102 | G27: 1 | K27: ='Raw Data'!I29 -> 3.4883721 | M27: =IF(G27=1,$K27*$E27,0) -> 355.81395 | N27: =IF(H27=1,$K27*$E27,0) -> 0 | O27: =IF(I27=1,$K27*$E27,0) -> 0 | P27: =IF(G27=1,$K27*$F27,0) -> 0 | Q27: =IF(H27=1,$K27*$F27,0) -> 0 | R27: =IF(I27=1,$K27*$F27,0) -> 0 | U27: =U25/U26 -> 36.077085 | V27: =V25/V26 -> 400.12025
A28: Bayside Youth school ret | C28: homework | D28: 0 | E28: 0 | F28: 0 | H28: 1 | K28: ='Raw Data'!I30 -> N/A | M28: =IF(G28=1,$K28*$E28,0) -> 0 | N28: 0 | O28: =IF(I28=1,$K28*$E28,0) -> 0 | P28: =IF(G28=1,$K28*$F28,0) -> 0 | Q28: 0 | R28: =IF(I28=1,$K28*$F28,0) -> 0
A29: Noah's Ark | B29: sibling camps | D29: 19 | E29: 15 | F29: 4 | I29: 1 | K29: ='Raw Data'!I31 -> 400.12025 | M29: =IF(G29=1,$K29*$E29,0) -> 0 | N29: =IF(H29=1,$K29*$E29,0) -> 0 | O29: =IF(I29=1,$K29*$E29,0) -> 6001.8038 | P29: =IF(G29=1,$K29*$F29,0) -> 0 | Q29: =IF(H29=1,$K29*$F29,0) -> 0 | R29: =IF(I29=1,$K29*$F29,0) -> 1600.481
A30: Gardenvale pri | B30: life skills | C30: BCC/ Jugglers | D30: 54 | E30: 54 | G30: 1 | K30: ='Raw Data'!I32 -> 26.703704 | M30: =IF(G30=1,$K30*$E30,0) -> 1442 | N30: =IF(H30=1,$K30*$E30,0) -> 0 | O30: =IF(I30=1,$K30*$E30,0) -> 0 | P30: =IF(G30=1,$K30*$F30,0) -> 0 | Q30: =IF(H30=1,$K30*$F30,0) -> 0 | R30: =IF(I30=1,$K30*$F30,0) -> 0
A31: Bayside council | B31: life skills | C31: BCC/ Jugglers | D31: 8 | E31: 8 | G31: 1 | K31: ='Raw Data'!I33 -> 118.25 | M31: =IF(G31=1,$K31*$E31,0) -> 946 | N31: =IF(H31=1,$K31*$E31,0) -> 0 | O31: =IF(I31=1,$K31*$E31,0) -> 0 | P31: =IF(G31=1,$K31*$F31,0) -> 0 | Q31: =IF(H31=1,$K31*$F31,0) -> 0 | R31: =IF(I31=1,$K31*$F31,0) -> 0
A32: St Josephs | B32: peerskills | C32: REFS | D32: 23 | E32: 23 | G32: 1 | K32: ='Raw Data'!I34 -> 62.173913 | M32: =IF(G32=1,$K32*$E32,0) -> 1430 | N32: =IF(H32=1,$K32*$E32,0) -> 0 | O32: =IF(I32=1,$K32*$E32,0) -> 0 | P32: =IF(G32=1,$K32*$F32,0) -> 0 | Q32: =IF(H32=1,$K32*$F32,0) -> 0 | R32: =IF(I32=1,$K32*$F32,0) -> 0
A33: St Patricks | B33: bullying | C33: SFL (NOV) | D33: 50 | E33: 50 | G33: 1 | K33: ='Raw Data'!I35 -> 30 | M33: =IF(G33=1,$K33*$E33,0) -> 1500 | N33: =IF(H33=1,$K33*$E33,0) -> 0 | O33: =IF(I33=1,$K33*$E33,0) -> 0 | P33: =IF(G33=1,$K33*$F33,0) -> 0 | Q33: =IF(H33=1,$K33*$F33,0) -> 0 | R33: =IF(I33=1,$K33*$F33,0) -> 0
A34: Moordialloc pri | B34: bullying | C34: SFL (NOV) | D34: 74 | E34: 74 | G34: 1 | K34: ='Raw Data'!I36 -> 20.27027 | M34: =IF(G34=1,$K34*$E34,0) -> 1500 | N34: =IF(H34=1,$K34*$E34,0) -> 0 | O34: =IF(I34=1,$K34*$E34,0) -> 0 | P34: =IF(G34=1,$K34*$F34,0) -> 0 | Q34: =IF(H34=1,$K34*$F34,0) -> 0 | R34: =IF(I34=1,$K34*$F34,0) -> 0
E35: =SUM(E24:E34) -> 488 | F35: =SUM(F28:F34) -> 4 | G35: =SUM(G24:G34) -> 9 | H35: 1 | I35: 1 | M35: =SUM(M24:M34) -> 11603.814 | N35: =SUM(N24:N34) -> 0 | O35: =SUM(O24:O34) -> 6001.8038 | P35: =SUM(P24:P34) -> 0 | Q35: =SUM(Q24:Q34) -> 0 | R35: =SUM(R24:R34) -> 1600.481 | S35: =SUM(M35:R35) -> 19206.099
A36: Total particips | B36: =SUM(E20+E35) -> 1002 | C36: =SUM(F35+F20) -> 1030 | M36: ='Age Charts'!B44 -> 473 | N36: ='Age Charts'!C44 -> 0 | O36: ='Age Charts'!D44 -> 15 | P36: ='Age Charts'!B45 -> 0 | Q36: ='Age Charts'!C45 -> 0 | R36: ='Age Charts'!D45 -> 4 | S36: =SUM(M36:R36) -> 492
M37: =M35/M36 -> 24.532376 | N37: 0 | O37: =O35/O36 -> 400.12025 | P37: 0 | Q37: 0 | R37: =R35/R36 -> 400.12025 | S37: =S35/S36 -> 39.036786

Sheet Age Charts
A1: Primary | B1: Secondary | C1: Peer skills | D1: Culture | E1: Health | F1: School Retention | G1: ='Age Data'!K3 -> $$ per child
A2: 141 | C2: 1 | G2: ='Age Data'!K4 -> 10.26393
B3: 7 | C3: 1 | G3: ='Age Data'!K5 -> 290.02857
A4: 2 | B4: 2 | F4: 1 | G4: ='Age Data'!K6 -> 875
B5: 148 | C5: 1 | G5: ='Age Data'!K7 -> 26.216216
B6: 19 | D6: 1 | G6: ='Age Data'!K8 -> 180.28632
A7: 66 | C7: 1 | G7: ='Age Data'!K9 -> 45.454545
A8: 1 | B8: 37 | E8: 1 | G8: ='Age Data'!K10 -> 92.105263
B9: 60 | E9: 1 | G9: ='Age Data'!K11 -> 27.5
A10: 92 | C10: 1 | G10: ='Age Data'!K12 -> 32.608696
B11: 30 | F11: 1 | G11: ='Age Data'!K13 -> 85.365854
A12: 56 | C12: 1 | G12: ='Age Data'!K14 -> 18.5
B13: 32 | E13: 1 | G13: ='Age Data'!K15 -> 31.03125
B14: 691 | F14: 1 | G14: ='Age Data'!K16 -> 2.1997106
A15: 89 | C15: 1 | G15: ='Age Data'!K17 -> 16.853933
A16: 67 | C16: 1 | G16: ='Age Data'!K18 -> 20.149254
A17: 0 | B17: 14 | F17: 1 | G17: ='Age Data'!K19 -> 71.428571
A18: =SUM(A2:A17) -> 514 | B18: =SUM(B3:B14) -> 1026 | C18: =SUM(C2:C16) -> 8 | D18: 1 | E18: 3 | F18: 4
A21: 2000
B22: Peer skills | C22: Culture | D22: Health | E22: School Retention
A23: Primary | B23: =SUM(A2+A7+A10+A12+A15+A16) -> 511 | C23: 0 | D23: =SUM(A8) -> 1 | E23: =SUM(A4) -> 2 | F23: particpants
A24: Secondary | B24: =SUM(B3+B5) -> 155 | C24: =B6 -> 19 | D24: =SUM(B8+B9+B13) -> 129 | E24: =SUM(B4+B11+B14) -> 723
A25: Primary | B25: ='Age Data'!M22 -> 22.178501 | C25: ='Age Data'!N22 -> 0 | D25: ='Age Data'!O22 -> 92.105263 | E25: ='Age Data'!P22 -> 875 | F25: $$ per participant
A26: Secondary | B26: ='Age Data'!Q22 -> 38.130323 | C26: ='Age Data'!R22 -> 180.28632 | D26: ='Age Data'!S22 -> 46.906161 | E26: ='Age Data'!T22 -> 8.0649732
A29: ='Age Data'!E23 -> Primary | B29: ='Age Data'!F23 -> Secondary | C29: ='Age Data'!G23 -> Peer skills | D29: ='Age Data'!H23 -> School Retention | E29: ='Age Data'!I23 -> Sibling camps | F29: ='Age Data'!K23 -> $$ per child
A30: ='Age Data'!E24 -> 42 | B30: ='Age Data'!F24 -> 0 | C30: ='Age Data'!G24 -> 1 | D30: ='Age Data'!H24 -> 0 | E30: ='Age Data'!I24 -> 0 | F30: ='Age Data'!K24 -> 35.714286
A31: ='Age Data'!E25 -> 90 | B31: ='Age Data'!F25 -> 0 | C31: ='Age Data'!G25 -> 1 | D31: ='Age Data'!H25 -> 0 | E31: ='Age Data'!I25 -> 0 | F31: ='Age Data'!K25 -> 16.666667
A32: ='Age Data'!E26 -> 30 | B32: ='Age Data'!F26 -> 0 | C32: ='Age Data'!G26 -> 1 | D32: ='Age Data'!H26 -> 0 | E32: ='Age Data'!I26 -> 0 | F32: ='Age Data'!K26 -> 47.666667
A33: ='Age Data'!E27 -> 102 | B33: ='Age Data'!F27 -> 0 | C33: ='Age Data'!G27 -> 1 | D33: ='Age Data'!H27 -> 0 | E33: ='Age Data'!I27 -> 0 | F33: ='Age Data'!K27 -> 3.4883721
A34: ='Age Data'!E28 -> 0 | B34: ='Age Data'!F28 -> 0 | C34: ='Age Data'!G28 -> 0 | D34: ='Age Data'!H28 -> 1 | E34: ='Age Data'!I28 -> 0 | F34: ='Age Data'!K28 -> N/A
A35: ='Age Data'!E29 -> 15 | B35: ='Age Data'!F29 -> 4 | C35: ='Age Data'!G29 -> 0 | D35: ='Age Data'!H29 -> 0 | E35: ='Age Data'!I29 -> 1 | F35: ='Age Data'!K29 -> 400.12025
A36: ='Age Data'!E30 -> 54 | B36: ='Age Data'!F30 -> 0 | C36: ='Age Data'!G30 -> 1 | D36: ='Age Data'!H30 -> 0 | E36: ='Age Data'!I30 -> 0 | F36: ='Age Data'!K30 -> 26.703704
A37: ='Age Data'!E31 -> 8 | B37: ='Age Data'!F31 -> 0 | C37: ='Age Data'!G31 -> 1 | D37: ='Age Data'!H31 -> 0 | E37: ='Age Data'!I31 -> 0 | F37: ='Age Data'!K31 -> 118.25
A38: ='Age Data'!E32 -> 23 | B38: ='Age Data'!F32 -> 0 | C38: ='Age Data'!G32 -> 1 | D38: ='Age Data'!H32 -> 0 | E38: ='Age Data'!I32 -> 0 | F38: ='Age Data'!K32 -> 62.173913
A39: ='Age Data'!E33 -> 50 | B39: ='Age Data'!F33 -> 0 | C39: ='Age Data'!G33 -> 1 | D39: ='Age Data'!H33 -> 0 | E39: ='Age Data'!I33 -> 0 | F39: ='Age Data'!K33 -> 30
A40: ='Age Data'!E34 -> 74 | B40: ='Age Data'!F34 -> 0 | C40: ='Age Data'!G34 -> 1 | D40: ='Age Data'!H34 -> 0 | E40: ='Age Data'!I34 -> 0 | F40: ='Age Data'!K34 -> 20.27027
A41: ='Age Data'!E35 -> 488 | B41: ='Age Data'!F35 -> 4 | C41: ='Age Data'!G35 -> 9 | D41: ='Age Data'!H35 -> 1 | E41: ='Age Data'!I35 -> 1
A43: 2001 | B43: =C29 -> Peer skills | C43: =D29 -> School Retention | D43: =E29 -> Sibling camps
A44: Primary | B44: =A30+A31+A32+A33+A36+A37+A38+A39+A40 -> 473 | C44: 0 | D44: 15 | E44: particpants
A45: Secondary | B45: 0 | C45: 0 | D45: =B35 -> 4
...
