Workbook
Name AP_Beg: 'AP Bal'!$C$8
Name AP_End: 'AP Bal'!$C$14
Name AP_In: 'AP Flow'!$C$12
Name AP_Out: 'AP Flow'!$C$22
Name AR_Beg: 'AP Bal'!$C$8
Name AR_Beg: 'AR Bal'!$C$8
Name AR_End: 'AP Bal'!$C$14
Name AR_End: 'AR Bal'!$C$15
Name AR_In: 'AP Flow'!$C$12
Name AR_In: 'AR Flow'!$C$17
Name AR_Out: 'AP Flow'!$C$22
Name AR_Out: 'AR Flow'!$C$31
Name Assets_Beg: 'Income Statement'!$D$20
Name Assets_Beg: 'Balance Sheet'!$D$15
Name Assets_End: 'Income Statement'!$F$20
Name Assets_End: 'Balance Sheet'!$F$15
Name Cash_Beg: 'Cash Bal'!$C$11
Name Cash_End: 'Cash Bal'!$C$20
Name Cash_In: 'Income Add'!#REF!
Name Cash_In: 'Cash Flow'!$D$23
Name Cash_Out: 'Income Add'!#REF!
Name Cash_Out: 'Cash Flow'!$D$60
Name Chapter_Name: 'Balance Sheet'!$C$5
Name Dues: 'Cash Flow'!$D$11
Name Equip_Beg: 'Equip Bal'!$D$9
Name Equip_End: 'Equip Bal'!$D$18
Name Equip_In: 'Equip Flow'!$E$10
Name Equip_Out: 'Equip Flow'!$E$18
Name Interest: 'Cash Flow'!$D$12
Name Inv_Beg: 'Inv Bal'!$E$24
Name Inv_End: 'Inv Bal'!$E$77
Name Inv_In: 'Inv Flow'!$F$30
Name Inv_Out: 'Inv Flow'!$F$66
Name Liables_Beg: 'Income Statement'!$D$28
Name Liables_Beg: 'Balance Sheet'!$D$22
Name Liables_End: 'Income Statement'!$F$28
Name Liables_End: 'Balance Sheet'!$F$22
Name Worth_Beg: 'Income Statement'!$D$30
Name Worth_Beg: 'Balance Sheet'!$D$25
Name Worth_End: 'Income Statement'!$F$30
Name Worth_End: 'Balance Sheet'!$F$25
Name Year: 'Balance Sheet'!$C$6

Sheet Balance Sheet
G1: AR~3
C2: National Space Society
C3: Creating a spacefaring civilization...
A4: This report must be filed by 15 FEB of each year.
A5: BALANCE SHEET for | C5: (Chapter Name)
A6: Fiscal year from 1 JAN | C6: 1997 | D6: to 31 DEC | E6: =Year -> 1997 | F6: .
A8: ASSETS | D8: Beginning Year | F8: Ending Year
A9: 1 | B9: Cash | D9: =Cash_Beg -> 1500 | F9: =Cash_End -> 900
A10: 2 | B10: Accounts Receivable | D10: =AR_Beg -> 0 | F10: =AR_End -> 60
B11: (money owed to you)
A12: 3 | B12: Equipment | D12: =Equip_Beg -> 370 | F12: =Equip_End -> 710
A13: 4 | B13: Inventory | D13: =Inv_Beg -> 654.79 | F13: =Inv_End -> 1174.9
A14: 5 | B14: Other (attach schedule) | D14: 0 | F14: 0
A15: 6 | B15: TOTAL ASSETS | D15: =SUM(D9:D13) -> 2524.79 | F15: =SUM(F9:F13) -> 2844.9
A17: LIABILITIES | D17: Beginning Year | F17: Ending Year
A18: 7 | B18: Accounts Payable | D18: =AP_Beg -> 25 | F18: =AP_End -> 0
B19: (money you owe)
A20: 8 | B20: Loans | D20: 0 | F20: 0
A21: 9 | B21: Other (attach schedule) | D21: 0 | F21: 0
A22: 10 | B22: TOTAL LIABILITIES | D22: =SUM(D18:D21) -> 25 | F22: =SUM(F18:F21) -> 0
A25: 11 | B25: Assets minus Liabilities | D25: =Assets_Beg - Liables_Beg -> 2499.79 | F25: =Assets_End - Liables_End -> 2844.9
B26: (subtract line 10 from line 6)
A27: 12 | B27: Prior year Net Worth | F27: =Worth_Beg -> 2499.79
B28: (Transfer from line 11 Beginning Year)
A29: 13 | B29: Change in Net Worth | F29: =Worth_End - Worth_Beg -> 345.11
B30: (Subtract line 12 from line 11)

Sheet Income Statement
G1: AR~4
A2: INCOME STATEMENT for | D2: =Chapter_Name -> (Chapter Name)
E3: (chapter name)
A4: Fiscal year from 1 JAN | C4: =Year -> 1997 | D4: to 31 DEC | E4: =Year -> 1997 | F4: .
C5: (last year) | E5: (last year)
A6: INCOME | F6: Amount
A7: 14 | B7: Contributions | F7: =SUM('Income Add'!D7:D9) -> 800
A8: 15 | B8: Rebates from NSS HQ | F8: 20
A9: 16 | B9: Membership Dues | F9: =Dues -> 800
A10: 17 | B10: Interest | F10: =Interest -> 12.73
A11: 18 | B11: Special fundraising events (attach schedule)
B12: Gross Revenue | D12: =SUM('Income Add'!D11:D12) -> 5
B13: minus direct expense | D13: =SUM('Income Add'!D14) -> 15.12
B14: Net Income (or Loss) | F14: =D12 - D13 -> -10.12
A15: 19 | B15: Merchandise sales (attach schedule)
B16: Gross Revenue | D16: =SUM('Income Add'!D16:D17) -> 330.8
B17: minus direct expense | D17: =SUM('Income Add'!D19:D20) -> 122.63
B18: Net Income (or Loss) | F18: =D16 - D17 -> 208.17
A19: 20 | B19: Other (attach schedule) | F19: =SUM('Income Add'!D21:D24) -> 137.5
A20: 21 | B20: TOTAL REVENUES | F20: =SUM(F7:F19) -> 1968.28
A22: EXPENSES | F22: Amount
A23: 22 | B23: Supplies (administrative & bank), used | F23: =SUM('Inv Flow'!F40:F46) -> 28.24
A24: 23 | B24: Telephone (administrative) | F24: 0
A25: 24 | B25: Postage and Shipping (administrative) | F25: 2.49
A26: 25 | B26: Occupancy (Rent and Utilities, mail box) | F26: 50
A27: 26 | B27: Other (attach schedule) | F27: =SUM('Income Add'!D29:D55) -> 1542.44
A28: 27 | B28: TOTAL EXPENSES | F28: =SUM(F23:F27) -> 1623.17
A30: 28 | B30: Income minus Expenses (subtract line 27 from line 21) | F30: =Assets_End - Liables_End -> 345.11
B31: Line 28 must be equal to line 13 or else there is an error.

Sheet Income Add
A1: ="INCOME STATEMENT ADDENDUM for: " & Chapter_Name -> INCOME STATEMENT ADDENDUM for: (Chapter Name)
A2: Fiscal year from 1 January to 31 December of the Year: | D2: =Year -> 1997
A5: INCOME SCHEDULES
A6: 14 | B6: Contributions, Positive Income, collected & due | C6: Code
B7: Cash donations to Chapter General Account | C7: DGA | D7: 100
B8: Cash donations to Project Account | C8: DPA | D8: 200
B9: Educational Grant for Project Account | C9: GPA | D9: 500
A10: 18 | B10: Regional Conference, Positive Income, collected & due
B11: Regional Conference Registrations | C11: CRG | D11: 45
B12: less Registration Refunds, paid | C12: CRR | D12: -40
A13: 18 | B13: Regional Conference, Negative Income, paid & owed
B14: Printing and Copying, paid | C14: CCP | D14: 15.12
A15: 19 | B15: Merchandise Sales, Positive Income, collected & due
B16: 30 Post Race for Space Project T-shirt Sales, price | C16: HTS | D16: =288+25 -> 313
B17: Project Equipment Sales and Rentals Fees | D17: 17.8
A18: 19 | B18: Merchandise Sales, Negative Income, paid & owed
B19: 30 Project T-shirt Sales, cost | C19: HTS | D19: 116.63
B20: 8 1993 ISDC T-shirts, depreciated down to $5 apiece | C20: T93 | D20: 6
A21: 20 | B21: Other, Cash Income, collected & due | C21: Code
B22: Chapter Newsletter Subscriptions (beyond members) | C22: SSS | D22: 37.5
A23: 20 | B23: Other, Non-cash Donations Income, collected & due
B24: 6-months CICI Internet service donated | D24: 100
A27: EXPENSE SCHEDULES
A28: 26 | B28: Other, Chapter Activities, paid & used
B29: Chapter Administrative Printing and Copying, used | C29: APC | D29: 30
B30: Chapter Prime Account Bank Fees, paid | D30: 12
B31: CICI Internet Service, 6 months | D31: 100
B32: NSS Chapters' Assembly Fee, paid | C32: ADF | D32: 10
B33: HATS Membership Dues, paid | C33: ADF | D33: 20
B34: Membership Recruitment Printing and Copying, paid | C34: MPC | D34: 300
B35: Membership Recruitment Postage and Shipping, paid | C35: MPS | D35: 50
B36: Membership Recruitment Ad Astra magazines, used | C36: MAA | D36: 19
B37: Newsletter Labor Fees, paid | C37: NLB | D37: 20
B38: Newsletter Printing and Copying, paid | C38: NPC | D38: 200
B39: Newsletter Postage and Shipping, paid | C39: NPS | D39: 100
B40: Newsletter Supplies, used | C40: NSP | D40: 10
B41: Programming Printing and Copying, paid | C41: PPC | D41: 50
B42: Programming Postage and Shipping, paid | C42: PPS | D42: 40
B43: Programming Supplies, used | C43: PSP | D43: 20
B44: Lobbying Printing and Copying, paid | C44: LPC | D44: 9.14
...

Sheet Cash Bal
A1: CHAPTER BALANCE SHEET for ACCOUNT: CASH
A2: Fiscal year from 1 January to 31 December of the Year: | C2: =Year -> 1997
A5: ="BEGINNING YEAR (BALANCE ON 1 JAN "&Year&")" -> BEGINNING YEAR (BALANCE ON 1 JAN 1997)
A6: 1 | B6: Chapter Cash Accounts
B7: Chapter General Account | C7: 500
B8: Chapter Project Account | C8: 600
B9: Chapter Conference Account | C9: 0
B10: Project Investment Account | C10: 400
A11: 1a. | B11: TOTAL ACCOUNT BALANCE | C11: =SUM(C7:C10) -> 1500
A14: ="ENDING YEAR (BALANCE ON 31 DEC "&Year&")" -> ENDING YEAR (BALANCE ON 31 DEC 1997)
A15: 1 | B15: Chapter Cash Accounts
B16: Chapter General Account | C16: 400
B17: Chapter Project Account | C17: 300
B18: Chapter Conference Account | C18: 200
B19: Project Investment Account | C19: 0
A20: 1b. | B20: TOTAL ACCOUNT BALANCE | C20: =SUM(C16:C19) -> 900
A23: 1a. | B23: Account balance at BEGINNING of year | C23: =Cash_Beg -> 1500
A24: 1b. | B24: Account balance at END of year | C24: =Cash_End -> 900
B25: Account change (Ending minus Beginning Balances) | C25: =Cash_End - Cash_Beg -> -600

Sheet Cash Flow
A1: CHAPTER FLOW STATEMENT for ACCOUNT: CASH
A2: Fiscal year from 1 January to 31 December of the Year: | D2: =Year -> 1997
A5: IN-FLOW (NET DEPOSITS DURING CURRENT YEAR)
A6: 14 | B6: Contributions | C6: Code
B7: Cash donations to Chapter General Account | C7: DGA | D7: 100
B8: Cash donations to Project Account | C8: DPA | D8: 200
B9: Educational Grant for Project Account | C9: GPA | D9: 500
A10: 15 | B10: Rebates from NSS HQ, Collected Revenue | C10: NCH | D10: 20
A11: 16 | B11: Membership Dues, Collected Revenue | C11: MEM | D11: 800
A12: 17 | B12: Interest | D12: 12.73
A13: 18 | B13: Special Fundraising Events, Regional Conference
B14: Regional Conference Registrations | C14: CRG | D14: 45
B15: less Printing and Copying, paid | C15: CPC | D15: -15.12
B16: less Registration Refunds | C16: CRR | D16: -40
A17: 19 | B17: Merchandise Sales
B18: Chapter T-shirt Sales | C18: TCH | D18: =288+25 -> 313
B19: Equipment Sales and Rentals Fees | D19: 17.8
A20: 20 | B20: Other
B21: NSS Memberships (NSS part), Collected Revenue | C21: NSS | D21: 15
B22: Newsletter Subscriptions (beyond members) | C22: SUB | D22: 37.5
A23: 21 | B23: TOTAL ACCOUNT IN-FLOW | D23: =SUM(D7:D22) -> 2005.91
A26: OUT-FLOW (PURCHASED GOODS AND SERVICES) | C26: Code
A27: 22 | B27: Supplies (HAL5 Administrative), purchased | C27: ASP | D27: 13.64
A28: 23 | B28: Telephone and Fax (HAL5 Administrative), paid | C28: ATF | D28: 0
A29: 24 | B29: Postage and Shipping (HAL5 Administrative), paid | C29: ASP | D29: 2.49
A30: 25 | B30: Occupancy (Rent and Utilities) | C30: AMB | D30: 50
A31: 26 | B31: Other, Administrative Activities
B32: Administrative Printing and Copying, paid | C32: APC | D32: 37.26
B33: Computer Supplies, purchased | C33: ASC | D33: 35.63
B34: Investment Account Bank Fees, paid | D34: 12
B35: NSS Chapters' Assembly Fee, paid | C35: ADF | D35: 10
B36: Membership Recruitment Printing and Copying, paid | C36: MPC | D36: 482.76
B37: Membership Recruitment Postage and Shipping, paid | C37: MPS | D37: 76.62
B38: Membership Recruitment Ad Astra magazines, purchased | C38: MAA | D38: 50
B39: NSS Memberships (NSS part), paid | C39: XHQ | D39: 15
B40: Newsletter Labor Fees, paid | C40: NLB | D40: 20
B41: Newsletter Printing and Copying, paid | C41: NPC | D41: 339.7
B42: Newsletter Postage and Shipping, paid | C42: NPS | D42: =144.1 + 1.28 -> 145.38
B43: Newsletter Supplies, purchased | C43: NSP | D43: 11.63
B44: Programming Printing and Copying, paid | C44: PPC | D44: =52.55 + 7.56 -> 60.11
...

Sheet Equip Bal
A1: CHAPTER BALANCE SHEET for ACCOUNT: CAPITAL EQUIPMENT
A2: Fiscal year from 1 January to 31 December of the Year: | D2: =Year -> 1997
A5: ="BEGINNING YEAR (BALANCE ON 1 JAN "&Year&")" -> BEGINNING YEAR (BALANCE ON 1 JAN 1997)
A6: 3 | B6: Capital Equipment ($100 or more in value) | C6: Code | E6: who
B7: HALO reusable 7-ft tethered red balloon | C7: EBA | D7: 220 | E7: RL
B8: Toroid Corporation 50-lb-capacity load cell | C8: TTH | D8: 150 | E8: TP
A9: 3a. | B9: TOTAL ACCOUNT BALANCE | D9: =SUM(D7:D8) -> 370
A12: ="ENDING YEAR (BALANCE ON 31 DEC "&Year&")" -> ENDING YEAR (BALANCE ON 31 DEC 1997)
A13: 3 | B13: Capital Equipment ($100 or more in value) | C13: Code | E13: who
B14: Project HALO portable exhibit | C14: FEX | D14: 300 | E14: GA
B15: HALO reusable 7-ft tethered red balloon | C15: EBA | D15: 200 | E15: RL
B16: Used 486 personal computer (no monitor) | C16: SCM | D16: 130 | E16: RL
B17: Sears Shop Vac | C17: SMT | D17: 80 | E17: TP
A18: 3b. | B18: TOTAL ACCOUNT BALANCE | D18: =SUM(D13:D17) -> 710
A21: 3a. | B21: Account balance at BEGINNING of year | D21: =Equip_Beg -> 370
A22: 3b. | B22: Account balance at END of year | D22: =Equip_End -> 710
B23: Account change (Ending minus Beginning Balances) | D23: =Equip_End - Equip_Beg -> 340
A25: Who | B25: is the person to contact and where is the equipment? | D25: Phone Number
A26: GA = | B26: Greg Allison, (place address here) | D26: 205-776-ZZZZ
A27: RL = | B27: Ronnie Lajoie, (place address here) | D27: 205-721-ZZZZ
A28: TP = | B28: Tim Pickens, (place address here) | D28: 205-971-ZZZZ

Sheet Equip Flow
A1: CHAPTER FLOW STATEMENT for ACCOUNT: CAPITAL EQUIPMENT
A2: Fiscal year from 1 January to 31 December of the Year: | E2: =Year -> 1997
A5: IN-FLOW (NEW ITEMS FROM CURRENT YEAR)
A6: 26 | B6: Project HALO Equipment, new items | C6: P/D | D6: Code
B7: Project HALO portable exhibit | C7: P | D7: FEX | E7: 300
B8: Used 386 personal computer (no monitor) | C8: P | D8: SCM | E8: 130
B9: Sears Shop Vac | C9: P | D9: SMT | E9: 80
A10: 27 | B10: TOTAL ACCOUNT IN-FLOW | E10: =SUM(E6:E9) -> 510
C11: P = purchased, D = donated
A13: OUT-FLOW (USED/SOLD ITEMS FROM PREVIOUS YEARS)
A14: 26 | B14: Project HALO Equipment, used/sold items | C14: U/S | D14: Code
B15: HALO reusable red balloon, depreciated | C15: U | D15: EBA | E15: 20
B16: Toroid Corporation 50-lb-capacity load cell | C16: J | D16: TTH | E16: 150
B17: 386 to 486 PC upgrade (less depreciation) | C17: U | D17: SCM | E17: 0
A18: 27 | B18: TOTAL ACCOUNT OUT-FLOW | E18: =SUM(E14:E17) -> 170
C19: U = used, S = sold, D = donated, J = junked
A21: ACCOUNT FLOW SUMMARY
A22: 21 | B22: TOTAL ACCOUNT IN-FLOW | E22: =Equip_In -> 510
A23: 27 | B23: TOTAL ACCOUNT OUT-FLOW | E23: =Equip_Out -> 170
B24: Net Change (IN-FLOW minus OUT-FLOW) | E24: =Equip_In - Equip_Out -> 340
A26: 3a. | B26: Account balance at BEGINNING of year | E26: =Equip_Beg -> 370
A27: 3b. | B27: Account balance at END of year | E27: =Equip_End -> 710
B28: Account change (Ending minus Beginning Balances) | E28: =Equip_End - Equip_Beg -> 340

Sheet Inv Bal
A1: CHAPTER BALANCE SHEET for ACCOUNT: INVENTORY
A2: Fiscal year from 1 January to 31 December of the Year: | E2: =Year -> 1997
A5: ="BEGINNING YEAR (BALANCE ON 1 JAN "&Year&")" -> BEGINNING YEAR (BALANCE ON 1 JAN 1997)
A6: 19 | B6: Merchandise Sales, items to be sold | C6: Qty | D6: Code | F6: who
B7: 1993 ISDC T-shirts, unsold items | C7: 8 | D7: T93 | E7: 46 | F7: RL
A8: 22 | B8: Supplies, Chapter Admin, items to be used
B9: ="Total from "&Year-1&" Inventory Balance Sheet" -> Total from 1996 Inventory Balance Sheet | D9: APR | E9: 24
B10: ="Total from "&Year-1&" Inventory Balance Sheet" -> Total from 1996 Inventory Balance Sheet | D10: ASP | E10: 39.6
B11: ="Total from "&Year-1&" Inventory Balance Sheet" -> Total from 1996 Inventory Balance Sheet | D11: ASB | E11: 85.78
A12: 26 | B12: Supplies, Recruitment, items to be used
B13: Chapter membership forms | C13: 60 | D13: MCP | E13: 9.72 | F13: RL
A14: 26 | B14: Supplies, Programming, items to be used
B15: ="Total from "&Year-1&" Inventory Balance Sheet" -> Total from 1996 Inventory Balance Sheet | D15: PPR | E15: 81.3
B16: ="Total from "&Year-1&" Inventory Balance Sheet" -> Total from 1996 Inventory Balance Sheet | D16: PSP | E16: 264.54
A17: 26 | B17: Supplies, Project Admin, items to be used
B18: Project stationary, sheets | C18: 500 | D18: APR | E18: 22.5 | F18: RL
B19: 3-ring binders, unused | C19: 1 | D19: ASP | E19: 4.42 | F19: RL
B20: ="Total from "&Year-1&" Inventory Balance Sheet" -> Total from 1996 Inventory Balance Sheet | D20: ASB | E20: 30.02
B21: Project photo albums | C21: 1 | D21: APA | E21: 16.19 | F21: RL
A22: 26 | B22: Supplies, Education, items to be used
B23: ="Total from "&Year-1&" Inventory Balance Sheet" -> Total from 1996 Inventory Balance Sheet | D23: ESP | E23: 30.72
A24: 4a. | B24: TOTAL ACCOUNT BALANCE | E24: =SUM(E6:E23) -> 654.79
A27: ="ENDING YEAR (BALANCE ON 31 DEC "&Year&")" -> ENDING YEAR (BALANCE ON 31 DEC 1997)
A28: 19 | B28: Merchandise Sales, items to be sold | C28: Qty | D28: Code | F28: who
B29: 1993 ISDC T-shirts, unsold items | C29: 8 | D29: T93 | E29: 40 | F29: RL
A30: 22 | B30: Supplies, Chapter Admin, items to be used
B31: Chapter stationary | C31: 30 | D31: APR | E31: 3 | F31: RL
B32: Chapter envelopes | C32: 290 | D32: APR | E32: 12.76 | F32: RL
B33: Chapter return envelopes | C33: 283 | D33: APR | E33: 15.28 | F33: RL
B34: Staplers | C34: 2 | D34: ASP | E34: 8 | F34: RL
B35: Staples, boxes | C35: 1 | D35: ASP | E35: 2 | F35: RL
B36: 3-ring binders, unused | C36: 2 | D36: ASP | E36: 6.46 | F36: RL
B37: Plastic file box | C37: 1 | D37: ASP | E37: 10 | F37: RL
B38: 3" x 3" Post-It notepads | C38: 3 | D38: ASP | E38: 1.05 | F38: RL
B39: 2" x 1.5" Post-It notepads | C39: 12 | D39: ASP | E39: 2.2 | F39: RL
B40: Paper clips, boxes | C40: 4 | D40: ASP | E40: 0.48 | F40: RL
B41: Holepunch reinforcements, boxes | C41: 0.5 | D41: ASP | E41: 0.75 | F41: RL
B42: Inkjet printer cartridge | C42: 0.5 | D42: ASC | E42: 17.81 | F42: GA
... B46: "For Deposit Only" stamp and ink | C46: 1 | D46: ASB | E46: 10 | F46: RL
A47: 26 | B47: Supplies, Recruitment, items to be used
...

Sheet Inv Flow
A1: CHAPTER FLOW STATEMENT for ACCOUNT: INVENTORY
A2: Fiscal year from 1 January to 31 December of the Year: | F2: =Year -> 1997
A5: IN-FLOW (NEW ITEMS FROM CURRENT YEAR)
A6: 19 | B6: Merchandise Sales, new items | C6: P/D | D6: Qty | E6: Code
B7: No new items | F7: 0
A8: 26 | B8: Supplies, Chapter Admin, new items
B9: Chapter return envelopes | C9: P | D9: 500 | E9: APR | F9: 30
B10: Return envelopes | C10: P | D10: 100 | E10: ASP | F10: 10
B11: 3-inch 3-ring binder for 1993 ISDC | C11: P | D11: 1 | E11: ASP | F11: 10
B12: Inkjet printer cartridge | C12: P | D12: 1 | E12: ASC | F12: 50
A13: 26 | B13: Supplies, Recruitment, new items
B14: NSS Ad Astra magazines | C14: P | D14: 50 | E14: MAA | F14: 100
A15: 26 | B15: Supplies, Newsletter, new items
B16: Mailing labels, sheets of 30 | C16: P | D16: =15 + 12.5 -> 27.5 | E16: NSP | F16: 15
A17: 26 | B17: Supplies, Programming, new items
B18: Post-It Note glue sticks | C18: P | D18: 1 | E18: PSP | F18: 2
B19: Mailing labels, sheets of 30 | C19: P | D19: =10 + 12.5 -> 22.5 | E19: PSP | F19: 15
A20: 26 | B20: Supplies, Project Admin, new items
B21: Project photo albums | C21: P | D21: 1 | E21: APA | F21: 20
A22: 26 | B22: Supplies, Project Fund-raising, new items | D22: Qty | E22: Code
B23: Project black folders | C23: P | D23: 200 | E23: FPR | F23: 305.1
B24: Velcro for Project exhibit | C24: P | D24: 1 | E24: FSP | F24: 10
A25: 26 | B25: Supplies, Project Education, new items
B26: 3-inch 3-ring Project Achievement binder | C26: P | D26: 1 | E26: ESP | F26: 10
B27: Project Achieve. sheet protectors, boxes | C27: P | D27: 1 | E27: ESP | F27: 30
B28: Separaters, packs | C28: P | D28: 6 | E28: ESP | F28: 5
B29: Transparencies, boxes | C29: P | D29: 1 | E29: ESP | F29: 50
A30: 27 | B30: TOTAL ACCOUNT IN-FLOW | F30: =SUM(F6:F29) -> 662.1
C31: P = purchased, D = donated
A33: OUT-FLOW (USED/SOLD ITEMS FROM PREVIOUS YEARS)
A34: 19 | B34: Merchandise Sales, items sold | C34: U/S | D34: Qty | E34: Code
B35: 1993 ISDC T-shirts, depreciated | C35: U | D35: 8 | E35: T93 | F35: 6
A36: 22 | B36: Supplies, Chapter Admin, items used/sold | D36: Qty | E36: Code
B37: Chapter stationary | C37: U | D37: 50 | E37: APR | F37: 5
B38: Chapter envelopes | C38: U | D38: 10 | E38: APR | F38: 0.44
B39: Chapter return envelopes | C39: U | D39: =130 + 217 -> 347 | E39: APR | F39: =2.8 + 11.72 -> 14.52
B40: Return envelopes | C40: U | D40: 100 | E40: ASP | F40: 2.85
B41: 10" x 13" yellow envelopes | C41: U | D41: 9 | E41: ASP | F41: 0.69
B42: Notepads | C42: U | D42: 2 | E42: ASP | F42: 0.2
B43: Receipt books, used portion | C43: U | D43: 0.64 | E43: ASP | F43: 2.56
...

Sheet AR Bal
A1: CHAPTER BALANCE SHEET for ACCOUNT: ACCOUNTS RECEIVABLE
A2: Fiscal year from 1 January to 31 December of the Year: | C2: =Year -> 1997
A5: ="BEGINNING YEAR (BALANCE ON 1 JAN "&Year&")" -> BEGINNING YEAR (BALANCE ON 1 JAN 1997)
A6: 2 | B6: Money Owed to Chapter
B7: No money owed to Chapter | C7: 0
A8: 2a. | B8: TOTAL ACCOUNT BALANCE | C8: =SUM(C7:C7) -> 0
A11: ="ENDING YEAR (BALANCE ON 31 DEC "&Year&")" -> ENDING YEAR (BALANCE ON 31 DEC 1997)
A12: 2 | B12: Money Owed to Chapter
B13: Unpaid Memberships | C13: 50
B14: Unpaid Subscriptions | C14: 10
A15: 2b. | B15: TOTAL ACCOUNT BALANCE | C15: =SUM(C13:C14) -> 60
A18: 2a. | B18: Account balance at BEGINNING of year | C18: =AR_Beg -> 0
A19: 2b. | B19: Account balance at END of year | C19: =AR_End -> 60
B20: Account change (Ending minus Beginning Balances) | C20: =AR_End - AR_Beg -> 60

Sheet AR Flow
A1: CHAPTER FLOW STATEMENT for ACCOUNT: ACCOUNTS RECEIVABLE
A2: Fiscal year from 1 January to 31 December of the Year: | C2: =Year -> 1997
A5: IN-FLOW (UNPAID SALES FROM CURRENT YEAR)
A6: 14 | B6: Contributions, not paid/deposited
B7: None | C7: 0
A8: 15 | B8: Rebates from NSS HQ, not paid/deposited | C8: 0
A9: 16 | B9: Membership Dues, not paid/deposited | C9: 0
A10: 18 | B10: Special Fundraising Events, not paid/deposited
B11: None | C11: 0
A12: 19 | B12: Merchandise Sales, not paid/deposited
B13: None | C13: 0
A14: 20 | B14: Other
B15: Unpaid Memberships | C15: 50
B16: Unpaid Subscriptions | C16: 10
A17: 21 | B17: TOTAL ACCOUNT IN-FLOW | C17: =SUM(C6:C16) -> 60
A20: OUT-FLOW (PAID SALES FROM PREVIOUS YEARS)
A21: 14 | B21: Contributions, paid or deposited
B22: None | C22: 0
A23: 15 | B23: Rebates from NSS HQ, paid or deposited | C23: 0
A24: 16 | B24: Membership Dues, paid or deposited | C24: 0
A25: 18 | B25: Special Fundraising Events, paid or deposited
B26: None | C26: 0
A27: 19 | B27: Merchandise Sales, paid or deposited
B28: None | C28: 0
A29: 20 | B29: Other
B30: NSS Memberships (NSS part), paid or deposited | C30: 0
A31: 27 | B31: TOTAL ACCOUNT OUT-FLOW | C31: =SUM(C21:C30) -> 0
A34: ACCOUNT FLOW SUMMARY
A35: 21 | B35: TOTAL ACCOUNT IN-FLOW | C35: =AR_In -> 60
A36: 27 | B36: TOTAL ACCOUNT OUT-FLOW | C36: =AR_Out -> 0
B37: Net Change (IN-FLOW minus OUT-FLOW) | C37: =AR_In - AR_Out -> 60
A39: 2a. | B39: Account balance at BEGINNING of year | C39: =AR_Beg -> 0
A40: 2b. | B40: Account balance at END of year | C40: =AR_End -> 60
B41: Account change (Ending minus Beginning Balances) | C41: =AR_End - AR_Beg -> 60

Sheet AP Bal
A1: CHAPTER BALANCE SHEET for ACCOUNT: ACCOUNTS PAYABLE
A2: Fiscal year from 1 January to 31 December of the Year: | C2: =Year -> 1997
A5: ="BEGINNING YEAR (BALANCE ON 1 JAN "&Year&")" -> BEGINNING YEAR (BALANCE ON 1 JAN 1997)
A6: 7 | B6: Money That Chapter Owes
B7: Mail Box Rental | C7: 25
A8: 7a. | B8: TOTAL ACCOUNT BALANCE | C8: =SUM(C7:C7) -> 25
A11: ="ENDING YEAR (BALANCE ON 31 DEC "&Year&")" -> ENDING YEAR (BALANCE ON 31 DEC 1997)
A12: 7 | B12: Money That Chapter Owes
B13: No money owed by Chapter | C13: 0
A14: 7b. | B14: TOTAL ACCOUNT BALANCE | C14: =SUM(C13:C13) -> 0
A17: 7a. | B17: Account balance at BEGINNING of year | C17: =AP_Beg -> 25
A18: 7b. | B18: Account balance at END of year | C18: =AP_End -> 0
B19: Account change (Ending minus Beginning Balances) | C19: =AP_End - AP_Beg -> -25

Sheet AP Flow
A1: CHAPTER FLOW STATEMENT for ACCOUNT: ACCOUNTS PAYABLE
A2: Fiscal year from 1 January to 31 December of the Year: | C2: =Year -> 1997
A5: IN-FLOW (UNPAID SALES FROM CURRENT YEAR)
A6: 22 | B6: Supplies, not paid | C6: 0
A7: 23 | B7: Telephone, not paid | C7: 0
A8: 24 | B8: Postage and Shipping, not paid | C8: 0
A9: 25 | B9: Occupancy, not paid | C9: 0
A10: 26 | B10: Other
B11: No unpaid expenses | C11: 0
A12: 27 | B12: TOTAL ACCOUNT IN-FLOW | C12: =SUM(C6:C11) -> 0
A15: OUT-FLOW (PAID SALES FROM PREVIOUS YEARS)
A16: 22 | B16: Supplies, paid | C16: 0
A17: 23 | B17: Telephone, paid | C17: 0
A18: 24 | B18: Postage and Shipping, paid | C18: 0
A19: 25 | B19: Occupancy, paid | C19: 25
A20: 26 | B20: Other
B21: No unpaid expenses | C21: 0
A22: 27 | B22: TOTAL ACCOUNT OUT-FLOW | C22: =SUM(C16:C21) -> 25
A25: ACCOUNT FLOW SUMMARY
A26: 21 | B26: TOTAL ACCOUNT IN-FLOW | C26: =AP_In -> 0
A27: 27 | B27: TOTAL ACCOUNT OUT-FLOW | C27: =AP_Out -> 25
B28: Net Change (IN-FLOW minus OUT-FLOW) | C28: =AP_In - AP_Out -> -25
A30: 1a. | B30: Account balance at BEGINNING of year | C30: =AP_Beg -> 25
A31: 1b. | B31: Account balance at END of year | C31: =AP_End -> 0
B32: Account change (Ending minus Beginning Balances) | C32: =AP_End - AP_Beg -> -25
