Workbook

Sheet Productivity
B1: This productivity grid was adapted from information in Capers Jones' book, Estimating Software Costs
C3: Hours per FP
B4: Activity | C4: Minimum | D4: Mode | E4: Maximum | F4: Adjusted? | G4: Est. Hours | H4: Adjusted? | I4: Justification
B5: Requirements | C5: 0.38 | D5: 0.75 | E5: 2.64 | F5: 0.75 | G5: =F5*'FP Summary'!C38 -> 168.165
B6: Prototyping | C6: 0.53 | D6: 0.88 | E6: 5.28 | F6: 0.88 | G6: =F6*'FP Summary'!$C$38 -> 197.3136
B7: Architecture | C7: 0.26 | D7: 0.44 | E7: 1.32 | F7: 0.44 | G7: =F7*'FP Summary'!$C$38 -> 98.6568
B8: Project Plans | C8: 0.09 | D8: 0.26 | E8: 0.66 | F8: 0.26 | G8: =F8*'FP Summary'!$C$38 -> 58.2972
B9: Initial Design | C9: 0.33 | D9: 0.75 | E9: 2.64 | F9: 0.5 | G9: =F9*'FP Summary'!$C$38 -> 112.11 | H9: Y | I9: Using existing design patterns
B10: Detailed Design | C10: 0.44 | D10: 0.88 | E10: 5.28 | F10: 0.88 | G10: =F10*'FP Summary'!$C$38 -> 197.3136
B11: Design Reviews | C11: 0.33 | D11: 0.59 | E11: 1.76 | F11: 0.59 | G11: =F11*'FP Summary'!$C$38 -> 132.2898
B12: Coding | C12: 0.66 | D12: 2.64 | E12: 8.8 | F12: 2.64 | G12: =F12*'FP Summary'!$C$38 -> 591.9408
B13: Reuse Acquisition | C13: 0.07 | D13: 0.22 | E13: 0.33 | F13: 0 | G13: =F13*'FP Summary'!$C$38 -> 0 | H13: Y | I13: not required for this project
B14: Package Purchase | C14: 0.09 | D14: 0.33 | E14: 0.38 | F14: 0.33 | G14: =F14*'FP Summary'!$C$38 -> 73.9926
B15: Code Inspections | C15: 0.44 | D15: 0.88 | E15: 1.76 | F15: 0.88 | G15: =F15*'FP Summary'!$C$38 -> 197.3136
B16: Independent verification and validation | C16: 0.66 | D16: 1.06 | E16: 1.76 | F16: 0 | G16: =F16*'FP Summary'!$C$38 -> 0 | H16: Y | I16: not required for this project
B17: Configuration Management | C17: 0.04 | D17: 0.08 | E17: 0.13 | F17: 0.08 | G17: =F17*'FP Summary'!$C$38 -> 17.9376
B18: Integration | C18: 0.26 | D18: 0.53 | E18: 0.88 | F18: 0.53 | G18: =F18*'FP Summary'!$C$38 -> 118.8366
B19: User Documentation | C19: 1.32 | D19: 1.89 | E19: 6.6 | F19: 1.89 | G19: =F19*'FP Summary'!$C$38 -> 423.7758
B20: Unit Testing | C20: 0.33 | D20: 0.88 | E20: 1.89 | F20: 0.88 | G20: =F20*'FP Summary'!$C$38 -> 197.3136
B21: Function Testing | C21: 0.44 | D21: 0.88 | E21: 5.28 | F21: 0.88 | G21: =F21*'FP Summary'!$C$38 -> 197.3136
B22: Integration Testing | C22: 0.33 | D22: 0.75 | E22: 1.76 | F22: 0.75 | G22: =F22*'FP Summary'!$C$38 -> 168.165
B23: System Testing | C23: 0.26 | D23: 0.66 | E23: 1.32 | F23: 0.66 | G23: =F23*'FP Summary'!$C$38 -> 147.9852
B24: Field Testing (Alpha/Beta testing) | C24: 0.26 | D24: 0.59 | E24: 1.76 | F24: 0.59 | G24: =F24*'FP Summary'!$C$38 -> 132.2898
B25: Acceptance Testing | C25: 0.22 | D25: 0.38 | E25: 1.76 | F25: 0.38 | G25: =F25*'FP Summary'!$C$38 -> 85.2036
B26: Independent Testing | C26: 0.44 | D26: 0.66 | E26: 1.32 | F26: 0.66 | G26: =F26*'FP Summary'!$C$38 -> 147.9852
B27: Quality Assurance | C27: 0.44 | D27: 0.88 | E27: 4.4 | F27: 0.88 | G27: =F27*'FP Summary'!$C$38 -> 197.3136
B28: Installation and Training | C28: 0.22 | D28: 0.38 | E28: 0.88 | F28: 0.38 | G28: =F28*'FP Summary'!$C$38 -> 85.2036
B29: Project Management | C29: 0.66 | D29: 1.32 | E29: 8.8 | F29: 1.32 | G29: =F29*'FP Summary'!$C$38 -> 295.9704
B30: Total hours/FP | C30: =SUM(C5:C29) -> 9.5 | D30: =SUM(D5:D29) -> 19.56 | E30: =SUM(E5:E29) -> 69.39 | F30: =SUM(F5:F29) -> 18.03 | G30: =SUM(G5:G29) -> 4042.6866
E32: Defect Rate Estimation by RUP Workflow
B33: Rollup by RUP workflow (from above) | C33: Est. Hours | E33: Avg. Rate | F33: Adj. Defect Rate | G33: Est. Defects | H33: Adjusted? | I33: Justification
B34: Business Modeling | C34: =G6+G7+G9 -> 408.0804 | E34: 0 | F34: =E34 -> 0 | G34: ='FP Summary'!$C$38*F34 -> 0
B35: Requirements | C35: =G5 -> 168.165 | E35: 1 | F35: 0.2 | G35: ='FP Summary'!$C$38*F35 -> 44.844 | H35: Y | I35: Due to stability of requirements in a known space, errors in requirements are kept to a minimum
B36: Analysis and Design | C36: =SUM(G10:G11)+(0.3*G27) -> 388.79748 | E36: 1.25 | F36: 0.3 | G36: ='FP Summary'!$C$38*F36 -> 67.266 | H36: Y | I36: Due to prototype nature, design defects are moot
B37: Implementation | C37: =SUM(G12:G15)+(0.3*G27) + G20 -> 1119.7547 | E37: =1.75 -> 1.75 | F37: =E37*0.8*0.9 -> 1.26 | G37: ='FP Summary'!$C$38*F37 -> 282.5172 | H37: Y | I37: Unit testing and some functional testing defects not counted; Sierra assumes developers will unit test and perform preliminary functional testing using test harnesses.
B38: Test | C38: =(0.9*SUM(G21:G26))+(0.4*G27) + G16 -> 869.9736 | E38: 0.4 | F38: =E38 -> 0.4 | G38: ='FP Summary'!$C$38*F38 -> 89.688 | I38: Bad fix defects
B39: Deployment | C39: =G28+G19 -> 508.9794 | E39: 0.6 | F39: 0.02 | G39: ='FP Summary'!$C$38*F39 -> 4.4844 | H39: Y | I39: Documentation defects (errors including online help screens, user documents, etc.) -- Adj down due to very limited UG requirements
B40: Configuration and Change Management | C40: =0.8*(G18+G17) -> 109.41936 | E40: 0 | F40: =E40 -> 0 | G40: ='FP Summary'!$C$38*F40 -> 0
B41: Project Management | C41: =(0.9*G29)+ (0.5*G8) -> 295.52196 | E41: 0 | F41: =E41 -> 0 | G41: ='FP Summary'!$C$38*F41 -> 0
B42: Environment | C42: =(0.5*G8)+ (0.2 *(G17+G18)) + (0.1*G29) + (0.1*SUM(G21:G26)) -> 173.99472 | E42: 0 | F42: =E42 -> 0 | G42: ='FP Summary'!$C$38*F42 -> 0
...

Sheet FP Summary
A1: New Development Project Function Point Count
B2: Project Name: | C2: Sample Project
B3: Client Name: | C3: Federal Republic of Elbonia
B6: Partner: | C6: Glenn Briskin
B7: Branch: | C7: Seattle - Olympia business unit
B9: Proj Start Date: | C9: 37469
B10: Proj End Date: | C10: 37726
B11: Project Status | C11: Entering Iterative Transition phase (finished iteration four, entering iteration five)
B12: (at time of count)
B14: FP Count Type: | C14: Application
B15: Date of Count: | C15: 37697
B16: Counted by: | C16: Nick Malik
B18: Date of Review: | C18: 37701
B19: Reviewed by: | C19: Daniel Condreay
B20: Count Version: | C20: 2
B21: Count Description: | C21: Application FP Count of Sample Project
B24: UFP | C24: Low | D24: Average | E24: High
B25: ILF's | C25: =[1]Formulations!E4 -> 14 | D25: =[1]Formulations!I4 -> 20 | E25: =[1]Formulations!M4 -> 45
B26: EIF's | C26: =[1]Formulations!E5 -> 20 | D26: =[1]Formulations!I5 -> 7 | E26: =[1]Formulations!M5 -> 20
B27: EI's | C27: =[1]Formulations!E7 -> 9 | D27: =[1]Formulations!I7 -> 0 | E27: =[1]Formulations!M7 -> 18
B28: EO's | C28: =[1]Formulations!E8 -> 12 | D28: =[1]Formulations!I8 -> 0 | E28: =[1]Formulations!M8 -> 14
B29: EQ's | C29: =[1]Formulations!E9 -> 27 | D29: =[1]Formulations!I9 -> 16 | E29: =[1]Formulations!M9 -> 0
B31: Total Unadjusted Function Points
C32: =[1]Formulations!O10 -> 222
B34: Value Adjustment Factor
C35: ='[1]General System Characteristics'!B18 -> 1.01
B37: Adjusted Function Points
C38: =C32*C35 -> 224.22
B40: Project Productivity Rate (hours per FP)
C41: =Productivity!F30 -> 18.03
B43: Total Effort Estimate (in days)
C44: =(F57)/8 -> 505.33583
B47: Hours by RUP Workflow (from productivity page) | F47: Est Hours
B48: =Productivity!B34 -> Business Modeling | F48: =Productivity!C34 -> 408.0804
B49: =Productivity!B35 -> Requirements | F49: =Productivity!C35 -> 168.165
B50: =Productivity!B36 -> Analysis and Design | F50: =Productivity!C36 -> 388.79748
B51: =Productivity!B37 -> Implementation | F51: =Productivity!C37 -> 1119.7547
B52: =Productivity!B38 -> Test | F52: =Productivity!C38 -> 869.9736
B53: =Productivity!B39 -> Deployment | F53: =Productivity!C39 -> 508.9794
B54: =Productivity!B40 -> Configuration and Change Management | F54: =Productivity!C40 -> 109.41936
...
