Workbook

Sheet Complete GAS Bank
A1: GAS Bank of Treatment Goals
A2: ID | B2: Topic | C2: Put X in box if goal selected | D2: Treatment Goal | E2: Most unfavorable treatment outcome thought likely | F2: Less than expected success with treatment | G2: Expected level of treatment success | H2: More than expected success with treatment | I2: Best anticipated success with treatment
A4: A1 | B4: Addiction | D4: Denial (Alcohol Related) | E4: Client does not think s/he has or has had any major problems due to drinking | F4: Client says maybe s/he has had problems due to drinking but nothing serious and nothing now | G4: Client says maybe s/he has current problems due to drinking but nothing s/he considers very serious | H4: Client can state 1 or 2 problems s/he wishes to work on | I4: Client is actively working on stated problems
A5: A2 | B5: Addiction | D5: Drug Use | E5: Gets arrested for possession or use of drugs or uses drugs almost every day | F5: No arrests for possession or use of drugs but uses them twice per week or more | G5: No arrest for possession or use of drugs but continues to use about 4 to 7 times per month | H5: No arrest for possession or use of drugs but uses them 1 to 3 times per month | I5: No arrests for possession or use and reports no drug usage
A6: A3 | B6: Addiction | D6: Drug Use Sponsor | E6: Does not attend group meetings and does not have a drug use sponsor | F6: Occasional attendance at group meetings, but does not have sponsor | G6: Occasional attendance at group meetings and finds and asks someone to be his/her sponsor | H6: Regular attendance at group meetings and less than daily contact with sponsor | I6: Daily attendance at group meetings and daily contact with sponsor
A7: A3a | B7: Addiction | D7: Index of Drug Involvement (IDI) | E7: Client scores a 40 or above indicating a clinically significant personal or social problem with drugs resulting in serious problems around the use and abuse of drugs | F7: Client scores between 20-39 indicating a clinically significant personal or social problem with drugs | G7: Client scores between 10-19, indicating a nonsignificant clinical personal or social problem with drugs | H7: Client scores between 5-9, indicating a nonsignificant clinical personal or social problem with drugs | I7: Client scores between 0-4 indicating a nonsignificant clinical personal or social problem with drugs
A8: A4 | B8: Addiction | D8: Individual Counseling for Drug Use | E8: No individual counseling for drug use | F8: Individual counseling for drug use sought | G8: Client can identify high risk people, places and things that influence drug use | H8: Client is making the attempt to change social setting (people, places, things) that influence drug use | I8: Client has changed social setting (people, places, things) that influence drug use
A9: A5 | B9: Addiction | D9: Individual Counseling: Understanding Drug Impact on Others | E9: No individual counseling for drug use | F9: Individual counseling for drug use sought | G9: Client can identify the consequences they/others have endured on behalf of his/her drug use | H9: Client is considering how to make amends to those who have been affected by his/her drug use | I9: Client has attempted to make amends to those who have been affected by his/her drug use
A10: A6 | B10: Addiction | D10: Substance Use | E10: Uses substances on a regular basis, no attempt to abstain. | F10: Attempts to abstain, but continues to use substances. | G10: Abstains from substance use, but doesn't attend group meetings. | H10: Abstains from use, and occasionally attends support group meetings. | I10: Complete abstinence and daily attendance in support groups.
A11: A7 | B11: Addiction | D11: Weekly Substance Abuse | E11: Uses substances at least weekly. Unable to abstain. | F11: Uses substances at least once a month. | G11: Has not used substances for at least _____ months. | H11: Has not used substances for ___ months and attending treatment. | I11: Has not used substances for ___ months, attends treatment and/or support groups.
A12: A8 | B12: Addiction | D12: ZCreate your own
A13: AC1 | B13: Affect/Cognition | D13: Anxiety (Clinical Anxiety Scale) | E13: Client scores a 50 or above indicating a significant level of phobic and/or anxiety reactions related to specific situations or events such as trembling, twitching, feeling shaky, aches, restlessness, fatigue, shortness of breath, tachycardia, sweating, dizziness, etc. | F13: Client scores 30-49 indicating a clinically significant level of phobic and/or anxiety reactions related to specific situations or events | G13: Client scores between 20-29 and is free of a clinically significant problem with anxiety or phobia | H13: Client scores between 10-19 and is free of a clinically significant problem with anxiety or phobia | I13: Client scores between 0-9 and is free of a clinically significant problem with anxiety or phobia
A14: AC1a | B14: Affect/Cognition | D14: Generalized Contentment Inventory | E14: A score of 70 or above indicating severe distress, possibly suicidal acting out | F14: A score between 31 and 69, indicating clinically significant nonpsychotic depression | G14: A score between 21-30, indicating client is free from clinical depression (nonpsychotic) | H14: A score between 11-20, indicating client is free from clinical depression (nonpsychotic) | I14: A score between 0-10, indicating client is free from clinical depression (nonpsychotic)
A15: AC2 | B15: Affect/Cognition | D15: Decision-Making | E15: Can consider alternatives but makes no decisions. | F15: Makes concrete plans, but no follow-through. | G15: Makes concrete plans, follows through with assistance. | H15: Makes concrete plans, follows through without assistance. | I15: Makes concrete plans, reaches goal without assistance.
A16: AC3 | B16: Affect/Cognition | D16: Depressed Mood | E16: Depressed mood most of the day, nearly every day for the past two months in which daily living activities are affected (eating, sleeping, working) | F16: Regular depressed mood within the past month in which daily living activities are affected (eating, sleeping, working) | G16: Occasional depressed mood within the past two weeks in which daily living activities are occasionally affected | H16: Some depression noted, but daily living activities are rarely affected | I16: Infrequent periods of depression that do not interfere with daily functioning.
A17: AC4 | B17: Affect/Cognition | D17: Depression Affecting Daily Activities | E17: Reported depression in which 5 or more of the following are reported: poor appetite; sleeplessness; low energy; low self esteem; poor concentration; hopelessness | F17: Reported depression in which 3-4 of the following are reported: poor appetite; sleeplessness; low energy; low self esteem; poor concentration; hopelessness | G17: Reported depression in which 1-2 of the following are reported: poor appetite; sleeplessness; low energy; low self esteem; poor concentration; hopelessness | H17: Sought treatment for depression; depression not reported in the past two weeks | I17: No depression; client feels better equipped to handle future episodes of depression
A18: AC5 | B18: Affect/Cognition | D18: Depression Diagnosis | E18: Has not followed through with professional diagnosis. No professional recommendations obtained. | F18: Professional diagnosis and does not agree to recommendations. | G18: Professional diagnosis obtained and agrees to professional recommendations for treatment. | H18: Has initiated recommended treatment. | I18: Ongoing treatment with reports of decreasing symptoms.
A19: AC6 | B19: Affect/Cognition | D19: Fear of Partner | E19: Client is fearful of partner, but is not seeking support | F19: Client is fearful of partner, but is considering seeking support | G19: Client is fearful of partner, but is actively seeking support | H19: Client is making changes to get out of a fearful environment | I19: Client is in a positive environment and is not fearful of partner
A20: AC7 | B20: Affect/Cognition | D20: Feelings About Self | E20: Client mostly reports negative feelings about self. | F20: Client reports more negative than positive feelings about self. | G20: Client reports positive and negative feelings about self equally. | H20: Client reports more positives about self than negatives. | I20: Client reports mostly positive feelings about self.
A21: AC9 | B21: Affect/Cognition | D21: Identifying Feelings | E21: Client is unable to identify feelings | F21: Client is able to identify feelings, but does not express feelings appropriately | G21: Client is able to identify and appropriately express feelings to counselor | H21: To counselor and in-home (parents and siblings) | I21: To counselor, in-home (parents and siblings), and out-of home (school)
A22: AC10 | B22: Affect/Cognition | D22: Nightmares | E22: Client reports frequent weekly nightmares | F22: Client reports several nightmares per week | G22: Client reports few nightmares per week and is beginning to use imagery rehearsal (or other cognitive restructuring) in which the nightmare is changed during waking hours | H22: Client reports nightmares have mostly subsided after using imagery rehearsal (or other cognitive restructuring) | I22: Client reports s/he has not had any nightmares within the past 30 days and is optimistic s/he can handle future nightmare episodes
A23: AC11 | B23: Affect/Cognition | D23: Nightmares | E23: Nightmares have increased. | F23: Nightmares have decreased by less than 25%. | G23: Nightmares have decreased by 25-50%. | H23: Nightmares have decreased by 51-75% | I23: All nightmares or almost all nightmares have subsided
A24: AC12 | B24: Affect/Cognition | D24: Index of Self Esteem (ISE) | E24: A score of 70 or above, indicating client has a significant self esteem problem, and is nearly always experiencing severe distress in which violence could be considered as a means of dealing | F24: A score between 31-69 indicating client has a significant self esteem problem | G24: A score between 21-30, indicating client is free from a significant self esteem problem | H24: A score between 11-20, indicating client is free from a significant self esteem problem | I24: A score between 0-10, indicating client is free from a significant self esteem problem
... A29: AC14 | B29: Affect/Cognition | D29: Suicidal thoughts | E29: Client reports suicidal thoughts frequently and has had more than ___ suicide attempt in the last ___ time period | F29: Client reports suicidal thoughts frequently and has made one suicidal attempt in the last __ time period. | G29: Client reports suicidal thoughts at least ___ times per month, but has not acted on thoughts. | H29: Client reports suicidal thoughts less than once every ___ and has not acted on thoughts. | I29: Client reports no suicidal thoughts.
A30: AC15 | B30: Affect/Cognition | D30: ZCreate your own
A31: B1 | B31: Behavior | D31: Ability to compromise | E31: 1 in 4 conflicts or less resolved with compromise | F31: About 1 in 3 conflicts resolved with compromise | G31: Youth and parents achieve acceptable compromise every other conflict | H31: Acceptable compromise almost every time (more than every other time) | I31: Acceptable compromise all the time
A32: B2 | B32: Behavior | D32: Anger Control | E32: Controls anger less than 25% of the time. | F32: Controls anger less than 50% of the time. | G32: Controls anger more than 50% of the time. | H32: Controls anger more than 75% of the time. | I32: Controls anger more than 75% of the time even when challenged by another angry individual or situation.
A33: B3 | B33: Behavior | D33: Anger: Physica/Verbal Retaliation | E33: Frequently client inappropriately expresses anger through verbal or physical retaliation | F33: Occasionally client inappropriately expresses anger through verbal or physical retaliation | G33: Client appropriately verbalizes his/her anger. Physical retaliation is infrequent. | H33: Occasionally client successfully uses self talk to "cool him/herself down" | I33: Client successfully uses self talk to "cool him/herself down". Client feels capable of handling future episodes of anger appropriately
A34: B3a | B34: Behavior | D34: Anxiety (Clinical Anxiety Scale) | E34: Client scores a 50 or above indicating a significant level of phobic and/or anxiety reactions related to specific situations or events such as trembling, twitching, feeling shaky, aches, restlessness, fatigue, shortness of breath, tachycardia, sweating, dizziness, etc. | F34: Client scores 30-49 indicating a clinically significant level of phobic and/or anxiety reactions related to specific situations or events | G34: Client scores between 20-29 and is free of a clinically significant problem with anxiety or phobia | H34: Client scores between 10-19 and is free of a clinically significant problem with anxiety or phobia | I34: Client scores between 0-9 and is free of a clinically significant problem with anxiety or phobia
A35: B4 | B35: Behavior | D35: Assaultive Behavior | E35: Patient has been isolated due to assaultive or destructive behavior | F35: Patient is destructive and assaultive every day | G35: 1 to 2 days free of assaultive behavior in last week | H35: 3 to 5 days free of assaultive behavior in last week | I35: 6 to 7 days free of assaultive behavior in last week
A36: B5 | B36: Behavior | D36: Assertiveness: Expressing Needs | E36: Rarely able to appropriately express needs and opinions | F36: Able to appropriately express needs and opinions some of the time | G36: Able to appropriately express needs and opinions some of the time, and is learning more appropriate ways of expression | H36: Able to appropriately express needs and opinions most of the time | I36: Able to appropriately express needs and opinions almost all of the time
A37: B6 | B37: Behavior | D37: Assertiveness: Learning Role Playing | E37: Client feels "walked over" by most people most of the time | F37: Client can identify situations in which s/he feels "walk over" | G37: Client is open to role-playing certain situations to increase assertiveness | H37: Client can role-play assertiveness and can transfer to real situations | I37: Client feels adequately prepared to handle future issues in which s/he will need to show assertiveness
A38: B7 | B38: Behavior | D38: Attention Seeking Behavior | E38: Spends less than 15 minutes in teacher/staff's company without inappropriate behaviors | F38: Spends at least 15 minutes in teacher/staff's company without inappropriate behaviors | G38: Spends at least 30 minutes in company of teacher/staff without inappropriate behaviors (poking, grabbing, screaming, or swearing) | H38: Spends at least 40 minutes | I38: At least 60 mins
A39: B8 | B39: Behavior | D39: Bedwetting | E39: Client wets the bed regularly | F39: Client wets the bed slightly less | G39: Client wets the bed 50% less | H39: Client rarely wets the bed | I39: Client has not wet the bed in the past 30 days
A40: B9 | B40: Behavior | D40: Bedwetting | E40: Wets to bed nightly. | F40: Wets to bed once a week. | G40: Child wets to bed once a month. | H40: Wets to bed less than once a month. | I40: No longer wets to bed.
A41: B10 | B41: Behavior | D41: Coping Skills | E41: Client reports no increase in ability to cope. | F41: Client reports minimal increase in ability to cope. | G41: Client reports an increased ability to cope with stressors after learning coping strategies. | H41: Client reports a significant increase in ability to cope. | I41: Client reports no major stressors and feels capable of coping with future stressors appropriately
A42: B11 | B42: Behavior | D42: Curfew | E42: Youth rarely comes home on time | F42: Youth comes home on time 2-3 times per week | G42: Youth comes home on time 4-5 times per week | H42: Youth comes home on time 6-7 times per week | I42: Youth has met curfew consistently for the past 4 weeks
... A65: B34 | B65: Behavior | D65: Verbal Aggression | E65: Verbal threats and verbal aggression used more than 5 times per week. | F65: Verbal threats and verbal aggression used at least once a week. | G65: Verbal threats & verbal aggression used less than once a week. | H65: Verbal threats and verbal aggression used less than once a month. | I65: Verbal threats and verbal aggression used less than once every 3 months.
A66: B35 | B66: Behavior | D66: ZCreate your own
A67: CC1 | B67: Child Care | D67: After School Care | E67: Children are not in after school care and no attempt to enroll. | F67: Children are enrolled in after school care but are attending infrequently (1 day per week). | G67: Children are in after school care and are attending most of the time | H67: Children are in after school care and are attending frequently | I67: Children are in after school care and are attending regularly
...

Sheet Your selected list
A1: Instructions:
A2: 1. Select goals from the "Complete GAS Bank" worksheet (the first tab at bottom left). In that worksheet, put an "x" in column B next to the chosen goal.
A3: 2. Once goals have been selected, move to worksheet titled "Your selected list" (this worksheet). Select "x" through the filter (the blue arrow) from "Put X in box if goal selected". Your chosen goals from the previous worksheet will appear.
A4: 3. You can type in the information asked in rows 8 and 9 (just double click on the selected cell to open it for modifications). You can make any needed goal or outcome modifications on this worksheet. You can put needed comments about the client's treatment at the bottom of this form.
A5: 4. If you want to save this document, click on the save icon and you will be prompted to save with a different file name.
A6: 5. To print this worksheet out, simply click on the print icon.
A7: 6. After your personalized goalsheet is printed out, put a date (of initial assessment) in the OUTCOME box (in the light blue box) that most accurately describes your client's state at initial assessment for each goal, and put a date (of the exit interview) in the OUTCOME box (in the white box) that most accurately describes your client's state at exit for each goal. You will also have these two dates in row 9.
A8: Personalized Goals for: | E8: Case Number: | G8: Counselor's Name:
A9: Date of Initial Assessment: (date first seen) | E9: Date of Final Assessment: (date last seen) | G9: # of Sessions: (including initial assessment)
A10: Reason for Termination: (put X in appropriate box or write in reason in space provided) | D10: Noncompliance | E10: No Shows | F10: Completed TX | G10: Other: _____________________________ ___________________________________
A11: GAS Code | B11: Put X in box if goal selected | C11: Treatment Goal | D11: Most unfavorable treatment outcome thought likely | E11: Less than expected success with treatment | F11: Expected level of treatment success | G11: More than expected success with treatment | H11: Best anticipated success with treatment
A12: ='Complete GAS Bank'!A4 -> A1 | B12: ='Complete GAS Bank'!C4 -> 0 | C12: ='Complete GAS Bank'!D4 -> Denial (Alcohol Related) | D12: ='Complete GAS Bank'!E4 -> Client does not think s/he has or has had any major problems due to drinking | E12: ='Complete GAS Bank'!F4 -> Client says maybe s/he has had problems due to drinking but nothing serious and nothing now | F12: ='Complete GAS Bank'!G4 -> Client says maybe s/he has current problems due to drinking but nothing s/he considers very serious | G12: ='Complete GAS Bank'!H4 -> Client can state 1 or 2 problems s/he wishes to work on | H12: ='Complete GAS Bank'!I4 -> Client is actively working on stated problems
A13: ='Complete GAS Bank'!A5 -> A2 | B13: ='Complete GAS Bank'!C5 -> 0 | C13: ='Complete GAS Bank'!D5 -> Drug Use | D13: ='Complete GAS Bank'!E5 -> Gets arrested for possession or use of drugs or uses drugs almost every day | E13: ='Complete GAS Bank'!F5 -> No arrests for possession or use of drugs but uses them twice per week or more | F13: ='Complete GAS Bank'!G5 -> No arrest for possession or use of drugs but continues to use about 4 to 7 times per month | G13: ='Complete GAS Bank'!H5 -> No arrest for possession or use of drugs but uses them 1 to 3 times per month | H13: ='Complete GAS Bank'!I5 -> No arrests for possession or use and reports no drug usage
A14: ='Complete GAS Bank'!A6 -> A3 | B14: ='Complete GAS Bank'!C6 -> 0 | C14: ='Complete GAS Bank'!D6 -> Drug Use Sponsor | D14: ='Complete GAS Bank'!E6 -> Does not attend group meetings and does not have a drug use sponsor | E14: ='Complete GAS Bank'!F6 -> Occasional attendance at group meetings, but does not have sponsor | F14: ='Complete GAS Bank'!G6 -> Occasional attendance at group meetings and finds and asks someone to be his/her sponsor | G14: ='Complete GAS Bank'!H6 -> Regular attendance at group meetings and less than daily contact with sponsor | H14: ='Complete GAS Bank'!I6 -> Daily attendance at group meetings and daily contact with sponsor
A15: ='Complete GAS Bank'!A7 -> A3a | B15: ='Complete GAS Bank'!C7 -> 0 | C15: ='Complete GAS Bank'!D7 -> Index of Drug Involvement (IDI) | D15: ='Complete GAS Bank'!E7 -> Client scores a 40 or above indicating a clinically significant personal or social problem with drugs resulting in serious problems around the use and abuse of drugs | E15: ='Complete GAS Bank'!F7 -> Client scores between 20-39 indicating a clinically significant personal or social problem with drugs | F15: ='Complete GAS Bank'!G7 -> Client scores between 10-19, indicating a nonsignificant clinical personal or social problem with drugs | G15: ='Complete GAS Bank'!H7 -> Client scores between 5-9, indicating a nonsignificant clinical personal or social problem with drugs | H15: ='Complete GAS Bank'!I7 -> Client scores between 0-4 indicating a nonsignificant clinical personal or social problem with drugs
A16: ='Complete GAS Bank'!A8 -> A4 | B16: ='Complete GAS Bank'!C8 -> 0 | C16: ='Complete GAS Bank'!D8 -> Individual Counseling for Drug Use | D16: ='Complete GAS Bank'!E8 -> No individual counseling for drug use | E16: ='Complete GAS Bank'!F8 -> Individual counseling for drug use sought | F16: ='Complete GAS Bank'!G8 -> Client can identify high risk people, places and things that influence drug use | G16: ='Complete GAS Bank'!H8 -> Client is making the attempt to change social setting (people, places, things) that influence drug use | H16: ='Complete GAS Bank'!I8 -> Client has changed social setting (people, places, things) that influence drug use
A17: ='Complete GAS Bank'!A9 -> A5 | B17: ='Complete GAS Bank'!C9 -> 0 | C17: ='Complete GAS Bank'!D9 -> Individual Counseling: Understanding Drug Impact on Others | D17: ='Complete GAS Bank'!E9 -> No individual counseling for drug use | E17: ='Complete GAS Bank'!F9 -> Individual counseling for drug use sought | F17: ='Complete GAS Bank'!G9 -> Client can identify the consequences they/others have endured on behalf of his/her drug use | G17: ='Complete GAS Bank'!H9 -> Client is considering how to make amends to those who have been affected by his/her drug use | H17: ='Complete GAS Bank'!I9 -> Client has attempted to make amends to those who have been affected by his/her drug use
A18: ='Complete GAS Bank'!A10 -> A6 | B18: ='Complete GAS Bank'!C10 -> 0 | C18: ='Complete GAS Bank'!D10 -> Substance Use | D18: ='Complete GAS Bank'!E10 -> Uses substances on a regular basis, no attempt to abstain. | E18: ='Complete GAS Bank'!F10 -> Attempts to abstain, but continues to use substances. | F18: ='Complete GAS Bank'!G10 -> Abstains from substance use, but doesn't attend group meetings. | G18: ='Complete GAS Bank'!H10 -> Abstains from use, and occasionally attends support group meetings. | H18: ='Complete GAS Bank'!I10 -> Complete abstinence and daily attendance in support groups.
A19: ='Complete GAS Bank'!A11 -> A7 | B19: ='Complete GAS Bank'!C11 -> 0 | C19: ='Complete GAS Bank'!D11 -> Weekly Substance Abuse | D19: ='Complete GAS Bank'!E11 -> Uses substances at least weekly. Unable to abstain. | E19: ='Complete GAS Bank'!F11 -> Uses substances at least once a month. | F19: ='Complete GAS Bank'!G11 -> Has not used substances for at least _____ months. | G19: ='Complete GAS Bank'!H11 -> Has not used substances for ___ months and attending treatment. | H19: ='Complete GAS Bank'!I11 -> Has not used substances for ___ months, attends treatment and/or support groups.
A20: ='Complete GAS Bank'!A12 -> A8 | B20: ='Complete GAS Bank'!C12 -> 0 | C20: ='Complete GAS Bank'!D12 -> ZCreate your own | D20: ='Complete GAS Bank'!E12 -> 0 | E20: ='Complete GAS Bank'!F12 -> 0 | F20: ='Complete GAS Bank'!G12 -> 0 | G20: ='Complete GAS Bank'!H12 -> 0 | H20: ='Complete GAS Bank'!I12 -> 0
A21: ='Complete GAS Bank'!A13 -> AC1 | B21: ='Complete GAS Bank'!C13 -> 0 | C21: ='Complete GAS Bank'!D13 -> Anxiety (Clinical Anxiety Scale) | D21: ='Complete GAS Bank'!E13 -> Client scores a 50 or above indicating a significant level of phobic and/or anxiety reactions related to specific situations or events such as trembling, twitching, feeling shaky, aches, restlessness, fatigue, shortness of breath, tachycardia, sweating, dizziness, etc. | E21: ='Complete GAS Bank'!F13 -> Client scores 30-49 indicating a clinically significant level of phobic and/or anxiety reactions related to specific situations or events | F21: ='Complete GAS Bank'!G13 -> Client scores between 20-29 and is free of a clinically significant problem with anxiety or phobia | G21: ='Complete GAS Bank'!H13 -> Client scores between 10-19 and is free of a clinically significant problem with anxiety or phobia | H21: ='Complete GAS Bank'!I13 -> Client scores between 0-9 and is free of a clinically significant problem with anxiety or phobia
A22: ='Complete GAS Bank'!A14 -> AC1a | B22: ='Complete GAS Bank'!C14 -> 0 | C22: ='Complete GAS Bank'!D14 -> Generalized Contentment Inventory | D22: ='Complete GAS Bank'!E14 -> A score of 70 or above indicating severe distress, possibly suicidal acting out | E22: ='Complete GAS Bank'!F14 -> A score between 31 and 69, indicating clinically significant nonpsychotic depression | F22: ='Complete GAS Bank'!G14 -> A score between 21-30, indicating client is free from clinical depression (nonpsychotic) | G22: ='Complete GAS Bank'!H14 -> A score between 11-20, indicating client is free from clinical depression (nonpsychotic) | H22: ='Complete GAS Bank'!I14 -> A score between 0-10, indicating client is free from clinical depression (nonpsychotic)
A23: ='Complete GAS Bank'!A15 -> AC2 | B23: ='Complete GAS Bank'!C15 -> 0 | C23: ='Complete GAS Bank'!D15 -> Decision-Making | D23: ='Complete GAS Bank'!E15 -> Can consider alternatives but makes no decisions. | E23: ='Complete GAS Bank'!F15 -> Makes concrete plans, but no follow-through. | F23: ='Complete GAS Bank'!G15 -> Makes concrete plans, follows through with assistance. | G23: ='Complete GAS Bank'!H15 -> Makes concrete plans, follows through without assistance. | H23: ='Complete GAS Bank'!I15 -> Makes concrete plans, reaches goal without assistance.
... A104: ='Complete GAS Bank'!A96 -> E3 | B104: ='Complete GAS Bank'!C96 -> 0 | C104: ='Complete GAS Bank'!D96 -> Education: HS Diploma/GED | D104: ='Complete GAS Bank'!E96 -> No high school diploma and not enrolled in GED. | E104: ='Complete GAS Bank'!F96 -> Enrolled in H.S. or GED but has multiple unexcused absences. | F104: ='Complete GAS Bank'!G96 -> Attending H.S./GED classes and no unexcused absences. | G104: ='Complete GAS Bank'!H96 -> Obtained GED/H.S. or attending vocational school after. | H104: ='Complete GAS Bank'!I96 -> Enrolled in classes at community or 4 year college.
A105: ='Complete GAS Bank'!A98 -> E4 | B105: ='Complete GAS Bank'!C98 -> 0 | C105: ='Complete GAS Bank'!D98 -> Educational Future: College/Vocational School | D105: ='Complete GAS Bank'!E98 -> No decision about educational future; still ambivalent and aimless | E105: ='Complete GAS Bank'!F98 -> Decision to attend college or vocational school, but has not actually enrolled | F105: ='Complete GAS Bank'!G98 -> Enrolled in a vocational school or college but does not appear motivated for scholastic activity | G105: ='Complete GAS Bank'!H98 -> Enrolled in vocational or college and seems motivated for scholastic activity | H105: ='Complete GAS Bank'!I98 -> Enrolled in vocational or college and is maintaining acceptable grades
A106: ='Complete GAS Bank'!A99 -> E5 | B106: ='Complete GAS Bank'!C99 -> 0 | C106: ='Complete GAS Bank'!D99 -> Father's education | D106: ='Complete GAS Bank'!E99 -> No high school diploma, not enrolled in GED classes, and not attending ESL classes, if applicable. | E106: ='Complete GAS Bank'!F99 -> Enrolled in GED class or High School or ESL classes and has multiple unexcused absences. | F106: ='Complete GAS Bank'!G99 -> Has no educational goals and/or attending ESL, GED, or High School classes with no unexcused absences. | G106: ='Complete GAS Bank'!H99 -> Obtained GED or has high school diploma or completed ESL classes. | H106: ='Complete GAS Bank'!I99 -> Enrolled in classes at a junior or 4-year college.
A107: ='Complete GAS Bank'!A100 -> E6 | B107: ='Complete GAS Bank'!C100 -> 0 | C107: ='Complete GAS Bank'!D100 -> Mother's education | D107: ='Complete GAS Bank'!E100 -> No high school diploma, not enrolled in GED classes, and not attending ESL classes, if applicable. | E107: ='Complete GAS Bank'!F100 -> Enrolled in GED class or High School or ESL classes and has multiple unexcused absences. | F107: ='Complete GAS Bank'!G100 -> Has no educational goals and/or attending ESL, GED, or High School classes with no unexcused absences. | G107: ='Complete GAS Bank'!H100 -> Obtained GED or has high school diploma or completed ESL classes or attending a vocational school. | H107: ='Complete GAS Bank'!I100 -> Enrolled in classes at a junior or 4-year college.
A108: ='Complete GAS Bank'!A101 -> E7 | B108: ='Complete GAS Bank'!C101 -> 0 | C108: ='Complete GAS Bank'!D101 -> ZCreate your own | D108: ='Complete GAS Bank'!E101 -> 0 | E108: ='Complete GAS Bank'!F101 -> 0 | F108: ='Complete GAS Bank'!G101 -> 0 | G108: ='Complete GAS Bank'!H101 -> 0 | H108: ='Complete GAS Bank'!I101 -> 0
A109: ='Complete GAS Bank'!A102 -> Em1 | B109: ='Complete GAS Bank'!C102 -> 0 | C109: ='Complete GAS Bank'!D102 -> Career Planning | D109: ='Complete GAS Bank'!E102 -> Has not chosen any preferred fields. | E109: ='Complete GAS Bank'!F102 -> One or more fields chosen but no planning. | F109: ='Complete GAS Bank'!G102 -> Selected one or more fields with plans for achieving at least one. | G109: ='Complete GAS Bank'!H102 -> Has followed through with plan (application, interview, etc.) | H109: ='Complete GAS Bank'!I102 -> Acquired job in a selected field.
A110: ='Complete GAS Bank'!A103 -> Em2 | B110: ='Complete GAS Bank'!C103 -> 0 | C110: ='Complete GAS Bank'!D103 -> Employment | D110: ='Complete GAS Bank'!E103 -> No Employment | E110: ='Complete GAS Bank'!F103 -> Less than 32 hours a week employment or employed 32+ hours a week | F110: ='Complete GAS Bank'!G103 -> Usually 32+ hours a week employment | G110: ='Complete GAS Bank'!H103 -> Consistently 32+ hours a week | H110: ='Complete GAS Bank'!I103 -> 32+ hours a week employment with full benefits.
A111: ='Complete GAS Bank'!A104 -> Em3 | B111: ='Complete GAS Bank'!C104 -> 0 | C111: ='Complete GAS Bank'!D104 -> Employment: Applications & Interviews | D111: ='Complete GAS Bank'!E104 -> No applications obtained | E111: ='Complete GAS Bank'!F104 -> Applications obtained. | F111: ='Complete GAS Bank'!G104 -> Applications submitted | G111: ='Complete GAS Bank'!H104 -> Interviews set | H111: ='Complete GAS Bank'!I104 -> Full time employment obtained
A112: ='Complete GAS Bank'!A105 -> Em4 | B112: ='Complete GAS Bank'!C105 -> 0 | C112: ='Complete GAS Bank'!D105 -> Employment: Applying and Maintaining | D112: ='Complete GAS Bank'!E105 -> Has not obtained employment and has not applied for employment. | E112: ='Complete GAS Bank'!F105 -> Has not obtained employment, but did apply for employment. | F112: ='Complete GAS Bank'!G105 -> Obtained employment. | G112: ='Complete GAS Bank'!H105 -> Maintained employment for at least 3months. | H112: ='Complete GAS Bank'!I105 -> Maintained employment for at least 6 months.
A113: ='Complete GAS Bank'!A106 -> Em5 | B113: ='Complete GAS Bank'!C106 -> 0 | C113: ='Complete GAS Bank'!D106 -> Employment: Pay Increase | D113: ='Complete GAS Bank'!E106 -> Pay not increased | E113: ='Complete GAS Bank'!F106 -> Pay increased by less than 3% | F113: ='Complete GAS Bank'!G106 -> Pay increased by 3-5% | G113: ='Complete GAS Bank'!H106 -> Pay increased by 6-10% | H113: ='Complete GAS Bank'!I106 -> Pay increased by more than 10%
A114: ='Complete GAS Bank'!A107 -> Em6 | B114: ='Complete GAS Bank'!C107 -> 0 | C114: ='Complete GAS Bank'!D107 -> Father's employment | D114: ='Complete GAS Bank'!E107 -> No employment or job training. | E114: ='Complete GAS Bank'!F107 -> Enrolled in job training with unexcused absences or sporadic employment search or unstable employment. | F114: ='Complete GAS Bank'!G107 -> Caring for non-school age child full-time or in job training program with no unexcused absences or actively seeking work. | G114: ='Complete GAS Bank'!H107 -> Stable full-time or part-time employment and receiving supplemental public assistance. | H114: ='Complete GAS Bank'!I107 -> Stable full-time or part-time employment and receiving no supplemental public assistance.
A115: ='Complete GAS Bank'!A108 -> Em7 | B115: ='Complete GAS Bank'!C108 -> 0 | C115: ='Complete GAS Bank'!D108 -> Maintaining Employment | D115: ='Complete GAS Bank'!E108 -> Has not worked since case opened. | E115: ='Complete GAS Bank'!F108 -> Has worked some, but not currently working. | F115: ='Complete GAS Bank'!G108 -> Currently working, changes jobs or first job. | G115: ='Complete GAS Bank'!H108 -> Currently working, has not changed jobs for at least 6 months. | H115: ='Complete GAS Bank'!I108 -> Currently working, has not changed jobs for at least 12 months.
A116: ='Complete GAS Bank'!A109 -> Em8 | B116: ='Complete GAS Bank'!C109 -> 0 | C116: ='Complete GAS Bank'!D109 -> Mother’s employment | D116: ='Complete GAS Bank'!E109 -> No employment or job training | E116: ='Complete GAS Bank'!F109 -> Enrolled in job training with unexcused absences or sporadic employment search or unstable employment | F116: ='Complete GAS Bank'!G109 -> Caring for non-school age child full-time or in job training program with no unexcused absences or actively seeking work OR Mother unavailable for employment | G116: ='Complete GAS Bank'!H109 -> Stable full-time or part-time employment and receiving and supplemental public assistance | H116: ='Complete GAS Bank'!I109 -> Stable full-time or part-time employment and receiving no supplemental public assistance
... A142: ='Complete GAS Bank'!A135 -> H6 | B142: ='Complete GAS Bank'!C135 -> 0 | C142: ='Complete GAS Bank'!D135 -> Health Coverage | D142: ='Complete GAS Bank'!E135 -> Not eligible for CHIPS or Medicaid/no health coverage. | E142: ='Complete GAS Bank'!F135 -> Has not enrolled in CHIPS or Medicaid. | F142: ='Complete GAS Bank'!G135 -> Enrolled in CHIPS or Medicaid | G142: ='Complete GAS Bank'!H135 -> CHIPS or Medicaid obtained and utilized. | H142: ='Complete GAS Bank'!I135 -> Health coverage beyond CHIPS/Medicaid obtained.
A143: ='Complete GAS Bank'!A137 -> H7 | B143: ='Complete GAS Bank'!C137 -> 0 | C143: ='Complete GAS Bank'!D137 -> Hygiene | D143: ='Complete GAS Bank'!E137 -> Chronic hygiene problems. | E143: ='Complete GAS Bank'!F137 -> Occasional hygiene problems. | F143: ='Complete GAS Bank'!G137 -> Meets minimum hygiene. Working towards better hygiene | G143: ='Complete GAS Bank'!H137 -> Consistent proper hygiene. | H143: ='Complete GAS Bank'!I137 -> No school referrals or observations regarding hygiene. Hygiene not a problem for any family member.
A144: ='Complete GAS Bank'!A138 -> H8 | B144: ='Complete GAS Bank'!C138 -> 0 | C144: ='Complete GAS Bank'!D138 -> Medical Needs | D144: ='Complete GAS Bank'!E138 -> Medical problems go unaddressed. | E144: ='Complete GAS Bank'!F138 -> Plans made to address immediate medical problems. | F144: ='Complete GAS Bank'!G138 -> Immediate medical needs addressed. | G144: ='Complete GAS Bank'!H138 -> Progress made toward resolution of all medical needs. | H144: ='Complete GAS Bank'!I138 -> All medical needs resolved.
A145: ='Complete GAS Bank'!A139 -> H9 | B145: ='Complete GAS Bank'!C139 -> 0 | C145: ='Complete GAS Bank'!D139 -> Prenatal care | D145: ='Complete GAS Bank'!E139 -> No prenatal care | E145: ='Complete GAS Bank'!F139 -> Seeking prenatal care but have delayed access | F145: ='Complete GAS Bank'!G139 -> Client has prenatal care upon confirmation of pregnancy and attends all doctor appointments | G145: ='Complete GAS Bank'!H139 -> Client has prenatal care and also participates in parenting classes and/or child birth education classes | H145: ='Complete GAS Bank'!I139 -> Client has prenatal care in first trimester and also participates in parenting classes and/or child birth education classes
...
