Workbook

Sheet input-output
M2: ='Data Analysis'!A2 -> Geotech
H3: ='Data Analysis'!A2 -> Geotech | I3: ='Data Analysis'!B1 -> Outcome Total | J3: Outcome | K3: Comparison | M3: ='Data Analysis'!CO3 -> Fundamntal Courses | N3: ='Data Analysis'!CP3 -> CE 1030 | O3: ='Data Analysis'!CQ3 -> CE 2000 | P3: ='Data Analysis'!CR3 -> CE 2001 | Q3: ='Data Analysis'!CS3 -> CE 2020 | R3: ='Data Analysis'!CT3 -> ES 3004 | S3: ='Data Analysis'!CU3 -> CE 3041
H4: ='Data Analysis'!A3 -> OUTCOMES | I4: Sum | J4: Target | M4: ='Data Analysis'!CO4 -> Background Courss | N4: ='Data Analysis'!CP4 -> CE 3030 | O4: ='Data Analysis'!CQ4 -> ES 2503 | P4: ='Data Analysis'!CR4 -> ES 3001 | Q4: ='Data Analysis'!CS4 -> no EE 3601
H5: ='Data Analysis'!A4 -> 1. Components of civil engineering practice: | I5: ='Data Analysis'!B4 -> 134 | J5: 106.2 | K5: =IF(I5>J5,"Over","Under") -> Over | M5: ='Data Analysis'!CO5 -> Structural | N5: ='Data Analysis'!CP5 -> CE 3010 | O5: ='Data Analysis'!CQ5 -> CE 2002 | P5: ='Data Analysis'!CR5 -> - | Q5: ='Data Analysis'!CS5 -> CE 3008 | R5: ='Data Analysis'!CT5 -> CE 3026 | S5: ='Data Analysis'!CU5 -> - | T5: ='Data Analysis'!CV5 -> -
H6: ='Data Analysis'!A5 -> a. Technical | I6: ='Data Analysis'!B5 -> 73 | J6: 72 | K6: =IF(I6>J6,"Over","Under") -> Over | M6: ='Data Analysis'!CO6 -> Geotechnical | N6: ='Data Analysis'!CP6 -> CE 3041 | O6: ='Data Analysis'!CQ6 -> CE 3044 | P6: ='Data Analysis'!CR6 -> CE 4046 | Q6: ='Data Analysis'!CS6 -> CE 4048
H7: ='Data Analysis'!A6 -> b. Professional | I7: ='Data Analysis'!B6 -> 41 | J7: 27 | K7: =IF(I7>J7,"Over","Under") -> Over | M7: ='Data Analysis'!CO7 -> Environmental and Hydraulics | N7: ='Data Analysis'!CP7 -> - | O7: ='Data Analysis'!CQ7 -> - | P7: ='Data Analysis'!CR7 -> - | Q7: ='Data Analysis'!CS7 -> - | R7: ='Data Analysis'!CT7 -> - | S7: ='Data Analysis'!CU7 -> -
H8: ='Data Analysis'!A7 -> c. Ethical | I8: ='Data Analysis'!B7 -> 20 | J8: 7.2 | K8: =IF(I8>J8,"Over","Under") -> Over | M8: ='Data Analysis'!CO8 -> Urban and Environmental Planning | N8: ='Data Analysis'!CP8 -> - | O8: ='Data Analysis'!CQ8 -> - | P8: ='Data Analysis'!CR8 -> -
C9: Name | D9: Geotech | H9: ='Data Analysis'!A8 -> 2. Preparation for the future changes in civil engineering. | I9: ='Data Analysis'!B8 -> 29 | J9: 21.6 | K9: =IF(I9>J9,"Over","Under") -> Over | M9: ='Data Analysis'!CO9 -> Transportation | N9: ='Data Analysis'!CP9 -> CE 3050 | O9: ='Data Analysis'!CQ9 -> - | P9: ='Data Analysis'!CR9 -> - | Q9: ='Data Analysis'!CS9 -> -
C10: CE1030 | D10: x | E10: ES 2503 | F10: x | H10: ='Data Analysis'!A9 -> 3. Understanding of basic principles of civil engineering (please list and assess each principle). | I10: ='Data Analysis'!B9 -> 263 | J10: 124.2 | K10: =IF(I10>J10,"Over","Under") -> Over | M10: ='Data Analysis'!CO10 -> Construction and Management | N10: ='Data Analysis'!CP10 -> CE 3020 | O10: ='Data Analysis'!CQ10 -> - | P10: ='Data Analysis'!CR10 -> - | Q10: ='Data Analysis'!CS10 -> - | R10: ='Data Analysis'!CT10 -> -
C11: CE2000 | D11: x | E11: ES 3001 | F11: x | H11: ='Data Analysis'!A10 -> a. Computers and Information Technology | I11: ='Data Analysis'!B10 -> 34 | J11: 24.3 | K11: =IF(I11>J11,"Over","Under") -> Over | M11: Chemistry | N11: ='Data Analysis'!CP11 -> CH 1010 | O11: ='Data Analysis'!CQ11 -> - | P11: Outcome = | Q11: =I23 -> 11
C12: CE2001 | D12: x | E12: EE 3601 | H12: ='Data Analysis'!A11 -> b. Geographic Positioning and Measurements | I12: ='Data Analysis'!B11 -> 23 | J12: 8.1 | K12: =IF(I12>J12,"Over","Under") -> Over | M12: Statistics | N12: ='Data Analysis'!CP12 -> MA 2011 | P12: Outcome = | Q12: =I28 -> 16
C13: CE2002 | D13: x | E13: MA 2611 | F13: x | H13: ='Data Analysis'!A12 -> c. Solid (Structural) Mechanics | I13: ='Data Analysis'!B12 -> 49 | J13: 14.4 | K13: =IF(I13>J13,"Over","Under") -> Over
C14: CE2020 | D14: x | E14: CH 1010 | F14: x | H14: ='Data Analysis'!A13 -> d. Soil Mechanics | I14: ='Data Analysis'!B13 -> 22 | J14: 3.6 | K14: =IF(I14>J14,"Over","Under") -> Over
C15: ES3004 | D15: x | E15: CH 2020 | H15: ='Data Analysis'!A14 -> e. Fluid Mechanics/Hydrology | I15: ='Data Analysis'!B14 -> 16 | J15: 18 | K15: =IF(I15>J15,"Over","Under") -> Under
C16: CE3006 | H16: ='Data Analysis'!A15 -> f. Design | I16: ='Data Analysis'!B15 -> 55 | J16: 32.4 | K16: =IF(I16>J16,"Over","Under") -> Over
C17: CE3008 | D17: x | H17: ='Data Analysis'!A16 -> g. Construction Materials | I17: ='Data Analysis'!B16 -> 28 | J17: 7.2 | K17: =IF(I17>J17,"Over","Under") -> Over
C18: CE3010 | D18: x | H18: ='Data Analysis'!A17 -> h. Systems Analysis and Modeling | I18: ='Data Analysis'!B17 -> 11 | J18: 8.1 | K18: =IF(I18>J18,"Over","Under") -> Over | M18: Total Course (Equiv) Science = | N18: ='Data Analysis'!EJ3 -> 11
C19: CE3020 | D19: x | H19: ='Data Analysis'!A18 -> i. Engineering Economics & Risk Management | I19: ='Data Analysis'!B18 -> 25 | J19: 8.1 | K19: =IF(I19>J19,"Over","Under") -> Over | M19: Total Course (Equiv) Design = | N19: ='Data Analysis'!EJ4 -> 7
C20: CE3021 | H20: ='Data Analysis'!A19 -> j.
C21: CE3022 | H21: ='Data Analysis'!A20 -> 4. Understanding and application of: | I21: ='Data Analysis'!B20 -> 118 | J21: 32.22 | K21: =IF(I21>J21,"Over","Under") -> Over
C22: CE3023 | H22: ='Data Analysis'!A21 -> a. Biology | I22: ='Data Analysis'!B21 -> 1 | J22: 1.8 | K22: =IF(I22>J22,"Over","Under") -> Under | P22: Sum of all Extents = | R22: =I52 -> 956
C23: CE3024 | H23: ='Data Analysis'!A22 -> b. Chemistry | I23: ='Data Analysis'!B22 -> 11 | J23: 5.4 | K23: =IF(I23>J23,"Over","Under") -> Over
C24: CE3026 | D24: x | H24: ='Data Analysis'!A23 -> c. Geology | I24: ='Data Analysis'!B23 -> 12 | J24: 4.5 | K24: =IF(I24>J24,"Over","Under") -> Over
C25: CE3030 | D25: x | H25: ='Data Analysis'!A24 -> d. Physics | I25: ='Data Analysis'!B24 -> 26 | J25: 3.6 | K25: =IF(I25>J25,"Over","Under") -> Over
C26: CE3041 | D26: x | H26: ='Data Analysis'!A25 -> e. Differential and Integral Calculus | I26: ='Data Analysis'!B25 -> 22 | J26: 5.4 | K26: =IF(I26>J26,"Over","Under") -> Over
C27: CE3044 | D27: x | H27: ='Data Analysis'!A26 -> f. Differential Equations | I27: ='Data Analysis'!B26 -> 15 | J27: 1.8 | K27: =IF(I27>J27,"Over","Under") -> Over
C28: CE3050 | D28: x | H28: ='Data Analysis'!A27 -> g. Probability and Statistics | I28: ='Data Analysis'!B27 -> 16 | J28: 7.2 | K28: =IF(I28>J28,"Over","Under") -> Over
C29: CE3051 | H29: ='Data Analysis'!A28 -> h. Linear Algebra | I29: ='Data Analysis'!B28 -> 13 | J29: 1.8 | K29: =IF(I29>J29,"Over","Under") -> Over
C30: CE3054 | H30: ='Data Analysis'!A29 -> i. Higher Mathematics | I30: ='Data Analysis'!B29 -> 2 | J30: 0.72 | K30: =IF(I30>J30,"Over","Under") -> Over
C31: CE3059 | H31: ='Data Analysis'!A30 -> 5. Understanding of engineering design process, including the following: | I31: ='Data Analysis'!B30 -> 168 | J31: 117.9 | K31: =IF(I31>J31,"Over","Under") -> Over
C32: CE3060 | H32: ='Data Analysis'!A31 -> a. Ability to perform design. | I32: ='Data Analysis'!B31 -> 47 | J32: 50.4 | K32: =IF(I32>J32,"Over","Under") -> Under
C33: CE3061 | H33: ='Data Analysis'!A32 -> b. Multidisciplinary aspects. | I33: ='Data Analysis'!B32 -> 20 | J33: 8.1 | K33: =IF(I33>J33,"Over","Under") -> Over
C34: CE3062 | H34: ='Data Analysis'!A33 -> c. Collaboration skills. | I34: ='Data Analysis'!B33 -> 27 | J34: 21.6 | K34: =IF(I34>J34,"Over","Under") -> Over
C35: CE3070 | H35: ='Data Analysis'!A34 -> d. Communication skills. | I35: ='Data Analysis'!B34 -> 38 | J35: 21.6 | K35: =IF(I35>J35,"Over","Under") -> Over
C36: CE3074 | H36: ='Data Analysis'!A35 -> e. Consideration of cost. | I36: ='Data Analysis'!B35 -> 26 | J36: 8.1 | K36: =IF(I36>J36,"Over","Under") -> Over
C37: CE4007 | H37: ='Data Analysis'!A36 -> f. Consideration of time management. | I37: ='Data Analysis'!B36 -> 10 | J37: 8.1 | K37: =IF(I37>J37,"Over","Under") -> Over
C38: CE4017 | H38: ='Data Analysis'!A37 -> 6. Demonstration of an ability to: | I38: ='Data Analysis'!B37 -> 66 | J38: 37.8 | K38: =IF(I38>J38,"Over","Under") -> Over
C39: CE355X | H39: ='Data Analysis'!A38 -> a. Setup experiments. | I39: ='Data Analysis'!B38 -> 18 | J39: 9 | K39: =IF(I39>J39,"Over","Under") -> Over
C40: CE4046 | D40: x | H40: ='Data Analysis'!A39 -> b. Gather and analyze data. | I40: ='Data Analysis'!B39 -> 23 | J40: 14.4 | K40: =IF(I40>J40,"Over","Under") -> Over
C41: CE4048 | D41: x | H41: ='Data Analysis'!A40 -> c. Apply the data to practical engineering problems. | I41: ='Data Analysis'!B40 -> 25 | J41: 14.4 | K41: =IF(I41>J41,"Over","Under") -> Over
...

Sheet Data Analysis
A1: Note: Courses highlighted in red have no outcomes identified | B1: Outcome Total | C1: Outcome (%) | D1: CE1030 | E1: CE2000 | F1: CE2001 | G1: CE2002 | H1: CE2020 | I1: ES3004 | J1: CE3006 | K1: CE3008 | L1: CE3010 | M1: CE3020 | N1: CE3021 | O1: CE3022 | P1: CE3023 | Q1: CE3024 | R1: CE3026 | S1: CE3030 | T1: CE3041 | U1: CE3044 | V1: CE3050 | W1: CE3051 | X1: CE3054 | Y1: CE3059 | Z1: CE3060 | AA1: CE3061 | AB1: CE3062 | AC1: CE3070 | AD1: CE3074 | AE1: CE4007 | AF1: CE4017 | AG1: CE355X | AH1: CE4046 | AI1: CE4048 | AJ1: CE4060 | AK1: CE4061 | AL1: CE4071 | AM1: ES2503 | AN1: ES3001 | AO1: EE3601 | AP1: MA 2011 | AQ1: CH 1010 | AR1: CH 1020 | CX1: CE1030 | CY1: CE2000 | CZ1: CE2001 | DA1: CE2002 | DB1: CE2020 | DC1: ES3004 | DD1: CE3006 | DE1: CE3008 | DF1: CE3010 | DG1: CE3020 | DH1: CE3021 | DI1: CE3022 | DJ1: CE3023 | DK1: CE3024 | DL1: CE3026 | DM1: CE3030 | DN1: CE3041 | DO1: CE3044 | DP1: CE3050 | DQ1: CE3051 | DR1: CE3054 | DS1: CE3059 | DT1: CE3060 | DU1: CE3061 | DV1: CE3062 | DW1: CE3070 | DX1: CE3074 | DY1: CE4007 | DZ1: CE4017 | EA1: CE355X | EB1: CE4046 | EC1: CE4048 | ED1: CE4060 | EE1: CE4061 | EF1: CE4071 | EG1: ES2503 | EH1: ES3001 | EI1: EE3601 | EJ1: Sum
A2: ='input-output'!D9 -> Geotech | D2: ='input-output'!D10 -> x | E2: ='input-output'!D11 -> x | F2: ='input-output'!D12 -> x | G2: ='input-output'!D13 -> x | H2: ='input-output'!D14 -> x | I2: ='input-output'!D15 -> x | J2: ='input-output'!D16 -> 0 | K2: ='input-output'!D17 -> x | L2: ='input-output'!D18 -> x | M2: ='input-output'!D19 -> x | N2: ='input-output'!D20 -> 0 | O2: ='input-output'!D21 -> 0 | P2: ='input-output'!D22 -> 0 | Q2: ='input-output'!D23 -> 0 | R2: ='input-output'!D24 -> x | S2: ='input-output'!D25 -> x | T2: ='input-output'!D26 -> x | U2: ='input-output'!D27 -> x | V2: ='input-output'!D28 -> x | W2: ='input-output'!D29 -> 0 | X2: ='input-output'!D30 -> 0 | Y2: ='input-output'!D31 -> 0 | Z2: ='input-output'!D32 -> 0 | AA2: ='input-output'!D33 -> 0 | AB2: ='input-output'!D34 -> 0 | AC2: ='input-output'!D35 -> 0 | AD2: ='input-output'!D36 -> 0 | AE2: ='input-output'!D37 -> 0 | AF2: ='input-output'!D38 -> 0 | AG2: ='input-output'!D39 -> 0 | AH2: ='input-output'!D40 -> x | AI2: ='input-output'!D41 -> x | AJ2: ='input-output'!D42 -> 0 | AK2: ='input-output'!D43 -> 0 | AL2: ='input-output'!D44 -> 0 | AM2: ='input-output'!F10 -> x | AN2: ='input-output'!F11 -> x | AO2: ='input-output'!F12 -> 0 | AP2: ='input-output'!F13 -> x | AQ2: ='input-output'!F14 -> x | AR2: ='input-output'!F15 -> 0 | CR2: Civil Engineering Distribution
A3: OUTCOMES | CO3: Fundamntal Courses | CP3: =IF(D2="x","CE 1030", "(no CE 1030 )") -> CE 1030 | CQ3: =IF(E2="x"," CE 2000 ","no CE 2000 ") -> CE 2000 | CR3: =IF(F2="x","CE 2001","no CE 2001") -> CE 2001 | CS3: =IF(H2="x","CE 2020", "no CE 2020") -> CE 2020 | CT3: =IF(I2="x","ES 3004", "no ES 3004") -> ES 3004 | CU3: =IF(T2="x","CE 3041", "no CE 3041") -> CE 3041 | CX3: =IF(D$2="x",0.5,0) -> 0.5 | CY3: =IF(E$2="x",1,0) -> 1 | CZ3: =IF(F$2="x",1,0) -> 1 | DA3: =IF(G$2="x",1,0) -> 1 | DB3: =IF(H$2="x",1,0) -> 1 | DC3: =IF(I$2="x",1,0) -> 1 | DD3: =IF(J$2="x",0,0) -> 0 | DE3: =IF(K$2="x",0,0) -> 0 | DF3: =IF(L$2="x",0,0) -> 0 | DG3: =IF(M$2="x",0.25,0) -> 0.25 | DH3: =IF(N$2="x",0.25,0) -> 0 | DI3: =IF(O$2="x",0,0) -> 0 | DJ3: =IF(P$2="x",0,0) -> 0 | DK3: =IF(Q$2="x",1,0) -> 0 | DL3: =IF(R$2="x",1,0) -> 1 | DM3: =IF(S$2="x",0.25,0) -> 0.25 | DN3: =IF(T$2="x",1,0) -> 1 | DO3: =IF(U$2="x",0,0) -> 0 | DP3: =IF(V$2="x",0.25,0) -> 0.25 | DQ3: =IF(W$2="x",0.5,0) -> 0 | DR3: =IF(X$2="x",0.5,0) -> 0 | DS3: =IF(Y$2="x",0.75,0) -> 0 | DT3: =IF(Z$2="x",0.25,0) -> 0 | DU3: =IF(AA$2="x",0.25,0) -> 0 | DV3: =IF(AB$2="x",0.75,0) -> 0 | DW3: =IF(AC$2="x",0,0) -> 0 | DX3: =IF(AD$2="x",0.75,0) -> 0 | DY3: =IF(AE$2="x",1,0) -> 0 | DZ3: =IF(AF$2="x",0,0) -> 0 | EA3: =IF(AG$2="x",0.9,0) -> 0 | EB3: =IF(AH$2="x",0.5,0) -> 0.5 | EC3: =IF(AI$2="x",0.25,0) -> 0.25 | ED3: =IF(AJ$2="x",0.75,0) -> 0 | EE3: =IF(AK$2="x",0.5,0) -> 0 | EF3: =IF(AL$2="x",0,0) -> 0 | EG3: =IF(AM$2="x",1,0) -> 1 | EH3: =IF(AN$2="x",1,0) -> 1 | EI3: =IF(AO$2="x",1,0) -> 0 | EJ3: =SUM(CX3:EI3) -> 11 | EK3: sum sci
A4: 1. Components of civil engineering practice: | B4: =SUM(B5:B7) -> 134 | C4: =B4/$B$46 -> 0.14016736 | CO4: Background Courss | CP4: =IF(S2="x","CE 3030", "no CE 3030 ") -> CE 3030 | CQ4: =IF(AM2="x","ES 2503", "no ES 2503 ") -> ES 2503 | CR4: =IF(AN2="x","ES 3001", "no ES 3001") -> ES 3001 | CS4: =IF(AO2="x","EE 3601", "no EE 3601") -> no EE 3601 | CX4: =IF(D$2="x",0.5,0) -> 0.5 | CY4: =IF(E$2="x",0,0) -> 0 | CZ4: =IF(F$2="x",0,0) -> 0 | DA4: =IF(G$2="x",0,0) -> 0 | DB4: =IF(H$2="x",0,0) -> 0 | DC4: =IF(I$2="x",0,0) -> 0 | DD4: =IF(J$2="x",1,0) -> 0 | DE4: =IF(K$2="x",1,0) -> 1 | DF4: =IF(L$2="x",1,0) -> 1 | DG4: =IF(M$2="x",0.75,0) -> 0.75 | DH4: =IF(N$2="x",0.75,0) -> 0 | DI4: =IF(O$2="x",0.75,0) -> 0 | DJ4: =IF(P$2="x",1,0) -> 0 | DK4: =IF(Q$2="x",0,0) -> 0 | DL4: =IF(R$2="x",0,0) -> 0 | DM4: =IF(S$2="x",0.75,0) -> 0.75 | DN4: =IF(T$2="x",0,0) -> 0 | DO4: =IF(U$2="x",1,0) -> 1 | DP4: =IF(V$2="x",0.75,0) -> 0.75 | DQ4: =IF(W$2="x",0.5,0) -> 0 | DR4: =IF(X$2="x",0.5,0) -> 0 | DS4: =IF(Y$2="x",0.25,0) -> 0 | DT4: =IF(Z$2="x",0.75,0) -> 0 | DU4: =IF(AA$2="x",0.75,0) -> 0 | DV4: =IF(AB$2="x",0.25,0) -> 0 | DW4: =IF(AC$2="x",1,0) -> 0 | DX4: =IF(AD$2="x",0.25,0) -> 0 | DY4: =IF(AE$2="x",0,0) -> 0 | DZ4: =IF(AF$2="x",1,0) -> 0 | EA4: =IF(AG$2="x",0.1,0) -> 0 | EB4: =IF(AH$2="x",0.5,0) -> 0.5 | EC4: =IF(AI$2="x",0.75,0) -> 0.75 | ED4: =IF(AJ$2="x",0.25,0) -> 0 | EE4: =IF(AK$2="x",0.5,0) -> 0 | EF4: =IF(AL$2="x",1,0) -> 0 | EG4: =IF(AM$2="x",0,0) -> 0 | EH4: =IF(AN$2="x",0,0) -> 0 | EI4: =IF(AO$2="x",0,0) -> 0 | EJ4: =SUM(CX4:EI4) -> 7 | EK4: sum eng
A5: a. Technical | B5: =IF('input-output'!$I$48="Y", 'Data Analysis'!CL5,'Data Analysis'!CM5) -> 73 | C5: =B5/$B$46 -> 0.076359833 | D5: 2 | E5: 5 | F5: 5 | G5: 5 | H5: 3 | I5: 4 | J5: 5 | K5: 5 | L5: 5 | M5: 4 | N5: 4 | O5: 0 | P5: 4 | Q5: 3 | R5: 5 | S5: 5 | T5: 5 | U5: 5 | V5: 5 | W5: 5 | X5: 5 | Y5: 4 | Z5: 4 | AA5: 4 | AB5: 4 | AC5: 0 | AD5: 5 | AE5: 5 | AF5: 5 | AG5: 5 | AH5: 5 | AI5: 5 | AJ5: 5 | AK5: 4 | AL5: 0 | AU5: =IF(D$2="x",D5,0) -> 2 | AV5: =IF(E$2="x",E5,0) -> 5 | AW5: =IF(F$2="x",F5,0) -> 5 | AX5: =IF(G$2="x",G5,0) -> 5 | AY5: =IF(H$2="x",H5,0) -> 3 | AZ5: =IF(I$2="x",I5,0) -> 4 | BA5: =IF(J$2="x",J5,0) -> 0 | BB5: =IF(K$2="x",K5,0) -> 5 | ... CI5: =IF(AR$2="x",AR5,0) -> 0 | CL5: =SUM(AU5:CI5) -> 73 | CM5: =SUM(IF(AU5>=4,AU5,0)+IF(AV5>=4,AV5,0)+IF(AW5>=4,AW5,0)+IF(AX5>=4,AX5,0)+IF(AY5>=4,AY5,0)+IF(AZ5>=4,AZ5,0)+IF(BA5>=4,BA5,0)+IF(BB5>=4,BB5,0)+IF(BC5>=4,BC5,0)+IF(BD5>=4,BD5,0)+IF(BE5>=4,BE5,0)+IF(BF5>=4,BF5,0)+IF(BG5>=4,BG5,0)+IF(BH5>=4,BH5,0)+IF(BI5>=4,BI5,0)+IF(BJ5>=4,BJ5,0)+IF(BK5>=4,BK5,0)+IF(BL5>=4,BL5,0)+IF(BM5>=4,BM5,0)+IF(BN5>=4,BN5,0)+IF(BO5>=4,BO5,0)+IF(BP5>=4,BP5,0)+IF(BQ5>=4,BQ5,0)+IF(BR5>=4,BR5,0)+IF(BS5>=4,BS5,0)+IF(BT5>=4,BT5,0)+IF(BU5>=4,BU5,0)+IF(BV5>=4,BV5,0)+IF(BW5>=4,BW5,0)+IF(BX5>=4,BX5,0)+IF(BY5>=4,BY5,0)+IF(BZ5>=4,BZ5,0)+IF(CA5>=4,CA5,0)+IF(CB5>=4,CB5,0)+IF(CC5>=4,CC5,0)+IF(CD5>=4,CD5,0)+IF(CE5>=4,CE5,0)+IF(CF5>=4,CF5,0)+IF(CG5>=4,CG5,0)+IF(CH5>=4,CH5,0)+IF(CI5>=4,CI5,0)) -> 68 | CO5: Structural | CP5: =IF(L2="x","CE 3010", "-") -> CE 3010 | CQ5: =IF(G2="x","CE 2002", "-") -> CE 2002 | CR5: =IF(J2="x","CE 3006", "-") -> - | CS5: =IF(K2="x","CE 3008", "-") -> CE 3008 | CT5: =IF(R2="x","CE 3026", "-") -> CE 3026 | CU5: =IF(AE2="x","CE 4007", "-") -> - | CV5: =IF(AF2="x","CE 4017", "-") -> -
A6: b. Professional | B6: =IF('input-output'!$I$48="Y", 'Data Analysis'!CL6,'Data Analysis'!CM6) -> 41 | C6: =B6/$B$46 -> 0.042887029 | D6: 2 | E6: 1 | F6: 1 | G6: 2 | H6: 3 | I6: 2 | J6: 3 | K6: 4 | L6: 3 | M6: 3 | N6: 2 | O6: 5 | P6: 3 | Q6: 3 | R6: 3 | S6: 3 | T6: 3 | U6: 3 | V6: 2 | W6: 2 | X6: 3 | Y6: 2 | Z6: 0 | AA6: 3 | AB6: 0 | AC6: 3 | AD6: 0 | AE6: 3 | AF6: 4 | AH6: 3 | AI6: 3 | AJ6: 0 | AK6: 0 | AL6: 3 | AU6: =IF(D$2="x",D6,0) -> 2 | AV6: =IF(E$2="x",E6,0) -> 1 | AW6: =IF(F$2="x",F6,0) -> 1 | AX6: =IF(G$2="x",G6,0) -> 2 | AY6: =IF(H$2="x",H6,0) -> 3 | AZ6: =IF(I$2="x",I6,0) -> 2 | BA6: =IF(J$2="x",J6,0) -> 0 | BB6: =IF(K$2="x",K6,0) -> 4 | ... CI6: =IF(AR$2="x",AR6,0) -> 0 | CL6: =SUM(AU6:CI6) -> 41 | CM6: =SUM(IF(AU6>=4,AU6,0)+IF(AV6>=4,AV6,0)+IF(AW6>=4,AW6,0)+IF(AX6>=4,AX6,0)+IF(AY6>=4,AY6,0)+IF(AZ6>=4,AZ6,0)+IF(BA6>=4,BA6,0)+IF(BB6>=4,BB6,0)+IF(BC6>=4,BC6,0)+IF(BD6>=4,BD6,0)+IF(BE6>=4,BE6,0)+IF(BF6>=4,BF6,0)+IF(BG6>=4,BG6,0)+IF(BH6>=4,BH6,0)+IF(BI6>=4,BI6,0)+IF(BJ6>=4,BJ6,0)+IF(BK6>=4,BK6,0)+IF(BL6>=4,BL6,0)+IF(BM6>=4,BM6,0)+IF(BN6>=4,BN6,0)+IF(BO6>=4,BO6,0)+IF(BP6>=4,BP6,0)+IF(BQ6>=4,BQ6,0)+IF(BR6>=4,BR6,0)+IF(BS6>=4,BS6,0)+IF(BT6>=4,BT6,0)+IF(BU6>=4,BU6,0)+IF(BV6>=4,BV6,0)+IF(BW6>=4,BW6,0)+IF(BX6>=4,BX6,0)+IF(BY6>=4,BY6,0)+IF(BZ6>=4,BZ6,0)+IF(CA6>=4,CA6,0)+IF(CB6>=4,CB6,0)+IF(CC6>=4,CC6,0)+IF(CD6>=4,CD6,0)+IF(CE6>=4,CE6,0)+IF(CF6>=4,CF6,0)+IF(CG6>=4,CG6,0)+IF(CH6>=4,CH6,0)+IF(CI6>=4,CI6,0)) -> 4 | CO6: Geotechnical | CP6: =IF(T2="x","CE 3041", "-") -> CE 3041 | CQ6: =IF(U2="x","CE 3044", "-") -> CE 3044 | CR6: =IF(AH2="x","CE 4046", "-") -> CE 4046 | CS6: =IF(AI2="x","CE 4048", "-") -> CE 4048
A7: c. Ethical | B7: =IF('input-output'!$I$48="Y", 'Data Analysis'!CL7,'Data Analysis'!CM7) -> 20 | C7: =B7/$B$46 -> 0.020920502 | D7: 4 | E7: 0 | F7: 0 | G7: 0 | H7: 3 | I7: 1 | J7: 0 | K7: 2 | L7: 0 | M7: 1 | N7: 1 | O7: 4 | P7: 0 | Q7: 3 | R7: 1 | S7: 0 | T7: 1 | U7: 1 | V7: 2 | W7: 0 | X7: 0 | Y7: 2 | Z7: 4 | AA7: 0 | AB7: 0 | AC7: 3 | AD7: 0 | AE7: 0 | AF7: 3 | AH7: 1 | AI7: 3 | AJ7: 1 | AK7: 0 | AL7: 0 | AU7: =IF(D$2="x",D7,0) -> 4 | AV7: =IF(E$2="x",E7,0) -> 0 | AW7: =IF(F$2="x",F7,0) -> 0 | AX7: =IF(G$2="x",G7,0) -> 0 | AY7: =IF(H$2="x",H7,0) -> 3 | AZ7: =IF(I$2="x",I7,0) -> 1 | BA7: =IF(J$2="x",J7,0) -> 0 | BB7: =IF(K$2="x",K7,0) -> 2 | ... CI7: =IF(AR$2="x",AR7,0) -> 0 | CL7: =SUM(AU7:CI7) -> 20 | CM7: =SUM(IF(AU7>=4,AU7,0)+IF(AV7>=4,AV7,0)+IF(AW7>=4,AW7,0)+IF(AX7>=4,AX7,0)+IF(AY7>=4,AY7,0)+IF(AZ7>=4,AZ7,0)+IF(BA7>=4,BA7,0)+IF(BB7>=4,BB7,0)+IF(BC7>=4,BC7,0)+IF(BD7>=4,BD7,0)+IF(BE7>=4,BE7,0)+IF(BF7>=4,BF7,0)+IF(BG7>=4,BG7,0)+IF(BH7>=4,BH7,0)+IF(BI7>=4,BI7,0)+IF(BJ7>=4,BJ7,0)+IF(BK7>=4,BK7,0)+IF(BL7>=4,BL7,0)+IF(BM7>=4,BM7,0)+IF(BN7>=4,BN7,0)+IF(BO7>=4,BO7,0)+IF(BP7>=4,BP7,0)+IF(BQ7>=4,BQ7,0)+IF(BR7>=4,BR7,0)+IF(BS7>=4,BS7,0)+IF(BT7>=4,BT7,0)+IF(BU7>=4,BU7,0)+IF(BV7>=4,BV7,0)+IF(BW7>=4,BW7,0)+IF(BX7>=4,BX7,0)+IF(BY7>=4,BY7,0)+IF(BZ7>=4,BZ7,0)+IF(CA7>=4,CA7,0)+IF(CB7>=4,CB7,0)+IF(CC7>=4,CC7,0)+IF(CD7>=4,CD7,0)+IF(CE7>=4,CE7,0)+IF(CF7>=4,CF7,0)+IF(CG7>=4,CG7,0)+IF(CH7>=4,CH7,0)+IF(CI7>=4,CI7,0)) -> 4 | CO7: Environmental and Hydraulics | CP7: =IF(Y2="x","CE 3059", "-") -> - | CQ7: =IF(Z2="x","CE 3060", "-") -> - | CR7: =IF(AA2="x","CE 3061", "-") -> - | CS7: =IF(AB2="x","CE 3062", "-") -> - | CT7: =IF(AJ2="x","CE 4060", "-") -> - | CU7: =IF(AK2="x","CE 4061", "-") -> -
A8: 2. Preparation for the future changes in civil engineering. | B8: =IF('input-output'!$I$48="Y", 'Data Analysis'!CL8,'Data Analysis'!CM8) -> 29 | C8: =B8/$B$46 -> 0.030334728 | D8: 3 | E8: 0 | F8: 0 | G8: 0 | H8: 3 | I8: 2 | J8: 0 | K8: 4 | L8: 0 | M8: 3 | N8: 3 | O8: 3 | P8: 3 | Q8: 3 | R8: 2 | S8: 3 | T8: 3 | U8: 3 | V8: 0 | W8: 0 | X8: 5 | Y8: 5 | Z8: 2 | AA8: 4 | AB8: 0 | AC8: 5 | AD8: 3 | AE8: 0 | AF8: 4 | AH8: 0 | AI8: 3 | AJ8: 2 | AK8: 0 | AL8: 3 | AU8: =IF(D$2="x",D8,0) -> 3 | AV8: =IF(E$2="x",E8,0) -> 0 | AW8: =IF(F$2="x",F8,0) -> 0 | AX8: =IF(G$2="x",G8,0) -> 0 | AY8: =IF(H$2="x",H8,0) -> 3 | AZ8: =IF(I$2="x",I8,0) -> 2 | BA8: =IF(J$2="x",J8,0) -> 0 | BB8: =IF(K$2="x",K8,0) -> 4 | ... CI8: =IF(AR$2="x",AR8,0) -> 0 | CL8: =SUM(AU8:CI8) -> 29 | CM8: =SUM(IF(AU8>=4,AU8,0)+IF(AV8>=4,AV8,0)+IF(AW8>=4,AW8,0)+IF(AX8>=4,AX8,0)+IF(AY8>=4,AY8,0)+IF(AZ8>=4,AZ8,0)+IF(BA8>=4,BA8,0)+IF(BB8>=4,BB8,0)+IF(BC8>=4,BC8,0)+IF(BD8>=4,BD8,0)+IF(BE8>=4,BE8,0)+IF(BF8>=4,BF8,0)+IF(BG8>=4,BG8,0)+IF(BH8>=4,BH8,0)+IF(BI8>=4,BI8,0)+IF(BJ8>=4,BJ8,0)+IF(BK8>=4,BK8,0)+IF(BL8>=4,BL8,0)+IF(BM8>=4,BM8,0)+IF(BN8>=4,BN8,0)+IF(BO8>=4,BO8,0)+IF(BP8>=4,BP8,0)+IF(BQ8>=4,BQ8,0)+IF(BR8>=4,BR8,0)+IF(BS8>=4,BS8,0)+IF(BT8>=4,BT8,0)+IF(BU8>=4,BU8,0)+IF(BV8>=4,BV8,0)+IF(BW8>=4,BW8,0)+IF(BX8>=4,BX8,0)+IF(BY8>=4,BY8,0)+IF(BZ8>=4,BZ8,0)+IF(CA8>=4,CA8,0)+IF(CB8>=4,CB8,0)+IF(CC8>=4,CC8,0)+IF(CD8>=4,CD8,0)+IF(CE8>=4,CE8,0)+IF(CF8>=4,CF8,0)+IF(CG8>=4,CG8,0)+IF(CH8>=4,CH8,0)+IF(CI8>=4,CI8,0)) -> 4 | CO8: Urban and Environmental Planning | CP8: =IF(AC2="x","CE 3070", "-") -> - | CQ8: =IF(AD2="x","CE 3074", "-") -> - | CR8: =IF(AL2="x","CE 4071", "-") -> -
A9: 3. Understanding of basic principles of civil engineering (please list and assess each principle). | B9: =SUM(B10:B19) -> 263 | C9: =B9/$B$46 -> 0.2751046 | AU9: =IF(D$2="x",D9,0) -> 0 | CL9: =SUM(AU9:CI9) -> 0 | CM9: =SUM(IF(AU9>=4,AU9,0)+IF(AV9>=4,AV9,0)+IF(AW9>=4,AW9,0)+IF(AX9>=4,AX9,0)+IF(AY9>=4,AY9,0)+IF(AZ9>=4,AZ9,0)+IF(BA9>=4,BA9,0)+IF(BB9>=4,BB9,0)+IF(BC9>=4,BC9,0)+IF(BD9>=4,BD9,0)+IF(BE9>=4,BE9,0)+IF(BF9>=4,BF9,0)+IF(BG9>=4,BG9,0)+IF(BH9>=4,BH9,0)+IF(BI9>=4,BI9,0)+IF(BJ9>=4,BJ9,0)+IF(BK9>=4,BK9,0)+IF(BL9>=4,BL9,0)+IF(BM9>=4,BM9,0)+IF(BN9>=4,BN9,0)+IF(BO9>=4,BO9,0)+IF(BP9>=4,BP9,0)+IF(BQ9>=4,BQ9,0)+IF(BR9>=4,BR9,0)+IF(BS9>=4,BS9,0)+IF(BT9>=4,BT9,0)+IF(BU9>=4,BU9,0)+IF(BV9>=4,BV9,0)+IF(BW9>=4,BW9,0)+IF(BX9>=4,BX9,0)+IF(BY9>=4,BY9,0)+IF(BZ9>=4,BZ9,0)+IF(CA9>=4,CA9,0)+IF(CB9>=4,CB9,0)+IF(CC9>=4,CC9,0)+IF(CD9>=4,CD9,0)+IF(CE9>=4,CE9,0)+IF(CF9>=4,CF9,0)+IF(CG9>=4,CG9,0)+IF(CH9>=4,CH9,0)+IF(CI9>=4,CI9,0)) -> 0 | CO9: Transportation | CP9: =IF(V2="x","CE 3050", "-") -> CE 3050 | CQ9: =IF(W2="x","CE 3051", "-") -> - | CR9: =IF(X2="x","CE 3054", "-") -> - | CS9: =IF(AG2="x","CE 355X", "-") -> -
A10: a. Computers and Information Technology | B10: =IF('input-output'!$I$48="Y", 'Data Analysis'!CL10,'Data Analysis'!CM10) -> 34 | C10: =B10/$B$46 -> 0.035564854 | D10: 0 | E10: 2 | F10: 2 | G10: 4 | H10: 0 | I10: 2 | J10: 5 | K10: 2 | L10: 0 | M10: 4 | N10: 4 | O10: 0 | P10: 0 | Q10: 0 | R10: 5 | S10: 5 | T10: 0 | U10: 1 | V10: 0 | W10: 2 | X10: 4 | Y10: 1 | Z10: 0 | AA10: 2 | AB10: 0 | AC10: 0 | AD10: 3 | AE10: 0 | AF10: 0 | AH10: 2 | AI10: 5 | AJ10: 0 | AK10: 0 | AL10: 0 | AU10: =IF(D$2="x",D10,0) -> 0 | AV10: =IF(E$2="x",E10,0) -> 2 | AW10: =IF(F$2="x",F10,0) -> 2 | AX10: =IF(G$2="x",G10,0) -> 4 | AY10: =IF(H$2="x",H10,0) -> 0 | AZ10: =IF(I$2="x",I10,0) -> 2 | BA10: =IF(J$2="x",J10,0) -> 0 | BB10: =IF(K$2="x",K10,0) -> 2 | ... CI10: =IF(AR$2="x",AR10,0) -> 0 | CL10: =SUM(AU10:CI10) -> 34 | CM10: =SUM(IF(AU10>=4,AU10,0)+IF(AV10>=4,AV10,0)+IF(AW10>=4,AW10,0)+IF(AX10>=4,AX10,0)+IF(AY10>=4,AY10,0)+IF(AZ10>=4,AZ10,0)+IF(BA10>=4,BA10,0)+IF(BB10>=4,BB10,0)+IF(BC10>=4,BC10,0)+IF(BD10>=4,BD10,0)+IF(BE10>=4,BE10,0)+IF(BF10>=4,BF10,0)+IF(BG10>=4,BG10,0)+IF(BH10>=4,BH10,0)+IF(BI10>=4,BI10,0)+IF(BJ10>=4,BJ10,0)+IF(BK10>=4,BK10,0)+IF(BL10>=4,BL10,0)+IF(BM10>=4,BM10,0)+IF(BN10>=4,BN10,0)+IF(BO10>=4,BO10,0)+IF(BP10>=4,BP10,0)+IF(BQ10>=4,BQ10,0)+IF(BR10>=4,BR10,0)+IF(BS10>=4,BS10,0)+IF(BT10>=4,BT10,0)+IF(BU10>=4,BU10,0)+IF(BV10>=4,BV10,0)+IF(BW10>=4,BW10,0)+IF(BX10>=4,BX10,0)+IF(BY10>=4,BY10,0)+IF(BZ10>=4,BZ10,0)+IF(CA10>=4,CA10,0)+IF(CB10>=4,CB10,0)+IF(CC10>=4,CC10,0)+IF(CD10>=4,CD10,0)+IF(CE10>=4,CE10,0)+IF(CF10>=4,CF10,0)+IF(CG10>=4,CG10,0)+IF(CH10>=4,CH10,0)+IF(CI10>=4,CI10,0)) -> 23 | CO10: Construction and Management | CP10: =IF(M2="x","CE 3020", "-") -> CE 3020 | CQ10: =IF(N2="x","CE 3021", "-") -> - | CR10: =IF(O2="x","CE 3022", "-") -> - | CS10: =IF(P2="x","CE 3023", "-") -> - | CT10: =IF(Q2="x","CE 3024", "-") -> -
A11: b. Geographic Positioning and Measurements | B11: =IF('input-output'!$I$48="Y", 'Data Analysis'!CL11,'Data Analysis'!CM11) -> 23 | C11: =B11/$B$46 -> 0.024058577 | D11: 0 | E11: 0 | F11: 0 | G11: 0 | H11: 5 | I11: 1 | J11: 0 | K11: 0 | L11: 0 | M11: 2 | N11: 3 | O11: 0 | P11: 5 | Q11: 5 | R11: 0 | S11: 4 | T11: 0 | U11: 0 | V11: 5 | W11: 2 | X11: 0 | Y11: 1 | Z11: 0 | AA11: 0 | AB11: 0 | AC11: 0 | AD11: 3 | AE11: 0 | AF11: 0 | AH11: 5 | AI11: 1 | AJ11: 0 | AK11: 0 | AL11: 0 | AU11: =IF(D$2="x",D11,0) -> 0 | AV11: =IF(E$2="x",E11,0) -> 0 | AW11: =IF(F$2="x",F11,0) -> 0 | AX11: =IF(G$2="x",G11,0) -> 0 | AY11: =IF(H$2="x",H11,0) -> 5 | AZ11: =IF(I$2="x",I11,0) -> 1 | BA11: =IF(J$2="x",J11,0) -> 0 | BB11: =IF(K$2="x",K11,0) -> 0 | ... CI11: =IF(AR$2="x",AR11,0) -> 0 | CL11: =SUM(AU11:CI11) -> 23 | CM11: =SUM(IF(AU11>=4,AU11,0)+IF(AV11>=4,AV11,0)+IF(AW11>=4,AW11,0)+IF(AX11>=4,AX11,0)+IF(AY11>=4,AY11,0)+IF(AZ11>=4,AZ11,0)+IF(BA11>=4,BA11,0)+IF(BB11>=4,BB11,0)+IF(BC11>=4,BC11,0)+IF(BD11>=4,BD11,0)+IF(BE11>=4,BE11,0)+IF(BF11>=4,BF11,0)+IF(BG11>=4,BG11,0)+IF(BH11>=4,BH11,0)+IF(BI11>=4,BI11,0)+IF(BJ11>=4,BJ11,0)+IF(BK11>=4,BK11,0)+IF(BL11>=4,BL11,0)+IF(BM11>=4,BM11,0)+IF(BN11>=4,BN11,0)+IF(BO11>=4,BO11,0)+IF(BP11>=4,BP11,0)+IF(BQ11>=4,BQ11,0)+IF(BR11>=4,BR11,0)+IF(BS11>=4,BS11,0)+IF(BT11>=4,BT11,0)+IF(BU11>=4,BU11,0)+IF(BV11>=4,BV11,0)+IF(BW11>=4,BW11,0)+IF(BX11>=4,BX11,0)+IF(BY11>=4,BY11,0)+IF(BZ11>=4,BZ11,0)+IF(CA11>=4,CA11,0)+IF(CB11>=4,CB11,0)+IF(CC11>=4,CC11,0)+IF(CD11>=4,CD11,0)+IF(CE11>=4,CE11,0)+IF(CF11>=4,CF11,0)+IF(CG11>=4,CG11,0)+IF(CH11>=4,CH11,0)+IF(CI11>=4,CI11,0)) -> 19 | CO11: Chemistry | CP11: =IF(AQ2="x","CH 1010", "-") -> CH 1010 | CQ11: =IF(AR2="x","CH 1020", "-") -> -
A12: c. Solid (Structural) Mechanics | B12: =IF('input-output'!$I$48="Y", 'Data Analysis'!CL12,'Data Analysis'!CM12) -> 49 | C12: =B12/$B$46 -> 0.05125523 | D12: 0 | E12: 5 | F12: 5 | G12: 5 | H12: 0 | I12: 1 | J12: 5 | K12: 4 | L12: 5 | M12: 1 | N12: 0 | O12: 0 | P12: 0 | Q12: 0 | R12: 4 | S12: 3 | T12: 4 | U12: 5 | V12: 0 | W12: 4 | X12: 5 | Y12: 0 | Z12: 0 | AA12: 0 | AB12: 0 | AC12: 0 | AD12: 0 | AE12: 0 | AF12: 4 | AH12: 3 | AI12: 4 | AJ12: 0 | AK12: 0 | AL12: 0 | AU12: =IF(D$2="x",D12,0) -> 0 | AV12: =IF(E$2="x",E12,0) -> 5 | AW12: =IF(F$2="x",F12,0) -> 5 | AX12: =IF(G$2="x",G12,0) -> 5 | AY12: =IF(H$2="x",H12,0) -> 0 | AZ12: =IF(I$2="x",I12,0) -> 1 | BA12: =IF(J$2="x",J12,0) -> 0 | BB12: =IF(K$2="x",K12,0) -> 4 | ... CI12: =IF(AR$2="x",AR12,0) -> 0 | CL12: =SUM(AU12:CI12) -> 49 | CM12: =SUM(IF(AU12>=4,AU12,0)+IF(AV12>=4,AV12,0)+IF(AW12>=4,AW12,0)+IF(AX12>=4,AX12,0)+IF(AY12>=4,AY12,0)+IF(AZ12>=4,AZ12,0)+IF(BA12>=4,BA12,0)+IF(BB12>=4,BB12,0)+IF(BC12>=4,BC12,0)+IF(BD12>=4,BD12,0)+IF(BE12>=4,BE12,0)+IF(BF12>=4,BF12,0)+IF(BG12>=4,BG12,0)+IF(BH12>=4,BH12,0)+IF(BI12>=4,BI12,0)+IF(BJ12>=4,BJ12,0)+IF(BK12>=4,BK12,0)+IF(BL12>=4,BL12,0)+IF(BM12>=4,BM12,0)+IF(BN12>=4,BN12,0)+IF(BO12>=4,BO12,0)+IF(BP12>=4,BP12,0)+IF(BQ12>=4,BQ12,0)+IF(BR12>=4,BR12,0)+IF(BS12>=4,BS12,0)+IF(BT12>=4,BT12,0)+IF(BU12>=4,BU12,0)+IF(BV12>=4,BV12,0)+IF(BW12>=4,BW12,0)+IF(BX12>=4,BX12,0)+IF(BY12>=4,BY12,0)+IF(BZ12>=4,BZ12,0)+IF(CA12>=4,CA12,0)+IF(CB12>=4,CB12,0)+IF(CC12>=4,CC12,0)+IF(CD12>=4,CD12,0)+IF(CE12>=4,CE12,0)+IF(CF12>=4,CF12,0)+IF(CG12>=4,CG12,0)+IF(CH12>=4,CH12,0)+IF(CI12>=4,CI12,0)) -> 41 | CO12: Statistics | CP12: =IF(AP2="x","MA 2011", "-") -> MA 2011
A13: d. Soil Mechanics | B13: =IF('input-output'!$I$48="Y", 'Data Analysis'!CL13,'Data Analysis'!CM13) -> 22 | C13: =B13/$B$46 -> 0.023012552 | D13: 0 | E13: 0 | F13: 0 | G13: 0 | H13: 0 | I13: 1 | J13: 0 | K13: 0 | L13: 0 | M13: 1 | N13: 0 | O13: 0 | P13: 0 | Q13: 0 | R13: 0 | S13: 0 | T13: 5 | U13: 5 | V13: 0 | W13: 5 | X13: 0 | Y13: 0 | Z13: 0 | AA13: 0 | AB13: 0 | AC13: 0 | AD13: 0 | AE13: 0 | AF13: 3 | AH13: 5 | AI13: 5 | AJ13: 0 | AK13: 0 | AL13: 0 | AU13: =IF(D$2="x",D13,0) -> 0 | AV13: =IF(E$2="x",E13,0) -> 0 | AW13: =IF(F$2="x",F13,0) -> 0 | AX13: =IF(G$2="x",G13,0) -> 0 | AY13: =IF(H$2="x",H13,0) -> 0 | AZ13: =IF(I$2="x",I13,0) -> 1 | BA13: =IF(J$2="x",J13,0) -> 0 | BB13: =IF(K$2="x",K13,0) -> 0 | ... CI13: =IF(AR$2="x",AR13,0) -> 0 | CL13: =SUM(AU13:CI13) -> 22 | CM13: =SUM(IF(AU13>=4,AU13,0)+IF(AV13>=4,AV13,0)+IF(AW13>=4,AW13,0)+IF(AX13>=4,AX13,0)+IF(AY13>=4,AY13,0)+IF(AZ13>=4,AZ13,0)+IF(BA13>=4,BA13,0)+IF(BB13>=4,BB13,0)+IF(BC13>=4,BC13,0)+IF(BD13>=4,BD13,0)+IF(BE13>=4,BE13,0)+IF(BF13>=4,BF13,0)+IF(BG13>=4,BG13,0)+IF(BH13>=4,BH13,0)+IF(BI13>=4,BI13,0)+IF(BJ13>=4,BJ13,0)+IF(BK13>=4,BK13,0)+IF(BL13>=4,BL13,0)+IF(BM13>=4,BM13,0)+IF(BN13>=4,BN13,0)+IF(BO13>=4,BO13,0)+IF(BP13>=4,BP13,0)+IF(BQ13>=4,BQ13,0)+IF(BR13>=4,BR13,0)+IF(BS13>=4,BS13,0)+IF(BT13>=4,BT13,0)+IF(BU13>=4,BU13,0)+IF(BV13>=4,BV13,0)+IF(BW13>=4,BW13,0)+IF(BX13>=4,BX13,0)+IF(BY13>=4,BY13,0)+IF(BZ13>=4,BZ13,0)+IF(CA13>=4,CA13,0)+IF(CB13>=4,CB13,0)+IF(CC13>=4,CC13,0)+IF(CD13>=4,CD13,0)+IF(CE13>=4,CE13,0)+IF(CF13>=4,CF13,0)+IF(CG13>=4,CG13,0)+IF(CH13>=4,CH13,0)+IF(CI13>=4,CI13,0)) -> 20
A14: e. Fluid Mechanics/Hydrology | B14: =IF('input-output'!$I$48="Y", 'Data Analysis'!CL14,'Data Analysis'!CM14) -> 16 | C14: =B14/$B$46 -> 0.016736402 | D14: 0 | E14: 0 | F14: 0 | G14: 0 | H14: 0 | I14: 5 | J14: 0 | K14: 1 | L14: 0 | M14: 0 | N14: 0 | O14: 0 | P14: 0 | Q14: 0 | R14: 0 | S14: 0 | T14: 3 | U14: 1 | V14: 0 | W14: 5 | X14: 0 | Y14: 4 | Z14: 3 | AA14: 3 | AB14: 5 | AC14: 0 | AD14: 0 | AE14: 0 | AF14: 4 | AH14: 3 | AI14: 3 | AJ14: 3 | AK14: 4 | AL14: 0 | AU14: =IF(D$2="x",D14,0) -> 0 | AV14: =IF(E$2="x",E14,0) -> 0 | AW14: =IF(F$2="x",F14,0) -> 0 | AX14: =IF(G$2="x",G14,0) -> 0 | AY14: =IF(H$2="x",H14,0) -> 0 | AZ14: =IF(I$2="x",I14,0) -> 5 | BA14: =IF(J$2="x",J14,0) -> 0 | BB14: =IF(K$2="x",K14,0) -> 1 | ... CI14: =IF(AR$2="x",AR14,0) -> 0 | CL14: =SUM(AU14:CI14) -> 16 | CM14: =SUM(IF(AU14>=4,AU14,0)+IF(AV14>=4,AV14,0)+IF(AW14>=4,AW14,0)+IF(AX14>=4,AX14,0)+IF(AY14>=4,AY14,0)+IF(AZ14>=4,AZ14,0)+IF(BA14>=4,BA14,0)+IF(BB14>=4,BB14,0)+IF(BC14>=4,BC14,0)+IF(BD14>=4,BD14,0)+IF(BE14>=4,BE14,0)+IF(BF14>=4,BF14,0)+IF(BG14>=4,BG14,0)+IF(BH14>=4,BH14,0)+IF(BI14>=4,BI14,0)+IF(BJ14>=4,BJ14,0)+IF(BK14>=4,BK14,0)+IF(BL14>=4,BL14,0)+IF(BM14>=4,BM14,0)+IF(BN14>=4,BN14,0)+IF(BO14>=4,BO14,0)+IF(BP14>=4,BP14,0)+IF(BQ14>=4,BQ14,0)+IF(BR14>=4,BR14,0)+IF(BS14>=4,BS14,0)+IF(BT14>=4,BT14,0)+IF(BU14>=4,BU14,0)+IF(BV14>=4,BV14,0)+IF(BW14>=4,BW14,0)+IF(BX14>=4,BX14,0)+IF(BY14>=4,BY14,0)+IF(BZ14>=4,BZ14,0)+IF(CA14>=4,CA14,0)+IF(CB14>=4,CB14,0)+IF(CC14>=4,CC14,0)+IF(CD14>=4,CD14,0)+IF(CE14>=4,CE14,0)+IF(CF14>=4,CF14,0)+IF(CG14>=4,CG14,0)+IF(CH14>=4,CH14,0)+IF(CI14>=4,CI14,0)) -> 5
A15: f. Design | B15: =IF('input-output'!$I$48="Y", 'Data Analysis'!CL15,'Data Analysis'!CM15) -> 55 | C15: =B15/$B$46 -> 0.057531381 | D15: 0 | E15: 4 | F15: 4 | G15: 4 | H15: 0 | I15: 3 | J15: 5 | K15: 5 | L15: 5 | M15: 1 | N15: 1 | O15: 2 | P15: 4 | Q15: 0 | R15: 4 | S15: 4 | T15: 2 | U15: 5 | V15: 5 | W15: 5 | X15: 5 | Y15: 3 | Z15: 0 | AA15: 5 | AB15: 0 | AC15: 5 | AD15: 4 | AE15: 0 | AF15: 5 | AH15: 4 | AI15: 5 | AJ15: 0 | AK15: 0 | AL15: 0 | AU15: =IF(D$2="x",D15,0) -> 0 | AV15: =IF(E$2="x",E15,0) -> 4 | AW15: =IF(F$2="x",F15,0) -> 4 | AX15: =IF(G$2="x",G15,0) -> 4 | AY15: =IF(H$2="x",H15,0) -> 0 | AZ15: =IF(I$2="x",I15,0) -> 3 | BA15: =IF(J$2="x",J15,0) -> 0 | BB15: =IF(K$2="x",K15,0) -> 5 | ... CI15: =IF(AR$2="x",AR15,0) -> 0 | CL15: =SUM(AU15:CI15) -> 55 | CM15: =SUM(IF(AU15>=4,AU15,0)+IF(AV15>=4,AV15,0)+IF(AW15>=4,AW15,0)+IF(AX15>=4,AX15,0)+IF(AY15>=4,AY15,0)+IF(AZ15>=4,AZ15,0)+IF(BA15>=4,BA15,0)+IF(BB15>=4,BB15,0)+IF(BC15>=4,BC15,0)+IF(BD15>=4,BD15,0)+IF(BE15>=4,BE15,0)+IF(BF15>=4,BF15,0)+IF(BG15>=4,BG15,0)+IF(BH15>=4,BH15,0)+IF(BI15>=4,BI15,0)+IF(BJ15>=4,BJ15,0)+IF(BK15>=4,BK15,0)+IF(BL15>=4,BL15,0)+IF(BM15>=4,BM15,0)+IF(BN15>=4,BN15,0)+IF(BO15>=4,BO15,0)+IF(BP15>=4,BP15,0)+IF(BQ15>=4,BQ15,0)+IF(BR15>=4,BR15,0)+IF(BS15>=4,BS15,0)+IF(BT15>=4,BT15,0)+IF(BU15>=4,BU15,0)+IF(BV15>=4,BV15,0)+IF(BW15>=4,BW15,0)+IF(BX15>=4,BX15,0)+IF(BY15>=4,BY15,0)+IF(BZ15>=4,BZ15,0)+IF(CA15>=4,CA15,0)+IF(CB15>=4,CB15,0)+IF(CC15>=4,CC15,0)+IF(CD15>=4,CD15,0)+IF(CE15>=4,CE15,0)+IF(CF15>=4,CF15,0)+IF(CG15>=4,CG15,0)+IF(CH15>=4,CH15,0)+IF(CI15>=4,CI15,0)) -> 49
A16: g. Construction Materials | B16: =IF('input-output'!$I$48="Y", 'Data Analysis'!CL16,'Data Analysis'!CM16) -> 28 | C16: =B16/$B$46 -> 0.029288703 | D16: 0 | E16: 0 | F16: 0 | G16: 0 | H16: 0 | I16: 1 | J16: 0 | K16: 3 | L16: 0 | M16: 1 | N16: 2 | O16: 0 | P16: 2 | Q16: 0 | R16: 5 | S16: 3 | T16: 4 | U16: 3 | V16: 1 | W16: 5 | X16: 5 | Z16: 0 | AA16: 0 | AB16: 0 | AC16: 0 | AD16: 0 | AE16: 0 | AF16: 5 | AH16: 3 | AI16: 4 | AJ16: 0 | AK16: 0 | AL16: 0 | AU16: =IF(D$2="x",D16,0) -> 0 | AV16: =IF(E$2="x",E16,0) -> 0 | AW16: =IF(F$2="x",F16,0) -> 0 | AX16: =IF(G$2="x",G16,0) -> 0 | AY16: =IF(H$2="x",H16,0) -> 0 | AZ16: =IF(I$2="x",I16,0) -> 1 | BA16: =IF(J$2="x",J16,0) -> 0 | BB16: =IF(K$2="x",K16,0) -> 3 | ... CI16: =IF(AR$2="x",AR16,0) -> 0 | CL16: =SUM(AU16:CI16) -> 28 | CM16: =SUM(IF(AU16>=4,AU16,0)+IF(AV16>=4,AV16,0)+IF(AW16>=4,AW16,0)+IF(AX16>=4,AX16,0)+IF(AY16>=4,AY16,0)+IF(AZ16>=4,AZ16,0)+IF(BA16>=4,BA16,0)+IF(BB16>=4,BB16,0)+IF(BC16>=4,BC16,0)+IF(BD16>=4,BD16,0)+IF(BE16>=4,BE16,0)+IF(BF16>=4,BF16,0)+IF(BG16>=4,BG16,0)+IF(BH16>=4,BH16,0)+IF(BI16>=4,BI16,0)+IF(BJ16>=4,BJ16,0)+IF(BK16>=4,BK16,0)+IF(BL16>=4,BL16,0)+IF(BM16>=4,BM16,0)+IF(BN16>=4,BN16,0)+IF(BO16>=4,BO16,0)+IF(BP16>=4,BP16,0)+IF(BQ16>=4,BQ16,0)+IF(BR16>=4,BR16,0)+IF(BS16>=4,BS16,0)+IF(BT16>=4,BT16,0)+IF(BU16>=4,BU16,0)+IF(BV16>=4,BV16,0)+IF(BW16>=4,BW16,0)+IF(BX16>=4,BX16,0)+IF(BY16>=4,BY16,0)+IF(BZ16>=4,BZ16,0)+IF(CA16>=4,CA16,0)+IF(CB16>=4,CB16,0)+IF(CC16>=4,CC16,0)+IF(CD16>=4,CD16,0)+IF(CE16>=4,CE16,0)+IF(CF16>=4,CF16,0)+IF(CG16>=4,CG16,0)+IF(CH16>=4,CH16,0)+IF(CI16>=4,CI16,0)) -> 13
A17: h. Systems Analysis and Modeling | B17: =IF('input-output'!$I$48="Y", 'Data Analysis'!CL17,'Data Analysis'!CM17) -> 11 | C17: =B17/$B$46 -> 0.011506276 | D17: 0 | E17: 0 | F17: 0 | G17: 0 | H17: 0 | I17: 3 | J17: 0 | K17: 0 | L17: 0 | M17: 3 | N17: 0 | O17: 0 | P17: 0 | Q17: 0 | R17: 0 | S17: 0 | T17: 0 | U17: 0 | V17: 5 | W17: 0 | X17: 0 | Y17: 3 | Z17: 0 | AA17: 5 | AB17: 0 | AC17: 4 | AD17: 0 | AE17: 5 | AF17: 3 | AH17: 0 | AI17: 0 | AJ17: 0 | AK17: 4 | AL17: 0 | AU17: =IF(D$2="x",D17,0) -> 0 | AV17: =IF(E$2="x",E17,0) -> 0 | AW17: =IF(F$2="x",F17,0) -> 0 | AX17: =IF(G$2="x",G17,0) -> 0 | AY17: =IF(H$2="x",H17,0) -> 0 | AZ17: =IF(I$2="x",I17,0) -> 3 | BA17: =IF(J$2="x",J17,0) -> 0 | BB17: =IF(K$2="x",K17,0) -> 0 | ... CI17: =IF(AR$2="x",AR17,0) -> 0 | CL17: =SUM(AU17:CI17) -> 11 | CM17: =SUM(IF(AU17>=4,AU17,0)+IF(AV17>=4,AV17,0)+IF(AW17>=4,AW17,0)+IF(AX17>=4,AX17,0)+IF(AY17>=4,AY17,0)+IF(AZ17>=4,AZ17,0)+IF(BA17>=4,BA17,0)+IF(BB17>=4,BB17,0)+IF(BC17>=4,BC17,0)+IF(BD17>=4,BD17,0)+IF(BE17>=4,BE17,0)+IF(BF17>=4,BF17,0)+IF(BG17>=4,BG17,0)+IF(BH17>=4,BH17,0)+IF(BI17>=4,BI17,0)+IF(BJ17>=4,BJ17,0)+IF(BK17>=4,BK17,0)+IF(BL17>=4,BL17,0)+IF(BM17>=4,BM17,0)+IF(BN17>=4,BN17,0)+IF(BO17>=4,BO17,0)+IF(BP17>=4,BP17,0)+IF(BQ17>=4,BQ17,0)+IF(BR17>=4,BR17,0)+IF(BS17>=4,BS17,0)+IF(BT17>=4,BT17,0)+IF(BU17>=4,BU17,0)+IF(BV17>=4,BV17,0)+IF(BW17>=4,BW17,0)+IF(BX17>=4,BX17,0)+IF(BY17>=4,BY17,0)+IF(BZ17>=4,BZ17,0)+IF(CA17>=4,CA17,0)+IF(CB17>=4,CB17,0)+IF(CC17>=4,CC17,0)+IF(CD17>=4,CD17,0)+IF(CE17>=4,CE17,0)+IF(CF17>=4,CF17,0)+IF(CG17>=4,CG17,0)+IF(CH17>=4,CH17,0)+IF(CI17>=4,CI17,0)) -> 5
A18: i. Engineering Economics & Risk Management | B18: =IF('input-output'!$I$48="Y", 'Data Analysis'!CL18,'Data Analysis'!CM18) -> 25 | C18: =B18/$B$46 -> 0.026150628 | D18: 0 | E18: 0 | F18: 0 | G18: 0 | H18: 0 | I18: 1 | J18: 0 | K18: 2 | L18: 0 | M18: 4 | N18: 4 | O18: 2 | P18: 0 | Q18: 0 | R18: 1 | S18: 0 | T18: 0 | U18: 4 | V18: 5 | W18: 3 | X18: 4 | Y18: 3 | Z18: 0 | AA18: 0 | AB18: 0 | AC18: 0 | AD18: 4 | AE18: 0 | AF18: 0 | AH18: 4 | AI18: 4 | AJ18: 0 | AK18: 0 | AL18: 0 | AU18: =IF(D$2="x",D18,0) -> 0 | AV18: =IF(E$2="x",E18,0) -> 0 | AW18: =IF(F$2="x",F18,0) -> 0 | AX18: =IF(G$2="x",G18,0) -> 0 | AY18: =IF(H$2="x",H18,0) -> 0 | AZ18: =IF(I$2="x",I18,0) -> 1 | BA18: =IF(J$2="x",J18,0) -> 0 | BB18: =IF(K$2="x",K18,0) -> 2 | ... CI18: =IF(AR$2="x",AR18,0) -> 0 | CL18: =SUM(AU18:CI18) -> 25 | CM18: =SUM(IF(AU18>=4,AU18,0)+IF(AV18>=4,AV18,0)+IF(AW18>=4,AW18,0)+IF(AX18>=4,AX18,0)+IF(AY18>=4,AY18,0)+IF(AZ18>=4,AZ18,0)+IF(BA18>=4,BA18,0)+IF(BB18>=4,BB18,0)+IF(BC18>=4,BC18,0)+IF(BD18>=4,BD18,0)+IF(BE18>=4,BE18,0)+IF(BF18>=4,BF18,0)+IF(BG18>=4,BG18,0)+IF(BH18>=4,BH18,0)+IF(BI18>=4,BI18,0)+IF(BJ18>=4,BJ18,0)+IF(BK18>=4,BK18,0)+IF(BL18>=4,BL18,0)+IF(BM18>=4,BM18,0)+IF(BN18>=4,BN18,0)+IF(BO18>=4,BO18,0)+IF(BP18>=4,BP18,0)+IF(BQ18>=4,BQ18,0)+IF(BR18>=4,BR18,0)+IF(BS18>=4,BS18,0)+IF(BT18>=4,BT18,0)+IF(BU18>=4,BU18,0)+IF(BV18>=4,BV18,0)+IF(BW18>=4,BW18,0)+IF(BX18>=4,BX18,0)+IF(BY18>=4,BY18,0)+IF(BZ18>=4,BZ18,0)+IF(CA18>=4,CA18,0)+IF(CB18>=4,CB18,0)+IF(CC18>=4,CC18,0)+IF(CD18>=4,CD18,0)+IF(CE18>=4,CE18,0)+IF(CF18>=4,CF18,0)+IF(CG18>=4,CG18,0)+IF(CH18>=4,CH18,0)+IF(CI18>=4,CI18,0)) -> 21
A19: j. | B19: =IF('input-output'!$I$48="Y", 'Data Analysis'!CL19,'Data Analysis'!CM19) -> 0 | CL19: =SUM(AU19:CI19) -> 0 | CM19: =SUM(IF(AU19>=4,AU19,0)+IF(AV19>=4,AV19,0)+IF(AW19>=4,AW19,0)+IF(AX19>=4,AX19,0)+IF(AY19>=4,AY19,0)+IF(AZ19>=4,AZ19,0)+IF(BA19>=4,BA19,0)+IF(BB19>=4,BB19,0)+IF(BC19>=4,BC19,0)+IF(BD19>=4,BD19,0)+IF(BE19>=4,BE19,0)+IF(BF19>=4,BF19,0)+IF(BG19>=4,BG19,0)+IF(BH19>=4,BH19,0)+IF(BI19>=4,BI19,0)+IF(BJ19>=4,BJ19,0)+IF(BK19>=4,BK19,0)+IF(BL19>=4,BL19,0)+IF(BM19>=4,BM19,0)+IF(BN19>=4,BN19,0)+IF(BO19>=4,BO19,0)+IF(BP19>=4,BP19,0)+IF(BQ19>=4,BQ19,0)+IF(BR19>=4,BR19,0)+IF(BS19>=4,BS19,0)+IF(BT19>=4,BT19,0)+IF(BU19>=4,BU19,0)+IF(BV19>=4,BV19,0)+IF(BW19>=4,BW19,0)+IF(BX19>=4,BX19,0)+IF(BY19>=4,BY19,0)+IF(BZ19>=4,BZ19,0)+IF(CA19>=4,CA19,0)+IF(CB19>=4,CB19,0)+IF(CC19>=4,CC19,0)+IF(CD19>=4,CD19,0)+IF(CE19>=4,CE19,0)+IF(CF19>=4,CF19,0)+IF(CG19>=4,CG19,0)+IF(CH19>=4,CH19,0)+IF(CI19>=4,CI19,0)) -> 0
A20: 4. Understanding and application of: | B20: =SUM(B21:B29) -> 118 | C20: =B20/$B$46 -> 0.12343096 | CL20: =SUM(AU20:CI20) -> 0 | CM20: =SUM(IF(AU20>=4,AU20,0)+IF(AV20>=4,AV20,0)+IF(AW20>=4,AW20,0)+IF(AX20>=4,AX20,0)+IF(AY20>=4,AY20,0)+IF(AZ20>=4,AZ20,0)+IF(BA20>=4,BA20,0)+IF(BB20>=4,BB20,0)+IF(BC20>=4,BC20,0)+IF(BD20>=4,BD20,0)+IF(BE20>=4,BE20,0)+IF(BF20>=4,BF20,0)+IF(BG20>=4,BG20,0)+IF(BH20>=4,BH20,0)+IF(BI20>=4,BI20,0)+IF(BJ20>=4,BJ20,0)+IF(BK20>=4,BK20,0)+IF(BL20>=4,BL20,0)+IF(BM20>=4,BM20,0)+IF(BN20>=4,BN20,0)+IF(BO20>=4,BO20,0)+IF(BP20>=4,BP20,0)+IF(BQ20>=4,BQ20,0)+IF(BR20>=4,BR20,0)+IF(BS20>=4,BS20,0)+IF(BT20>=4,BT20,0)+IF(BU20>=4,BU20,0)+IF(BV20>=4,BV20,0)+IF(BW20>=4,BW20,0)+IF(BX20>=4,BX20,0)+IF(BY20>=4,BY20,0)+IF(BZ20>=4,BZ20,0)+IF(CA20>=4,CA20,0)+IF(CB20>=4,CB20,0)+IF(CC20>=4,CC20,0)+IF(CD20>=4,CD20,0)+IF(CE20>=4,CE20,0)+IF(CF20>=4,CF20,0)+IF(CG20>=4,CG20,0)+IF(CH20>=4,CH20,0)+IF(CI20>=4,CI20,0)) -> 0
A21: a. Biology | B21: =IF('input-output'!$I$48="Y", 'Data Analysis'!CL21,'Data Analysis'!CM21) -> 1 | C21: =B21/$B$46 -> 0.0010460251 | D21: 0 | E21: 0 | F21: 0 | G21: 0 | H21: 0 | I21: 1 | J21: 0 | K21: 0 | L21: 0 | M21: 0 | N21: 0 | O21: 0 | P21: 0 | Q21: 0 | R21: 0 | S21: 0 | T21: 0 | U21: 0 | V21: 0 | W21: 0 | X21: 0 | Y21: 5 | Z21: 0 | AA21: 2 | AB21: 0 | AC21: 4 | AD21: 5 | AE21: 0 | AF21: 0 | AH21: 0 | AI21: 0 | AJ21: 2 | AK21: 0 | AL21: 1 | AU21: =IF(D$2="x",D21,0) -> 0 | AV21: =IF(E$2="x",E21,0) -> 0 | AW21: =IF(F$2="x",F21,0) -> 0 | AX21: =IF(G$2="x",G21,0) -> 0 | AY21: =IF(H$2="x",H21,0) -> 0 | AZ21: =IF(I$2="x",I21,0) -> 1 | BA21: =IF(J$2="x",J21,0) -> 0 | BB21: =IF(K$2="x",K21,0) -> 0 | ... CI21: =IF(AR$2="x",AR21,0) -> 0 | CL21: =SUM(AU21:CI21) -> 1 | CM21: =SUM(IF(AU21>=4,AU21,0)+IF(AV21>=4,AV21,0)+IF(AW21>=4,AW21,0)+IF(AX21>=4,AX21,0)+IF(AY21>=4,AY21,0)+IF(AZ21>=4,AZ21,0)+IF(BA21>=4,BA21,0)+IF(BB21>=4,BB21,0)+IF(BC21>=4,BC21,0)+IF(BD21>=4,BD21,0)+IF(BE21>=4,BE21,0)+IF(BF21>=4,BF21,0)+IF(BG21>=4,BG21,0)+IF(BH21>=4,BH21,0)+IF(BI21>=4,BI21,0)+IF(BJ21>=4,BJ21,0)+IF(BK21>=4,BK21,0)+IF(BL21>=4,BL21,0)+IF(BM21>=4,BM21,0)+IF(BN21>=4,BN21,0)+IF(BO21>=4,BO21,0)+IF(BP21>=4,BP21,0)+IF(BQ21>=4,BQ21,0)+IF(BR21>=4,BR21,0)+IF(BS21>=4,BS21,0)+IF(BT21>=4,BT21,0)+IF(BU21>=4,BU21,0)+IF(BV21>=4,BV21,0)+IF(BW21>=4,BW21,0)+IF(BX21>=4,BX21,0)+IF(BY21>=4,BY21,0)+IF(BZ21>=4,BZ21,0)+IF(CA21>=4,CA21,0)+IF(CB21>=4,CB21,0)+IF(CC21>=4,CC21,0)+IF(CD21>=4,CD21,0)+IF(CE21>=4,CE21,0)+IF(CF21>=4,CF21,0)+IF(CG21>=4,CG21,0)+IF(CH21>=4,CH21,0)+IF(CI21>=4,CI21,0)) -> 0
A22: b. Chemistry | B22: =IF('input-output'!$I$48="Y", 'Data Analysis'!CL22,'Data Analysis'!CM22) -> 11 | C22: =B22/$B$46 -> 0.011506276 | D22: 0 | E22: 0 | F22: 0 | G22: 0 | H22: 0 | I22: 1 | J22: 0 | K22: 0 | L22: 0 | M22: 0 | N22: 0 | O22: 0 | P22: 0 | Q22: 0 | R22: 3 | S22: 0 | T22: 2 | U22: 0 | V22: 0 | W22: 2 | X22: 3 | Y22: 5 | Z22: 3 | AA22: 4 | AB22: 0 | AC22: 0 | AD22: 0 | AE22: 0 | AF22: 3 | AH22: 2 | AI22: 3 | AJ22: 4 | AK22: 0 | AL22: 0 | AQ22: 0 | AR22: 0 | AU22: =IF(D$2="x",D22,0) -> 0 | AV22: =IF(E$2="x",E22,0) -> 0 | AW22: =IF(F$2="x",F22,0) -> 0 | AX22: =IF(G$2="x",G22,0) -> 0 | AY22: =IF(H$2="x",H22,0) -> 0 | AZ22: =IF(I$2="x",I22,0) -> 1 | BA22: =IF(J$2="x",J22,0) -> 0 | BB22: =IF(K$2="x",K22,0) -> 0 | ... CI22: =IF(AR$2="x",AR22,0) -> 0 | CL22: =SUM(AU22:CI22) -> 11 | CM22: =SUM(IF(AU22>=4,AU22,0)+IF(AV22>=4,AV22,0)+IF(AW22>=4,AW22,0)+IF(AX22>=4,AX22,0)+IF(AY22>=4,AY22,0)+IF(AZ22>=4,AZ22,0)+IF(BA22>=4,BA22,0)+IF(BB22>=4,BB22,0)+IF(BC22>=4,BC22,0)+IF(BD22>=4,BD22,0)+IF(BE22>=4,BE22,0)+IF(BF22>=4,BF22,0)+IF(BG22>=4,BG22,0)+IF(BH22>=4,BH22,0)+IF(BI22>=4,BI22,0)+IF(BJ22>=4,BJ22,0)+IF(BK22>=4,BK22,0)+IF(BL22>=4,BL22,0)+IF(BM22>=4,BM22,0)+IF(BN22>=4,BN22,0)+IF(BO22>=4,BO22,0)+IF(BP22>=4,BP22,0)+IF(BQ22>=4,BQ22,0)+IF(BR22>=4,BR22,0)+IF(BS22>=4,BS22,0)+IF(BT22>=4,BT22,0)+IF(BU22>=4,BU22,0)+IF(BV22>=4,BV22,0)+IF(BW22>=4,BW22,0)+IF(BX22>=4,BX22,0)+IF(BY22>=4,BY22,0)+IF(BZ22>=4,BZ22,0)+IF(CA22>=4,CA22,0)+IF(CB22>=4,CB22,0)+IF(CC22>=4,CC22,0)+IF(CD22>=4,CD22,0)+IF(CE22>=4,CE22,0)+IF(CF22>=4,CF22,0)+IF(CG22>=4,CG22,0)+IF(CH22>=4,CH22,0)+IF(CI22>=4,CI22,0)) -> 0
A23: c. Geology | B23: =IF('input-output'!$I$48="Y", 'Data Analysis'!CL23,'Data Analysis'!CM23) -> 12 | C23: =B23/$B$46 -> 0.012552301 | D23: 0 | E23: 0 | F23: 0 | G23: 0 | H23: 0 | I23: 1 | J23: 0 | K23: 0 | L23: 0 | M23: 0 | N23: 0 | O23: 0 | P23: 0 | Q23: 0 | R23: 0 | S23: 0 | T23: 3 | U23: 3 | V23: 0 | W23: 0 | X23: 3 | Y23: 3 | Z23: 0 | AA23: 0 | AB23: 0 | AC23: 0 | AD23: 3 | AE23: 0 | AF23: 3 | AH23: 2 | AI23: 3 | AJ23: 0 | AK23: 0 | AL23: 0 | AU23: =IF(D$2="x",D23,0) -> 0 | AV23: =IF(E$2="x",E23,0) -> 0 | AW23: =IF(F$2="x",F23,0) -> 0 | AX23: =IF(G$2="x",G23,0) -> 0 | AY23: =IF(H$2="x",H23,0) -> 0 | AZ23: =IF(I$2="x",I23,0) -> 1 | BA23: =IF(J$2="x",J23,0) -> 0 | BB23: =IF(K$2="x",K23,0) -> 0 | ... CI23: =IF(AR$2="x",AR23,0) -> 0 | CL23: =SUM(AU23:CI23) -> 12 | CM23: =SUM(IF(AU23>=4,AU23,0)+IF(AV23>=4,AV23,0)+IF(AW23>=4,AW23,0)+IF(AX23>=4,AX23,0)+IF(AY23>=4,AY23,0)+IF(AZ23>=4,AZ23,0)+IF(BA23>=4,BA23,0)+IF(BB23>=4,BB23,0)+IF(BC23>=4,BC23,0)+IF(BD23>=4,BD23,0)+IF(BE23>=4,BE23,0)+IF(BF23>=4,BF23,0)+IF(BG23>=4,BG23,0)+IF(BH23>=4,BH23,0)+IF(BI23>=4,BI23,0)+IF(BJ23>=4,BJ23,0)+IF(BK23>=4,BK23,0)+IF(BL23>=4,BL23,0)+IF(BM23>=4,BM23,0)+IF(BN23>=4,BN23,0)+IF(BO23>=4,BO23,0)+IF(BP23>=4,BP23,0)+IF(BQ23>=4,BQ23,0)+IF(BR23>=4,BR23,0)+IF(BS23>=4,BS23,0)+IF(BT23>=4,BT23,0)+IF(BU23>=4,BU23,0)+IF(BV23>=4,BV23,0)+IF(BW23>=4,BW23,0)+IF(BX23>=4,BX23,0)+IF(BY23>=4,BY23,0)+IF(BZ23>=4,BZ23,0)+IF(CA23>=4,CA23,0)+IF(CB23>=4,CB23,0)+IF(CC23>=4,CC23,0)+IF(CD23>=4,CD23,0)+IF(CE23>=4,CE23,0)+IF(CF23>=4,CF23,0)+IF(CG23>=4,CG23,0)+IF(CH23>=4,CH23,0)+IF(CI23>=4,CI23,0)) -> 0 | CP23: ='input-output'!D9 -> Geotech | CQ23: 1
A24: d. Physics | B24: =IF('input-output'!$I$48="Y", 'Data Analysis'!CL24,'Data Analysis'!CM24) -> 26 | C24: =B24/$B$46 -> 0.027196653 | D24: 0 | E24: 1 | F24: 1 | G24: 1 | H24: 3 | I24: 5 | J24: 1 | K24: 2 | L24: 1 | M24: 0 | N24: 0 | O24: 0 | P24: 0 | Q24: 3 | R24: 3 | S24: 0 | T24: 2 | U24: 2 | V24: 2 | W24: 2 | X24: 2 | Y24: 0 | Z24: 0 | AA24: 0 | AB24: 0 | AC24: 0 | AD24: 0 | AE24: 0 | AF24: 3 | AH24: 1 | AI24: 2 | AJ24: 0 | AK24: 0 | AL24: 0 | AU24: =IF(D$2="x",D24,0) -> 0 | AV24: =IF(E$2="x",E24,0) -> 1 | AW24: =IF(F$2="x",F24,0) -> 1 | AX24: =IF(G$2="x",G24,0) -> 1 | AY24: =IF(H$2="x",H24,0) -> 3 | AZ24: =IF(I$2="x",I24,0) -> 5 | BA24: =IF(J$2="x",J24,0) -> 0 | BB24: =IF(K$2="x",K24,0) -> 2 | ... CI24: =IF(AR$2="x",AR24,0) -> 0 | CL24: =SUM(AU24:CI24) -> 26 | CM24: =SUM(IF(AU24>=4,AU24,0)+IF(AV24>=4,AV24,0)+IF(AW24>=4,AW24,0)+IF(AX24>=4,AX24,0)+IF(AY24>=4,AY24,0)+IF(AZ24>=4,AZ24,0)+IF(BA24>=4,BA24,0)+IF(BB24>=4,BB24,0)+IF(BC24>=4,BC24,0)+IF(BD24>=4,BD24,0)+IF(BE24>=4,BE24,0)+IF(BF24>=4,BF24,0)+IF(BG24>=4,BG24,0)+IF(BH24>=4,BH24,0)+IF(BI24>=4,BI24,0)+IF(BJ24>=4,BJ24,0)+IF(BK24>=4,BK24,0)+IF(BL24>=4,BL24,0)+IF(BM24>=4,BM24,0)+IF(BN24>=4,BN24,0)+IF(BO24>=4,BO24,0)+IF(BP24>=4,BP24,0)+IF(BQ24>=4,BQ24,0)+IF(BR24>=4,BR24,0)+IF(BS24>=4,BS24,0)+IF(BT24>=4,BT24,0)+IF(BU24>=4,BU24,0)+IF(BV24>=4,BV24,0)+IF(BW24>=4,BW24,0)+IF(BX24>=4,BX24,0)+IF(BY24>=4,BY24,0)+IF(BZ24>=4,BZ24,0)+IF(CA24>=4,CA24,0)+IF(CB24>=4,CB24,0)+IF(CC24>=4,CC24,0)+IF(CD24>=4,CD24,0)+IF(CE24>=4,CE24,0)+IF(CF24>=4,CF24,0)+IF(CG24>=4,CG24,0)+IF(CH24>=4,CH24,0)+IF(CI24>=4,CI24,0)) -> 5 | CO24: Fundamntal Courses | CP24: =IF(D2="x",1, 0) -> 1 | CQ24: =IF(E2="x",1, 0) -> 1 | CR24: =IF(F2="x",1, 0) -> 1 | CS24: =IF(H2="x",1, 0) -> 1 | CT24: =IF(I2="x",1, 0) -> 1 | CU24: =IF(T2="x",1, 0) -> 1
A25: e. Differential and Integral Calculus | B25: =IF('input-output'!$I$48="Y", 'Data Analysis'!CL25,'Data Analysis'!CM25) -> 22 | C25: =B25/$B$46 -> 0.023012552 | D25: 0 | E25: 2 | F25: 4 | G25: 4 | H25: 0 | I25: 4 | J25: 0 | K25: 1 | L25: 0 | M25: 0 | N25: 0 | O25: 0 | P25: 0 | Q25: 0 | R25: 2 | S25: 0 | T25: 1 | U25: 1 | V25: 2 | W25: 2 | X25: 0 | Y25: 0 | Z25: 0 | AA25: 4 | AB25: 4 | AC25: 0 | AD25: 0 | AE25: 0 | AF25: 3 | AH25: 0 | AI25: 1 | AJ25: 0 | AK25: 0 | AL25: 0 | AU25: =IF(D$2="x",D25,0) -> 0 | AV25: =IF(E$2="x",E25,0) -> 2 | AW25: =IF(F$2="x",F25,0) -> 4 | AX25: =IF(G$2="x",G25,0) -> 4 | AY25: =IF(H$2="x",H25,0) -> 0 | AZ25: =IF(I$2="x",I25,0) -> 4 | BA25: =IF(J$2="x",J25,0) -> 0 | BB25: =IF(K$2="x",K25,0) -> 1 | ... CI25: =IF(AR$2="x",AR25,0) -> 0 | CL25: =SUM(AU25:CI25) -> 22 | CM25: =SUM(IF(AU25>=4,AU25,0)+IF(AV25>=4,AV25,0)+IF(AW25>=4,AW25,0)+IF(AX25>=4,AX25,0)+IF(AY25>=4,AY25,0)+IF(AZ25>=4,AZ25,0)+IF(BA25>=4,BA25,0)+IF(BB25>=4,BB25,0)+IF(BC25>=4,BC25,0)+IF(BD25>=4,BD25,0)+IF(BE25>=4,BE25,0)+IF(BF25>=4,BF25,0)+IF(BG25>=4,BG25,0)+IF(BH25>=4,BH25,0)+IF(BI25>=4,BI25,0)+IF(BJ25>=4,BJ25,0)+IF(BK25>=4,BK25,0)+IF(BL25>=4,BL25,0)+IF(BM25>=4,BM25,0)+IF(BN25>=4,BN25,0)+IF(BO25>=4,BO25,0)+IF(BP25>=4,BP25,0)+IF(BQ25>=4,BQ25,0)+IF(BR25>=4,BR25,0)+IF(BS25>=4,BS25,0)+IF(BT25>=4,BT25,0)+IF(BU25>=4,BU25,0)+IF(BV25>=4,BV25,0)+IF(BW25>=4,BW25,0)+IF(BX25>=4,BX25,0)+IF(BY25>=4,BY25,0)+IF(BZ25>=4,BZ25,0)+IF(CA25>=4,CA25,0)+IF(CB25>=4,CB25,0)+IF(CC25>=4,CC25,0)+IF(CD25>=4,CD25,0)+IF(CE25>=4,CE25,0)+IF(CF25>=4,CF25,0)+IF(CG25>=4,CG25,0)+IF(CH25>=4,CH25,0)+IF(CI25>=4,CI25,0)) -> 12 | CO25: Background Courss | CP25: =IF(S2="x",1, 0) -> 1 | CQ25: =IF(AM2="x",1, 0) -> 1 | CR25: =IF(AN2="x",1, 0) -> 1 | CS25: =IF(AO2="x",1, 0) -> 0
A26: f. Differential Equations | B26: =IF('input-output'!$I$48="Y", 'Data Analysis'!CL26,'Data Analysis'!CM26) -> 15 | C26: =B26/$B$46 -> 0.015690377 | D26: 0 | E26: 0 | F26: 0 | G26: 0 | H26: 0 | I26: 4 | J26: 0 | K26: 2 | L26: 0 | M26: 0 | N26: 0 | O26: 0 | P26: 0 | Q26: 0 | R26: 2 | S26: 0 | T26: 1 | U26: 1 | V26: 2 | W26: 2 | X26: 0 | Y26: 0 | Z26: 0 | AA26: 0 | AB26: 4 | AC26: 0 | AD26: 0 | AE26: 5 | AF26: 4 | AH26: 0 | AI26: 3 | AJ26: 0 | AK26: 0 | AL26: 0 | AU26: =IF(D$2="x",D26,0) -> 0 | AV26: =IF(E$2="x",E26,0) -> 0 | AW26: =IF(F$2="x",F26,0) -> 0 | AX26: =IF(G$2="x",G26,0) -> 0 | AY26: =IF(H$2="x",H26,0) -> 0 | AZ26: =IF(I$2="x",I26,0) -> 4 | BA26: =IF(J$2="x",J26,0) -> 0 | BB26: =IF(K$2="x",K26,0) -> 2 | ... CI26: =IF(AR$2="x",AR26,0) -> 0 | CL26: =SUM(AU26:CI26) -> 15 | CM26: =SUM(IF(AU26>=4,AU26,0)+IF(AV26>=4,AV26,0)+IF(AW26>=4,AW26,0)+IF(AX26>=4,AX26,0)+IF(AY26>=4,AY26,0)+IF(AZ26>=4,AZ26,0)+IF(BA26>=4,BA26,0)+IF(BB26>=4,BB26,0)+IF(BC26>=4,BC26,0)+IF(BD26>=4,BD26,0)+IF(BE26>=4,BE26,0)+IF(BF26>=4,BF26,0)+IF(BG26>=4,BG26,0)+IF(BH26>=4,BH26,0)+IF(BI26>=4,BI26,0)+IF(BJ26>=4,BJ26,0)+IF(BK26>=4,BK26,0)+IF(BL26>=4,BL26,0)+IF(BM26>=4,BM26,0)+IF(BN26>=4,BN26,0)+IF(BO26>=4,BO26,0)+IF(BP26>=4,BP26,0)+IF(BQ26>=4,BQ26,0)+IF(BR26>=4,BR26,0)+IF(BS26>=4,BS26,0)+IF(BT26>=4,BT26,0)+IF(BU26>=4,BU26,0)+IF(BV26>=4,BV26,0)+IF(BW26>=4,BW26,0)+IF(BX26>=4,BX26,0)+IF(BY26>=4,BY26,0)+IF(BZ26>=4,BZ26,0)+IF(CA26>=4,CA26,0)+IF(CB26>=4,CB26,0)+IF(CC26>=4,CC26,0)+IF(CD26>=4,CD26,0)+IF(CE26>=4,CE26,0)+IF(CF26>=4,CF26,0)+IF(CG26>=4,CG26,0)+IF(CH26>=4,CH26,0)+IF(CI26>=4,CI26,0)) -> 4 | CO26: Structural | CP26: =IF(L2="x",1, 0) -> 1 | CQ26: =IF(G2="x",1, 0) -> 1 | CR26: =IF(J2="x",1, 0) -> 0 | CS26: =IF(K2="x",1, 0) -> 1 | CT26: =IF(R2="x",1, 0) -> 1 | CU26: =IF(AE2="x",1, 0) -> 0 | CV26: =IF(AF2="x",1, 0) -> 0
A27: g. Probability and Statistics | B27: =IF('input-output'!$I$48="Y", 'Data Analysis'!CL27,'Data Analysis'!CM27) -> 16 | C27: =B27/$B$46 -> 0.016736402 | D27: 0 | E27: 0 | F27: 0 | G27: 0 | H27: 3 | I27: 2 | J27: 1 | K27: 1 | L27: 1 | M27: 2 | N27: 0 | O27: 0 | P27: 0 | Q27: 3 | R27: 3 | S27: 0 | T27: 0 | U27: 0 | V27: 3 | W27: 3 | X27: 5 | Y27: 2 | Z27: 0 | AA27: 0 | AB27: 0 | AC27: 0 | AD27: 0 | AE27: 0 | AF27: 3 | AH27: 1 | AI27: 0 | AJ27: 1 | AK27: 4 | AL27: 0 | AP27: 0 | AU27: =IF(D$2="x",D27,0) -> 0 | AV27: =IF(E$2="x",E27,0) -> 0 | AW27: =IF(F$2="x",F27,0) -> 0 | AX27: =IF(G$2="x",G27,0) -> 0 | AY27: =IF(H$2="x",H27,0) -> 3 | AZ27: =IF(I$2="x",I27,0) -> 2 | BA27: =IF(J$2="x",J27,0) -> 0 | BB27: =IF(K$2="x",K27,0) -> 1 | ... CI27: =IF(AR$2="x",AR27,0) -> 0 | CL27: =SUM(AU27:CI27) -> 16 | CM27: =SUM(IF(AU27>=4,AU27,0)+IF(AV27>=4,AV27,0)+IF(AW27>=4,AW27,0)+IF(AX27>=4,AX27,0)+IF(AY27>=4,AY27,0)+IF(AZ27>=4,AZ27,0)+IF(BA27>=4,BA27,0)+IF(BB27>=4,BB27,0)+IF(BC27>=4,BC27,0)+IF(BD27>=4,BD27,0)+IF(BE27>=4,BE27,0)+IF(BF27>=4,BF27,0)+IF(BG27>=4,BG27,0)+IF(BH27>=4,BH27,0)+IF(BI27>=4,BI27,0)+IF(BJ27>=4,BJ27,0)+IF(BK27>=4,BK27,0)+IF(BL27>=4,BL27,0)+IF(BM27>=4,BM27,0)+IF(BN27>=4,BN27,0)+IF(BO27>=4,BO27,0)+IF(BP27>=4,BP27,0)+IF(BQ27>=4,BQ27,0)+IF(BR27>=4,BR27,0)+IF(BS27>=4,BS27,0)+IF(BT27>=4,BT27,0)+IF(BU27>=4,BU27,0)+IF(BV27>=4,BV27,0)+IF(BW27>=4,BW27,0)+IF(BX27>=4,BX27,0)+IF(BY27>=4,BY27,0)+IF(BZ27>=4,BZ27,0)+IF(CA27>=4,CA27,0)+IF(CB27>=4,CB27,0)+IF(CC27>=4,CC27,0)+IF(CD27>=4,CD27,0)+IF(CE27>=4,CE27,0)+IF(CF27>=4,CF27,0)+IF(CG27>=4,CG27,0)+IF(CH27>=4,CH27,0)+IF(CI27>=4,CI27,0)) -> 0 | CO27: Geotechnical | CP27: =IF(T2="x",1, 0) -> 1 | CQ27: =IF(U2="x",1, 0) -> 1 | CR27: =IF(AH2="x",1, 0) -> 1 | CS27: =IF(AI2="x",1, 0) -> 1
A28: h. Linear Algebra | B28: =IF('input-output'!$I$48="Y", 'Data Analysis'!CL28,'Data Analysis'!CM28) -> 13 | C28: =B28/$B$46 -> 0.013598326 | D28: 0 | E28: 0 | F28: 0 | G28: 0 | H28: 3 | I28: 2 | J28: 0 | K28: 2 | L28: 0 | M28: 0 | N28: 0 | O28: 0 | P28: 0 | Q28: 3 | R28: 3 | S28: 0 | T28: 0 | U28: 0 | V28: 0 | W28: 0 | X28: 0 | Y28: 0 | Z28: 0 | AA28: 0 | AB28: 0 | AC28: 0 | AD28: 0 | AE28: 5 | AF28: 4 | AH28: 0 | AI28: 3 | AJ28: 0 | AK28: 0 | AL28: 0 | AU28: =IF(D$2="x",D28,0) -> 0 | AV28: =IF(E$2="x",E28,0) -> 0 | AW28: =IF(F$2="x",F28,0) -> 0 | AX28: =IF(G$2="x",G28,0) -> 0 | AY28: =IF(H$2="x",H28,0) -> 3 | AZ28: =IF(I$2="x",I28,0) -> 2 | BA28: =IF(J$2="x",J28,0) -> 0 | BB28: =IF(K$2="x",K28,0) -> 2 | ... CI28: =IF(AR$2="x",AR28,0) -> 0 | CL28: =SUM(AU28:CI28) -> 13 | CM28: =SUM(IF(AU28>=4,AU28,0)+IF(AV28>=4,AV28,0)+IF(AW28>=4,AW28,0)+IF(AX28>=4,AX28,0)+IF(AY28>=4,AY28,0)+IF(AZ28>=4,AZ28,0)+IF(BA28>=4,BA28,0)+IF(BB28>=4,BB28,0)+IF(BC28>=4,BC28,0)+IF(BD28>=4,BD28,0)+IF(BE28>=4,BE28,0)+IF(BF28>=4,BF28,0)+IF(BG28>=4,BG28,0)+IF(BH28>=4,BH28,0)+IF(BI28>=4,BI28,0)+IF(BJ28>=4,BJ28,0)+IF(BK28>=4,BK28,0)+IF(BL28>=4,BL28,0)+IF(BM28>=4,BM28,0)+IF(BN28>=4,BN28,0)+IF(BO28>=4,BO28,0)+IF(BP28>=4,BP28,0)+IF(BQ28>=4,BQ28,0)+IF(BR28>=4,BR28,0)+IF(BS28>=4,BS28,0)+IF(BT28>=4,BT28,0)+IF(BU28>=4,BU28,0)+IF(BV28>=4,BV28,0)+IF(BW28>=4,BW28,0)+IF(BX28>=4,BX28,0)+IF(BY28>=4,BY28,0)+IF(BZ28>=4,BZ28,0)+IF(CA28>=4,CA28,0)+IF(CB28>=4,CB28,0)+IF(CC28>=4,CC28,0)+IF(CD28>=4,CD28,0)+IF(CE28>=4,CE28,0)+IF(CF28>=4,CF28,0)+IF(CG28>=4,CG28,0)+IF(CH28>=4,CH28,0)+IF(CI28>=4,CI28,0)) -> 0 | CO28: Environmental and Hydraulics | CP28: =IF(Y2="x",1, 0) -> 0 | CQ28: =IF(Z2="x",1, 0) -> 0 | CR28: =IF(AA2="x",1, 0) -> 0 | CS28: =IF(AB2="x",1, 0) -> 0 | CT28: =IF(AJ2="x",1, 0) -> 0 | CU28: =IF(AK2="x",1, 0) -> 0
A29: i. Higher Mathematics | B29: =IF('input-output'!$I$48="Y", 'Data Analysis'!CL29,'Data Analysis'!CM29) -> 2 | C29: =B29/$B$46 -> 0.0020920502 | D29: 0 | E29: 0 | F29: 0 | G29: 0 | H29: 0 | I29: 2 | J29: 0 | K29: 0 | L29: 0 | M29: 0 | N29: 0 | O29: 0 | P29: 0 | Q29: 0 | R29: 0 | S29: 0 | T29: 0 | U29: 0 | V29: 0 | W29: 0 | X29: 0 | Y29: 0 | Z29: 0 | AA29: 0 | AB29: 0 | AC29: 0 | AD29: 0 | AE29: 0 | AF29: 3 | AH29: 0 | AI29: 0 | AJ29: 0 | AK29: 0 | AL29: 0 | AU29: =IF(D$2="x",D29,0) -> 0 | AV29: =IF(E$2="x",E29,0) -> 0 | AW29: =IF(F$2="x",F29,0) -> 0 | AX29: =IF(G$2="x",G29,0) -> 0 | AY29: =IF(H$2="x",H29,0) -> 0 | AZ29: =IF(I$2="x",I29,0) -> 2 | BA29: =IF(J$2="x",J29,0) -> 0 | BB29: =IF(K$2="x",K29,0) -> 0 | ... CI29: =IF(AR$2="x",AR29,0) -> 0 | CL29: =SUM(AU29:CI29) -> 2 | CM29: =SUM(IF(AU29>=4,AU29,0)+IF(AV29>=4,AV29,0)+IF(AW29>=4,AW29,0)+IF(AX29>=4,AX29,0)+IF(AY29>=4,AY29,0)+IF(AZ29>=4,AZ29,0)+IF(BA29>=4,BA29,0)+IF(BB29>=4,BB29,0)+IF(BC29>=4,BC29,0)+IF(BD29>=4,BD29,0)+IF(BE29>=4,BE29,0)+IF(BF29>=4,BF29,0)+IF(BG29>=4,BG29,0)+IF(BH29>=4,BH29,0)+IF(BI29>=4,BI29,0)+IF(BJ29>=4,BJ29,0)+IF(BK29>=4,BK29,0)+IF(BL29>=4,BL29,0)+IF(BM29>=4,BM29,0)+IF(BN29>=4,BN29,0)+IF(BO29>=4,BO29,0)+IF(BP29>=4,BP29,0)+IF(BQ29>=4,BQ29,0)+IF(BR29>=4,BR29,0)+IF(BS29>=4,BS29,0)+IF(BT29>=4,BT29,0)+IF(BU29>=4,BU29,0)+IF(BV29>=4,BV29,0)+IF(BW29>=4,BW29,0)+IF(BX29>=4,BX29,0)+IF(BY29>=4,BY29,0)+IF(BZ29>=4,BZ29,0)+IF(CA29>=4,CA29,0)+IF(CB29>=4,CB29,0)+IF(CC29>=4,CC29,0)+IF(CD29>=4,CD29,0)+IF(CE29>=4,CE29,0)+IF(CF29>=4,CF29,0)+IF(CG29>=4,CG29,0)+IF(CH29>=4,CH29,0)+IF(CI29>=4,CI29,0)) -> 0 | CO29: Urban and Environmental Planning | CP29: =IF(AC2="x",1, 0) -> 0 | CQ29: =IF(AD2="x",1, 0) -> 0 | CR29: =IF(AL2="x",1, 0) -> 0
A30: 5. Understanding of engineering design process, including the following: | B30: =SUM(B31:B36) -> 168 | C30: =B30/$B$46 -> 0.17573222 | CL30: =SUM(AU30:CI30) -> 0 | CM30: =SUM(IF(AU30>=4,AU30,0)+IF(AV30>=4,AV30,0)+IF(AW30>=4,AW30,0)+IF(AX30>=4,AX30,0)+IF(AY30>=4,AY30,0)+IF(AZ30>=4,AZ30,0)+IF(BA30>=4,BA30,0)+IF(BB30>=4,BB30,0)+IF(BC30>=4,BC30,0)+IF(BD30>=4,BD30,0)+IF(BE30>=4,BE30,0)+IF(BF30>=4,BF30,0)+IF(BG30>=4,BG30,0)+IF(BH30>=4,BH30,0)+IF(BI30>=4,BI30,0)+IF(BJ30>=4,BJ30,0)+IF(BK30>=4,BK30,0)+IF(BL30>=4,BL30,0)+IF(BM30>=4,BM30,0)+IF(BN30>=4,BN30,0)+IF(BO30>=4,BO30,0)+IF(BP30>=4,BP30,0)+IF(BQ30>=4,BQ30,0)+IF(BR30>=4,BR30,0)+IF(BS30>=4,BS30,0)+IF(BT30>=4,BT30,0)+IF(BU30>=4,BU30,0)+IF(BV30>=4,BV30,0)+IF(BW30>=4,BW30,0)+IF(BX30>=4,BX30,0)+IF(BY30>=4,BY30,0)+IF(BZ30>=4,BZ30,0)+IF(CA30>=4,CA30,0)+IF(CB30>=4,CB30,0)+IF(CC30>=4,CC30,0)+IF(CD30>=4,CD30,0)+IF(CE30>=4,CE30,0)+IF(CF30>=4,CF30,0)+IF(CG30>=4,CG30,0)+IF(CH30>=4,CH30,0)+IF(CI30>=4,CI30,0)) -> 0 | CO30: Transportation | CP30: =IF(V2="x",1, 0) -> 1 | CQ30: =IF(W2="x",1, 0) -> 0 | CR30: =IF(X2="x",1, 0) -> 0 | CS30: =IF(AG2="x",1, 0) -> 0
A31: a. Ability to perform design. | B31: =IF('input-output'!$I$48="Y", 'Data Analysis'!CL31,'Data Analysis'!CM31) -> 47 | C31: =B31/$B$46 -> 0.04916318 | D31: 0 | E31: 4 | F31: 4 | G31: 5 | H31: 0 | I31: 2 | J31: 5 | K31: 5 | L31: 5 | M31: 1 | N31: 1 | O31: 0 | P31: 3 | Q31: 0 | R31: 3 | S31: 3 | T31: 1 | U31: 3 | V31: 5 | W31: 5 | X31: 5 | Y31: 3 | Z31: 4 | AA31: 5 | AB31: 4 | AC31: 0 | AD31: 4 | AE31: 0 | AF31: 5 | AH31: 4 | AI31: 2 | AJ31: 0 | AK31: 0 | AL31: 0 | AU31: =IF(D$2="x",D31,0) -> 0 | AV31: =IF(E$2="x",E31,0) -> 4 | AW31: =IF(F$2="x",F31,0) -> 4 | AX31: =IF(G$2="x",G31,0) -> 5 | AY31: =IF(H$2="x",H31,0) -> 0 | AZ31: =IF(I$2="x",I31,0) -> 2 | BA31: =IF(J$2="x",J31,0) -> 0 | BB31: =IF(K$2="x",K31,0) -> 5 | ... CI31: =IF(AR$2="x",AR31,0) -> 0 | CL31: =SUM(AU31:CI31) -> 47 | CM31: =SUM(IF(AU31>=4,AU31,0)+IF(AV31>=4,AV31,0)+IF(AW31>=4,AW31,0)+IF(AX31>=4,AX31,0)+IF(AY31>=4,AY31,0)+IF(AZ31>=4,AZ31,0)+IF(BA31>=4,BA31,0)+IF(BB31>=4,BB31,0)+IF(BC31>=4,BC31,0)+IF(BD31>=4,BD31,0)+IF(BE31>=4,BE31,0)+IF(BF31>=4,BF31,0)+IF(BG31>=4,BG31,0)+IF(BH31>=4,BH31,0)+IF(BI31>=4,BI31,0)+IF(BJ31>=4,BJ31,0)+IF(BK31>=4,BK31,0)+IF(BL31>=4,BL31,0)+IF(BM31>=4,BM31,0)+IF(BN31>=4,BN31,0)+IF(BO31>=4,BO31,0)+IF(BP31>=4,BP31,0)+IF(BQ31>=4,BQ31,0)+IF(BR31>=4,BR31,0)+IF(BS31>=4,BS31,0)+IF(BT31>=4,BT31,0)+IF(BU31>=4,BU31,0)+IF(BV31>=4,BV31,0)+IF(BW31>=4,BW31,0)+IF(BX31>=4,BX31,0)+IF(BY31>=4,BY31,0)+IF(BZ31>=4,BZ31,0)+IF(CA31>=4,CA31,0)+IF(CB31>=4,CB31,0)+IF(CC31>=4,CC31,0)+IF(CD31>=4,CD31,0)+IF(CE31>=4,CE31,0)+IF(CF31>=4,CF31,0)+IF(CG31>=4,CG31,0)+IF(CH31>=4,CH31,0)+IF(CI31>=4,CI31,0)) -> 32 | CO31: Construction and Management | CP31: =IF(M2="x",1, 0) -> 1 | CQ31: =IF(N2="x",1, 0) -> 0 | CR31: =IF(X2="x",1, 0) -> 0 | CS31: =IF(P2="x",1, 0) -> 0 | CT31: =IF(Q2="x",1, 0) -> 0
A32: b. Multidisciplinary aspects. | B32: =IF('input-output'!$I$48="Y", 'Data Analysis'!CL32,'Data Analysis'!CM32) -> 20 | C32: =B32/$B$46 -> 0.020920502 | D32: 0 | E32: 0 | F32: 0 | G32: 0 | H32: 0 | I32: 0 | J32: 2 | K32: 3 | L32: 2 | M32: 5 | N32: 2 | O32: 2 | P32: 4 | Q32: 0 | R32: 0 | S32: 3 | T32: 1 | U32: 3 | V32: 0 | W32: 0 | X32: 0 | Y32: 5 | Z32: 0 | AA32: 0 | AB32: 0 | AC32: 4 | AD32: 5 | AE32: 0 | AF32: 4 | AH32: 1 | AI32: 2 | AJ32: 0 | AK32: 0 | AL32: 5 | AU32: =IF(D$2="x",D32,0) -> 0 | AV32: =IF(E$2="x",E32,0) -> 0 | AW32: =IF(F$2="x",F32,0) -> 0 | AX32: =IF(G$2="x",G32,0) -> 0 | AY32: =IF(H$2="x",H32,0) -> 0 | AZ32: =IF(I$2="x",I32,0) -> 0 | BA32: =IF(J$2="x",J32,0) -> 0 | BB32: =IF(K$2="x",K32,0) -> 3 | ... CI32: =IF(AR$2="x",AR32,0) -> 0 | CL32: =SUM(AU32:CI32) -> 20 | CM32: =SUM(IF(AU32>=4,AU32,0)+IF(AV32>=4,AV32,0)+IF(AW32>=4,AW32,0)+IF(AX32>=4,AX32,0)+IF(AY32>=4,AY32,0)+IF(AZ32>=4,AZ32,0)+IF(BA32>=4,BA32,0)+IF(BB32>=4,BB32,0)+IF(BC32>=4,BC32,0)+IF(BD32>=4,BD32,0)+IF(BE32>=4,BE32,0)+IF(BF32>=4,BF32,0)+IF(BG32>=4,BG32,0)+IF(BH32>=4,BH32,0)+IF(BI32>=4,BI32,0)+IF(BJ32>=4,BJ32,0)+IF(BK32>=4,BK32,0)+IF(BL32>=4,BL32,0)+IF(BM32>=4,BM32,0)+IF(BN32>=4,BN32,0)+IF(BO32>=4,BO32,0)+IF(BP32>=4,BP32,0)+IF(BQ32>=4,BQ32,0)+IF(BR32>=4,BR32,0)+IF(BS32>=4,BS32,0)+IF(BT32>=4,BT32,0)+IF(BU32>=4,BU32,0)+IF(BV32>=4,BV32,0)+IF(BW32>=4,BW32,0)+IF(BX32>=4,BX32,0)+IF(BY32>=4,BY32,0)+IF(BZ32>=4,BZ32,0)+IF(CA32>=4,CA32,0)+IF(CB32>=4,CB32,0)+IF(CC32>=4,CC32,0)+IF(CD32>=4,CD32,0)+IF(CE32>=4,CE32,0)+IF(CF32>=4,CF32,0)+IF(CG32>=4,CG32,0)+IF(CH32>=4,CH32,0)+IF(CI32>=4,CI32,0)) -> 5
