Workbook

Sheet Names
B1: Quarter 1 | C1: Test Grade | D1: Quiz Grade | E1: Notebook Grade | F1: Homework Grade | G1: Participation Grade | H1: Total
B2: Class | C2: 0.5 | D2: 0.2 | E2: 0.1 | F2: 0.15 | G2: 0.05 | H2: =SUM(C2:G2) -> 1
B3: Enter names here | C3: Enter The weights here | I3: Date Called
U4: Enter the grade range here
A5: # | B5: Last Name, First Name | C5: Phone # | E5: E-Mail | I5: Parent Name | J5: #
A6: 1 | B6: Adams, Bob
A7: 2 | B7: Jones, George
A8: 3 | B8: Smith, Ralph
A9: 4
A10: 5 | U10: Grade Scale
A11: 6 | U11: 1 | V11: to | W11: 0.99 | X11: A+
A12: 7 | U12: 0.98 | V12: to | W12: 0.95 | X12: A
A13: 8 | U13: 0.94 | V13: to | W13: 0.93 | X13: A-
A14: 9 | U14: 0.92 | V14: to | W14: 0.91 | X14: B+
A15: 10 | U15: 0.9 | V15: to | W15: 0.87 | X15: B
A16: 11 | U16: 0.86 | V16: to | W16: 0.85 | X16: B-
A17: 12 | U17: 0.84 | V17: to | W17: 0.83 | X17: C+
A18: 13 | U18: 0.82 | V18: to | W18: 0.79 | X18: C
A19: 14 | U19: 0.78 | V19: to | W19: 0.77 | X19: C- | AA19: Enter your personal information here.
A20: 15 | U20: 0.76 | V20: to | W20: 0.74 | X20: D+
A21: 16 | U21: 0.73 | V21: to | W21: 0.7 | X21: D
A22: 17 | U22: 0.69 | V22: to | W22: 0 | X22: F
A23: 18
A24: 19
A25: 20 | Z25: Voice Mail: | AA25: 447-2727 ext. 127
A26: 21 | Z26: E-Mail: | AA26: mharmless@fcslafayette.org
A27: 22 | Z27: Home Phone: | AA27: 742-8189
A28: 23
A29: 24
A30: 25
A31: 26
A32: 27
A33: 28
A34: 29
A35: 30
A36: 31
A37: 32
A38: 33
A39: 34
A40: 35

Sheet Progress Report
B1: =Names!B1 -> Quarter 1
B2: =Names!B2 -> Class
B3: Final Grade
C4: Final Grade | D4: Letter Grade | E4: =Names!C1 -> Test Grade | F4: =Names!D1 -> Quiz Grade | G4: =Names!E1 -> Notebook Grade | H4: =Names!F1 -> Homework Grade | I4: # of Missing Homework Assignments out of… | J4: =Names!G1 -> Participation Grade
A5: =Names!$A:$A -> # | B5: =Names!$B:$B -> Last Name, First Name | C5: 1 | E5: =Names!C2 -> 0.5 | F5: =Names!D2 -> 0.2 | G5: =Names!E2 -> 0.1 | H5: =Names!F2 -> 0.15 | I5: ='Homework Grade'!E5 -> 5 | J5: =Names!G2 -> 0.05
A6: =Names!$A:$A -> 1 | B6: =Names!$B:$B -> Adams, Bob | C6: =ROUND(((E6*E5)+(F6*F5)+(G6*G5)+(H6*H5)+(J6*J5)),2) -> 0.94 | D6: =HLOOKUP(C6,$Z$24:$AK$25,2) -> A- | E6: ='Test Grade'!C6 -> 0.96499518 | F6: ='Quiz Grade'!C6 -> 0.92855816 | G6: ='Notebook Grade'!C6 -> 0.9499525 | H6: ='Homework Grade'!C6 -> 0.83330556 | I6: ='Homework Grade'!E6 -> 1 | J6: ='Participation Grade'!C6 -> 0.99980004
A7: =Names!$A:$A -> 2 | B7: =Names!$B:$B -> Jones, George | C7: =ROUND(((E7*E5)+(F7*F5)+(G7*G5)+(H7*H5)+(J7*J5)),2) -> 0.89 | D7: =HLOOKUP(C7,$Z$24:$AK$25,2) -> B | E7: ='Test Grade'!C7 -> 0.90499548 | F7: ='Quiz Grade'!C7 -> 0.97141469 | G7: ='Notebook Grade'!C7 -> 0.99995 | H7: ='Homework Grade'!C7 -> 0.66664445 | I7: ='Homework Grade'!E7 -> 2 | J7: ='Participation Grade'!C7 -> 0.79984003
A8: =Names!$A:$A -> 3 | B8: =Names!$B:$B -> Smith, Ralph | C8: =ROUND(((E8*E5)+(F8*F5)+(G8*G5)+(H8*H5)+(J8*J5)),2) -> 0.98 | D8: =HLOOKUP(C8,$Z$24:$AK$25,2) -> A | E8: ='Test Grade'!C8 -> 0.96999515 | F8: ='Quiz Grade'!C8 -> 0.97141469 | G8: ='Notebook Grade'!C8 -> 0.99995 | H8: ='Homework Grade'!C8 -> 0.99996667 | I8: ='Homework Grade'!E8 -> 0 | J8: ='Participation Grade'!C8 -> 0.99980004
A9: =Names!$A:$A -> 4 | B9: =Names!$B:$B -> 0 | C9: =ROUND(((E9*E5)+(F9*F5)+(G9*G5)+(H9*H5)+(J9*J5)),2) -> 0 | D9: =HLOOKUP(C9,$Z$24:$AK$25,2) -> F | E9: ='Test Grade'!C9 -> 0 | F9: ='Quiz Grade'!C9 -> 0 | G9: ='Notebook Grade'!C9 -> 0 | H9: ='Homework Grade'!C9 -> 0 | I9: ='Homework Grade'!E9 -> 5 | J9: ='Participation Grade'!C9 -> 0
A10: =Names!$A:$A -> 5 | B10: =Names!$B:$B -> 0 | C10: =ROUND(((E10*E5)+(F10*F5)+(G10*G5)+(H10*H5)+(J10*J5)),2) -> 0 | D10: =HLOOKUP(C10,$Z$24:$AK$25,2) -> F | E10: ='Test Grade'!C10 -> 0 | F10: ='Quiz Grade'!C10 -> 0 | G10: ='Notebook Grade'!C10 -> 0 | H10: ='Homework Grade'!C10 -> 0 | I10: ='Homework Grade'!E10 -> 5 | J10: ='Participation Grade'!C10 -> 0
A11: =Names!$A:$A -> 6 | B11: =Names!$B:$B -> 0 | C11: =ROUND(((E11*E5)+(F11*F5)+(G11*G5)+(H11*H5)+(J11*J5)),2) -> 0 | D11: =HLOOKUP(C11,$Z$24:$AK$25,2) -> F | E11: ='Test Grade'!C11 -> 0 | F11: ='Quiz Grade'!C11 -> 0 | G11: ='Notebook Grade'!C11 -> 0 | H11: ='Homework Grade'!C11 -> 0 | I11: ='Homework Grade'!E11 -> 5 | J11: ='Participation Grade'!C11 -> 0
A12: =Names!$A:$A -> 7 | B12: =Names!$B:$B -> 0 | C12: =ROUND(((E12*E5)+(F12*F5)+(G12*G5)+(H12*H5)+(J12*J5)),2) -> 0 | D12: =HLOOKUP(C12,$Z$24:$AK$25,2) -> F | E12: ='Test Grade'!C12 -> 0 | F12: ='Quiz Grade'!C12 -> 0 | G12: ='Notebook Grade'!C12 -> 0 | H12: ='Homework Grade'!C12 -> 0 | I12: ='Homework Grade'!E12 -> 5 | J12: ='Participation Grade'!C12 -> 0
A13: =Names!$A:$A -> 8 | B13: =Names!$B:$B -> 0 | C13: =ROUND(((E13*E5)+(F13*F5)+(G13*G5)+(H13*H5)+(J13*J5)),2) -> 0 | D13: =HLOOKUP(C13,$Z$24:$AK$25,2) -> F | E13: ='Test Grade'!C13 -> 0 | F13: ='Quiz Grade'!C13 -> 0 | G13: ='Notebook Grade'!C13 -> 0 | H13: ='Homework Grade'!C13 -> 0 | I13: ='Homework Grade'!E13 -> 5 | J13: ='Participation Grade'!C13 -> 0
A14: =Names!$A:$A -> 9 | B14: =Names!$B:$B -> 0 | C14: =ROUND(((E14*E5)+(F14*F5)+(G14*G5)+(H14*H5)+(J14*J5)),2) -> 0 | D14: =HLOOKUP(C14,$Z$24:$AK$25,2) -> F | E14: ='Test Grade'!C14 -> 0 | F14: ='Quiz Grade'!C14 -> 0 | G14: ='Notebook Grade'!C14 -> 0 | H14: ='Homework Grade'!C14 -> 0 | I14: ='Homework Grade'!E14 -> 5 | J14: ='Participation Grade'!C14 -> 0
A15: =Names!$A:$A -> 10 | B15: =Names!$B:$B -> 0 | C15: =ROUND(((E15*E5)+(F15*F5)+(G15*G5)+(H15*H5)+(J15*J5)),2) -> 0 | D15: =HLOOKUP(C15,$Z$24:$AK$25,2) -> F | E15: ='Test Grade'!C15 -> 0 | F15: ='Quiz Grade'!C15 -> 0 | G15: ='Notebook Grade'!C15 -> 0 | H15: ='Homework Grade'!C15 -> 0 | I15: ='Homework Grade'!E15 -> 5 | J15: ='Participation Grade'!C15 -> 0
A16: =Names!$A:$A -> 11 | B16: =Names!$B:$B -> 0 | C16: =ROUND(((E16*E5)+(F16*F5)+(G16*G5)+(H16*H5)+(J16*J5)),2) -> 0 | D16: =HLOOKUP(C16,$Z$24:$AK$25,2) -> F | E16: ='Test Grade'!C16 -> 0 | F16: ='Quiz Grade'!C16 -> 0 | G16: ='Notebook Grade'!C16 -> 0 | H16: ='Homework Grade'!C16 -> 0 | I16: ='Homework Grade'!E16 -> 5 | J16: ='Participation Grade'!C16 -> 0
A17: =Names!$A:$A -> 12 | B17: =Names!$B:$B -> 0 | C17: =ROUND(((E17*E5)+(F17*F5)+(G17*G5)+(H17*H5)+(J17*J5)),2) -> 0 | D17: =HLOOKUP(C17,$Z$24:$AK$25,2) -> F | E17: ='Test Grade'!C17 -> 0 | F17: ='Quiz Grade'!C17 -> 0 | G17: ='Notebook Grade'!C17 -> 0 | H17: ='Homework Grade'!C17 -> 0 | I17: ='Homework Grade'!E17 -> 5 | J17: ='Participation Grade'!C17 -> 0
A18: =Names!$A:$A -> 13 | B18: =Names!$B:$B -> 0 | C18: =ROUND(((E18*E5)+(F18*F5)+(G18*G5)+(H18*H5)+(J18*J5)),2) -> 0 | D18: =HLOOKUP(C18,$Z$24:$AK$25,2) -> F | E18: ='Test Grade'!C18 -> 0 | F18: ='Quiz Grade'!C18 -> 0 | G18: ='Notebook Grade'!C18 -> 0 | H18: ='Homework Grade'!C18 -> 0 | I18: ='Homework Grade'!E18 -> 5 | J18: ='Participation Grade'!C18 -> 0
A19: =Names!$A:$A -> 14 | B19: =Names!$B:$B -> 0 | C19: =ROUND(((E19*E5)+(F19*F5)+(G19*G5)+(H19*H5)+(J19*J5)),2) -> 0 | D19: =HLOOKUP(C19,$Z$24:$AK$25,2) -> F | E19: ='Test Grade'!C19 -> 0 | F19: ='Quiz Grade'!C19 -> 0 | G19: ='Notebook Grade'!C19 -> 0 | H19: ='Homework Grade'!C19 -> 0 | I19: ='Homework Grade'!E19 -> 5 | J19: ='Participation Grade'!C19 -> 0
A20: =Names!$A:$A -> 15 | B20: =Names!$B:$B -> 0 | C20: =ROUND(((E20*E5)+(F20*F5)+(G20*G5)+(H20*H5)+(J20*J5)),2) -> 0 | D20: =HLOOKUP(C20,$Z$24:$AK$25,2) -> F | E20: ='Test Grade'!C20 -> 0 | F20: ='Quiz Grade'!C20 -> 0 | G20: ='Notebook Grade'!C20 -> 0 | H20: ='Homework Grade'!C20 -> 0 | I20: ='Homework Grade'!E20 -> 5 | J20: ='Participation Grade'!C20 -> 0
A21: =Names!$A:$A -> 16 | B21: =Names!$B:$B -> 0 | C21: =ROUND(((E21*E5)+(F21*F5)+(G21*G5)+(H21*H5)+(J21*J5)),2) -> 0 | D21: =HLOOKUP(C21,$Z$24:$AK$25,2) -> F | E21: ='Test Grade'!C21 -> 0 | F21: ='Quiz Grade'!C21 -> 0 | G21: ='Notebook Grade'!C21 -> 0 | H21: ='Homework Grade'!C21 -> 0 | I21: ='Homework Grade'!E21 -> 5 | J21: ='Participation Grade'!C21 -> 0
A22: =Names!$A:$A -> 17 | B22: =Names!$B:$B -> 0 | C22: =ROUND(((E22*E5)+(F22*F5)+(G22*G5)+(H22*H5)+(J22*J5)),2) -> 0 | D22: =HLOOKUP(C22,$Z$24:$AK$25,2) -> F | E22: ='Test Grade'!C22 -> 0 | F22: ='Quiz Grade'!C22 -> 0 | G22: ='Notebook Grade'!C22 -> 0 | H22: ='Homework Grade'!C22 -> 0 | I22: ='Homework Grade'!E22 -> 5 | J22: ='Participation Grade'!C22 -> 0 | Z22: HLookup
A23: =Names!$A:$A -> 18 | B23: =Names!$B:$B -> 0 | C23: =ROUND(((E23*E5)+(F23*F5)+(G23*G5)+(H23*H5)+(J23*J5)),2) -> 0 | D23: =HLOOKUP(C23,$Z$24:$AK$25,2) -> F | E23: ='Test Grade'!C23 -> 0 | F23: ='Quiz Grade'!C23 -> 0 | G23: ='Notebook Grade'!C23 -> 0 | H23: ='Homework Grade'!C23 -> 0 | I23: ='Homework Grade'!E23 -> 5 | J23: ='Participation Grade'!C23 -> 0
A24: =Names!$A:$A -> 19 | B24: =Names!$B:$B -> 0 | C24: =ROUND(((E24*E5)+(F24*F5)+(G24*G5)+(H24*H5)+(J24*J5)),2) -> 0 | D24: =HLOOKUP(C24,$Z$24:$AK$25,2) -> F | E24: ='Test Grade'!C24 -> 0 | F24: ='Quiz Grade'!C24 -> 0 | G24: ='Notebook Grade'!C24 -> 0 | H24: ='Homework Grade'!C24 -> 0 | I24: ='Homework Grade'!E24 -> 5 | J24: ='Participation Grade'!C24 -> 0 | Z24: =Names!W22 -> 0 | AA24: =Names!W21-0.0051 -> 0.6949 | AB24: =Names!W20-0.0051 -> 0.7349 | AC24: =Names!W19-0.0051 -> 0.7649 | AD24: =Names!W18-0.0051 -> 0.7849 | AE24: =Names!W17-0.0051 -> 0.8249 | AF24: =Names!W16-0.0051 -> 0.8449 | AG24: =Names!W15-0.0051 -> 0.8649 | AH24: =Names!W14-0.0051 -> 0.9049 | AI24: =Names!W13-0.0051 -> 0.9249 | AJ24: =Names!W12-0.0051 -> 0.9449 | AK24: =Names!W11-0.0051 -> 0.9849
A25: =Names!$A:$A -> 20 | B25: =Names!$B:$B -> 0 | C25: =ROUND(((E25*E5)+(F25*F5)+(G25*G5)+(H25*H5)+(J25*J5)),2) -> 0 | D25: =HLOOKUP(C25,$Z$24:$AK$25,2) -> F | E25: ='Test Grade'!C25 -> 0 | F25: ='Quiz Grade'!C25 -> 0 | G25: ='Notebook Grade'!C25 -> 0 | H25: ='Homework Grade'!C25 -> 0 | I25: ='Homework Grade'!E25 -> 5 | J25: ='Participation Grade'!C25 -> 0 | Z25: F | AA25: D | AB25: D+ | AC25: C- | AD25: C | AE25: C+ | AF25: B- | AG25: B | AH25: B+ | AI25: A- | AJ25: A | AK25: A+
A26: =Names!$A:$A -> 21 | B26: =Names!$B:$B -> 0 | C26: =ROUND(((E26*E5)+(F26*F5)+(G26*G5)+(H26*H5)+(J26*J5)),2) -> 0 | D26: =HLOOKUP(C26,$Z$24:$AK$25,2) -> F | E26: ='Test Grade'!C26 -> 0 | F26: ='Quiz Grade'!C26 -> 0 | G26: ='Notebook Grade'!C26 -> 0 | H26: ='Homework Grade'!C26 -> 0 | I26: ='Homework Grade'!E26 -> 5 | J26: ='Participation Grade'!C26 -> 0
A27: =Names!$A:$A -> 22 | B27: =Names!$B:$B -> 0 | C27: =ROUND(((E27*E5)+(F27*F5)+(G27*G5)+(H27*H5)+(J27*J5)),2) -> 0 | D27: =HLOOKUP(C27,$Z$24:$AK$25,2) -> F | E27: ='Test Grade'!C27 -> 0 | F27: ='Quiz Grade'!C27 -> 0 | G27: ='Notebook Grade'!C27 -> 0 | H27: ='Homework Grade'!C27 -> 0 | I27: ='Homework Grade'!E27 -> 5 | J27: ='Participation Grade'!C27 -> 0
A28: =Names!$A:$A -> 23 | B28: =Names!$B:$B -> 0 | C28: =ROUND(((E28*E5)+(F28*F5)+(G28*G5)+(H28*H5)+(J28*J5)),2) -> 0 | D28: =HLOOKUP(C28,$Z$24:$AK$25,2) -> F | E28: ='Test Grade'!C28 -> 0 | F28: ='Quiz Grade'!C28 -> 0 | G28: ='Notebook Grade'!C28 -> 0 | H28: ='Homework Grade'!C28 -> 0 | I28: ='Homework Grade'!E28 -> 5 | J28: ='Participation Grade'!C28 -> 0
A29: =Names!$A:$A -> 24 | B29: =Names!$B:$B -> 0 | C29: =ROUND(((E29*E5)+(F29*F5)+(G29*G5)+(H29*H5)+(J29*J5)),2) -> 0 | D29: =HLOOKUP(C29,$Z$24:$AK$25,2) -> F | E29: ='Test Grade'!C29 -> 0 | F29: ='Quiz Grade'!C29 -> 0 | G29: ='Notebook Grade'!C29 -> 0 | H29: ='Homework Grade'!C29 -> 0 | I29: ='Homework Grade'!E29 -> 5 | J29: ='Participation Grade'!C29 -> 0
A30: =Names!$A:$A -> 25 | B30: =Names!$B:$B -> 0 | C30: =ROUND(((E30*E5)+(F30*F5)+(G30*G5)+(H30*H5)+(J30*J5)),2) -> 0 | D30: =HLOOKUP(C30,$Z$24:$AK$25,2) -> F | E30: ='Test Grade'!C30 -> 0 | F30: ='Quiz Grade'!C30 -> 0 | G30: ='Notebook Grade'!C30 -> 0 | H30: ='Homework Grade'!C30 -> 0 | I30: ='Homework Grade'!E30 -> 5 | J30: ='Participation Grade'!C30 -> 0
A31: =Names!$A:$A -> 26 | B31: =Names!$B:$B -> 0 | C31: =ROUND(((E31*E5)+(F31*F5)+(G31*G5)+(H31*H5)+(J31*J5)),2) -> 0 | D31: =HLOOKUP(C31,$Z$24:$AK$25,2) -> F | E31: ='Test Grade'!C31 -> 0 | F31: ='Quiz Grade'!C31 -> 0 | G31: ='Notebook Grade'!C31 -> 0 | H31: ='Homework Grade'!C31 -> 0 | I31: ='Homework Grade'!E31 -> 5 | J31: ='Participation Grade'!C31 -> 0
A32: =Names!$A:$A -> 27 | B32: =Names!$B:$B -> 0 | C32: =ROUND(((E32*E5)+(F32*F5)+(G32*G5)+(H32*H5)+(J32*J5)),2) -> 0 | D32: =HLOOKUP(C32,$Z$24:$AK$25,2) -> F | E32: ='Test Grade'!C32 -> 0 | F32: ='Quiz Grade'!C32 -> 0 | G32: ='Notebook Grade'!C32 -> 0 | H32: ='Homework Grade'!C32 -> 0 | I32: ='Homework Grade'!E32 -> 5 | J32: ='Participation Grade'!C32 -> 0
A33: =Names!$A:$A -> 28 | B33: =Names!$B:$B -> 0 | C33: =ROUND(((E33*E5)+(F33*F5)+(G33*G5)+(H33*H5)+(J33*J5)),2) -> 0 | D33: =HLOOKUP(C33,$Z$24:$AK$25,2) -> F | E33: ='Test Grade'!C33 -> 0 | F33: ='Quiz Grade'!C33 -> 0 | G33: ='Notebook Grade'!C33 -> 0 | H33: ='Homework Grade'!C33 -> 0 | I33: ='Homework Grade'!E33 -> 5 | J33: ='Participation Grade'!C33 -> 0
A34: =Names!$A:$A -> 29 | B34: =Names!$B:$B -> 0 | C34: =ROUND(((E34*E5)+(F34*F5)+(G34*G5)+(H34*H5)+(J34*J5)),2) -> 0 | D34: =HLOOKUP(C34,$Z$24:$AK$25,2) -> F | E34: ='Test Grade'!C34 -> 0 | F34: ='Quiz Grade'!C34 -> 0 | G34: ='Notebook Grade'!C34 -> 0 | H34: ='Homework Grade'!C34 -> 0 | I34: ='Homework Grade'!E34 -> 5 | J34: ='Participation Grade'!C34 -> 0
A35: =Names!$A:$A -> 30 | B35: =Names!$B:$B -> 0 | C35: =ROUND(((E35*E5)+(F35*F5)+(G35*G5)+(H35*H5)+(J35*J5)),2) -> 0 | D35: =HLOOKUP(C35,$Z$24:$AK$25,2) -> F | E35: ='Test Grade'!C35 -> 0 | F35: ='Quiz Grade'!C35 -> 0 | G35: ='Notebook Grade'!C35 -> 0 | H35: ='Homework Grade'!C35 -> 0 | I35: ='Homework Grade'!E35 -> 5 | J35: ='Participation Grade'!C35 -> 0
A36: =Names!$A:$A -> 31 | B36: =Names!$B:$B -> 0 | C36: =ROUND(((E36*E5)+(F36*F5)+(G36*G5)+(H36*H5)+(J36*J5)),2) -> 0 | D36: =HLOOKUP(C36,$Z$24:$AK$25,2) -> F | E36: ='Test Grade'!C36 -> 0 | F36: ='Quiz Grade'!C36 -> 0 | G36: ='Notebook Grade'!C36 -> 0 | H36: ='Homework Grade'!C36 -> 0 | I36: ='Homework Grade'!E36 -> 5 | J36: ='Participation Grade'!C36 -> 0
A37: =Names!$A:$A -> 32 | B37: =Names!$B:$B -> 0 | C37: =ROUND(((E37*E5)+(F37*F5)+(G37*G5)+(H37*H5)+(J37*J5)),2) -> 0 | D37: =HLOOKUP(C37,$Z$24:$AK$25,2) -> F | E37: ='Test Grade'!C37 -> 0 | F37: ='Quiz Grade'!C37 -> 0 | G37: ='Notebook Grade'!C37 -> 0 | H37: ='Homework Grade'!C37 -> 0 | I37: ='Homework Grade'!E37 -> 5 | J37: ='Participation Grade'!C37 -> 0
A38: =Names!$A:$A -> 33 | B38: =Names!$B:$B -> 0 | C38: =ROUND(((E38*E5)+(F38*F5)+(G38*G5)+(H38*H5)+(J38*J5)),2) -> 0 | D38: =HLOOKUP(C38,$Z$24:$AK$25,2) -> F | E38: ='Test Grade'!C38 -> 0 | F38: ='Quiz Grade'!C38 -> 0 | G38: ='Notebook Grade'!C38 -> 0 | H38: ='Homework Grade'!C38 -> 0 | I38: ='Homework Grade'!E38 -> 5 | J38: ='Participation Grade'!C38 -> 0
A39: =Names!$A:$A -> 34 | B39: =Names!$B:$B -> 0 | C39: =ROUND(((E39*E5)+(F39*F5)+(G39*G5)+(H39*H5)+(J39*J5)),2) -> 0 | D39: =HLOOKUP(C39,$Z$24:$AK$25,2) -> F | E39: ='Test Grade'!C39 -> 0 | F39: ='Quiz Grade'!C39 -> 0 | G39: ='Notebook Grade'!C39 -> 0 | H39: ='Homework Grade'!C39 -> 0 | I39: ='Homework Grade'!E39 -> 5 | J39: ='Participation Grade'!C39 -> 0
A40: =Names!$A:$A -> 35 | B40: =Names!$B:$B -> 0 | C40: =ROUND(((E40*E5)+(F40*F5)+(G40*G5)+(H40*H5)+(J40*J5)),2) -> 0 | D40: =HLOOKUP(C40,$Z$24:$AK$25,2) -> F | E40: ='Test Grade'!C40 -> 0 | F40: ='Quiz Grade'!C40 -> 0 | G40: ='Notebook Grade'!C40 -> 0 | H40: ='Homework Grade'!C40 -> 0 | I40: ='Homework Grade'!E40 -> 5 | J40: ='Participation Grade'!C40 -> 0
...

Sheet Test Grade
B1: =Names!B1 -> Quarter 1
B2: =Names!B2 -> Class
B3: =Names!C1 -> Test Grade | C3: =Names!C2 -> 0.5 | D3: Date
C4: Percentage | D4: Total points | E4: Test 1 | F4: test 2 | G4: etc.
A5: =Names!$A:$A -> # | B5: =Names!$B:$B -> Last Name, First Name | C5: 1 | D5: =SUM(E5:IV5)+0.001 -> 200.001 | E5: 100 | F5: 100
A6: =Names!$A:$A -> 1 | B6: =Names!$B:$B -> Adams, Bob | C6: =D6/D5 -> 0.96499518 | D6: =SUM(E6:IV6) -> 193 | E6: 98 | F6: 95
A7: =Names!$A:$A -> 2 | B7: =Names!$B:$B -> Jones, George | C7: =D7/D5 -> 0.90499548 | D7: =SUM(E7:IV7) -> 181 | E7: 95 | F7: 86
A8: =Names!$A:$A -> 3 | B8: =Names!$B:$B -> Smith, Ralph | C8: =D8/D5 -> 0.96999515 | D8: =SUM(E8:IV8) -> 194 | E8: 97 | F8: 97
A9: =Names!$A:$A -> 4 | B9: =Names!$B:$B -> 0 | C9: =D9/D5 -> 0 | D9: =SUM(E9:IV9) -> 0
A10: =Names!$A:$A -> 5 | B10: =Names!$B:$B -> 0 | C10: =D10/D5 -> 0 | D10: =SUM(E10:IV10) -> 0
A11: =Names!$A:$A -> 6 | B11: =Names!$B:$B -> 0 | C11: =D11/D5 -> 0 | D11: =SUM(E11:IV11) -> 0
A12: =Names!$A:$A -> 7 | B12: =Names!$B:$B -> 0 | C12: =D12/D5 -> 0 | D12: =SUM(E12:IV12) -> 0
A13: =Names!$A:$A -> 8 | B13: =Names!$B:$B -> 0 | C13: =D13/D5 -> 0 | D13: =SUM(E13:IV13) -> 0
A14: =Names!$A:$A -> 9 | B14: =Names!$B:$B -> 0 | C14: =D14/D5 -> 0 | D14: =SUM(E14:IV14) -> 0
A15: =Names!$A:$A -> 10 | B15: =Names!$B:$B -> 0 | C15: =D15/D5 -> 0 | D15: =SUM(E15:IV15) -> 0
A16: =Names!$A:$A -> 11 | B16: =Names!$B:$B -> 0 | C16: =D16/D5 -> 0 | D16: =SUM(E16:IV16) -> 0
A17: =Names!$A:$A -> 12 | B17: =Names!$B:$B -> 0 | C17: =D17/D5 -> 0 | D17: =SUM(E17:IV17) -> 0
A18: =Names!$A:$A -> 13 | B18: =Names!$B:$B -> 0 | C18: =D18/D5 -> 0 | D18: =SUM(E18:IV18) -> 0
A19: =Names!$A:$A -> 14 | B19: =Names!$B:$B -> 0 | C19: =D19/D5 -> 0 | D19: =SUM(E19:IV19) -> 0
A20: =Names!$A:$A -> 15 | B20: =Names!$B:$B -> 0 | C20: =D20/D5 -> 0 | D20: =SUM(E20:IV20) -> 0
A21: =Names!$A:$A -> 16 | B21: =Names!$B:$B -> 0 | C21: =D21/D5 -> 0 | D21: =SUM(E21:IV21) -> 0
A22: =Names!$A:$A -> 17 | B22: =Names!$B:$B -> 0 | C22: =D22/D5 -> 0 | D22: =SUM(E22:IV22) -> 0
A23: =Names!$A:$A -> 18 | B23: =Names!$B:$B -> 0 | C23: =D23/D5 -> 0 | D23: =SUM(E23:IV23) -> 0
A24: =Names!$A:$A -> 19 | B24: =Names!$B:$B -> 0 | C24: =D24/D5 -> 0 | D24: =SUM(E24:IV24) -> 0
A25: =Names!$A:$A -> 20 | B25: =Names!$B:$B -> 0 | C25: =D25/D5 -> 0 | D25: =SUM(E25:IV25) -> 0
A26: =Names!$A:$A -> 21 | B26: =Names!$B:$B -> 0 | C26: =D26/D5 -> 0 | D26: =SUM(E26:IV26) -> 0
A27: =Names!$A:$A -> 22 | B27: =Names!$B:$B -> 0 | C27: =D27/D5 -> 0 | D27: =SUM(E27:IV27) -> 0
A28: =Names!$A:$A -> 23 | B28: =Names!$B:$B -> 0 | C28: =D28/D5 -> 0 | D28: =SUM(E28:IV28) -> 0
A29: =Names!$A:$A -> 24 | B29: =Names!$B:$B -> 0 | C29: =D29/D5 -> 0 | D29: =SUM(E29:IV29) -> 0
A30: =Names!$A:$A -> 25 | B30: =Names!$B:$B -> 0 | C30: =D30/D5 -> 0 | D30: =SUM(E30:IV30) -> 0
A31: =Names!$A:$A -> 26 | B31: =Names!$B:$B -> 0 | C31: =D31/D5 -> 0 | D31: =SUM(E31:IV31) -> 0
A32: =Names!$A:$A -> 27 | B32: =Names!$B:$B -> 0 | C32: =D32/D5 -> 0 | D32: =SUM(E32:IV32) -> 0
A33: =Names!$A:$A -> 28 | B33: =Names!$B:$B -> 0 | C33: =D33/D5 -> 0 | D33: =SUM(E33:IV33) -> 0
A34: =Names!$A:$A -> 29 | B34: =Names!$B:$B -> 0 | C34: =D34/D5 -> 0 | D34: =SUM(E34:IV34) -> 0
A35: =Names!$A:$A -> 30 | B35: =Names!$B:$B -> 0 | C35: =D35/D5 -> 0 | D35: =SUM(E35:IV35) -> 0
A36: =Names!$A:$A -> 31 | B36: =Names!$B:$B -> 0 | C36: =D36/D5 -> 0 | D36: =SUM(E36:IV36) -> 0
A37: =Names!$A:$A -> 32 | B37: =Names!$B:$B -> 0 | C37: =D37/D5 -> 0 | D37: =SUM(E37:IV37) -> 0
A38: =Names!$A:$A -> 33 | B38: =Names!$B:$B -> 0 | C38: =D38/D5 -> 0 | D38: =SUM(E38:IV38) -> 0
A39: =Names!$A:$A -> 34 | B39: =Names!$B:$B -> 0 | C39: =D39/D5 -> 0 | D39: =SUM(E39:IV39) -> 0
A40: =Names!$A:$A -> 35 | B40: =Names!$B:$B -> 0 | C40: =D40/D5 -> 0 | D40: =SUM(E40:IV40) -> 0

Sheet Quiz Grade
B1: =Names!B1 -> Quarter 1
B2: =Names!B2 -> Class
B3: =Names!D1 -> Quiz Grade | C3: =Names!D2 -> 0.2 | D3: Date
C4: Percentage | D4: Total points | E4: quiz 1 | F4: quiz 2 | G4: etc.
A5: =Names!$A:$A -> # | B5: =Names!$B:$B -> Last Name, First Name | C5: 1 | D5: =SUM(E5:IV5)+0.001 -> 70.001 | E5: 20 | F5: 50
A6: =Names!$A:$A -> 1 | B6: =Names!$B:$B -> Adams, Bob | C6: =D6/D5 -> 0.92855816 | D6: =SUM(E6:IV6) -> 65 | E6: 20 | F6: 45
A7: =Names!$A:$A -> 2 | B7: =Names!$B:$B -> Jones, George | C7: =D7/D5 -> 0.97141469 | D7: =SUM(E7:IV7) -> 68 | E7: 18 | F7: 50
A8: =Names!$A:$A -> 3 | B8: =Names!$B:$B -> Smith, Ralph | C8: =D8/D5 -> 0.97141469 | D8: =SUM(E8:IV8) -> 68 | E8: 19 | F8: 49
A9: =Names!$A:$A -> 4 | B9: =Names!$B:$B -> 0 | C9: =D9/D5 -> 0 | D9: =SUM(E9:IV9) -> 0
A10: =Names!$A:$A -> 5 | B10: =Names!$B:$B -> 0 | C10: =D10/D5 -> 0 | D10: =SUM(E10:IV10) -> 0
A11: =Names!$A:$A -> 6 | B11: =Names!$B:$B -> 0 | C11: =D11/D5 -> 0 | D11: =SUM(E11:IV11) -> 0
A12: =Names!$A:$A -> 7 | B12: =Names!$B:$B -> 0 | C12: =D12/D5 -> 0 | D12: =SUM(E12:IV12) -> 0
A13: =Names!$A:$A -> 8 | B13: =Names!$B:$B -> 0 | C13: =D13/D5 -> 0 | D13: =SUM(E13:IV13) -> 0
A14: =Names!$A:$A -> 9 | B14: =Names!$B:$B -> 0 | C14: =D14/D5 -> 0 | D14: =SUM(E14:IV14) -> 0
A15: =Names!$A:$A -> 10 | B15: =Names!$B:$B -> 0 | C15: =D15/D5 -> 0 | D15: =SUM(E15:IV15) -> 0
A16: =Names!$A:$A -> 11 | B16: =Names!$B:$B -> 0 | C16: =D16/D5 -> 0 | D16: =SUM(E16:IV16) -> 0
A17: =Names!$A:$A -> 12 | B17: =Names!$B:$B -> 0 | C17: =D17/D5 -> 0 | D17: =SUM(E17:IV17) -> 0
A18: =Names!$A:$A -> 13 | B18: =Names!$B:$B -> 0 | C18: =D18/D5 -> 0 | D18: =SUM(E18:IV18) -> 0
A19: =Names!$A:$A -> 14 | B19: =Names!$B:$B -> 0 | C19: =D19/D5 -> 0 | D19: =SUM(E19:IV19) -> 0
A20: =Names!$A:$A -> 15 | B20: =Names!$B:$B -> 0 | C20: =D20/D5 -> 0 | D20: =SUM(E20:IV20) -> 0
A21: =Names!$A:$A -> 16 | B21: =Names!$B:$B -> 0 | C21: =D21/D5 -> 0 | D21: =SUM(E21:IV21) -> 0
A22: =Names!$A:$A -> 17 | B22: =Names!$B:$B -> 0 | C22: =D22/D5 -> 0 | D22: =SUM(E22:IV22) -> 0
A23: =Names!$A:$A -> 18 | B23: =Names!$B:$B -> 0 | C23: =D23/D5 -> 0 | D23: =SUM(E23:IV23) -> 0
A24: =Names!$A:$A -> 19 | B24: =Names!$B:$B -> 0 | C24: =D24/D5 -> 0 | D24: =SUM(E24:IV24) -> 0
A25: =Names!$A:$A -> 20 | B25: =Names!$B:$B -> 0 | C25: =D25/D5 -> 0 | D25: =SUM(E25:IV25) -> 0
A26: =Names!$A:$A -> 21 | B26: =Names!$B:$B -> 0 | C26: =D26/D5 -> 0 | D26: =SUM(E26:IV26) -> 0
A27: =Names!$A:$A -> 22 | B27: =Names!$B:$B -> 0 | C27: =D27/D5 -> 0 | D27: =SUM(E27:IV27) -> 0
A28: =Names!$A:$A -> 23 | B28: =Names!$B:$B -> 0 | C28: =D28/D5 -> 0 | D28: =SUM(E28:IV28) -> 0
A29: =Names!$A:$A -> 24 | B29: =Names!$B:$B -> 0 | C29: =D29/D5 -> 0 | D29: =SUM(E29:IV29) -> 0
A30: =Names!$A:$A -> 25 | B30: =Names!$B:$B -> 0 | C30: =D30/D5 -> 0 | D30: =SUM(E30:IV30) -> 0
A31: =Names!$A:$A -> 26 | B31: =Names!$B:$B -> 0 | C31: =D31/D5 -> 0 | D31: =SUM(E31:IV31) -> 0
A32: =Names!$A:$A -> 27 | B32: =Names!$B:$B -> 0 | C32: =D32/D5 -> 0 | D32: =SUM(E32:IV32) -> 0
A33: =Names!$A:$A -> 28 | B33: =Names!$B:$B -> 0 | C33: =D33/D5 -> 0 | D33: =SUM(E33:IV33) -> 0
A34: =Names!$A:$A -> 29 | B34: =Names!$B:$B -> 0 | C34: =D34/D5 -> 0 | D34: =SUM(E34:IV34) -> 0
A35: =Names!$A:$A -> 30 | B35: =Names!$B:$B -> 0 | C35: =D35/D5 -> 0 | D35: =SUM(E35:IV35) -> 0
A36: =Names!$A:$A -> 31 | B36: =Names!$B:$B -> 0 | C36: =D36/D5 -> 0 | D36: =SUM(E36:IV36) -> 0
A37: =Names!$A:$A -> 32 | B37: =Names!$B:$B -> 0 | C37: =D37/D5 -> 0 | D37: =SUM(E37:IV37) -> 0
A38: =Names!$A:$A -> 33 | B38: =Names!$B:$B -> 0 | C38: =D38/D5 -> 0 | D38: =SUM(E38:IV38) -> 0
A39: =Names!$A:$A -> 34 | B39: =Names!$B:$B -> 0 | C39: =D39/D5 -> 0 | D39: =SUM(E39:IV39) -> 0
A40: =Names!$A:$A -> 35 | B40: =Names!$B:$B -> 0 | C40: =D40/D5 -> 0 | D40: =SUM(E40:IV40) -> 0

Sheet Notebook Grade
B1: =Names!B1 -> Quarter 1
B2: =Names!B2 -> Class
B3: =Names!E1 -> Notebook Grade | C3: =Names!E2 -> 0.1
C4: Percentage | D4: Total points | E4: Notebook check one | F4: Notebook check two
A5: =Names!$A:$A -> # | B5: =Names!$B:$B -> Last Name, First Name | C5: 1 | D5: =SUM(E5:IV5)+0.001 -> 20.001 | E5: 10 | F5: 10
A6: =Names!$A:$A -> 1 | B6: =Names!$B:$B -> Adams, Bob | C6: =D6/D5 -> 0.9499525 | D6: =SUM(E6:IV6) -> 19 | E6: 10 | F6: 9
A7: =Names!$A:$A -> 2 | B7: =Names!$B:$B -> Jones, George | C7: =D7/D5 -> 0.99995 | D7: =SUM(E7:IV7) -> 20 | E7: 10 | F7: 10
A8: =Names!$A:$A -> 3 | B8: =Names!$B:$B -> Smith, Ralph | C8: =D8/D5 -> 0.99995 | D8: =SUM(E8:IV8) -> 20 | E8: 10 | F8: 10
A9: =Names!$A:$A -> 4 | B9: =Names!$B:$B -> 0 | C9: =D9/D5 -> 0 | D9: =SUM(E9:IV9) -> 0
A10: =Names!$A:$A -> 5 | B10: =Names!$B:$B -> 0 | C10: =D10/D5 -> 0 | D10: =SUM(E10:IV10) -> 0
A11: =Names!$A:$A -> 6 | B11: =Names!$B:$B -> 0 | C11: =D11/D5 -> 0 | D11: =SUM(E11:IV11) -> 0
A12: =Names!$A:$A -> 7 | B12: =Names!$B:$B -> 0 | C12: =D12/D5 -> 0 | D12: =SUM(E12:IV12) -> 0
A13: =Names!$A:$A -> 8 | B13: =Names!$B:$B -> 0 | C13: =D13/D5 -> 0 | D13: =SUM(E13:IV13) -> 0
A14: =Names!$A:$A -> 9 | B14: =Names!$B:$B -> 0 | C14: =D14/D5 -> 0 | D14: =SUM(E14:IV14) -> 0
A15: =Names!$A:$A -> 10 | B15: =Names!$B:$B -> 0 | C15: =D15/D5 -> 0 | D15: =SUM(E15:IV15) -> 0
A16: =Names!$A:$A -> 11 | B16: =Names!$B:$B -> 0 | C16: =D16/D5 -> 0 | D16: =SUM(E16:IV16) -> 0
A17: =Names!$A:$A -> 12 | B17: =Names!$B:$B -> 0 | C17: =D17/D5 -> 0 | D17: =SUM(E17:IV17) -> 0
A18: =Names!$A:$A -> 13 | B18: =Names!$B:$B -> 0 | C18: =D18/D5 -> 0 | D18: =SUM(E18:IV18) -> 0
A19: =Names!$A:$A -> 14 | B19: =Names!$B:$B -> 0 | C19: =D19/D5 -> 0 | D19: =SUM(E19:IV19) -> 0
A20: =Names!$A:$A -> 15 | B20: =Names!$B:$B -> 0 | C20: =D20/D5 -> 0 | D20: =SUM(E20:IV20) -> 0
A21: =Names!$A:$A -> 16 | B21: =Names!$B:$B -> 0 | C21: =D21/D5 -> 0 | D21: =SUM(E21:IV21) -> 0
A22: =Names!$A:$A -> 17 | B22: =Names!$B:$B -> 0 | C22: =D22/D5 -> 0 | D22: =SUM(E22:IV22) -> 0
A23: =Names!$A:$A -> 18 | B23: =Names!$B:$B -> 0 | C23: =D23/D5 -> 0 | D23: =SUM(E23:IV23) -> 0
A24: =Names!$A:$A -> 19 | B24: =Names!$B:$B -> 0 | C24: =D24/D5 -> 0 | D24: =SUM(E24:IV24) -> 0
A25: =Names!$A:$A -> 20 | B25: =Names!$B:$B -> 0 | C25: =D25/D5 -> 0 | D25: =SUM(E25:IV25) -> 0
A26: =Names!$A:$A -> 21 | B26: =Names!$B:$B -> 0 | C26: =D26/D5 -> 0 | D26: =SUM(E26:IV26) -> 0
A27: =Names!$A:$A -> 22 | B27: =Names!$B:$B -> 0 | C27: =D27/D5 -> 0 | D27: =SUM(E27:IV27) -> 0
A28: =Names!$A:$A -> 23 | B28: =Names!$B:$B -> 0 | C28: =D28/D5 -> 0 | D28: =SUM(E28:IV28) -> 0
A29: =Names!$A:$A -> 24 | B29: =Names!$B:$B -> 0 | C29: =D29/D5 -> 0 | D29: =SUM(E29:IV29) -> 0
A30: =Names!$A:$A -> 25 | B30: =Names!$B:$B -> 0 | C30: =D30/D5 -> 0 | D30: =SUM(E30:IV30) -> 0
A31: =Names!$A:$A -> 26 | B31: =Names!$B:$B -> 0 | C31: =D31/D5 -> 0 | D31: =SUM(E31:IV31) -> 0
A32: =Names!$A:$A -> 27 | B32: =Names!$B:$B -> 0 | C32: =D32/D5 -> 0 | D32: =SUM(E32:IV32) -> 0
A33: =Names!$A:$A -> 28 | B33: =Names!$B:$B -> 0 | C33: =D33/D5 -> 0 | D33: =SUM(E33:IV33) -> 0
A34: =Names!$A:$A -> 29 | B34: =Names!$B:$B -> 0 | C34: =D34/D5 -> 0 | D34: =SUM(E34:IV34) -> 0
A35: =Names!$A:$A -> 30 | B35: =Names!$B:$B -> 0 | C35: =D35/D5 -> 0 | D35: =SUM(E35:IV35) -> 0
A36: =Names!$A:$A -> 31 | B36: =Names!$B:$B -> 0 | C36: =D36/D5 -> 0 | D36: =SUM(E36:IV36) -> 0
A37: =Names!$A:$A -> 32 | B37: =Names!$B:$B -> 0 | C37: =D37/D5 -> 0 | D37: =SUM(E37:IV37) -> 0
A38: =Names!$A:$A -> 33 | B38: =Names!$B:$B -> 0 | C38: =D38/D5 -> 0 | D38: =SUM(E38:IV38) -> 0
A39: =Names!$A:$A -> 34 | B39: =Names!$B:$B -> 0 | C39: =D39/D5 -> 0 | D39: =SUM(E39:IV39) -> 0
A40: =Names!$A:$A -> 35 | B40: =Names!$B:$B -> 0 | C40: =D40/D5 -> 0 | D40: =SUM(E40:IV40) -> 0

Sheet Homework Grade
B1: =Names!B1 -> Quarter 1
B2: =Names!B2 -> Class | F2: m | G2: t | H2: w | I2: th | J2: f | K2: m | L2: t | M2: w | N2: th | O2: f | P2: m | Q2: t | R2: w | S2: th | T2: f | U2: m | V2: t | W2: w | X2: th | Y2: f | Z2: m | AA2: t | AB2: w | AC2: th | AD2: f | AE2: m | AF2: t | AG2: w | AH2: th | AI2: f | AJ2: m | AK2: t | AL2: w | AM2: th | AN2: f | AO2: m | AP2: t | AQ2: w | AR2: th | AS2: f | AT2: m | AU2: t | AV2: w | AW2: th | AX2: f
B3: =Names!F1 -> Homework Grade | C3: =Names!F2 -> 0.15 | D3: Date
C4: Percent | D4: Total points | E4: # of missing assignments | F4: assignment 1 | G4: assignment 2 | H4: assignment 3 | I4: assignment 4 | J4: assignment 5
A5: =Names!$A:$A -> # | B5: =Names!$B:$B -> Last Name, First Name | C5: 1 | D5: =SUM(F5:IV5)+0.001 -> 30.001 | E5: =(COUNT(F5:AS5)) -> 5 | F5: 5 | G5: 10 | H5: 5 | I5: 5 | J5: 5
A6: =Names!$A:$A -> 1 | B6: =Names!$B:$B -> Adams, Bob | C6: =D6/D5 -> 0.83330556 | D6: =SUM(F6:IV6) -> 25 | E6: =E5-(COUNT(F6:AS6)) -> 1 | F6: 5 | G6: 10 | H6: 5 | I6: 5
A7: =Names!$A:$A -> 2 | B7: =Names!$B:$B -> Jones, George | C7: =D7/D5 -> 0.66664445 | D7: =SUM(F7:IV7) -> 20 | E7: =E5-(COUNT(F7:AS7)) -> 2 | F7: 5 | G7: 10 | H7: 5
A8: =Names!$A:$A -> 3 | B8: =Names!$B:$B -> Smith, Ralph | C8: =D8/D5 -> 0.99996667 | D8: =SUM(F8:IV8) -> 30 | E8: =E5-(COUNT(F8:AS8)) -> 0 | F8: 5 | G8: 10 | H8: 5 | I8: 5 | J8: 5
A9: =Names!$A:$A -> 4 | B9: =Names!$B:$B -> 0 | C9: =D9/D5 -> 0 | D9: =SUM(F9:IV9) -> 0 | E9: =E5-(COUNT(F9:AS9)) -> 5
A10: =Names!$A:$A -> 5 | B10: =Names!$B:$B -> 0 | C10: =D10/D5 -> 0 | D10: =SUM(F10:IV10) -> 0 | E10: =E5-(COUNT(F10:AS10)) -> 5
A11: =Names!$A:$A -> 6 | B11: =Names!$B:$B -> 0 | C11: =D11/D5 -> 0 | D11: =SUM(F11:IV11) -> 0 | E11: =E5-(COUNT(F11:AS11)) -> 5
A12: =Names!$A:$A -> 7 | B12: =Names!$B:$B -> 0 | C12: =D12/D5 -> 0 | D12: =SUM(F12:IV12) -> 0 | E12: =E5-(COUNT(F12:AS12)) -> 5
A13: =Names!$A:$A -> 8 | B13: =Names!$B:$B -> 0 | C13: =D13/D5 -> 0 | D13: =SUM(F13:IV13) -> 0 | E13: =E5-(COUNT(F13:AS13)) -> 5
A14: =Names!$A:$A -> 9 | B14: =Names!$B:$B -> 0 | C14: =D14/D5 -> 0 | D14: =SUM(F14:IV14) -> 0 | E14: =E5-(COUNT(F14:AS14)) -> 5
A15: =Names!$A:$A -> 10 | B15: =Names!$B:$B -> 0 | C15: =D15/D5 -> 0 | D15: =SUM(F15:IV15) -> 0 | E15: =E5-(COUNT(F15:AS15)) -> 5
A16: =Names!$A:$A -> 11 | B16: =Names!$B:$B -> 0 | C16: =D16/D5 -> 0 | D16: =SUM(F16:IV16) -> 0 | E16: =E5-(COUNT(F16:AS16)) -> 5
A17: =Names!$A:$A -> 12 | B17: =Names!$B:$B -> 0 | C17: =D17/D5 -> 0 | D17: =SUM(F17:IV17) -> 0 | E17: =E5-(COUNT(F17:AS17)) -> 5
A18: =Names!$A:$A -> 13 | B18: =Names!$B:$B -> 0 | C18: =D18/D5 -> 0 | D18: =SUM(F18:IV18) -> 0 | E18: =E5-(COUNT(F18:AS18)) -> 5
A19: =Names!$A:$A -> 14 | B19: =Names!$B:$B -> 0 | C19: =D19/D5 -> 0 | D19: =SUM(F19:IV19) -> 0 | E19: =E5-(COUNT(F19:AS19)) -> 5
A20: =Names!$A:$A -> 15 | B20: =Names!$B:$B -> 0 | C20: =D20/D5 -> 0 | D20: =SUM(F20:IV20) -> 0 | E20: =E5-(COUNT(F20:AS20)) -> 5
A21: =Names!$A:$A -> 16 | B21: =Names!$B:$B -> 0 | C21: =D21/D5 -> 0 | D21: =SUM(F21:IV21) -> 0 | E21: =E5-(COUNT(F21:AS21)) -> 5
A22: =Names!$A:$A -> 17 | B22: =Names!$B:$B -> 0 | C22: =D22/D5 -> 0 | D22: =SUM(F22:IV22) -> 0 | E22: =E5-(COUNT(F22:AS22)) -> 5
A23: =Names!$A:$A -> 18 | B23: =Names!$B:$B -> 0 | C23: =D23/D5 -> 0 | D23: =SUM(F23:IV23) -> 0 | E23: =E5-(COUNT(F23:AS23)) -> 5
A24: =Names!$A:$A -> 19 | B24: =Names!$B:$B -> 0 | C24: =D24/D5 -> 0 | D24: =SUM(F24:IV24) -> 0 | E24: =E5-(COUNT(F24:AS24)) -> 5
A25: =Names!$A:$A -> 20 | B25: =Names!$B:$B -> 0 | C25: =D25/D5 -> 0 | D25: =SUM(F25:IV25) -> 0 | E25: =E5-(COUNT(F25:AS25)) -> 5
A26: =Names!$A:$A -> 21 | B26: =Names!$B:$B -> 0 | C26: =D26/D5 -> 0 | D26: =SUM(F26:IV26) -> 0 | E26: =E5-(COUNT(F26:AS26)) -> 5
A27: =Names!$A:$A -> 22 | B27: =Names!$B:$B -> 0 | C27: =D27/D5 -> 0 | D27: =SUM(F27:IV27) -> 0 | E27: =E5-(COUNT(F27:AS27)) -> 5
A28: =Names!$A:$A -> 23 | B28: =Names!$B:$B -> 0 | C28: =D28/D5 -> 0 | D28: =SUM(F28:IV28) -> 0 | E28: =E5-(COUNT(F28:AS28)) -> 5
A29: =Names!$A:$A -> 24 | B29: =Names!$B:$B -> 0 | C29: =D29/D5 -> 0 | D29: =SUM(F29:IV29) -> 0 | E29: =E5-(COUNT(F29:AS29)) -> 5
A30: =Names!$A:$A -> 25 | B30: =Names!$B:$B -> 0 | C30: =D30/D5 -> 0 | D30: =SUM(F30:IV30) -> 0 | E30: =E5-(COUNT(F30:AS30)) -> 5
A31: =Names!$A:$A -> 26 | B31: =Names!$B:$B -> 0 | C31: =D31/D5 -> 0 | D31: =SUM(F31:IV31) -> 0 | E31: =E5-(COUNT(F31:AS31)) -> 5
A32: =Names!$A:$A -> 27 | B32: =Names!$B:$B -> 0 | C32: =D32/D5 -> 0 | D32: =SUM(F32:IV32) -> 0 | E32: =E5-(COUNT(F32:AS32)) -> 5
A33: =Names!$A:$A -> 28 | B33: =Names!$B:$B -> 0 | C33: =D33/D5 -> 0 | D33: =SUM(F33:IV33) -> 0 | E33: =E5-(COUNT(F33:AS33)) -> 5
A34: =Names!$A:$A -> 29 | B34: =Names!$B:$B -> 0 | C34: =D34/D5 -> 0 | D34: =SUM(F34:IV34) -> 0 | E34: =E5-(COUNT(F34:AS34)) -> 5
A35: =Names!$A:$A -> 30 | B35: =Names!$B:$B -> 0 | C35: =D35/D5 -> 0 | D35: =SUM(F35:IV35) -> 0 | E35: =E5-(COUNT(F35:AS35)) -> 5
A36: =Names!$A:$A -> 31 | B36: =Names!$B:$B -> 0 | C36: =D36/D5 -> 0 | D36: =SUM(F36:IV36) -> 0 | E36: =E5-(COUNT(F36:AS36)) -> 5
A37: =Names!$A:$A -> 32 | B37: =Names!$B:$B -> 0 | C37: =D37/D5 -> 0 | D37: =SUM(F37:IV37) -> 0 | E37: =E5-(COUNT(F37:AS37)) -> 5
A38: =Names!$A:$A -> 33 | B38: =Names!$B:$B -> 0 | C38: =D38/D5 -> 0 | D38: =SUM(F38:IV38) -> 0 | E38: =E5-(COUNT(F38:AS38)) -> 5
A39: =Names!$A:$A -> 34 | B39: =Names!$B:$B -> 0 | C39: =D39/D5 -> 0 | D39: =SUM(F39:IV39) -> 0 | E39: =E5-(COUNT(F39:AS39)) -> 5
A40: =Names!$A:$A -> 35 | B40: =Names!$B:$B -> 0 | C40: =D40/D5 -> 0 | D40: =SUM(F40:IV40) -> 0 | E40: =E5-(COUNT(F40:AS40)) -> 5

Sheet Participation Grade
B1: =Names!B1 -> Quarter 1
B2: =Names!B2 -> Class
B3: =Names!G1 -> Participation Grade | C3: =Names!G2 -> 0.05
C4: Percentage | D4: Total points | E4: prog report 1 | F4: Report card
A5: =Names!$A:$A -> # | B5: =Names!$B:$B -> Last Name, First Name | C5: 1 | D5: =SUM(E5:IV5)+0.001 -> 5.001 | E5: 5
A6: =Names!$A:$A -> 1 | B6: =Names!$B:$B -> Adams, Bob | C6: =D6/D5 -> 0.99980004 | D6: =SUM(E6:IV6) -> 5 | E6: 5
A7: =Names!$A:$A -> 2 | B7: =Names!$B:$B -> Jones, George | C7: =D7/D5 -> 0.79984003 | D7: =SUM(E7:IV7) -> 4 | E7: 4
A8: =Names!$A:$A -> 3 | B8: =Names!$B:$B -> Smith, Ralph | C8: =D8/D5 -> 0.99980004 | D8: =SUM(E8:IV8) -> 5 | E8: 5
A9: =Names!$A:$A -> 4 | B9: =Names!$B:$B -> 0 | C9: =D9/D5 -> 0 | D9: =SUM(E9:IV9) -> 0
A10: =Names!$A:$A -> 5 | B10: =Names!$B:$B -> 0 | C10: =D10/D5 -> 0 | D10: =SUM(E10:IV10) -> 0
A11: =Names!$A:$A -> 6 | B11: =Names!$B:$B -> 0 | C11: =D11/D5 -> 0 | D11: =SUM(E11:IV11) -> 0
A12: =Names!$A:$A -> 7 | B12: =Names!$B:$B -> 0 | C12: =D12/D5 -> 0 | D12: =SUM(E12:IV12) -> 0
A13: =Names!$A:$A -> 8 | B13: =Names!$B:$B -> 0 | C13: =D13/D5 -> 0 | D13: =SUM(E13:IV13) -> 0
A14: =Names!$A:$A -> 9 | B14: =Names!$B:$B -> 0 | C14: =D14/D5 -> 0 | D14: =SUM(E14:IV14) -> 0
A15: =Names!$A:$A -> 10 | B15: =Names!$B:$B -> 0 | C15: =D15/D5 -> 0 | D15: =SUM(E15:IV15) -> 0
A16: =Names!$A:$A -> 11 | B16: =Names!$B:$B -> 0 | C16: =D16/D5 -> 0 | D16: =SUM(E16:IV16) -> 0
A17: =Names!$A:$A -> 12 | B17: =Names!$B:$B -> 0 | C17: =D17/D5 -> 0 | D17: =SUM(E17:IV17) -> 0
A18: =Names!$A:$A -> 13 | B18: =Names!$B:$B -> 0 | C18: =D18/D5 -> 0 | D18: =SUM(E18:IV18) -> 0
A19: =Names!$A:$A -> 14 | B19: =Names!$B:$B -> 0 | C19: =D19/D5 -> 0 | D19: =SUM(E19:IV19) -> 0
A20: =Names!$A:$A -> 15 | B20: =Names!$B:$B -> 0 | C20: =D20/D5 -> 0 | D20: =SUM(E20:IV20) -> 0
A21: =Names!$A:$A -> 16 | B21: =Names!$B:$B -> 0 | C21: =D21/D5 -> 0 | D21: =SUM(E21:IV21) -> 0
A22: =Names!$A:$A -> 17 | B22: =Names!$B:$B -> 0 | C22: =D22/D5 -> 0 | D22: =SUM(E22:IV22) -> 0
A23: =Names!$A:$A -> 18 | B23: =Names!$B:$B -> 0 | C23: =D23/D5 -> 0 | D23: =SUM(E23:IV23) -> 0
A24: =Names!$A:$A -> 19 | B24: =Names!$B:$B -> 0 | C24: =D24/D5 -> 0 | D24: =SUM(E24:IV24) -> 0
A25: =Names!$A:$A -> 20 | B25: =Names!$B:$B -> 0 | C25: =D25/D5 -> 0 | D25: =SUM(E25:IV25) -> 0
A26: =Names!$A:$A -> 21 | B26: =Names!$B:$B -> 0 | C26: =D26/D5 -> 0 | D26: =SUM(E26:IV26) -> 0
A27: =Names!$A:$A -> 22 | B27: =Names!$B:$B -> 0 | C27: =D27/D5 -> 0 | D27: =SUM(E27:IV27) -> 0
A28: =Names!$A:$A -> 23 | B28: =Names!$B:$B -> 0 | C28: =D28/D5 -> 0 | D28: =SUM(E28:IV28) -> 0
A29: =Names!$A:$A -> 24 | B29: =Names!$B:$B -> 0 | C29: =D29/D5 -> 0 | D29: =SUM(E29:IV29) -> 0
A30: =Names!$A:$A -> 25 | B30: =Names!$B:$B -> 0 | C30: =D30/D5 -> 0 | D30: =SUM(E30:IV30) -> 0
A31: =Names!$A:$A -> 26 | B31: =Names!$B:$B -> 0 | C31: =D31/D5 -> 0 | D31: =SUM(E31:IV31) -> 0
A32: =Names!$A:$A -> 27 | B32: =Names!$B:$B -> 0 | C32: =D32/D5 -> 0 | D32: =SUM(E32:IV32) -> 0
A33: =Names!$A:$A -> 28 | B33: =Names!$B:$B -> 0 | C33: =D33/D5 -> 0 | D33: =SUM(E33:IV33) -> 0
A34: =Names!$A:$A -> 29 | B34: =Names!$B:$B -> 0 | C34: =D34/D5 -> 0 | D34: =SUM(E34:IV34) -> 0
A35: =Names!$A:$A -> 30 | B35: =Names!$B:$B -> 0 | C35: =D35/D5 -> 0 | D35: =SUM(E35:IV35) -> 0
A36: =Names!$A:$A -> 31 | B36: =Names!$B:$B -> 0 | C36: =D36/D5 -> 0 | D36: =SUM(E36:IV36) -> 0
A37: =Names!$A:$A -> 32 | B37: =Names!$B:$B -> 0 | C37: =D37/D5 -> 0 | D37: =SUM(E37:IV37) -> 0
A38: =Names!$A:$A -> 33 | B38: =Names!$B:$B -> 0 | C38: =D38/D5 -> 0 | D38: =SUM(E38:IV38) -> 0
A39: =Names!$A:$A -> 34 | B39: =Names!$B:$B -> 0 | C39: =D39/D5 -> 0 | D39: =SUM(E39:IV39) -> 0
A40: =Names!$A:$A -> 35 | B40: =Names!$B:$B -> 0 | C40: =D40/D5 -> 0 | D40: =SUM(E40:IV40) -> 0

Sheet Seating Chart
C1: Chalk Board | G1: White Board
I2: Lecturn | N2: Closet
N3: Closet
N4: Door
N6: Closet
B9: Back Wall

Sheet Attendance sheet
B1: =Names!B1 -> Quarter 1 | D1: t - tardy | G1: np - not prepared
B2: =Names!B2 -> Class | D2: a - absent | G2: nd - homework not done
A5: =Names!A5 -> # | B5: =Names!B5 -> Last Name, First Name | C5: 1 | D5: 2 | E5: 3 | F5: 4 | G5: 5 | H5: 6 | I5: 7 | J5: 8 | K5: 9 | L5: 10 | M5: 11 | N5: 12 | O5: 13 | P5: 14 | Q5: 15 | R5: 16 | S5: 17 | T5: 18 | U5: 19 | V5: 20 | W5: 21 | X5: 22 | Y5: 23 | Z5: 24 | AA5: 25 | AB5: 26 | AC5: 27 | AD5: 28 | AE5: 29 | AF5: 30
A6: =Names!A6 -> 1 | B6: =Names!$B:$B -> Adams, Bob
A7: =Names!A7 -> 2 | B7: =Names!$B:$B -> Jones, George
A8: =Names!A8 -> 3 | B8: =Names!$B:$B -> Smith, Ralph
A9: =Names!A9 -> 4 | B9: =Names!$B:$B -> 0
A10: =Names!A10 -> 5 | B10: =Names!$B:$B -> 0
A11: =Names!A11 -> 6 | B11: =Names!$B:$B -> 0
A12: =Names!A12 -> 7 | B12: =Names!$B:$B -> 0
A13: =Names!A13 -> 8 | B13: =Names!$B:$B -> 0
A14: =Names!A14 -> 9 | B14: =Names!$B:$B -> 0
A15: =Names!A15 -> 10 | B15: =Names!$B:$B -> 0
A16: =Names!A16 -> 11 | B16: =Names!$B:$B -> 0
A17: =Names!A17 -> 12 | B17: =Names!$B:$B -> 0
... A40: =Names!A40 -> 35 | B40: =Names!$B:$B -> 0

Sheet Daily Grade
B1: Date
C2: Week ___
B3: Name | C3: Monday | E3: Tuesday | G3: Wednesday | I3: Thursday | K3: Friday
A5: 1 | B5: =Names!$B:$B -> Last Name, First Name
A6: 2 | B6: =Names!B7 -> Jones, George
A7: 3 | B7: =Names!B8 -> Smith, Ralph
A8: 4 | B8: =Names!B9 -> 0
A9: 5 | B9: =Names!B10 -> 0
A10: 6 | B10: =Names!B11 -> 0
A11: 7 | B11: =Names!B12 -> 0
A12: 8 | B12: =Names!B13 -> 0
A13: 9 | B13: =Names!B14 -> 0
A14: 10 | B14: =Names!B15 -> 0
A15: 11 | B15: =Names!B16 -> 0
A16: 12 | B16: =Names!B17 -> 0
A17: 13 | B17: =Names!B18 -> 0
... A39: 35 | B39: =Names!B40 -> 0

Sheet Attendance Sheet 2
B1: =Names!B1 -> Quarter 1 | D1: t - tardy | I1: np - not prepared | AC1: t - tardy | AH1: np - not prepared
B2: =Names!B2 -> Class | D2: a - absent | AC2: a - absent
C3: week 1 | H3: week 2 | M3: week 3 | R3: week 4 | W3: week 5 | AB3: week 6 | AG3: week 7 | AL3: week 8 | AQ3: week 9 | AV3: extra
A5: =Names!A5 -> # | B5: =Names!B5 -> Last Name, First Name | C5: m | D5: t | E5: w | F5: th | G5: f | H5: m | I5: t | J5: w | K5: th | L5: f | M5: m | N5: t | O5: w | P5: th | Q5: f | R5: m | S5: t | T5: w | U5: th | V5: f | W5: m | X5: t | Y5: w | Z5: th | AA5: f | AB5: m | AC5: t | AD5: w | AE5: th | AF5: f | AG5: m | AH5: t | AI5: w | AJ5: th | AK5: f | AL5: m | AM5: t | AN5: w | AO5: th | AP5: f | AQ5: m | AR5: t | AS5: w | AT5: th | AU5: f
A6: =Names!A6 -> 1 | B6: =Names!$B:$B -> Adams, Bob
A7: =Names!A7 -> 2 | B7: =Names!$B:$B -> Jones, George
A8: =Names!A8 -> 3 | B8: =Names!$B:$B -> Smith, Ralph
A9: =Names!A9 -> 4 | B9: =Names!$B:$B -> 0
A10: =Names!A10 -> 5 | B10: =Names!$B:$B -> 0
A11: =Names!A11 -> 6 | B11: =Names!$B:$B -> 0
A12: =Names!A12 -> 7 | B12: =Names!$B:$B -> 0
A13: =Names!A13 -> 8 | B13: =Names!$B:$B -> 0
A14: =Names!A14 -> 9 | B14: =Names!$B:$B -> 0
A15: =Names!A15 -> 10 | B15: =Names!$B:$B -> 0
A16: =Names!A16 -> 11 | B16: =Names!$B:$B -> 0
A17: =Names!A17 -> 12 | B17: =Names!$B:$B -> 0
... A40: =Names!A40 -> 35 | B40: =Names!$B:$B -> 0
