Workbook
Name N: Results!$D$5

Sheet Instructions
B3: Homework 1 | C3: This spreadsheet gives you a working model of CreditMetrics.
B5: Warning: | C5: Do not move anything, and do not insert columns or rows.
C6: If you need extra cells, use the ones to the right or below.
B8: Suggestion: | C8: Save this spreadsheet now and do your work on a copy.
B11: Important: | C11: Enter here each student who is part of this work:
C13: Name | D13: E-Mail
C20: When you are done with Hw1, please save this entire workbook with a name that identifies all authors,
C21: For example, Hw1_DonQ_Sancho.xls
C22: Then E-mail the entire spreadsheet to me. Please put "Hw1" in the subject.
C23: Jon.Frye@chi.frb.org

Sheet Hw1
C3: Homework #1 is due Saturday May 18 at 6AM.
C4: Your objective for this homework is to learn how CreditMetrics works.
C5: Your grade will be based on your inputs to cells having this format:
B7: Sheet | C7: Homework #1, Due Saturday, May 18 at 6AM
B9: Values | C9: Put in formulas for "a" and "b" in columns AE and AF.
C10: This will replace the current numerical constants.
C11: "a" and "b" are the parameters of the beta distribution.
C12: They should depend on the mean and SD of the distribution, which are given.
B14: Probabilities | C14: This sheet works fine. It is worth a long look, though.
B16: Correlations | C16: Compute the lower triangular Choleski matrix.
C17: You can use any method you like to do this.
C18: Enter the elements in the proper place in the spreadsheet.
C19: This will replace the current contents (which is an identity matrix).
C20: If you do this accurately, the elements in rows 53-72 will be zero.
B22: Simulation Run | C22: Enter formulas into two areas of the sheet:
D23: Cummulative probabilities,
D24: and the new rating.
C25: To see if this is working properly, press F9--some of the new ratings should change.
B27: Results | C27: Press the button and the simulation will run 10,000 times.
C28: The charts will reflect this simulation.
C29: For comparison, I put snapshots of my results further to the right.
C30: You can control the number of runs in cell C5, up to 65,536, but 10,000 is enough.
C33: Suppose the bank with this portfolio wants an "investment grade" rating.
C34: (Investment grade is BBB or better.)
C35: How much credit capital do they need?
B36: This sheet--1 | D36: Credit Capital =
C38: Do they need more capital (in total) than this to be considered BBB?
B39: This sheet--2 | C39: (Hint: Remember, I work at the Federal Reserve) | H39: Yes/No =
C41: List some reasons that the bank needs capital in excess of credit capital:
B42: This sheet--3

Sheet Values
B3: 1. Portfolio of Bonds (Table 11.1) | I3: 2. Cash Flows, dated one year forward | R3: 5. One-Year Forward Price Conditional on Transition | AA3: 7. Beta Distribution Parameters
B4: Bond | C4: Rating | D4: Coupon | E4: Maty | F4: Seniority | G4: Face | I4: 0 | J4: =I4+1 -> 1 | K4: =J4+1 -> 2 | L4: =K4+1 -> 3 | M4: =L4+1 -> 4 | N4: =M4+1 -> 5 | O4: =N4+1 -> 6 | P4: =O4+1 -> 7 | R4: AAA | S4: AA | T4: A | U4: BBB | V4: BB | W4: B | X4: CCC | Y4: Default | AA4: Seniority | AB4: Index | AC4: Mean | AD4: SD | AE4: a | AF4: b
B5: 1 | C5: AAA | D5: 5 | E5: 3 | F5: Sen Secured | G5: 7 | I5: =(I$4<$E5)*$D5+100*($E5=I$4+1) -> 5 | J5: =(J$4<$E5)*$D5+100*($E5=J$4+1) -> 5 | K5: =(K$4<$E5)*$D5+100*($E5=K$4+1) -> 105 | L5: =(L$4<$E5)*$D5+100*($E5=L$4+1) -> 0 | M5: =(M$4<$E5)*$D5+100*($E5=M$4+1) -> 0 | N5: =(N$4<$E5)*$D5+100*($E5=N$4+1) -> 0 | O5: =(O$4<$E5)*$D5+100*($E5=O$4+1) -> 0 | P5: =(P$4<$E5)*$D5+100*($E5=P$4+1) -> 0 | R5: =MMULT($I5:$P5,R$29:R$36)/100 -> 1.0658806 | S5: =MMULT($I5:$P5,S$29:S$36)/100 -> 1.0649291 | T5: =MMULT($I5:$P5,T$29:T$36)/100 -> 1.0630441 | U5: =MMULT($I5:$P5,U$29:U$36)/100 -> 1.0564264 | V5: =MMULT($I5:$P5,V$29:V$36)/100 -> 1.0315146 | W5: =MMULT($I5:$P5,W$29:W$36)/100 -> 1.0139155 | X5: =MMULT($I5:$P5,X$29:X$36)/100 -> 0.88713413 | Y5: =BETAINV(RAND(),AE5,AF5) -> 0.22601574 | AA5: =F5 -> Sen Secured | AB5: =MATCH(AA5,$AA$29:$AA$33,0) -> 1 | AC5: =INDEX(AB$29:AB$33,$AB5) -> 0.538 | AD5: =INDEX(AC$29:AC$33,$AB5) -> 0.2686 | AE5: =AC5+AD5*EXP(1) -> 1.2681305 | AF5: =AD5+AC5*PI() -> 1.9587768
B6: 2 | C6: AA | D6: 5.52 | E6: 4 | F6: Junior Sub | G6: 1 | I6: =(I$4<$E6)*$D6+100*($E6=I$4+1) -> 5.52 | J6: =(J$4<$E6)*$D6+100*($E6=J$4+1) -> 5.52 | K6: =(K$4<$E6)*$D6+100*($E6=K$4+1) -> 5.52 | L6: =(L$4<$E6)*$D6+100*($E6=L$4+1) -> 105.52 | M6: =(M$4<$E6)*$D6+100*($E6=M$4+1) -> 0 | N6: =(N$4<$E6)*$D6+100*($E6=N$4+1) -> 0 | O6: =(O$4<$E6)*$D6+100*($E6=O$4+1) -> 0 | P6: =(P$4<$E6)*$D6+100*($E6=P$4+1) -> 0 | R6: =MMULT($I6:$P6,R$29:R$36)/100 -> 1.0779404 | S6: =MMULT($I6:$P6,S$29:S$36)/100 -> 1.0765515 | T6: =MMULT($I6:$P6,T$29:T$36)/100 -> 1.07249 | U6: =MMULT($I6:$P6,U$29:U$36)/100 -> 1.0636516 | V6: =MMULT($I6:$P6,V$29:V$36)/100 -> 1.0232992 | W6: =MMULT($I6:$P6,W$29:W$36)/100 -> 0.99240084 | X6: =MMULT($I6:$P6,X$29:X$36)/100 -> 0.85657171 | Y6: =BETAINV(RAND(),AE6,AF6) -> 0.2094326 | AA6: =F6 -> Junior Sub | AB6: =MATCH(AA6,$AA$29:$AA$33,0) -> 5 | AC6: =INDEX(AB$29:AB$33,$AB6) -> 0.1709 | AD6: =INDEX(AC$29:AC$33,$AB6) -> 0.109 | AE6: =AC6+AD6*EXP(1) -> 0.46719272 | AF6: =AD6+AC6*PI() -> 0.64589818
B7: 3 | C7: A | D7: 5.4 | E7: 3 | F7: Junior Sub | G7: 1 | I7: =(I$4<$E7)*$D7+100*($E7=I$4+1) -> 5.4 | J7: =(J$4<$E7)*$D7+100*($E7=J$4+1) -> 5.4 | K7: =(K$4<$E7)*$D7+100*($E7=K$4+1) -> 105.4 | L7: =(L$4<$E7)*$D7+100*($E7=L$4+1) -> 0 | M7: =(M$4<$E7)*$D7+100*($E7=M$4+1) -> 0 | N7: =(N$4<$E7)*$D7+100*($E7=N$4+1) -> 0 | O7: =(O$4<$E7)*$D7+100*($E7=O$4+1) -> 0 | P7: =(P$4<$E7)*$D7+100*($E7=P$4+1) -> 0 | R7: =MMULT($I7:$P7,R$29:R$36)/100 -> 1.0774278 | S7: =MMULT($I7:$P7,S$29:S$36)/100 -> 1.0764709 | T7: =MMULT($I7:$P7,T$29:T$36)/100 -> 1.0745762 | U7: =MMULT($I7:$P7,U$29:U$36)/100 -> 1.0679199 | V7: =MMULT($I7:$P7,V$29:V$36)/100 -> 1.042863 | W7: =MMULT($I7:$P7,W$29:W$36)/100 -> 1.0251797 | X7: =MMULT($I7:$P7,X$29:X$36)/100 -> 0.8976344 | Y7: =BETAINV(RAND(),AE7,AF7) -> 0.029895672 | AA7: =F7 -> Junior Sub | AB7: =MATCH(AA7,$AA$29:$AA$33,0) -> 5 | AC7: =INDEX(AB$29:AB$33,$AB7) -> 0.1709 | AD7: =INDEX(AC$29:AC$33,$AB7) -> 0.109 | AE7: =AC7+AD7*EXP(1) -> 0.46719272 | AF7: =AD7+AC7*PI() -> 0.64589818
B8: 4 | C8: BBB | D8: 6.2 | E8: 4 | F8: Junior Sub | G8: 1 | I8: =(I$4<$E8)*$D8+100*($E8=I$4+1) -> 6.2 | J8: =(J$4<$E8)*$D8+100*($E8=J$4+1) -> 6.2 | K8: =(K$4<$E8)*$D8+100*($E8=K$4+1) -> 6.2 | L8: =(L$4<$E8)*$D8+100*($E8=L$4+1) -> 106.2 | M8: =(M$4<$E8)*$D8+100*($E8=M$4+1) -> 0 | N8: =(N$4<$E8)*$D8+100*($E8=N$4+1) -> 0 | O8: =(O$4<$E8)*$D8+100*($E8=O$4+1) -> 0 | P8: =(P$4<$E8)*$D8+100*($E8=P$4+1) -> 0 | R8: =MMULT($I8:$P8,R$29:R$36)/100 -> 1.1034902 | S8: =MMULT($I8:$P8,S$29:S$36)/100 -> 1.1020837 | T8: =MMULT($I8:$P8,T$29:T$36)/100 -> 1.0979804 | U8: =MMULT($I8:$P8,U$29:U$36)/100 -> 1.0890229 | V8: =MMULT($I8:$P8,V$29:V$36)/100 -> 1.0481766 | W8: =MMULT($I8:$P8,W$29:W$36)/100 -> 1.0169436 | X8: =MMULT($I8:$P8,X$29:X$36)/100 -> 0.87900836 | Y8: =BETAINV(RAND(),AE8,AF8) -> 0.062246074 | AA8: =F8 -> Junior Sub | AB8: =MATCH(AA8,$AA$29:$AA$33,0) -> 5 | AC8: =INDEX(AB$29:AB$33,$AB8) -> 0.1709 | AD8: =INDEX(AC$29:AC$33,$AB8) -> 0.109 | AE8: =AC8+AD8*EXP(1) -> 0.46719272 | AF8: =AD8+AC8*PI() -> 0.64589818
B9: 5 | C9: BB | D9: 7.54 | E9: 3 | F9: Junior Sub | G9: 1 | I9: =(I$4<$E9)*$D9+100*($E9=I$4+1) -> 7.54 | J9: =(J$4<$E9)*$D9+100*($E9=J$4+1) -> 7.54 | K9: =(K$4<$E9)*$D9+100*($E9=K$4+1) -> 107.54 | L9: =(L$4<$E9)*$D9+100*($E9=L$4+1) -> 0 | M9: =(M$4<$E9)*$D9+100*($E9=M$4+1) -> 0 | N9: =(N$4<$E9)*$D9+100*($E9=N$4+1) -> 0 | O9: =(O$4<$E9)*$D9+100*($E9=O$4+1) -> 0 | P9: =(P$4<$E9)*$D9+100*($E9=P$4+1) -> 0 | R9: =MMULT($I9:$P9,R$29:R$36)/100 -> 1.1392051 | S9: =MMULT($I9:$P9,S$29:S$36)/100 -> 1.1382194 | T9: =MMULT($I9:$P9,T$29:T$36)/100 -> 1.136273 | U9: =MMULT($I9:$P9,U$29:U$36)/100 -> 1.1294101 | V9: =MMULT($I9:$P9,V$29:V$36)/100 -> 1.1035764 | W9: =MMULT($I9:$P9,W$29:W$36)/100 -> 1.0854435 | X9: =MMULT($I9:$P9,X$29:X$36)/100 -> 0.95381086 | Y9: =BETAINV(RAND(),AE9,AF9) -> 0.00096273767 | AA9: =F9 -> Junior Sub | AB9: =MATCH(AA9,$AA$29:$AA$33,0) -> 5 | AC9: =INDEX(AB$29:AB$33,$AB9) -> 0.1709 | AD9: =INDEX(AC$29:AC$33,$AB9) -> 0.109 | AE9: =AC9+AD9*EXP(1) -> 0.46719272 | AF9: =AD9+AC9*PI() -> 0.64589818
B10: 6 | C10: B | D10: 10.78 | E10: 4 | F10: Junior Sub | G10: 1 | I10: =(I$4<$E10)*$D10+100*($E10=I$4+1) -> 10.78 | J10: =(J$4<$E10)*$D10+100*($E10=J$4+1) -> 10.78 | K10: =(K$4<$E10)*$D10+100*($E10=K$4+1) -> 10.78 | L10: =(L$4<$E10)*$D10+100*($E10=L$4+1) -> 110.78 | M10: =(M$4<$E10)*$D10+100*($E10=M$4+1) -> 0 | N10: =(N$4<$E10)*$D10+100*($E10=N$4+1) -> 0 | O10: =(O$4<$E10)*$D10+100*($E10=O$4+1) -> 0 | P10: =(P$4<$E10)*$D10+100*($E10=P$4+1) -> 0 | R10: =MMULT($I10:$P10,R$29:R$36)/100 -> 1.2755759 | S10: =MMULT($I10:$P10,S$29:S$36)/100 -> 1.2740504 | T10: =MMULT($I10:$P10,T$29:T$36)/100 -> 1.2696661 | U10: =MMULT($I10:$P10,U$29:U$36)/100 -> 1.2599059 | V10: =MMULT($I10:$P10,V$29:V$36)/100 -> 1.2157328 | W10: =MMULT($I10:$P10,W$29:W$36)/100 -> 1.1822466 | X10: =MMULT($I10:$P10,X$29:X$36)/100 -> 1.0301258 | Y10: =BETAINV(RAND(),AE10,AF10) -> 0.4336906 | AA10: =F10 -> Junior Sub | AB10: =MATCH(AA10,$AA$29:$AA$33,0) -> 5 | AC10: =INDEX(AB$29:AB$33,$AB10) -> 0.1709 | AD10: =INDEX(AC$29:AC$33,$AB10) -> 0.109 | AE10: =AC10+AD10*EXP(1) -> 0.46719272 | AF10: =AD10+AC10*PI() -> 0.64589818
B11: 7 | C11: CCC | D11: 22.16 | E11: 2 | F11: Junior Sub | G11: 1 | I11: =(I$4<$E11)*$D11+100*($E11=I$4+1) -> 22.16 | J11: =(J$4<$E11)*$D11+100*($E11=J$4+1) -> 122.16 | K11: =(K$4<$E11)*$D11+100*($E11=K$4+1) -> 0 | L11: =(L$4<$E11)*$D11+100*($E11=L$4+1) -> 0 | M11: =(M$4<$E11)*$D11+100*($E11=M$4+1) -> 0 | N11: =(N$4<$E11)*$D11+100*($E11=N$4+1) -> 0 | O11: =(O$4<$E11)*$D11+100*($E11=O$4+1) -> 0 | P11: =(P$4<$E11)*$D11+100*($E11=P$4+1) -> 0 | R11: =MMULT($I11:$P11,R$29:R$36)/100 -> 1.4007506 | S11: =MMULT($I11:$P11,S$29:S$36)/100 -> 1.4001818 | T11: =MMULT($I11:$P11,T$29:T$36)/100 -> 1.3993863 | U11: =MMULT($I11:$P11,U$29:U$36)/100 -> 1.395087 | V11: =MMULT($I11:$P11,V$29:V$36)/100 -> 1.3789662 | W11: =MMULT($I11:$P11,W$29:W$36)/100 -> 1.3735095 | X11: =MMULT($I11:$P11,X$29:X$36)/100 -> 1.2833992 | Y11: =BETAINV(RAND(),AE11,AF11) -> 0.13198975 | AA11: =F11 -> Junior Sub | AB11: =MATCH(AA11,$AA$29:$AA$33,0) -> 5 | AC11: =INDEX(AB$29:AB$33,$AB11) -> 0.1709 | AD11: =INDEX(AC$29:AC$33,$AB11) -> 0.109 | AE11: =AC11+AD11*EXP(1) -> 0.46719272 | AF11: =AD11+AC11*PI() -> 0.64589818
B12: 8 | C12: A | D12: 6.23 | E12: 8 | F12: Sen Secured | G12: 10 | I12: =(I$4<$E12)*$D12+100*($E12=I$4+1) -> 6.23 | J12: =(J$4<$E12)*$D12+100*($E12=J$4+1) -> 6.23 | K12: =(K$4<$E12)*$D12+100*($E12=K$4+1) -> 6.23 | L12: =(L$4<$E12)*$D12+100*($E12=L$4+1) -> 6.23 | M12: =(M$4<$E12)*$D12+100*($E12=M$4+1) -> 6.23 | N12: =(N$4<$E12)*$D12+100*($E12=N$4+1) -> 6.23 | O12: =(O$4<$E12)*$D12+100*($E12=O$4+1) -> 6.23 | P12: =(P$4<$E12)*$D12+100*($E12=P$4+1) -> 106.23 | R12: =MMULT($I12:$P12,R$29:R$36)/100 -> 1.1287543 | S12: =MMULT($I12:$P12,S$29:S$36)/100 -> 1.1257599 | T12: =MMULT($I12:$P12,T$29:T$36)/100 -> 1.116942 | U12: =MMULT($I12:$P12,U$29:U$36)/100 -> 1.0987097 | V12: =MMULT($I12:$P12,V$29:V$36)/100 -> 1.0097038 | W12: =MMULT($I12:$P12,W$29:W$36)/100 -> 0.9486622 | X12: =MMULT($I12:$P12,X$29:X$36)/100 -> 0.74249181 | Y12: =BETAINV(RAND(),AE12,AF12) -> 0.16497923 | AA12: =F12 -> Sen Secured | AB12: =MATCH(AA12,$AA$29:$AA$33,0) -> 1 | AC12: =INDEX(AB$29:AB$33,$AB12) -> 0.538 | AD12: =INDEX(AC$29:AC$33,$AB12) -> 0.2686 | AE12: =AC12+AD12*EXP(1) -> 1.2681305 | AF12: =AD12+AC12*PI() -> 1.9587768
B13: 9 | C13: BB | D13: 7.35 | E13: 2 | F13: Subordinated | G13: 5 | I13: =(I$4<$E13)*$D13+100*($E13=I$4+1) -> 7.35 | J13: =(J$4<$E13)*$D13+100*($E13=J$4+1) -> 107.35 | K13: =(K$4<$E13)*$D13+100*($E13=K$4+1) -> 0 | L13: =(L$4<$E13)*$D13+100*($E13=L$4+1) -> 0 | M13: =(M$4<$E13)*$D13+100*($E13=M$4+1) -> 0 | N13: =(N$4<$E13)*$D13+100*($E13=N$4+1) -> 0 | O13: =(O$4<$E13)*$D13+100*($E13=O$4+1) -> 0 | P13: =(P$4<$E13)*$D13+100*($E13=P$4+1) -> 0 | R13: =MMULT($I13:$P13,R$29:R$36)/100 -> 1.1096969 | S13: =MMULT($I13:$P13,S$29:S$36)/100 -> 1.1091971 | T13: =MMULT($I13:$P13,T$29:T$36)/100 -> 1.1084981 | U13: =MMULT($I13:$P13,U$29:U$36)/100 -> 1.10472 | V13: =MMULT($I13:$P13,V$29:V$36)/100 -> 1.0905535 | W13: =MMULT($I13:$P13,W$29:W$36)/100 -> 1.0857584 | X13: =MMULT($I13:$P13,X$29:X$36)/100 -> 1.0065726 | Y13: =BETAINV(RAND(),AE13,AF13) -> 0.90643159 | AA13: =F13 -> Subordinated | AB13: =MATCH(AA13,$AA$29:$AA$33,0) -> 4 | AC13: =INDEX(AB$29:AB$33,$AB13) -> 0.3274 | AD13: =INDEX(AC$29:AC$33,$AB13) -> 0.2018 | AE13: =AC13+AD13*EXP(1) -> 0.87594927 | AF13: =AD13+AC13*PI() -> 1.2303574
B14: 10 | C14: A | D14: 5.41 | E14: 2 | F14: Subordinated | G14: 3 | I14: =(I$4<$E14)*$D14+100*($E14=I$4+1) -> 5.41 | J14: =(J$4<$E14)*$D14+100*($E14=J$4+1) -> 105.41 | K14: =(K$4<$E14)*$D14+100*($E14=K$4+1) -> 0 | L14: =(L$4<$E14)*$D14+100*($E14=L$4+1) -> 0 | M14: =(M$4<$E14)*$D14+100*($E14=M$4+1) -> 0 | N14: =(N$4<$E14)*$D14+100*($E14=N$4+1) -> 0 | O14: =(O$4<$E14)*$D14+100*($E14=O$4+1) -> 0 | P14: =(P$4<$E14)*$D14+100*($E14=P$4+1) -> 0 | R14: =MMULT($I14:$P14,R$29:R$36)/100 -> 1.071571 | S14: =MMULT($I14:$P14,S$29:S$36)/100 -> 1.0710802 | T14: =MMULT($I14:$P14,T$29:T$36)/100 -> 1.0703939 | U14: =MMULT($I14:$P14,U$29:U$36)/100 -> 1.0666841 | V14: =MMULT($I14:$P14,V$29:V$36)/100 -> 1.0527736 | W14: =MMULT($I14:$P14,W$29:W$36)/100 -> 1.0480651 | X14: =MMULT($I14:$P14,X$29:X$36)/100 -> 0.97031034 | Y14: =BETAINV(RAND(),AE14,AF14) -> 0.58395467 | AA14: =F14 -> Subordinated | AB14: =MATCH(AA14,$AA$29:$AA$33,0) -> 4 | AC14: =INDEX(AB$29:AB$33,$AB14) -> 0.3274 | AD14: =INDEX(AC$29:AC$33,$AB14) -> 0.2018 | AE14: =AC14+AD14*EXP(1) -> 0.87594927 | AF14: =AD14+AC14*PI() -> 1.2303574
B15: 11 | C15: A | D15: 5.73 | E15: 4 | F15: Junior Sub | G15: 1 | I15: =(I$4<$E15)*$D15+100*($E15=I$4+1) -> 5.73 | J15: =(J$4<$E15)*$D15+100*($E15=J$4+1) -> 5.73 | K15: =(K$4<$E15)*$D15+100*($E15=K$4+1) -> 5.73 | L15: =(L$4<$E15)*$D15+100*($E15=L$4+1) -> 105.73 | M15: =(M$4<$E15)*$D15+100*($E15=M$4+1) -> 0 | N15: =(N$4<$E15)*$D15+100*($E15=N$4+1) -> 0 | O15: =(O$4<$E15)*$D15+100*($E15=O$4+1) -> 0 | P15: =(P$4<$E15)*$D15+100*($E15=P$4+1) -> 0 | R15: =MMULT($I15:$P15,R$29:R$36)/100 -> 1.0858308 | S15: =MMULT($I15:$P15,S$29:S$36)/100 -> 1.0844364 | T15: =MMULT($I15:$P15,T$29:T$36)/100 -> 1.080362 | U15: =MMULT($I15:$P15,U$29:U$36)/100 -> 1.0714869 | V15: =MMULT($I15:$P15,V$29:V$36)/100 -> 1.030982 | W15: =MMULT($I15:$P15,W$29:W$36)/100 -> 0.99998024 | X15: =MMULT($I15:$P15,X$29:X$36)/100 -> 0.86350067 | Y15: =BETAINV(RAND(),AE15,AF15) -> 0.65061312 | AA15: =F15 -> Junior Sub | AB15: =MATCH(AA15,$AA$29:$AA$33,0) -> 5 | AC15: =INDEX(AB$29:AB$33,$AB15) -> 0.1709 | AD15: =INDEX(AC$29:AC$33,$AB15) -> 0.109 | AE15: =AC15+AD15*EXP(1) -> 0.46719272 | AF15: =AD15+AC15*PI() -> 0.64589818
B16: 12 | C16: A | D16: 6.02 | E16: 5 | F16: Subordinated | G16: 2 | I16: =(I$4<$E16)*$D16+100*($E16=I$4+1) -> 6.02 | J16: =(J$4<$E16)*$D16+100*($E16=J$4+1) -> 6.02 | K16: =(K$4<$E16)*$D16+100*($E16=K$4+1) -> 6.02 | L16: =(L$4<$E16)*$D16+100*($E16=L$4+1) -> 6.02 | M16: =(M$4<$E16)*$D16+100*($E16=M$4+1) -> 106.02 | N16: =(N$4<$E16)*$D16+100*($E16=N$4+1) -> 0 | O16: =(O$4<$E16)*$D16+100*($E16=O$4+1) -> 0 | P16: =(P$4<$E16)*$D16+100*($E16=P$4+1) -> 0 | R16: =MMULT($I16:$P16,R$29:R$36)/100 -> 1.0944443 | S16: =MMULT($I16:$P16,S$29:S$36)/100 -> 1.0926381 | T16: =MMULT($I16:$P16,T$29:T$36)/100 -> 1.0873422 | U16: =MMULT($I16:$P16,U$29:U$36)/100 -> 1.0762163 | V16: =MMULT($I16:$P16,V$29:V$36)/100 -> 1.0209466 | W16: =MMULT($I16:$P16,W$29:W$36)/100 -> 0.98172519 | X16: =MMULT($I16:$P16,X$29:X$36)/100 -> 0.83703824 | Y16: =BETAINV(RAND(),AE16,AF16) -> 0.40164122 | AA16: =F16 -> Subordinated | AB16: =MATCH(AA16,$AA$29:$AA$33,0) -> 4 | AC16: =INDEX(AB$29:AB$33,$AB16) -> 0.3274 | AD16: =INDEX(AC$29:AC$33,$AB16) -> 0.2018 | AE16: =AC16+AD16*EXP(1) -> 0.87594927 | AF16: =AD16+AC16*PI() -> 1.2303574
... B24: 20 | C24: AA | D24: 5.81 | E24: 5 | F24: Subordinated | G24: 5 | I24: =(I$4<$E24)*$D24+100*($E24=I$4+1) -> 5.81 | J24: =(J$4<$E24)*$D24+100*($E24=J$4+1) -> 5.81 | K24: =(K$4<$E24)*$D24+100*($E24=K$4+1) -> 5.81 | L24: =(L$4<$E24)*$D24+100*($E24=L$4+1) -> 5.81 | M24: =(M$4<$E24)*$D24+100*($E24=M$4+1) -> 105.81 | N24: =(N$4<$E24)*$D24+100*($E24=N$4+1) -> 0 | O24: =(O$4<$E24)*$D24+100*($E24=O$4+1) -> 0 | P24: =(P$4<$E24)*$D24+100*($E24=P$4+1) -> 0 | R24: =MMULT($I24:$P24,R$29:R$36)/100 -> 1.0848341 | S24: =MMULT($I24:$P24,S$29:S$36)/100 -> 1.0830367 | T24: =MMULT($I24:$P24,T$29:T$36)/100 -> 1.0777634 | U24: =MMULT($I24:$P24,U$29:U$36)/100 -> 1.0666942 | V24: =MMULT($I24:$P24,V$29:V$36)/100 -> 1.0116779 | W24: =MMULT($I24:$P24,W$29:W$36)/100 -> 0.9726316 | X24: =MMULT($I24:$P24,X$29:X$36)/100 -> 0.82884475 | Y24: =BETAINV(RAND(),AE24,AF24) -> 0.69380665 | AA24: =F24 -> Subordinated | AB24: =MATCH(AA24,$AA$29:$AA$33,0) -> 4 | AC24: =INDEX(AB$29:AB$33,$AB24) -> 0.3274 | AD24: =INDEX(AC$29:AC$33,$AB24) -> 0.2018 | AE24: =AC24+AD24*EXP(1) -> 0.87594927 | AF24: =AD24+AC24*PI() -> 1.2303574
Q27: 4. One-Year Forward Discount Rates | AA27: 6. Recovery Stats (Table 7.1)
Q28: Year | R28: AAA | S28: AA | T28: A | U28: BBB | V28: BB | W28: B | X28: CCC | AA28: Seniority | AB28: Mean | AC28: SD
Q29: 0 | R29: 1 | S29: 1 | T29: 1 | U29: 1 | V29: 1 | W29: 1 | X29: 1 | AA29: Sen Secured | AB29: 0.538 | AC29: 0.2686
Q30: 1 | R30: =1/(1+R41)^$Q41 -> 0.96525097 | S30: =1/(1+S41)^$Q41 -> 0.96478534 | T30: =1/(1+T41)^$Q41 -> 0.96413421 | U30: =1/(1+U41)^$Q41 -> 0.96061479 | V30: =1/(1+V41)^$Q41 -> 0.94741829 | W30: =1/(1+W41)^$Q41 -> 0.94295144 | X30: =1/(1+X41)^$Q41 -> 0.86918731 | AA30: Sen Unsec | AB30: 0.5113 | AC30: 0.2545
Q31: 2 | R31: =1/(1+R42)^$Q42 -> 0.92154102 | S31: =1/(1+S42)^$Q42 -> 0.92065701 | T31: =1/(1+T42)^$Q42 -> 0.91889279 | U31: =1/(1+U42)^$Q42 -> 0.9127578 | V31: =1/(1+V42)^$Q42 -> 0.88966069 | W31: =1/(1+W42)^$Q42 -> 0.8731123 | X31: =1/(1+X42)^$Q42 -> 0.75588073 | AA31: Sen Sub | AB31: 0.3852 | AC31: 0.2381
Q32: 3 | R32: =1/(1+R43)^$Q43 -> 0.87053591 | S32: =1/(1+S43)^$Q43 -> 0.86929027 | T32: =1/(1+T43)^$Q43 -> 0.86556758 | U32: =1/(1+U43)^$Q43 -> 0.8576966 | V32: =1/(1+V43)^$Q43 -> 0.82135376 | W32: =1/(1+W43)^$Q43 -> 0.79317108 | X32: =1/(1+X43)^$Q43 -> 0.67443892 | AA32: Subordinated | AB32: 0.3274 | AC32: 0.2018
Q33: 4 | R33: =1/(1+R44)^$Q44 -> 0.81895227 | S33: =1/(1+S44)^$Q44 -> 0.81739599 | T33: =1/(1+T44)^$Q44 -> 0.81274929 | U33: =1/(1+U44)^$Q44 -> 0.80325027 | V33: =1/(1+V44)^$Q44 -> 0.75524329 | W33: =1/(1+W44)^$Q44 -> 0.72104249 | X33: =1/(1+X44)^$Q44 -> 0.60215801 | AA33: Junior Sub | AB33: 0.1709 | AC33: 0.109
Q34: =Q33+1 -> 5 | R34: =1/(1+R45)^$Q45 -> 0.77906418 | S34: =1/(1+S45)^$Q45 -> 0.77721403 | T34: =1/(1+T45)^$Q45 -> 0.77169511 | U34: =1/(1+U45)^$Q45 -> 0.76043763 | V34: =1/(1+V45)^$Q45 -> 0.70405826 | W34: =1/(1+W45)^$Q45 -> 0.66443282 | X34: =1/(1+X45)^$Q45 -> 0.53044222
Q35: =Q34+1 -> 6 | R35: =1/(1+R46)^$Q46 -> 0.7411189 | S35: =1/(1+S46)^$Q46 -> 0.73900735 | T35: =1/(1+T46)^$Q46 -> 0.73271469 | U35: =1/(1+U46)^$Q46 -> 0.71990688 | V35: =1/(1+V46)^$Q46 -> 0.65634218 | W35: =1/(1+W46)^$Q46 -> 0.61226762 | X35: =1/(1+X46)^$Q46 -> 0.46726764
Q36: =Q35+1 -> 7 | R36: =1/(1+R47)^$Q47 -> 0.70502178 | S36: =1/(1+S47)^$Q47 -> 0.70267885 | T36: =1/(1+T47)^$Q47 -> 0.69570327 | U36: =1/(1+U47)^$Q47 -> 0.68153638 | V36: =1/(1+V47)^$Q47 -> 0.61185996 | W36: =1/(1+W47)^$Q47 -> 0.56419795 | X36: =1/(1+X47)^$Q47 -> 0.41161702
Q39: 3. One-Year Forward Zero Coupon Rates (Table 2.3)
Q40: Year | R40: AAA | S40: AA | T40: A | U40: BBB | V40: BB | W40: B | X40: CCC
Q41: 1 | R41: 0.036 | S41: 0.0365 | T41: 0.0372 | U41: 0.041 | V41: 0.0555 | W41: 0.0605 | X41: 0.1505
Q42: 2 | R42: 0.0417 | S42: 0.0422 | T42: 0.0432 | U42: 0.0467 | V42: 0.0602 | W42: 0.0702 | X42: 0.1502
Q43: 3 | R43: 0.0473 | S43: 0.0478 | T43: 0.0493 | U43: 0.0525 | V43: 0.0678 | W43: 0.0803 | X43: 0.1403
Q44: 4 | R44: 0.0512 | S44: 0.0517 | T44: 0.0532 | U44: 0.0563 | V44: 0.0727 | W44: 0.0852 | X44: 0.1352
Q45: =Q44+1 -> 5 | R45: =R44 -> 0.0512 | S45: =S44 -> 0.0517 | T45: =T44 -> 0.0532 | U45: =U44 -> 0.0563 | V45: =V44 -> 0.0727 | W45: =W44 -> 0.0852 | X45: =X44 -> 0.1352
Q46: =Q45+1 -> 6 | R46: =R45 -> 0.0512 | S46: =S45 -> 0.0517 | T46: =T45 -> 0.0532 | U46: =U45 -> 0.0563 | V46: =V45 -> 0.0727 | W46: =W45 -> 0.0852 | X46: =X45 -> 0.1352
Q47: =Q46+1 -> 7 | R47: =R46 -> 0.0512 | S47: =S46 -> 0.0517 | T47: =T46 -> 0.0532 | U47: =U46 -> 0.0563 | V47: =V46 -> 0.0727 | W47: =W46 -> 0.0852 | X47: =X46 -> 0.1352

Sheet Probabilities
AA2: 4. Expected Values
B3: 1. Transition Matrix (Table 6.9) | M3: 2. Portfolio | R3: 3. Portfolio Transition Probabilities | AA3: Default | AB3: MTM mode | AD3: Default-only mode
C4: AAA | D4: AA | E4: A | F4: BBB | G4: BB | H4: B | I4: CCC | J4: D | K4: Check | M4: Bond | N4: Rating | O4: Face | P4: Index | R4: AAA | S4: AA | T4: A | U4: BBB | V4: BB | W4: B | X4: CCC | Y4: D | AA4: Price | AB4: Price | AC4: Value | AD4: Price | AE4: Value
B5: AAA | C5: 0.5857 | D5: 0.3902 | E5: 0.0142 | F5: 0.0063 | G5: 0.0018 | H5: 0.0014 | I5: 0.0003 | J5: 0.0001 | K5: =SUM(C5:J5) -> 1 | M5: =Values!B5 -> 1 | N5: =Values!C5 -> AAA | O5: =Values!G5 -> 7 | P5: =MATCH(N5,$C$4:$I$4,0) -> 1 | R5: =INDEX(C$5:C$12,$P5) -> 0.5857 | S5: =INDEX(D$5:D$12,$P5) -> 0.3902 | T5: =INDEX(E$5:E$12,$P5) -> 0.0142 | U5: =INDEX(F$5:F$12,$P5) -> 0.0063 | V5: =INDEX(G$5:G$12,$P5) -> 0.0018 | W5: =INDEX(H$5:H$12,$P5) -> 0.0014 | X5: =INDEX(I$5:I$12,$P5) -> 0.0003 | Y5: =INDEX(J$5:J$12,$P5) -> 0.0001 | AA5: =Values!AC5 -> 0.538 | AB5: =SUMPRODUCT(R5:X5,Values!R5:X5)+Y5*AA5 -> 1.0651685 | AC5: =AB5*O5 -> 7.4561794 | AD5: =Y5*AA5+(1-Y5)*1 -> 0.9999538 | AE5: =O5*AD5 -> 6.9996766
B6: AA | C6: 0.0071 | D6: 0.8946 | E6: 0.0747 | F6: 0.0139 | G6: 0.0072 | H6: 0.0018 | I6: 0.0005 | J6: 0.0002 | K6: =SUM(C6:J6) -> 1 | M6: =Values!B6 -> 2 | N6: =Values!C6 -> AA | O6: =Values!G6 -> 1 | P6: =MATCH(N6,$C$4:$I$4,0) -> 2 | R6: =INDEX(C$5:C$12,$P6) -> 0.0071 | S6: =INDEX(D$5:D$12,$P6) -> 0.8946 | T6: =INDEX(E$5:E$12,$P6) -> 0.0747 | U6: =INDEX(F$5:F$12,$P6) -> 0.0139 | V6: =INDEX(G$5:G$12,$P6) -> 0.0072 | W6: =INDEX(H$5:H$12,$P6) -> 0.0018 | X6: =INDEX(I$5:I$12,$P6) -> 0.0005 | Y6: =INDEX(J$5:J$12,$P6) -> 0.0002 | AA6: =Values!AC6 -> 0.1709 | AB6: =SUMPRODUCT(R6:X6,Values!R6:X6)+Y6*AA6 -> 1.0752527 | AC6: =AB6*O6 -> 1.0752527 | AD6: =Y6*AA6+(1-Y6)*1 -> 0.99983418 | AE6: =O6*AD6 -> 0.99983418
B7: A | C7: 0.0025 | D7: 0.0383 | E7: 0.9115 | F7: 0.0373 | G7: 0.0077 | H7: 0.0014 | I7: 0.0007 | J7: 0.0006 | K7: =SUM(C7:J7) -> 1 | M7: =Values!B7 -> 3 | N7: =Values!C7 -> A | O7: =Values!G7 -> 1 | P7: =MATCH(N7,$C$4:$I$4,0) -> 3 | R7: =INDEX(C$5:C$12,$P7) -> 0.0025 | S7: =INDEX(D$5:D$12,$P7) -> 0.0383 | T7: =INDEX(E$5:E$12,$P7) -> 0.9115 | U7: =INDEX(F$5:F$12,$P7) -> 0.0373 | V7: =INDEX(G$5:G$12,$P7) -> 0.0077 | W7: =INDEX(H$5:H$12,$P7) -> 0.0014 | X7: =INDEX(I$5:I$12,$P7) -> 0.0007 | Y7: =INDEX(J$5:J$12,$P7) -> 0.0006 | AA7: =Values!AC7 -> 0.1709 | AB7: =SUMPRODUCT(R7:X7,Values!R7:X7)+Y7*AA7 -> 1.0734282 | AC7: =AB7*O7 -> 1.0734282 | AD7: =Y7*AA7+(1-Y7)*1 -> 0.99950254 | AE7: =O7*AD7 -> 0.99950254
B8: BBB | C8: 0.0207 | D8: 0.0226 | E8: 0.1003 | F8: 0.8028 | G8: 0.0453 | H8: 0.005 | I8: 0.0015 | J8: 0.0018 | K8: =SUM(C8:J8) -> 1 | M8: =Values!B8 -> 4 | N8: =Values!C8 -> BBB | O8: =Values!G8 -> 1 | P8: =MATCH(N8,$C$4:$I$4,0) -> 4 | R8: =INDEX(C$5:C$12,$P8) -> 0.0207 | S8: =INDEX(D$5:D$12,$P8) -> 0.0226 | T8: =INDEX(E$5:E$12,$P8) -> 0.1003 | U8: =INDEX(F$5:F$12,$P8) -> 0.8028 | V8: =INDEX(G$5:G$12,$P8) -> 0.0453 | W8: =INDEX(H$5:H$12,$P8) -> 0.005 | X8: =INDEX(I$5:I$12,$P8) -> 0.0015 | Y8: =INDEX(J$5:J$12,$P8) -> 0.0018 | AA8: =Values!AC8 -> 0.1709 | AB8: =SUMPRODUCT(R8:X8,Values!R8:X8)+Y8*AA8 -> 1.0863376 | AC8: =AB8*O8 -> 1.0863376 | AD8: =Y8*AA8+(1-Y8)*1 -> 0.99850762 | AE8: =O8*AD8 -> 0.99850762
B9: BB | C9: 0.0015 | D9: 0.0357 | E9: 0.0784 | F9: 0.1038 | G9: 0.5591 | H9: 0.1618 | I9: 0.0491 | J9: 0.0106 | K9: =SUM(C9:J9) -> 1 | M9: =Values!B9 -> 5 | N9: =Values!C9 -> BB | O9: =Values!G9 -> 1 | P9: =MATCH(N9,$C$4:$I$4,0) -> 5 | R9: =INDEX(C$5:C$12,$P9) -> 0.0015 | S9: =INDEX(D$5:D$12,$P9) -> 0.0357 | T9: =INDEX(E$5:E$12,$P9) -> 0.0784 | U9: =INDEX(F$5:F$12,$P9) -> 0.1038 | V9: =INDEX(G$5:G$12,$P9) -> 0.5591 | W9: =INDEX(H$5:H$12,$P9) -> 0.1618 | X9: =INDEX(I$5:I$12,$P9) -> 0.0491 | Y9: =INDEX(J$5:J$12,$P9) -> 0.0106 | AA9: =Values!AC9 -> 0.1709 | AB9: =SUMPRODUCT(R9:X9,Values!R9:X9)+Y9*AA9 -> 1.0899378 | AC9: =AB9*O9 -> 1.0899378 | AD9: =Y9*AA9+(1-Y9)*1 -> 0.99121154 | AE9: =O9*AD9 -> 0.99121154
B10: B | C10: 0.0014 | D10: 0.0062 | E10: 0.1921 | F10: 0.0244 | G10: 0.0055 | H10: 0.5486 | I10: 0.1724 | J10: 0.0494 | K10: =SUM(C10:J10) -> 1 | M10: =Values!B10 -> 6 | N10: =Values!C10 -> B | O10: =Values!G10 -> 1 | P10: =MATCH(N10,$C$4:$I$4,0) -> 6 | R10: =INDEX(C$5:C$12,$P10) -> 0.0014 | S10: =INDEX(D$5:D$12,$P10) -> 0.0062 | T10: =INDEX(E$5:E$12,$P10) -> 0.1921 | U10: =INDEX(F$5:F$12,$P10) -> 0.0244 | V10: =INDEX(G$5:G$12,$P10) -> 0.0055 | W10: =INDEX(H$5:H$12,$P10) -> 0.5486 | X10: =INDEX(I$5:I$12,$P10) -> 0.1724 | Y10: =INDEX(J$5:J$12,$P10) -> 0.0494 | AA10: =Values!AC10 -> 0.1709 | AB10: =SUMPRODUCT(R10:X10,Values!R10:X10)+Y10*AA10 -> 1.1256326 | AC10: =AB10*O10 -> 1.1256326 | AD10: =Y10*AA10+(1-Y10)*1 -> 0.95904246 | AE10: =O10*AD10 -> 0.95904246
B11: CCC | C11: 0.0004 | D11: 0.0014 | E11: 0.0585 | F11: 0.0077 | G11: 0.0033 | H11: 0.411 | I11: 0.3263 | J11: 0.1914 | K11: =SUM(C11:J11) -> 1 | M11: =Values!B11 -> 7 | N11: =Values!C11 -> CCC | O11: =Values!G11 -> 1 | P11: =MATCH(N11,$C$4:$I$4,0) -> 7 | R11: =INDEX(C$5:C$12,$P11) -> 0.0004 | S11: =INDEX(D$5:D$12,$P11) -> 0.0014 | T11: =INDEX(E$5:E$12,$P11) -> 0.0585 | U11: =INDEX(F$5:F$12,$P11) -> 0.0077 | V11: =INDEX(G$5:G$12,$P11) -> 0.0033 | W11: =INDEX(H$5:H$12,$P11) -> 0.411 | X11: =INDEX(I$5:I$12,$P11) -> 0.3263 | Y11: =INDEX(J$5:J$12,$P11) -> 0.1914 | AA11: =Values!AC11 -> 0.1709 | AB11: =SUMPRODUCT(R11:X11,Values!R11:X11)+Y11*AA11 -> 1.1156732 | AC11: =AB11*O11 -> 1.1156732 | AD11: =Y11*AA11+(1-Y11)*1 -> 0.84131026 | AE11: =O11*AD11 -> 0.84131026
B12: D | C12: 0 | D12: 0 | E12: 0 | F12: 0 | G12: 0 | H12: 0 | I12: 0 | J12: 1 | K12: =SUM(C12:J12) -> 1 | M12: =Values!B12 -> 8 | N12: =Values!C12 -> A | O12: =Values!G12 -> 10 | P12: =MATCH(N12,$C$4:$I$4,0) -> 3 | R12: =INDEX(C$5:C$12,$P12) -> 0.0025 | S12: =INDEX(D$5:D$12,$P12) -> 0.0383 | T12: =INDEX(E$5:E$12,$P12) -> 0.9115 | U12: =INDEX(F$5:F$12,$P12) -> 0.0373 | V12: =INDEX(G$5:G$12,$P12) -> 0.0077 | W12: =INDEX(H$5:H$12,$P12) -> 0.0014 | X12: =INDEX(I$5:I$12,$P12) -> 0.0007 | Y12: =INDEX(J$5:J$12,$P12) -> 0.0006 | AA12: =Values!AC12 -> 0.538 | AB12: =SUMPRODUCT(R12:X12,Values!R12:X12)+Y12*AA12 -> 1.1149584 | AC12: =AB12*O12 -> 11.149584 | AD12: =Y12*AA12+(1-Y12)*1 -> 0.9997228 | AE12: =O12*AD12 -> 9.997228
M13: =Values!B13 -> 9 | N13: =Values!C13 -> BB | O13: =Values!G13 -> 5 | P13: =MATCH(N13,$C$4:$I$4,0) -> 5 | R13: =INDEX(C$5:C$12,$P13) -> 0.0015 | S13: =INDEX(D$5:D$12,$P13) -> 0.0357 | T13: =INDEX(E$5:E$12,$P13) -> 0.0784 | U13: =INDEX(F$5:F$12,$P13) -> 0.1038 | V13: =INDEX(G$5:G$12,$P13) -> 0.5591 | W13: =INDEX(H$5:H$12,$P13) -> 0.1618 | X13: =INDEX(I$5:I$12,$P13) -> 0.0491 | Y13: =INDEX(J$5:J$12,$P13) -> 0.0106 | AA13: =Values!AC13 -> 0.3274 | AB13: =SUMPRODUCT(R13:X13,Values!R13:X13)+Y13*AA13 -> 1.0811364 | AC13: =AB13*O13 -> 5.405682 | AD13: =Y13*AA13+(1-Y13)*1 -> 0.99287044 | AE13: =O13*AD13 -> 4.9643522
M14: =Values!B14 -> 10 | N14: =Values!C14 -> A | O14: =Values!G14 -> 3 | P14: =MATCH(N14,$C$4:$I$4,0) -> 3 | R14: =INDEX(C$5:C$12,$P14) -> 0.0025 | S14: =INDEX(D$5:D$12,$P14) -> 0.0383 | T14: =INDEX(E$5:E$12,$P14) -> 0.9115 | U14: =INDEX(F$5:F$12,$P14) -> 0.0373 | V14: =INDEX(G$5:G$12,$P14) -> 0.0077 | W14: =INDEX(H$5:H$12,$P14) -> 0.0014 | X14: =INDEX(I$5:I$12,$P14) -> 0.0007 | Y14: =INDEX(J$5:J$12,$P14) -> 0.0006 | AA14: =Values!AC14 -> 0.3274 | AB14: =SUMPRODUCT(R14:X14,Values!R14:X14)+Y14*AA14 -> 1.0696019 | AC14: =AB14*O14 -> 3.2088058 | AD14: =Y14*AA14+(1-Y14)*1 -> 0.99959644 | AE14: =O14*AD14 -> 2.9987893
M15: =Values!B15 -> 11 | N15: =Values!C15 -> A | O15: =Values!G15 -> 1 | P15: =MATCH(N15,$C$4:$I$4,0) -> 3 | R15: =INDEX(C$5:C$12,$P15) -> 0.0025 | S15: =INDEX(D$5:D$12,$P15) -> 0.0383 | T15: =INDEX(E$5:E$12,$P15) -> 0.9115 | U15: =INDEX(F$5:F$12,$P15) -> 0.0373 | V15: =INDEX(G$5:G$12,$P15) -> 0.0077 | W15: =INDEX(H$5:H$12,$P15) -> 0.0014 | X15: =INDEX(I$5:I$12,$P15) -> 0.0007 | Y15: =INDEX(J$5:J$12,$P15) -> 0.0006 | AA15: =Values!AC15 -> 0.1709 | AB15: =SUMPRODUCT(R15:X15,Values!R15:X15)+Y15*AA15 -> 1.0790105 | AC15: =AB15*O15 -> 1.0790105 | AD15: =Y15*AA15+(1-Y15)*1 -> 0.99950254 | AE15: =O15*AD15 -> 0.99950254
M16: =Values!B16 -> 12 | N16: =Values!C16 -> A | O16: =Values!G16 -> 2 | P16: =MATCH(N16,$C$4:$I$4,0) -> 3 | R16: =INDEX(C$5:C$12,$P16) -> 0.0025 | S16: =INDEX(D$5:D$12,$P16) -> 0.0383 | T16: =INDEX(E$5:E$12,$P16) -> 0.9115 | U16: =INDEX(F$5:F$12,$P16) -> 0.0373 | V16: =INDEX(G$5:G$12,$P16) -> 0.0077 | W16: =INDEX(H$5:H$12,$P16) -> 0.0014 | X16: =INDEX(I$5:I$12,$P16) -> 0.0007 | Y16: =INDEX(J$5:J$12,$P16) -> 0.0006 | AA16: =Values!AC16 -> 0.3274 | AB16: =SUMPRODUCT(R16:X16,Values!R16:X16)+Y16*AA16 -> 1.0858575 | AC16: =AB16*O16 -> 2.171715 | AD16: =Y16*AA16+(1-Y16)*1 -> 0.99959644 | AE16: =O16*AD16 -> 1.9991929
M17: =Values!B17 -> 13 | N17: =Values!C17 -> B | O17: =Values!G17 -> 0.6 | P17: =MATCH(N17,$C$4:$I$4,0) -> 6 | R17: =INDEX(C$5:C$12,$P17) -> 0.0014 | S17: =INDEX(D$5:D$12,$P17) -> 0.0062 | T17: =INDEX(E$5:E$12,$P17) -> 0.1921 | U17: =INDEX(F$5:F$12,$P17) -> 0.0244 | V17: =INDEX(G$5:G$12,$P17) -> 0.0055 | W17: =INDEX(H$5:H$12,$P17) -> 0.5486 | X17: =INDEX(I$5:I$12,$P17) -> 0.1724 | Y17: =INDEX(J$5:J$12,$P17) -> 0.0494 | AA17: =Values!AC17 -> 0.1709 | AB17: =SUMPRODUCT(R17:X17,Values!R17:X17)+Y17*AA17 -> 1.1102742 | AC17: =AB17*O17 -> 0.6661645 | AD17: =Y17*AA17+(1-Y17)*1 -> 0.95904246 | AE17: =O17*AD17 -> 0.57542548
M18: =Values!B18 -> 14 | N18: =Values!C18 -> B | O18: =Values!G18 -> 1 | P18: =MATCH(N18,$C$4:$I$4,0) -> 6 | R18: =INDEX(C$5:C$12,$P18) -> 0.0014 | S18: =INDEX(D$5:D$12,$P18) -> 0.0062 | T18: =INDEX(E$5:E$12,$P18) -> 0.1921 | U18: =INDEX(F$5:F$12,$P18) -> 0.0244 | V18: =INDEX(G$5:G$12,$P18) -> 0.0055 | W18: =INDEX(H$5:H$12,$P18) -> 0.5486 | X18: =INDEX(I$5:I$12,$P18) -> 0.1724 | Y18: =INDEX(J$5:J$12,$P18) -> 0.0494 | AA18: =Values!AC18 -> 0.1709 | AB18: =SUMPRODUCT(R18:X18,Values!R18:X18)+Y18*AA18 -> 1.0952086 | AC18: =AB18*O18 -> 1.0952086 | AD18: =Y18*AA18+(1-Y18)*1 -> 0.95904246 | AE18: =O18*AD18 -> 0.95904246
M19: =Values!B19 -> 15 | N19: =Values!C19 -> B | O19: =Values!G19 -> 3 | P19: =MATCH(N19,$C$4:$I$4,0) -> 6 | R19: =INDEX(C$5:C$12,$P19) -> 0.0014 | S19: =INDEX(D$5:D$12,$P19) -> 0.0062 | T19: =INDEX(E$5:E$12,$P19) -> 0.1921 | U19: =INDEX(F$5:F$12,$P19) -> 0.0244 | V19: =INDEX(G$5:G$12,$P19) -> 0.0055 | W19: =INDEX(H$5:H$12,$P19) -> 0.5486 | X19: =INDEX(I$5:I$12,$P19) -> 0.1724 | Y19: =INDEX(J$5:J$12,$P19) -> 0.0494 | AA19: =Values!AC19 -> 0.3274 | AB19: =SUMPRODUCT(R19:X19,Values!R19:X19)+Y19*AA19 -> 1.0952161 | AC19: =AB19*O19 -> 3.2856483 | AD19: =Y19*AA19+(1-Y19)*1 -> 0.96677356 | AE19: =O19*AD19 -> 2.9003207
M20: =Values!B20 -> 16 | N20: =Values!C20 -> B | O20: =Values!G20 -> 2 | P20: =MATCH(N20,$C$4:$I$4,0) -> 6 | R20: =INDEX(C$5:C$12,$P20) -> 0.0014 | S20: =INDEX(D$5:D$12,$P20) -> 0.0062 | T20: =INDEX(E$5:E$12,$P20) -> 0.1921 | U20: =INDEX(F$5:F$12,$P20) -> 0.0244 | V20: =INDEX(G$5:G$12,$P20) -> 0.0055 | W20: =INDEX(H$5:H$12,$P20) -> 0.5486 | X20: =INDEX(I$5:I$12,$P20) -> 0.1724 | Y20: =INDEX(J$5:J$12,$P20) -> 0.0494 | AA20: =Values!AC20 -> 0.3274 | AB20: =SUMPRODUCT(R20:X20,Values!R20:X20)+Y20*AA20 -> 1.1255238 | AC20: =AB20*O20 -> 2.2510476 | AD20: =Y20*AA20+(1-Y20)*1 -> 0.96677356 | AE20: =O20*AD20 -> 1.9335471
M21: =Values!B21 -> 17 | N21: =Values!C21 -> BBB | O21: =Values!G21 -> 1 | P21: =MATCH(N21,$C$4:$I$4,0) -> 4 | R21: =INDEX(C$5:C$12,$P21) -> 0.0207 | S21: =INDEX(D$5:D$12,$P21) -> 0.0226 | T21: =INDEX(E$5:E$12,$P21) -> 0.1003 | U21: =INDEX(F$5:F$12,$P21) -> 0.8028 | V21: =INDEX(G$5:G$12,$P21) -> 0.0453 | W21: =INDEX(H$5:H$12,$P21) -> 0.005 | X21: =INDEX(I$5:I$12,$P21) -> 0.0015 | Y21: =INDEX(J$5:J$12,$P21) -> 0.0018 | AA21: =Values!AC21 -> 0.1709 | AB21: =SUMPRODUCT(R21:X21,Values!R21:X21)+Y21*AA21 -> 1.104836 | AC21: =AB21*O21 -> 1.104836 | AD21: =Y21*AA21+(1-Y21)*1 -> 0.99850762 | AE21: =O21*AD21 -> 0.99850762
M22: =Values!B22 -> 18 | N22: =Values!C22 -> BBB | O22: =Values!G22 -> 8 | P22: =MATCH(N22,$C$4:$I$4,0) -> 4 | R22: =INDEX(C$5:C$12,$P22) -> 0.0207 | S22: =INDEX(D$5:D$12,$P22) -> 0.0226 | T22: =INDEX(E$5:E$12,$P22) -> 0.1003 | U22: =INDEX(F$5:F$12,$P22) -> 0.8028 | V22: =INDEX(G$5:G$12,$P22) -> 0.0453 | W22: =INDEX(H$5:H$12,$P22) -> 0.005 | X22: =INDEX(I$5:I$12,$P22) -> 0.0015 | Y22: =INDEX(J$5:J$12,$P22) -> 0.0018 | AA22: =Values!AC22 -> 0.538 | AB22: =SUMPRODUCT(R22:X22,Values!R22:X22)+Y22*AA22 -> 1.0945835 | AC22: =AB22*O22 -> 8.7566678 | AD22: =Y22*AA22+(1-Y22)*1 -> 0.9991684 | AE22: =O22*AD22 -> 7.9933472
M23: =Values!B23 -> 19 | N23: =Values!C23 -> BBB | O23: =Values!G23 -> 1 | P23: =MATCH(N23,$C$4:$I$4,0) -> 4 | R23: =INDEX(C$5:C$12,$P23) -> 0.0207 | S23: =INDEX(D$5:D$12,$P23) -> 0.0226 | T23: =INDEX(E$5:E$12,$P23) -> 0.1003 | U23: =INDEX(F$5:F$12,$P23) -> 0.8028 | V23: =INDEX(G$5:G$12,$P23) -> 0.0453 | W23: =INDEX(H$5:H$12,$P23) -> 0.005 | X23: =INDEX(I$5:I$12,$P23) -> 0.0015 | Y23: =INDEX(J$5:J$12,$P23) -> 0.0018 | AA23: =Values!AC23 -> 0.1709 | AB23: =SUMPRODUCT(R23:X23,Values!R23:X23)+Y23*AA23 -> 1.0792356 | AC23: =AB23*O23 -> 1.0792356 | AD23: =Y23*AA23+(1-Y23)*1 -> 0.99850762 | AE23: =O23*AD23 -> 0.99850762
M24: =Values!B24 -> 20 | N24: =Values!C24 -> AA | O24: =Values!G24 -> 5 | P24: =MATCH(N24,$C$4:$I$4,0) -> 2 | R24: =INDEX(C$5:C$12,$P24) -> 0.0071 | S24: =INDEX(D$5:D$12,$P24) -> 0.8946 | T24: =INDEX(E$5:E$12,$P24) -> 0.0747 | U24: =INDEX(F$5:F$12,$P24) -> 0.0139 | V24: =INDEX(G$5:G$12,$P24) -> 0.0072 | W24: =INDEX(H$5:H$12,$P24) -> 0.0018 | X24: =INDEX(I$5:I$12,$P24) -> 0.0005 | Y24: =INDEX(J$5:J$12,$P24) -> 0.0002 | AA24: =Values!AC24 -> 0.3274 | AB24: =SUMPRODUCT(R24:X24,Values!R24:X24)+Y24*AA24 -> 1.0814376 | AC24: =AB24*O24 -> 5.4071881 | AD24: =Y24*AA24+(1-Y24)*1 -> 0.99986548 | AE24: =O24*AD24 -> 4.9993274
AD26: Expected Portfolio Values
AC27: =SUM(AC5:AC24) -> 60.683236 | AE27: =SUM(AE5:AE24) -> 55.106176

Sheet Correlations
B3: Asset Correlations of Bonds in Portfolio (Table 11.2)
B4: Firm | C4: 1 | D4: 2 | E4: 3 | F4: 4 | G4: 5 | H4: 6 | I4: 7 | J4: 8 | K4: 9 | L4: 10 | M4: 11 | N4: 12 | O4: 13 | P4: 14 | Q4: 15 | R4: 16 | S4: 17 | T4: 18 | U4: 19 | V4: 20
B5: 1 | C5: 1 | D5: 0.45 | E5: 0.45 | F5: 0.45 | G5: 0.15 | H5: 0.15 | I5: 0.15 | J5: 0.15 | K5: 0.15 | L5: 0.15 | M5: 0.1 | N5: 0.1 | O5: 0.1 | P5: 0.1 | Q5: 0.1 | R5: 0.1 | S5: 0.1 | T5: 0.1 | U5: 0.1 | V5: 0.1
B6: 2 | C6: 0.45 | D6: 1 | E6: 0.45 | F6: 0.45 | G6: 0.15 | H6: 0.15 | I6: 0.15 | J6: 0.15 | K6: 0.15 | L6: 0.15 | M6: 0.1 | N6: 0.1 | O6: 0.1 | P6: 0.1 | Q6: 0.1 | R6: 0.1 | S6: 0.1 | T6: 0.1 | U6: 0.1 | V6: 0.1
B7: 3 | C7: 0.45 | D7: 0.45 | E7: 1 | F7: 0.45 | G7: 0.15 | H7: 0.15 | I7: 0.15 | J7: 0.15 | K7: 0.15 | L7: 0.15 | M7: 0.1 | N7: 0.1 | O7: 0.1 | P7: 0.1 | Q7: 0.1 | R7: 0.1 | S7: 0.1 | T7: 0.1 | U7: 0.1 | V7: 0.1
B8: 4 | C8: 0.45 | D8: 0.45 | E8: 0.45 | F8: 1 | G8: 0.15 | H8: 0.15 | I8: 0.15 | J8: 0.15 | K8: 0.15 | L8: 0.15 | M8: 0.1 | N8: 0.1 | O8: 0.1 | P8: 0.1 | Q8: 0.1 | R8: 0.1 | S8: 0.1 | T8: 0.1 | U8: 0.1 | V8: 0.1
B9: 5 | C9: 0.15 | D9: 0.15 | E9: 0.15 | F9: 0.15 | G9: 1 | H9: 0.35 | I9: 0.35 | J9: 0.35 | K9: 0.35 | L9: 0.35 | M9: 0.2 | N9: 0.2 | O9: 0.2 | P9: 0.2 | Q9: 0.2 | R9: 0.15 | S9: 0.15 | T9: 0.15 | U9: 0.1 | V9: 0.1
B10: 6 | C10: 0.15 | D10: 0.15 | E10: 0.15 | F10: 0.15 | G10: 0.35 | H10: 1 | I10: 0.35 | J10: 0.35 | K10: 0.35 | L10: 0.35 | M10: 0.2 | N10: 0.2 | O10: 0.2 | P10: 0.2 | Q10: 0.2 | R10: 0.15 | S10: 0.15 | T10: 0.15 | U10: 0.1 | V10: 0.1
B11: 7 | C11: 0.15 | D11: 0.15 | E11: 0.15 | F11: 0.15 | G11: 0.35 | H11: 0.35 | I11: 1 | J11: 0.35 | K11: 0.35 | L11: 0.35 | M11: 0.2 | N11: 0.2 | O11: 0.2 | P11: 0.2 | Q11: 0.2 | R11: 0.15 | S11: 0.15 | T11: 0.15 | U11: 0.1 | V11: 0.1
B12: 8 | C12: 0.15 | D12: 0.15 | E12: 0.15 | F12: 0.15 | G12: 0.35 | H12: 0.35 | I12: 0.35 | J12: 1 | K12: 0.35 | L12: 0.35 | M12: 0.2 | N12: 0.2 | O12: 0.2 | P12: 0.2 | Q12: 0.2 | R12: 0.15 | S12: 0.15 | T12: 0.15 | U12: 0.1 | V12: 0.1
B13: 9 | C13: 0.15 | D13: 0.15 | E13: 0.15 | F13: 0.15 | G13: 0.35 | H13: 0.35 | I13: 0.35 | J13: 0.35 | K13: 1 | L13: 0.35 | M13: 0.2 | N13: 0.2 | O13: 0.2 | P13: 0.2 | Q13: 0.2 | R13: 0.15 | S13: 0.15 | T13: 0.15 | U13: 0.1 | V13: 0.1
B14: 10 | C14: 0.15 | D14: 0.15 | E14: 0.15 | F14: 0.15 | G14: 0.35 | H14: 0.35 | I14: 0.35 | J14: 0.35 | K14: 0.35 | L14: 1 | M14: 0.2 | N14: 0.2 | O14: 0.2 | P14: 0.2 | Q14: 0.2 | R14: 0.15 | S14: 0.15 | T14: 0.15 | U14: 0.1 | V14: 0.1
B15: 11 | C15: 0.1 | D15: 0.1 | E15: 0.1 | F15: 0.1 | G15: 0.2 | H15: 0.2 | I15: 0.2 | J15: 0.2 | K15: 0.2 | L15: 0.2 | M15: 1 | N15: 0.45 | O15: 0.45 | P15: 0.45 | Q15: 0.45 | R15: 0.2 | S15: 0.2 | T15: 0.2 | U15: 0.1 | V15: 0.1
B16: 12 | C16: 0.1 | D16: 0.1 | E16: 0.1 | F16: 0.1 | G16: 0.2 | H16: 0.2 | I16: 0.2 | J16: 0.2 | K16: 0.2 | L16: 0.2 | M16: 0.45 | N16: 1 | O16: 0.45 | P16: 0.45 | Q16: 0.45 | R16: 0.2 | S16: 0.2 | T16: 0.2 | U16: 0.1 | V16: 0.1
... B24: 20 | C24: 0.1 | D24: 0.1 | E24: 0.1 | F24: 0.1 | G24: 0.1 | H24: 0.1 | I24: 0.1 | J24: 0.1 | K24: 0.1 | L24: 0.1 | M24: 0.1 | N24: 0.1 | O24: 0.1 | P24: 0.1 | Q24: 0.1 | R24: 0.25 | S24: 0.25 | T24: 0.25 | U24: 0.65 | V24: 1
B27: Choleski Decomposition of Correlation Matrix
B28: Firm | C28: 1 | D28: 2 | E28: 3 | F28: 4 | G28: 5 | H28: 6 | I28: 7 | J28: 8 | K28: 9 | L28: 10 | M28: 11 | N28: 12 | O28: 13 | P28: 14 | Q28: 15 | R28: 16 | S28: 17 | T28: 18 | U28: 19 | V28: 20
B29: 1 | C29: 1 | D29: 0 | E29: 0 | F29: 0 | G29: 0 | H29: 0 | I29: 0 | J29: 0 | K29: 0 | L29: 0 | M29: 0 | N29: 0 | O29: 0 | P29: 0 | Q29: 0 | R29: 0 | S29: 0 | T29: 0 | U29: 0 | V29: 0
B30: 2 | C30: 0 | D30: 1 | E30: 0 | F30: 0 | G30: 0 | H30: 0 | I30: 0 | J30: 0 | K30: 0 | L30: 0 | M30: 0 | N30: 0 | O30: 0 | P30: 0 | Q30: 0 | R30: 0 | S30: 0 | T30: 0 | U30: 0 | V30: 0
B31: 3 | C31: 0 | D31: 0 | E31: 1 | F31: 0 | G31: 0 | H31: 0 | I31: 0 | J31: 0 | K31: 0 | L31: 0 | M31: 0 | N31: 0 | O31: 0 | P31: 0 | Q31: 0 | R31: 0 | S31: 0 | T31: 0 | U31: 0 | V31: 0
B32: 4 | C32: 0 | D32: 0 | E32: 0 | F32: 1 | G32: 0 | H32: 0 | I32: 0 | J32: 0 | K32: 0 | L32: 0 | M32: 0 | N32: 0 | O32: 0 | P32: 0 | Q32: 0 | R32: 0 | S32: 0 | T32: 0 | U32: 0 | V32: 0
B33: 5 | C33: 0 | D33: 0 | E33: 0 | F33: 0 | G33: 1 | H33: 0 | I33: 0 | J33: 0 | K33: 0 | L33: 0 | M33: 0 | N33: 0 | O33: 0 | P33: 0 | Q33: 0 | R33: 0 | S33: 0 | T33: 0 | U33: 0 | V33: 0
B34: 6 | C34: 0 | D34: 0 | E34: 0 | F34: 0 | G34: 0 | H34: 1 | I34: 0 | J34: 0 | K34: 0 | L34: 0 | M34: 0 | N34: 0 | O34: 0 | P34: 0 | Q34: 0 | R34: 0 | S34: 0 | T34: 0 | U34: 0 | V34: 0
B35: 7 | C35: 0 | D35: 0 | E35: 0 | F35: 0 | G35: 0 | H35: 0 | I35: 1 | J35: 0 | K35: 0 | L35: 0 | M35: 0 | N35: 0 | O35: 0 | P35: 0 | Q35: 0 | R35: 0 | S35: 0 | T35: 0 | U35: 0 | V35: 0
B36: 8 | C36: 0 | D36: 0 | E36: 0 | F36: 0 | G36: 0 | H36: 0 | I36: 0 | J36: 1 | K36: 0 | L36: 0 | M36: 0 | N36: 0 | O36: 0 | P36: 0 | Q36: 0 | R36: 0 | S36: 0 | T36: 0 | U36: 0 | V36: 0
B37: 9 | C37: 0 | D37: 0 | E37: 0 | F37: 0 | G37: 0 | H37: 0 | I37: 0 | J37: 0 | K37: 1 | L37: 0 | M37: 0 | N37: 0 | O37: 0 | P37: 0 | Q37: 0 | R37: 0 | S37: 0 | T37: 0 | U37: 0 | V37: 0
B38: 10 | C38: 0 | D38: 0 | E38: 0 | F38: 0 | G38: 0 | H38: 0 | I38: 0 | J38: 0 | K38: 0 | L38: 1 | M38: 0 | N38: 0 | O38: 0 | P38: 0 | Q38: 0 | R38: 0 | S38: 0 | T38: 0 | U38: 0 | V38: 0
B39: 11 | C39: 0 | D39: 0 | E39: 0 | F39: 0 | G39: 0 | H39: 0 | I39: 0 | J39: 0 | K39: 0 | L39: 0 | M39: 1 | N39: 0 | O39: 0 | P39: 0 | Q39: 0 | R39: 0 | S39: 0 | T39: 0 | U39: 0 | V39: 0
B40: 12 | C40: 0 | D40: 0 | E40: 0 | F40: 0 | G40: 0 | H40: 0 | I40: 0 | J40: 0 | K40: 0 | L40: 0 | M40: 0 | N40: 1 | O40: 0 | P40: 0 | Q40: 0 | R40: 0 | S40: 0 | T40: 0 | U40: 0 | V40: 0
... B48: 20 | C48: 0 | D48: 0 | E48: 0 | F48: 0 | G48: 0 | H48: 0 | I48: 0 | J48: 0 | K48: 0 | L48: 0 | M48: 0 | N48: 0 | O48: 0 | P48: 0 | Q48: 0 | R48: 0 | S48: 0 | T48: 0 | U48: 0 | V48: 1
B51: Proof that the Choleski Matrix is Correct
B52: Firm | C52: 1 | D52: 2 | E52: 3 | F52: 4 | G52: 5 | H52: 6 | I52: 7 | J52: 8 | K52: 9 | L52: 10 | M52: 11 | N52: 12 | O52: 13 | P52: 14 | Q52: 15 | R52: 16 | S52: 17 | T52: 18 | U52: 19 | V52: 20
B53: 1 | C53: {=MMULT(C29:V48,TRANSPOSE(C29:V48))-C5:V24} -> 0 | D53: -0.45 | E53: -0.45 | F53: -0.45 | G53: -0.15 | H53: -0.15 | I53: -0.15 | J53: -0.15 | K53: -0.15 | L53: -0.15 | M53: -0.1 | N53: -0.1 | O53: -0.1 | P53: -0.1 | Q53: -0.1 | R53: -0.1 | S53: -0.1 | T53: -0.1 | U53: -0.1 | V53: -0.1
B54: 2 | C54: -0.45 | D54: 0 | E54: -0.45 | F54: -0.45 | G54: -0.15 | H54: -0.15 | I54: -0.15 | J54: -0.15 | K54: -0.15 | L54: -0.15 | M54: -0.1 | N54: -0.1 | O54: -0.1 | P54: -0.1 | Q54: -0.1 | R54: -0.1 | S54: -0.1 | T54: -0.1 | U54: -0.1 | V54: -0.1
B55: 3 | C55: -0.45 | D55: -0.45 | E55: 0 | F55: -0.45 | G55: -0.15 | H55: -0.15 | I55: -0.15 | J55: -0.15 | K55: -0.15 | L55: -0.15 | M55: -0.1 | N55: -0.1 | O55: -0.1 | P55: -0.1 | Q55: -0.1 | R55: -0.1 | S55: -0.1 | T55: -0.1 | U55: -0.1 | V55: -0.1
B56: 4 | C56: -0.45 | D56: -0.45 | E56: -0.45 | F56: 0 | G56: -0.15 | H56: -0.15 | I56: -0.15 | J56: -0.15 | K56: -0.15 | L56: -0.15 | M56: -0.1 | N56: -0.1 | O56: -0.1 | P56: -0.1 | Q56: -0.1 | R56: -0.1 | S56: -0.1 | T56: -0.1 | U56: -0.1 | V56: -0.1
B57: 5 | C57: -0.15 | D57: -0.15 | E57: -0.15 | F57: -0.15 | G57: 0 | H57: -0.35 | I57: -0.35 | J57: -0.35 | K57: -0.35 | L57: -0.35 | M57: -0.2 | N57: -0.2 | O57: -0.2 | P57: -0.2 | Q57: -0.2 | R57: -0.15 | S57: -0.15 | T57: -0.15 | U57: -0.1 | V57: -0.1
B58: 6 | C58: -0.15 | D58: -0.15 | E58: -0.15 | F58: -0.15 | G58: -0.35 | H58: 0 | I58: -0.35 | J58: -0.35 | K58: -0.35 | L58: -0.35 | M58: -0.2 | N58: -0.2 | O58: -0.2 | P58: -0.2 | Q58: -0.2 | R58: -0.15 | S58: -0.15 | T58: -0.15 | U58: -0.1 | V58: -0.1
B59: 7 | C59: -0.15 | D59: -0.15 | E59: -0.15 | F59: -0.15 | G59: -0.35 | H59: -0.35 | I59: 0 | J59: -0.35 | K59: -0.35 | L59: -0.35 | M59: -0.2 | N59: -0.2 | O59: -0.2 | P59: -0.2 | Q59: -0.2 | R59: -0.15 | S59: -0.15 | T59: -0.15 | U59: -0.1 | V59: -0.1
B60: 8 | C60: -0.15 | D60: -0.15 | E60: -0.15 | F60: -0.15 | G60: -0.35 | H60: -0.35 | I60: -0.35 | J60: 0 | K60: -0.35 | L60: -0.35 | M60: -0.2 | N60: -0.2 | O60: -0.2 | P60: -0.2 | Q60: -0.2 | R60: -0.15 | S60: -0.15 | T60: -0.15 | U60: -0.1 | V60: -0.1
...

Sheet Simulation Run
J2: 6. Simulated Portfolio
B3: 1. Portfolio | G3: 3. Latent Variables | J3: Rating | L3: MTM mode | N3: Default-only mode | Q3: 4. Cumulative Probabilities (see section 8.4) | AA3: 2. Choleski Decomposition of Correlation Matrix
B4: Bond | C4: Rating | D4: Face | E4: Index | G4: Uncorrel | H4: Correl | J4: Index | K4: Rating | L4: Price | M4: Value | N4: Price | O4: Value | R4: AAA | S4: AA | T4: A | U4: BBB | V4: BB | W4: B | X4: CCC | Y4: D | AA4: Firm | AB4: 1 | AC4: 2 | AD4: 3 | AE4: 4 | AF4: 5 | AG4: 6 | AH4: 7 | AI4: 8 | AJ4: 9 | AK4: 10 | AL4: 11 | AM4: 12 | AN4: 13 | AO4: 14 | AP4: 15 | AQ4: 16 | AR4: 17 | AS4: 18 | AT4: 19 | AU4: 20
B5: =Probabilities!M5 -> 1 | C5: =Probabilities!N5 -> AAA | D5: =Probabilities!O5 -> 7 | E5: =Probabilities!P5 -> 1 | G5: =NORMSINV(RAND()) -> -1.5162855 | H5: {=MMULT(AB5:AU24,$G$5:$G$24)} -> -1.5162855 | J5: 1 | K5: =INDEX($Q$5:$Q$12,J5) -> AAA | L5: =INDEX(Values!R5:Y5,J5) -> 1.0658806 | M5: =L5*D5 -> 7.4611643 | N5: =IF(J5=8,Values!Y5,1) -> 1 | O5: =D5*N5 -> 7 | Q5: AAA | R5: 1 | S5: 0.9 | T5: 0.8 | U5: 0.7 | V5: 0.6 | W5: 0.5 | X5: 0.4 | Y5: 0.3 | AA5: 1 | AB5: =Correlations!C29 -> 1 | AC5: =Correlations!D29 -> 0 | AD5: =Correlations!E29 -> 0 | AE5: =Correlations!F29 -> 0 | AF5: =Correlations!G29 -> 0 | AG5: =Correlations!H29 -> 0 | AH5: =Correlations!I29 -> 0 | AI5: =Correlations!J29 -> 0 | ... AU5: =Correlations!V29 -> 0
B6: =Probabilities!M6 -> 2 | C6: =Probabilities!N6 -> AA | D6: =Probabilities!O6 -> 1 | E6: =Probabilities!P6 -> 2 | G6: =NORMSINV(RAND()) -> 0.32677174 | H6: 0.32677174 | J6: 2 | K6: =INDEX($Q$5:$Q$12,J6) -> AA | L6: =INDEX(Values!R6:Y6,J6) -> 1.0765515 | M6: =L6*D6 -> 1.0765515 | N6: =IF(J6=8,Values!Y6,1) -> 1 | O6: =D6*N6 -> 1 | Q6: AA | R6: 1 | S6: 0.9 | T6: 0.8 | U6: 0.7 | V6: 0.6 | W6: 0.5 | X6: 0.4 | Y6: 0.3 | AA6: 2 | AB6: =Correlations!C30 -> 0 | AC6: =Correlations!D30 -> 1 | AD6: =Correlations!E30 -> 0 | AE6: =Correlations!F30 -> 0 | AF6: =Correlations!G30 -> 0 | AG6: =Correlations!H30 -> 0 | AH6: =Correlations!I30 -> 0 | AI6: =Correlations!J30 -> 0 | ... AU6: =Correlations!V30 -> 0
B7: =Probabilities!M7 -> 3 | C7: =Probabilities!N7 -> A | D7: =Probabilities!O7 -> 1 | E7: =Probabilities!P7 -> 3 | G7: =NORMSINV(RAND()) -> 0.72187155 | H7: 0.72187155 | J7: 4 | K7: =INDEX($Q$5:$Q$12,J7) -> BBB | L7: =INDEX(Values!R7:Y7,J7) -> 1.0679199 | M7: =L7*D7 -> 1.0679199 | N7: =IF(J7=8,Values!Y7,1) -> 1 | O7: =D7*N7 -> 1 | Q7: A | R7: 1 | S7: 0.9 | T7: 0.8 | U7: 0.7 | V7: 0.6 | W7: 0.5 | X7: 0.4 | Y7: 0.3 | AA7: 3 | AB7: =Correlations!C31 -> 0 | AC7: =Correlations!D31 -> 0 | AD7: =Correlations!E31 -> 1 | AE7: =Correlations!F31 -> 0 | AF7: =Correlations!G31 -> 0 | AG7: =Correlations!H31 -> 0 | AH7: =Correlations!I31 -> 0 | AI7: =Correlations!J31 -> 0 | ... AU7: =Correlations!V31 -> 0
B8: =Probabilities!M8 -> 4 | C8: =Probabilities!N8 -> BBB | D8: =Probabilities!O8 -> 1 | E8: =Probabilities!P8 -> 4 | G8: =NORMSINV(RAND()) -> 0.67188888 | H8: 0.67188888 | J8: 3 | K8: =INDEX($Q$5:$Q$12,J8) -> A | L8: =INDEX(Values!R8:Y8,J8) -> 1.0979804 | M8: =L8*D8 -> 1.0979804 | N8: =IF(J8=8,Values!Y8,1) -> 1 | O8: =D8*N8 -> 1 | Q8: BBB | R8: 1 | S8: 0.9 | T8: 0.8 | U8: 0.7 | V8: 0.6 | W8: 0.5 | X8: 0.4 | Y8: 0.3 | AA8: 4 | AB8: =Correlations!C32 -> 0 | AC8: =Correlations!D32 -> 0 | AD8: =Correlations!E32 -> 0 | AE8: =Correlations!F32 -> 1 | AF8: =Correlations!G32 -> 0 | AG8: =Correlations!H32 -> 0 | AH8: =Correlations!I32 -> 0 | AI8: =Correlations!J32 -> 0 | ... AU8: =Correlations!V32 -> 0
B9: =Probabilities!M9 -> 5 | C9: =Probabilities!N9 -> BB | D9: =Probabilities!O9 -> 1 | E9: =Probabilities!P9 -> 5 | G9: =NORMSINV(RAND()) -> 1.761078 | H9: 1.761078 | J9: 6 | K9: =INDEX($Q$5:$Q$12,J9) -> B | L9: =INDEX(Values!R9:Y9,J9) -> 1.0854435 | M9: =L9*D9 -> 1.0854435 | N9: =IF(J9=8,Values!Y9,1) -> 1 | O9: =D9*N9 -> 1 | Q9: BB | R9: 1 | S9: 0.9 | T9: 0.8 | U9: 0.7 | V9: 0.6 | W9: 0.5 | X9: 0.4 | Y9: 0.3 | AA9: 5 | AB9: =Correlations!C33 -> 0 | AC9: =Correlations!D33 -> 0 | AD9: =Correlations!E33 -> 0 | AE9: =Correlations!F33 -> 0 | AF9: =Correlations!G33 -> 1 | AG9: =Correlations!H33 -> 0 | AH9: =Correlations!I33 -> 0 | AI9: =Correlations!J33 -> 0 | ... AU9: =Correlations!V33 -> 0
B10: =Probabilities!M10 -> 6 | C10: =Probabilities!N10 -> B | D10: =Probabilities!O10 -> 1 | E10: =Probabilities!P10 -> 6 | G10: =NORMSINV(RAND()) -> 0.47239993 | H10: 0.47239993 | J10: 7 | K10: =INDEX($Q$5:$Q$12,J10) -> CCC | L10: =INDEX(Values!R10:Y10,J10) -> 1.0301258 | M10: =L10*D10 -> 1.0301258 | N10: =IF(J10=8,Values!Y10,1) -> 1 | O10: =D10*N10 -> 1 | Q10: B | R10: 1 | S10: 0.9 | T10: 0.8 | U10: 0.7 | V10: 0.6 | W10: 0.5 | X10: 0.4 | Y10: 0.3 | AA10: 6 | AB10: =Correlations!C34 -> 0 | AC10: =Correlations!D34 -> 0 | AD10: =Correlations!E34 -> 0 | AE10: =Correlations!F34 -> 0 | AF10: =Correlations!G34 -> 0 | AG10: =Correlations!H34 -> 1 | AH10: =Correlations!I34 -> 0 | AI10: =Correlations!J34 -> 0 | ... AU10: =Correlations!V34 -> 0
B11: =Probabilities!M11 -> 7 | C11: =Probabilities!N11 -> CCC | D11: =Probabilities!O11 -> 1 | E11: =Probabilities!P11 -> 7 | G11: =NORMSINV(RAND()) -> -0.38019766 | H11: -0.38019766 | J11: 7 | K11: =INDEX($Q$5:$Q$12,J11) -> CCC | L11: =INDEX(Values!R11:Y11,J11) -> 1.2833992 | M11: =L11*D11 -> 1.2833992 | N11: =IF(J11=8,Values!Y11,1) -> 1 | O11: =D11*N11 -> 1 | Q11: CCC | R11: 1 | S11: 0.9 | T11: 0.8 | U11: 0.7 | V11: 0.6 | W11: 0.5 | X11: 0.4 | Y11: 0.3 | AA11: 7 | AB11: =Correlations!C35 -> 0 | AC11: =Correlations!D35 -> 0 | AD11: =Correlations!E35 -> 0 | AE11: =Correlations!F35 -> 0 | AF11: =Correlations!G35 -> 0 | AG11: =Correlations!H35 -> 0 | AH11: =Correlations!I35 -> 1 | AI11: =Correlations!J35 -> 0 | ... AU11: =Correlations!V35 -> 0
B12: =Probabilities!M12 -> 8 | C12: =Probabilities!N12 -> A | D12: =Probabilities!O12 -> 10 | E12: =Probabilities!P12 -> 3 | G12: =NORMSINV(RAND()) -> 0.49050952 | H12: 0.49050952 | J12: 3 | K12: =INDEX($Q$5:$Q$12,J12) -> A | L12: =INDEX(Values!R12:Y12,J12) -> 1.116942 | M12: =L12*D12 -> 11.16942 | N12: =IF(J12=8,Values!Y12,1) -> 1 | O12: =D12*N12 -> 10 | Q12: D | R12: =SUM(Probabilities!C12:$J12) -> 1 | S12: =SUM(Probabilities!D12:$J12) -> 1 | T12: =SUM(Probabilities!E12:$J12) -> 1 | U12: =SUM(Probabilities!F12:$J12) -> 1 | V12: =SUM(Probabilities!G12:$J12) -> 1 | W12: =SUM(Probabilities!H12:$J12) -> 1 | X12: =SUM(Probabilities!I12:$J12) -> 1 | Y12: =SUM(Probabilities!J12:$J12) -> 1 | AA12: 8 | AB12: =Correlations!C36 -> 0 | AC12: =Correlations!D36 -> 0 | AD12: =Correlations!E36 -> 0 | AE12: =Correlations!F36 -> 0 | AF12: =Correlations!G36 -> 0 | AG12: =Correlations!H36 -> 0 | AH12: =Correlations!I36 -> 0 | AI12: =Correlations!J36 -> 1 | ... AU12: =Correlations!V36 -> 0
B13: =Probabilities!M13 -> 9 | C13: =Probabilities!N13 -> BB | D13: =Probabilities!O13 -> 5 | E13: =Probabilities!P13 -> 5 | G13: =NORMSINV(RAND()) -> 0.6492541 | H13: 0.6492541 | J13: 5 | K13: =INDEX($Q$5:$Q$12,J13) -> BB | L13: =INDEX(Values!R13:Y13,J13) -> 1.0905535 | M13: =L13*D13 -> 5.4527676 | N13: =IF(J13=8,Values!Y13,1) -> 1 | O13: =D13*N13 -> 5 | AA13: 9 | AB13: =Correlations!C37 -> 0 | AC13: =Correlations!D37 -> 0 | AD13: =Correlations!E37 -> 0 | AE13: =Correlations!F37 -> 0 | AF13: =Correlations!G37 -> 0 | AG13: =Correlations!H37 -> 0 | AH13: =Correlations!I37 -> 0 | AI13: =Correlations!J37 -> 0 | ... AU13: =Correlations!V37 -> 0
B14: =Probabilities!M14 -> 10 | C14: =Probabilities!N14 -> A | D14: =Probabilities!O14 -> 3 | E14: =Probabilities!P14 -> 3 | G14: =NORMSINV(RAND()) -> -1.4321346 | H14: -1.4321346 | J14: 3 | K14: =INDEX($Q$5:$Q$12,J14) -> A | L14: =INDEX(Values!R14:Y14,J14) -> 1.0703939 | M14: =L14*D14 -> 3.2111816 | N14: =IF(J14=8,Values!Y14,1) -> 1 | O14: =D14*N14 -> 3 | AA14: 10 | AB14: =Correlations!C38 -> 0 | AC14: =Correlations!D38 -> 0 | AD14: =Correlations!E38 -> 0 | AE14: =Correlations!F38 -> 0 | AF14: =Correlations!G38 -> 0 | AG14: =Correlations!H38 -> 0 | AH14: =Correlations!I38 -> 0 | AI14: =Correlations!J38 -> 0 | ... AU14: =Correlations!V38 -> 0
B15: =Probabilities!M15 -> 11 | C15: =Probabilities!N15 -> A | D15: =Probabilities!O15 -> 1 | E15: =Probabilities!P15 -> 3 | G15: =NORMSINV(RAND()) -> 0.99040204 | H15: 0.99040204 | J15: 2 | K15: =INDEX($Q$5:$Q$12,J15) -> AA | L15: =INDEX(Values!R15:Y15,J15) -> 1.0844364 | M15: =L15*D15 -> 1.0844364 | N15: =IF(J15=8,Values!Y15,1) -> 1 | O15: =D15*N15 -> 1 | Q15: 5. Critical Points of Normal Distribution (see section 8.4) | AA15: 11 | AB15: =Correlations!C39 -> 0 | AC15: =Correlations!D39 -> 0 | AD15: =Correlations!E39 -> 0 | AE15: =Correlations!F39 -> 0 | AF15: =Correlations!G39 -> 0 | AG15: =Correlations!H39 -> 0 | AH15: =Correlations!I39 -> 0 | AI15: =Correlations!J39 -> 0 | ... AU15: =Correlations!V39 -> 0
B16: =Probabilities!M16 -> 12 | C16: =Probabilities!N16 -> A | D16: =Probabilities!O16 -> 2 | E16: =Probabilities!P16 -> 3 | G16: =NORMSINV(RAND()) -> -0.45784445 | H16: -0.45784445 | J16: 3 | K16: =INDEX($Q$5:$Q$12,J16) -> A | L16: =INDEX(Values!R16:Y16,J16) -> 1.0873422 | M16: =L16*D16 -> 2.1746844 | N16: =IF(J16=8,Values!Y16,1) -> 1 | O16: =D16*N16 -> 2 | R16: AAA | S16: AA | T16: A | U16: BBB | V16: BB | W16: B | X16: CCC | Y16: D | AA16: 12 | AB16: =Correlations!C40 -> 0 | AC16: =Correlations!D40 -> 0 | AD16: =Correlations!E40 -> 0 | AE16: =Correlations!F40 -> 0 | AF16: =Correlations!G40 -> 0 | AG16: =Correlations!H40 -> 0 | AH16: =Correlations!I40 -> 0 | AI16: =Correlations!J40 -> 0 | ... AU16: =Correlations!V40 -> 0
B17: =Probabilities!M17 -> 13 | C17: =Probabilities!N17 -> B | D17: =Probabilities!O17 -> 0.6 | E17: =Probabilities!P17 -> 6 | G17: =NORMSINV(RAND()) -> 0.71069109 | H17: 0.71069109 | J17: 6 | K17: =INDEX($Q$5:$Q$12,J17) -> B | L17: =INDEX(Values!R17:Y17,J17) -> 1.1716151 | M17: =L17*D17 -> 0.70296903 | N17: =IF(J17=8,Values!Y17,1) -> 1 | O17: =D17*N17 -> 0.6 | Q17: AAA | R17: 100 | S17: =NORMSINV(S5) -> 1.2815516 | T17: =NORMSINV(T5) -> 0.84162123 | U17: =NORMSINV(U5) -> 0.52440051 | V17: =NORMSINV(V5) -> 0.2533471 | W17: =NORMSINV(W5) -> 0 | X17: =NORMSINV(X5) -> -0.2533471 | Y17: =NORMSINV(Y5) -> -0.52440051 | AA17: 13 | AB17: =Correlations!C41 -> 0 | AC17: =Correlations!D41 -> 0 | AD17: =Correlations!E41 -> 0 | AE17: =Correlations!F41 -> 0 | AF17: =Correlations!G41 -> 0 | AG17: =Correlations!H41 -> 0 | AH17: =Correlations!I41 -> 0 | AI17: =Correlations!J41 -> 0 | ... AU17: =Correlations!V41 -> 0
B18: =Probabilities!M18 -> 14 | C18: =Probabilities!N18 -> B | D18: =Probabilities!O18 -> 1 | E18: =Probabilities!P18 -> 6 | G18: =NORMSINV(RAND()) -> 0.52919636 | H18: 0.52919636 | J18: 8 | K18: =INDEX($Q$5:$Q$12,J18) -> D | L18: =INDEX(Values!R18:Y18,J18) -> 0.05761194 | M18: =L18*D18 -> 0.05761194 | N18: =IF(J18=8,Values!Y18,1) -> 0.05761194 | O18: =D18*N18 -> 0.05761194 | Q18: AA | R18: 100 | S18: =NORMSINV(S6) -> 1.2815516 | T18: =NORMSINV(T6) -> 0.84162123 | U18: =NORMSINV(U6) -> 0.52440051 | V18: =NORMSINV(V6) -> 0.2533471 | W18: =NORMSINV(W6) -> 0 | X18: =NORMSINV(X6) -> -0.2533471 | Y18: =NORMSINV(Y6) -> -0.52440051 | AA18: 14 | AB18: =Correlations!C42 -> 0 | AC18: =Correlations!D42 -> 0 | AD18: =Correlations!E42 -> 0 | AE18: =Correlations!F42 -> 0 | AF18: =Correlations!G42 -> 0 | AG18: =Correlations!H42 -> 0 | AH18: =Correlations!I42 -> 0 | AI18: =Correlations!J42 -> 0 | ... AU18: =Correlations!V42 -> 0
B19: =Probabilities!M19 -> 15 | C19: =Probabilities!N19 -> B | D19: =Probabilities!O19 -> 3 | E19: =Probabilities!P19 -> 6 | G19: =NORMSINV(RAND()) -> 0.95702665 | H19: 0.95702665 | J19: 6 | K19: =INDEX($Q$5:$Q$12,J19) -> B | L19: =INDEX(Values!R19:Y19,J19) -> 1.1444355 | M19: =L19*D19 -> 3.4333065 | N19: =IF(J19=8,Values!Y19,1) -> 1 | O19: =D19*N19 -> 3 | Q19: A | R19: 100 | S19: =NORMSINV(S7) -> 1.2815516 | T19: =NORMSINV(T7) -> 0.84162123 | U19: =NORMSINV(U7) -> 0.52440051 | V19: =NORMSINV(V7) -> 0.2533471 | W19: =NORMSINV(W7) -> 0 | X19: =NORMSINV(X7) -> -0.2533471 | Y19: =NORMSINV(Y7) -> -0.52440051 | AA19: 15 | AB19: =Correlations!C43 -> 0 | AC19: =Correlations!D43 -> 0 | AD19: =Correlations!E43 -> 0 | AE19: =Correlations!F43 -> 0 | AF19: =Correlations!G43 -> 0 | AG19: =Correlations!H43 -> 0 | AH19: =Correlations!I43 -> 0 | AI19: =Correlations!J43 -> 0 | ... AU19: =Correlations!V43 -> 0
B20: =Probabilities!M20 -> 16 | C20: =Probabilities!N20 -> B | D20: =Probabilities!O20 -> 2 | E20: =Probabilities!P20 -> 6 | G20: =NORMSINV(RAND()) -> -1.6713872 | H20: -1.6713872 | J20: 3 | K20: =INDEX($Q$5:$Q$12,J20) -> A | L20: =INDEX(Values!R20:Y20,J20) -> 1.2610443 | M20: =L20*D20 -> 2.5220886 | N20: =IF(J20=8,Values!Y20,1) -> 1 | O20: =D20*N20 -> 2 | Q20: BBB | R20: 100 | S20: =NORMSINV(S8) -> 1.2815516 | T20: =NORMSINV(T8) -> 0.84162123 | U20: =NORMSINV(U8) -> 0.52440051 | V20: =NORMSINV(V8) -> 0.2533471 | W20: =NORMSINV(W8) -> 0 | X20: =NORMSINV(X8) -> -0.2533471 | Y20: =NORMSINV(Y8) -> -0.52440051 | AA20: 16 | AB20: =Correlations!C44 -> 0 | AC20: =Correlations!D44 -> 0 | AD20: =Correlations!E44 -> 0 | AE20: =Correlations!F44 -> 0 | AF20: =Correlations!G44 -> 0 | AG20: =Correlations!H44 -> 0 | AH20: =Correlations!I44 -> 0 | AI20: =Correlations!J44 -> 0 | ... AU20: =Correlations!V44 -> 0
B21: =Probabilities!M21 -> 17 | C21: =Probabilities!N21 -> BBB | D21: =Probabilities!O21 -> 1 | E21: =Probabilities!P21 -> 4 | G21: =NORMSINV(RAND()) -> 0.50537074 | H21: 0.50537074 | J21: 4 | K21: =INDEX($Q$5:$Q$12,J21) -> BBB | L21: =INDEX(Values!R21:Y21,J21) -> 1.1083032 | M21: =L21*D21 -> 1.1083032 | N21: =IF(J21=8,Values!Y21,1) -> 1 | O21: =D21*N21 -> 1 | Q21: BB | R21: 100 | S21: =NORMSINV(S9) -> 1.2815516 | T21: =NORMSINV(T9) -> 0.84162123 | U21: =NORMSINV(U9) -> 0.52440051 | V21: =NORMSINV(V9) -> 0.2533471 | W21: =NORMSINV(W9) -> 0 | X21: =NORMSINV(X9) -> -0.2533471 | Y21: =NORMSINV(Y9) -> -0.52440051 | AA21: 17 | AB21: =Correlations!C45 -> 0 | AC21: =Correlations!D45 -> 0 | AD21: =Correlations!E45 -> 0 | AE21: =Correlations!F45 -> 0 | AF21: =Correlations!G45 -> 0 | AG21: =Correlations!H45 -> 0 | AH21: =Correlations!I45 -> 0 | AI21: =Correlations!J45 -> 0 | ... AU21: =Correlations!V45 -> 0
B22: =Probabilities!M22 -> 18 | C22: =Probabilities!N22 -> BBB | D22: =Probabilities!O22 -> 8 | E22: =Probabilities!P22 -> 4 | G22: =NORMSINV(RAND()) -> 0.21068103 | H22: 0.21068103 | J22: 4 | K22: =INDEX($Q$5:$Q$12,J22) -> BBB | L22: =INDEX(Values!R22:Y22,J22) -> 1.0970742 | M22: =L22*D22 -> 8.7765934 | N22: =IF(J22=8,Values!Y22,1) -> 1 | O22: =D22*N22 -> 8 | Q22: B | R22: 100 | S22: =NORMSINV(S10) -> 1.2815516 | T22: =NORMSINV(T10) -> 0.84162123 | U22: =NORMSINV(U10) -> 0.52440051 | V22: =NORMSINV(V10) -> 0.2533471 | W22: =NORMSINV(W10) -> 0 | X22: =NORMSINV(X10) -> -0.2533471 | Y22: =NORMSINV(Y10) -> -0.52440051 | AA22: 18 | AB22: =Correlations!C46 -> 0 | AC22: =Correlations!D46 -> 0 | AD22: =Correlations!E46 -> 0 | AE22: =Correlations!F46 -> 0 | AF22: =Correlations!G46 -> 0 | AG22: =Correlations!H46 -> 0 | AH22: =Correlations!I46 -> 0 | AI22: =Correlations!J46 -> 0 | ... AU22: =Correlations!V46 -> 0
B23: =Probabilities!M23 -> 19 | C23: =Probabilities!N23 -> BBB | D23: =Probabilities!O23 -> 1 | E23: =Probabilities!P23 -> 4 | G23: =NORMSINV(RAND()) -> 0.6895229 | H23: 0.6895229 | J23: 4 | K23: =INDEX($Q$5:$Q$12,J23) -> BBB | L23: =INDEX(Values!R23:Y23,J23) -> 1.0814248 | M23: =L23*D23 -> 1.0814248 | N23: =IF(J23=8,Values!Y23,1) -> 1 | O23: =D23*N23 -> 1 | Q23: CCC | R23: 100 | S23: =NORMSINV(S11) -> 1.2815516 | T23: =NORMSINV(T11) -> 0.84162123 | U23: =NORMSINV(U11) -> 0.52440051 | V23: =NORMSINV(V11) -> 0.2533471 | W23: =NORMSINV(W11) -> 0 | X23: =NORMSINV(X11) -> -0.2533471 | Y23: =NORMSINV(Y11) -> -0.52440051 | AA23: 19 | AB23: =Correlations!C47 -> 0 | AC23: =Correlations!D47 -> 0 | AD23: =Correlations!E47 -> 0 | AE23: =Correlations!F47 -> 0 | AF23: =Correlations!G47 -> 0 | AG23: =Correlations!H47 -> 0 | AH23: =Correlations!I47 -> 0 | AI23: =Correlations!J47 -> 0 | ... AU23: =Correlations!V47 -> 0
B24: =Probabilities!M24 -> 20 | C24: =Probabilities!N24 -> AA | D24: =Probabilities!O24 -> 5 | E24: =Probabilities!P24 -> 2 | G24: =NORMSINV(RAND()) -> -0.26143352 | H24: -0.26143352 | J24: 2 | K24: =INDEX($Q$5:$Q$12,J24) -> AA | L24: =INDEX(Values!R24:Y24,J24) -> 1.0830367 | M24: =L24*D24 -> 5.4151833 | N24: =IF(J24=8,Values!Y24,1) -> 1 | O24: =D24*N24 -> 5 | Q24: D | R24: 100 | S24: 100 | T24: 100 | U24: 100 | V24: 100 | W24: 100 | X24: 100 | Y24: 100 | AA24: 20 | AB24: =Correlations!C48 -> 0 | AC24: =Correlations!D48 -> 0 | AD24: =Correlations!E48 -> 0 | AE24: =Correlations!F48 -> 0 | AF24: =Correlations!G48 -> 0 | AG24: =Correlations!H48 -> 0 | AH24: =Correlations!I48 -> 0 | AI24: =Correlations!J48 -> 0 | ... AU24: =Correlations!V48 -> 1
L26: Portfolio value, this run = | M26: =SUM(M5:M24) -> 60.292556 | O26: =SUM(O5:O24) -> 54.657612
L27: Expected Portfolio Value = | M27: =Probabilities!AC27 -> 60.683236 | O27: =Probabilities!AE27 -> 55.106176
L28: Profit = | M28: =M26-M27 -> -0.39067962 | O28: =O26-O27 -> -0.44856378

Sheet Results
I3: Bins | J3: Freq
I4: -15.5 | J4: {=FREQUENCY(A:A,I4:I23)} -> 0 | L4: <-15 | M4: =J4/N -> 0
D5: 10000 | E5: = Number of Runs | I5: =I4+1 -> -14.5 | J5: 0 | L5: -15 | M5: =J5/N -> 0
I6: =I5+1 -> -13.5 | J6: 0 | L6: =L5+1 -> -14 | M6: =J6/N -> 0
I7: =I6+1 -> -12.5 | J7: 0 | L7: =L6+1 -> -13 | M7: =J7/N -> 0
E8: XS Profit Stats | I8: =I7+1 -> -11.5 | J8: 0 | L8: =L7+1 -> -12 | M8: =J8/N -> 0
F9: MTM | G9: DM | I9: =I8+1 -> -10.5 | J9: 0 | L9: =L8+1 -> -11 | M9: =J9/N -> 0
