Workbook

Sheet Eff4
A1: Inputs:
B2: Correlation Matrix
B3: 1 | C3: 2 | D3: 3 | E3: 4
A4: 1 | B4: 1 | C4: 0.26103539 | D4: 0.29397414 | E4: 0.32109094
A5: 2 | B5: 0.26103539 | C5: 1 | D5: 0.34651847 | E5: 0.37848207
A6: 3 | B6: 0.29397414 | C6: 0.34651847 | D6: 1 | E6: 0.42624083
A7: 4 | B7: 0.32109094 | C7: 0.37848207 | D7: 0.42624083 | E7: 1
B9: E(R) | D9: Vol/Std Dev
A10: 1 | B10: 0.12573651 | D10: 0.34
A11: 2 | B11: 0.11502593 | D11: 0.36055513 | F11: R_f | G11: 0.05
A12: 3 | B12: 0.12431534 | D12: 0.38418745
A13: 4 | B13: 0.13360476 | D13: 0.41036569
A15: Outputs: | C15: Note: The equations here are almost all implemented using array
C16: functions. These are functions that multiply groups of numbers
C17: (like vectors or matricies). If you change these functions, you will
C18: have to press CNTL-SHIFT-ENTER to re-enter them properly. You
C19: should not have to change anything for the homework assignment.
C20: stdev | D20: {=TRANSPOSE(D10:D13)} -> 0.34 | E20: 0.36055513 | F20: 0.38418745 | G20: 0.41036569
D21: Covariance Matrix
B22: stdev | D22: 1 | E22: 2 | F22: 3 | G22: 4 | I22: ones
B23: {=D10:D13} -> 0.34 | C23: 1 | D23: =B4*D$20*$B23 -> 0.1156 | E23: =C4*E$20*$B23 -> 0.032 | F23: =D4*F$20*$B23 -> 0.0384 | G23: =E4*G$20*$B23 -> 0.0448 | I23: 1
B24: 0.36055513 | C24: 2 | D24: =B5*D$20*$B24 -> 0.032 | E24: =C5*E$20*$B24 -> 0.13 | F24: =D5*F$20*$B24 -> 0.048 | G24: =E5*G$20*$B24 -> 0.056 | I24: 1
B25: 0.38418745 | C25: 3 | D25: =B6*D$20*$B25 -> 0.0384 | E25: =C6*E$20*$B25 -> 0.048 | F25: =D6*F$20*$B25 -> 0.1476 | G25: =E6*G$20*$B25 -> 0.0672 | I25: 1
B26: 0.41036569 | C26: 4 | D26: =B7*D$20*$B26 -> 0.0448 | E26: =C7*E$20*$B26 -> 0.056 | F26: =D7*F$20*$B26 -> 0.0672 | G26: =E7*G$20*$B26 -> 0.1684 | I26: 1
A28: Portfolio Weghts | D28: MV | E28: P | F28: MVE
C29: 1 | D29: {=MMULT(MINVERSE($D$23:$G$26),$I$23:$I$26)/H29} -> 0.38469388 | E29: {=MMULT(MINVERSE($D$23:$G$26),$B$10:$B$13)/H30} -> 0.39356204 | F29: {=MMULT(MINVERSE($D$23:$G$26),$B$10:$B$13-$G$11)/H31} -> 0.39962005 | G29: k1 | H29: {=MMULT(TRANSPOSE(I23:I26),MMULT(MINVERSE($D$23:$G$26),$I$23:$I$26))} -> 14.936747
C30: 2 | D30: 0.29489796 | E30: 0.23747128 | F30: 0.19824206 | G30: k2 | H30: {=MMULT(TRANSPOSE(I23:I26),MMULT(MINVERSE($D$23:$G$26),$B$10:$B$13))} -> 1.840114
C31: 3 | D31: 0.20510204 | E31: 0.20214599 | F31: 0.20012665 | G31: k3 | H31: {=MMULT(TRANSPOSE(I23:I26),MMULT(MINVERSE($D$23:$G$26),$B$10:$B$13-$G$11))} -> 1.0932766
C32: 4 | D32: 0.11530612 | E32: 0.16682069 | F32: 0.20201124
C33: sum | D33: =SUM(D29:D32) -> 1 | E33: =SUM(E29:E32) -> 1 | F33: =SUM(F29:F32) -> 1
C35: E(R) | D35: {=MMULT(TRANSPOSE(D29:D32),$B$10:$B$13)} -> 0.12319375 | E35: {=MMULT(TRANSPOSE(E29:E32),$B$10:$B$13)} -> 0.12421836 | F35: {=MMULT(TRANSPOSE(F29:F32),$B$10:$B$13)} -> 0.12491828
C36: VAR | D36: {=MMULT(MMULT(TRANSPOSE(D29:D32),$D$23:$G$26),D29:D32)} -> 0.06694898 | E36: {=MMULT(MMULT(TRANSPOSE(E29:E32),$D$23:$G$26),E29:E32)} -> 0.067505795 | F36: {=MMULT(MMULT(TRANSPOSE(F29:F32),$D$23:$G$26),F29:F32)} -> 0.068526375
C37: STD DEV | D37: =SQRT(D36) -> 0.25874501 | E37: =SQRT(E36) -> 0.25981877 | F37: =SQRT(F36) -> 0.26177543
D39: MV | E39: P | F39: MVE
A40: Covariance | C40: MV | D40: {=MMULT(MMULT(TRANSPOSE(D29:F32),D23:G26),D29:F32)} -> 0.06694898 | E40: 0.06694898 | F40: 0.06694898
A41: Matrix | C41: P | D41: 0.06694898 | E41: 0.067505795 | F41: 0.067886166
C42: WVE | D42: 0.06694898 | E42: 0.067886166 | F42: 0.068526375

Sheet Problem Data
A2: Security | B2: Variance | C2: Stdev | D2: Market Value
A3: A | B3: 0.1156 | C3: =SQRT(B3) -> 0.34 | D3: 239363.24
A4: B | B4: 0.13 | C4: =SQRT(B4) -> 0.36055513 | D4: 246454.41
A5: C | B5: 0.1476 | C5: =SQRT(B5) -> 0.38418745 | D5: 253545.59
A6: D | B6: 0.1684 | C6: =SQRT(B6) -> 0.41036569 | D6: 260636.76
A8: Variance/Covariance Matrix:
B9: A | C9: B | D9: C | E9: D
A10: A | B10: 0.1156 | C10: 0.032 | D10: 0.0384 | E10: 0.0448
A11: B | B11: 0.032 | C11: 0.13 | D11: 0.048 | E11: 0.056
A12: C | B12: 0.0384 | C12: 0.048 | D12: 0.1476 | E12: 0.0672
A13: D | B13: 0.0448 | C13: 0.056 | D13: 0.0672 | E13: 0.1684
A15: Correlation Matrix:
B16: A | C16: B | D16: C | E16: D
A17: A | B17: 1 | C17: 0.26103539 | D17: 0.29397414 | E17: 0.32109094
A18: B | B18: 0.26103539 | C18: 1 | D18: 0.34651847 | E18: 0.37848207
A19: C | B19: 0.29397414 | C19: 0.34651847 | D19: 1 | E19: 0.42624083
A20: D | B20: 0.32109094 | C20: 0.37848207 | D20: 0.42624083 | E20: 1

Sheet Solution
A1: 1 | B1: To get the variance of the market portfolio, we just find its weights
B2: and then calculate its variance using the method in the
B3: portfolio_covariance example spreadsheet.
A5: Security | C5: Mkt Value | D5: weight
A6: A | C6: 239363.24 | D6: =C6/$C$10 -> 0.23936324
A7: B | C7: 246454.41 | D7: =C7/$C$10 -> 0.24645441
A8: C | C8: 253545.59 | D8: =C8/$C$10 -> 0.25354559
A9: D | C9: 260636.76 | D9: =C9/$C$10 -> 0.26063676
A10: Total | C10: =SUM(C6:C9) -> 1000000
C12: {=TRANSPOSE($D$6:$D$9)} -> 0.23936324 | D12: 0.24645441 | E12: 0.25354559 | F12: 0.26063676
C13: A | D13: B | E13: C | F13: D
A14: 0.23936324 | B14: A | C14: =C$12*$A14*'Problem Data'!B10 -> 0.0066232744 | D14: =D$12*$A14*'Problem Data'!C10 -> 0.0018877481 | E14: =E$12*$A14*'Problem Data'!D10 -> 0.0023304765 | F14: =F$12*$A14*'Problem Data'!E10 -> 0.0027949313
A15: 0.24645441 | B15: B | C15: =C$12*$A15*'Problem Data'!B11 -> 0.0018877481 | D15: =D$12*$A15*'Problem Data'!C11 -> 0.0078961712 | E15: =E$12*$A15*'Problem Data'!D11 -> 0.0029993966 | F15: =F$12*$A15*'Problem Data'!E11 -> 0.0035971645
A16: 0.25354559 | B16: C | C16: =C$12*$A16*'Problem Data'!B12 -> 0.0023304765 | D16: =D$12*$A16*'Problem Data'!C12 -> 0.0029993966 | E16: =E$12*$A16*'Problem Data'!D12 -> 0.0094885198 | F16: =F$12*$A16*'Problem Data'!E12 -> 0.0044407977
A17: 0.26063676 | B17: D | C17: =C$12*$A17*'Problem Data'!B13 -> 0.0027949313 | D17: =D$12*$A17*'Problem Data'!C13 -> 0.0035971645 | E17: =E$12*$A17*'Problem Data'!D13 -> 0.0044407977 | F17: =F$12*$A17*'Problem Data'!E13 -> 0.011439668
C19: Variance | D19: =SUM(C14:F17) -> 0.071548663
B21: To get the covariance of the market with A, for example, we
B22: just sum up the market weights on each of the four assets
B23: times their covariances with A. This is easy to do with the
B24: covariance matrix
A26: cov(Ri,Rm) | C26: {=TRANSPOSE($D$6:$D$9)} -> 0.23936324 | D26: 0.24645441 | E26: 0.25354559 | F26: 0.26063676
C27: A | D27: B | E27: C | F27: D
A28: =SUM(C28:F28) -> 0.056969609 | B28: A | C28: =C$26*'Problem Data'!B10 -> 0.027670391 | D28: =D$26*'Problem Data'!C10 -> 0.0078865412 | E28: =E$26*'Problem Data'!D10 -> 0.0097361505 | F28: =F$26*'Problem Data'!E10 -> 0.011676527
A29: =SUM(C29:F29) -> 0.066464544 | B29: B | C29: =C$26*'Problem Data'!B11 -> 0.0076596237 | D29: =D$26*'Problem Data'!C11 -> 0.032039074 | E29: =E$26*'Problem Data'!D11 -> 0.012170188 | F29: =F$26*'Problem Data'!E11 -> 0.014595658
A30: =SUM(C30:F30) -> 0.075959479 | B30: C | C30: =C$26*'Problem Data'!B12 -> 0.0091915485 | D30: =D$26*'Problem Data'!C12 -> 0.011829812 | E30: =E$26*'Problem Data'!D12 -> 0.037423329 | F30: =F$26*'Problem Data'!E12 -> 0.01751479
A31: =SUM(C31:F31) -> 0.085454414 | B31: D | C31: =C$26*'Problem Data'!B13 -> 0.010723473 | D31: =D$26*'Problem Data'!C13 -> 0.013801447 | E31: =E$26*'Problem Data'!D13 -> 0.017038263 | F31: =F$26*'Problem Data'!E13 -> 0.04389123
A34: 2 | B34: The betas are just the covariances divided by the market variances:
C35: Beta
B36: A | C36: =A28/$D$19 -> 0.79623584
B37: B | C37: =A29/$D$19 -> 0.92894181
B38: C | C38: =A30/$D$19 -> 1.0616478
B39: D | C39: =A31/$D$19 -> 1.1943538
A41: 3 | B41: The expected returns come from the CAPM:
C42: E(Rm)= | D42: 0.12
C43: Rf= | D43: 0.05
C44: E(Ri)
B45: A | C45: =$D$43+C36*($D$42-$D$43) -> 0.10573651
B46: B | C46: =$D$43+C37*($D$42-$D$43) -> 0.11502593
B47: C | C47: =$D$43+C38*($D$42-$D$43) -> 0.12431534
B48: D | C48: =$D$43+C39*($D$42-$D$43) -> 0.13360476
...

Sheet Sheet4

Sheet Sheet5

Sheet Sheet6

Sheet Sheet7

Sheet Sheet8

Sheet Sheet9

Sheet Sheet10

Sheet Sheet11

Sheet Sheet12

Sheet Sheet13

Sheet Sheet14

Sheet Sheet15

Sheet Sheet16
