Workbook
Name Rf: 'Data & RP'!$K$114

Sheet Data & RP
A1: Homework No. 8
A2: Financial Management
A3: Data for Problems 16-20 from Take-Home Test
A6: Date | B6: T. Days | C6: Disc Rate | D6: CMB | E6: COL | F6: F | G6: HWP | H6: INTC | I6: KO | J6: S&P500 | K6: Disc Rate | L6: RP CMB | M6: RP COL | N6: RP F | O6: RP HWP | P6: RP INTC | Q6: RP KO | R6: RP Port | S6: RP S&P
A7: 32295 | B7: 22 | C7: 0.005 | D7: 0.076577 | E7: 0.249839 | F7: 0.092308 | G7: -0.038759 | H7: 0.155894 | I7: 0.012882 | J7: 0.025547
A8: 32325 | B8: 21 | C8: 0.005 | D8: 0.008368 | E8: -0.057089 | F8: -0.004695 | G8: -0.094203 | H8: -0.03798 | I8: -0.016 | J8: -0.005411
A9: 32356 | B9: 23 | C9: 0.005408 | D9: -0.041494 | E9: 0.060545 | F9: -0.070755 | G9: -0.079208 | H9: -0.194291 | I9: 0.042318 | J9: -0.0386
A10: 32387 | B10: 22 | C10: 0.005408 | D10: 0.04329 | E10: 0 | F10: 0.038091 | G10: 0.072602 | H10: -0.017857 | I10: 0.0938 | J10: 0.039714
A11: 32417 | B11: 21 | C11: 0.005408 | D11: -0.037344 | E11: -0.085719 | F11: 0.007315 | G11: 0.012511 | H11: -0.099927 | I11: -0.014262 | J11: 0.025972
A12: 32448 | B12: 22 | C12: 0.005408 | D12: -0.038793 | E12: 0.156385 | F12: 0.009709 | G12: -0.042059 | H12: -0.171784 | I12: 0.00575 | J12: -0.018895
A13: 32478 | B13: 22 | C13: 0.005408 | D13: 0.026906 | E13: 0.162153 | F13: -0.028846 | G13: 0.100794 | H13: 0.158634 | I13: 0.028772 | J13: 0.014691
A14: 32509 | B14: 22 | C14: 0.005408 | D14: 0.100437 | E14: -0.023301 | F14: 0.081703 | G14: 0.084504 | H14: 0.094645 | I14: 0.047687 | J14: 0.071115
A15: 32540 | B15: 20 | C15: 0.005824 | D15: 0 | E15: 0 | F15: -0.054919 | G15: -0.043289 | H15: -0.009538 | I15: 0.021389 | J15: -0.028938
A16: 32568 | B16: 23 | C16: 0.005833 | D16: 0.202381 | E16: -0.166714 | F16: -0.053268 | G16: -0.070151 | H16: 0.019571 | I16: 0.073212 | J16: 0.020806
A17: 32599 | B17: 20 | C17: 0.005833 | D17: -0.029703 | E17: 0.14298 | F17: -0.023038 | G17: 0.10464 | H17: 0.104509 | I17: 0.058539 | J17: 0.05008
A18: 32629 | B18: 23 | C18: 0.005833 | D18: -0.006803 | E18: -0.025049 | F18: 0.020942 | G18: -0.048492 | H18: 0.12069 | I18: 0.064592 | J18: 0.035148
... A49: 33573 | B49: 22 | C49: 0.002917 | D49: 0.17 | E49: 0.1333 | F49: 0.188583 | G49: 0.18444 | H49: 0.195122 | I49: 0.160228 | J49: 0.111594
A50: Date | B50: T. Days | C50: Disc Rate | D50: CMB | E50: COL | F50: F | G50: HWP | H50: INTC | I50: KO | J50: S&P500 | K50: Disc Rate | L50: RP CMB | M50: RP COL | N50: RP F | O50: RP HWP | P50: RP INTC | Q50: RP KO | R50: RP Port | S50: RP S&P
A51: 33604 | B51: 23 | C51: 0.002917 | D51: 0.188406 | E51: 0.147093 | F51: 0.084406 | G51: 0.041684 | H51: 0.221959 | I51: -0.034292 | J51: -0.019924 | K51: 0.002917 | L51: =D51-$C51 -> 0.185489 | M51: =E51-$C51 -> 0.144176 | N51: =F51-$C51 -> 0.081489 | O51: =G51-$C51 -> 0.038767 | P51: =H51-$C51 -> 0.219042 | Q51: =I51-$C51 -> -0.037209 | R51: =SUM(L51:Q51)/6 -> 0.10529233 | S51: =J51-$C51 -> -0.022841
A52: 33635 | B52: 20 | C52: 0.002917 | D52: 0.182927 | E52: 0.038462 | F52: 0.204918 | G52: 0.232026 | H52: 0.060525 | I52: 0.054865 | J52: 0.009582 | K52: 0.002917 | L52: =D52-$C52 -> 0.18001 | M52: =E52-$C52 -> 0.035545 | N52: =F52-$C52 -> 0.202001 | O52: =G52-$C52 -> 0.229109 | P52: =H52-$C52 -> 0.057608 | Q52: =I52-$C52 -> 0.051948 | R52: =SUM(L52:Q52)/6 -> 0.12603683 | S52: =J52-$C52 -> 0.006665
A53: 33664 | B53: 22 | C53: 0.002917 | D53: -0.003093 | E53: 0.01237 | F53: 0.055129 | G53: 0.10274 | H53: -0.12989 | I53: 0.003425 | J53: -0.021832 | K53: 0.002917 | L53: =D53-$C53 -> -0.00601 | M53: =E53-$C53 -> 0.009453 | N53: =F53-$C53 -> 0.052212 | O53: =G53-$C53 -> 0.099823 | P53: =H53-$C53 -> -0.132807 | Q53: =I53-$C53 -> 0.000508 | R53: =SUM(L53:Q53)/6 -> 0.0038631667 | S53: =J53-$C53 -> -0.024749
A54: 33695 | B54: 22 | C54: 0.002917 | D54: 0.073298 | E54: -0.121973 | F54: 0.182406 | G54: -0.003727 | H54: -0.031709 | I54: 0.015266 | J54: 0.027893 | K54: 0.002917 | L54: =D54-$C54 -> 0.070381 | M54: =E54-$C54 -> -0.12489 | N54: =F54-$C54 -> 0.179489 | O54: =G54-$C54 -> -0.006644 | P54: =H54-$C54 -> -0.034626 | Q54: =I54-$C54 -> 0.012349 | R54: =SUM(L54:Q54)/6 -> 0.016009833 | S54: =J54-$C54 -> 0.024976
A55: 33725 | B55: 21 | C55: 0.002917 | D55: 0.082927 | E55: -0.013917 | F55: -0.022038 | G55: -0.05 | H55: -0.065421 | I55: 0.060241 | J55: 0.000971 | K55: 0.002917 | L55: =D55-$C55 -> 0.08001 | M55: =E55-$C55 -> -0.016834 | N55: =F55-$C55 -> -0.024955 | O55: =G55-$C55 -> -0.052917 | P55: =H55-$C55 -> -0.068338 | Q55: =I55-$C55 -> 0.057324 | R55: =SUM(L55:Q55)/6 -> -0.004285 | S55: =J55-$C55 -> -0.001946
A56: 33756 | B56: 22 | C56: 0.002917 | D56: 0.006306 | E56: -0.070396 | F56: 0.042816 | G56: -0.093737 | H56: 0.14 | I56: -0.087727 | J56: -0.017366 | K56: 0.002917 | L56: =D56-$C56 -> 0.003389 | M56: =E56-$C56 -> -0.073313 | N56: =F56-$C56 -> 0.039899 | O56: =G56-$C56 -> -0.096654 | P56: =H56-$C56 -> 0.137083 | Q56: =I56-$C56 -> -0.090644 | R56: =SUM(L56:Q56)/6 -> -0.013373333 | S56: =J56-$C56 -> -0.020283
A57: 33786 | B57: 23 | C57: 0.0025 | D57: -0.095023 | E57: 0.075727 | F57: -0.002747 | G57: 0.070039 | H57: 0.048281 | I57: 0.0469 | J57: 0.039377 | K57: 0.0025 | L57: =D57-$C57 -> -0.097523 | M57: =E57-$C57 -> 0.073227 | N57: =F57-$C57 -> -0.005247 | O57: =G57-$C57 -> 0.067539 | P57: =H57-$C57 -> 0.045781 | Q57: =I57-$C57 -> 0.0444 | R57: =SUM(L57:Q57)/6 -> 0.021362833 | S57: =J57-$C57 -> 0.036877
A58: 33817 | B58: 21 | C58: 0.0025 | D58: -0.09 | E58: -0.028142 | F58: -0.10929 | G58: -0.221061 | H58: -0.029321 | I58: 0.026841 | J58: -0.023993 | K58: 0.0025 | L58: =D58-$C58 -> -0.0925 | M58: =E58-$C58 -> -0.030642 | N58: =F58-$C58 -> -0.11179 | O58: =G58-$C58 -> -0.223561 | P58: =H58-$C58 -> -0.031821 | Q58: =I58-$C58 -> 0.024341 | R58: =SUM(L58:Q58)/6 -> -0.077662167 | S58: =J58-$C58 -> -0.026493
A59: 33848 | B59: 22 | C59: 0.0025 | D59: 0.002198 | E59: -0.014522 | F59: -0.020859 | G59: -0.0262 | H59: 0.135379 | I59: -0.054884 | J59: 0.009106 | K59: 0.0025 | L59: =D59-$C59 -> -0.000302 | M59: =E59-$C59 -> -0.017022 | N59: =F59-$C59 -> -0.023359 | O59: =G59-$C59 -> -0.0287 | P59: =H59-$C59 -> 0.132879 | Q59: =I59-$C59 -> -0.057384 | R59: =SUM(L59:Q59)/6 -> 0.0010186667 | S59: =J59-$C59 -> 0.006606
A60: 33878 | B60: 22 | C60: 0.0025 | D60: 0.066667 | E60: -0.117621 | F60: -0.075949 | G60: 0.020161 | H60: 0.026585 | I60: 0.003111 | J60: 0.002099 | K60: 0.0025 | L60: =D60-$C60 -> 0.064167 | M60: =E60-$C60 -> -0.120121 | N60: =F60-$C60 -> -0.078449 | O60: =G60-$C60 -> 0.017661 | P60: =H60-$C60 -> 0.024085 | Q60: =I60-$C60 -> 0.000611 | R60: =SUM(L60:Q60)/6 -> -0.015341 | S60: =J60-$C60 -> -0.000401
A61: 33909 | B61: 21 | C61: 0.0025 | D61: 0.140625 | E61: 0.3667 | F61: 0.150685 | G61: 0.16921 | H61: 0.059259 | I61: -0.021563 | J61: 0.030269 | K61: 0.0025 | L61: =D61-$C61 -> 0.138125 | M61: =E61-$C61 -> 0.3642 | N61: =F61-$C61 -> 0.148185 | O61: =G61-$C61 -> 0.16671 | P61: =H61-$C61 -> 0.056759 | Q61: =I61-$C61 -> -0.024063 | R61: =SUM(L61:Q61)/6 -> 0.14165267 | S61: =J61-$C61 -> 0.027769
A62: 33939 | B62: 23 | C62: 0.0025 | D62: 0.052055 | E62: 0.036584 | F62: 0.030381 | G62: 0.050767 | H62: 0.218182 | I62: 0.057006 | J62: 0.010106 | K62: 0.0025 | L62: =D62-$C62 -> 0.049555 | M62: =E62-$C62 -> 0.034084 | N62: =F62-$C62 -> 0.027881 | O62: =G62-$C62 -> 0.048267 | P62: =H62-$C62 -> 0.215682 | Q62: =I62-$C62 -> 0.054506 | R62: =SUM(L62:Q62)/6 -> 0.0716625 | S62: =J62-$C62 -> 0.007606
... A110: 35400 | B110: 21 | C110: 0.004167 | D110: -0.054233 | E110: 0.01875 | F110: -0.015267 | G110: -0.067285 | H110: 0.032512 | I110: 0.02934 | J110: -0.021505 | K110: 0.004167 | L110: =D110-$C110 -> -0.0584 | M110: =E110-$C110 -> 0.014583 | N110: =F110-$C110 -> -0.019434 | O110: =G110-$C110 -> -0.071452 | P110: =H110-$C110 -> 0.028345 | Q110: =I110-$C110 -> 0.025173 | R110: =SUM(L110:Q110)/6 -> -0.013530833 | S110: =J110-$C110 -> -0.025672
A111: 35431 | B111: 23 | C111: 0.004167 | D111: 0.034965 | E111: -0.030675 | F111: -0.003876 | G111: 0.047264 | H111: 0.23855 | I111: 0.099762 | J111: 0.06129 | K111: 0.004167
A113: Item | B113: T. Days | C113: Disc Rate | D113: CMB | E113: COL | F113: F | G113: HWP | H113: INTC | I113: KO | J113: S&P500 | K113: Disc Rate | L113: RP CMB | M113: RP COL | N113: RP F | O113: RP HWP | P113: RP INTC | Q113: RP KO | R113: RP Port | S113: RP S&P
A114: Mean | K114: =AVERAGE(K$51:K$110) -> 0.0033577167 | L114: =AVERAGE(L$51:L$110) -> 0.02967615 | M114: =AVERAGE(M$51:M$110) -> 0.022054633 | N114: =AVERAGE(N$51:N$110) -> 0.014833983 | O114: =AVERAGE(O$51:O$110) -> 0.02221985 | P114: =AVERAGE(P$51:P$110) -> 0.041695567 | Q114: =AVERAGE(Q$51:Q$110) -> 0.014631367 | R114: =AVERAGE(R$51:R$110) -> 0.024185258 | S114: =AVERAGE(S$51:S$110) -> 0.0065672833
A115: Std Dev | K115: =STDEV(K$51:K$110) -> 0.00080925333 | L115: =STDEV(L$51:L$110) -> 0.074807768 | M115: =STDEV(M$51:M$110) -> 0.090085725 | N115: =STDEV(N$51:N$110) -> 0.067991419 | O115: =STDEV(O$51:O$110) -> 0.088397431 | P115: =STDEV(P$51:P$110) -> 0.098988719 | Q115: =STDEV(Q$51:Q$110) -> 0.04246629 | R115: =STDEV(R$51:R$110) -> 0.043630426 | S115: =STDEV(S$51:S$110) -> 0.024802138
A117: Alpha | L117: =INTERCEPT(L$51:L$110,$S$51:$S$110) -> 0.022187355 | M117: =INTERCEPT(M$51:M$110,$S$51:$S$110) -> 0.017211085 | N117: =INTERCEPT(N$51:N$110,$S$51:$S$110) -> 0.011372343 | O117: =INTERCEPT(O$51:O$110,$S$51:$S$110) -> 0.010845177 | P117: =INTERCEPT(P$51:P$110,$S$51:$S$110) -> 0.033813685 | Q117: =INTERCEPT(Q$51:Q$110,$S$51:$S$110) -> 0.011245317 | R117: =INTERCEPT(R$51:R$110,$S$51:$S$110) -> 0.01777916 | S117: =INTERCEPT(S$51:S$110,$S$51:$S$110) -> 0
A118: Beta | L118: =SLOPE(L$51:L$110,$S$51:$S$110) -> 1.1403186 | M118: =SLOPE(M$51:M$110,$S$51:$S$110) -> 0.73752701 | N118: =SLOPE(N$51:N$110,$S$51:$S$110) -> 0.52710379 | O118: =SLOPE(O$51:O$110,$S$51:$S$110) -> 1.7320211 | P118: =SLOPE(P$51:P$110,$S$51:$S$110) -> 1.2001739 | Q118: =SLOPE(Q$51:Q$110,$S$51:$S$110) -> 0.51559362 | R118: =SLOPE(R$51:R$110,$S$51:$S$110) -> 0.97545632 | S118: =SLOPE(S$51:S$110,$S$51:$S$110) -> 1
A119: R2 | L119: =RSQ(L$51:L$110,$S$51:$S$110) -> 0.14293455 | M119: =RSQ(M$51:M$110,$S$51:$S$110) -> 0.041230835 | N119: =RSQ(N$51:N$110,$S$51:$S$110) -> 0.036971094 | O119: =RSQ(O$51:O$110,$S$51:$S$110) -> 0.23615943 | P119: =RSQ(P$51:P$110,$S$51:$S$110) -> 0.09042638 | Q119: =RSQ(Q$51:Q$110,$S$51:$S$110) -> 0.09067857 | R119: =RSQ(R$51:R$110,$S$51:$S$110) -> 0.30747866 | S119: =RSQ(S$51:S$110,$S$51:$S$110) -> 1
A120: R | L120: =PEARSON(L$51:L$110,$S$51:$S$110) -> 0.37806686 | M120: =PEARSON(M$51:M$110,$S$51:$S$110) -> 0.20305377 | N120: =PEARSON(N$51:N$110,$S$51:$S$110) -> 0.19227869 | O120: =PEARSON(O$51:O$110,$S$51:$S$110) -> 0.48596237 | P120: =PEARSON(P$51:P$110,$S$51:$S$110) -> 0.30070979 | Q120: =PEARSON(Q$51:Q$110,$S$51:$S$110) -> 0.30112883 | R120: =PEARSON(R$51:R$110,$S$51:$S$110) -> 0.55450759 | S120: =PEARSON(S$51:S$110,$S$51:$S$110) -> 1
A122: Covariance Matrix (from Tools|Data Analysis|Covariance) | K122: Plotting Data
...
