Workbook

Sheet Enter data
A1: Experiment 8.
A2: Blue Cells have instructions.
A3: Enter data in yellow cells.
A4: Keep going until you hit the Finish Line.
A8: Table 8.2 Distribution of Demander Types
A9: Buyer V. | B9: Number of Buyers
A10: 24 | B10: 5
A11: 18 | B11: 5
A12: 12 | B12: 5
A13: 8 | B13: 7
A17: Copy and paste the data from Session 1, Round 1 below.
A18: owner id | B18: buyer val | C18: price
A19: 736 | B19: 18 | C19: 11
B20: 12 | C20: 11
B21: 24 | C21: 11
B22: 12 | C22: 10
A23: 728 | B23: 24 | C23: 11
B24: 18 | C24: 11
B25: 24 | C25: 11
B26: 18 | C26: 11
A27: 730 | B27: 18 | C27: 11.5
B28: 24 | C28: 11.5
B29: 12 | C29: 11.35
B30: 8 | C30: 8
A31: 740 | B31: 24 | C31: 11.25
B32: 8 | C32: 7.5
B33: 8 | C33: 7.25
B34: 8 | C34: 8
A35: 725 | B35: 18 | C35: 8
B36: 8 | C36: 8
B37: 12 | C37: 6
B38: 8 | C38: 6
A65: Sort the data above by owner ID
A66: Then count the number of different restaurants.
A67: Enter that number below.
A69: number of restaurants equals | D69: 5
A70: number of meals sold | D70: =COUNT(C19:C53) -> 20
A71: mean price | D71: =AVERAGE(C19:C53) -> 9.5675
A72: restaurant's profits | D72: =D71*D70-5*D70-20*D69 -> -8.65
A75: Copy and paste the data from Session 1, Round 2 below.
...

Sheet Graphs
B1: demand | C1: supply | D1: supply
A2: quantity | B2: price | C2: price 1 | D2: price 2
A3: 0 | B3: 30
A4: 0 | B4: 24
A5: ='Enter data'!B10 -> 5 | B5: 24
A6: =A5 -> 5 | B6: 18
A7: =A6+'Enter data'!B11 -> 10 | B7: 18
A8: =A7 -> 10 | B8: 12
A9: =A8+'Enter data'!B12 -> 15 | B9: 12
A10: =A9 -> 15 | B10: 8
A11: =A10+'Enter data'!B13 -> 22 | B11: 8
A12: =A11 -> 22 | B12: 0
A13: 0 | C13: 0
A14: 0 | C14: 5
A15: =4*'Enter data'!D69 -> 20 | C15: 5
A16: =A15 -> 20 | C16: 30
A17: 0 | D17: 0
A18: 0 | D18: 5
A19: ='Enter data'!D127*4 -> 16 | D19: 5
A20: =A19 -> 16 | D20: 30
B29: demand | C29: supply | D29: supply
A30: quantity | B30: price | C30: price 1 | D30: price 2
A31: 0 | B31: 30
A32: 0 | B32: 24
A33: ='Enter data'!B10 -> 5 | B33: 24
A34: =A33 -> 5 | B34: 18
A35: =A34+'Enter data'!B11 -> 10 | B35: 18
A36: =A35 -> 10 | B36: 12
A37: =A36+'Enter data'!B12 -> 15 | B37: 12
A38: =A37 -> 15 | B38: 8
A39: =A38+'Enter data'!B13 -> 22 | B39: 8
A40: =A39 -> 22 | B40: 0
A41: 0 | C41: 0
A42: 0 | C42: 8
A43: ='Enter data'!D205*4 -> 16 | C43: 8
A44: =A43 -> 16 | C44: 30
A45: 0 | D45: 0
A46: 0 | D46: 8
A47: ='Enter data'!D263*4 -> 12 | D47: 8
A48: =A47 -> 12 | D48: 30

Sheet Homework Answers
A1: Homework for Experiment 8
A2: Problem 8.1
A3: Part a.
A4: Number of restaurants opened:
A5: Session 1, Round 1 | C5: 5
A6: Session 1, Round 2 | C6: 4
A8: Part b), c), and d).
A9: Figure 8.4: Short-Run Supply and Demand-Session 1
A30: Table 8.7: Competitive Equilibrium Predictions, Session 1
D31: Mean | E31: Number of | F31: Restaurants'
D32: Price | E32: Meals | F32: Total Profit
A33: Short-Run Competitive
A34: Equilibrium in First Round | D34: 5 | E34: 20 | F34: =20*5-20*5-20*4 -> -80
A35: Short-Run Competitive
A36: Equilibrium in the Last Round | D36: 12 | E36: 16 | F36: =16*12-16*5-4*20 -> 32
A37: Long-Run Competitive
A38: Equilibrium | D38: 12 | E38: 16 | F38: 32
A40: Table 8.8: Experimental Outcomes, Session 1
D41: Mean | E41: Number of | F41: Restaurants'
D42: Price | E42: Meals | F42: Total Profits
A43: Session 1, First Round | D43: ='Enter data'!D71 -> 9.5675 | E43: ='Enter data'!D70 -> 20 | F43: ='Enter data'!D72 -> -8.65
A44: Session 2, Last Round | D44: ='Enter data'!D129 -> 10.421875 | E44: ='Enter data'!D128 -> 16 | F44: ='Enter data'!D130 -> 6.75
A47: Problem 8.4
A48: Part a)
A49: Number of Restaurants:
A50: Session 2, Round 1 | C50: ='Enter data'!D205 -> 4
A51: Session 2, Round 2 | C51: ='Enter data'!D263 -> 3
A53: Part b)
A54: With a $3 sales tax, restaurants have a variable cost of $8 per meal.
A55: Each restaurant that is open will want to supply 0 meals if
A56: the price is below $8, and 4 meals if the price is greater than $8.
A58: Part c), d), and e).
A59: Figure 8.5: Short-Run Supply and Demand-Session 2
A81: Problem 8.5
A82: Table 8.9 Competitive Equilibrium Predictions, Session 2
D83: Mean | E83: Number of | F83: Restaurants'
D84: Price | E84: Meals | F84: Total Profits
A85: Short-Run Competitive
A86: Equilibrium in First Round | D86: 8 | E86: 16 | F86: =E86*D86-E86*8-20*4 -> -80
A87: Short-Run Competitive
...
