Workbook

Sheet Secured
A1: Creditor Information
A3: Secured Debts: Loans, (Incl. Mortgage) & Hire Purchase
C5: Outstanding Bal. | D5: Monthly Repay't | E5: Arrears
A7: Creditor 1
A8: Creditor 2
A9: Creditor 3
A10: Creditor 4
A11: Creditor 5
A12: Creditor 6
A13: Creditor 7
A14: Creditor 8
A15: Creditor 9
A17: Total Secured Debts | C17: =SUM(C6:C16) -> 0 | D17: =SUM(D6:D16) -> 0 | E17: =SUM(E6:E16) -> 0
B19: Notes:

Sheet Unsecured
A1: Creditor Information
A3: Unsecured Loans (Loans, Credit Cards, Store Cards, Overdraft, etc.)
C5: Outstanding Bal. | D5: Monthly Repay't | E5: Arrears
A6: Creditor 1
A7: Creditor 2
A8: Creditor 3
A9: Creditor 4
A10: Creditor 5
A11: Creditor 6
A12: Creditor 7
A13: Creditor 8
A14: Creditor 9
A16: Total Unsecured Debts | C16: =SUM(C6:C15) -> 0 | D16: =SUM(D6:D15) -> 0 | E16: =SUM(E6:E15) -> 0
B18: Notes:

Sheet Income
A1: Income
B3: £ per week | C3: £ per month | D3: £ per year | E3: Rev £/m
A4: Wages/ Salary | C4: =B4*52/12 -> 0
A5: Wages/ Salary (spouse/partner) | C5: =B5*52/12 -> 0
C6: =B6*52/12 -> 0
A7: Child Benefit | C7: =B7*52/12 -> 0
A8: Income Support | C8: =B8*52/12 -> 0
A9: Unemployment Benefit | C9: =B9*52/12 -> 0
A10: Family Credit | C10: =B10*52/12 -> 0
C11: =B11*52/12 -> 0
A12: Disability Allowance | C12: =B12*52/12 -> 0
A13: Maternity Allowance | C13: =B13*52/12 -> 0
C14: =B14*52/12 -> 0
A15: Pension | C15: =B15*52/12 -> 0
C16: =B16*52/12 -> 0
A17: Child Maintenance | C17: =B17*52/12 -> 0
A18: Sickness Benefit | C18: =B18*52/12 -> 0
A19: Invalidity Benefit | C19: =B19*52/12 -> 0
C20: =B20*52/12 -> 0
A21: Contributions (non-dependants) | C21: =B21*52/12 -> 0
A22: Contributions (lodger) | C22: =B22*52/12 -> 0
C23: =B23*52/12 -> 0
A24: Interest Income (Bank) | C24: =B24*52/12 -> 0
A25: Interest Income (Building Society) | C25: =B25*52/12 -> 0
C26: =B26*52/12 -> 0
A27: Other Income (Specify) | C27: =B27*52/12 -> 0
A28: Other Income (Specify) | C28: =B28*52/12 -> 0
C29: =B29*52/12 -> 0
A30: Total Income | B30: =SUM(B4:B29) -> 0 | C30: =SUM(C4:C29) -> 0 | D30: =SUM(D4:D29) -> 0 | E30: =SUM(E4:E29) -> 0
B32: Payslips: | E32: Notes:

Sheet Priorities
A1: Priority Commitments
B3: £ per week | C3: £ per month | D3: £ per year | E3: Rev £/m
A4: Rent or Mortgage | C4: =B4*52/12 -> 0
A5: Mortgage Endowment Premium | C5: =B5*52/12 -> 0
A6: Secured Loan/2nd mortgage | C6: =B6*52/12 -> 0
A7: Ground Rent, Service Charges, etc. | C7: =B7*52/12 -> 0
C8: =B8*52/12 -> 0
A9: Council Tax | C9: =B9*52/12 -> 0
A10: Water Charges | C10: =B10*52/12 -> 0
C11: =B11*52/12 -> 0
A12: Electricity | C12: =B12*52/12 -> 0
A13: Gas | C13: =B13*52/12 -> 0
A14: Oil | C14: =B14*52/12 -> 0
A16: CSA/Maintenance
A18: Total Priority Commitments. | B18: =SUM(B4:B17) -> 0 | C18: =SUM(C4:C17) -> 0 | D18: =SUM(D4:D17) -> 0 | E18: =SUM(E4:E17) -> 0
B20: Notes:

Sheet Formal
A1: Formal Commitments
B3: £ per week | C3: £ per month | D3: £ per year | E3: Rev £/m
A4: Other Household Fuels | C4: =B4*52/12 -> 0
C5: =B5*52/12 -> 0
A6: House Insurance (Building) | C6: =B6*52/12 -> 0
A7: House Insurance (Contents) | C7: =B7*52/12 -> 0
A8: Life Insurance | C8: =B8*52/12 -> 0
A9: Medical Insurance | C9: =B9*52/12 -> 0
A10: Dental Insurance | C10: =B10*52/12 -> 0
A12: Telephone | C12: =B12*52/12 -> 0
A13: Telephone (Mobile)
C14: =B14*52/12 -> 0
A15: TV License | C15: =B15*52/12 -> 0
A16: Appliance Rentals | C16: =B16*52/12 -> 0
A17: Appliance Service Contracts/Insurance | C17: =B17*52/12 -> 0
A20: Total Formal Commitments | B20: =SUM(B4:B19) -> 0 | C20: =SUM(C4:C19) -> 0 | D20: =SUM(D4:D19) -> 0 | E20: =SUM(E4:E19) -> 0
B22: Notes:

Sheet Everyday
A1: Everyday Expenditure
B3: £ per week | C3: £ per month | D3: £ per year | E3: Rev £/m
A4: Food | C4: =B4*52/12 -> 0
A5: Toiletries & Soaps | C5: =B5*52/12 -> 0
A6: Detergents & Cleaning Materials | C6: =B6*52/12 -> 0
A7: Meals (work) | C7: =B7*52/12 -> 0
C8: =B8*52/12 -> 0
A9: Car Road Fund License | C9: =B9*52/12 -> 0
A10: Car MOT | C10: =B10*52/12 -> 0
A11: Car Insurance | C11: =B11*52/12 -> 0
A12: AA, RAC, etc. | C12: =B12*52/12 -> 0
A13: Car Fuel | C13: =B13*52/12 -> 0
A14: Parking | C14: =B14*52/12 -> 0
A15: Car Repairs & Servicing | C15: =B15*52/12 -> 0
A16: Car Spares & Accessories | C16: =B16*52/12 -> 0
C17: =B17*52/12 -> 0
A18: Fares & Travel | C18: =B18*52/12 -> 0
C19: =B19*52/12 -> 0
A20: Baby costs | C20: =B20*52/12 -> 0
A21: Children's Pocket Money | C21: =B21*52/12 -> 0
A22: Childminder | C22: =B22*52/12 -> 0
A23: Meals Lunches | C23: =B23*52/12 -> 0
A24: Toys & Books | C24: =B24*52/12 -> 0
C25: =B25*52/12 -> 0
A26: Pets & Pet Food | C26: =B26*52/12 -> 0
A27: Laundry & Dry Cleaning Costs | C27: =B27*52/12 -> 0
A28: Chemist | C28: =B28*52/12 -> 0
C29: =B29*52/12 -> 0
A30: TV Rental (Sky, Cable, etc) | C30: =B30*52/12 -> 0
A31: Video Rental | C31: =B31*52/12 -> 0
A32: Evening Classes | C32: =B32*52/12 -> 0
A33: Hobbies/Sports | C33: =B33*52/12 -> 0
A34: Records/Tapes/CD's | C34: =B34*52/12 -> 0
A35: Computer Games | C35: =B35*52/12 -> 0
C36: =B36*52/12 -> 0
A37: Church/Charity | C37: =B37*52/12 -> 0
C38: =B38*52/12 -> 0
A39: Alcoholic Drinks | C39: =B39*52/12 -> 0
A40: Cigarettes/Tobacco | C40: =B40*52/12 -> 0
A41: Newspapers/Magazines | C41: =B41*52/12 -> 0
...

Sheet Occasional
A1: Occasional Costs
B3: £ per week | C3: £ per month | D3: £ per year | E3: Rev £/m
A4: Birthdays | C4: =B4*52/12 -> 0
A5: Christmas | C5: =B5*52/12 -> 0
A6: Holiday | C6: =B6*52/12 -> 0
C7: =B7*52/12 -> 0
A8: Appliance Repairs | C8: =B8*52/12 -> 0
A9: Redecoration | C9: =B9*52/12 -> 0
A10: Vet Bills | C10: =B10*52/12 -> 0
C11: =B11*52/12 -> 0
A12: Clothing, Men's | C12: =B12*52/12 -> 0
A13: Clothing, Women's | C13: =B13*52/12 -> 0
A14: Clothing, Children | C14: =B14*52/12 -> 0
C15: =B15*52/12 -> 0
A16: Hairdressing | C16: =B16*52/12 -> 0
C17: =B17*52/12 -> 0
A18: School Trips | C18: =B18*52/12 -> 0
A19: Prescription Costs | C19: =B19*52/12 -> 0
A20: Dentist | C20: =B20*52/12 -> 0
A21: Optician | C21: =B21*52/12 -> 0
A22: Meals Out | C22: =B22*52/12 -> 0
C23: =B23*52/12 -> 0
A24: Window Cleaning | C24: =B24*52/12 -> 0
A25: Postage & Stationery | C25: =B25*52/12 -> 0
A27: Other | C27: =B27*52/12 -> 0
A28: Other | C28: =B28*52/12 -> 0
A30: Total Occasional Costs | B30: =SUM(B4:B29) -> 0 | C30: =SUM(C4:C29) -> 0 | D30: =SUM(D4:D29) -> 0 | E30: =SUM(E4:E29) -> 0
B32: Notes:

Sheet Summary
A1: Summary of Income/Expenditure
B3: £ per week | C3: £ per month | D3: £ per year | E3: Rev £/m
A5: Total Income | C5: =Income!$C$30 -> 0
A7: Total Expenditure | C7: =B7*52/12 -> 0
A8: Total Priority Commitments (1) | C8: =Priorities!$C$18 -> 0
A9: Total Formal Commitments (2) | C9: =Formal!$C$20 -> 0
A10: Total Everyday Spending (3) | C10: =Everyday!$C$45 -> 0
A11: Total Occasional Costs (4) | C11: =Occasional!$C$30 -> 0
A12: Total Expenditure | B12: =SUM(B7:B11) -> 0 | C12: =SUM(C8:C11) -> 0 | D12: =SUM(D7:D11) -> 0 | E12: =SUM(E7:E11) -> 0
A15: Surplus (Deficit) | B15: =B5-B12 -> 0 | C15: =C5-C12 -> 0 | D15: =D5-D12 -> 0 | E15: =E5-E12 -> 0
C18: O/s Bal. | D18: Mon. Repay't | E18: Arrears
A20: =Secured!A17 -> Total Secured Debts | B20: =Secured!B17 -> 0 | C20: =Secured!C17 -> 0 | D20: =Secured!D17 -> 0 | E20: =Secured!E17 -> 0
A22: =Unsecured!A16 -> Total Unsecured Debts | B22: =Unsecured!B16 -> 0 | C22: =Unsecured!C16 -> 0 | D22: =Unsecured!D16 -> 0 | E22: =Unsecured!E16 -> 0

Sheet Capital
A1: Capital, Investments, Insurances, etc.
A3: Equity in Property
A5: Endowment Policies
A6: P.E.P.
A7: Whole Life Insurance
A8: Shares
A10: Bank
A11: Bank
A12: Bank
A14: Building Society
A15: Building Society
A16: Building Society
... A21: Other

Sheet Financial Statement -1
A1: Financial Statement | E1: Client Reference:
A2: As of | E2: Client Company:
A3: No. in family | E3: Client Name:
A4: Ages of Children | E4: Money Adviser:
C6: Monthly | E6: Priority Debts | G6: Arrears | H6: Offer | I6: CCJ's
A7: Income (salary) | C7: =Income!$C$4 -> 0 | E7: Mortgage
A8: Income (salary) | C8: =Income!$C$5 -> 0 | E8: Rent
A9: Income (other) | C9: =Income!$C$15 -> 0 | E9: Council Tax
A10: Child Benefit | C10: =Income!$C$7 -> 0 | E10: Water Charges
A11: Other Benefits | C11: =Income!$C$8+Income!C9+Income!C10+Income!C12+Income!C13+Income!C18+Income!C19 -> 0 | E11: Gas
A12: Other | C12: =Income!$C$21+Income!C22+Income!C24+Income!C25+Income!C27+Income!C28+Income!C17 -> 0 | E12: Electricity
B13: Total | C13: =SUM(C7:C12) -> 0 | E13: Maint./CSA
E14: Fines
A15: Outgoings | E15: Others
A16: Mortgage/Rent | C16: =Priorities!$C$4 -> 0
A17: Ground Rent, Service Charges | C17: =Priorities!$C$7 -> 0 | E17: Creditors | F17: Person | G17: O/S Bal. | H17: Offer | I17: CCJ's
A18: Secured Loan | C18: =Priorities!$C$6 -> 0 | E18: =Secured!B7 -> 0 | G18: =Secured!C7 -> 0
A19: Endowment | C19: =Priorities!$C$5 -> 0 | E19: =Secured!B8 -> 0 | G19: =Secured!C8 -> 0
A20: Life Insurance | C20: =Formal!$C$8 -> 0 | E20: =Secured!B9 -> 0 | G20: =Secured!C9 -> 0
A21: House Insurance | C21: =Formal!$C$6+Formal!$C$7 -> 0 | E21: =Secured!B10 -> 0 | G21: =Secured!C10 -> 0
A22: Maintenance/CSA | C22: =Priorities!$C$16 -> 0 | E22: =Secured!B11 -> 0 | G22: =Secured!C11 -> 0
A23: Council Tax | C23: =Priorities!$C$9 -> 0 | E23: =Secured!B12 -> 0 | G23: =Secured!C12 -> 0
A24: Gas | C24: =Priorities!$C$13 -> 0 | E24: =Secured!B13 -> 0 | G24: =Secured!C13 -> 0
A25: Electricity | C25: =Priorities!$C$12 -> 0 | E25: =Secured!B14 -> 0 | G25: =Secured!C14 -> 0
A26: Water Charges | C26: =Priorities!$C$10 -> 0 | E26: =Secured!B15 -> 0 | G26: =Secured!C15 -> 0
A27: Telephone | C27: =Formal!$C$12+Formal!$C$13 -> 0 | E27: =Unsecured!B6 -> 0 | G27: =Unsecured!C6 -> 0
A28: Housekeeping | C28: =Everyday!$C$4+Everyday!$C$5+Everyday!$C$6+Everyday!$C$7+Everyday!C20+Everyday!C21+Everyday!C22+Everyday!C23+Everyday!C24+Everyday!C26+Everyday!C27+Everyday!C39+Everyday!C40+Everyday!C43 -> 0 | E28: =Unsecured!B7 -> 0 | G28: =Unsecured!C7 -> 0
A29: Car Costs | C29: =Everyday!$C$9+Everyday!$C$10+Everyday!$C$11+Everyday!$C$12+Everyday!$C$13+Everyday!$C$14+Everyday!$C$15+Everyday!$C$16 -> 0 | E29: =Unsecured!B8 -> 0 | G29: =Unsecured!C8 -> 0
A30: Other Travel | C30: =Everyday!$C$18 -> 0 | E30: =Unsecured!B9 -> 0 | G30: =Unsecured!C9 -> 0
A31: TV (Cable, satellite, etc.) | C31: =Formal!$C$15+Everyday!C30+Everyday!C31 -> 0 | E31: =Unsecured!B10 -> 0 | G31: =Unsecured!C10 -> 0
A32: Health Costs | C32: =Formal!$C$9+Formal!$C$10+Everyday!C28+Occasional!C19+Occasional!C20+Occasional!C21 -> 0 | E32: =Unsecured!B11 -> 0 | G32: =Unsecured!C11 -> 0
A33: Clothing & Shoes | C33: =Occasional!$C$12+Occasional!C13+Occasional!C14 -> 0 | E33: =Unsecured!B12 -> 0 | G33: =Unsecured!C12 -> 0
A34: Spending Money | C34: =Occasional!$C$22 -> 0 | E34: =Unsecured!B13 -> 0 | G34: =Unsecured!C13 -> 0
A35: Extras | C35: =Everyday!$C$32+Everyday!C33+Everyday!C34+Everyday!C35+Everyday!C41 -> 0 | E35: =Unsecured!B14 -> 0 | G35: =Unsecured!C14 -> 0
A36: Contingency | C36: =Occasional!$C$24+Occasional!C27+Occasional!C28 -> 0 | D36: Total | G36: =SUM(G18:G35) -> 0
A37: Other (Formal) | C37: =Formal!$C$16+Formal!$C$17 -> 0
A38: Other (Occasional) | C38: =Occasional!$C$4+Occasional!C5+Occasional!C6+Occasional!C8+Occasional!C16+Occasional!C10+Occasional!C9+Occasional!C18+Occasional!C24+Occasional!C25 -> 0
A39: Other (Everyday) | C39: =Everyday!$C$37 -> 0
B40: Total | C40: =SUM(C16:C39) -> 0
A42: Disposable Income | C42: =C13-C40 -> 0

Sheet Financial Statement - 2
A1: Financial Statement - Rev. | E1: Client Reference:
A2: As of | E2: Client Company:
A3: No. in family | E3: Client Name:
A4: Ages of Children | E4: Money Adviser:
C6: Monthly | E6: Priority Debts | G6: Arrears | H6: Offer | I6: CCJ's
A7: Income (salary) | C7: =Income!$E$4 -> 0 | E7: Mortgage
A8: Income (salary) | C8: =Income!$E$5 -> 0 | E8: Rent
A9: Income (other) | C9: =Income!$E$15 -> 0 | E9: Council Tax
A10: Child Benefit | C10: =Income!$E$7 -> 0 | E10: Water Charges
A11: Other Benefits | C11: =Income!$E$8+Income!E9+Income!E10+Income!E12+Income!E13+Income!E18+Income!E19 -> 0 | E11: Gas
A12: Other | C12: =Income!$E$21+Income!E22+Income!E24+Income!E25+Income!E27+Income!E28 -> 0 | E12: Electricity
B13: Total | C13: =SUM(C7:C12) -> 0 | E13: Maint./CSA
E14: Fines
A15: Outgoings | E15: Others
A16: Mortgage | C16: =Priorities!$E$4 -> 0
A17: Rent | C17: =Priorities!$E$7 -> 0 | E17: Creditors | F17: Person | G17: O/S Bal. | H17: Offer | I17: CCJ's
A18: Secured Loan | C18: =Priorities!$E$6 -> 0 | E18: =Secured!B7 -> 0 | G18: =Secured!E7 -> 0
A19: Endowment | C19: =Priorities!$E$5 -> 0 | E19: =Secured!B8 -> 0 | G19: =Secured!E8 -> 0
A20: Life Insurance | C20: =Formal!$E$8 -> 0 | E20: =Secured!B9 -> 0 | G20: =Secured!E9 -> 0
A21: House Insurance | C21: =Formal!$E$6+Formal!$E$7 -> 0 | E21: =Secured!B10 -> 0 | G21: =Secured!E10 -> 0
A22: Maintenance/CSA | C22: =Priorities!$E$16 -> 0 | E22: =Secured!B11 -> 0 | G22: =Secured!E11 -> 0
A23: Council Tax | C23: =Priorities!$E$9 -> 0 | E23: =Secured!B12 -> 0 | G23: =Secured!E12 -> 0
A24: Gas | C24: =Priorities!$E$13 -> 0 | E24: =Secured!B13 -> 0 | G24: =Secured!E13 -> 0
A25: Electricity | C25: =Priorities!$E$12 -> 0 | E25: =Secured!B14 -> 0 | G25: =Secured!E14 -> 0
A26: Water Charges | C26: =Priorities!$E$10 -> 0 | E26: =Secured!B15 -> 0 | G26: =Secured!E15 -> 0
A27: Telephone | C27: =Formal!$E$12++Formal!$E$13 -> 0 | E27: =Unsecured!B6 -> 0 | G27: =Unsecured!E6 -> 0
A28: Housekeeping | C28: =Everyday!$E$4+Everyday!$E$5+Everyday!$E$6+Everyday!$E$7+Everyday!E20+Everyday!E21+Everyday!E22+Everyday!E23+Everyday!E24+Everyday!E26+Everyday!E27+Everyday!E39+Everyday!E40+Everyday!E43 -> 0 | E28: =Unsecured!B7 -> 0 | G28: =Unsecured!E7 -> 0
A29: Car Costs | C29: =Everyday!$E$9+Everyday!$E$10+Everyday!$E$11+Everyday!$E$12+Everyday!$E$13+Everyday!$E$14+Everyday!$E$15+Everyday!$E$16 -> 0 | E29: =Unsecured!B8 -> 0 | G29: =Unsecured!E8 -> 0
A30: Other Travel | C30: =Everyday!$E$18 -> 0 | E30: =Unsecured!B9 -> 0 | G30: =Unsecured!E9 -> 0
A31: TV (Cable, satellite, etc.) | C31: =Formal!$E$15+Everyday!E30+Everyday!E31 -> 0 | E31: =Unsecured!B10 -> 0 | G31: =Unsecured!E10 -> 0
A32: Health Costs | C32: =Formal!$E$9+Formal!$C$10+Everyday!E28+Occasional!E19+Occasional!EE20+Occasional!E21 -> 0 | E32: =Unsecured!B11 -> 0 | G32: =Unsecured!E11 -> 0
A33: Clothing & Shoes | C33: =Occasional!$E$12+Occasional!E13+Occasional!E14 -> 0 | E33: =Unsecured!B12 -> 0 | G33: =Unsecured!E12 -> 0
A34: Spending Money | C34: =Occasional!$E$22 -> 0 | E34: =Unsecured!B13 -> 0 | G34: =Unsecured!E13 -> 0
A35: Extras | C35: =Everyday!$E$32+Everyday!E33+Everyday!E34+Everyday!E35+Everyday!E41 -> 0 | E35: =Unsecured!B14 -> 0 | G35: =Unsecured!E14 -> 0
A36: Contingency | C36: =Occasional!$E$24+Occasional!E25+Occasional!E27+Occasional!E28 -> 0 | D36: Total | G36: =SUM(G18:G35) -> 0
A37: Other (Formal) | C37: =Formal!$E$16+Formal!$E$17 -> 0
A38: Other (Occasional) | C38: =Occasional!$E$4+Occasional!E5+Occasional!E6+Occasional!E8+Occasional!E16+Occasional!E10+Occasional!E9+Occasional!E18+Occasional!E24+Occasional!E25 -> 0
A39: Other (Everyday) | C39: =Everyday!$E$37 -> 0
B40: Total | C40: =SUM(C16:C39) -> 0
A42: Disposable Income | C42: =C13-C40 -> 0
