Workbook

Sheet Internal Rate of Return
A1: =+Assumptions!D6 -> Papa John's International, Inc.
A2: Internal Rate of Return
A3: (1) Based on TEV/EBITDA Multiple | E3: =+'Income Statement'!F6 -> 2002E | F3: =+'Income Statement'!G6 -> 2003E | G3: =+'Income Statement'!H6 -> 2004E | H3: =+'Income Statement'!I6 -> 2005E | I3: =+'Income Statement'!J6 -> 2006E
A4: Internal Rate of Return | E4: =+'Transaction Summary'!C6*-1 -> -224185.33 | F4: 0 | G4: 0 | H4: 0 | I4: 0
B5: EBITDA | I5: =+'Income Statement'!J40+('Income Statement'!J33) -> 180621.32
B6: EBITDA Multiple | I6: 6
I7: =+I5*I6 -> 1083727.9
B8: Less Debt | I8: =-'Balance Sheet'!J39 -> -510653.71
B9: Total Cash Flow | I9: =+I7+I8 -> 573074.2
B10: Percentage Owned | I10: =+'Transaction Summary'!C21 -> 0.85
A12: Total Investment Cash Flows | E12: =+E4 -> -224185.33 | F12: 0 | G12: 0 | H12: 0 | I12: =+I9*I10 -> 487113.07
E14: =IRR(E12:I12) -> 0.21410332
A15: (2) Based On P/E Multiple | I15: =+'Transaction Summary'!G26*'Income Statement'!J49 -> 571090.76
B16: Percentage Owned | I16: =+'Transaction Summary'!C21 -> 0.85
E17: =+E4 -> -224185.33 | F17: =+F12 -> 0 | G17: 0 | H17: 0 | I17: =+I15*I16 -> 485427.14
A19: Internal Rate of Return | E19: =IRR(E17:I17) -> 0.21305144

Sheet Transaction Summary
A1: =+Assumptions!D6 -> Papa John's International, Inc.
A2: LBO/Leverage Recap Transaction Summary
A5: Sources: | B5: Issuing New Debt | C5: 600000 | E5: Pricing Information: | F5: Transaction Date | G5: 37622
B6: Buyout Equity Investment | C6: =+C19*G9 -> 224185.33 | F6: Shares Outstanding (000s) | G6: =+Assumptions!C45 -> 22600
B7: Total | C7: =+C5+C6 -> 824185.33 | F7: Outstanding Debt | G7: =+'Balance Sheet'!E39+'Balance Sheet'!E34 -> 140547.45
B9: % of Sources from Issuing New Debt | C9: =+C5/C7 -> 0.7279916 | F9: Transaction Price | G9: 32
B10: % of Sources from Equity Investment | C10: =+C6/C7 -> 0.2720084
F11: % Shares Bought Back | G11: =+C17/G6 -> 0.63530497
A13: Uses: | B13: Retire Old Debt | C13: =+'Balance Sheet'!E34+'Balance Sheet'!E39 -> 140547.45 | E13: Transaction Type: | F13: Recap=0 / LBO=1 | G13: 0
B14: Equity repurchased | C14: =+(C17+C19)*G9 -> 683637.88
B15: Total | C15: =+C13+C14 -> 824185.33
A17: Ownership Summary: | B17: # of Shares Repurchased with Debt | C17: =+(C5-'Balance Sheet'!E39)/G9 -> 14357.892
B18: # of Shares Remaining | C18: =+G6-C17 -> 8242.1077
B19: # of Shares Purchased by LBO Firm | C19: =+C18*C21 -> 7005.7916 | E19: Multiples: | F19: Current Share Price | G19: 23.44
B20: # of Shares Outstanding After Buyback | C20: =+C18-C19 -> 1236.3162 | F20: 2002 EBITDA | G20: =+'Income Statement'!F40+('Income Statement'!F33*(1-Assumptions!C43)) -> 93249.17
B21: % Ownership of Buyout Firm Post Transaction | C21: 0.85 | F21: Implied EBITDA Multiple | G21: =+(G19*G6)/G20 -> 5.6809514
F22: 2002 EPS | G22: =+'Income Statement'!F51 -> 1.9056178
F23: Implied P/E Multiple | G23: =+G19/G22 -> 12.300473
A24: Goodwill: | B24: Fair Value | C24: =+G6*G9 -> 723200
B25: Book Value | C25: =+'Balance Sheet'!E57 -> 238698.96 | F25: Assumed EBITDA Exit Multiple | G25: 6
B26: Writeup of net assets | C26: 0 | F26: Assumed P/E Exit Multiple | G26: 10
B27: Excess of Fair Value over Book Value | C27: =+C24-(C25*(1+C26)) -> 484501.04
F28: Assumed Exit Date | G28: 39082
B30: Goodwill if 100% change of control | C30: =C27 -> 484501.04
B31: Goodwill for this transaction if LBO | C31: =+C21*C30 -> 411825.88
B32: Amortization period for goodwill | C32: Not Required

Sheet Recap Transaction Figure
A1: =+"Leveraged Recapitalization of " &Assumptions!D6 -> Leveraged Recapitalization of Papa John's International, Inc.
E12: =+'Transaction Summary'!C21 -> 0.85
E13: =+'Transaction Summary'!C6 -> 224185.33
G16: =+E13+C22-H22 -> 683637.88
G17: =1-E12 -> 0.15
C22: =+'Transaction Summary'!C5 -> 600000 | H22: =+'Balance Sheet'!E39+'Balance Sheet'!E34 -> 140547.45
C23: New Debt | H23: Repay Old Debt

Sheet LBO Transaction Figure
A1: =+"LBO of "&Assumptions!D6 -> LBO of Papa John's International, Inc.
E9: =+'Transaction Summary'!C21 -> 0.85 | G9: =1-'Transaction Summary'!C21 -> 0.15
E10: =+E9*(J17-C19) -> 224185.33 | G10: =+G9*(J17-C19) -> 39562.117
J17: =+'Transaction Summary'!G9*'Transaction Summary'!G6 -> 723200
J18: Value of Firm
C19: =+'Balance Sheet'!F39 -> 459452.55
C20: Net new debt

Sheet Assumptions
A1: =D6 -> Papa John's International, Inc.
A4: Model Settings
A6: Company Name | D6: Papa John's International, Inc.
A7: Financial Format (0 = Thousands, 1= Millions) | D7: 0
A8: Last Year of Audited Financials | D8: 2001
A11: Income Statement Assumptions
C13: =+$D$8+1&"E" -> 2002E | D13: =+$D$8+2&"E" -> 2003E | E13: =+$D$8+3&"E" -> 2004E | F13: =+$D$8+4&"E" -> 2005E | G13: =+$D$8+5&"E" -> 2006E
A14: Revenues (Growth Rates)
A15: Restaurant Sales | C15: 0.25 | D15: 0.2 | E15: 0.15 | F15: 0.1 | G15: 0.05
A16: Franchise Royalties | C16: 0.25 | D16: 0.2 | E16: 0.15 | F16: 0.1 | G16: 0.05
A17: Franchise and Development Fees | C17: 0.25 | D17: 0.2 | E17: 0.15 | F17: 0.1 | G17: 0.05
A18: Commisary Sales | C18: 0.25 | D18: 0.2 | E18: 0.15 | F18: 0.1 | G18: 0.05
A19: Equipment and Other Sales | C19: 0.25 | D19: 0.2 | E19: 0.15 | F19: 0.1 | G19: 0.05
A21: Expenses
A22: Restaurant Expenses (As a % of Restaurant Sales)
A23: Cost of Sales | C23: 0.268 | D23: 0.268 | E23: 0.268 | F23: 0.268 | G23: 0.268
A24: Salaries and Benefits | C24: 0.271 | D24: 0.268 | E24: 0.268 | F24: 0.268 | G24: 0.268
A25: Advertising and Related Costs | C25: 0.087 | D25: 0.083 | E25: 0.083 | F25: 0.083 | G25: 0.083
A26: Occupancy Costs | C26: 0.049 | D26: 0.049 | E26: 0.049 | F26: 0.049 | G26: 0.049
A27: Other Operating Expenses | C27: 0.131 | D27: 0.13 | E27: 0.13 | F27: 0.13 | G27: 0.13
A29: Commissary, Equipment and Other Expenses (As a % of Commissary and Equipment Revenue)
A30: Cost of Sales | C30: 0.782 | D30: 0.782 | E30: 0.782 | F30: 0.782 | G30: 0.782
A31: Salaries and Benefits | C31: 0.056 | D31: 0.056 | E31: 0.056 | F31: 0.056 | G31: 0.056
A32: Other Operating Expenses | C32: 0.074 | D32: 0.074 | E32: 0.074 | F32: 0.074 | G32: 0.074
A34: General and Administrative Expenses (As a % of Total Revenues) | C34: 0.071 | D34: 0.068 | E34: 0.068 | F34: 0.068 | G34: 0.068
A35: Pre-Opening and Other General Expenses (As a % of Total Revenues) | C35: 0.003 | D35: 0.003 | E35: 0.003 | F35: 0.003 | G35: 0.003
A36: Depreciation and Amortization (As a % of Total Revenues) | C36: SEE FIXED ASSET SCHEDULE
A37: International expenses (as a % of total revenues) | C37: 0.008 | D37: 0.008 | E37: 0.008 | F37: 0.008 | G37: 0.008
A38: Other expenses (% of total revenues) | C38: 0.027 | D38: 0.027 | E38: 0.027 | F38: 0.027 | G38: 0.027
A40: Investment Income (As a % of Investments) | C40: 0.06 | D40: 0.06 | E40: 0.06 | F40: 0.06 | G40: 0.06
A41: Interest expense (as a % of total LT debt) | C41: 0.045 | D41: 0.08 | E41: 0.08 | F41: 0.08 | G41: 0.08
A43: Effective Tax Rate | C43: 0.375 | D43: 0.375 | E43: 0.375 | F43: 0.375 | G43: 0.375
A45: Projected Shares Outstanding (Thousands) | C45: 22600 | D45: 22600 | E45: 22600 | F45: 22600 | G45: 22600
A47: Balance Sheet Assumptions
C49: =+C13 -> 2002E | D49: =+D13 -> 2003E | E49: =+E13 -> 2004E | F49: =+F13 -> 2005E | G49: =+G13 -> 2006E
A50: Assets (As a % of Total Revenues)
A51: Current Assets
A52: Cash and Cash Equivalents | C52: 0.005 | D52: 0.005 | E52: 0.005 | F52: 0.005 | G52: 0.005
A53: Accounts Receivable | C53: 0.024 | D53: 0.024 | E53: 0.024 | F53: 0.024 | G53: 0.024
A54: Accounts Receivable - Affiliates | C54: 0.004 | D54: 0.004 | E54: 0.004 | F54: 0.004 | G54: 0.004
...

Sheet Income Statement
A1: =Assumptions!D6 -> Papa John's International, Inc.
A3: Consolidated Statements of Income
A4: (Dollars in Thousands Except Per Share Data)
A5: Note: Some of the items of the 10K were grouped
B6: =+C6-1 -> 1998 | C6: =+D6-1 -> 1999 | D6: =+E6-1 -> 2000 | E6: =+Assumptions!D8 -> 2001 | F6: =+Assumptions!C13 -> 2002E | G6: =+Assumptions!D13 -> 2003E | H6: =+Assumptions!E13 -> 2004E | I6: =+Assumptions!F13 -> 2005E | J6: =+Assumptions!G13 -> 2006E
A7: Revenues
A8: Restaurant Sales | B8: 344089 | C8: 397197 | D8: 482183 | E8: 471863 | F8: =E8*(1+Assumptions!C15) -> 589828.75 | G8: =F8*(1+Assumptions!D15) -> 707794.5 | H8: =G8*(1+Assumptions!E15) -> 813963.67 | I8: =H8*(1+Assumptions!F15) -> 895360.04 | J8: =I8*(1+Assumptions!G15) -> 940128.04
A9: Franchise Royalties | B9: 32120 | C9: 40567 | D9: 47145 | E9: 50768 | F9: =E9*(1+Assumptions!C16) -> 63460 | G9: =F9*(1+Assumptions!D16) -> 76152 | H9: =G9*(1+Assumptions!E16) -> 87574.8 | I9: =H9*(1+Assumptions!F16) -> 96332.28 | J9: =I9*(1+Assumptions!G16) -> 101148.89
A10: Franchise and Development Fees | B10: 5456 | C10: 7574 | D10: 10861 | E10: 8822 | F10: =E10*(1+Assumptions!C17) -> 11027.5 | G10: =F10*(1+Assumptions!D17) -> 13233 | H10: =G10*(1+Assumptions!E17) -> 15217.95 | I10: =H10*(1+Assumptions!F17) -> 16739.745 | J10: =I10*(1+Assumptions!G17) -> 17576.732
A11: Commisary Sales | B11: 255083 | C11: 306909 | D11: 351255 | E11: 387049 | F11: =E11*(1+Assumptions!C18) -> 483811.25 | G11: =F11*(1+Assumptions!D18) -> 580573.5 | H11: =G11*(1+Assumptions!E18) -> 667659.52 | I11: =H11*(1+Assumptions!F18) -> 734425.48 | J11: =I11*(1+Assumptions!G18) -> 771146.75
A12: Equipment and Other Sales | B12: 45404 | C12: 53078 | D12: 53233 | E12: 52730 | F12: =E12*(1+Assumptions!C19) -> 65912.5 | G12: =F12*(1+Assumptions!D19) -> 79095 | H12: =G12*(1+Assumptions!E19) -> 90959.25 | I12: =H12*(1+Assumptions!F19) -> 100055.18 | J12: =I12*(1+Assumptions!G19) -> 105057.93
A13: Total Revenues | B13: =SUM(B8:B12) -> 682152 | C13: =SUM(C8:C12) -> 805325 | D13: =SUM(D8:D12) -> 944677 | E13: 971232 | F13: =SUM(F8:F12) -> 1214040 | G13: =SUM(G8:G12) -> 1456848 | H13: =SUM(H8:H12) -> 1675375.2 | I13: =SUM(I8:I12) -> 1842912.7 | J13: =SUM(J8:J12) -> 1935058.4
A15: Expenses
A16: Restaurant Expenses
A17: Cost of Sales | B17: 92612 | C17: 100261 | D17: 111609 | E17: 110632 | F17: =F$8*Assumptions!C23 -> 158074.11 | G17: =G$8*Assumptions!D23 -> 189688.93 | H17: =H$8*Assumptions!E23 -> 218142.26 | I17: =I$8*Assumptions!F23 -> 239956.49 | J17: =J$8*Assumptions!G23 -> 251954.32
A18: Salaries and Benefits | B18: 92372 | C18: 106713 | D18: 127318 | E18: 130882 | F18: =F$8*Assumptions!C24 -> 159843.59 | G18: =G$8*Assumptions!D24 -> 189688.93 | H18: =H$8*Assumptions!E24 -> 218142.26 | I18: =I$8*Assumptions!F24 -> 239956.49 | J18: =J$8*Assumptions!G24 -> 251954.32
A19: Advertising and Related Costs | B19: 29846 | C19: 36008 | D19: 41729 | E19: 35297 | F19: =F$8*Assumptions!C25 -> 51315.101 | G19: =G$8*Assumptions!D25 -> 58746.944 | H19: =H$8*Assumptions!E25 -> 67558.985 | I19: =I$8*Assumptions!F25 -> 74314.884 | J19: =J$8*Assumptions!G25 -> 78030.628
A20: Occupancy Costs | B20: 17138 | C20: 19541 | D20: 23248 | E20: 25326 | F20: =F$8*Assumptions!C26 -> 28901.609 | G20: =G$8*Assumptions!D26 -> 34681.931 | H20: =H$8*Assumptions!E26 -> 39884.22 | I20: =I$8*Assumptions!F26 -> 43872.642 | J20: =J$8*Assumptions!G26 -> 46066.274
A21: Other Operating Expenses | B21: 44685 | C21: 53463 | D21: 65074 | E21: 60721 | F21: =F$8*Assumptions!C27 -> 77267.566 | G21: =G$8*Assumptions!D27 -> 92013.285 | H21: =H$8*Assumptions!E27 -> 105815.28 | I21: =I$8*Assumptions!F27 -> 116396.81 | J21: =J$8*Assumptions!G27 -> 122216.65
A22: Total Restaurant Expenses | B22: =SUM(B17:B21) -> 276653 | C22: =SUM(C17:C21) -> 315986 | D22: =SUM(D17:D21) -> 368978 | E22: 362858 | F22: =SUM(F17:F21) -> 475401.97 | G22: =SUM(G17:G21) -> 564820.01 | H22: =SUM(H17:H21) -> 649543.01 | I22: =SUM(I17:I21) -> 714497.31 | J22: =SUM(J17:J21) -> 750222.18
A24: Commissary, Equipment and Other Expenses
A25: Cost of Sales | B25: 235934 | C25: 274613 | D25: 304338 | E25: 323954 | F25: =(F$11+F$12)*Assumptions!C30 -> 429883.97 | G25: =(G$11+G$12)*Assumptions!D30 -> 515860.77 | H25: =(H$11+H$12)*Assumptions!E30 -> 593239.88 | I25: =(I$11+I$12)*Assumptions!F30 -> 652563.87 | J25: =(J$11+J$12)*Assumptions!G30 -> 685192.06
A26: Salaries and Benefits | B26: 16981 | C26: 23719 | D26: 27682 | E26: 30124 | F26: =(F$11+F$12)*Assumptions!C31 -> 30784.53 | G26: =(G$11+G$12)*Assumptions!D31 -> 36941.436 | H26: =(H$11+H$12)*Assumptions!E31 -> 42482.651 | I26: =(I$11+I$12)*Assumptions!F31 -> 46730.917 | J26: =(J$11+J$12)*Assumptions!G31 -> 49067.462
A27: Other Operating Expenses | B27: 22560 | C27: 27702 | D27: 30736 | E27: 41053 | F27: =(F$11+F$12)*Assumptions!C32 -> 40679.557 | G27: =(G$11+G$12)*Assumptions!D32 -> 48815.469 | H27: =(H$11+H$12)*Assumptions!E32 -> 56137.789 | I27: =(I$11+I$12)*Assumptions!F32 -> 61751.568 | J27: =(J$11+J$12)*Assumptions!G32 -> 64839.147
A28: Total Commissary Equipment and Other Expenses | B28: =SUM(B25:B27) -> 275475 | C28: =SUM(C25:C27) -> 326034 | D28: =SUM(D25:D27) -> 362756 | E28: 395131 | F28: =SUM(F25:F27) -> 501348.06 | G28: =SUM(G25:G27) -> 601617.67 | H28: =SUM(H25:H27) -> 691860.32 | I28: =SUM(I25:I27) -> 761046.36 | J28: =SUM(J25:J27) -> 799098.67
A30: Other Expenses
A31: General and Administrative Expenses | B31: 53008 | C31: 54386 | D31: 72402 | E31: 69487 | F31: =F$13*Assumptions!C34 -> 86196.84 | G31: =G$13*Assumptions!D34 -> 99065.664 | H31: =H$13*Assumptions!E34 -> 113925.51 | I31: =I$13*Assumptions!F34 -> 125318.06 | J31: =J$13*Assumptions!G34 -> 131583.97
A32: Pre-Opening and Other General Expenses | B32: 2838 | C32: 3414 | D32: 2158 | E32: 3521 | F32: =F$13*Assumptions!C35 -> 3642.12 | G32: =G$13*Assumptions!D35 -> 4370.544 | H32: =H$13*Assumptions!E35 -> 5026.1256 | I32: =I$13*Assumptions!F35 -> 5528.7382 | J32: =J$13*Assumptions!G35 -> 5805.1751
A33: Depreciation and Amortization | B33: 20490 | C33: 24827 | D33: 34172 | E33: 35176 | F33: =+'Fixed Asset Schedule'!E14 -> 31227.833 | G33: =+'Fixed Asset Schedule'!F14 -> 35894.5 | H33: =+'Fixed Asset Schedule'!G14 -> 40561.167 | I33: =+'Fixed Asset Schedule'!H14 -> 45227.833 | J33: =+'Fixed Asset Schedule'!I14 -> 49894.5
A34: International expenses | B34: 0 | C34: 2090 | D34: 21700 | E34: 21739 | F34: =F$13*Assumptions!C37 -> 9712.32 | G34: =G$13*Assumptions!D37 -> 11654.784 | H34: =H$13*Assumptions!E37 -> 13403.002 | I34: =I$13*Assumptions!F37 -> 14743.302 | J34: =J$13*Assumptions!G37 -> 15480.467
A35: Other Expenses | B35: 0 | C35: 6104 | D35: 25122 | E35: 537 | F35: =F$13*Assumptions!C38 -> 32779.08 | G35: =G$13*Assumptions!D38 -> 39334.896 | H35: =H$13*Assumptions!E38 -> 45235.13 | I35: =I$13*Assumptions!F38 -> 49758.643 | J35: =J$13*Assumptions!G38 -> 52246.576
A36: Total Other Expenses | B36: =SUM(B31:B35) -> 76336 | C36: =SUM(C31:C35) -> 90821 | D36: =SUM(D31:D35) -> 155554 | E36: 130460 | F36: =SUM(F31:F35) -> 163558.19 | G36: =SUM(G31:G35) -> 190320.39 | H36: =SUM(H31:H35) -> 218150.94 | I36: =SUM(I31:I35) -> 240576.58 | J36: =SUM(J31:J35) -> 255010.69
A38: Total Expenses | B38: =B22+B28+B36 -> 628464 | C38: =C22+C28+C36 -> 732841 | D38: =D22+D28+D36 -> 887288 | E38: 888449 | F38: =F22+F28+F36 -> 1140308.2 | G38: =G22+G28+G36 -> 1356758.1 | H38: =H22+H28+H36 -> 1559554.3 | I38: =I22+I28+I36 -> 1716120.3 | J38: =J22+J28+J36 -> 1804331.5
A40: Operating Income (EBIT) | B40: =B13-B38 -> 53688 | C40: =C13-C38 -> 72484 | D40: =D13-D38 -> 57389 | E40: 82783 | F40: =F13-F38 -> 73731.774 | G40: =G13-G38 -> 100089.93 | H40: =H13-H38 -> 115820.93 | I40: =I13-I38 -> 126792.47 | J40: =J13-J38 -> 130726.82
A41: Investment Income | B41: 4100 | C41: 3384 | D41: 1943 | E41: 1958 | F41: =+Assumptions!C40*Assumptions!C61 -> 1500 | G41: =+Assumptions!D40*Assumptions!D61 -> 1500 | H41: =+Assumptions!E40*Assumptions!E61 -> 1500 | I41: =+Assumptions!F40*Assumptions!F61 -> 1500 | J41: =+Assumptions!G40*Assumptions!G61 -> 1500
A42: Interest expense | B42: -643 | C42: -151 | D42: -7746 | E42: -8857 | F42: =-Assumptions!C41*('Balance Sheet'!E39+'Balance Sheet'!E34) -> -6324.6351 | G42: =-Assumptions!D41*('Balance Sheet'!G39+'Balance Sheet'!G34) -> -47838.608 | H42: =-Assumptions!E41*('Balance Sheet'!H39+'Balance Sheet'!H34) -> -46508.217 | I42: =-Assumptions!F41*('Balance Sheet'!I39+'Balance Sheet'!I34) -> -44103.546 | J42: =-Assumptions!G41*('Balance Sheet'!J39+'Balance Sheet'!J34) -> -40852.297
A44: Income Before Taxes and Cumulative Effect of a Change in Accounting Principle | B44: =SUM(B40:B42) -> 57145 | C44: =SUM(C40:C42) -> 75717 | D44: =SUM(D40:D42) -> 51586 | E44: 75884 | F44: =SUM(F40:F42) -> 68907.139 | G44: =SUM(G40:G42) -> 53751.321 | H44: =SUM(H40:H42) -> 70812.71 | I44: =SUM(I40:I42) -> 84188.924 | J44: =SUM(J40:J42) -> 91374.521
A45: Provision for Income Taxes | B45: 22181 | C45: 28431 | D45: 19762 | E45: 28639 | F45: =+F44*Assumptions!C43 -> 25840.177 | G45: =+G44*Assumptions!D43 -> 20156.745 | H45: =+H44*Assumptions!E43 -> 26554.766 | I45: =+I44*Assumptions!F43 -> 31570.846 | J45: =+J44*Assumptions!G43 -> 34265.445
A47: Income Before Cumulative Effect of a Change in Accounting Principle | B47: =B44-B45 -> 34964 | C47: =C44-C45 -> 47286 | D47: =D44-D45 -> 31824 | E47: 47245 | F47: =F44-F45 -> 43066.962 | G47: =G44-G45 -> 33594.576 | H47: =H44-H45 -> 44257.944 | I47: =I44-I45 -> 52618.077 | J47: =J44-J45 -> 57109.076
A48: Cumulative Effect of Accounting Change, Net of Tax | B48: -2603 | C48: 0 | D48: 0 | E48: 0 | F48: 0 | G48: 0 | H48: 0 | I48: 0 | J48: 0
...

Sheet Balance Sheet
A1: =Assumptions!D6 -> Papa John's International, Inc.
A3: Balance Sheet
A4: ="(Dollars in "& IF(Assumptions!D6=1, "Millions", "Thousands") &" Except Per Share Data)" -> (Dollars in Thousands Except Per Share Data)
A6: Assets | B6: =+'Income Statement'!C6 -> 1999 | C6: =+'Income Statement'!D6 -> 2000 | D6: =+'Income Statement'!E6 -> 2001 | E6: =+Assumptions!C13 -> 2002E | F6: Transaction | G6: =+Assumptions!D13 -> 2003E | H6: =+Assumptions!E13 -> 2004E | I6: =+Assumptions!F13 -> 2005E | J6: =+Assumptions!G13 -> 2006E
A7: Current Assets
A8: Cash and Cash Equivalents | B8: 3698 | C8: 6141 | D8: 17609 | E8: =Assumptions!C52*'Income Statement'!F$13 -> 6070.2 | G8: =Assumptions!D52*'Income Statement'!G$13 -> 7284.24 | H8: =Assumptions!E52*'Income Statement'!H$13 -> 8376.876 | I8: =Assumptions!F52*'Income Statement'!I$13 -> 9214.5636 | J8: =Assumptions!G52*'Income Statement'!J$13 -> 9675.2918
A9: Excess cash | B9: 0 | C9: 0 | D9: 0 | E9: =+E44+SUM(E49:E55)-E25-SUM(E10:E15)-E8 -> -6.0936145e-11 | G9: =+G44+SUM(G49:G55)-G25-SUM(G10:G15)-G8 -> 1.2187229e-10 | H9: =+H44+SUM(H49:H55)-H25-SUM(H10:H15)-H8 -> 0 | I9: =+I44+SUM(I49:I55)-I25-SUM(I10:I15)-I8 -> 6.7302608e-11 | J9: =+J44+SUM(J49:J55)-J25-SUM(J10:J15)-J8 -> 1.0186341e-10
A10: Accounts Receivable | B10: 18113 | C10: 20259 | D10: 18891 | E10: =Assumptions!C53*'Income Statement'!F$13 -> 29136.96 | G10: =Assumptions!D53*'Income Statement'!G$13 -> 34964.352 | H10: =Assumptions!E53*'Income Statement'!H$13 -> 40209.005 | I10: =Assumptions!F53*'Income Statement'!I$13 -> 44229.905 | J10: =Assumptions!G53*'Income Statement'!J$13 -> 46441.401
A11: Accounts Receivable - Affiliates | B11: 3302 | C11: 2805 | D11: 4347 | E11: =Assumptions!C54*'Income Statement'!F$13 -> 4856.16 | G11: =Assumptions!D54*'Income Statement'!G$13 -> 5827.392 | H11: =Assumptions!E54*'Income Statement'!H$13 -> 6701.5008 | I11: =Assumptions!F54*'Income Statement'!I$13 -> 7371.6509 | J11: =Assumptions!G54*'Income Statement'!J$13 -> 7740.2334
A12: Inventories | B12: 10637 | C12: 18321 | D12: 12659 | E12: =Assumptions!C55*'Income Statement'!F$13 -> 19424.64 | G12: =Assumptions!D55*'Income Statement'!G$13 -> 23309.568 | H12: =Assumptions!E55*'Income Statement'!H$13 -> 26806.003 | I12: =Assumptions!F55*'Income Statement'!I$13 -> 29486.604 | J12: =Assumptions!G55*'Income Statement'!J$13 -> 30960.934
A13: Deferred Pre-Opening Costs | B13: 0 | C13: 0 | E13: =Assumptions!C56*'Income Statement'!F$13 -> 4856.16 | G13: =Assumptions!D56*'Income Statement'!G$13 -> 5827.392 | H13: =Assumptions!E56*'Income Statement'!H$13 -> 6701.5008 | I13: =Assumptions!F56*'Income Statement'!I$13 -> 7371.6509 | J13: =Assumptions!G56*'Income Statement'!J$13 -> 7740.2334
A14: Prepaid Expenses and Other Current Assets | B14: 7378 | C14: 13167 | D14: 8986 | E14: =Assumptions!C57*'Income Statement'!F$13 -> 7284.24 | G14: =Assumptions!D57*'Income Statement'!G$13 -> 8741.088 | H14: =Assumptions!E57*'Income Statement'!H$13 -> 10052.251 | I14: =Assumptions!F57*'Income Statement'!I$13 -> 11057.476 | J14: =Assumptions!G57*'Income Statement'!J$13 -> 11610.35
A15: Deferred Income Taxes | B15: 2977 | C15: 4822 | D15: 2639 | E15: =Assumptions!C58*'Income Statement'!F$13 -> 2428.08 | G15: =Assumptions!D58*'Income Statement'!G$13 -> 2913.696 | H15: =Assumptions!E58*'Income Statement'!H$13 -> 3350.7504 | I15: =Assumptions!F58*'Income Statement'!I$13 -> 3685.8254 | J15: =Assumptions!G58*'Income Statement'!J$13 -> 3870.1167
A16: Total Current Assets | B16: =SUM(B8:B15) -> 46105 | C16: =SUM(C8:C15) -> 65515 | D16: =SUM(D8:D15) -> 65131 | E16: =SUM(E8:E15) -> 74056.44 | G16: =SUM(G8:G15) -> 88867.728 | H16: =SUM(H8:H15) -> 102197.89 | I16: =SUM(I8:I15) -> 112417.68 | J16: =SUM(J8:J15) -> 118038.56
A18: Non-Current Assets
A19: Investments | B19: 22086 | C19: 0 | D19: 3424 | E19: =Assumptions!C61 -> 25000 | G19: =Assumptions!D61 -> 25000 | H19: =Assumptions!E61 -> 25000 | I19: =Assumptions!F61 -> 25000 | J19: =Assumptions!G61 -> 25000
A20: Net Property and Equipment | B20: 227813 | C20: 245874 | D20: 238945 | E20: =+'Fixed Asset Schedule'!E21 -> 317717.17 | G20: =+'Fixed Asset Schedule'!F21 -> 351822.67 | H20: =+'Fixed Asset Schedule'!G21 -> 381261.5 | I20: =+'Fixed Asset Schedule'!H21 -> 406033.67 | J20: =+'Fixed Asset Schedule'!I21 -> 426139.17
A21: Notes Receivable - Franchisees | B21: 8153 | C21: 9862 | D21: 16913 | E21: ='Income Statement'!F$13*Assumptions!C63 -> 10926.36 | G21: ='Income Statement'!G$13*Assumptions!D63 -> 13111.632 | H21: ='Income Statement'!H$13*Assumptions!E63 -> 15078.377 | I21: ='Income Statement'!I$13*Assumptions!F63 -> 16586.214 | J21: ='Income Statement'!J$13*Assumptions!G63 -> 17415.525
A22: Notes Receivable - Affiliates | B22: 3590 | C22: 6813 | D22: 661 | E22: ='Income Statement'!F$13*Assumptions!C64 -> 9712.32 | G22: ='Income Statement'!G$13*Assumptions!D64 -> 11654.784 | H22: ='Income Statement'!H$13*Assumptions!E64 -> 13403.002 | I22: ='Income Statement'!I$13*Assumptions!F64 -> 14743.302 | J22: ='Income Statement'!J$13*Assumptions!G64 -> 15480.467
A23: Goodwill | B23: 0 | C23: 0 | D23: 0 | E23: 0 | F23: =IF('Transaction Summary'!G13=0,0,'Transaction Summary'!C31) -> 0 | G23: =+E23+F23 -> 0 | H23: =+G23 -> 0 | I23: =+H23 -> 0 | J23: =+I23 -> 0
A24: Other Assets | B24: 64304 | C24: 67594 | D24: 62365 | E24: ='Income Statement'!F$13*Assumptions!C65 -> 49775.64 | G24: ='Income Statement'!G$13*Assumptions!D65 -> 59730.768 | H24: ='Income Statement'!H$13*Assumptions!E65 -> 68690.383 | I24: ='Income Statement'!I$13*Assumptions!F65 -> 75559.422 | J24: ='Income Statement'!J$13*Assumptions!G65 -> 79337.393
A25: Total Non-Current Assets | B25: =SUM(B19:B24) -> 325946 | C25: =SUM(C19:C24) -> 330143 | D25: =SUM(D19:D24) -> 322308 | E25: =SUM(E19:E24) -> 413131.49 | G25: =SUM(G19:G24) -> 461319.85 | H25: =SUM(H19:H24) -> 503433.26 | I25: =SUM(I19:I24) -> 537922.6 | J25: =SUM(J19:J24) -> 563372.55
A27: Total Assets | B27: =B16+B25 -> 372051 | C27: =C16+C25 -> 395658 | D27: =D16+D25 -> 387439 | E27: =E16+E25 -> 487187.93 | G27: =G16+G25 -> 550187.58 | H27: =H16+H25 -> 605631.15 | I27: =I16+I25 -> 650340.28 | J27: =J16+J25 -> 681411.11
A29: Liabilities & Stockholder's Equity | B29: =+B6 -> 1999 | C29: =+C6 -> 2000 | D29: =+D6 -> 2001 | E29: =+E6 -> 2002E | G29: =+G6 -> 2003E | H29: =+H6 -> 2004E | I29: =+I6 -> 2005E | J29: =+J6 -> 2006E
A30: Current Liabilities
A31: Accounts Payable | B31: 24947 | C31: 23586 | D31: 23808 | E31: ='Income Statement'!F$13*Assumptions!C69 -> 33993.12 | G31: ='Income Statement'!G$13*Assumptions!D69 -> 40791.744 | H31: ='Income Statement'!H$13*Assumptions!E69 -> 46910.506 | I31: ='Income Statement'!I$13*Assumptions!F69 -> 51601.556 | J31: ='Income Statement'!J$13*Assumptions!G69 -> 54181.634
A32: Accrued Expenses | B32: 38516 | C32: 45266 | D32: 42401 | E32: ='Income Statement'!F$13*Assumptions!C70 -> 41277.36 | G32: ='Income Statement'!G$13*Assumptions!D70 -> 49532.832 | H32: ='Income Statement'!H$13*Assumptions!E70 -> 56962.757 | I32: ='Income Statement'!I$13*Assumptions!F70 -> 62659.032 | J32: ='Income Statement'!J$13*Assumptions!G70 -> 65791.984
A33: Deferred Income Taxes | B33: 0 | C33: 0 | D33: 0 | E33: =+SUM('Fixed Asset Schedule'!$E$42:'Fixed Asset Schedule'!E42)*Assumptions!C43-SUM('Fixed Asset Schedule'!$E$14:'Fixed Asset Schedule'!E14)*Assumptions!C43 -> 14460.438 | G33: =+SUM('Fixed Asset Schedule'!$E$42:'Fixed Asset Schedule'!F42)*Assumptions!D43-SUM('Fixed Asset Schedule'!$E$14:'Fixed Asset Schedule'!F14)*Assumptions!D43 -> 27186.7 | H33: =+SUM('Fixed Asset Schedule'!$E$42:'Fixed Asset Schedule'!G42)*Assumptions!E43-SUM('Fixed Asset Schedule'!$E$14:'Fixed Asset Schedule'!G14)*Assumptions!E43 -> 38175.622 | I33: =+SUM('Fixed Asset Schedule'!$E$42:'Fixed Asset Schedule'!H42)*Assumptions!F43-SUM('Fixed Asset Schedule'!$E$14:'Fixed Asset Schedule'!H14)*Assumptions!F43 -> 47424.673 | J33: =+SUM('Fixed Asset Schedule'!$E$42:'Fixed Asset Schedule'!I42)*Assumptions!G43-SUM('Fixed Asset Schedule'!$E$14:'Fixed Asset Schedule'!I14)*Assumptions!G43 -> 54931.826
A34: Current portion of debt | B34: 5308 | C34: 897 | D34: 225 | E34: 0 | G34: 0 | H34: 0 | I34: 0 | J34: 0
A35: Total Current Liabilities | B35: =SUM(B31:B34) -> 68771 | C35: =SUM(C31:C34) -> 69749 | D35: 66434 | E35: =SUM(E31:E34) -> 89730.918 | G35: =SUM(G31:G34) -> 117511.28 | H35: =SUM(H31:H34) -> 142048.88 | I35: =SUM(I31:I34) -> 161685.26 | J35: =SUM(J31:J34) -> 174905.44
A37: Non-Current Liabilities
A38: Unearned Franchise and Development Fees | B38: 6222 | C38: 6033 | D38: 3292 | E38: ='Income Statement'!F$13*Assumptions!C75 -> 10926.36 | G38: ='Income Statement'!G$13*Assumptions!D75 -> 13111.632 | H38: ='Income Statement'!H$13*Assumptions!E75 -> 15078.377 | I38: ='Income Statement'!I$13*Assumptions!F75 -> 16586.214 | J38: ='Income Statement'!J$13*Assumptions!G75 -> 17415.525
A39: Long term debt, net of current portion | B39: 925 | C39: 145710 | D39: 105085 | E39: =MAX(E8+SUM(E10:E15)+E25-E38-E35-E40-E41-SUM(E49:E55),0) -> 140547.45 | F39: =IF('Transaction Summary'!G13=0,'Transaction Summary'!C5-'Transaction Summary'!C13,'Transaction Summary'!C5-'Transaction Summary'!C13) -> 459452.55 | G39: =MAX(G8+SUM(G10:G15)+G25-G38-G35-G40-G41-SUM(G49:G55),0) -> 597982.6 | H39: =MAX(H8+SUM(H10:H15)+H25-H38-H35-H40-H41-SUM(H49:H55),0) -> 581352.71 | I39: =MAX(I8+SUM(I10:I15)+I25-I38-I35-I40-I41-SUM(I49:I55),0) -> 551294.32 | J39: =MAX(J8+SUM(J10:J15)+J25-J38-J35-J40-J41-SUM(J49:J55),0) -> 510653.71
A40: Deferred Income Taxes | B40: 2109 | C40: 0 | D40: 3467 | E40: ='Income Statement'!F$13*Assumptions!C77 -> 4856.16 | G40: ='Income Statement'!G$13*Assumptions!D77 -> 5827.392 | H40: ='Income Statement'!H$13*Assumptions!E77 -> 6701.5008 | I40: ='Income Statement'!I$13*Assumptions!F77 -> 7371.6509 | J40: ='Income Statement'!J$13*Assumptions!G77 -> 7740.2334
A41: Other Long-Term Liabilities | B41: 1891 | C41: 7845 | D41: 13529 | E41: ='Income Statement'!F$13*Assumptions!C78 -> 2428.08 | G41: ='Income Statement'!G$13*Assumptions!D78 -> 2913.696 | H41: ='Income Statement'!H$13*Assumptions!E78 -> 3350.7504 | I41: ='Income Statement'!I$13*Assumptions!F78 -> 3685.8254 | J41: ='Income Statement'!J$13*Assumptions!G78 -> 3870.1167
A42: Total Non-Current Liabilities | B42: =SUM(B38:B41) -> 11147 | C42: =SUM(C38:C41) -> 159588 | D42: =SUM(D38:D41) -> 125373 | E42: =SUM(E38:E41) -> 158758.05 | G42: =SUM(G38:G41) -> 619835.32 | H42: =SUM(H38:H41) -> 606483.34 | I42: =SUM(I38:I41) -> 578938.01 | J42: =SUM(J38:J41) -> 539679.59
A44: Total Liabilities | B44: =B35+B42 -> 79918 | C44: =C35+C42 -> 229337 | D44: =D35+D42 -> 191807 | E44: =E35+E42 -> 248488.96 | G44: =G35+G42 -> 737346.59 | H44: =H35+H42 -> 748532.22 | I44: =I35+I42 -> 740623.27 | J44: =J35+J42 -> 714585.03
A47: Common stock ($.01 par value per share;
A48: authorized 50,000,000 shares, issued
A49: 30,504,185 in 1999 and 29,866,832 in 1998) | B49: 305 | C49: 307 | D49: 310 | E49: 310 | G49: 310 | H49: 310 | I49: 310 | J49: 310
...

Sheet Fixed Asset Schedule
A1: =+Assumptions!D6 -> Papa John's International, Inc.
A3: Fixed Asset Schedule
A4: (Dollars in Thousands Except Per Share Data)
E6: Depreciation Schedule
D7: =+Assumptions!D8 -> 2001 | E7: =+D7+1 -> 2002 | F7: =+E7+1 -> 2003 | G7: =+F7+1 -> 2004 | H7: =+G7+1 -> 2005 | I7: =+H7+1 -> 2006
A8: Beginning Net Property and Equipment | B8: =+'Balance Sheet'!D20 -> 238945 | E8: =IF($J$24=0,IF(E7-$D$7>$B$26,0,($B$8-(D26*B8))/$B$26),B8*$E$26) -> 23894.5 | F8: =IF($J$24=0,IF(F7-$D$7>$B$26,0,($B$8-($B8*$D$26))/$B$26),($B$8-SUM($E8:E8))*$E$26) -> 23894.5 | G8: =IF($J$24=0,IF(G7-$D$7>$B$26,0,($B$8-($B8*$D$26))/$B$26),($B$8-SUM($E8:F8))*$E$26) -> 23894.5 | H8: =IF($J$24=0,IF(H7-$D$7>$B$26,0,($B$8-($B8*$D$26))/$B$26),($B$8-SUM($E8:G8))*$E$26) -> 23894.5 | I8: =IF($J$24=0,IF(I7-$D$7>$B$26,0,($B$8-($B8*$D$26))/$B$26),($B$8-SUM($E8:H8))*$E$26) -> 23894.5
A9: 2002 CAPEX | B9: 110000 | E9: =IF($J$24=0,IF(E7-$D$7>$B$27,0,($B$9-($B$9*$D$27))/$B$27),$B$9*$E$26) -> 7333.3333 | F9: =IF($J$24=0,IF(F$7-$D$7>$B$27,0,($B$9-($B$9*$D$27))/$B$27),($B$9-SUM($C9:E9))*$E$27) -> 7333.3333 | G9: =IF($J$24=0,IF(G$7-$D$7>$B$27,0,($B$9-($B$9*$D$27))/$B$27),($B$9-SUM($C9:F9))*$E$27) -> 7333.3333 | H9: =IF($J$24=0,IF(H$7-$D$7>$B$27,0,($B$9-($B$9*$D$27))/$B$27),($B$9-SUM($C9:G9))*$E$27) -> 7333.3333 | I9: =IF($J$24=0,IF(I$7-$D$7>$B$27,0,($B$9-($B$9*$D$27))/$B$27),($B$9-SUM($C9:H9))*$E$27) -> 7333.3333
A10: 2003 CAPEX | B10: 70000 | F10: =IF($J$24=0,IF(F7-$E$7>$B$28,0,($B$10-($B$10*$D$28))/$B$28),($B$10-SUM($E10:E10))*$E$28) -> 4666.6667 | G10: =IF($J$24=0,IF(G7-$E$7>$B$28,0,($B$10-($B$10*$D$28))/$B$28),($B$10-SUM($E10:F10))*$E$28) -> 4666.6667 | H10: =IF($J$24=0,IF(H7-$E$7>$B$28,0,($B$10-($B$10*$D$28))/$B$28),($B$10-SUM($E10:G10))*$E$28) -> 4666.6667 | I10: =IF($J$24=0,IF(I7-$E$7>$B$28,0,($B$10-($B$10*$D$28))/$B$28),($B$10-SUM($E10:H10))*$E$28) -> 4666.6667
A11: 2004 CAPEX | B11: 70000 | G11: =IF($J$24=0,IF(G7-$F$7>$B$29,0,($B$11-($B$11*$D$29))/$B$29),($B$11-SUM($E11:F11))*$E$29) -> 4666.6667 | H11: =IF($J$24=0,IF(H7-$F$7>$B$29,0,($B$11-($B$11*$D$29))/$B$29),($B$11-SUM($E11:G11))*$E$29) -> 4666.6667 | I11: =IF($J$24=0,IF(I7-$F$7>$B$29,0,($B$11-($B$11*$D$29))/$B$29),($B$11-SUM($E11:H11))*$E$29) -> 4666.6667
A12: 2005 CAPEX | B12: 70000 | H12: =IF($J$24=0,IF(H7-$G$7>$B$30,0,($B$12-($B$12*$D$30))/$B$30),($B$12-SUM($E12:G12))*$E$30) -> 4666.6667 | I12: =IF($J$24=0,IF(I7-$G$7>$B$30,0,($B$12-($B$12*$D$30))/$B$30),($B$12-SUM($E12:H12))*$E$30) -> 4666.6667
A13: 2006 CAPEX | B13: 70000 | I13: =IF($J$24=0,IF(I7-$I$7>$B$31,0,($B$13-($B$13*$D$31))/$B$31),($B$13-SUM($E13:H13))*$E$31) -> 4666.6667
A14: Total Depreciation | E14: =SUM(E8:E13) -> 31227.833 | F14: =SUM(F8:F13) -> 35894.5 | G14: =SUM(G8:G13) -> 40561.167 | H14: =SUM(H8:H13) -> 45227.833 | I14: =SUM(I8:I13) -> 49894.5
E17: =+Assumptions!C13 -> 2002E | F17: =+Assumptions!D13 -> 2003E | G17: =+Assumptions!E13 -> 2004E | H17: =+Assumptions!F13 -> 2005E | I17: =+Assumptions!G13 -> 2006E
A18: Beginning Balance | E18: =B8 -> 238945 | F18: =E21 -> 317717.17 | G18: =F21 -> 351822.67 | H18: =G21 -> 381261.5 | I18: =H21 -> 406033.67
A19: Add: CAPEX | E19: =B9 -> 110000 | F19: =B10 -> 70000 | G19: =B11 -> 70000 | H19: =B12 -> 70000 | I19: =B13 -> 70000
A20: Less: Depreciation | E20: =E14 -> 31227.833 | F20: =F14 -> 35894.5 | G20: =G14 -> 40561.167 | H20: =H14 -> 45227.833 | I20: =I14 -> 49894.5
A21: Ending Balance | E21: =E18+E19-E20 -> 317717.17 | F21: =F18+F19-F20 -> 351822.67 | G21: =G18+G19-G20 -> 381261.5 | H21: =H18+H19-H20 -> 406033.67 | I21: =I18+I19-I20 -> 426139.17
G24: Straight-Line=0; Accelerated=1 | J24: 0
B25: # of years | C25: Est. Salvage | E25: %declining
A26: Estimated useful life of beginning Net PPE (in years) | B26: 10 | D26: 0 | E26: 0.2
A27: Estimate useful life of 2002 CAPEX | B27: 15 | D27: 0 | E27: 0.2
A28: Estimate useful life of 2003 CAPEX | B28: 15 | D28: 0 | E28: 0.2
A29: Estimate useful life of 2004 CAPEX | B29: 15 | D29: 0 | E29: 0.2
A30: Estimate useful life of 2005 CAPEX | B30: 15 | D30: 0 | E30: 0.2
A31: Estimate useful life of 2006 CAPEX | B31: 15 | D31: 0 | E31: 0.2
E34: Depreciation for Tax Purposes
B35: =+B8 -> 238945 | E35: =$B$8*$E$26 -> 47789 | F35: =($B$35-SUM($E35:E35))*$E$26 -> 38231.2 | G35: =($B$35-SUM($E35:F35))*$E$26 -> 30584.96 | H35: =($B$35-SUM($E35:G35))*$E$26 -> 24467.968 | I35: =($B$35-SUM($E35:H35))*$E$26 -> 19574.374
B36: =+B9 -> 110000 | E36: =+B9*E27 -> 22000 | F36: =($B36-SUM($E36:E36))*$E27 -> 17600 | G36: =($B36-SUM($E36:F36))*$E27 -> 14080 | H36: =($B36-SUM($E36:G36))*$E27 -> 11264 | I36: =($B36-SUM($E36:H36))*$E27 -> 9011.2
B37: =+B10 -> 70000 | F37: =($B37-SUM($E37:E37))*$E28 -> 14000 | G37: =($B37-SUM($E37:F37))*$E28 -> 11200 | H37: =($B37-SUM($E37:G37))*$E28 -> 8960 | I37: =($B37-SUM($E37:H37))*$E28 -> 7168
B38: =+B11 -> 70000 | G38: =($B38-SUM($E38:F38))*$E29 -> 14000 | H38: =($B38-SUM($E38:G38))*$E29 -> 11200 | I38: =($B38-SUM($E38:H38))*$E29 -> 8960
B39: =+B12 -> 70000 | H39: =($B39-SUM($E39:G39))*$E30 -> 14000 | I39: =($B39-SUM($E39:H39))*$E30 -> 11200
B40: =+B13 -> 70000 | I40: =($B40-SUM($E40:H40))*$E31 -> 14000
E42: =SUM(E35:E40) -> 69789 | F42: =SUM(F35:F40) -> 69831.2 | G42: =SUM(G35:G40) -> 69864.96 | H42: =SUM(H35:H40) -> 69891.968 | I42: =SUM(I35:I40) -> 69913.574

Sheet DCF
A1: =+Assumptions!D6 -> Papa John's International, Inc.
A4: Discounted Cash Flow Analysis | D4: Do not use this year for discounting
C7: 2002E | D7: 2003E | E7: 2004E | F7: 2005E | G7: 2006E
A9: CFO | C9: =+SCF!C19 -> 75275.073 | D9: =+SCF!D19 -> 87314.306 | E9: =+SCF!E19 -> 100397.1 | F9: =+SCF!F19 -> 110613.25 | G9: =+SCF!G19 -> 116445.79
A10: +Interest Expense net of tax | C10: =-(1-Assumptions!C$43)*'Income Statement'!F42 -> 3952.897 | D10: =-(1-Assumptions!D$43)*'Income Statement'!G42 -> 29899.13 | E10: =-(1-Assumptions!E$43)*'Income Statement'!H42 -> 29067.635 | F10: =-(1-Assumptions!F$43)*'Income Statement'!I42 -> 27564.716 | G10: =-(1-Assumptions!G$43)*'Income Statement'!J42 -> 25532.686
A11: +CFI | C11: =+SCF!C27 -> -122051.32 | D11: =+SCF!D27 -> -84082.864 | E11: =+SCF!E27 -> -82674.578 | F11: =+SCF!F27 -> -79717.176 | G11: =+SCF!G27 -> -75344.447
A12: -Change in operating cash | C12: ='Balance Sheet'!D8-'Balance Sheet'!E8 -> 11538.8 | D12: ='Balance Sheet'!E8-'Balance Sheet'!G8 -> -1214.04 | E12: ='Balance Sheet'!G8-'Balance Sheet'!H8 -> -1092.636 | F12: ='Balance Sheet'!H8-'Balance Sheet'!I8 -> -837.6876 | G12: ='Balance Sheet'!I8-'Balance Sheet'!J8 -> -460.72818
A13: =Free Cash Flows to the Firm | C13: =SUM(C9:C12) -> -31284.55 | D13: =SUM(D9:D12) -> 31916.532 | E13: =SUM(E9:E12) -> 45697.526 | F13: =SUM(F9:F12) -> 57623.101 | G13: =SUM(G9:G12) -> 66173.297
A15: Terminal value at 12/31/2006 | G15: =H15*('Income Statement'!J40+('Income Statement'!J33)) -> 1083727.9 | H15: 6 | I15: x EBITDA
A17: Weighted Average Cost of Capital | B17: 0.1
A18: Terminal Growth Rate | B18: 0.02
A20: Calculation of Total Enterprise Value at 12/31/2002:
A22: NPV of FCF for years 2003-2006 | B22: =NPV($B$17,$D$13:$G$13) -> 155271.92
A23: +NPV of Terminal Value | B23: =G15/(1+B17)^4 -> 740200.74
A24: =Total Present Value of Firm at 12/31/2002 | B24: =SUM(B22:B23) -> 895472.66
A25: -Debt (book value) | B25: =-'Balance Sheet'!$E$39-'Balance Sheet'!$E$34 -> -140547.45
A26: +Excess Cash (=Investments) at 12/31/2002 | B26: =+'Balance Sheet'!$E$19 -> 25000
A27: =Value of Equity at 12/31/2002 | B27: =SUM(B24:B26) -> 779925.22
A28: Divided by # of shrs o/s at 12/31/2002 | B28: =+Assumptions!C45 -> 22600
A29: =Value per share | B29: =B27/B28 -> 34.509965
D32: EBITDA multiple
A33: Sensitivity Analysis | B33: =+B27/B28 -> 34.509965 | C33: 5 | D33: 5.5 | E33: 6 | F33: 6.5 | G33: 7
B34: 0.085 | C34: 30.8499 | D34: 33.733345 | E34: 36.61679 | F34: 39.500234 | G34: 42.383679
B35: 0.09 | C35: 30.23692 | D35: 33.06782 | E35: 35.89872 | F35: 38.729621 | G35: 41.560521
B36: 0.095 | C36: 29.637493 | D36: 32.41704 | E36: 35.196588 | F36: 37.976135 | G36: 40.755683
A37: WACC | B37: 0.1 | C37: 29.051258 | D37: 31.780612 | E37: 34.509965 | F37: 37.239319 | G37: 39.968673
B38: 0.105 | C38: 28.477864 | D38: 31.158151 | E38: 33.838439 | F38: 36.518727 | G38: 39.199015
B39: 0.11 | C39: 27.91697 | D39: 30.54929 | E39: 33.18161 | F39: 35.813929 | G39: 38.446249
B40: 0.115 | C40: 27.368248 | D40: 29.953668 | E40: 32.539088 | F40: 35.124508 | G40: 37.709928

Sheet SCF
A1: =+Assumptions!D6 -> Papa John's International, Inc.
A3: Consolidated Statement of Cash Flows
A4: ="(Dollars in "& IF(Assumptions!D6=1, "Millions", "Thousands") &" Except Per Share Data)" -> (Dollars in Thousands Except Per Share Data)
B6: 2001 | C6: =+B6+1 -> 2002 | D6: =+C6+1 -> 2003 | E6: =+D6+1 -> 2004 | F6: =+E6+1 -> 2005 | G6: =+F6+1 -> 2006
A7: Cash Flow from Operations
A8: Net Income | C8: =+'Income Statement'!F49 -> 43066.962 | D8: =+'Income Statement'!G49 -> 33594.576 | E8: =+'Income Statement'!H49 -> 44257.944 | F8: =+'Income Statement'!I49 -> 52618.077 | G8: =+'Income Statement'!J49 -> 57109.076
A9: Depreciation and Amortization | C9: =+'Income Statement'!F33 -> 31227.833 | D9: =+'Income Statement'!G33 -> 35894.5 | E9: =+'Income Statement'!H33 -> 40561.167 | F9: =+'Income Statement'!I33 -> 45227.833 | G9: =+'Income Statement'!J33 -> 49894.5
A10: (Increase) Decrease in Net Receivables | C10: =+('Balance Sheet'!D10-'Balance Sheet'!E10)+('Balance Sheet'!D11-'Balance Sheet'!E11) -> -10755.12 | D10: =+('Balance Sheet'!E10-'Balance Sheet'!G10)+('Balance Sheet'!E11-'Balance Sheet'!G11) -> -6798.624 | E10: =+('Balance Sheet'!G10-'Balance Sheet'!H10)+('Balance Sheet'!G11-'Balance Sheet'!H11) -> -6118.7616 | F10: =+('Balance Sheet'!H10-'Balance Sheet'!I10)+('Balance Sheet'!H11-'Balance Sheet'!I11) -> -4691.0506 | G10: =+('Balance Sheet'!I10-'Balance Sheet'!J10)+('Balance Sheet'!I11-'Balance Sheet'!J11) -> -2580.0778
A11: (Increase) Decrease in Inventories | C11: =+'Balance Sheet'!D12-'Balance Sheet'!E12 -> -6765.64 | D11: =+'Balance Sheet'!E12-'Balance Sheet'!G12 -> -3884.928 | E11: =+'Balance Sheet'!G12-'Balance Sheet'!H12 -> -3496.4352 | F11: =+'Balance Sheet'!H12-'Balance Sheet'!I12 -> -2680.6003 | G11: =+'Balance Sheet'!I12-'Balance Sheet'!J12 -> -1474.3302
A12: (Increase) Decrease in Deferred Pre-Opening Costs | C12: =+'Balance Sheet'!D13-'Balance Sheet'!E13 -> -4856.16 | D12: =+'Balance Sheet'!E13-'Balance Sheet'!G13 -> -971.232 | E12: =+'Balance Sheet'!G13-'Balance Sheet'!H13 -> -874.1088 | F12: =+'Balance Sheet'!H13-'Balance Sheet'!I13 -> -670.15008 | G12: =+'Balance Sheet'!I13-'Balance Sheet'!J13 -> -368.58254
A13: (Increase) Decrease in Prepaid Expenses and Other Current Assets | C13: =+'Balance Sheet'!D14-'Balance Sheet'!E14 -> 1701.76 | D13: =+'Balance Sheet'!E14-'Balance Sheet'!G14 -> -1456.848 | E13: =+'Balance Sheet'!G14-'Balance Sheet'!H14 -> -1311.1632 | F13: =+'Balance Sheet'!H14-'Balance Sheet'!I14 -> -1005.2251 | G13: =+'Balance Sheet'!I14-'Balance Sheet'!J14 -> -552.87382
A14: (Increase) Decrease in Deferred Income Taxes | C14: =+('Balance Sheet'!D15-'Balance Sheet'!E15)+('Balance Sheet'!E33-'Balance Sheet'!D33)+('Balance Sheet'!E40-'Balance Sheet'!D40) -> 16060.517 | D14: =+('Balance Sheet'!E15-'Balance Sheet'!G15)+('Balance Sheet'!G33-'Balance Sheet'!E33)+('Balance Sheet'!G40-'Balance Sheet'!E40) -> 13211.879 | E14: =+('Balance Sheet'!G15-'Balance Sheet'!H15)+('Balance Sheet'!H33-'Balance Sheet'!G33)+('Balance Sheet'!H40-'Balance Sheet'!G40) -> 11425.977 | F14: =+('Balance Sheet'!H15-'Balance Sheet'!I15)+('Balance Sheet'!I33-'Balance Sheet'!H33)+('Balance Sheet'!I40-'Balance Sheet'!H40) -> 9584.1255 | G14: =+('Balance Sheet'!I15-'Balance Sheet'!J15)+('Balance Sheet'!J33-'Balance Sheet'!I33)+('Balance Sheet'!J40-'Balance Sheet'!I40) -> 7691.4442
A15: Increase (Decrease) in Accounts Payable | C15: =+'Balance Sheet'!E31-'Balance Sheet'!D31 -> 10185.12 | D15: =+'Balance Sheet'!G31-'Balance Sheet'!E31 -> 6798.624 | E15: =+'Balance Sheet'!H31-'Balance Sheet'!G31 -> 6118.7616 | F15: =+'Balance Sheet'!I31-'Balance Sheet'!H31 -> 4691.0506 | G15: =+'Balance Sheet'!J31-'Balance Sheet'!I31 -> 2580.0778
A16: Increase (Decrease) in Accrued Expenses | C16: =+'Balance Sheet'!E32-'Balance Sheet'!D32 -> -1123.64 | D16: =+'Balance Sheet'!G32-'Balance Sheet'!E32 -> 8255.472 | E16: =+'Balance Sheet'!H32-'Balance Sheet'!G32 -> 7429.9248 | F16: =+'Balance Sheet'!I32-'Balance Sheet'!H32 -> 5696.2757 | G16: =+'Balance Sheet'!J32-'Balance Sheet'!I32 -> 3132.9516
A17: Increase (Decrease) in Unearned Franchise and Development Fees | C17: =+'Balance Sheet'!E38-'Balance Sheet'!D38 -> 7634.36 | D17: =+'Balance Sheet'!G38-'Balance Sheet'!E38 -> 2185.272 | E17: =+'Balance Sheet'!H38-'Balance Sheet'!G38 -> 1966.7448 | F17: =+'Balance Sheet'!I38-'Balance Sheet'!H38 -> 1507.8377 | G17: =+'Balance Sheet'!J38-'Balance Sheet'!I38 -> 829.31072
A18: Increase (Decrease) in Other Liabilities | C18: =+'Balance Sheet'!E41-'Balance Sheet'!D41 -> -11100.92 | D18: =+'Balance Sheet'!G41-'Balance Sheet'!E41 -> 485.616 | E18: =+'Balance Sheet'!H41-'Balance Sheet'!G41 -> 437.0544 | F18: =+'Balance Sheet'!I41-'Balance Sheet'!H41 -> 335.07504 | G18: =+'Balance Sheet'!J41-'Balance Sheet'!I41 -> 184.29127
A19: Total | C19: =SUM(C8:C18) -> 75275.073 | D19: =SUM(D8:D18) -> 87314.306 | E19: =SUM(E8:E18) -> 100397.1 | F19: =SUM(F8:F18) -> 110613.25 | G19: =SUM(G8:G18) -> 116445.79
A21: Cash Flow from Investing
A22: Acquisition | C22: =-(+'Balance Sheet'!E23-'Balance Sheet'!D23) -> 0 | D22: =-(+'Balance Sheet'!F23-'Balance Sheet'!E23) -> 0 | E22: =-(+'Balance Sheet'!G23-'Balance Sheet'!F23) -> 0 | F22: =-(+'Balance Sheet'!H23-'Balance Sheet'!G23) -> 0 | G22: =-(+'Balance Sheet'!I23-'Balance Sheet'!H23) -> 0
A23: CAPEX | C23: =-(('Balance Sheet'!E20-'Balance Sheet'!D20)+'Income Statement'!F33) -> -110000 | D23: =-(('Balance Sheet'!G20-'Balance Sheet'!E20)+'Income Statement'!G33) -> -70000 | E23: =-(('Balance Sheet'!H20-'Balance Sheet'!G20)+'Income Statement'!H33) -> -70000 | F23: =-(('Balance Sheet'!I20-'Balance Sheet'!H20)+'Income Statement'!I33) -> -70000 | G23: =-(('Balance Sheet'!J20-'Balance Sheet'!I20)+'Income Statement'!J33) -> -70000
A24: (Increase) Decrease in Other Assets | C24: =+'Balance Sheet'!D24-'Balance Sheet'!E24 -> 12589.36 | D24: =+'Balance Sheet'!E24-'Balance Sheet'!G24 -> -9955.128 | E24: =+'Balance Sheet'!G24-'Balance Sheet'!H24 -> -8959.6152 | F24: =+'Balance Sheet'!H24-'Balance Sheet'!I24 -> -6869.0383 | G24: =+'Balance Sheet'!I24-'Balance Sheet'!J24 -> -3777.9711
A25: (Increase) Decrease in Investments | C25: =+'Balance Sheet'!D19-'Balance Sheet'!E19 -> -21576 | D25: =+'Balance Sheet'!E19-'Balance Sheet'!G19 -> 0 | E25: =+'Balance Sheet'!G19-'Balance Sheet'!H19 -> 0 | F25: =+'Balance Sheet'!H19-'Balance Sheet'!I19 -> 0 | G25: =+'Balance Sheet'!I19-'Balance Sheet'!J19 -> 0
A26: (Increase) Decrease in Notes Receivable | C26: =+('Balance Sheet'!D21-'Balance Sheet'!E21)+('Balance Sheet'!D22-'Balance Sheet'!E22) -> -3064.68 | D26: =+('Balance Sheet'!E21-'Balance Sheet'!G21)+('Balance Sheet'!E22-'Balance Sheet'!G22) -> -4127.736 | E26: =+('Balance Sheet'!G21-'Balance Sheet'!H21)+('Balance Sheet'!G22-'Balance Sheet'!H22) -> -3714.9624 | F26: =+('Balance Sheet'!H21-'Balance Sheet'!I21)+('Balance Sheet'!H22-'Balance Sheet'!I22) -> -2848.1378 | G26: =+('Balance Sheet'!I21-'Balance Sheet'!J21)+('Balance Sheet'!I22-'Balance Sheet'!J22) -> -1566.4758
A27: Total | C27: =SUM(C22:C26) -> -122051.32 | D27: =SUM(D22:D26) -> -84082.864 | E27: =SUM(E22:E26) -> -82674.578 | F27: =SUM(F22:F26) -> -79717.176 | G27: =SUM(G22:G26) -> -75344.447
A29: Cash Flow from Financing
A31: (Dividends Paid) | C31: =+Assumptions!C81*'Income Statement'!F49 -> 0 | D31: =+Assumptions!D81*'Income Statement'!G49 -> 0 | E31: =+Assumptions!E81*'Income Statement'!H49 -> 0 | F31: =+Assumptions!F81*'Income Statement'!I49 -> 0 | G31: =+Assumptions!G81*'Income Statement'!J49 -> 0
A32: Equity Issues (Equity Repurchase) | C32: ='Balance Sheet'!E55-'Balance Sheet'!D55 -> 0 | D32: ='Balance Sheet'!G55-'Balance Sheet'!E55 -> -459452.55 | E32: ='Balance Sheet'!H55-'Balance Sheet'!G55 -> 0 | F32: ='Balance Sheet'!I55-'Balance Sheet'!H55 -> 0 | G32: ='Balance Sheet'!J55-'Balance Sheet'!I55 -> 0
A33: Long Term Debt | C33: =('Balance Sheet'!E39-'Balance Sheet'!D39)+('Balance Sheet'!E34-'Balance Sheet'!D34) -> 35237.447 | D33: =('Balance Sheet'!G39-'Balance Sheet'!E39)+('Balance Sheet'!G34-'Balance Sheet'!E34) -> 457435.15 | E33: =('Balance Sheet'!H39-'Balance Sheet'!G39)+('Balance Sheet'!H34-'Balance Sheet'!G34) -> -16629.891 | F33: =('Balance Sheet'!I39-'Balance Sheet'!H39)+('Balance Sheet'!I34-'Balance Sheet'!H34) -> -30058.385 | G33: =('Balance Sheet'!J39-'Balance Sheet'!I39)+('Balance Sheet'!J34-'Balance Sheet'!I34) -> -40640.612
A34: Total | C34: =SUM(C31:C33) -> 35237.447 | D34: =SUM(D31:D33) -> -2017.4022 | E34: =SUM(E31:E33) -> -16629.891 | F34: =SUM(F31:F33) -> -30058.385 | G34: =SUM(G31:G33) -> -40640.612
A36: Net Change in Cash | C36: =+C19+C27+C34 -> -11538.8 | D36: =+D19+D27+D34 -> 1214.04 | E36: =+E19+E27+E34 -> 1092.636 | F36: =+F19+F27+F34 -> 837.6876 | G36: =+G19+G27+G34 -> 460.72818
A37: Cash at Beginning of Year | C37: ='Balance Sheet'!D8+'Balance Sheet'!D9 -> 17609 | D37: ='Balance Sheet'!E8+'Balance Sheet'!E9 -> 6070.2 | E37: ='Balance Sheet'!G8+'Balance Sheet'!G9 -> 7284.24 | F37: ='Balance Sheet'!H8+'Balance Sheet'!H9 -> 8376.876 | G37: ='Balance Sheet'!I8+'Balance Sheet'!I9 -> 9214.5636
A38: Cash at End of Year | C38: =+C36+C37 -> 6070.2 | D38: =+D36+D37 -> 7284.24 | E38: =+E36+E37 -> 8376.876 | F38: =+F36+F37 -> 9214.5636 | G38: =+G36+G37 -> 9675.2918
A39: Cash Per Balance Sheet | C39: ='Balance Sheet'!E8+'Balance Sheet'!E9 -> 6070.2 | D39: ='Balance Sheet'!G8+'Balance Sheet'!G9 -> 7284.24 | E39: ='Balance Sheet'!H8+'Balance Sheet'!H9 -> 8376.876 | F39: ='Balance Sheet'!I8+'Balance Sheet'!I9 -> 9214.5636 | G39: ='Balance Sheet'!J8+'Balance Sheet'!J9 -> 9675.2918
A40: Unreconciled Difference | C40: =+C39-C38 -> -2.910383e-11 | D40: =+D39-D38 -> 2.1827873e-10 | E40: =+E39-E38 -> -2.0918378e-10 | F40: =+F39-F38 -> 3.4560799e-11 | G40: =+G39-G38 -> 7.2759576e-11

Sheet Dupont
A1: =Assumptions!D6 -> Papa John's International, Inc.
A3: Dupont ROE Decomposition
A5: Overall Profitability Measures | D5: =+Assumptions!D8 -> 2001 | E5: =+Assumptions!C13 -> 2002E | F5: =+Assumptions!D13 -> 2003E | G5: =+Assumptions!E13 -> 2004E | H5: =+Assumptions!F13 -> 2005E | I5: =+Assumptions!G13 -> 2006E
A7: Return on Equity | B7: Net Income/Average Shareholder's Equity | D7: ='Income Statement'!E49/(('Balance Sheet'!D57+'Balance Sheet'!C57)/2) -> 0.26105599 | E7: ='Income Statement'!F49/(('Balance Sheet'!E57+'Balance Sheet'!D57)/2) -> 0.19831403 | F7: ='Income Statement'!G49/(('Balance Sheet'!G57+'Balance Sheet'!E57)/2) -> 1.3036325 | G7: ='Income Statement'!H49/(('Balance Sheet'!H57+'Balance Sheet'!G57)/2) -> -0.26818113 | H7: ='Income Statement'!I49/(('Balance Sheet'!I57+'Balance Sheet'!H57)/2) -> -0.4513008 | I7: ='Income Statement'!J49/(('Balance Sheet'!J57+'Balance Sheet'!I57)/2) -> -0.92516611
A9: Return on Assets | B9: Net Income/Average Total Assets | D9: ='Income Statement'!E49/(('Balance Sheet'!D27+'Balance Sheet'!C27)/2) -> 0.12066194 | E9: ='Income Statement'!F49/(('Balance Sheet'!E27+'Balance Sheet'!D27)/2) -> 0.098480759 | F9: ='Income Statement'!G49/(('Balance Sheet'!G27+'Balance Sheet'!E27)/2) -> 0.0647684 | G9: ='Income Statement'!H49/(('Balance Sheet'!H27+'Balance Sheet'!G27)/2) -> 0.076582846 | H9: ='Income Statement'!I49/(('Balance Sheet'!I27+'Balance Sheet'!H27)/2) -> 0.083788653 | I9: ='Income Statement'!J49/(('Balance Sheet'!J27+'Balance Sheet'!I27)/2) -> 0.08576537
A11: Financial Leverage | B11: Average Total Assets/Average Shareholder's Equity | D11: =(('Balance Sheet'!D27+'Balance Sheet'!C27)/2)/(('Balance Sheet'!D57+'Balance Sheet'!C57)/2) -> 2.1635323 | E11: =(('Balance Sheet'!E27+'Balance Sheet'!D27)/2)/(('Balance Sheet'!E57+'Balance Sheet'!D57)/2) -> 2.0137338 | F11: =(('Balance Sheet'!G27+'Balance Sheet'!E27)/2)/(('Balance Sheet'!G57+'Balance Sheet'!E57)/2) -> 20.127601 | G11: =(('Balance Sheet'!H27+'Balance Sheet'!G27)/2)/(('Balance Sheet'!H57+'Balance Sheet'!G57)/2) -> -3.5018434 | H11: =(('Balance Sheet'!I27+'Balance Sheet'!H27)/2)/(('Balance Sheet'!I57+'Balance Sheet'!H57)/2) -> -5.3861803 | I11: =(('Balance Sheet'!J27+'Balance Sheet'!I27)/2)/(('Balance Sheet'!J57+'Balance Sheet'!I57)/2) -> -10.787176
A13: Return on Sales | B13: Net Income/Sales | D13: ='Income Statement'!E49/'Income Statement'!E13 -> 0.048644402 | E13: ='Income Statement'!F49/'Income Statement'!F13 -> 0.035474088 | F13: ='Income Statement'!G49/'Income Statement'!G13 -> 0.023059767 | G13: ='Income Statement'!H49/'Income Statement'!H13 -> 0.026416736 | H13: ='Income Statement'!I49/'Income Statement'!I13 -> 0.028551584 | I13: ='Income Statement'!J49/'Income Statement'!J13 -> 0.029512844
A15: Asset Turnover | B15: Sales/Average Total Assets | D15: ='Income Statement'!E13/(('Balance Sheet'!D27+'Balance Sheet'!C27)/2) -> 2.4804896 | E15: ='Income Statement'!F13/(('Balance Sheet'!E27+'Balance Sheet'!D27)/2) -> 2.7761322 | F15: ='Income Statement'!G13/(('Balance Sheet'!G27+'Balance Sheet'!E27)/2) -> 2.8087187 | G15: ='Income Statement'!H13/(('Balance Sheet'!H27+'Balance Sheet'!G27)/2) -> 2.8990276 | H15: ='Income Statement'!I13/(('Balance Sheet'!I27+'Balance Sheet'!H27)/2) -> 2.9346412 | I15: ='Income Statement'!J13/(('Balance Sheet'!J27+'Balance Sheet'!I27)/2) -> 2.9060354

Sheet CMN SZ IS 
A1: =Assumptions!D6 -> Papa John's International, Inc.
A3: Consolidated Statements of Income
A4: Common Size
A5: Note: Some of the items of the 10K were grouped
B6: =+'Income Statement'!B6 -> 1998 | C6: =+'Income Statement'!C6 -> 1999 | D6: =+'Income Statement'!D6 -> 2000 | E6: =+'Income Statement'!E6 -> 2001 | F6: =+'Income Statement'!F6 -> 2002E | G6: =+'Income Statement'!G6 -> 2003E | H6: =+'Income Statement'!H6 -> 2004E | I6: =+'Income Statement'!I6 -> 2005E | J6: =+'Income Statement'!J6 -> 2006E
A7: Revenues
A8: Restaurant Sales | B8: =+'Income Statement'!B8/'Income Statement'!B$13 -> 0.5044169 | C8: =+'Income Statement'!C8/'Income Statement'!C$13 -> 0.4932133 | D8: =+'Income Statement'!D8/'Income Statement'!D$13 -> 0.51042102 | E8: =+'Income Statement'!E8/'Income Statement'!E$13 -> 0.48583963 | F8: =+'Income Statement'!F8/'Income Statement'!F$13 -> 0.48583963 | G8: =+'Income Statement'!G8/'Income Statement'!G$13 -> 0.48583963 | H8: =+'Income Statement'!H8/'Income Statement'!H$13 -> 0.48583963 | I8: =+'Income Statement'!I8/'Income Statement'!I$13 -> 0.48583963 | J8: =+'Income Statement'!J8/'Income Statement'!J$13 -> 0.48583963
A9: Franchise Royalties | B9: =+'Income Statement'!B9/'Income Statement'!B$13 -> 0.04708628 | C9: =+'Income Statement'!C9/'Income Statement'!C$13 -> 0.050373452 | D9: =+'Income Statement'!D9/'Income Statement'!D$13 -> 0.049905947 | E9: =+'Income Statement'!E9/'Income Statement'!E$13 -> 0.052271754 | F9: =+'Income Statement'!F9/'Income Statement'!F$13 -> 0.052271754 | G9: =+'Income Statement'!G9/'Income Statement'!G$13 -> 0.052271754 | H9: =+'Income Statement'!H9/'Income Statement'!H$13 -> 0.052271754 | I9: =+'Income Statement'!I9/'Income Statement'!I$13 -> 0.052271754 | J9: =+'Income Statement'!J9/'Income Statement'!J$13 -> 0.052271754
A10: Franchise and Development Fees | B10: =+'Income Statement'!B10/'Income Statement'!B$13 -> 0.0079982174 | C10: =+'Income Statement'!C10/'Income Statement'!C$13 -> 0.0094048986 | D10: =+'Income Statement'!D10/'Income Statement'!D$13 -> 0.011497051 | E10: =+'Income Statement'!E10/'Income Statement'!E$13 -> 0.0090833086 | F10: =+'Income Statement'!F10/'Income Statement'!F$13 -> 0.0090833086 | G10: =+'Income Statement'!G10/'Income Statement'!G$13 -> 0.0090833086 | H10: =+'Income Statement'!H10/'Income Statement'!H$13 -> 0.0090833086 | I10: =+'Income Statement'!I10/'Income Statement'!I$13 -> 0.0090833086 | J10: =+'Income Statement'!J10/'Income Statement'!J$13 -> 0.0090833086
A11: Commisary Sales | B11: =+'Income Statement'!B11/'Income Statement'!B$13 -> 0.37393865 | C11: =+'Income Statement'!C11/'Income Statement'!C$13 -> 0.38109956 | D11: =+'Income Statement'!D11/'Income Statement'!D$13 -> 0.3718255 | E11: =+'Income Statement'!E11/'Income Statement'!E$13 -> 0.39851343 | F11: =+'Income Statement'!F11/'Income Statement'!F$13 -> 0.39851343 | G11: =+'Income Statement'!G11/'Income Statement'!G$13 -> 0.39851343 | H11: =+'Income Statement'!H11/'Income Statement'!H$13 -> 0.39851343 | I11: =+'Income Statement'!I11/'Income Statement'!I$13 -> 0.39851343 | J11: =+'Income Statement'!J11/'Income Statement'!J$13 -> 0.39851343
A12: Equipment and Other Sales | B12: =+'Income Statement'!B12/'Income Statement'!B$13 -> 0.066559946 | C12: =+'Income Statement'!C12/'Income Statement'!C$13 -> 0.065908795 | D12: =+'Income Statement'!D12/'Income Statement'!D$13 -> 0.056350477 | E12: =+'Income Statement'!E12/'Income Statement'!E$13 -> 0.054291868 | F12: =+'Income Statement'!F12/'Income Statement'!F$13 -> 0.054291868 | G12: =+'Income Statement'!G12/'Income Statement'!G$13 -> 0.054291868 | H12: =+'Income Statement'!H12/'Income Statement'!H$13 -> 0.054291868 | I12: =+'Income Statement'!I12/'Income Statement'!I$13 -> 0.054291868 | J12: =+'Income Statement'!J12/'Income Statement'!J$13 -> 0.054291868
A13: Total Revenues | B13: =SUM(B8:B12) -> 1 | C13: =SUM(C8:C12) -> 1 | D13: =SUM(D8:D12) -> 1 | E13: =SUM(E8:E12) -> 1 | F13: =SUM(F8:F12) -> 1 | G13: =SUM(G8:G12) -> 1 | H13: =SUM(H8:H12) -> 1 | I13: =SUM(I8:I12) -> 1 | J13: =SUM(J8:J12) -> 1
A15: Expenses
A16: Restaurant Expenses
A17: Cost of Sales (% Restaurant Sales) | B17: =+'Income Statement'!B17/'Income Statement'!B$8 -> 0.2691513 | C17: =+'Income Statement'!C17/'Income Statement'!C$8 -> 0.25242134 | D17: =+'Income Statement'!D17/'Income Statement'!D$8 -> 0.23146606 | E17: =+'Income Statement'!E17/'Income Statement'!E$8 -> 0.23445788 | F17: =+'Income Statement'!F17/'Income Statement'!F$8 -> 0.268 | G17: =+'Income Statement'!G17/'Income Statement'!G$8 -> 0.268 | H17: =+'Income Statement'!H17/'Income Statement'!H$8 -> 0.268 | I17: =+'Income Statement'!I17/'Income Statement'!I$8 -> 0.268 | J17: =+'Income Statement'!J17/'Income Statement'!J$8 -> 0.268
A18: Salaries and Benefits (% Restaurant Sales) | B18: =+'Income Statement'!B18/'Income Statement'!B$8 -> 0.2684538 | C18: =+'Income Statement'!C18/'Income Statement'!C$8 -> 0.26866517 | D18: =+'Income Statement'!D18/'Income Statement'!D$8 -> 0.26404498 | E18: =+'Income Statement'!E18/'Income Statement'!E$8 -> 0.27737288 | F18: =+'Income Statement'!F18/'Income Statement'!F$8 -> 0.271 | G18: =+'Income Statement'!G18/'Income Statement'!G$8 -> 0.268 | H18: =+'Income Statement'!H18/'Income Statement'!H$8 -> 0.268 | I18: =+'Income Statement'!I18/'Income Statement'!I$8 -> 0.268 | J18: =+'Income Statement'!J18/'Income Statement'!J$8 -> 0.268
A19: Advertising and Related Costs (% of Restaurant Sales) | B19: =+'Income Statement'!B19/'Income Statement'!B$8 -> 0.086739187 | C19: =+'Income Statement'!C19/'Income Statement'!C$8 -> 0.090655267 | D19: =+'Income Statement'!D19/'Income Statement'!D$8 -> 0.086541832 | E19: =+'Income Statement'!E19/'Income Statement'!E$8 -> 0.074803492 | F19: =+'Income Statement'!F19/'Income Statement'!F$8 -> 0.087 | G19: =+'Income Statement'!G19/'Income Statement'!G$8 -> 0.083 | H19: =+'Income Statement'!H19/'Income Statement'!H$8 -> 0.083 | I19: =+'Income Statement'!I19/'Income Statement'!I$8 -> 0.083 | J19: =+'Income Statement'!J19/'Income Statement'!J$8 -> 0.083
A20: Occupancy Costs (% of Restaurant Sales) | B20: =+'Income Statement'!B20/'Income Statement'!B$8 -> 0.049806881 | C20: =+'Income Statement'!C20/'Income Statement'!C$8 -> 0.04919725 | D20: =+'Income Statement'!D20/'Income Statement'!D$8 -> 0.04821406 | E20: =+'Income Statement'!E20/'Income Statement'!E$8 -> 0.053672358 | F20: =+'Income Statement'!F20/'Income Statement'!F$8 -> 0.049 | G20: =+'Income Statement'!G20/'Income Statement'!G$8 -> 0.049 | H20: =+'Income Statement'!H20/'Income Statement'!H$8 -> 0.049 | I20: =+'Income Statement'!I20/'Income Statement'!I$8 -> 0.049 | J20: =+'Income Statement'!J20/'Income Statement'!J$8 -> 0.049
A21: Other Operating Expenses (% of Restaurant Sales) | B21: =+'Income Statement'!B21/'Income Statement'!B$8 -> 0.12986466 | C21: =+'Income Statement'!C21/'Income Statement'!C$8 -> 0.13460071 | D21: =+'Income Statement'!D21/'Income Statement'!D$8 -> 0.13495706 | E21: =+'Income Statement'!E21/'Income Statement'!E$8 -> 0.12868354 | F21: =+'Income Statement'!F21/'Income Statement'!F$8 -> 0.131 | G21: =+'Income Statement'!G21/'Income Statement'!G$8 -> 0.13 | H21: =+'Income Statement'!H21/'Income Statement'!H$8 -> 0.13 | I21: =+'Income Statement'!I21/'Income Statement'!I$8 -> 0.13 | J21: =+'Income Statement'!J21/'Income Statement'!J$8 -> 0.13
A22: Total Restaurant Expenses (% of Restaurant Sales) | B22: =SUM(B17:B21) -> 0.80401582 | C22: =SUM(C17:C21) -> 0.79553974 | D22: =SUM(D17:D21) -> 0.76522399 | E22: =SUM(E17:E21) -> 0.76899015 | F22: =SUM(F17:F21) -> 0.806 | G22: =SUM(G17:G21) -> 0.798 | H22: =SUM(H17:H21) -> 0.798 | I22: =SUM(I17:I21) -> 0.798 | J22: =SUM(J17:J21) -> 0.798
A24: Commissary, Equipment and Other Expenses
A25: Cost of Sales (% of Com. Equip & other expenses) | B25: =+'Income Statement'!B25/'Income Statement'!B$11 -> 0.92493032 | C25: =+'Income Statement'!C25/'Income Statement'!C$11 -> 0.89477011 | D25: =+'Income Statement'!D25/'Income Statement'!D$11 -> 0.86643037 | E25: =+'Income Statement'!E25/'Income Statement'!E$11 -> 0.83698446 | F25: =+'Income Statement'!F25/'Income Statement'!F$11 -> 0.88853654 | G25: =+'Income Statement'!G25/'Income Statement'!G$11 -> 0.88853654 | H25: =+'Income Statement'!H25/'Income Statement'!H$11 -> 0.88853654 | I25: =+'Income Statement'!I25/'Income Statement'!I$11 -> 0.88853654 | J25: =+'Income Statement'!J25/'Income Statement'!J$11 -> 0.88853654
A26: Salaries and Benefits | B26: =+'Income Statement'!B26/'Income Statement'!B$11 -> 0.066570489 | C26: =+'Income Statement'!C26/'Income Statement'!C$11 -> 0.077283494 | D26: =+'Income Statement'!D26/'Income Statement'!D$11 -> 0.078808843 | E26: =+'Income Statement'!E26/'Income Statement'!E$11 -> 0.077829939 | F26: =+'Income Statement'!F26/'Income Statement'!F$11 -> 0.063629215 | G26: =+'Income Statement'!G26/'Income Statement'!G$11 -> 0.063629215 | H26: =+'Income Statement'!H26/'Income Statement'!H$11 -> 0.063629215 | I26: =+'Income Statement'!I26/'Income Statement'!I$11 -> 0.063629215 | J26: =+'Income Statement'!J26/'Income Statement'!J$11 -> 0.063629215
A27: Other Operating Expenses | B27: =+'Income Statement'!B27/'Income Statement'!B$11 -> 0.088441801 | C27: =+'Income Statement'!C27/'Income Statement'!C$11 -> 0.090261283 | D27: =+'Income Statement'!D27/'Income Statement'!D$11 -> 0.087503381 | E27: =+'Income Statement'!E27/'Income Statement'!E$11 -> 0.10606667 | F27: =+'Income Statement'!F27/'Income Statement'!F$11 -> 0.084081463 | G27: =+'Income Statement'!G27/'Income Statement'!G$11 -> 0.084081463 | H27: =+'Income Statement'!H27/'Income Statement'!H$11 -> 0.084081463 | I27: =+'Income Statement'!I27/'Income Statement'!I$11 -> 0.084081463 | J27: =+'Income Statement'!J27/'Income Statement'!J$11 -> 0.084081463
A28: Total Commissary Equipment and Other Expenses | B28: =SUM(B25:B27) -> 1.0799426 | C28: =SUM(C25:C27) -> 1.0623149 | D28: =SUM(D25:D27) -> 1.0327426 | E28: =SUM(E25:E27) -> 1.0208811 | F28: =SUM(F25:F27) -> 1.0362472 | G28: =SUM(G25:G27) -> 1.0362472 | H28: =SUM(H25:H27) -> 1.0362472 | I28: =SUM(I25:I27) -> 1.0362472 | J28: =SUM(J25:J27) -> 1.0362472
A30: Other Expenses
