Workbook

Sheet Instructions
B18: Name:
B19: Phone:
B20: Email:
B21: Student ID:
B22: Area of Concentration:

Sheet course list
B1: Core | C1: Concentration | D1: Elective | E1: Units | F1: Project | G1: Subject | H1: Catalog Nbr | I1: Course Description | J1: Core | K1: Concen | L1: Elective | M1: Errors | N1: Units | O1: Project | P1: Subject | Q1: Catalog Nbr | R1: Course Description | S1: Core | T1: Concen | U1: Elective | X1: Units | Y1: Project | Z1: Subject | AA1: Catalog Nbr | AB1: Course Description | AC1: Core | AD1: Concen | AE1: Elective | AH1: Units | AI1: Project | AJ1: Subject | AK1: Catalog Nbr | AL1: Course Description | AM1: Core | AN1: Concen | AO1: Elective | AR1: Units | AS1: Project | AT1: Subject | AU1: Catalog Nbr | AV1: Course Description | AW1: Core | AX1: Concen | AY1: Elective | BB1: Units | BC1: Project | BD1: Subject | BE1: Catalog Nbr | BF1: Course Description | BG1: Core | BH1: Concen | BI1: Elective | BK1: Units | BL1: Project | BM1: Subject | BN1: Catalog Nbr | BO1: Course Description | BP1: Core | BQ1: Concen | BR1: Elective
G2: ENGR | H2: 140A | I2: MANAGEMENT OF TECHNOLOGY VENTURES | J2: FALSE | K2: FALSE | L2: FALSE | M2: =IF(OR(AND(J2,K2),AND(J2,L2),AND(K2,L2)),"Choose for one only","") | N2: Units | O2: Project | P2: Subject | Q2: Catalog Nbr | R2: Course Description | S2: Core | T2: Concen | U2: Elective | X2: Units | Y2: Project | Z2: Subject | AA2: Catalog Nbr | AB2: Course Description | AC2: Core | AD2: Concen | AE2: Elective | AH2: Units | AI2: Project | AJ2: Subject | AK2: Catalog Nbr | AL2: Course Description | AM2: Core | AN2: Concen | AO2: Elective | AS2: ="IP" -> IP | AY2: =TRUE -> TRUE | BB2: >2 | BD2: ="MS"&"&"&"E" -> MS&E | BI2: TRUE
G3: ENGR | H3: 140B | I3: MANAGEMENT OF TECHNOLOGY VENTURES | J3: FALSE | K3: FALSE | L3: FALSE | M3: =IF(OR(AND(J3,K3),AND(J3,L3),AND(K3,L3)),"Choose for one only","") | AS3: P | AW3: =TRUE -> TRUE
G4: ENGR | H4: 140C | I4: MANAGEMENT OF TECHNOLOGY VENTURES | J4: FALSE | K4: FALSE | L4: FALSE | M4: =IF(OR(AND(J4,K4),AND(J4,L4),AND(K4,L4)),"Choose for one only","") | AS4: P | AX4: =TRUE -> TRUE | BB4: Units | BC4: Project | BD4: Subject | BE4: Catalog Nbr | BF4: Course Description | BG4: Core | BH4: Concen | BI4: Elective
G5: ENGR | H5: 145 | I5: INTRO TO HIGH TECH ENTREPRENEURSHIP | J5: FALSE | K5: FALSE | L5: FALSE | M5: =IF(OR(AND(J5,K5),AND(J5,L5),AND(K5,L5)),"Choose for one only","") | AS5: P | AY5: =TRUE -> TRUE | BD5: MS&E | BE5: 230 | BF5: INTRODUCTION TO COMPUTER NETWORKS | BG5: FALSE | BH5: FALSE | BI5: FALSE
G6: MS&E | H6: 101 | I6: UNDERGRADUATE DIRECTED STUDY | J6: FALSE | K6: FALSE | L6: FALSE | M6: =IF(OR(AND(J6,K6),AND(J6,L6),AND(K6,L6)),"Choose for one only","") | BD6: MS&E | BE6: 243 | BF6: ENERGY POLICY ANALYSIS | BG6: FALSE | BH6: FALSE | BI6: FALSE
G7: MS&E | H7: 107 | I7: INTERACTIVE MANAGEMENT SCIENCE | J7: FALSE | K7: FALSE | L7: FALSE | M7: =IF(OR(AND(J7,K7),AND(J7,L7),AND(K7,L7)),"Choose for one only","") | AR7: Units | AS7: Project | AT7: Subject | AU7: Catalog Nbr | AV7: Course Description | AW7: Core | AX7: Concen | AY7: Elective | BD7: MS&E | BE7: 265 | BF7: REENGINEERING THE MANUFACTURING FUNCTION | BG7: FALSE | BH7: FALSE | BI7: FALSE
G8: MS&E | H8: 108 | I8: SENIOR PROJECT | J8: FALSE | K8: FALSE | L8: FALSE | M8: =IF(OR(AND(J8,K8),AND(J8,L8),AND(K8,L8)),"Choose for one only","") | BC8: IP | BD8: MS&E | BE8: 270 | BF8: STRATEGY IN TECHNOLOGY-BASED COMPANIES | BG8: FALSE | BH8: FALSE | BI8: FALSE
G9: MS&E | H9: 112 | I9: NETWORK AND INTEGER OPTIMIZATION | J9: FALSE | K9: FALSE | L9: FALSE | M9: =IF(OR(AND(J9,K9),AND(J9,L9),AND(K9,L9)),"Choose for one only","")
G10: MS&E | H10: 120 | I10: PROBABILISTIC ANALYSIS | J10: FALSE | K10: FALSE | L10: FALSE | M10: =IF(OR(AND(J10,K10),AND(J10,L10),AND(K10,L10)),"Choose for one only","") | BC10: IP | BD10: MS&E | BE10: 279 | BF10: INNOVATION STRATEGY | BG10: FALSE | BH10: FALSE | BI10: FALSE
G11: MS&E | H11: 121 | I11: INTRO TO STOCHASTIC MODELING | J11: FALSE | K11: FALSE | L11: FALSE | M11: =IF(OR(AND(J11,K11),AND(J11,L11),AND(K11,L11)),"Choose for one only","") | BD11: MS&E | BE11: 284 | BF11: TECHNOLOGY & WORK | BG11: FALSE | BH11: FALSE | BI11: FALSE
G12: MS&E | H12: 130 | I12: INFORMATION SYSTEMS | J12: FALSE | K12: FALSE | L12: FALSE | M12: =IF(OR(AND(J12,K12),AND(J12,L12),AND(K12,L12)),"Choose for one only","") | BD12: MS&E | BE12: 296 | BF12: TRANSPORTATION SYSTEMS AND URBAN DEVELOPMENT | BG12: FALSE | BH12: FALSE | BI12: FALSE
G13: MS&E | H13: 131 | I13: INFORMATION SCIENCE | J13: FALSE | K13: FALSE | L13: FALSE | M13: =IF(OR(AND(J13,K13),AND(J13,L13),AND(K13,L13)),"Choose for one only","") | BD13: MS&E | BE13: 298 | BF13: TECH, POLICY, AND MGMT IN NEWLY-INDUSTRIALIZING COUNTRIES | BG13: FALSE | BH13: FALSE | BI13: FALSE
G14: MS&E | H14: 134 | I14: ORGANIZATIONS AND INFO SYSTEMS | J14: FALSE | K14: FALSE | L14: FALSE | M14: =IF(OR(AND(J14,K14),AND(J14,L14),AND(K14,L14)),"Choose for one only","")
G15: MS&E | H15: 140 | I15: INDUSTRIAL ACCOUNTNG | J15: FALSE | K15: FALSE | L15: FALSE | M15: =IF(OR(AND(J15,K15),AND(J15,L15),AND(K15,L15)),"Choose for one only","") | BD15: MS&E | BE15: 302 | BF15: OPTIMAL DYNAMIC SYSTEMS | BG15: FALSE | BH15: FALSE | BI15: FALSE
G16: MS&E | H16: 142 | I16: INVESTMENT SCIENCE | J16: FALSE | K16: FALSE | L16: FALSE | M16: =IF(OR(AND(J16,K16),AND(J16,L16),AND(K16,L16)),"Choose for one only","")
G17: MS&E | H17: 152 | I17: INTRO TO DECISION ANALYSIS | J17: FALSE | K17: FALSE | L17: FALSE | M17: =IF(OR(AND(J17,K17),AND(J17,L17),AND(K17,L17)),"Choose for one only","") | BD17: MS&E | BE17: 312 | BF17: OPTIMIZATIONS ALGORITHIMS | BG17: FALSE | BH17: FALSE | BI17: FALSE
G18: MS&E | H18: 153 | I18: INTRO TO DECISION MAKING IN ORGS | J18: FALSE | K18: FALSE | L18: FALSE | M18: =IF(OR(AND(J18,K18),AND(J18,L18),AND(K18,L18)),"Choose for one only","")
G19: MS&E | H19: 160 | I19: PRODUCTION & OPERATING SYSTEMS | J19: FALSE | K19: FALSE | L19: FALSE | M19: =IF(OR(AND(J19,K19),AND(J19,L19),AND(K19,L19)),"Choose for one only","") | BD19: MS&E | BE19: 314 | BF19: SEMIDEFINITE PROGRAMMING | BG19: FALSE | BH19: FALSE | BI19: FALSE
G20: MS&E | H20: 164 | I20: MANUFACTURING SYSTEMS DESIGN | J20: FALSE | K20: FALSE | L20: FALSE | M20: =IF(OR(AND(J20,K20),AND(J20,L20),AND(K20,L20)),"Choose for one only","") | BD20: MS&E | BE20: 316 | BF20: LINEAR COMPLEMENTARITY | BG20: FALSE | BH20: FALSE | BI20: FALSE
G21: MS&E | H21: 169 | I21: QUALITY ASSURANCE AND CONTROL | J21: FALSE | K21: FALSE | L21: FALSE | M21: =IF(OR(AND(J21,K21),AND(J21,L21),AND(K21,L21)),"Choose for one only","") | BD21: MS&E | BE21: 318 | BF21: LARGE-SCALE NUMERICAL OPTIMIZATION | BG21: FALSE | BH21: FALSE | BI21: FALSE
G22: MS&E | H22: 180 | I22: ORGANIZATIONS: THEORY & MGMT | J22: FALSE | K22: FALSE | L22: FALSE | M22: =IF(OR(AND(J22,K22),AND(J22,L22),AND(K22,L22)),"Choose for one only","") | BD22: MS&E | BE22: 322 | BF22: STOCHASTIC CALCULUS AND CONTROL | BG22: FALSE | BH22: FALSE | BI22: FALSE
G23: MS&E | H23: 181 | I23: ISSUES IN TECHNOLOGY & WORK | J23: FALSE | K23: FALSE | L23: FALSE | M23: =IF(OR(AND(J23,K23),AND(J23,L23),AND(K23,L23)),"Choose for one only","") | BD23: MS&E | BE23: 323 | BF23: STOCHASTIC SIMULATION | BG23: FALSE | BH23: FALSE | BI23: FALSE
G24: MS&E | H24: 182 | I24: WORK, TECHNOLOGY, AND SOCIETY | J24: FALSE | K24: FALSE | L24: FALSE | M24: =IF(OR(AND(J24,K24),AND(J24,L24),AND(K24,L24)),"Choose for one only","") | BC24: IP | BD24: MS&E | BE24: 339 | BF24: NEURO-DYNAMIC PROGRAMMING AND REINFORCEMENT LEARNING | BG24: FALSE | BH24: FALSE | BI24: FALSE
G25: MS&E | H25: 193 | I25: TECHNOLOGY AND NAT'L SECURITY | J25: FALSE | K25: FALSE | L25: FALSE | M25: =IF(OR(AND(J25,K25),AND(J25,L25),AND(K25,L25)),"Choose for one only","") | BD25: MS&E | BE25: 346 | BF25: ECONOMIC ANALYSIS OF MARKET ORGANIZATIONS | BG25: FALSE | BH25: FALSE | BI25: FALSE
G26: MS&E | H26: 196 | I26: TRANSPORTATION SYS AND URBAN DEV | J26: FALSE | K26: FALSE | L26: FALSE | M26: =IF(OR(AND(J26,K26),AND(J26,L26),AND(K26,L26)),"Choose for one only","") | BA26: =SUM(BA28:BA143) -> 0 | BD26: MS&E | BE26: 363 | BF26: ADVANCED MODELS IN MGMT SCIENCE | BG26: FALSE | BH26: FALSE | BI26: FALSE
G27: MS&E | H27: 197 | I27: ETHICS AND PUBLIC POLICY | J27: FALSE | K27: FALSE | L27: FALSE | M27: =IF(OR(AND(J27,K27),AND(J27,L27),AND(K27,L27)),"Choose for one only","") | BA27: Calc for MSandE Grad Units | BD27: MS&E | BE27: 371 | BF27: INNOVATION AND STRATEGIC CHANGE | BG27: FALSE | BH27: FALSE | BI27: FALSE
F28: IP | G28: MS&E | H28: 201 | I28: DYNAMIC SYSTEMS | J28: FALSE | K28: FALSE | L28: FALSE | M28: =IF(OR(AND(J28,K28),AND(J28,L28),AND(K28,L28)),"Choose for one only","") | BA28: =IF(E28>2,E28,0) -> 0 | BD28: MS&E | BE28: 376 | BF28: STRATEGY AND ORGS DOCTORAL RESEARCH SEMINAR | BG28: FALSE | BH28: FALSE | BI28: FALSE
G29: MS&E | H29: 206 | I29: ART OF MATHEMATICAL MODELING | J29: FALSE | K29: FALSE | L29: FALSE | M29: =IF(OR(AND(J29,K29),AND(J29,L29),AND(K29,L29)),"Choose for one only","") | BA29: =IF(E29>2,E29,0) -> 0 | BD29: MS&E | BE29: 380 | BF29: DOCTORAL RESEARCH SEMINAR IN ORGANIZATIONS | BG29: FALSE | BH29: FALSE | BI29: FALSE
F30: IP | G30: MS&E | H30: 207 | I30: INTERACTIVE MANAGEMENT SCIENCE | J30: FALSE | K30: FALSE | L30: FALSE | M30: =IF(OR(AND(J30,K30),AND(J30,L30),AND(K30,L30)),"Choose for one only","") | BA30: =IF(E30>2,E30,0) -> 0 | BD30: MS&E | BE30: 381 | BF30: DOCTORAL RESEARCH SEMINAR IN WORK, TECH, AND ORGS | BG30: FALSE | BH30: FALSE | BI30: FALSE
G31: MS&E | H31: 208 | I31: PRACTICAL TRAINING | J31: FALSE | K31: FALSE | L31: FALSE | M31: =IF(OR(AND(J31,K31),AND(J31,L31),AND(K31,L31)),"Choose for one only","") | BA31: =IF(E31>2,E31,0) -> 0 | BD31: MS&E | BE31: 385 | BF31: GEOGRAPHICALLY DISTRIBUTED WORK | BG31: FALSE | BH31: FALSE | BI31: FALSE
G32: MS&E | H32: 211 | I32: LINEAR &NONLINEAR OPTIMIZATION | J32: FALSE | K32: FALSE | L32: FALSE | M32: =IF(OR(AND(J32,K32),AND(J32,L32),AND(K32,L32)),"Choose for one only","") | BA32: =IF(E32>2,E32,0) -> 0 | BC32: P | BD32: MS&E | BE32: 430 | BF32: CONTEXTUAL AND ORGANIZATIONAL ISSUES IN HUMAN-COMPUTER INTERACTION | BG32: FALSE | BH32: FALSE | BI32: FALSE
F33: IP | G33: MS&E | H33: 212 | I33: NETWORK & INTEGER OPTIMIZATION | J33: FALSE | K33: FALSE | L33: FALSE | M33: =IF(OR(AND(J33,K33),AND(J33,L33),AND(K33,L33)),"Choose for one only","") | BA33: =IF(E33>2,E33,0) -> 0 | BD33: MS&E | BE33: 451 | BF33: DECISION SYSTEMS I: PROFESSIONAL SECRETS AND TRICKS OF THE TRADE | BG33: FALSE | BH33: FALSE | BI33: FALSE
G34: MS&E | H34: 217 | I34: COMBINATORIAL OPTIMIZATION | J34: FALSE | K34: FALSE | L34: FALSE | M34: =IF(OR(AND(J34,K34),AND(J34,L34),AND(K34,L34)),"Choose for one only","")
G35: MS&E | H35: 220 | I35: PROBABILISTIC ANALYSIS | J35: FALSE | K35: FALSE | L35: FALSE | M35: =IF(OR(AND(J35,K35),AND(J35,L35),AND(K35,L35)),"Choose for one only","") | BA35: =IF(E35>2,E35,0) -> 0 | BD35: MS&E | BE35: 456 | BF35: DECISION MAKING IN ORGANIZATIONS II: HOW TO STRUCTURE, MODEL, AND ANALYZE | BG35: FALSE | BH35: FALSE | BI35: FALSE
G36: MS&E | H36: 221 | I36: STOCHASTIC MODELING | J36: FALSE | K36: FALSE | L36: FALSE | M36: =IF(OR(AND(J36,K36),AND(J36,L36),AND(K36,L36)),"Choose for one only","") | BA36: =IF(E36>2,E36,0) -> 0 | BD36: MS&E | BE36: 459 | BF36: INTERDISCIPLINARY SEMINAR ON CONFLICT AND DISPUTE | BG36: FALSE | BH36: FALSE | BI36: FALSE
G37: MS&E | H37: 223 | I37: SIMULATION | J37: FALSE | K37: FALSE | L37: FALSE | M37: =IF(OR(AND(J37,K37),AND(J37,L37),AND(K37,L37)),"Choose for one only","") | BA37: =IF(E37>2,E37,0) -> 0 | BD37: MS&E | BE37: 478 | BF37: TOPICS IN INTERNATIONAL TECHNOLOGY MANAGEMENT | BG37: FALSE | BH37: FALSE | BI37: FALSE
G38: MS&E | H38: 230 | I38: INTRODUCTION TO COMPUTER NETWORKS | J38: FALSE | K38: FALSE | L38: FALSE | M38: =IF(OR(AND(J38,K38),AND(J38,L38),AND(K38,L38)),"Choose for one only","") | BA38: =IF(E38>2,E38,0) -> 0 | BD38: MS&E | BE38: 498 | BF38: MEDICAL MODELING WORKSHOP | BG38: FALSE | BH38: FALSE | BI38: FALSE
G39: MS&E | H39: 231 | I39: INFORMATION SYSTEMS | J39: FALSE | K39: FALSE | L39: FALSE | M39: =IF(OR(AND(J39,K39),AND(J39,L39),AND(K39,L39)),"Choose for one only","")
F40: IP | G40: MS&E | H40: 232 | I40: INFO TECH & SUPPLY CHAIN MGMT | J40: FALSE | K40: FALSE | L40: FALSE | M40: =IF(OR(AND(J40,K40),AND(J40,L40),AND(K40,L40)),"Choose for one only","") | BA40: =IF(E40>2,E40,0) -> 0
...

Sheet Print
A1: MS&E Master's Program Proposal
A2: Student Name | B2: Phone | C2: E-Mail | D2: Date Prepared
A3: =Instructions!C18 -> 0 | B3: =Instructions!C19 -> 0 | C3: =Instructions!C20 -> 0 | D3: =TODAY() -> 43857
A4: Student ID | B4: =Instructions!C21 -> 0 | C4: Area of Concentration
C5: =Instructions!C22 -> 0
A6: Backround Requirements | C6: Institution
A7: One Year of Calculus
A8: One Course in computer programming
A9: 15 units of engineering science
A10: One Course in probability
A12: Core Requirements | B12: Course | C12: Title | D12: Units
A13: (minimum of five courses) | B13: ='course list'!AJ3&" "&'course list'!AK3 | C13: ='course list'!AL3 -> 0 | D13: ='course list'!AH3 -> 0
B14: ='course list'!AJ4&" "&'course list'!AK4 | C14: ='course list'!AL4 -> 0 | D14: ='course list'!AH4 -> 0
B15: ='course list'!AJ5&" "&'course list'!AK5 | C15: ='course list'!AL5 -> 0 | D15: ='course list'!AH5 -> 0
B16: ='course list'!AJ6&" "&'course list'!AK6 | C16: ='course list'!AL6 -> 0 | D16: ='course list'!AH6 -> 0
B17: ='course list'!AJ7&" "&'course list'!AK7 | C17: ='course list'!AL7 -> 0 | D17: ='course list'!AH7 -> 0
B18: ='course list'!AJ8&" "&'course list'!AK8 | C18: ='course list'!AL8 -> 0 | D18: ='course list'!AH8 -> 0
B20: ='course list'!AJ10&" "&'course list'!AK10 | C20: ='course list'!AL10 -> 0 | D20: ='course list'!AH10 -> 0
A21: Concentration
A22: (three approved courses) | B22: ='course list'!Z3&" "&'course list'!AA3 | C22: ='course list'!AB3 -> 0 | D22: ='course list'!X3 -> 0
B23: ='course list'!Z4&" "&'course list'!AA4 | C23: ='course list'!AB4 -> 0 | D23: ='course list'!X4 -> 0
B24: ='course list'!Z5&" "&'course list'!AA5 | C24: ='course list'!AB5 -> 0 | D24: ='course list'!X5 -> 0
B25: ='course list'!Z6&" "&'course list'!AA6 | C25: ='course list'!AB6 -> 0 | D25: ='course list'!X6 -> 0
B26: ='course list'!Z7&" "&'course list'!AA7 | C26: ='course list'!AB7 -> 0 | D26: ='course list'!X7 -> 0
B27: ='course list'!Z8&" "&'course list'!AA8 | C27: ='course list'!AB8 -> 0 | D27: ='course list'!X8 -> 0
B28: ='course list'!Z10&" "&'course list'!AA10 | C28: ='course list'!AB10 -> 0 | D28: ='course list'!X10 -> 0
B29: ='course list'!Z11&" "&'course list'!AA11 | C29: ='course list'!AB11 -> 0 | D29: ='course list'!X11 -> 0
A30: Project Courses
A31: (one project or two | B31: ='course list'!AT8&" "&'course list'!AU8 | C31: ='course list'!AV8 -> 0
A32: integrated project courses) | B32: ='course list'!AT10&" "&'course list'!AU10 | C32: ='course list'!AV10 -> 0
A34: Electives
B35: ='course list'!P3&" "&'course list'!Q3 | C35: ='course list'!R3 -> 0 | D35: ='course list'!N3 -> 0
B36: ='course list'!P4&" "&'course list'!Q4 | C36: ='course list'!R4 -> 0 | D36: ='course list'!N4 -> 0
B37: ='course list'!P5&" "&'course list'!Q5 | C37: ='course list'!R5 -> 0 | D37: ='course list'!N5 -> 0
B38: ='course list'!P6&" "&'course list'!Q6 | C38: ='course list'!R6 -> 0 | D38: ='course list'!N6 -> 0
B39: ='course list'!P7&" "&'course list'!Q7 | C39: ='course list'!R7 -> 0 | D39: ='course list'!N7 -> 0
B40: ='course list'!P8&" "&'course list'!Q8 | C40: ='course list'!R8 -> 0 | D40: ='course list'!N8 -> 0
B41: ='course list'!P10&" "&'course list'!Q10 | C41: ='course list'!R10 -> 0 | D41: ='course list'!N10 -> 0
B42: ='course list'!P11&" "&'course list'!Q11 | C42: ='course list'!R11 -> 0 | D42: ='course list'!N11 -> 0
B43: ='course list'!P12&" "&'course list'!Q12 | C43: ='course list'!R12 -> 0 | D43: ='course list'!N12 -> 0
...
