Workbook
Name task_reporting_database: 'Application Fixes'!$A$2:$I$53
Name task_reporting_database: 'By V.P Area'!$A$1:$D$1
Name task_reporting_database: Electives!$B$2:$L$514
Name task_reporting_database: 'Emergency Fixes'!$A$2:$I$53
Name task_reporting_database: Investigations!$A$2:$I$52
Name task_reporting_database: 'New Applications'!$A$2:$I$5
Name task_reporting_database: OnePurdue!$A$2:$I$6
Name task_reporting_database: 'Production Support'!$A$2:$D$2
Name task_reporting_database: 'Scheduled Modifications'!$A$2:$D$3
Name task_reporting_database_1: 'Application Fixes'!$A$2:$I$6
Name task_reporting_database_1: 'By V.P Area'!$A$1:$I$105
Name task_reporting_database_1: Electives!$A$2:$I$181
Name task_reporting_database_1: 'Emergency Fixes'!$A$2:$I$6
Name task_reporting_database_1: 'New Applications'!$A$2:$J$3
Name task_reporting_database_1: 'Production Support'!$A$2:$I$132
Name task_reporting_database_1: 'Scheduled Modifications'!$A$2:$I$107
Name task_reporting_database_2: 'Application Fixes'!$A$2:$I$103
Name task_reporting_database_2: 'By V.P Area'!$C$1:$J$2
Name task_reporting_database_2: 'Production Support'!$A$2:$I$29
Name task_reporting_database_2: 'Scheduled Modifications'!$A$2:$I$139

Sheet Summary
A1: Classification | B1: Total Work In Process | C1: Academics | D1: Business Services | E1: Engagement | F1: Housing & Food Services | G1: Institutional Research | H1: ITaP / ITEA | I1: Physical Facilities | J1: Research Admin. | K1: Student Services | L1: University Advancement | M1: Total # of Request for Service (RFS)
A2: Non-Electives | B2: =SUM(B3:B8) -> 155 | M2: =SUM(M3:M8) -> 324
A3: New Applications | B3: =COUNTIF('New Applications'!C:C,"Started") -> 0 | C3: 0 | D3: =COUNTIF('New Applications'!A:A,"Business Services") -> 0 | E3: =COUNTIF('New Applications'!A:A,"engagement") -> 0 | F3: =COUNTIF('New Applications'!A:A,"University Residences") -> 0 | G3: =COUNTIF('New Applications'!A:A,"Institutional Research") -> 0 | H3: =COUNTIF('New Applications'!A:A,"IT*") -> 0 | I3: =COUNTIF('New Applications'!A:A,"Physical Facilities") -> 0 | J3: 0 | K3: =COUNTIF('New Applications'!A:A,"Student Services") -> 0 | L3: =COUNTIF('New Applications'!A:A,"University Development") -> 0 | M3: =SUM(D3:L3) -> 0
A4: Investigations | B4: =COUNTIF(Investigations!C:C,"Started") -> 27 | C4: 0 | D4: =COUNTIF(Investigations!A:A,"Business Services") -> 30 | E4: =COUNTIF(Investigations!A:A,"Engagement") -> 0 | F4: =COUNTIF(Investigations!A:A,"University Residences") -> 3 | G4: =COUNTIF(Investigations!A:A,"Institutional Research") -> 0 | H4: =COUNTIF(Investigations!A:A,"IT*") -> 3 | I4: =COUNTIF(Investigations!A:A,"Physical Facilities") -> 0 | J4: 0 | K4: =COUNTIF(Investigations!A:A,"Student Services") -> 14 | L4: =COUNTIF(Investigations!A:A,"University Development") -> 1 | M4: =SUM(D4:L4) -> 51
A5: Emergency Fixes | B5: =COUNTIF('Emergency Fixes'!C:C,"Started") -> 5 | C5: 0 | D5: =COUNTIF('Emergency Fixes'!A:A,"Business Services") -> 3 | E5: =COUNTIF('Emergency Fixes'!A:A,"Engagement") -> 0 | F5: =COUNTIF('Emergency Fixes'!A:A,"University Residences") -> 0 | G5: =COUNTIF('Emergency Fixes'!A:A,"Institutional Research") -> 0 | H5: =COUNTIF('Emergency Fixes'!A:A,"IT*") -> 0 | I5: =COUNTIF('Emergency Fixes'!A:A,"Physical Facilities") -> 0 | J5: 0 | K5: =COUNTIF('Emergency Fixes'!A:A,"Student Services") -> 2 | L5: =COUNTIF('Emergency Fixes'!A:A,"University Development") -> 0 | M5: =SUM(D5:L5) -> 5
A6: Application Fixes | B6: =COUNTIF('Application Fixes'!C:C,"Started") -> 49 | C6: 0 | D6: =COUNTIF('Application Fixes'!A:A,"Business Services") -> 27 | E6: =COUNTIF('Application Fixes'!A:A,"Engagement") -> 11 | F6: =COUNTIF('Application Fixes'!A:A,"University Residences") -> 5 | G6: =COUNTIF('Application Fixes'!A:A,"Institutional Research") -> 0 | H6: =COUNTIF('Application Fixes'!A:A,"IT*") -> 5 | I6: =COUNTIF('Application Fixes'!A:A,"Physical Facilities") -> 2 | J6: 0 | K6: =COUNTIF('Application Fixes'!A:A,"Student Services") -> 40 | L6: =COUNTIF('Application Fixes'!A:A,"University Development") -> 12 | M6: =SUM(D6:L6) -> 102
A7: Scheduled Modification | B7: =COUNTIF('Scheduled Modifications'!C:C,"Started") -> 59 | C7: 0 | D7: =COUNTIF('Scheduled Modifications'!A:A,"Business Services") -> 48 | E7: =COUNTIF('Scheduled Modifications'!A:A,"Engagement") -> 0 | F7: =COUNTIF('Scheduled Modifications'!A:A,"University Residences") -> 3 | G7: =COUNTIF('Scheduled Modifications'!A:A,"Institutional Research") -> 0 | H7: =COUNTIF('Scheduled Modifications'!A:A,"IT*") -> 17 | I7: =COUNTIF('Scheduled Modifications'!A:A,"Physical Facilities") -> 0 | J7: 0 | K7: =COUNTIF('Scheduled Modifications'!A:A,"Student Services") -> 39 | L7: =COUNTIF('Scheduled Modifications'!A:A,"University Development") -> 31 | M7: =SUM(D7:L7) -> 138
A8: Production Support | B8: =COUNTIF('Production Support'!C:C,"Started") -> 15 | C8: 0 | D8: =COUNTIF('Production Support'!A:A,"Business Services") -> 18 | E8: =COUNTIF('Production Support'!A:A,"Engagement") -> 0 | F8: =COUNTIF('Production Support'!A:A,"University Residences") -> 2 | G8: =COUNTIF('Production Support'!A:A,"Institutional Research") -> 0 | H8: =COUNTIF('Production Support'!A:A,"IT*") -> 5 | I8: =COUNTIF('Production Support'!A:A,"Physical Facilities") -> 0 | J8: 0 | K8: =COUNTIF('Production Support'!A:A,"Student Services") -> 3 | L8: =COUNTIF('Production Support'!A:A,"University Development") -> 0 | M8: =SUM(D8:L8) -> 28
A9: OnePurdue | B9: =COUNTIF(OnePurdue!C:C,"Started") -> 3 | C9: 0 | D9: =COUNTIF(OnePurdue!A:A,"Business Services") -> 1 | E9: =COUNTIF(OnePurdue!A:A,"Engagement") -> 0 | F9: =COUNTIF(OnePurdue!A:A,"University Residences") -> 0 | G9: =COUNTIF(OnePurdue!A:A,"Institutional Research") -> 1 | H9: =COUNTIF(OnePurdue!A:A,"IT*") -> 3 | I9: =COUNTIF(OnePurdue!A:A,"Physical Facilities") -> 0 | J9: 0 | K9: =COUNTIF(OnePurdue!A:A,"Student Services") -> 0 | L9: =COUNTIF(OnePurdue!A:A,"University Development") -> 0 | M9: =SUM(D9:L9) -> 5
A10: Electives | B10: =COUNTIF(Electives!C:C,"Started") -> 30 | C10: 0 | D10: =COUNTIF(Electives!A:A,"Business Services") -> 30 | E10: =COUNTIF(Electives!A:A,"Engagement") -> 4 | F10: =COUNTIF(Electives!A:A,"University Residences") -> 5 | G10: =COUNTIF(Electives!A:A,"Institutional Research") -> 0 | H10: =COUNTIF(Electives!A:A,"IT*") -> 15 | I10: =COUNTIF(Electives!A:A,"Physical Facilities") -> 3 | J10: 0 | K10: =COUNTIF(Electives!A:A,"Student Services") -> 89 | L10: =COUNTIF(Electives!A:A,"University Development") -> 34 | M10: =SUM(C10:L10) -> 180
A11: Total | B11: =SUM(B3:B10) -> 188 | C11: =SUM(C2:C10) -> 0 | D11: =SUM(D2:D10) -> 157 | E11: =SUM(E2:E10) -> 15 | F11: =SUM(F2:F10) -> 18 | G11: =SUM(G2:G10) -> 1 | H11: =SUM(H2:H10) -> 48 | I11: =SUM(I2:I10) -> 5 | J11: =SUM(J2:J10) -> 0 | ... L11: =SUM(L2:L10) -> 78 | M11: =SUM(M3:M10) -> 509

Sheet Electives
A1: V.P. Area | B1: System | C1: Status | D1: ITEA RFS # | E1: Short Description | F1: Date Received | G1: Target Date | H1: Low Estimate | I1: High Estimate
A2: Business Services | B2: Ariba | C2: Not Started | D2: 14355 | E2: Improve Ariba documentation | F2: 37908 | G2: 38533 | H2: 150 | I2: 300
A3: Business Services | B3: Ariba | C3: Not Started | D3: 14356 | E3: Automate user load | F3: 37908 | G3: 38717 | H3: 80 | I3: 120
A4: Business Services | B4: Ariba | C4: Not Started | D4: 14359 | E4: Implement Change Order Processing | F4: 37908 | H4: 100 | I4: 150
A5: Business Services | B5: Ariba | C5: Not Started | D5: 14360 | E5: Implement Email Approval | F5: 37908 | H5: 100 | I5: 150
A6: Business Services | B6: Ariba | C6: Not Started | D6: 14637 | E6: Show more data on the chooser screen for approver | F6: 37939 | G6: 38352 | H6: 24 | I6: 40
A7: Business Services | B7: Ariba | C7: Pending | D7: 14474 | E7: Find a way to disable the "new ship tor" button for all users | F7: 37925 | H7: 30 | I7: 50
A8: Business Services | B8: Ariba | C8: Ready for Class Review | D8: 15004 | E8: Replace helpdesk phone number on POs | F8: 38009 | H8: 40 | I8: 80
A9: Business Services | B9: BUDG | C9: Started | D9: 14008 | E9: Elective modifications for 2004-05 Budget year | F9: 37841 | H9: 100 | I9: 300
A10: Business Services | B10: CAAC | C10: Not Started | D10: 14314 | E10: CADE - Modify to add audit on screen A922 14314 | F10: 37900 | H10: 20 | I10: 50
A11: Business Services | B11: CARS | C11: Not Started | D11: 14118 | E11: CARS - Agency Payment Report 14118 | F11: 37161 | H11: 40 | I11: 80
A12: Business Services | B12: CARS | C12: Not Started | D12: 14119 | E12: CARS - Expand comment screen limit 14119 | F12: 37879 | H12: 80 | I12: 120
A13: Business Services | B13: COEUS | C13: Pending | D13: 14124 | E13: COEUS - Implement new modules of COEUS 14124 | F13: 37879 | H13: 1000 | I13: 2000
A14: Business Services | B14: E-Commerce | C14: Not Started | D14: 14441 | E14: Commas in Amounts in Purdue-pay | F14: 37875 | H14: 20 | I14: 40
A15: Business Services | B15: E-Commerce | C15: Not Started | D15: 14443 | E15: Partial Refunds in IPS | F15: 37699 | H15: 80 | I15: 120
A16: Business Services | B16: E-Commerce | C16: Not Started | D16: 14444 | E16: Update ability for rejected ACH payments | F16: 37719 | H16: 80 | I16: 120
A17: Business Services | B17: E-Commerce | C17: Not Started | D17: 14446 | E17: Administrative site access without update | F17: 37719 | H17: 60 | I17: 100
A18: Business Services | B18: E-Commerce | C18: Not Started | D18: 14447 | E18: Purdue-pay e-mail links on payer pages | F18: 37719 | H18: 60 | I18: 100
... A23: Business Services | B23: FMIS | C23: Pending | D23: 2513 | E23: FMIS - e-routing of CRV's & other Acct docs 2513 | F23: 34639 | H23: 500 | I23: 1000
A24: Business Services | B24: FMIS | C24: Started | D24: 14662 | E24: e-Comm - Implement ReconNET 14662 | F24: 37935 | G24: 37970 | H24: 15 | I24: 30
A25: Business Services | B25: HRMT | C25: Not Started | D25: 14700 | E25: HR Self Service - Add Update Capabilities | F25: 37960 | G25: 38061 | H25: 1000 | I25: 1500
A26: Business Services | B26: HRMT | C26: Not Started | D26: 14701 | E26: HR Self Service - Benefits Open Enrollment | F26: 37960 | G26: 37865 | H26: 1000 | I26: 1500
A27: Business Services | B27: HRMT | C27: Started | D27: 13577 | E27: HR Self Service (13577) | F27: 37634 | H27: 1000 | I27: 2000
A28: Business Services | B28: PAFX | C28: Not Started | D28: 13658 | E28: FLEX Ad Hoc Report Request | F28: 37670 | H28: 80 | I28: 100
A29: Business Services | B29: PAYR | C29: Pending | D29: 14329 | E29: Determine an easy way to track Temporary Positions | F29: 37907 | G29: 37914 | H29: 150 | I29: 200
A30: Business Services | B30: RFSP | C30: Not Started | D30: 13540 | E30: SPS - Award Notification (EARNIP) Phase II 13540 | F30: 37591 | G30: 38168 | H30: 200 | I30: 300
A31: Business Services | B31: SLAC | C31: Pending | D31: 11017 | E31: SLAC - Est ACH draw down student loan pmts 11017 | F31: 36829 | H31: 200 | I31: 400
A32: Engagement | B32: PREMIS | C32: Ready for Advisory Group | D32: 14575 | E32: Purdue Registration & Event Management Information System (PREMIS) Phase IV | F32: 37930 | G32: 38169 | H32: 1000 | I32: 9999
A33: Engagement | B33: PREMIS | C33: Ready for Advisory Group | D33: 14576 | E33: Purdue Registration & Event Management Information System (PREMIS) Phase V | F33: 37930 | G33: 38233 | H33: 1000 | I33: 9999
A34: Engagement | B34: PREMIS | C34: Started | D34: 14573 | E34: Purdue Registration & Event Management Information System (PREMIS) Phase II | F34: 37930 | G34: 38037 | H34: 1000 | I34: 9999
A35: Engagement | B35: PREMIS | C35: Started | D35: 14574 | E35: Purdue Registration & Event Management Information System (PREMIS) Phase III | F35: 37930 | G35: 38114 | H35: 1000 | I35: 9999
A36: ITaP | B36: WAI | C36: Not Started | D36: 14385 | E36: Fix the Probability of earning a C in the Profile table. | F36: 37910 | G36: 37987 | H36: 5 | I36: 10
A37: ITaP | B37: WAI | C37: Not Started | D37: 14387 | E37: Change the Student Program Change table to pick up the semester information prior to and subsequent from a person's change in campus or school. | F37: 37910 | G37: 37987 | H37: 10 | I37: 20
A38: ITaP | B38: WAI | C38: Not Started | D38: 14388 | E38: Describe the CA_POSTPAY file to the DSS data warehouse so users can query as the person level detail for payroll data and balance with the University general ledger. | F38: 37910 | G38: 38168 | H38: 100 | I38: 500
A39: ITaP | B39: WAI | C39: Not Started | D39: 14709 | E39: Define COEUS data models and load corresponding information to the Data Warehouse | F39: 37963 | G39: 38169 | H39: 200 | I39: 500
A40: ITaP | B40: WAI | C40: Started | D40: 14166 | E40: Remove access to Instructional Tables | F40: 37881 | G40: 38017 | H40: 10 | I40: 20
A41: ITaP | B41: WAI | C41: Started | D41: 14381 | E41: Expand 'regular hours' field for Athletics. | F41: 37910 | G41: 38017 | H41: 20 | I41: 30
A42: ITaP | B42: WAI | C42: Started | D42: 14384 | E42: Correct Years in Position Calculation. | F42: 37910 | G42: 38017 | H42: 10 | I42: 30
A43: ITaP | B43: WAI | C43: Started | D43: 14386 | E43: Remove Disability information from DSS for HIPAA.. | F43: 37910 | G43: 38007 | H43: 10 | I43: 20
... A50: ITEA | B50: Standards | C50: Started | D50: 14277 | E50: ITEA Software Administration Database | F50: 37895 | G50: 37956 | H50: 50 | I50: 150
...

Sheet OnePurdue
A1: V.P. Area | B1: System | C1: Status | D1: ITEA RFS # | E1: Short Description | F1: Date Received | G1: Target Date | H1: Low Estimate | I1: High Estimate
A2: Business Services | B2: E-Commerce | C2: Not Started | D2: 14450 | E2: help with RFI for new ecommerce solution. | F2: 37659 | H2: 100 | I2: 150
A3: Institutional Research | B3: OIR | C3: Started | D3: 14057 | E3: IDN Data Mart & Metrics Reporting-Phase I | F3: 37726 | G3: 38047 | H3: 1800 | I3: 2500
A4: ITaP | B4: Data Admin | C4: Placeholder | D4: 14578 | E4: Information Quality | F4: 37931 | G4: 38352 | H4: 1000 | I4: 9999
A5: ITaP | B5: Data Admin | C5: Started | D5: 14056 | E5: Business Intelligence | F5: 37585 | G5: 38078 | H5: 8000 | I5: 16000
A6: ITaP | B6: WAI | C6: Started | D6: 14173 | E6: Complete the Profile Project Phase I | F6: 37622 | G6: 38017 | H6: 650 | I6: 950

Sheet New Applications
A1: V.P. Area | B1: System | C1: Status | D1: ITEA RFS # | E1: Short Description | F1: Date Received | G1: Target Date | H1: Low Estimate | I1: High Estimate

Sheet Investigations
A1: V.P. Area | B1: System | C1: Status | D1: ITEA RFS # | E1: Short Description | F1: Date Received | G1: Target Date | H1: Low Estimate | I1: High Estimate
A2: Business Services | B2: Ariba | C2: Not Started | D2: 14358 | E2: Pcard percent variance tolerances | F2: 37908 | G2: 38077 | H2: 40 | I2: 80
A3: Business Services | B3: Ariba | C3: Not Started | D3: 14476 | E3: Status of received orders not "processed" | F3: 37925 | H3: 20 | I3: 100
A4: Business Services | B4: Ariba | C4: Not Started | D4: 14851 | E4: ‎Investigate alternatives to use of SysAdmin role | F4: 37993 | G4: 38352 | H4: 80 | I4: 100
A5: Business Services | B5: Ariba | C5: Started | D5: 14351 | E5: User load issue | F5: 37908 | G5: 38260 | H5: 40 | I5: 80
A6: Business Services | B6: Ariba | C6: Started | D6: 14427 | E6: Check Ariba logs daily for a 6 month period | F6: 37916 | G6: 38343 | H6: 950 | I6: 950
A7: Business Services | B7: Ariba | C7: Started | D7: 14486 | E7: ASN orders are sometimes showing "failed" status | F7: 37925 | G7: 38077 | H7: 40 | I7: 80
A8: Business Services | B8: Ariba | C8: Started | D8: 14630 | E8: Need to add more detail to the PCard testing plan. | F8: 37939 | H8: 3 | I8: 10
A9: Business Services | B9: Ariba | C9: Started | D9: 14852 | E9: Verify accessibility of csv files on UNIX box | F9: 37993 | G9: 38352 | H9: 20 | I9: 30
A10: Business Services | B10: ASER | C10: Pending | D10: 14087 | E10: ASER - Mtch Error Rpt not ‎recog 098 instruc 14087 | F10: 37878 | G10: 38200 | H10: 40 | I10: 100
A11: Business Services | B11: CARS | C11: Started | D11: 11855 | E11: CARS - Bottom of bill not adding up 11855 | F11: 37034 | H11: 40 | I11: 120
A12: Business Services | B12: COEUS | C12: Started | D12: 14860 | E12: COEUS - Avg # days in UCG report problem 14860 | F12: 37995 | H12: 30 | I12: 90
A13: Business Services | B13: FMIS | C13: Started | D13: 14945 | E13: FMIS - Problem w/ Canadian prov. code 14945 | F13: 37991 | G13: 38006 | H13: 4 | I13: 8
A14: Business Services | B14: FMIS | C14: Started | D14: 14965 | E14: FMIS - MSA Software Review 14965 | F14: 38002 | H14: 50 | I14: 100
A15: Business Services | B15: FMIS | C15: Started | D15: 14987 | E15: FMIS - Investig bank table used for EC 35 14987 | F15: 38007 | G15: 38009 | H15: 4 | I15: 8
A16: Business Services | B16: PAFX | C16: Started | D16: 14903 | E16: FLEX "Wednesday morning" last-year process (14903) | F16: 37995 | G16: 38008 | H16: 2 | I16: 8
A17: Business Services | B17: PAFX | C17: Started | D17: 14977 | E17: Gale/Julie noticed text on CARS billing records not same as in plan file | F17: 38002 | H17: 1 | I17: 10
A18: Business Services | B18: PAIS | C18: Pending | D18: 14859 | E18: PAIS Reappointment Issues (14859) | F18: 37995 | G18: 38044 | H18: 10 | I18: 40
A19: Business Services | B19: PAVE | C19: Pending | D19: 14129 | E19: PAVE - Risk Mgt Information System/Software 14129 | F19: 37880 | H19: 100 | I19: 200
A20: Business Services | B20: PAYR | C20: Not Started | D20: 14895 | E20: Justification report excess ins message (14895) | F20: 37999 | G20: 38077 | H20: 20 | I20: 100
A21: Business Services | B21: PAYR | C21: Pending | D21: 14140 | E21: Test CICS Bank Description Issue (14140) | F21: 37880 | H21: 10 | I21: 20
A22: Business Services | B22: PAYR | C22: Started | D22: 14054 | E22: Payroll Charge File Change at YTD Rollback (14054) | F22: 37869 | H22: 8 | I22: 40
A23: Business Services | B23: PESN | C23: Not Started | D23: 14641 | E23: "T" in Level Field in PEDB Current Staff (14641) | F23: 37942 | G23: 38044 | H23: 4 | I23: 8
A24: Business Services | B24: PESN | C24: Not Started | D24: 14642 | E24: Missing Effective Date on Terminations (14642) | F24: 37942 | G24: 38077 | H24: 2 | I24: 4
A25: Business Services | B25: PESN | C25: Started | D25: 13998 | E25: PEBLOCK related Clean-Up (13998) | F25: 37837 | G25: 38077 | H25: 4 | I25: 16
A26: Business Services | B26: PESN | C26: Started | D26: 14817 | E26: NRA Student Adresses on IN New Hire File (14817) | F26: 37986 | G26: 38044 | H26: 2 | I26: 4
A27: Business Services | B27: RFSP | C27: Pending | D27: 14691 | E27: SPS - Consult Interim Routing Discvry Park 14691 | F27: 37957 | H27: 30 | I27: 60
A28: Business Services | B28: RFSP | C28: Started | D28: 14864 | E28: SPS - Wrong e-mail verbiage for Attrib 14864 | F28: 37995 | H28: 10 | I28: 100
A29: Business Services | B29: SLAC | C29: Not Started | D29: 14327 | E29: SLAC - Erroneous Late Chrgs on Pd-off Loans 14327 | F29: 37904 | G29: 38169 | H29: 40 | I29: 120
A30: Business Services | B30: SLAC | C30: Pending | D30: 14185 | E30: SLAC - E-Prom Note Functionality Investig 14185 | F30: 37881 | H30: 30 | I30: 50
A31: Business Services | B31: SLAC | C31: Started | D31: 14097 | E31: SLAC - Fix errors on Encumb Discrepancy Rpts 14097 | F31: 37876 | G31: 38169 | H31: 40 | I31: 120
A32: ITAP | B32: PUID | C32: Not Started | D32: 14728 | E32: People in source file with no PUID | F32: 37970 | H32: 40 | I32: 200
A33: ITAP | B33: PUID | C33: Started | D33: 14688 | E33: Include Alumni relationships in PUID | F33: 37956 | G33: 38018 | H33: 15 | I33: 40
A34: ITaP | B34: WAI | C34: Not Started | D34: 14600 | E34: Modifications required to load budget data. | F34: 37935 | G34: 38018 | H34: 1 | I34: 10
A35: Student Services | B35: Bursar | C35: Not Started | D35: 14633 | E35: Enable Lab Course Special Fees | F35: 37939 | G35: 38169 | H35: 100 | I35: 500
A36: Student Services | B36: Bursar | C36: Pending | D36: 11377 | E36: Add mailers choice sorting to Housing invoices. | F36: 36931 | H36: 40 | I36: 80
A37: Student Services | B37: Bursar | C37: Pending | D37: 14377 | E37: Fold up Designated Fees into General Fees | F37: 37910 | G37: 38169 | H37: 25 | I37: 50
A38: Student Services | B38: Bursar | C38: Started | D38: 14009 | E38: Mainframe Support July 03 - June 04 (14009) | F38: 37841 | G38: 38168 | H38: 100 | I38: 1000
A39: Student Services | B39: CN | C39: Started | D39: 12308 | E39: Support Replacement of PACERS | F39: 37011 | H39: 25 | I39: 150
A40: Student Services | B40: DFA | C40: Started | D40: 14464 | E40: Mainframe Support July 03-June 04 (14464) | F40: 37922 | G40: 38168 | H40: 1 | I40: 800
...

Sheet Emergency Fixes
A1: V.P. Area | B1: System | C1: Status | D1: ITEA RFS # | E1: Short Description | F1: Date Received | G1: Target Date | H1: Low Estimate | I1: High Estimate
A2: Business Services | B2: Ariba | C2: Started | D2: 14428 | E2: Research reported log problems and fix as needed | F2: 37916 | G2: 38343 | H2: 560 | I2: 560
A3: Business Services | B3: E-Commerce | C3: Started | D3: 14432 | E3: Rejected pmnts and unsuccessful pmnts for 6 months | F3: 37917 | G3: 38099 | H3: 200 | I3: 250
A4: Business Services | B4: E-Commerce | C4: Started | D4: 14459 | E4: Daily Maintenance Job and support for a 6 months | F4: 37922 | G4: 38105 | H4: 520 | I4: 600
A5: Student Services | B5: Bursar | C5: Started | D5: 14776 | E5: Deferred Fee Bill Window (14776) | F5: 37979 | G5: 38016 | H5: 10 | I5: 50
A6: Student Services | B6: Bursar | C6: Started | D6: 14777 | E6: Aid type 93 disbursement problem (14777) | F6: 37979 | G6: 38032 | H6: 10 | I6: 50

Sheet Application Fixes
A1: V.P. Area | B1: System | C1: Status | D1: ITEA RFS # | E1: Short Description | F1: Date Received | G1: Target Date | H1: Low Estimate | I1: High Estimate
A2: Business Services | B2: Ariba | C2: Not Started | D2: 14475 | E2: Modify shell script for supplier load. | F2: 37925 | G2: 38260 | H2: 20 | I2: 40
A3: Business Services | B3: Ariba | C3: Not Started | D3: 14671 | E3: Add an auxiliary part number filter to the system | F3: 37946 | H3: 16 | I3: 32
A4: Business Services | B4: Ariba | C4: Not Started | D4: 14672 | E4: Fix filter by purchasing card number | F4: 37946 | G4: 38044 | H4: 40 | I4: 60
A5: Business Services | B5: Ariba | C5: Not Started | D5: 14716 | E5: Order does not appear in the approver's box | F5: 37964 | H5: 40 | I5: 80
A6: Business Services | B6: Ariba | C6: Started | D6: 14344 | E6: bad approvables causing user problems | F6: 37951 | H6: 10 | I6: 120
A7: Business Services | B7: Ariba | C7: Started | D7: 14345 | E7: Fix Punchout catalogs - Kirby Risk example | F7: 37908 | H7: 80 | I7: 120
A8: Business Services | B8: Ariba | C8: Started | D8: 14346 | E8: Performance Issues | F8: 37908 | H8: 100 | I8: 200
A9: Business Services | B9: Ariba | C9: Started | D9: 14348 | E9: Migrating suppliers to the ASN | F9: 37908 | H9: 40 | I9: 80
A10: Business Services | B10: Ariba | C10: Started | D10: 14350 | E10: PC charge push to G/L | F10: 37908 | G10: 38352 | H10: 20 | I10: 40
A11: Business Services | B11: Ariba | C11: Started | D11: 14353 | E11: Behavior of the reserve code on the user interface | F11: 37908 | G11: 38260 | H11: 40 | I11: 80
A12: Business Services | B12: Ariba | C12: Started | D12: 14673 | E12: Make country code required on "new ship to" | F12: 37946 | G12: 38016 | H12: 40 | I12: 60
A13: Business Services | B13: Ariba | C13: Started | D13: 14884 | E13: Ariba Purges for 12 months | F13: 37998 | G13: 38333 | H13: 48 | I13: 48
A14: Business Services | B14: Ariba | C14: Started | D14: 14885 | E14: Reset the aribasystem password every 30 days for 6 months. | F14: 37998 | G14: 38150 | H14: 1 | I14: 1
A15: Business Services | B15: Ariba | C15: Started | D15: 14893 | E15: Find out which search filters are indexed in Ariba | F15: 37995 | H15: 40 | I15: 80
A16: Business Services | B16: Ariba | C16: Started | D16: 14894 | E16: Build a mini ODS for searches needed by PFSB/Lilly | F16: 37995 | G16: 38044 | H16: 75 | I16: 100
A17: Business Services | B17: CAAC | C17: Not Started | D17: 2507 | E17: CAAC - Abend on CAACT923 rpt group bud scrn 2507 | F17: 37879 | H17: 10 | I17: 50
A18: Business Services | B18: CARS | C18: Not Started | D18: 11639 | E18: CARS - Encumb files upd problems for type W 11639 | F18: 36984 | G18: 38200 | H18: 40 | I18: 160
A19: Business Services | B19: CARS | C19: Not Started | D19: 14853 | E19: CARS- Acct# for SPS on Master, not on name 14853 | F19: 37994 | H19: 40 | I19: 100
A20: Business Services | B20: CARS | C20: Started | D20: 14863 | E20: CARS - Printing Serv problems w/ AR ‎mail‎ 14863 | F20: 37995 | G20: 38047 | H20: 10 | I20: 100
A21: Business Services | B21: E-Commerce | C21: Not Started | D21: 14436 | E21: Time-zone problem for IPS applications | F21: 37921 | H21: 60 | I21: 100
A22: Business Services | B22: E-Commerce | C22: Not Started | D22: 14449 | E22: PGP Encryption Changes at Mellon | F22: 37832 | H22: 60 | I22: 80
A23: Business Services | B23: E-Commerce | C23: Started | D23: 14437 | E23: Change the server address used in external procedures as requested by IT | F23: 37921 | H23: 8 | I23: 16
A24: Business Services | B24: FMIS | C24: Started | D24: 14127 | E24: FMIS - Purdue Foundation Rewrite (FMIS) 14127 | F24: 37880 | H24: 30 | I24: 60
A25: Business Services | B25: FMIS | C25: Started | D25: 15005 | E25: FMIS - Add Explosion Rules for Fund 920 15005 | F25: 37992 | G25: 38016 | H25: 4 | I25: 20
A26: Business Services | B26: PAVE | C26: Not Started | D26: 14998 | E26: PAVE - Problem with deleting fields in sys - 14998 | F26: 38009 | H26: 24 | I26: 40
A27: Business Services | B27: PROP | C27: Started | D27: 13908 | E27: PROP - New field not added in equip file 13908 | F27: 37799 | G27: 37799 | H27: 40 | I27: 80
A28: Business Services | B28: SLAC | C28: Started | D28: 14194 | E28: SLAC - Negative Transaction Edits 14194 | F28: 37883 | G28: 38078 | H28: 40 | I28: 160
A29: Engagement | B29: PACERS | C29: Ready for Class Review | D29: 14952 | E29: Provide support for the Home and Family conference | F29: 38001 | G29: 38145 | H29: 1 | I29: 100
A30: Engagement | B30: PACERS | C30: Ready for Class Review | D30: 14953 | E30: Provide support for the 4-H Workshops | F30: 38001 | G30: 38147 | H30: 1 | I30: 100
A31: Engagement | B31: PACERS | C31: Started | D31: 14589 | E31: TRA 97 Reporting for 2003 | F31: 37932 | G31: 37995 | H31: 1 | I31: 100
A32: Engagement | B32: PACERS | C32: Started | D32: 14590 | E32: Indiana Wine and Grape | F32: 37932 | G32: 38169 | H32: 1 | I32: 100
A33: Engagement | B33: PACERS | C33: Started | D33: 14591 | E33: Science Fair 2004‎ | F33: 37932 | G33: 38051 | H33: 100 | I33: 500
A34: Engagement | B34: PACERS | C34: Started | D34: 14595 | E34: Sports Camps 2004‎ | F34: 37932 | G34: 38137 | H34: 100 | I34: 500
A35: Engagement | B35: PACERS | C35: Started | D35: 14596 | E35: Road School 2004‎ | F35: 37932 | G35: 38056 | H35: 100 | I35: 500
A36: Engagement | B36: PACERS | C36: Started | D36: 14652 | E36: Compressor Conference | F36: 37943 | G36: 38076 | H36: 1 | I36: 100
A37: Engagement | B37: PACERS | C37: Started | D37: 14653 | E37: Pest Technology Course | F37: 37943 | G37: 38009 | H37: 1 | I37: 100
A38: Engagement | B38: PACERS | C38: Started | D38: 14755 | E38: Exciting Science at Purdue | F38: 37977 | G38: 38052 | H38: 1 | I38: 100
... A45: Physical Facilities | B45: PPWP | C45: Not Started | D45: 14049 | E45: PPWP - Fiscal Year 2003-04 14049 | F45: 37862 | G45: 38200 | H45: 20 | I45: 50
A46: Physical Facilities | B46: PUST | C46: Started | D46: 13269 | E46: PUST - Decommission Old PUST/SIRS System 13269 | F46: 37496 | H46: 50 | I46: 100
...

Sheet Scheduled Modifications
A1: V.P. Area | B1: System | C1: Status | D1: ITEA RFS # | E1: Short Description | F1: Date Received | G1: Target Date | H1: Low Estimate | I1: High Estimate
A2: Business Services | B2: Ariba | C2: Not Started | D2: 14357 | E2: Remove MERS number | F2: 37908 | G2: 38168 | H2: 40 | I2: 80
A3: Business Services | B3: Ariba | C3: Not Started | D3: 14821 | E3: Work with zone to create monthly list of csv files | F3: 37991 | G3: 38077 | H3: 20 | I3: 30
A4: Business Services | B4: Ariba | C4: Started | D4: 14349 | E4: Investigate and implement Ariba standard reports | F4: 37908 | G4: 38260 | H4: 80 | I4: 120
A5: Business Services | B5: Ariba | C5: Started | D5: 14352 | E5: PCR reroute back to the approver | F5: 37908 | G5: 38352 | H5: 40 | I5: 80
A6: Business Services | B6: Ariba | C6: Started | D6: 14819 | E6: Try to produce report of orders over the $100 cap | F6: 37991 | G6: 38077 | H6: 50 | I6: 150
A7: Business Services | B7: Ariba | C7: Started | D7: 14820 | E7: Store only last 6 digits of SS# in user.csv file | F7: 37991 | G7: 38168 | H7: 50 | I7: 100
A8: Business Services | B8: ASER | C8: Started | D8: 14626 | E8: HR - Med Contrib Field Expan in FI, Ag, ASER 14626 | F8: 37938 | G8: 38017 | H8: 100 | I8: 150
A9: Business Services | B9: BUDG | C9: Started | D9: 13985 | E9: Annual Budget System Mods for 04-05 Budget (13985) | F9: 37832 | H9: 100 | I9: 500
A10: Business Services | B10: CAAC | C10: Pending | D10: 11008 | E10: SPS - Create new F&A Base for SPS Accounts 11008 | F10: 36846 | G10: 37072 | H10: 5 | I10: 10
A11: Business Services | B11: CARS | C11: Not Started | D11: 14731 | E11: CARS - Reflect in FMIS chg acct from CARS - 14731 | F11: 37970 | G11: 38169 | H11: 100 | I11: 300
A12: Business Services | B12: CARS | C12: Pending | D12: 12870 | E12: CARS - Modify FMIS feeds payments to write-offs 12870 | F12: 37343 | G12: 37407 | H12: 20 | I12: 60
A13: Business Services | B13: CARS | C13: Pending | D13: 13108 | E13: CARS - Credit balance on type W accounts 13108 | F13: 37427 | H13: 30 | I13: 60
A14: Business Services | B14: CARS | C14: Pending | D14: 14546 | E14: CARS - W-O NFEE not posting bad debt to FMIS 14546 | F14: 37924 | H14: 20 | I14: 40
A15: Business Services | B15: CARS | C15: Started | D15: 14732 | E15: CARS - Incl Reg Campus 1-2140 on Mo Recon - 14732 | F15: 37970 | G15: 38047 | H15: 20 | I15: 40
A16: Business Services | B16: COEUS | C16: Not Started | D16: 14071 | E16: COEUS - Impl IRB module - Phase I & Phase II 14071 | F16: 37874 | H16: 800 | I16: 1600
A17: Business Services | B17: FMIS | C17: Not Started | D17: 15006 | E17: FMIS - Add Obj 49102 to SPS Front End Edit 15006 | F17: 37988 | G17: 38016 | H17: 8 | I17: 20
A18: Business Services | B18: FMIS | C18: Pending | D18: 14094 | E18: FMIS - Fix Schedule I object mapping 14094 | F18: 37879 | H18: 20 | I18: 40
A19: Business Services | B19: ODS Replication | C19: Started | D19: 14949 | E19: Replicate 11 new tables for Paciolan interface | F19: 37742 | G19: 37986 | H19: 160 | I19: 240
A20: Business Services | B20: ODS Reporting | C20: Started | D20: 14913 | E20: Pacesetter - Move withdrawn proposals to result report | F20: 37824 | G20: 37865 | H20: 100 | I20: 160
A21: Business Services | B21: PAFX | C21: Started | D21: 13710 | E21: Employer Medical Field Expansion (13710) | F21: 37690 | H21: 900 | I21: 1200
A22: Business Services | B22: PAFX | C22: Started | D22: 13783 | E22: FSA Duplicate Claims Problem (13783) | F22: 37725 | H22: 8 | I22: 40
A23: Business Services | B23: PAFX | C23: Started | D23: 13887 | E23: Spousal Opt-out without Medical Credit (13887) | F23: 37788 | H23: 4 | I23: 8
A24: Business Services | B24: PAYR | C24: Not Started | D24: 14724 | E24: Need to Handle 2 PayPeriod 80s in FY 04-05 (14724) | F24: 37967 | G24: 38533 | H24: 800 | I24: 1200
A25: Business Services | B25: PAYR | C25: Placeholder | D25: 15002 | E25: Modify Regional Grad Health Insurance in Paryoll Charge | F25: 38009 | H25: 30 | I25: 50
A26: Business Services | B26: PAYR | C26: Started | D26: 12277 | E26: COBOLII Conversions (12277) | F26: 37140 | H26: 90 | I26: 100
A27: Business Services | B27: PAYR | C27: Started | D27: 13958 | E27: Payroll Year End 2003 (13958) | F27: 37819 | H27: 100 | I27: 500
A28: Business Services | B28: PAYR | C28: Started | D28: 14242 | E28: Excess Insurance W-2 Modification (14242) | F28: 37890 | G28: 38077 | H28: 200 | I28: 400
A29: Business Services | B29: PAYR | C29: Started | D29: 14467 | E29: SS/OASDI Wage Base for 2004 (14467) | F29: 37923 | G29: 37985 | H29: 4 | I29: 8
A30: Business Services | B30: PAYR/PAFX | C30: Pending | D30: 10999 | E30: Modify Liberty Mutual Workers Comp Data (10999) | F30: 36774 | H30: 40 | I30: 80
A31: Business Services | B31: PAYR/PAFX | C31: Placeholder | D31: 14974 | E31: Health Assessment Benefit (14974) | F31: 38002 | H31: 1 | I31: 999
A32: Business Services | B32: PAYR/PAFX | C32: Placeholder | D32: 14975 | E32: Health Savings Account Benefit (14975) | F32: 38002 | H32: 1 | I32: 999
A33: Business Services | B33: PAYR/PAFX | C33: Placeholder | D33: 14976 | E33: Direct Charge Leave Accruals (14976) | F33: 38002 | H33: 1 | I33: 999
A34: Business Services | B34: PAYR/PAFX | C34: Started | D34: 14373 | E34: Voluntary Benefit Bill & Remit Vendor File (14373) | F34: 37909 | G34: 37956 | H34: 200 | I34: 300
A35: Business Services | B35: PESN | C35: Not Started | D35: 14702 | E35: Replace Student/Personnel Interface (14702) | F35: 37958 | G35: 37951 | H35: 1 | I35: 1
A36: Business Services | B36: PESN | C36: Started | D36: 13977 | E36: Missing Form 4 Biweekly Updates (13977) | F36: 37831 | G36: 37845 | H36: 40 | I36: 120
A37: Business Services | B37: PESN | C37: Started | D37: 13978 | E37: Academic Rank Date Fix (13978) | F37: 37831 | G37: 37846 | H37: 40 | I37: 120
A38: Business Services | B38: PESN/PAYR | C38: Placeholder | D38: 14972 | E38: Research Faculty Position Code (14972) | F38: 38002 | H38: 1 | I38: 999
A39: Business Services | B39: PESN/PAYR | C39: Placeholder | D39: 14973 | E39: New Grad Student Classification (14973) | F39: 38002 | H39: 1 | I39: 999
A40: Business Services | B40: PROP | C40: Pending | D40: 12958 | E40: PROP - Action History File problms - Form data missing 12958 | F40: 37257 | G40: 37376 | H40: 40 | I40: 200
...

Sheet Production Support
A1: V.P. Area | B1: System | C1: Status | D1: ITEA RFS # | E1: Short Description | F1: Date Received | G1: Target Date | H1: Low Estimate | I1: High Estimate
A2: Business Services | B2: Ariba | C2: Not Started | D2: 14997 | E2: Follow up with infrastructure staff to run diagnostic suggested by Ariba in conference call on 1/22/04. Provide feedback to Ariba so that they can help determine if there is a way to lower the CPU being used by the bin process. | F2: 38008 | H2: 20 | I2: 40
A3: Business Services | B3: BUDG | C3: Started | D3: 7145 | E3: General Support - Budget (7145) | F3: 35856 | H3: 40 | I3: 400
A4: Business Services | B4: COEUS | C4: Started | D4: 14999 | E4: COEUS - Support Rollout to Regionals 14999 | F4: 38009 | H4: 10 | I4: 30
A5: Business Services | B5: FMIS | C5: Started | D5: 14967 | E5: FMIS - Fund Explosion File Listing‎ 14967 | F5: 38002 | H5: 1 | I5: 10
A6: Business Services | B6: FMIS | C6: Started | D6: 14968 | E6: FMIS - Attribute File Data Load 14968 | F6: 38002 | H6: 1 | I6: 10
A7: Business Services | B7: PAFX | C7: Not Started | D7: 14956 | E7: Flex Open/Close Enrollment 2004 (14956) | F7: 38001 | G7: 11354 | H7: 100 | I7: 200
A8: Business Services | B8: PAFX | C8: Started | D8: 8098 | E8: Audit Emergency ACID's for FlexSystem (8098) | F8: 36157 | H8: 40 | I8: 40
A9: Business Services | B9: PAFX | C9: Started | D9: 9460 | E9: General Support - Flex (9460) | F9: 36497 | H9: 100 | I9: 300
A10: Business Services | B10: PAIS | C10: Started | D10: 12585 | E10: General Support - PAIS (12585) | F10: 37251 | H10: 4 | I10: 100
A11: Business Services | B11: PAYR | C11: Not Started | D11: 14938 | E11: Salary Budget Forward 2004 (14938) | F11: 38000 | G11: 38199 | H11: 200 | I11: 400
A12: Business Services | B12: PAYR | C12: Not Started | D12: 14939 | E12: August AY Payroll 2004 (14939) | F12: 38000 | G12: 38260 | H12: 100 | I12: 200
A13: Business Services | B13: PAYR | C13: Not Started | D13: 14954 | E13: Payroll Year-End 2004 (14954) | F13: 38001 | G13: 38412 | H13: 200 | I13: 400
A14: Business Services | B14: PAYR | C14: Started | D14: 10495 | E14: General Support - Payroll Calculator (10495) | F14: 36740 | H14: 80 | I14: 100
A15: Business Services | B15: PAYR | C15: Started | D15: 12415 | E15: General Support - Payroll (12415) | F15: 37186 | H15: 1 | I15: 40
A16: Business Services | B16: PESN | C16: Started | D16: 8317 | E16: General Support - Resumix (8317) | F16: 36229 | H16: 100 | I16: 150
A17: Business Services | B17: PESN | C17: Started | D17: 11435 | E17: General Support - Personnel (11435) | F17: 36941 | H17: 1 | I17: 100
A18: Business Services | B18: PESN | C18: Started | D18: 13628 | E18: Administrative Overhead for HR team (13628) | F18: 37657 | H18: 100 | I18: 200
A19: Business Services | B19: YREND | C19: Not Started | D19: 14160 | E19: FMIS - Year end support 2004 14160 | F19: 37881 | H19: 50 | I19: 100
A20: ITaP | B20: WAI | C20: Ready for Class Review | D20: 14889 | E20: Maintenance procedures for Data Cubes | F20: 37998 | G20: 38139 | H20: 200 | I20: 400
A21: ITaP | B21: WAI | C21: Ready for Class Review | D21: 14994 | E21: Investigate DSS Refresh Data Load Procedures | F21: 38007 | H21: 20 | I21: 40
A22: ITaP | B22: WAI | C22: Started | D22: 14848 | E22: Financial trouble shooting and system admin | F22: 37993 | G22: 38017 | H22: 10 | I22: 50
A23: ITaP | B23: WAI | C23: Started | D23: 14849 | E23: Student DSS system admin and trouble shooting | F23: 37993 | G23: 38017 | H23: 10 | I23: 50
A24: ITaP | B24: WAI | C24: Started | D24: 14870 | E24: Trouble Shooting/mainrtenance of ETL environment | F24: 37995 | G24: 38017 | H24: 10 | I24: 50
A25: Student Services | B25: SIS | C25: Pending | D25: 14935 | E25: Predictive Modeling - Annual Support Prospect | F25: 38000 | H25: 75 | I25: 125
A26: Student Services | B26: SIS | C26: Pending | D26: 14936 | E26: Predictive Modeling - Annual Support Inquiry | F26: 38000 | H26: 75 | I26: 125
A27: Student Services | B27: SIS | C27: Pending | D27: 14937 | E27: Predictive Modeling - Annual Support Admit | F27: 38000 | H27: 75 | I27: 125
A28: University Residences | B28: PRIDE | C28: Not Started | D28: 13992 | E28: PRIDE - Remove and Archive PRIDE System 13992 | F28: 37865 | G28: 38353 | H28: 50 | I28: 100
A29: University Residences | B29: RHAC | C29: Not Started | D29: 14255 | E29: RHAC - Annual Reporting 2003-2004 14255 | F29: 37893 | G29: 38259 | H29: 100 | I29: 200

Sheet By V.P Area
A1: Classification | B1: Business Services | C1: Porfolio for Business Services
A2: Non-Electives
A3: New Applications | B3: =Summary!D3 -> 0
A4: Investigations | B4: =Summary!D4 -> 30
A5: Emergency Fixes | B5: =Summary!D5 -> 3
A6: Application Fixes | B6: =Summary!D6 -> 27
A7: Scheduled Modification | B7: =Summary!D7 -> 48
A8: Production Support | B8: =Summary!D8 -> 18
A9: OnePurdue | B9: =Summary!D9 -> 1
A10: Electives | B10: =Summary!D10 -> 30
A22: Classification | B22: Housing & Food Services | C22: Porfolio for Housing & Food Services
A23: Non-Electives
A24: New Applications | B24: =Summary!F3 -> 0
A25: Investigations | B25: =Summary!F4 -> 3
A26: Emergency Fixes | B26: =Summary!F5 -> 0
A27: Application Fixes | B27: =Summary!F6 -> 5
A28: Scheduled Modification | B28: =Summary!F7 -> 3
A29: Production Support | B29: =Summary!F8 -> 2
A30: OnePurdue | B30: =Summary!F9 -> 0
A31: Electives | B31: =Summary!F10 -> 5
A42: Classification | B42: ITaP / ITEA | C42: Porfolio for ITaP / ITEA
A43: Non-Electives
A44: New Applications | B44: =Summary!H3 -> 0
A45: Investigations | B45: =Summary!H4 -> 3
A46: Emergency Fixes | B46: =Summary!H5 -> 0
A47: Application Fixes | B47: =Summary!H6 -> 5
A48: Scheduled Modification | B48: =Summary!H7 -> 17
A49: Production Support | B49: =Summary!H8 -> 5
A50: OnePurdue | B50: =Summary!H9 -> 3
A51: Electives | B51: =Summary!H10 -> 15
A62: Classification | B62: Physical Facilities | C62: Porfolio for Physical Facilities
A63: Non-Electives
A64: New Applications | B64: =Summary!I3 -> 0
A65: Investigations | B65: =Summary!I4 -> 0
A66: Emergency Fixes | B66: =Summary!I5 -> 0
A67: Application Fixes | B67: =Summary!I6 -> 2
A68: Scheduled Modification | B68: =Summary!I7 -> 0
A69: Production Support | B69: =Summary!I8 -> 0
A70: OnePurdue | B70: =Summary!I9 -> 0
A71: Electives | B71: =Summary!I10 -> 3
...

Sheet Glossary of System Names
A1: System | B1: System Name
A2: ACAG | B2: Agriculture Accounting
A3: Advance C/S | B3: Advance C/S
A4: Ariba | B4: Ariba
A5: ASER | B5: Analytical Studies - Effort Reporting
A6: BADR | B6: Bus. Admin. - Dept Reference
A7: BUDG | B7: Budget
A8: BUFC | B8: Faculty Contracts
A9: Bursar | B9: Bursar
A10: Business Intel Arch | B10: Business Intelligence Architecture
A11: CAAC | B11: Sponsored Programs Accounting
A12: CARS | B12: Centralized Accounts Receivable System.
... A81: YREND | B81: Financial Year End Processing
