Workbook
Name Belg: Dialogbox!$B$30
Name Change_names: '2001 Grossed'!$B$2
Name Country_Name: Help!$B$113
Name DATA_TYPES: Help!$B$56
Name Example: Help!$D$95:$D$131
Name Help: Help!$A$1
Name Structure: Help!$J$1

Sheet 2001
A1: Name | B1: Type | C1: Code | D1: Population '000s | E1: Libraries - Total Administrative Units | F1: Libraries - Service Points | G1: Collections - Books & Bound Periodicals | H1: Collections - Current Periodicals - Titles | I1: Collections - Current Periodicals - Subscriptions | J1: Collections - Manuscripts | K1: Collections - Microforms | L1: Collections - Audio-visual Materials | M1: Collections - CD-ROMs | N1: Additions - Books & Bound Periodicals | O1: Additions - Audio-visual Materials | P1: Facilities & Services - Percentage Stock on Open Access | Q1: Facilities & Services - Percentage Catalogue Records Automated | R1: Facilities & Services - Number of Workstations for users | S1: Facilities & Services - Number connected to the internet | T1: Use & Users - Registered Users | U1: Use & Users - Loan Transactions | V1: Use & Users - Number of Visits | W1: Use & Users - Number of virtual referrals and transactions | X1: Use & Users - Number of virtual visits to networked library services | Y1: Use & Users - Potential Total Population Served | Z1: Library Staff FTE - Trained Librarians | AA1: Library Staff FTE - Other Library Staff | AB1: Library Staff FTE - Total Staff | AC1: Recurrent Expenditure (Euros) - Staff | AD1: Recurrent Expenditure (Euros) - Acquisition of Stock | AE1: Recurrent Expenditure (Euros) - Electronic Information | AF1: Recurrent Expenditure (Euros) - Automation | AG1: Recurrent Expenditure (Euros) - Premises and Related Costs | AH1: Recurrent Expenditure (Euros) - New Buildings / Refurbishment | AI1: Recurrent Expenditure (Euros) - Other Expenditure | AJ1: Recurrent Expenditure (Euros) - TOTAL EXPENDITURE | AK1: Income - Public Funding | AL1: Income - Fees & Charges | AM1: Income - Other Income | AN1: Income - TOTAL INCOME | AO1: Capital Expenditure - New Buildings / Refurbishment | AP1: Capital Expenditure - Acquisition of Stock | AQ1: Capital Expenditure - Automation | AR1: Capital Expenditure - Other Capital Expenditure | AS1: Capital Expenditure - TOTAL CAPITAL PAYMENTS | AT1: Additions | AU1: Loans per visit | AV1: Cost per pop | AW1: Users per 1000 pop | AX1: visits per 1000 pop | AY1: Bookstock per 1000 pop | AZ1: Total stock per 1000 pop | BA1: AV materials per 1000 pop
A2: Bulgaria | B2: CEE | C2: C1 | D2: =+Y2/1000 -> 7819.633 | E2: 3757 | F2: 3757 | G2: 52004510 | H2: 16841 | K2: 84843 | L2: 852026 | N2: 280475 | O2: 5354 | P2: 80 | T2: 901512 | U2: 17999677 | V2: 8252063 | W2: 12021 | X2: 13754 | Y2: 7819633 | Z2: 2915 | AA2: 406 | AB2: 3321 | AC2: 3960297 | AD2: 543433 | AE2: 0 | AF2: 0 | AG2: 0 | AH2: 0 | AI2: 830890 | AJ2: 5334620 | AK2: 4721347 | AL2: 359705 | AM2: 253568 | AN2: 5334620 | AT2: =+N2+O2 -> 285829 | AU2: =+U2/V2 -> 2.1812336 | AV2: =+AJ2/Y2 -> 0.68220849 | AW2: =+T2/D2 -> 115.28828 | AX2: =+V2/D2 -> 1055.3005 | AY2: =+G2/D2 -> 6650.5052 | AZ2: =SUM(G2:M2)/D2 -> 6772.4687 | BA2: =+L2/D2 -> 108.95985
A3: Czech Republic | B3: CEE | C3: C2 | D3: =+Y3/1000 -> 10223.833 | E3: 6090 | F3: 7179 | G3: 54293396 | H3: 78645 | I3: 87177 | J3: 3951 | K3: 130796 | L3: 676032 | M3: 25018 | N3: 1667841 | O3: 22204 | P3: 76 | Q3: 46 | R3: 3166 | S3: 2116 | T3: 1466682 | U3: 69208089 | V3: 16485563 | W3: 68703 | X3: 48228 | Y3: 10223833 | Z3: 3807 | AA3: 594 | AB3: 4401 | AC3: 22656487 | AD3: 5164471 | AE3: 10916 | AF3: 358727 | AG3: 1333161 | AH3: 380860 | AI3: 14089619 | AJ3: 43994240 | AK3: 45846096 | AL3: 157236 | AM3: 172074 | AN3: 46175406 | AO3: 1044702 | AP3: 0 | AQ3: 0 | AR3: 2938566 | AS3: 3983268 | AT3: =+N3+O3 -> 1690045 | AU3: =+U3/V3 -> 4.1981028 | AV3: =+AJ3/Y3 -> 4.3031063 | AW3: =+T3/D3 -> 143.45716 | AX3: =+V3/D3 -> 1612.464 | AY3: =+G3/D3 -> 5310.4737 | AZ3: =SUM(G3:M3)/D3 -> 5408.4427 | BA3: =+L3/D3 -> 66.123146
A4: Estonia | B4: CEE | C4: C3 | D4: =+Y4/1000 -> 1431.553 | E4: 546 | F4: 664 | G4: 10986247 | H4: 16010 | I4: 17865 | J4: 87 | K4: 1600 | L4: 54302 | M4: 900 | N4: 535439 | O4: 4708 | P4: 75 | Q4: 5 | R4: 631 | S4: 603 | T4: 447834 | U4: 13503545 | V4: 6426415 | W4: 0 | X4: 0 | Y4: 1431553 | Z4: 1224 | AA4: 257 | AB4: 1481 | AC4: 5053889 | AD4: 3335506 | AE4: 0 | AF4: 446677 | AG4: 0 | AH4: 0 | AI4: 1928745 | AJ4: 10764818 | AK4: 13209526 | AL4: 0 | AM4: 269121 | AN4: 13478647 | AO4: 2513456 | AP4: 0 | AQ4: 101119 | AR4: 88273 | AS4: 2702849 | AT4: =+N4+O4 -> 540147 | AU4: =+U4/V4 -> 2.1012563 | AV4: =+AJ4/Y4 -> 7.5196783 | AW4: =+T4/D4 -> 312.83089 | AX4: =+V4/D4 -> 4489.1213 | AY4: =+G4/D4 -> 7674.3558 | AZ4: =SUM(G4:M4)/D4 -> 7737.7582 | BA4: =+L4/D4 -> 37.932232
A5: Hungary | B5: CEE | C5: C4 | D5: =+Y5/1000 -> 10017.547 | E5: 2470 | F5: 3003 | G5: 40714533 | H5: 44888 | L5: 1443321 | M5: 48915 | N5: 1079410 | O5: 70025 | T5: 1362096 | U5: 12554527 | V5: 16580105 | W5: 15962 | X5: 45618 | Y5: 10017547 | Z5: 3566 | AA5: 2166 | AB5: 5732 | AC5: 21484399 | AD5: 5045211 | AE5: 0 | AF5: 0 | AG5: 0 | AH5: 0 | AI5: 18160365 | AJ5: 44689975 | AK5: 30615395 | AL5: 0 | AM5: 14074580 | AN5: 44689975 | AT5: =+N5+O5 -> 1149435 | AU5: =+U5/V5 -> 0.75720431 | AV5: =+AJ5/Y5 -> 4.4611695 | AW5: =+T5/D5 -> 135.97101 | AX5: =+V5/D5 -> 1655.1063 | AY5: =+G5/D5 -> 4064.3216 | AZ5: =SUM(G5:M5)/D5 -> 4217.7648 | BA5: =+L5/D5 -> 144.07928
A6: Latvia | B6: CEE | C6: C5 | D6: =+Y6/1000 -> 2326.2 | E6: 920 | F6: 920 | G6: 11738720 | K6: 1358 | L6: 164674 | N6: 298116 | O6: 14554 | T6: 575148 | U6: 21104458 | V6: 6440086 | W6: 0 | X6: 0 | Y6: 2326200 | Z6: 1828 | AA6: 655 | AB6: 2483 | AC6: 5638690 | AD6: 1456082 | AE6: 0 | AF6: 0 | AG6: 0 | AH6: 0 | AI6: 3072809 | AJ6: 10167581 | AK6: 10126712 | AL6: 26955 | AM6: 13914 | AN6: 10167581 | AO6: 109075 | AP6: 6964 | AQ6: 34978 | AR6: 32330 | AS6: 183347 | AT6: =+N6+O6 -> 312670 | AU6: =+U6/V6 -> 3.277046 | AV6: =+AJ6/Y6 -> 4.3708972 | AW6: =+T6/D6 -> 247.24787 | AX6: =+V6/D6 -> 2768.5006 | AY6: =+G6/D6 -> 5046.3073 | AZ6: =SUM(G6:M6)/D6 -> 5117.6821 | BA6: =+L6/D6 -> 70.79099
A7: Lithuania | B7: CEE | C7: C6 | D7: =+Y7/1000 -> 3646.32 | E7: 66 | F7: 1432 | G7: 22471450 | J7: 9522 | K7: 1174 | L7: 245876 | M7: 1958 | N7: 916453 | O7: 4992 | P7: 96 | R7: 375 | S7: 66 | T7: 831741 | U7: 25190465 | V7: 9794035 | W7: 9376 | X7: 71675 | Y7: 3646320 | Z7: 3104 | AA7: 892 | AB7: 3996 | AC7: 9291103 | AD7: 1787983 | AE7: 145149 | AF7: 214887 | AG7: 506659 | AH7: 0 | AI7: 4400886 | AJ7: 16346667 | AK7: 15696957 | AL7: 441912 | AM7: 266475 | AN7: 16405344 | AT7: =+N7+O7 -> 921445 | AU7: =+U7/V7 -> 2.5720211 | AV7: =+AJ7/Y7 -> 4.4830588 | AW7: =+T7/D7 -> 228.10423 | AX7: =+V7/D7 -> 2686.0053 | AY7: =+G7/D7 -> 6162.7751 | AZ7: =SUM(G7:M7)/D7 -> 6233.6767 | BA7: =+L7/D7 -> 67.431273
A8: Poland | B8: CEE | C8: C7 | D8: =+Y8/1000 -> 38652 | E8: 9226 | F8: 3564 | G8: 135816403 | K8: 10379 | L8: 2596064 | N8: 3792692 | O8: 121162 | T8: 7219507 | U8: 188957087 | W8: 103292 | X8: 118293 | Y8: 38652000 | Z8: 11133 | AA8: 6688 | AB8: 17821 | AT8: =+N8+O8 -> 3913854 | AU8: =+U8/V8 -> #DIV/0! | AV8: =+AJ8/Y8 -> 0 | AW8: =+T8/D8 -> 186.78224 | AX8: =+V8/D8 -> 0 | AY8: =+G8/D8 -> 3513.826 | AZ8: =SUM(G8:M8)/D8 -> 3581.2596 | BA8: =+L8/D8 -> 67.165063
A9: Romania | B9: CEE | C9: C8 | D9: =+Y9/1000 -> 22104.442 | E9: 2814 | F9: 3190 | G9: 48716685 | H9: 8923 | I9: 10268 | J9: 69088 | K9: 9439 | L9: 305960 | M9: 4000 | N9: 1033452 | O9: 7300 | P9: 74 | Q9: 9 | R9: 288 | S9: 114 | T9: 2046676 | U9: 36324232 | V9: 16890884 | W9: 3676 | X9: 4316 | Y9: 22104442 | Z9: 4475 | AA9: 783 | AB9: 5257 | AC9: 9775415 | AD9: 1394188 | AE9: 3028 | AF9: 47040 | AG9: 101912 | AH9: 17291 | AI9: 2079678 | AJ9: 13418552 | AK9: 13015995 | AL9: 134186 | AM9: 268371 | AN9: 13418552 | AO9: 942312 | AP9: 60231 | AQ9: 307789 | AR9: 272292 | AS9: 1582624 | AT9: =+N9+O9 -> 1040752 | AU9: =+U9/V9 -> 2.1505229 | AV9: =+AJ9/Y9 -> 0.60705228 | AW9: =+T9/D9 -> 92.591163 | AX9: =+V9/D9 -> 764.13981 | AY9: =+G9/D9 -> 2203.9319 | AZ9: =SUM(G9:M9)/D9 -> 2222.3752 | BA9: =+L9/D9 -> 13.841562
A10: Slovak Rep | B10: CEE | C10: C9 | D10: =+Y10/1000 -> 5398.983 | E10: 2656 | F10: 2909 | G10: 18954167 | H10: 11271 | I10: 13335 | J10: 633 | K10: 100 | L10: 243788 | M10: 2058 | N10: 334372 | O10: 1686 | P10: 93 | Q10: 30 | R10: 160 | S10: 142 | T10: 678637 | U10: 24702257 | V10: 6843282 | W10: 4852 | X10: 8475 | Y10: 5398983 | Z10: 1585 | AA10: 211 | AB10: 1796 | AC10: 4007711 | AD10: 846135 | AE10: 0 | AF10: 0 | AG10: 0 | AH10: 0 | AI10: 3279804 | AJ10: 8133651 | AK10: 6826698 | AL10: 671913 | AM10: 635040 | AN10: 8133651 | AO10: 448943 | AP10: 0 | AQ10: 64424 | AR10: 83734 | AS10: 597102 | AT10: =+N10+O10 -> 336058 | AU10: =+U10/V10 -> 3.6097091 | AV10: =+AJ10/Y10 -> 1.5065154 | AW10: =+T10/D10 -> 125.69719 | AX10: =+V10/D10 -> 1267.5132 | AY10: =+G10/D10 -> 3510.6921 | AZ10: =SUM(G10:M10)/D10 -> 3560.921 | BA10: =+L10/D10 -> 45.15443
A11: Slovenia | B11: CEE | C11: C10 | D11: =+Y11/1000 -> 1988.348 | E11: 60 | F11: 256 | G11: 7087968 | H11: 11079 | I11: 27950 | J11: 13689 | K11: 719 | L11: 234315 | M11: 13843 | N11: 354622 | O11: 34022 | P11: 82 | Q11: 74 | R11: 675 | S11: 387 | T11: 486108 | U11: 21883936 | V11: 7830326 | W11: 0 | X11: 0 | Y11: 1988348 | Z11: 626 | AA11: 242 | AB11: 868 | AC11: 15399404 | AD11: 5863893 | AE11: 96704 | AF11: 794158 | AG11: 6797167 | AH11: 1467029 | AI11: 0 | AJ11: 30418356 | AK11: 22032865 | AL11: 3557514 | AM11: 3049829 | AN11: 28640208 | AO11: 2514440 | AP11: 160718 | AQ11: 821296 | AR11: 726577 | AS11: 4223031 | AT11: =+N11+O11 -> 388644 | AU11: =+U11/V11 -> 2.7947669 | AV11: =+AJ11/Y11 -> 15.298306 | AW11: =+T11/D11 -> 244.47833 | AX11: =+V11/D11 -> 3938.1064 | AY11: =+G11/D11 -> 3564.7522 | AZ11: =SUM(G11:M11)/D11 -> 3716.4334 | BA11: =+L11/D11 -> 117.84406
A12: Austria | B12: EU | C12: C11 | D12: =+Y12/1000 -> 8122.933 | E12: 993 | F12: 1825 | G12: 9432575 | P12: 100 | Q12: 72 | R12: 1852 | S12: 1852 | T12: 848586 | U12: 14275803 | V12: 5249111 | W12: 19868 | X12: 21718 | Y12: 8122933 | Z12: 667 | AA12: 532 | AB12: 1199 | AC12: 33403971 | AD12: 5639644 | AE12: 22031 | AF12: 776573 | AG12: 2915684 | AH12: 41276 | AI12: 8435044 | AJ12: 51234223 | AK12: 46302662 | AL12: 3252539 | AM12: 1679022 | AN12: 51234223 | AT12: =+N12+O12 -> 0 | AU12: =+U12/V12 -> 2.7196611 | AV12: =+AJ12/Y12 -> 6.3073551 | AW12: =+T12/D12 -> 104.46793 | AX12: =+V12/D12 -> 646.20883 | AY12: =+G12/D12 -> 1161.2277 | AZ12: =SUM(G12:M12)/D12 -> 1161.2277 | BA12: =+L12/D12 -> 0
A13: België Vlaamse Gemeenschap | B13: België Vlaamse Gemeenschap | C13: C12a | D13: =+Y13/1000 -> 6260.144 | E13: 309 | F13: 879 | G13: 21553143 | I13: 43967 | L13: 2235649 | M13: 129303 | N13: 1372535 | O13: 231928 | Q13: 98 | T13: 1713351 | U13: 53679183 | Y13: 6260144 | Z13: 1724 | AA13: 977 | AB13: 2701 | AC13: 92360814 | AD13: 18239528 | AE13: 3783959 | AF13: 0 | AG13: 0 | AH13: 20638480 | AI13: 21364633 | AJ13: 156387414 | AK13: 54231239 | AL13: 9258630 | AM13: 822122 | AN13: 64311991 | AT13: =+N13+O13 -> 1604463 | AU13: =+U13/V13 -> #DIV/0! | AV13: =+AJ13/Y13 -> 24.98144 | AW13: =+T13/D13 -> 273.69195 | AX13: =+V13/D13 -> 0 | AY13: =+G13/D13 -> 3442.9149 | AZ13: =SUM(G13:M13)/D13 -> 3827.7174 | BA13: =+L13/D13 -> 357.12421
A14: Belgique-Communauté française | B14: Belgique-Communauté française | C14: C12b | D14: =+Y14/1000 -> 4139.223 | E14: 175 | F14: 572 | G14: 12496226 | I14: 99387 | L14: 93862 | M14: 9803 | N14: 253157 | O14: 2701 | R14: 395 | T14: 790555 | Y14: 4139223 | Z14: 700 | AA14: 301 | AB14: 1001 | AC14: 35790136 | AD14: 5428064 | AE14: 0 | AF14: 0 | AG14: 5084090 | AH14: 1405423 | AI14: 1182478 | AJ14: 48890191 | AK14: 40035871 | AL14: 3293057 | AM14: 0 | AN14: 43328928 | AT14: =+N14+O14 -> 255858 | AU14: =+U14/V14 -> #DIV/0! | AV14: =+AJ14/Y14 -> 11.811442 | AW14: =+T14/D14 -> 190.99116 | AX14: =+V14/D14 -> 0 | AY14: =+G14/D14 -> 3018.9787 | AZ14: =SUM(G14:M14)/D14 -> 3068.0343 | BA14: =+L14/D14 -> 22.676237
A15: Belgium | B15: EU | C15: C12 | D15: =+Y15/1000 -> 10399.367 | E15: 485 | F15: 1451 | G15: 34049369 | I15: 143354 | L15: 2329511 | M15: 139106 | N15: 1625692 | O15: 234629 | Q15: 98 | T15: 2503906 | W15: 41891 | X15: 35445 | Y15: 10399367 | Z15: 2424 | AA15: 1278 | AB15: 3702 | AC15: 128150950 | AD15: 23667592 | AE15: 3783959 | AF15: 0 | AG15: 5084090 | AH15: 22043903 | AI15: 22547111 | AJ15: 205277605 | AK15: 203318996 | AL15: 8470710 | AM15: 5887384 | AN15: 217677090 | AT15: =+N15+O15 -> 1860321 | AU15: =+U15/V15 -> #DIV/0! | AV15: =+AJ15/Y15 -> 19.739433 | AW15: =+T15/D15 -> 240.77485 | AX15: =+V15/D15 -> 0 | AY15: =+G15/D15 -> 3274.1771 | AZ15: =SUM(G15:M15)/D15 -> 3525.3434 | BA15: =+L15/D15 -> 224.00508
A16: Denmark | B16: EU | C16: C13 | D16: =+Y16/1000 -> 5367.226 | E16: 244 | F16: 797 | G16: 27081405 | H16: 2834 | I16: 184810 | J16: 25951 | K16: 355 | L16: 2988653 | M16: 121535 | N16: 1543188 | O16: 378324 | P16: 89 | Q16: 73 | R16: 3590 | S16: 2551 | T16: 1880587 | U16: 71657119 | V16: 32971560 | W16: 875756 | X16: 11249571 | Y16: 5367226 | Z16: 2286 | AA16: 2792 | AB16: 5078 | AC16: 202488396 | AD16: 49767930 | AI16: 92690956 | AJ16: 344947282 | AK16: 344947282 | AN16: 344947282 | AT16: =+N16+O16 -> 1921512 | AU16: =+U16/V16 -> 2.1733008 | AV16: =+AJ16/Y16 -> 64.269193 | AW16: =+T16/D16 -> 350.38342 | AX16: =+V16/D16 -> 6143.1287 | AY16: =+G16/D16 -> 5045.6987 | AZ16: =SUM(G16:M16)/D16 -> 5665.0387 | BA16: =+L16/D16 -> 556.83383
A17: Eire | B17: EU | C17: C15 | D17: =+Y17/1000 -> 3802.333 | E17: 32 | F17: 360 | G17: 11528071 | H17: 12663 | I17: 1710 | J17: 12728 | K17: 21307 | L17: 348422 | M17: 3436 | N17: 1004393 | O17: 37824 | P17: 89 | Q17: 73 | R17: 1317 | S17: 835 | T17: 905397 | U17: 12046407 | V17: 20373338 | W17: 1860 | X17: 4708 | Y17: 3802333 | Z17: 295 | AA17: 1105 | AB17: 1400 | AC17: 34418420 | AD17: 9778592 | AE17: 0 | AF17: 1616215 | AG17: 8339853 | AH17: 0 | AI17: 6795565 | AJ17: 60948645 | AK17: 53279598 | AL17: 1560092 | AM17: 6108955 | AN17: 60948645 | AO17: 3882190 | AP17: 4544227 | AQ17: 2042719 | AR17: 1376111 | AS17: 11845247 | AT17: =+N17+O17 -> 1042217 | AU17: =+U17/V17 -> 0.59128293 | AV17: =+AJ17/Y17 -> 16.029276 | AW17: =+T17/D17 -> 238.11618 | AX17: =+V17/D17 -> 5358.1151 | AY17: =+G17/D17 -> 3031.8415 | AZ17: =SUM(G17:M17)/D17 -> 3137.11 | BA17: =+L17/D17 -> 91.633742
A18: Finland | B18: EU | C18: C16 | D18: =+Y18/1000 -> 5158.44 | E18: 436 | F18: 1117 | G18: 37073549 | I18: 97972 | L18: 4353661 | M18: 24086 | N18: 1597165 | O18: 344380 | P18: 100 | Q18: 100 | R18: 2633 | S18: 1370 | T18: 2384067 | U18: 102216649 | V18: 63922228 | W18: 186232 | X18: 194134 | Y18: 5158440 | Z18: 1493 | AA18: 2662 | AB18: 4155 | AC18: 133788467 | AD18: 41960202 | AE18: 0 | AF18: 0 | AG18: 0 | AH18: 0 | AI18: 62732665 | AJ18: 238481334 | AK18: 219279683 | AL18: 4525438 | AM18: 14676213 | AN18: 238481334 | AO18: 19549279 | AP18: 1249550 | AQ18: 6385416 | AR18: 5648995 | AS18: 32833240 | AT18: =+N18+O18 -> 1941545 | AU18: =+U18/V18 -> 1.5990783 | AV18: =+AJ18/Y18 -> 46.23129 | AW18: =+T18/D18 -> 462.16821 | AX18: =+V18/D18 -> 12391.775 | AY18: =+G18/D18 -> 7186.9691 | AZ18: =SUM(G18:M18)/D18 -> 8054.6188 | BA18: =+L18/D18 -> 843.98791
A19: France | B19: EU | C19: C17 | D19: =+Y19/1000 -> 59463.538 | E19: 3989 | F19: 3884 | G19: 152159231 | I19: 230713 | L19: 10231729 | M19: 216654 | N19: 7042112 | O19: 1011847 | P19: 85 | T19: 12025650 | U19: 310175619 | W19: 18939 | X19: 21692 | Y19: 59463538 | Z19: 7031 | AA19: 14498 | AB19: 21529 | AC19: 685948897 | AD19: 124603730 | AE19: 650962 | AF19: 16711785 | AG19: 57245238 | AH19: 27126 | AI19: 171025601 | AJ19: 1056213339 | AK19: 1022860539 | AL19: 27109539 | AM19: 6243261 | AN19: 1056213339 | AO19: 218371411 | AP19: 8895576 | AQ19: 45457951 | AR19: 40215347 | AS19: 312940285 | AT19: =+N19+O19 -> 8053959 | AU19: =+U19/V19 -> #DIV/0! | AV19: =+AJ19/Y19 -> 17.76237 | AW19: =+T19/D19 -> 202.2357 | AX19: =+V19/D19 -> 0 | AY19: =+G19/D19 -> 2558.8661 | AZ19: =SUM(G19:M19)/D19 -> 2738.4567 | BA19: =+L19/D19 -> 172.06728
A20: Greece | B20: EU | C20: C18 | D20: =+Y20/1000 -> 10824 | E20: 733 | F20: 829 | G20: 9907012 | H20: 164430 | I20: 126978 | J20: 1540926 | K20: 324200 | L20: 104669 | M20: 13776 | N20: 302533 | O20: 12523 | P20: 89 | Q20: 73 | R20: 5020 | S20: 2545 | T20: 2951314 | U20: 1994343 | V20: 2492594 | W20: 8912 | X20: 12469 | Y20: 10824000 | Z20: 1029 | AA20: 805 | AB20: 1834 | AC20: 42171895 | AD20: 9424764 | AE20: 50573 | AF20: 1298353 | AG20: 4447434 | AH20: 2108 | AI20: 13287131 | AJ20: 70682258 | AT20: =+N20+O20 -> 315056 | AU20: =+U20/V20 -> 0.80010744 | AV20: =+AJ20/Y20 -> 6.5301421 | AW20: =+T20/D20 -> 272.6639 | AX20: =+V20/D20 -> 230.284 | AY20: =+G20/D20 -> 915.28197 | AZ20: =SUM(G20:M20)/D20 -> 1125.4611 | BA20: =+L20/D20 -> 9.670085
A21: Iceland | B21: EFTA | C21: C19 | D21: =+Y21/1000 -> 281.31 | E21: 127 | F21: 133 | G21: 2067665 | I21: 94 | J21: 600 | K21: 3178 | L21: 70718 | M21: 880 | N21: 83407 | O21: 4962 | T21: 90696 | U21: 2233208 | V21: 842590 | W21: 497 | X21: 2192 | Y21: 281310 | Z21: 80 | AA21: 220 | AB21: 300 | AC21: 4801006 | AD21: 1665216 | AE21: 0 | AF21: 94929 | AG21: 675864 | AH21: 226685 | AI21: 1253994 | AJ21: 8717694 | AK21: 7937709 | AL21: 620304 | AM21: 159681 | AN21: 8717694 | AT21: =+N21+O21 -> 88369 | AU21: =+U21/V21 -> 2.6504089 | AV21: =+AJ21/Y21 -> 30.989634 | AW21: =+T21/D21 -> 322.40589 | AX21: =+V21/D21 -> 2995.2366 | AY21: =+G21/D21 -> 7350.1298 | AZ21: =SUM(G21:M21)/D21 -> 7618.4103 | BA21: =+L21/D21 -> 251.38815
A22: Italy | B22: EU | C22: C20 | D22: =+Y22/1000 -> 57843.667 | E22: 84 | F22: 6003 | G22: 42214563 | N22: 3993273 | W22: 457999 | X22: 500805 | Y22: 57843667 | Z22: 5984 | AA22: 17856 | AB22: 23840 | AT22: =+N22+O22 -> 3993273 | AU22: =+U22/V22 -> #DIV/0! | AV22: =+AJ22/Y22 -> 0 | AW22: =+T22/D22 -> 0 | AX22: =+V22/D22 -> 0 | AY22: =+G22/D22 -> 729.80441 | AZ22: =SUM(G22:M22)/D22 -> 729.80441 | BA22: =+L22/D22 -> 0
A23: Liechtenstein | B23: EFTA | C23: C21 | D23: =+Y23/1000 -> 33.322 | E23: 3 | F23: 3 | G23: 24588 | N23: 6087 | S23: 5 | U23: 80227 | W23: 1373 | X23: 1009 | Y23: 33322 | Z23: 2 | AA23: 3 | AB23: 5 | AT23: =+N23+O23 -> 6087 | AU23: =+U23/V23 -> #DIV/0! | AV23: =+AJ23/Y23 -> 0 | AW23: =+T23/D23 -> 0 | AX23: =+V23/D23 -> 0 | AY23: =+G23/D23 -> 737.89088 | AZ23: =SUM(G23:M23)/D23 -> 737.89088 | BA23: =+L23/D23 -> 0
A24: Luxembourg | B24: EU | C24: C22 | D24: =+Y24/1000 -> 457.333 | E24: 8 | F24: 8 | G24: 248480 | H24: 188 | I24: 173 | J24: 0 | K24: 0 | L24: 1530 | M24: 332 | N24: 10102 | O24: 114 | P24: 91 | Q24: 44 | R24: 52 | S24: 28 | T24: 37112 | U24: 129535 | V24: 78357 | W24: 2210 | X24: 3887 | Y24: 457333 | Z24: 18 | AA24: 5 | AB24: 23 | AC24: 1117927 | AD24: 257520 | AE24: 418 | AF24: 21 | AG24: 38878 | AH24: 41805 | AI24: 32997 | AJ24: 1489566 | AO24: 8895 | AP24: 453 | AQ24: 2300 | AR24: 1785 | AS24: 13433 | AT24: =+N24+O24 -> 10216 | AU24: =+U24/V24 -> 1.6531388 | AV24: =+AJ24/Y24 -> 3.2570709 | AW24: =+T24/D24 -> 81.148747 | AX24: =+V24/D24 -> 171.33467 | AY24: =+G24/D24 -> 543.32401 | AZ24: =SUM(G24:M24)/D24 -> 548.1848 | BA24: =+L24/D24 -> 3.3454835
A25: Netherlands | B25: EU | C25: C23 | D25: =+Y25/1000 -> 16250.667 | E25: 490 | F25: 1101 | G25: 42386215 | N25: 3817553 | U25: 197036000 | W25: 125021 | X25: 136747 | Y25: 16250667 | Z25: 2510 | AA25: 5898 | AB25: 8408 | AC25: 264286000 | AD25: 52415923 | AE25: 278786 | AF25: 35398000 | AG25: 72518000 | AH25: 12961 | AI25: 72677330 | AJ25: 497587000 | AK25: 338790000 | AL25: 61509000 | AM25: 97288000 | AN25: 497587000 | AT25: =+N25+O25 -> 3817553 | AU25: =+U25/V25 -> #DIV/0! | AV25: =+AJ25/Y25 -> 30.619482 | AW25: =+T25/D25 -> 0 | AX25: =+V25/D25 -> 0 | AY25: =+G25/D25 -> 2608.2754 | AZ25: =SUM(G25:M25)/D25 -> 2608.2754 | BA25: =+L25/D25 -> 0
A26: Norway | B26: EFTA | C26: C24 | D26: =+Y26/1000 -> 4551.248 | E26: 435 | F26: 1010 | G26: 20642273 | H26: 21003 | I26: 42093 | J26: 36521 | K26: 291716 | L26: 1319527 | M26: 15746 | N26: 860640 | O26: 149152 | P26: 82 | Q26: 79 | R26: 1714 | S26: 1369 | T26: 1319108 | U26: 23467666 | V26: 22684118 | W26: 113996 | X26: 142338 | Y26: 4551248 | Z26: 931 | AA26: 940 | AB26: 1871 | AC26: 76697660 | AD26: 17104294 | AE26: 0 | AF26: 3535708 | AG26: 11524607 | AH26: 0 | AI26: 15907166 | AJ26: 124769435 | AK26: 113606123 | AL26: 8877923 | AM26: 2285388 | AN26: 124769435 | AT26: =+N26+O26 -> 1009792 | AU26: =+U26/V26 -> 1.0345417 | AV26: =+AJ26/Y26 -> 27.414334 | AW26: =+T26/D26 -> 289.83435 | AX26: =+V26/D26 -> 4984.1534 | AY26: =+G26/D26 -> 4535.5193 | AZ26: =SUM(G26:M26)/D26 -> 4914.8891 | BA26: =+L26/D26 -> 289.92641
A27: Portugal | B27: EU | C27: C25 | D27: =+Y27/1000 -> 9832 | E27: 164 | F27: 278 | G27: 6389929 | K27: 2488 | L27: 172137 | N27: 391909 | O27: 24585 | R27: 780 | T27: 3117902 | U27: 1486378 | W27: 563 | X27: 1 | Y27: 9832000 | Z27: 792 | AA27: 531 | AB27: 1323 | AC27: 13100349 | AD27: 2747158 | AE27: 27 | AF27: 731 | AG27: 3440 | AH27: 2359 | AI27: 2576928 | AJ27: 18430992 | AK27: 18183890 | AL27: 245749 | AM27: 1353 | AN27: 18430992 | AO27: 3150666 | AP27: 0 | AQ27: 0 | AR27: 2401210 | AS27: 5551876 | AT27: =+N27+O27 -> 416494 | AU27: =+U27/V27 -> #DIV/0! | AV27: =+AJ27/Y27 -> 1.8745924 | AW27: =+T27/D27 -> 317.11778 | AX27: =+V27/D27 -> 0 | AY27: =+G27/D27 -> 649.91141 | AZ27: =SUM(G27:M27)/D27 -> 667.67229 | BA27: =+L27/D27 -> 17.507832
A28: Spain | B28: EU | C28: C26 | D28: =+Y28/1000 -> 39542.333 | E28: 4829 | F28: 5209 | G28: 42817561 | H28: 97230 | I28: 158931 | J28: 28069 | K28: 253527 | L28: 1583579 | M28: 125123 | N28: 2494800 | O28: 209169 | P28: 89 | Q28: 73 | R28: 2941 | S28: 462 | T28: 7524176 | U28: 27491212 | V28: 204131947 | W28: 126139 | X28: 5171 | Y28: 39542333 | Z28: 4139 | AA28: 2469 | AB28: 6608 | AC28: 132172221 | AD28: 30509153 | AE28: 0 | AF28: 0 | AG28: 0 | AH28: 0 | AI28: 26443101 | AJ28: 189124475 | AK28: 170920259 | AL28: 12006324 | AM28: 6197892 | AN28: 189124475 | AT28: =+N28+O28 -> 2703969 | AU28: =+U28/V28 -> 0.13467374 | AV28: =+AJ28/Y28 -> 4.7828355 | AW28: =+T28/D28 -> 190.28154 | AX28: =+V28/D28 -> 5162.3648 | AY28: =+G28/D28 -> 1082.8284 | AZ28: =SUM(G28:M28)/D28 -> 1139.6399 | BA28: =+L28/D28 -> 40.047688
A29: Sweden | B29: EU | C29: C27 | D29: =+Y29/1000 -> 8909.457 | E29: 291 | F29: 1592 | G29: 44330201 | H29: 67961 | I29: 106470 | J29: 0 | K29: 0 | L29: 2619965 | M29: 0 | N29: 2054539 | O29: 185836 | P29: 87 | U29: 81381984 | V29: 47575528 | W29: 0 | X29: 0 | Y29: 8909457 | Z29: 2304 | AA29: 2587 | AB29: 4891 | AC29: 169515820 | AD29: 44940745 | AE29: 414356 | AF29: 10637532 | AG29: 36438244 | AH29: 17266 | AI29: 86343291 | AJ29: 348307254 | AK29: 314780866 | AL29: 22111838 | AM29: 11414550 | AN29: 348307254 | AO29: 9558144 | AP29: 610936 | AQ29: 3121994 | AR29: 2761940 | AS29: 16053014 | AT29: =+N29+O29 -> 2240375 | AU29: =+U29/V29 -> 1.710585 | AV29: =+AJ29/Y29 -> 39.094106 | AW29: =+T29/D29 -> 0 | AX29: =+V29/D29 -> 5339.8909 | AY29: =+G29/D29 -> 4975.6344 | AZ29: =SUM(G29:M29)/D29 -> 5289.2782 | BA29: =+L29/D29 -> 294.06562
A30: Switzerland | B30: EFTA | C30: C28 | D30: =+Y30/1000 -> 7320.8 | E30: 41 | F30: 2009 | G30: 28656291 | N30: 1405787 | U30: 6328307 | V30: 34171127 | W30: 306137 | X30: 225252 | Y30: 7320800 | Z30: 1841 | AA30: 3476 | AB30: 5317 | AT30: =+N30+O30 -> 1405787 | AU30: =+U30/V30 -> 0.18519456 | AV30: =+AJ30/Y30 -> 0 | AW30: =+T30/D30 -> 0 | AX30: =+V30/D30 -> 4667.6766 | AY30: =+G30/D30 -> 3914.3661 | AZ30: =SUM(G30:M30)/D30 -> 3914.3661 | BA30: =+L30/D30 -> 0
A31: UK | B31: EU | C31: C29 | D31: =+Y31/1000 -> 60296.633 | E31: 208 | F31: 4614 | G31: 115962000 | H31: 85000 | I31: 105000 | J31: 118000 | K31: 6442000 | L31: 7348000 | M31: 113867 | N31: 11019000 | O31: 1485000 | P31: 89 | R31: 23200 | S31: 13500 | T31: 33837000 | U31: 417004000 | V31: 318226000 | W31: 0 | X31: 0 | Y31: 60296633 | Z31: 6200 | AA31: 19600 | AB31: 25800 | AC31: 826620033 | AD31: 197243503 | AE31: 1597132 | AF31: 63528612 | AG31: 170044367 | AH31: 0 | AI31: 246985005 | AJ31: 1506018653 | AK31: 1334604424 | AL31: 139547913 | AM31: 31866316 | AN31: 1506018653 | AO31: 58724874 | AP31: 4906772 | AQ31: 24511194 | AR31: 6656214 | AS31: 94799054 | AT31: =+N31+O31 -> 12504000 | AU31: =+U31/V31 -> 1.310402 | AV31: =+AJ31/Y31 -> 24.976828 | AW31: =+T31/D31 -> 561.17561 | AX31: =+V31/D31 -> 5277.6745 | AY31: =+G31/D31 -> 1923.192 | AZ31: =SUM(G31:M31)/D31 -> 2158.8911 | BA31: =+L31/D31 -> 121.86418
A32: Germany | B32: EU | C32: C31 | D32: =+Y32/1000 -> 82213.913 | E32: 9062 | F32: 10932 | G32: 104358906 | I32: 139018 | L32: 10598899 | P32: 94 | T32: 8302968 | U32: 307159562 | V32: 298975665 | W32: 334807 | X32: 365413 | Y32: 82213913 | Z32: 8787 | AA32: 4387 | AB32: 13174 | AC32: 472325169 | AD32: 97497066 | AE32: 0 | AF32: 0 | AG32: 0 | AH32: 0 | AI32: 157417476 | AJ32: 727239711 | AK32: 645041124 | AL32: 56472303 | AM32: 25726284 | AN32: 727239711 | AO32: 32759294 | AP32: 2093906 | AQ32: 10700229 | AR32: 9466185 | AS32: 55019614 | AT32: =+N32+O32 -> 0 | AU32: =+U32/V32 -> 1.0273731 | AV32: =+AJ32/Y32 -> 8.8457012 | AW32: =+T32/D32 -> 100.99225 | AX32: =+V32/D32 -> 3636.558 | AY32: =+G32/D32 -> 1269.3582 | AZ32: =SUM(G32:M32)/D32 -> 1399.9677 | BA32: =+L32/D32 -> 128.91856
A33: USA | B33: World - A | C33: C50 | D33: =+Y33/1000 -> 275828.33 | E33: 9202 | F33: 16491 | G33: 749041643 | I33: 1944263 | J33: 0 | L33: 47383632 | M33: 1198051 | N33: 17331991 | O33: 3685613 | P33: 100 | S33: 18534 | U33: 1753498549 | V33: 1129238333 | W33: 1419166 | X33: 7196227 | Y33: 275828333 | Z33: 41693 | AA33: 84796 | AB33: 126489 | AC33: 4036684649 | AD33: 968301302 | AE33: 12862 | AF33: 363475 | AG33: 1707992 | AH33: 1171344 | AI33: 1279429168 | AJ33: 6287670792 | AK33: 5721780421 | AL33: 306744066 | AM33: 259146305 | AN33: 6287670792 | AT33: =+N33+O33 -> 21017604 | AU33: =+U33/V33 -> 1.5528153 | AV33: =+AJ33/Y33 -> 22.795594 | AW33: =+T33/D33 -> 0 | AX33: =+V33/D33 -> 4093.9896 | AY33: =+G33/D33 -> 2715.6081 | AZ33: =SUM(G33:M33)/D33 -> 2898.787 | BA33: =+L33/D33 -> 171.78667
A34: Turkey | B34: World - B | C34: C42 | D34: =+Y34/1000 -> 67090.173 | E34: 1434 | F34: 1982 | G34: 12476310 | I34: 131 | J34: 157015 | K34: 7118 | L34: 112952 | M34: 597 | Q34: 11 | S34: 28 | T34: 375214 | U34: 3665856 | V34: 18830433 | W34: 4443 | X34: 22528 | Y34: 67090173 | Z34: 264 | AA34: 2579 | AB34: 2843 | AC34: 16227540 | AD34: 0 | AE34: 0 | AF34: 200232 | AG34: 19840909 | AH34: 2880809 | AI34: 0 | AJ34: 39149490 | AK34: 35713148 | AL34: 1993510 | AM34: 1442832 | AN34: 39149490 | AT34: =+N34+O34 -> 0 | AU34: =+U34/V34 -> 0.1946772 | AV34: =+AJ34/Y34 -> 0.58353539 | AW34: =+T34/D34 -> 5.592682 | AX34: =+V34/D34 -> 280.67349 | AY34: =+G34/D34 -> 185.9633 | AZ34: =SUM(G34:M34)/D34 -> 190.10419 | BA34: =+L34/D34 -> 1.6835849
A35: Australia | B35: World - A | C35: C70 | D35: =+Y35/1000 -> 19261.779 | Y35: 19261779 | AT35: =+N35+O35 -> 0 | AU35: =+U35/V35 -> #DIV/0! | AV35: =+AJ35/Y35 -> 0 | AW35: =+T35/D35 -> 0 | AX35: =+V35/D35 -> 0 | AY35: =+G35/D35 -> 0 | AZ35: =SUM(G35:M35)/D35 -> 0 | BA35: =+L35/D35 -> 0
A36: Japan | B36: World - A | C36: C41 | D36: =+Y36/1000 -> 127474.33 | E36: 1716 | F36: 2680 | G36: 295816511 | N36: 19517960 | T36: 38679751 | U36: 552624145 | W36: 1000371 | X36: 5072629 | Y36: 127474333 | Z36: 11808 | AA36: 15431 | AB36: 27239 | AC36: 805959446 | AD36: 366403788 | AE36: 15656 | AF36: 870078 | AG36: 2241585 | AH36: 319311 | AI36: 135161399 | AJ36: 1310971263 | AK36: 1195900900 | AL36: 66755249 | AM36: 48315114 | AN36: 1310971263 | AT36: =+N36+O36 -> 19517960 | AU36: =+U36/V36 -> #DIV/0! | AV36: =+AJ36/Y36 -> 10.284198 | AW36: =+T36/D36 -> 303.43168 | AX36: =+V36/D36 -> 0 | AY36: =+G36/D36 -> 2320.5967 | AZ36: =SUM(G36:M36)/D36 -> 2320.5967 | BA36: =+L36/D36 -> 0
A37: Korea | B37: World - A | C37: C40 | D37: =+Y37/1000 -> 49235 | Y37: 49235000 | AT37: =+N37+O37 -> 0 | AU37: =+U37/V37 -> #DIV/0! | AV37: =+AJ37/Y37 -> 0 | AW37: =+T37/D37 -> 0 | AX37: =+V37/D37 -> 0 | AY37: =+G37/D37 -> 0 | AZ37: =SUM(G37:M37)/D37 -> 0 | BA37: =+L37/D37 -> 0
A38: Canada | B38: World - A | C38: C51 | D38: =+Y38/1000 -> 31374.667 | E38: 2739 | F38: 910 | G38: 75032608 | I38: 150814 | U38: 331565367 | Y38: 31374667 | Z38: 6733 | AA38: 6616 | AB38: 13349 | AC38: 212115444 | AD38: 45849663 | AE38: 0 | AF38: 0 | AG38: 0 | AH38: 0 | AI38: 68846851 | AJ38: 326811958 | AK38: 298126073 | AL38: 16641413 | AM38: 12044472 | AN38: 326811958 | AO38: 18361785 | AP38: 906999 | AQ38: 4634923 | AR38: 4100384 | AS38: 28004091 | AT38: =+N38+O38 -> 0 | AU38: =+U38/V38 -> #DIV/0! | AV38: =+AJ38/Y38 -> 10.416428 | AW38: =+T38/D38 -> 0 | AX38: =+V38/D38 -> 0 | AY38: =+G38/D38 -> 2391.5029 | AZ38: =SUM(G38:M38)/D38 -> 2396.3098 | BA38: =+L38/D38 -> 0
A39: New Zealand | B39: World - A | C39: C71 | D39: =+Y39/1000 -> 3931 | Y39: 3931000 | AT39: =+N39+O39 -> 0 | AU39: =+U39/V39 -> #DIV/0! | AV39: =+AJ39/Y39 -> 0 | AW39: =+T39/D39 -> 0 | AX39: =+V39/D39 -> 0 | AY39: =+G39/D39 -> 0 | AZ39: =SUM(G39:M39)/D39 -> 0 | BA39: =+L39/D39 -> 0
A40: Mexico | B40: World - B | C40: C72 | D40: =+Y40/1000 -> 98961.882 | Y40: 98961882 | AT40: =+N40+O40 -> 0 | AU40: =+U40/V40 -> #DIV/0! | AV40: =+AJ40/Y40 -> 0 | AW40: =+T40/D40 -> 0 | AX40: =+V40/D40 -> 0 | AY40: =+G40/D40 -> 0 | AZ40: =SUM(G40:M40)/D40 -> 0 | BA40: =+L40/D40 -> 0
...

Sheet 2000
A1: Name | B1: Type | C1: Code | D1: Population '000s | E1: Libraries - Total Administrative Units | F1: Libraries - Service Points | G1: Collections - Books & Bound Periodicals | H1: Collections - Current Periodicals - Titles | I1: Collections - Current Periodicals - Subscriptions | J1: Collections - Manuscripts | K1: Collections - Microforms | L1: Collections - Audio-visual Materials | M1: Collections - CD-ROMs | N1: Additions - Books & Bound Periodicals | O1: Additions - Audio-visual Materials | P1: Facilities & Services - Percentage Stock on Open Access | Q1: Facilities & Services - Percentage Catalogue Records Automated | R1: Facilities & Services - Number of Workstations for users | S1: Facilities & Services - Number connected to the internet | T1: Use & Users - Registered Users | U1: Use & Users - Loan Transactions | V1: Use & Users - Number of Visits | W1: Use & Users - Number of virtual referrals and transactions | X1: Use & Users - Number of virtual visits to networked library services | Y1: Use & Users - Potential Total Population Served | Z1: Library Staff FTE - Trained Librarians | AA1: Library Staff FTE - Other Library Staff | AB1: Library Staff FTE - Total Staff | AC1: Recurrent Expenditure (Euros) - Staff | AD1: Recurrent Expenditure (Euros) - Acquisition of Stock | AE1: Recurrent Expenditure (Euros) - Electronic Information | AF1: Recurrent Expenditure (Euros) - Automation | AG1: Recurrent Expenditure (Euros) - Premises and Related Costs | AH1: Recurrent Expenditure (Euros) - New Buildings / Refurbishment | AI1: Recurrent Expenditure (Euros) - Other Expenditure | AJ1: Recurrent Expenditure (Euros) - TOTAL EXPENDITURE | AK1: Income - Public Funding | AL1: Income - Fees & Charges | AM1: Income - Other Income | AN1: Income - TOTAL INCOME | AO1: Capital Expenditure - New Buildings / Refurbishment | AP1: Capital Expenditure - Acquisition of Stock | AQ1: Capital Expenditure - Automation | AR1: Capital Expenditure - Other Capital Expenditure | AS1: Capital Expenditure - TOTAL CAPITAL PAYMENTS | AT1: Additions | AU1: Loans per visit | AV1: Cost per pop | AW1: Users per 1000 pop | AX1: visits per 1000 pop | AY1: Bookstock per 1000 pop | AZ1: Total stock per 1000 pop | BA1: AV materials per 1000 pop
A2: Bulgaria | B2: CEE | C2: C1 | D2: =+Y2/1000 -> 8057 | E2: 3877 | F2: 3877 | G2: 49201077 | H2: 15242 | K2: 65323 | L2: 751137 | N2: 288783 | O2: 5065 | P2: 80 | T2: 899735 | U2: 18061316 | V2: 9443522 | W2: 11892 | X2: 13530 | Y2: 8057000 | Z2: 2979 | AA2: 415 | AB2: 3394 | AC2: 3949524 | AD2: 541955 | AE2: 0 | AF2: 0 | AG2: 0 | AH2: 0 | AI2: 828630 | AJ2: 5320109 | AK2: 4817791 | AL2: 367053 | AM2: 258747 | AN2: 5443591 | AT2: =+N2+O2 -> 293848 | AU2: =+U2/V2 -> 1.9125614 | AV2: =+AJ2/Y2 -> 0.66030892 | AW2: =+T2/D2 -> 111.67122 | AX2: =+V2/D2 -> 1172.0891 | AY2: =+G2/D2 -> 6106.6249 | AZ2: =SUM(G2:M2)/D2 -> 6209.8522 | BA2: =+L2/D2 -> 93.227876
A3: Czech Republic | B3: CEE | C3: C2 | D3: =+Y3/1000 -> 10242 | E3: 6018 | F3: 7140 | G3: 54351497 | H3: 78444 | I3: 89007 | J3: 3951 | K3: 91486 | L3: 592012 | M3: 16898 | N3: 1582143 | O3: 21063 | P3: 75 | Q3: 43 | R3: 1925 | S3: 1083 | T3: 1473800 | U3: 69804524 | V3: 16040601 | W3: 72277 | X3: 50671 | Y3: 10242000 | Z3: 3753 | AA3: 575 | AB3: 4328 | AC3: 17039993 | AD3: 4918543 | AE3: 10396 | AF3: 341645 | AG3: 1269677 | AH3: 362724 | AI3: 20340771 | AJ3: 44283749 | AK3: 42283749 | AL3: 1310907 | AM3: 1434618 | AN3: 45029274 | AO3: 2077990 | AP3: 0 | AQ3: 0 | AR3: 15637419 | AS3: 17715410 | AT3: =+N3+O3 -> 1603206 | AU3: =+U3/V3 -> 4.3517399 | AV3: =+AJ3/Y3 -> 4.3237404 | AW3: =+T3/D3 -> 143.89768 | AX3: =+V3/D3 -> 1566.1591 | AY3: =+G3/D3 -> 5306.7269 | AZ3: =SUM(G3:M3)/D3 -> 5391.8468 | BA3: =+L3/D3 -> 57.802382
A4: Estonia | B4: CEE | C4: C3 | D4: =+Y4/1000 -> 1439.197 | E4: 585 | F4: 711 | G4: 10851579 | H4: 10600 | I4: 18901 | J4: 85 | K4: 1600 | L4: 51600 | M4: 712 | N4: 542106 | O4: 4251 | P4: 72 | Q4: 0 | R4: 362 | S4: 310 | T4: 449495 | U4: 14011606 | V4: 6309760 | Y4: 1439197 | Z4: 1204 | AA4: 278 | AB4: 1482 | AC4: 4466601 | AD4: 3264051 | AE4: 0 | AF4: 440253 | AG4: 0 | AH4: 0 | AI4: 2002671 | AJ4: 10173576 | AK4: 11885650 | AL4: 0 | AM4: 191705 | AN4: 12077356 | AO4: 1529412 | AP4: 0 | AQ4: 263706 | AR4: 85209 | AS4: 1878327 | AT4: =+N4+O4 -> 546357 | AU4: =+U4/V4 -> 2.2206242 | AV4: =+AJ4/Y4 -> 7.0689252 | AW4: =+T4/D4 -> 312.32347 | AX4: =+V4/D4 -> 4384.2226 | AY4: =+G4/D4 -> 7540.0234 | AZ4: =SUM(G4:M4)/D4 -> 7598.0404 | BA4: =+L4/D4 -> 35.853327
A5: Hungary | B5: CEE | C5: C4 | D5: =+Y5/1000 -> 10047 | E5: 2573 | F5: 3132 | G5: 41380150 | H5: 42911 | L5: 1382491 | M5: 44468 | N5: 1069733 | O5: 57400 | T5: 1357449 | U5: 12554527 | V5: 16560559 | W5: 15908 | X5: 45462 | Y5: 10047000 | Z5: 3566 | AA5: 2166 | AB5: 5732 | AC5: 19708549 | AD5: 4628186 | AE5: 0 | AF5: 0 | AG5: 0 | AH5: 0 | AI5: 16659271 | AJ5: 40996006 | AK5: 28084798 | AL5: 0 | AM5: 12911208 | AN5: 40996006 | AT5: =+N5+O5 -> 1127133 | AU5: =+U5/V5 -> 0.75809802 | AV5: =+AJ5/Y5 -> 4.0804226 | AW5: =+T5/D5 -> 135.10988 | AX5: =+V5/D5 -> 1648.3088 | AY5: =+G5/D5 -> 4118.6573 | AZ5: =SUM(G5:M5)/D5 -> 4264.9567 | BA5: =+L5/D5 -> 137.60237
A6: Latvia | B6: CEE | C6: C5 | D6: =+Y6/1000 -> 2384 | E6: 932 | F6: 932 | G6: 12343319 | K6: 933 | L6: 167233 | N6: 293900 | O6: 18600 | T6: 531801 | U6: 20279759 | V6: 6167307 | W6: 0 | X6: 0 | Y6: 2384000 | Z6: 1872 | AA6: 620 | AB6: 2492 | AC6: 5340990 | AD6: 1277610 | AE6: 0 | AF6: 0 | AG6: 0 | AH6: 0 | AI6: 2811237 | AJ6: 9429837 | AK6: 8694303 | AL6: 23142 | AM6: 11946 | AN6: 8729391 | AO6: 0 | AP6: 0 | AQ6: 0 | AR6: 0 | AS6: 0 | AT6: =+N6+O6 -> 312500 | AU6: =+U6/V6 -> 3.2882681 | AV6: =+AJ6/Y6 -> 3.9554685 | AW6: =+T6/D6 -> 223.07089 | AX6: =+V6/D6 -> 2586.9576 | AY6: =+G6/D6 -> 5177.5667 | AZ6: =SUM(G6:M6)/D6 -> 5248.1061 | BA6: =+L6/D6 -> 70.14807
A7: Lithuania | B7: CEE | C7: C6 | D7: =+Y7/1000 -> 3661.14 | E7: 66 | F7: 1453 | G7: 22432006 | J7: 8557 | K7: 1102 | L7: 249805 | M7: 1113 | N7: 1011820 | O7: 3918 | P7: 96 | R7: 93 | S7: 36 | T7: 839499 | U7: 24637643 | V7: 9377600 | W7: 9341 | X7: 3433 | Y7: 3661140 | Z7: 3167 | AA7: 925 | AB7: 4092 | AC7: 9016424 | AD7: 1694692 | AE7: 52993 | AF7: 110946 | AG7: 394814 | AH7: 0 | AI7: 4252728 | AJ7: 15522597 | AK7: 14976990 | AL7: 421765 | AM7: 231840 | AN7: 15630594 | AT7: =+N7+O7 -> 1015738 | AU7: =+U7/V7 -> 2.6272866 | AV7: =+AJ7/Y7 -> 4.2398261 | AW7: =+T7/D7 -> 229.29989 | AX7: =+V7/D7 -> 2561.388 | AY7: =+G7/D7 -> 6127.055 | AZ7: =SUM(G7:M7)/D7 -> 6198.2287 | BA7: =+L7/D7 -> 68.23148
A8: Poland | B8: CEE | C8: C7 | D8: =+Y8/1000 -> 38654 | E8: 9227 | F8: 3564 | G8: 135829107 | K8: 10380 | L8: 2596307 | N8: 3793047 | O8: 121173 | T8: 7220254 | U8: 188976647 | W8: 105819 | X8: 120410 | Y8: 38654000 | Z8: 11134 | AA8: 6689 | AB8: 17823 | AT8: =+N8+O8 -> 3914220 | AU8: =+U8/V8 -> #DIV/0! | AV8: =+AJ8/Y8 -> 0 | AW8: =+T8/D8 -> 186.7919 | AX8: =+V8/D8 -> 0 | AY8: =+G8/D8 -> 3513.9729 | AZ8: =SUM(G8:M8)/D8 -> 3581.4093 | BA8: =+L8/D8 -> 67.167874
A9: Romania | B9: CEE | C9: C8 | D9: =+Y9/1000 -> 22334 | E9: 2849 | F9: 3174 | G9: 48364343 | H9: 8945 | I9: 10293 | J9: 68044 | K9: 9458 | L9: 300166 | M9: 2700 | N9: 977144 | O9: 7235 | P9: 68 | Q9: 8 | R9: 189 | S9: 59 | T9: 2057844 | U9: 35740786 | V9: 16421942 | W9: 3685 | X9: 4327 | Y9: 22334000 | Z9: 4346 | AA9: 774 | AB9: 5119 | AC9: 8146179 | AD9: 1161824 | AE9: 2524 | AF9: 39200 | AG9: 84927 | AH9: 14409 | AI9: 1733064 | AJ9: 11182127 | AK9: 10846663 | AL9: 111822 | AM9: 223642 | AN9: 11182127 | AO9: 785260 | AP9: 50193 | AQ9: 256491 | AR9: 226910 | AS9: 1318854 | AT9: =+N9+O9 -> 984379 | AU9: =+U9/V9 -> 2.1764043 | AV9: =+AJ9/Y9 -> 0.50067731 | AW9: =+T9/D9 -> 92.139518 | AX9: =+V9/D9 -> 735.28889 | AY9: =+G9/D9 -> 2165.503 | AZ9: =SUM(G9:M9)/D9 -> 2183.3952 | BA9: =+L9/D9 -> 13.439867
A10: Slovak Rep | B10: CEE | C10: C9 | D10: =+Y10/1000 -> 5396.15 | E10: 2657 | F10: 2916 | G10: 18695936 | H10: 9786 | I10: 11802 | J10: 631 | K10: 100 | L10: 252656 | M10: 1406 | N10: 345367 | O10: 2280 | P10: 93 | Q10: 26 | R10: 113 | S10: 100 | T10: 697006 | U10: 25017852 | V10: 7172297 | W10: 4273 | X10: 8571 | Y10: 5396150 | Z10: 1025 | AA10: 776 | AB10: 1801 | AC10: 3764903 | AD10: 799238 | AE10: 0 | AF10: 0 | AG10: 0 | AH10: 0 | AI10: 3191927 | AJ10: 7756068 | AK10: 6431570 | AL10: 623036 | AM10: 952076 | AN10: 8006682 | AO10: 349290 | AP10: 0 | AQ10: 151034 | AR10: 92687 | AS10: 593011 | AT10: =+N10+O10 -> 347647 | AU10: =+U10/V10 -> 3.4881227 | AV10: =+AJ10/Y10 -> 1.4373337 | AW10: =+T10/D10 -> 129.16728 | AX10: =+V10/D10 -> 1329.1508 | AY10: =+G10/D10 -> 3464.6806 | AZ10: =SUM(G10:M10)/D10 -> 3515.8987 | BA10: =+L10/D10 -> 46.82153
A11: Slovenia | B11: CEE | C11: C10 | D11: =+Y11/1000 -> 1990.094 | E11: 60 | F11: 283 | G11: 6983185 | H11: 11943 | I11: 19173 | J11: 13461 | K11: 609 | L11: 224973 | M11: 9478 | N11: 388991 | O11: 30369 | P11: 87 | Q11: 77 | R11: 528 | S11: 272 | T11: 491626 | U11: 19351425 | V11: 7423159 | W11: 0 | X11: 0 | Y11: 1990094 | Z11: 643 | AA11: 216 | AB11: 859 | AC11: 11998743 | AD11: 5749316 | AE11: 4843 | AF11: 159164 | AG11: 591511 | AH11: 13585 | AI11: 5214658 | AJ11: 23731821 | AK11: 21119629 | AL11: 2007707 | AM11: 1566564 | AN11: 24693900 | AO11: 2269544 | AP11: 145065 | AQ11: 741305 | AR11: 655812 | AS11: 3811726 | AT11: =+N11+O11 -> 419360 | AU11: =+U11/V11 -> 2.6068989 | AV11: =+AJ11/Y11 -> 11.924975 | AW11: =+T11/D11 -> 247.03657 | AX11: =+V11/D11 -> 3730.0545 | AY11: =+G11/D11 -> 3508.9724 | AZ11: =SUM(G11:M11)/D11 -> 3649.4869 | BA11: =+L11/D11 -> 113.04642
A12: Austria | B12: EU | C12: C11 | D12: =+Y12/1000 -> 8110.244 | E12: 991 | F12: 1873 | G12: 9351946 | P12: 100 | Q12: 61 | R12: 1452 | S12: 1452 | T12: 868648 | U12: 14638735 | V12: 6305411 | W12: 19946 | X12: 21906 | Y12: 8110244 | Z12: 728 | AA12: 580 | AB12: 1308 | AC12: 30251901 | AD12: 5107475 | AE12: 19952 | AF12: 703294 | AG12: 2640554 | AH12: 37381 | AI12: 7639096 | AJ12: 46399652 | AK12: 39527461 | AL12: 2776614 | AM12: 1433341 | AN12: 43737415 | AT12: =+N12+O12 -> 0 | AU12: =+U12/V12 -> 2.3216147 | AV12: =+AJ12/Y12 -> 5.7211167 | AW12: =+T12/D12 -> 107.10504 | AX12: =+V12/D12 -> 777.46255 | AY12: =+G12/D12 -> 1153.1029 | AZ12: =SUM(G12:M12)/D12 -> 1153.1029 | BA12: =+L12/D12 -> 0
A13: België Vlaamse Gemeenschap | B13: België Vlaamse Gemeenschap | C13: C12a | D13: =+Y13/1000 -> 6232.321 | E13: 320 | F13: 903 | G13: 21241805 | I13: 43443 | L13: 2051533 | M13: 94315 | N13: 1378323 | O13: 258468 | Q13: 98 | T13: 1658175 | U13: 52166885 | Y13: 6232321 | Z13: 1521 | AA13: 913 | AB13: 2434 | AC13: 88345956 | AD13: 16885140 | AE13: 3806378 | AF13: 0 | AG13: 0 | AH13: 27069661 | AI13: 20903469 | AJ13: 157010604 | AK13: 54557803 | AL13: 8627125 | AM13: 914522 | AN13: 64099451 | AV13: =+AJ13/Y13 -> 25.192958 | AW13: =+T13/D13 -> 266.06059 | AY13: =+G13/D13 -> 3408.3297 | AZ13: =SUM(G13:M13)/D13 -> 3759.6099
A14: Belgique-Communauté française | B14: Belgique-Communauté française | C14: C12b | D14: =+Y14/1000 -> 3987.679 | E14: 175 | F14: 572 | G14: 12243069 | I14: 96659 | L14: 91161 | M14: 8332 | T14: 756992 | Y14: 3987679 | AW14: =+T14/D14 -> 189.83273 | AY14: =+G14/D14 -> 3070.2243 | AZ14: =SUM(G14:M14)/D14 -> 3119.4138
A15: Belgium | B15: EU | C15: C12 | D15: =+Y15/1000 -> 10220 | E15: 495 | F15: 1475 | G15: 33484874 | I15: 140102 | L15: 2142694 | M15: 102647 | N15: 1602000 | O15: 211166 | Q15: 98 | T15: 2415167 | W15: 41168 | X15: 34834 | Y15: 10220000 | Z15: 2463 | AA15: 1297 | AB15: 3760 | AC15: 126001459 | AD15: 28159370 | AE15: 151105 | AF15: 3879229 | AG15: 13288071 | AH15: 6297 | AI15: 29699376 | AJ15: 201184906 | AK15: 194264948 | AL15: 8093499 | AM15: 5625211 | AN15: 207983658 | AT15: =+N15+O15 -> 1813166 | AU15: =+U15/V15 -> #DIV/0! | AV15: =+AJ15/Y15 -> 19.685412 | AW15: =+T15/D15 -> 236.31771 | AX15: =+V15/D15 -> 0 | AY15: =+G15/D15 -> 3276.4065 | AZ15: =SUM(G15:M15)/D15 -> 3509.8158 | BA15: =+L15/D15 -> 209.65695
A16: Denmark | B16: EU | C16: C13 | D16: =+Y16/1000 -> 5349.11 | E16: 245 | F16: 800 | G16: 27634549 | H16: 1688 | I16: 205550 | K16: 369 | L16: 2756369 | M16: 98401 | N16: 1660108 | O16: 297177 | R16: 3343 | S16: 2218 | T16: 1845698 | U16: 72464549 | V16: 30533524 | W16: 7280437 | X16: 11211602 | Y16: 5349110 | Z16: 2283 | AA16: 2787 | AB16: 5070 | AC16: 194778050 | AD16: 48800761 | AE16: 9585 | AF16: 535168 | AG16: 1236422 | AH16: 0 | AI16: 87186903 | AJ16: 332546890 | AK16: 293737414 | AL16: 26651389 | AM16: 12141194 | AN16: 332529998 | AO16: 0 | AP16: 0 | AQ16: 0 | AR16: 0 | AS16: 0 | AT16: =+N16+O16 -> 1957285 | AU16: =+U16/V16 -> 2.3732783 | AV16: =+AJ16/Y16 -> 62.168639 | AW16: =+T16/D16 -> 345.04768 | AX16: =+V16/D16 -> 5708.1503 | AY16: =+G16/D16 -> 5166.1957 | AZ16: =SUM(G16:M16)/D16 -> 5738.6978 | BA16: =+L16/D16 -> 515.29488
A17: Eire | B17: EU | C17: C15 | D17: =+Y17/1000 -> 3720 | E17: 32 | F17: 357 | G17: 11270238 | H17: 12426 | I17: 2204 | J17: 12481 | K17: 19840 | L17: 327891 | M17: 3202 | N17: 909438 | O17: 34111 | P17: 89 | Q17: 70 | R17: 1084 | S17: 668 | T17: 894606 | U17: 12268767 | V17: 20082704 | W17: 1820 | X17: 4606 | Y17: 3720000 | Z17: 291 | AA17: 1092 | AB17: 1383 | AC17: 32435319 | AD17: 9215175 | AE17: 0 | AF17: 1523093 | AG17: 7859332 | AH17: 0 | AI17: 6404022 | AJ17: 57436941 | AK17: 50565429 | AL17: 1480618 | AM17: 5797751 | AN17: 57843799 | AO17: 3120637 | AP17: 3652805 | AQ17: 1642007 | AR17: 1106164 | AS17: 9521614 | AT17: =+N17+O17 -> 943549 | AU17: =+U17/V17 -> 0.61091211 | AV17: =+AJ17/Y17 -> 15.440038 | AW17: =+T17/D17 -> 240.48548 | AX17: =+V17/D17 -> 5398.5763 | AY17: =+G17/D17 -> 3029.6339 | AZ17: =SUM(G17:M17)/D17 -> 3131.2586 | BA17: =+L17/D17 -> 88.142742
A18: Finland | B18: EU | C18: C16 | D18: =+Y18/1000 -> 5145.596 | E18: 436 | F18: 1138 | G18: 37013045 | I18: 97600 | L18: 3884200 | M18: 22219 | N18: 1606835 | O18: 309996 | P18: 99 | Q18: 99 | R18: 2500 | S18: 1256 | T18: 2417055 | U18: 102197190 | V18: 63990752 | W18: 184680 | X18: 192684 | Y18: 5145596 | Z18: 1500 | AA18: 2674 | AB18: 4174 | AC18: 130057045 | AD18: 40789913 | AE18: 0 | AF18: 0 | AG18: 0 | AH18: 0 | AI18: 60983022 | AJ18: 231829980 | AK18: 213163872 | AL18: 4399221 | AM18: 14266888 | AN18: 231829980 | AO18: 18378394 | AP18: 1174709 | AQ18: 6002968 | AR18: 5310654 | AS18: 30866725 | AT18: =+N18+O18 -> 1916831 | AU18: =+U18/V18 -> 1.5970619 | AV18: =+AJ18/Y18 -> 45.054058 | AW18: =+T18/D18 -> 469.73276 | AX18: =+V18/D18 -> 12436.023 | AY18: =+G18/D18 -> 7193.1502 | AZ18: =SUM(G18:M18)/D18 -> 7971.2951 | BA18: =+L18/D18 -> 754.85911
A19: France | B19: EU | C19: C17 | D19: =+Y19/1000 -> 59400 | E19: 3881 | F19: 3884 | G19: 144456108 | I19: 223647 | L19: 9670922 | M19: 216654 | N19: 6827452 | O19: 942839 | P19: 82 | T19: 12025650 | U19: 302627916 | W19: 18621 | X19: 21328 | Y19: 59400000 | Z19: 7031 | AA19: 14498 | AB19: 21529 | AC19: 646073217 | AD19: 117360248 | AE19: 613120 | AF19: 15740293 | AG19: 53917450 | AH19: 25549 | AI19: 161083516 | AJ19: 994813393 | AK19: 899963958 | AL19: 23852331 | AM19: 5493134 | AN19: 929309423 | AO19: 186846019 | AP19: 7611358 | AQ19: 38895372 | AR19: 34409621 | AS19: 267762370 | AT19: =+N19+O19 -> 7770291 | AU19: =+U19/V19 -> #DIV/0! | AV19: =+AJ19/Y19 -> 16.7477 | AW19: =+T19/D19 -> 202.45202 | AX19: =+V19/D19 -> 0 | AY19: =+G19/D19 -> 2431.921 | AZ19: =SUM(G19:M19)/D19 -> 2602.1436 | BA19: =+L19/D19 -> 162.81013
A20: Greece | B20: EU | C20: C18 | D20: =+Y20/1000 -> 10586 | E20: 718 | F20: 829 | G20: 9702367 | H20: 161033 | I20: 125025 | J20: 1509096 | K20: 317503 | L20: 102507 | M20: 12623 | N20: 296284 | O20: 12264 | P20: 89 | Q20: 70 | R20: 4032 | S20: 2025 | T20: 2875762 | U20: 1952957 | V20: 2440868 | W20: 8727 | X20: 12210 | Y20: 10586000 | Z20: 1029 | AA20: 805 | AB20: 1834 | AC20: 40693056 | AD20: 9094266 | AE20: 48800 | AF20: 1252824 | AG20: 4291476 | AH20: 2034 | AI20: 12821192 | AJ20: 68203648 | AT20: =+N20+O20 -> 308548 | AU20: =+U20/V20 -> 0.80010758 | AV20: =+AJ20/Y20 -> 6.4428158 | AW20: =+T20/D20 -> 271.65709 | AX20: =+V20/D20 -> 230.5751 | AY20: =+G20/D20 -> 916.52815 | AZ20: =SUM(G20:M20)/D20 -> 1126.9747 | BA20: =+L20/D20 -> 9.6832609
A21: Iceland | B21: EFTA | C21: C19 | D21: =+Y21/1000 -> 279 | E21: 137 | F21: 143 | G21: 2065660 | I21: 2087 | J21: 759 | K21: 3178 | L21: 67321 | M21: 743 | N21: 75879 | O21: 4640 | T21: 86073 | U21: 2224533 | V21: 859249 | W21: 867 | X21: 1852 | Y21: 279000 | Z21: 80 | AA21: 207 | AB21: 299 | AC21: 4582198 | AD21: 1589323 | AE21: 0 | AF21: 90603 | AG21: 645061 | AH21: 216354 | AI21: 1196842 | AJ21: 8320381 | AK21: 7589487 | AL21: 593092 | AM21: 152676 | AN21: 8335255 | AT21: =+N21+O21 -> 80519 | AU21: =+U21/V21 -> 2.5889271 | AV21: =+AJ21/Y21 -> 29.822154 | AW21: =+T21/D21 -> 308.50538 | AX21: =+V21/D21 -> 3079.7455 | AY21: =+G21/D21 -> 7403.7993 | AZ21: =SUM(G21:M21)/D21 -> 7669.3477 | BA21: =+L21/D21 -> 241.29391
A22: Italy | B22: EU | C22: C20 | D22: =+Y22/1000 -> 57535 | E22: 84 | F22: 6028 | G22: 42029422 | N22: 5558455 | W22: 450786 | X22: 495070 | Y22: 57535000 | Z22: 5984 | AA22: 17856 | AB22: 23840 | AT22: =+N22+O22 -> 5558455 | AU22: =+U22/V22 -> #DIV/0! | AV22: =+AJ22/Y22 -> 0 | AW22: =+T22/D22 -> 0 | AX22: =+V22/D22 -> 0 | AY22: =+G22/D22 -> 730.50182 | AZ22: =SUM(G22:M22)/D22 -> 730.50182 | BA22: =+L22/D22 -> 0
A23: Liechtenstein | B23: EFTA | C23: C21 | D23: =+Y23/1000 -> 32.528 | E23: 3 | F23: 3 | G23: 24441 | N23: 5865 | S23: 4 | U23: 78920 | W23: 1344 | X23: 994 | Y23: 32528 | Z23: 2 | AA23: 3 | AB23: 5 | AT23: =+N23+O23 -> 5865 | AU23: =+U23/V23 -> #DIV/0! | AV23: =+AJ23/Y23 -> 0 | AW23: =+T23/D23 -> 0 | AX23: =+V23/D23 -> 0 | AY23: =+G23/D23 -> 751.38342 | AZ23: =SUM(G23:M23)/D23 -> 751.38342 | BA23: =+L23/D23 -> 0
A24: Luxembourg | B24: EU | C24: C22 | D24: =+Y24/1000 -> 436 | E24: 9 | F24: 13 | G24: 253876 | H24: 244 | I24: 372 | J24: 0 | K24: 0 | L24: 1179 | M24: 296 | N24: 67838 | O24: 179 | P24: 90 | Q24: 43 | R24: 75 | S24: 16 | T24: 30356 | U24: 153385 | V24: 75204 | W24: 2089 | X24: 3687 | Y24: 436000 | Z24: 18 | AA24: 5 | AB24: 23 | AC24: 1073730 | AD24: 247339 | AE24: 401 | AF24: 20 | AG24: 37341 | AH24: 40152 | AI24: 31693 | AJ24: 1430676 | AO24: 8543 | AP24: 435 | AQ24: 2209 | AR24: 1715 | AS24: 12902 | AT24: =+N24+O24 -> 68017 | AU24: =+U24/V24 -> 2.0395857 | AV24: =+AJ24/Y24 -> 3.281367 | AW24: =+T24/D24 -> 69.623853 | AX24: =+V24/D24 -> 172.48624 | AY24: =+G24/D24 -> 582.2844 | AZ24: =SUM(G24:M24)/D24 -> 587.08028 | BA24: =+L24/D24 -> 2.7041284
A25: Netherlands | B25: EU | C25: C23 | D25: =+Y25/1000 -> 15840 | E25: 492 | F25: 1074 | G25: 42161911 | N25: 3515165 | U25: 149530000 | W25: 121053 | X25: 132945 | Y25: 15840000 | Z25: 2510 | AA25: 5898 | AB25: 8408 | AC25: 269200000 | AD25: 53532129 | AE25: 286909 | AF25: 35312000 | AG25: 69186000 | AH25: 12930 | AI25: 70686032 | AJ25: 498216000 | AK25: 331069000 | AL25: 61631000 | AM25: 105516000 | AN25: 498216000 | AT25: =+N25+O25 -> 3515165 | AU25: =+U25/V25 -> #DIV/0! | AV25: =+AJ25/Y25 -> 31.45303 | AW25: =+T25/D25 -> 0 | AX25: =+V25/D25 -> 0 | AY25: =+G25/D25 -> 2661.7368 | AZ25: =SUM(G25:M25)/D25 -> 2661.7368 | BA25: =+L25/D25 -> 0
A26: Norway | B26: EFTA | C26: C24 | D26: =+Y26/1000 -> 4503.436 | E26: 435 | F26: 1046 | G26: 20916571 | H26: 20978 | I26: 44805 | J26: 36735 | K26: 293423 | L26: 1244109 | M26: 12719 | N26: 946657 | O26: 132325 | P26: 82 | Q26: 76 | R26: 1477 | S26: 1072 | T26: 1314521 | U26: 23452990 | V26: 22084283 | W26: 113594 | X26: 142746 | Y26: 4503436 | Z26: 934 | AA26: 962 | AB26: 1896 | AC26: 71043116 | AD26: 16564858 | AE26: 0 | AF26: 3147538 | AG26: 9742878 | AH26: 0 | AI26: 11664659 | AJ26: 112163049 | AK26: 102127650 | AL26: 7980921 | AM26: 2054478 | AN26: 112163049 | AT26: =+N26+O26 -> 1078982 | AU26: =+U26/V26 -> 1.0619765 | AV26: =+AJ26/Y26 -> 24.906105 | AW26: =+T26/D26 -> 291.8929 | AX26: =+V26/D26 -> 4903.8741 | AY26: =+G26/D26 -> 4644.5805 | AZ26: =SUM(G26:M26)/D26 -> 5011.5823 | BA26: =+L26/D26 -> 276.25773
A27: Portugal | B27: EU | C27: C25 | D27: =+Y27/1000 -> 9901 | E27: 165 | F27: 278 | G27: 7182218 | K27: 2198 | L27: 184420 | N27: 513084 | O27: 31016 | R27: 643 | T27: 3150844 | U27: 1637369 | W27: 626 | X27: 2 | Y27: 9901000 | Z27: 844 | AA27: 565 | AB27: 1409 | AC27: 13020660 | AD27: 2730447 | AE27: 27 | AF27: 727 | AG27: 3419 | AH27: 2345 | AI27: 2561252 | AJ27: 18318877 | AK27: 25321556 | AL27: 342212 | AM27: 1887 | AN27: 25665652 | AO27: 4012345 | AP27: 0 | AQ27: 0 | AR27: 3057918 | AS27: 7070264 | AT27: =+N27+O27 -> 544100 | AU27: =+U27/V27 -> #DIV/0! | AV27: =+AJ27/Y27 -> 1.8502047 | AW27: =+T27/D27 -> 318.23493 | AX27: =+V27/D27 -> 0 | AY27: =+G27/D27 -> 725.40329 | AZ27: =SUM(G27:M27)/D27 -> 744.25169 | BA27: =+L27/D27 -> 18.626401
A28: Spain | B28: EU | C28: C26 | D28: =+Y28/1000 -> 39218 | E28: 4722 | F28: 5209 | G28: 41291671 | H28: 113759 | I28: 158516 | J28: 33445 | K28: 266645 | L28: 1432434 | M28: 121228 | N28: 2330100 | O28: 181377 | P28: 89 | Q28: 70 | R28: 3255 | S28: 803 | T28: 7172882 | U28: 26146158 | V28: 204131947 | W28: 125104 | X28: 5128 | Y28: 39218000 | Z28: 4139 | AA28: 2469 | AB28: 6608 | AC28: 121041037 | AD28: 27939755 | AE28: 0 | AF28: 0 | AG28: 0 | AH28: 0 | AI28: 24216136 | AJ28: 173196928 | AK28: 156522058 | AL28: 10994920 | AM28: 5675786 | AN28: 173192764 | AT28: =+N28+O28 -> 2511477 | AU28: =+U28/V28 -> 0.1280846 | AV28: =+AJ28/Y28 -> 4.4162611 | AW28: =+T28/D28 -> 182.8977 | AX28: =+V28/D28 -> 5205.0576 | AY28: =+G28/D28 -> 1052.8755 | AZ28: =SUM(G28:M28)/D28 -> 1107.086 | BA28: =+L28/D28 -> 36.524912
A29: Sweden | B29: EU | C29: C27 | D29: =+Y29/1000 -> 8894 | E29: 290 | F29: 1596 | G29: 44162401 | H29: 68255 | I29: 106262 | J29: 0 | K29: 0 | L29: 2574724 | M29: 0 | N29: 2005404 | O29: 182627 | P29: 87 | U29: 81156238 | V29: 47681646 | W29: 0 | X29: 0 | Y29: 8894000 | Z29: 2304 | AA29: 2587 | AB29: 4891 | AC29: 167033680 | AD29: 44282699 | AE29: 408289 | AF29: 10481772 | AG29: 35904696 | AH29: 17013 | AI29: 85079007 | AJ29: 343207156 | AK29: 310171679 | AL29: 21788065 | AM29: 11247412 | AN29: 343207156 | AO29: 8537937 | AP29: 545727 | AQ29: 2788762 | AR29: 2467138 | AS29: 14339565 | AT29: =+N29+O29 -> 2188031 | AU29: =+U29/V29 -> 1.7020435 | AV29: =+AJ29/Y29 -> 38.588617 | AW29: =+T29/D29 -> 0 | AX29: =+V29/D29 -> 5361.1025 | AY29: =+G29/D29 -> 4965.415 | AZ29: =SUM(G29:M29)/D29 -> 5274.5269 | BA29: =+L29/D29 -> 289.48999
A30: Switzerland | B30: EFTA | C30: C28 | D30: =+Y30/1000 -> 7206.1 | E30: 42 | F30: 2093 | G30: 28484968 | N30: 1354590 | U30: 6225230 | V30: 33229533 | W30: 301573 | X30: 223277 | Y30: 7206100 | Z30: 1841 | AA30: 3476 | AB30: 5317 | AT30: =+N30+O30 -> 1354590 | AU30: =+U30/V30 -> 0.18734028 | AV30: =+AJ30/Y30 -> 0 | AW30: =+T30/D30 -> 0 | AX30: =+V30/D30 -> 4611.3061 | AY30: =+G30/D30 -> 3952.8966 | AZ30: =SUM(G30:M30)/D30 -> 3952.8966 | BA30: =+L30/D30 -> 0
A31: UK | B31: EU | C31: C29 | D31: =+Y31/1000 -> 59974.2 | E31: 208 | F31: 4610 | G31: 118745000 | H31: 73000 | I31: 109000 | J31: 136000 | K31: 6752000 | L31: 7416000 | M31: 141000 | N31: 11042000 | O31: 1384000 | P31: 89 | R31: 16700 | S31: 8600 | T31: 34657000 | U31: 444548000 | V31: 323932000 | W31: 0 | X31: 0 | Y31: 59974200 | Z31: 6200 | AA31: 19400 | AB31: 25600 | AC31: 789825619 | AD31: 197912321 | AE31: 1597132 | AF31: 48678292 | AG31: 157878096 | AH31: 0 | AI31: 235752934 | AJ31: 1431644394 | AK31: 1293943937 | AL31: 84639831 | AM31: 36955671 | AN31: 1415539439 | AO31: 36000311 | AP31: 3008015 | AQ31: 15026181 | AR31: 4080482 | AS31: 58114989 | AT31: =+N31+O31 -> 12426000 | AU31: =+U31/V31 -> 1.3723498 | AV31: =+AJ31/Y31 -> 23.871004 | AW31: =+T31/D31 -> 577.86515 | AX31: =+V31/D31 -> 5401.1892 | AY31: =+G31/D31 -> 1979.9347 | AZ31: =SUM(G31:M31)/D31 -> 2223.8229 | BA31: =+L31/D31 -> 123.65317
A32: Germany | B32: EU | C32: C31 | D32: =+Y32/1000 -> 82163.475 | E32: 9417 | F32: 11332 | G32: 107772013 | I32: 139192 | L32: 9485250 | P32: 94 | T32: 8708712 | U32: 311619520 | V32: 332934647 | W32: 363080 | X32: 398746 | Y32: 82163475 | Z32: 8337 | AA32: 6661 | AB32: 14998 | AC32: 477535730 | AD32: 91699007 | AE32: 0 | AF32: 0 | AG32: 0 | AH32: 0 | AI32: 153311306 | AJ32: 722546043 | AK32: 639349381 | AL32: 57157968 | AM32: 26038642 | AN32: 722545992 | AO32: 25714289 | AP32: 1643604 | AQ32: 8399106 | AR32: 7430448 | AS32: 43187447 | AT32: =+N32+O32 -> 0 | AU32: =+U32/V32 -> 0.93597804 | AV32: =+AJ32/Y32 -> 8.7940054 | AW32: =+T32/D32 -> 105.9925 | AX32: =+V32/D32 -> 4052.1004 | AY32: =+G32/D32 -> 1311.6779 | AZ32: =SUM(G32:M32)/D32 -> 1428.8156 | BA32: =+L32/D32 -> 115.44363
A33: USA | B33: World - A | C33: C50 | D33: =+Y33/1000 -> 272861 | E33: 9143 | F33: 16391 | G33: 740318283 | I33: 1937947 | J33: 0 | L33: 45985974 | M33: 1148788 | N33: 16072993 | O33: 3647960 | P33: 100 | S33: 15521 | U33: 1737674662 | V33: 1111372500 | W33: 1403899 | X33: 7118811 | Y33: 272861000 | Z33: 41220 | AA33: 83834 | AB33: 125054 | AC33: 3856553363 | AD33: 925092240 | AE33: 12288 | AF33: 347255 | AG33: 1631775 | AH33: 1119074 | AI33: 1222336470 | AJ33: 6007092465 | AK33: 5946742797 | AL33: 318804276 | AM33: 269335122 | AN33: 6534882194 | AT33: =+N33+O33 -> 19720953 | AU33: =+U33/V33 -> 1.5635394 | AV33: =+AJ33/Y33 -> 22.015211 | AW33: =+T33/D33 -> 0 | AX33: =+V33/D33 -> 4073.0354 | AY33: =+G33/D33 -> 2713.17 | AZ33: =SUM(G33:M33)/D33 -> 2893.0151 | BA33: =+L33/D33 -> 168.5326
A34: Turkey | B34: World - B | C34: C42 | D34: =+Y34/1000 -> 66565 | E34: 1403 | F34: 1939 | G34: 12181330 | I34: 118 | J34: 158197 | K34: 6783 | L34: 110204 | M34: 540 | Q34: 11 | S34: 23 | T34: 386790 | U34: 3926314 | V34: 19903256 | W34: 8937 | X34: 45317 | Y34: 66565000 | Z34: 271 | AA34: 2652 | AB34: 2923 | AC34: 14548749 | AD34: 0 | AE34: 0 | AF34: 179517 | AG34: 17788303 | AH34: 2582780 | AI34: 0 | AJ34: 35099349 | AK34: 31638500 | AL34: 1766063 | AM34: 1278214 | AN34: 34682777 | AT34: =+N34+O34 -> 0 | AU34: =+U34/V34 -> 0.19726993 | AV34: =+AJ34/Y34 -> 0.52729436 | AW34: =+T34/D34 -> 5.8107113 | AX34: =+V34/D34 -> 299.00482 | AY34: =+G34/D34 -> 182.99902 | AZ34: =SUM(G34:M34)/D34 -> 187.14297 | BA34: =+L34/D34 -> 1.6555848
A35: Australia | B35: World - A | C35: C70 | D35: =+Y35/1000 -> 19111 | Y35: 19111000 | AT35: =+N35+O35 -> 0 | AU35: =+U35/V35 -> #DIV/0! | AV35: =+AJ35/Y35 -> 0 | AW35: =+T35/D35 -> 0 | AX35: =+V35/D35 -> 0 | AY35: =+G35/D35 -> 0 | AZ35: =SUM(G35:M35)/D35 -> 0 | BA35: =+L35/D35 -> 0
A36: Japan | B36: World - A | C36: C41 | D36: =+Y36/1000 -> 126920 | E36: 1687 | F36: 2635 | G36: 287111133 | N36: 19459470 | T36: 37275313 | U36: 527748609 | W36: 964048 | X36: 4888445 | Y36: 126920000 | Z36: 11559 | AA36: 15105 | AB36: 26664 | AC36: 762697794 | AD36: 346736256 | AE36: 14816 | AF36: 823375 | AG36: 2121263 | AH36: 302171 | AI36: 127906312 | AJ36: 1240601987 | AK36: 1118276748 | AL36: 62422265 | AM36: 45179053 | AN36: 1225878065 | AT36: =+N36+O36 -> 19459470 | AU36: =+U36/V36 -> #DIV/0! | AV36: =+AJ36/Y36 -> 9.7746769 | AW36: =+T36/D36 -> 293.6914 | AX36: =+V36/D36 -> 0 | AY36: =+G36/D36 -> 2262.1426 | AZ36: =SUM(G36:M36)/D36 -> 2262.1426 | BA36: =+L36/D36 -> 0
A37: Korea | B37: World - A | C37: C40 | D37: =+Y37/1000 -> 48800 | Y37: 48800000 | AT37: =+N37+O37 -> 0 | AU37: =+U37/V37 -> #DIV/0! | AV37: =+AJ37/Y37 -> 0 | AW37: =+T37/D37 -> 0 | AX37: =+V37/D37 -> 0 | AY37: =+G37/D37 -> 0 | AZ37: =SUM(G37:M37)/D37 -> 0 | BA37: =+L37/D37 -> 0
A38: Canada | B38: World - A | C38: C51 | D38: =+Y38/1000 -> 31281 | E38: 2739 | F38: 910 | G38: 75032608 | I38: 150814 | U38: 331565367 | Y38: 31281000 | Z38: 6733 | AA38: 6616 | AB38: 13349 | AC38: 229533941 | AD38: 49614746 | AE38: 0 | AF38: 0 | AG38: 0 | AH38: 0 | AI38: 74500417 | AJ38: 353649103 | AK38: 322607590 | AL38: 18007972 | AM38: 13033541 | AN38: 353649103 | AO38: 17655562 | AP38: 872114 | AQ38: 4456657 | AR38: 3942678 | AS38: 26927011 | AT38: =+N38+O38 -> 0 | AU38: =+U38/V38 -> #DIV/0! | AV38: =+AJ38/Y38 -> 11.305556 | AW38: =+T38/D38 -> 0 | AX38: =+V38/D38 -> 0 | AY38: =+G38/D38 -> 2398.664 | AZ38: =SUM(G38:M38)/D38 -> 2403.4852 | BA38: =+L38/D38 -> 0
A39: New Zealand | B39: World - A | C39: C71 | D39: =+Y39/1000 -> 3900 | Y39: 3900000 | AT39: =+N39+O39 -> 0 | AU39: =+U39/V39 -> #DIV/0! | AV39: =+AJ39/Y39 -> 0 | AW39: =+T39/D39 -> 0 | AX39: =+V39/D39 -> 0 | AY39: =+G39/D39 -> 0 | AZ39: =SUM(G39:M39)/D39 -> 0 | BA39: =+L39/D39 -> 0
A40: Mexico | B40: World - B | C40: C72 | D40: =+Y40/1000 -> 97400 | Y40: 97400000 | AT40: =+N40+O40 -> 0 | AU40: =+U40/V40 -> #DIV/0! | AV40: =+AJ40/Y40 -> 0 | AW40: =+T40/D40 -> 0 | AX40: =+V40/D40 -> 0 | AY40: =+G40/D40 -> 0 | AZ40: =SUM(G40:M40)/D40 -> 0 | BA40: =+L40/D40 -> 0
...

Sheet 1999
