Workbook

Sheet READ ME FIRST
A2: Public Support Percentage Calculation Model
A4: Introduction
A6: Organizations in the U.S. that are registered as tax-exempt charities -- such as under Section 501(c)(3) -- must show that they are broadly supported by the public (i.e., not reliant on a few major donors or investment income). Because these rules are rather cumbersome to use for planning purposes, we have developed this spreadsheet to help institutes work through the ramifications of different funding scenarios.
A8: Important Disclaimer! Please understand that this workbook has been developed for informational and educational use only. Atlas Economic Research Foundation does not assume responsibility for the accuracy of results calculated or forecast using this model, and we recommend consulting a lawyer or tax specialist to address the particular circumstances of your institute.
A10: Also note that there are special siuations not contemplated in this workbook. For example, some "one-time" gifts may be omitted from your public support calculations. Contributions from other public (non-private) charities count as public support in their entirety. Gifts that are pledges in one year, but paid out over several also require special treatment. Further, some organizations that fail the public support test are able to appeal and demonstrate their compliance with the rules regarding 501(c)(3) organizations. Again, please discuss these matters with an attorney or other quailfied advisor.
A12: This workbook simply is meant to help organizations identify how different funding scenarios will affect their Public Support Percentage (PS%) calculations. The basic idea is the IRS differentiates between modest contributions from unrelated supporters (e.g., "public support") and large contributions or investment income (i.e., "unqualified support"). The first "X" number of dollars that you receive from any donor is considered public support. Above the "X" threshold, funds from a large supporter are registered as "non-qualified" amounts, which count against your organization's PS%. If your PS% drops below 33.3%, your organization would fail the test for retaining tax-exempt status. What makes this difficult is the fact that "X" is a moving target, based upon the preceding four years of activity.
A14: Using this Spreadsheet
A16: This workbook consists of four sheets (excluding this one), which will help you calculate your Public Support Percentage. Throughout the workbook, cells that require you to enter information have text in the color RED. Cells that contain formulas, which should not be altered, have numbers in the color BLUE. Other text is in BLACK.
A18: Year-by-Year Data: Identify which years you are concerned with. (This sets up the columns appropriately. If you change this number, you will need to re-enter data for the individual columns.) Then enter in summary financial data direct from your IRS Form 990 for past years, and enter your best predictions for these numbers on your future Form 990s. Also enter historical donation numbers for large donors (replacing "Big Donor #1" with the appropriate name, etc.), and your predictions for coming years. To play it safe, it is best to input realistic-to-aggressive estimates of amounts that you will receive from major donors, investment income and through selling products or services. Then be somewhat conservative in your estimate of overall contributions.
A20: Calculations: Turning to the next page, you can see the public support percentage calculated for the years for which there was information (inputed into the Year-by-Year Data page) for the preceding four-year period. the four-year totals that will used in the calculation for the given tax year. Lower on the page, you can see how the calculation was made (based upon how much of each major donor's support is to be classified as non-qualified).

Sheet Year-by-Year Data
A2: First Step
B3: Enter the first year for which you want to input financial information: | F3: 1995
A5: Required Information | D5: =F3 -> 1995 | E5: =D5+1 -> 1996 | F5: =E5+1 -> 1997 | G5: =F5+1 -> 1998 | H5: =G5+1 -> 1999 | I5: =H5+1 -> 2000 | J5: =I5+1 -> 2001 | K5: =J5+1 -> 2002 | L5: =K5+1 -> 2003 | M5: =L5+1 -> 2004
B7: Overall Financial Information
C8: Contributions Received | D8: 0 | E8: 0 | F8: 0 | G8: 0 | H8: 0 | I8: 0 | J8: 0 | K8: 0 | L8: 0 | M8: 0
C9: Membership Fees | D9: 0 | E9: 0 | F9: 0 | G9: 0 | H9: 0 | I9: 0 | J9: 0 | K9: 0 | L9: 0 | M9: 0
C10: Registration Fees | D10: 0 | E10: 0 | F10: 0 | G10: 0 | H10: 0 | I10: 0 | J10: 0 | K10: 0 | L10: 0 | M10: 0
C11: Interest income | D11: 0 | E11: 0 | F11: 0 | G11: 0 | H11: 0 | I11: 0 | J11: 0 | K11: 0 | L11: 0 | M11: 0
C13: Total | D13: =SUM(D8:D11) -> 0 | E13: =SUM(E8:E11) -> 0 | F13: =SUM(F8:F11) -> 0 | G13: =SUM(G8:G11) -> 0 | H13: =SUM(H8:H11) -> 0 | I13: =SUM(I8:I11) -> 0 | J13: =SUM(J8:J11) -> 0 | K13: =SUM(K8:K11) -> 0 | ... M13: =SUM(M8:M11) -> 0
C14: Total less registration fees | D14: =D13-D10 -> 0 | E14: =E13-E10 -> 0 | F14: =F13-F10 -> 0 | G14: =G13-G10 -> 0 | H14: =H13-H10 -> 0 | I14: =I13-I10 -> 0 | J14: =J13-J10 -> 0 | K14: =K13-K10 -> 0 | ... M14: =M13-M10 -> 0
B16: Major Donor Lists
C17: Big Donor #1 | D17: 0 | E17: 0 | F17: 0 | G17: 0 | H17: 0 | I17: 0 | J17: 0 | K17: 0 | L17: 0 | M17: 0
C18: Big Donor #2 | D18: 0 | E18: 0 | F18: 0 | G18: 0 | H18: 0 | I18: 0 | J18: 0 | K18: 0 | L18: 0 | M18: 0
C19: Big Donor #3 | D19: 0 | E19: 0 | F19: 0 | G19: 0 | H19: 0 | I19: 0 | J19: 0 | K19: 0 | L19: 0 | M19: 0
C20: Big Donor #4 | D20: 0 | E20: 0 | F20: 0 | G20: 0 | H20: 0 | I20: 0 | J20: 0 | K20: 0 | L20: 0 | M20: 0
C21: Big Donor #5 | D21: 0 | E21: 0 | F21: 0 | G21: 0 | H21: 0 | I21: 0 | J21: 0 | K21: 0 | L21: 0 | M21: 0
C22: Big Donor #6 | D22: 0 | E22: 0 | F22: 0 | G22: 0 | H22: 0 | I22: 0 | J22: 0 | K22: 0 | L22: 0 | M22: 0
C23: Big Donor #7 | D23: 0 | E23: 0 | F23: 0 | G23: 0 | H23: 0 | I23: 0 | J23: 0 | K23: 0 | L23: 0 | M23: 0
C24: Big Donor #8 | D24: 0 | E24: 0 | F24: 0 | G24: 0 | H24: 0 | I24: 0 | J24: 0 | K24: 0 | L24: 0 | M24: 0
C25: Big Donor #9 | D25: 0 | E25: 0 | F25: 0 | G25: 0 | H25: 0 | I25: 0 | J25: 0 | K25: 0 | L25: 0 | M25: 0
C26: Big Donor #10 | D26: 0 | E26: 0 | F26: 0 | G26: 0 | H26: 0 | I26: 0 | J26: 0 | K26: 0 | L26: 0 | M26: 0
C27: Big Donor #11 | D27: 0 | E27: 0 | F27: 0 | G27: 0 | H27: 0 | I27: 0 | J27: 0 | K27: 0 | L27: 0 | M27: 0
C28: Big Donor #12 | D28: 0 | E28: 0 | F28: 0 | G28: 0 | H28: 0 | I28: 0 | J28: 0 | K28: 0 | L28: 0 | M28: 0
... C31: Big Donor #15 | D31: 0 | E31: 0 | F31: 0 | G31: 0 | H31: 0 | I31: 0 | J31: 0 | K31: 0 | L31: 0 | M31: 0
C33: Big Donor Total | D33: =SUM(D17:D31) -> 0 | E33: =SUM(E17:E31) -> 0 | F33: =SUM(F17:F31) -> 0 | G33: =SUM(G17:G31) -> 0 | H33: =SUM(H17:H31) -> 0 | I33: =SUM(I17:I31) -> 0 | J33: =SUM(J17:J31) -> 0 | K33: =SUM(K17:K31) -> 0 | ... M33: =SUM(M17:M31) -> 0
A35: Instructions
B37: Input all relevant historical data on this page in cells that have red font. For future years, use different estimates to do a sensitivity analysis of likely results in regard to your public support test.
B38: Create more lines for your major donors if necessary. But be very careful!! You must also add additional donor lines for "Calculations" worksheet and verify each cell in that row pulling information from appropriate cells.
C48: Calendar Year Info | D48: 1994 | E48: 1995 | F48: 1996 | G48: 1997 | H48: 1998 | I48: 1999 | J48: 2000 | K48: 2001 | L48: 2002 | M48: 2003 | N48: 2004
D49: Actual | E49: Actual | F49: Actual | G49: Actual | H49: Actual | I49: Actual | J49: Estimated | K49: Estimated | L49: Estimated | M49: Estimated | N49: Estimated
C51: Contributions Received | D51: 1982639 | E51: 1783529 | F51: 2484847 | G51: 1170306 | H51: 1605129 | I51: =3347433-1292663 -> 2054770 | J51: =3048594.05+1292663/2 -> 3694925.5 | K51: 2800000 | L51: 2800000 | M51: 2800000 | N51: 2800000
C52: Membership Fees | D52: 0 | E52: 0 | F52: 0 | G52: 0 | H52: 0 | I52: 0 | J52: 0 | K52: 0 | L52: 0 | M52: 0 | N52: 0
C53: Registration Fees | D53: 14662 | E53: 4989 | F53: 7348 | G53: 6929 | H53: 27604 | I53: 12750 | J53: 27604 | K53: 27604 | L53: 27604 | M53: 27604 | N53: 27604
C54: Interest income | D54: 81418 | E54: 90095 | F54: 94018 | G54: 82334 | H54: 63409 | I54: 59959 | J54: 63409 | K54: 63409 | L54: 63409 | M54: 63409 | N54: 63409
C56: Total | D56: =SUM(D51:D54) -> 2078719 | E56: =SUM(E51:E54) -> 1878613 | F56: =SUM(F51:F54) -> 2586213 | G56: =SUM(G51:G54) -> 1259569 | H56: =SUM(H51:H54) -> 1696142 | I56: =SUM(I51:I54) -> 2127479 | J56: =SUM(J51:J54) -> 3785938.5 | K56: =SUM(K51:K54) -> 2891013 | ... N56: =SUM(N51:N54) -> 2891013
C57: Total less registration fees | D57: =D56-D53 -> 2064057 | E57: =E56-E53 -> 1873624 | F57: =F56-F53 -> 2578865 | G57: =G56-G53 -> 1252640 | H57: =H56-H53 -> 1668538 | I57: =I56-I53 -> 2114729 | J57: =J56-J53 -> 3758334.5 | K57: =K56-K53 -> 2863409 | ... N57: =N56-N53 -> 2863409
C61: Totals (preceding four years) | D61: 1998 (94-97) | E61: 1999 (95-98) | F61: 2000 (96-99) | G61: 2001 (97-00) | H61: 2002 (98-01) | I61: 2003 (99-02) | J61: 2004 (00-03) | K61: 2005 (01-04) | L61: 2006 (02-05) | M61: 2007 (03-06) | N61: 2008 (04-07)
C63: Contributions Received | D63: =SUM(D51:G51) -> 7421321 | E63: =SUM(E51:H51) -> 7043811 | F63: =SUM(F51:I51) -> 7315052 | G63: =SUM(G51:J51) -> 8525130.6 | H63: =SUM(H51:K51) -> 10154825 | I63: =SUM(I51:L51) -> 11349696 | J63: =SUM(J51:M51) -> 12094926 | K63: =SUM(K51:N51) -> 11200000 | L63: =SUM(L51:N51)*4/3 -> 11200000 | M63: =SUM(M51:O51)*4/2 -> 11200000 | N63: =SUM(N51:P51)*4/1 -> 11200000
C64: Membership Fees | D64: =SUM(D52:G52) -> 0 | E64: =SUM(E52:H52) -> 0 | F64: =SUM(F52:I52) -> 0 | G64: =SUM(G52:J52) -> 0 | H64: =SUM(H52:K52) -> 0 | I64: =SUM(I52:L52) -> 0 | J64: =SUM(J52:M52) -> 0 | K64: =SUM(K52:N52) -> 0 | L64: =SUM(L52:N52)*4/3 -> 0 | M64: =SUM(M52:O52)*4/2 -> 0 | N64: =SUM(N52:P52)*4/1 -> 0
C65: Registration Fees | D65: =SUM(D53:G53) -> 33928 | E65: =SUM(E53:H53) -> 46870 | F65: =SUM(F53:I53) -> 54631 | G65: =SUM(G53:J53) -> 74887 | H65: =SUM(H53:K53) -> 95562 | I65: =SUM(I53:L53) -> 95562 | J65: =SUM(J53:M53) -> 110416 | K65: =SUM(K53:N53) -> 110416 | L65: =SUM(L53:N53)*4/3 -> 110416 | M65: =SUM(M53:O53)*4/2 -> 110416 | N65: =SUM(N53:P53)*4/1 -> 110416
...

Sheet Calculations
A1: Required Information | D1: ='Year-by-Year Data'!D5 -> 1995 | E1: ='Year-by-Year Data'!E5 -> 1996 | F1: ='Year-by-Year Data'!F5 -> 1997 | G1: ='Year-by-Year Data'!G5 -> 1998 | H1: ='Year-by-Year Data'!H5 -> 1999 | I1: ='Year-by-Year Data'!I5 -> 2000 | J1: ='Year-by-Year Data'!J5 -> 2001 | K1: ='Year-by-Year Data'!K5 -> 2002 | ... M1: ='Year-by-Year Data'!M5 -> 2004
B3: Four Year Term
C4: First year included | D4: =D5-3 -> 1991 | E4: =E5-3 -> 1992 | F4: =F5-3 -> 1993 | G4: =G5-3 -> 1994 | H4: =H5-3 -> 1995 | I4: =I5-3 -> 1996 | J4: =J5-3 -> 1997 | K4: =K5-3 -> 1998 | ... M4: =M5-3 -> 2000
C5: Last year included | D5: =D1-1 -> 1994 | E5: =E1-1 -> 1995 | F5: =F1-1 -> 1996 | G5: =G1-1 -> 1997 | H5: =H1-1 -> 1998 | I5: =I1-1 -> 1999 | J5: =J1-1 -> 2000 | K5: =K1-1 -> 2001 | ... M5: =M1-1 -> 2003
B8: Overall Financial Information
C9: Contributions Received | D9: N/A | E9: N/A | F9: N/A | G9: N/A | H9: =SUM('Year-by-Year Data'!D8:G8) -> 0 | I9: =SUM('Year-by-Year Data'!E8:H8) -> 0 | J9: =SUM('Year-by-Year Data'!F8:I8) -> 0 | K9: =SUM('Year-by-Year Data'!G8:J8) -> 0 | L9: =SUM('Year-by-Year Data'!H8:K8) -> 0 | M9: =SUM('Year-by-Year Data'!I8:L8) -> 0
C10: Membership Fees | D10: N/A | E10: N/A | F10: N/A | G10: N/A | H10: =SUM('Year-by-Year Data'!D9:G9) -> 0 | I10: =SUM('Year-by-Year Data'!E9:H9) -> 0 | J10: =SUM('Year-by-Year Data'!F9:I9) -> 0 | K10: =SUM('Year-by-Year Data'!G9:J9) -> 0 | L10: =SUM('Year-by-Year Data'!H9:K9) -> 0 | M10: =SUM('Year-by-Year Data'!I9:L9) -> 0
C11: Registration Fees | D11: N/A | E11: N/A | F11: N/A | G11: N/A | H11: =SUM('Year-by-Year Data'!D10:G10) -> 0 | I11: =SUM('Year-by-Year Data'!E10:H10) -> 0 | J11: =SUM('Year-by-Year Data'!F10:I10) -> 0 | K11: =SUM('Year-by-Year Data'!G10:J10) -> 0 | L11: =SUM('Year-by-Year Data'!H10:K10) -> 0 | M11: =SUM('Year-by-Year Data'!I10:L10) -> 0
C12: Interest income | D12: N/A | E12: N/A | F12: N/A | G12: N/A | H12: =SUM('Year-by-Year Data'!D11:G11) -> 0 | I12: =SUM('Year-by-Year Data'!E11:H11) -> 0 | J12: =SUM('Year-by-Year Data'!F11:I11) -> 0 | K12: =SUM('Year-by-Year Data'!G11:J11) -> 0 | L12: =SUM('Year-by-Year Data'!H11:K11) -> 0 | M12: =SUM('Year-by-Year Data'!I11:L11) -> 0
C14: Total | D14: N/A | E14: N/A | F14: N/A | G14: N/A | H14: =SUM('Year-by-Year Data'!D13:G13) -> 0 | I14: =SUM('Year-by-Year Data'!E13:H13) -> 0 | J14: =SUM('Year-by-Year Data'!F13:I13) -> 0 | K14: =SUM('Year-by-Year Data'!G13:J13) -> 0 | L14: =SUM('Year-by-Year Data'!H13:K13) -> 0 | M14: =SUM('Year-by-Year Data'!I13:L13) -> 0
C15: Total less registration fees | D15: N/A | E15: N/A | F15: N/A | G15: N/A | H15: =SUM('Year-by-Year Data'!D14:G14) -> 0 | I15: =SUM('Year-by-Year Data'!E14:H14) -> 0 | J15: =SUM('Year-by-Year Data'!F14:I14) -> 0 | K15: =SUM('Year-by-Year Data'!G14:J14) -> 0 | L15: =SUM('Year-by-Year Data'!H14:K14) -> 0 | M15: =SUM('Year-by-Year Data'!I14:L14) -> 0
B17: 2% of TLRF (Threshold Amount) | D17: N/A | E17: N/A | F17: N/A | G17: N/A | H17: =0.02*H15 -> 0 | I17: =0.02*I15 -> 0 | J17: =0.02*J15 -> 0 | K17: =0.02*K15 -> 0 | L17: =0.02*L15 -> 0 | M17: =0.02*M15 -> 0
B19: Amount of non-qualified donations | D19: N/A | E19: N/A | F19: N/A | G19: N/A | H19: =H62 -> 0 | I19: =I62 -> 0 | J19: =J62 -> 0 | K19: =K62 -> 0 | L19: =L62 -> 0 | M19: =M62 -> 0
B20: Non-qualified interest income | D20: N/A | E20: N/A | F20: N/A | G20: N/A | H20: =H12 -> 0 | I20: =I12 -> 0 | J20: =J12 -> 0 | K20: =K12 -> 0 | L20: =L12 -> 0 | M20: =M12 -> 0
C22: Total Non Qualified Amount | D22: N/A | E22: N/A | F22: N/A | G22: N/A | H22: =SUM(H19:H20) -> 0 | I22: =SUM(I19:I20) -> 0 | J22: =SUM(J19:J20) -> 0 | K22: =SUM(K19:K20) -> 0 | L22: =SUM(L19:L20) -> 0 | M22: =SUM(M19:M20) -> 0
C23: Total Qualified Amount | D23: N/A | E23: N/A | F23: N/A | G23: N/A | H23: =H15-H22 -> 0 | I23: =I15-I22 -> 0 | J23: =J15-J22 -> 0 | K23: =K15-K22 -> 0 | L23: =L15-L22 -> 0 | M23: =M15-M22 -> 0
C25: Public Support Percentage (PS%) | D25: N/A | E25: N/A | F25: N/A | G25: N/A | H25: =H23/H15 -> #DIV/0! | I25: =I23/I15 -> #DIV/0! | J25: =J23/J15 -> #DIV/0! | K25: =K23/K15 -> #DIV/0! | L25: =L23/L15 -> #DIV/0! | M25: =M23/M15 -> #DIV/0!
C26: Is PS% above 33.0%
B28: Major Donor Lists
C29: ='Year-by-Year Data'!C17 -> Big Donor #1 | D29: N/A | E29: N/A | F29: N/A | G29: N/A | H29: =SUM('Year-by-Year Data'!D17:G17) -> 0 | I29: =SUM('Year-by-Year Data'!E17:H17) -> 0 | J29: =SUM('Year-by-Year Data'!F17:I17) -> 0 | K29: =SUM('Year-by-Year Data'!G17:J17) -> 0 | L29: =SUM('Year-by-Year Data'!H17:K17) -> 0 | M29: =SUM('Year-by-Year Data'!I17:L17) -> 0
C30: ='Year-by-Year Data'!C18 -> Big Donor #2 | D30: N/A | E30: N/A | F30: N/A | G30: N/A | H30: =SUM('Year-by-Year Data'!D18:G18) -> 0 | I30: =SUM('Year-by-Year Data'!E18:H18) -> 0 | J30: =SUM('Year-by-Year Data'!F18:I18) -> 0 | K30: =SUM('Year-by-Year Data'!G18:J18) -> 0 | L30: =SUM('Year-by-Year Data'!H18:K18) -> 0 | M30: =SUM('Year-by-Year Data'!I18:L18) -> 0
C31: ='Year-by-Year Data'!C19 -> Big Donor #3 | D31: N/A | E31: N/A | F31: N/A | G31: N/A | H31: =SUM('Year-by-Year Data'!D19:G19) -> 0 | I31: =SUM('Year-by-Year Data'!E19:H19) -> 0 | J31: =SUM('Year-by-Year Data'!F19:I19) -> 0 | K31: =SUM('Year-by-Year Data'!G19:J19) -> 0 | L31: =SUM('Year-by-Year Data'!H19:K19) -> 0 | M31: =SUM('Year-by-Year Data'!I19:L19) -> 0
C32: ='Year-by-Year Data'!C20 -> Big Donor #4 | D32: N/A | E32: N/A | F32: N/A | G32: N/A | H32: =SUM('Year-by-Year Data'!D20:G20) -> 0 | I32: =SUM('Year-by-Year Data'!E20:H20) -> 0 | J32: =SUM('Year-by-Year Data'!F20:I20) -> 0 | K32: =SUM('Year-by-Year Data'!G20:J20) -> 0 | L32: =SUM('Year-by-Year Data'!H20:K20) -> 0 | M32: =SUM('Year-by-Year Data'!I20:L20) -> 0
C33: ='Year-by-Year Data'!C21 -> Big Donor #5 | D33: N/A | E33: N/A | F33: N/A | G33: N/A | H33: =SUM('Year-by-Year Data'!D21:G21) -> 0 | I33: =SUM('Year-by-Year Data'!E21:H21) -> 0 | J33: =SUM('Year-by-Year Data'!F21:I21) -> 0 | K33: =SUM('Year-by-Year Data'!G21:J21) -> 0 | L33: =SUM('Year-by-Year Data'!H21:K21) -> 0 | M33: =SUM('Year-by-Year Data'!I21:L21) -> 0
C34: ='Year-by-Year Data'!C22 -> Big Donor #6 | D34: N/A | E34: N/A | F34: N/A | G34: N/A | H34: =SUM('Year-by-Year Data'!D22:G22) -> 0 | I34: =SUM('Year-by-Year Data'!E22:H22) -> 0 | J34: =SUM('Year-by-Year Data'!F22:I22) -> 0 | K34: =SUM('Year-by-Year Data'!G22:J22) -> 0 | L34: =SUM('Year-by-Year Data'!H22:K22) -> 0 | M34: =SUM('Year-by-Year Data'!I22:L22) -> 0
C35: ='Year-by-Year Data'!C23 -> Big Donor #7 | D35: N/A | E35: N/A | F35: N/A | G35: N/A | H35: =SUM('Year-by-Year Data'!D23:G23) -> 0 | I35: =SUM('Year-by-Year Data'!E23:H23) -> 0 | J35: =SUM('Year-by-Year Data'!F23:I23) -> 0 | K35: =SUM('Year-by-Year Data'!G23:J23) -> 0 | L35: =SUM('Year-by-Year Data'!H23:K23) -> 0 | M35: =SUM('Year-by-Year Data'!I23:L23) -> 0
C36: ='Year-by-Year Data'!C24 -> Big Donor #8 | D36: N/A | E36: N/A | F36: N/A | G36: N/A | H36: =SUM('Year-by-Year Data'!D24:G24) -> 0 | I36: =SUM('Year-by-Year Data'!E24:H24) -> 0 | J36: =SUM('Year-by-Year Data'!F24:I24) -> 0 | K36: =SUM('Year-by-Year Data'!G24:J24) -> 0 | L36: =SUM('Year-by-Year Data'!H24:K24) -> 0 | M36: =SUM('Year-by-Year Data'!I24:L24) -> 0
C37: ='Year-by-Year Data'!C25 -> Big Donor #9 | D37: N/A | E37: N/A | F37: N/A | G37: N/A | H37: =SUM('Year-by-Year Data'!D25:G25) -> 0 | I37: =SUM('Year-by-Year Data'!E25:H25) -> 0 | J37: =SUM('Year-by-Year Data'!F25:I25) -> 0 | K37: =SUM('Year-by-Year Data'!G25:J25) -> 0 | L37: =SUM('Year-by-Year Data'!H25:K25) -> 0 | M37: =SUM('Year-by-Year Data'!I25:L25) -> 0
C38: ='Year-by-Year Data'!C26 -> Big Donor #10 | D38: N/A | E38: N/A | F38: N/A | G38: N/A | H38: =SUM('Year-by-Year Data'!D26:G26) -> 0 | I38: =SUM('Year-by-Year Data'!E26:H26) -> 0 | J38: =SUM('Year-by-Year Data'!F26:I26) -> 0 | K38: =SUM('Year-by-Year Data'!G26:J26) -> 0 | L38: =SUM('Year-by-Year Data'!H26:K26) -> 0 | M38: =SUM('Year-by-Year Data'!I26:L26) -> 0
C39: ='Year-by-Year Data'!C27 -> Big Donor #11 | D39: N/A | E39: N/A | F39: N/A | G39: N/A | H39: =SUM('Year-by-Year Data'!D27:G27) -> 0 | I39: =SUM('Year-by-Year Data'!E27:H27) -> 0 | J39: =SUM('Year-by-Year Data'!F27:I27) -> 0 | K39: =SUM('Year-by-Year Data'!G27:J27) -> 0 | L39: =SUM('Year-by-Year Data'!H27:K27) -> 0 | M39: =SUM('Year-by-Year Data'!I27:L27) -> 0
C40: ='Year-by-Year Data'!C28 -> Big Donor #12 | D40: N/A | E40: N/A | F40: N/A | G40: N/A | H40: =SUM('Year-by-Year Data'!D28:G28) -> 0 | I40: =SUM('Year-by-Year Data'!E28:H28) -> 0 | J40: =SUM('Year-by-Year Data'!F28:I28) -> 0 | K40: =SUM('Year-by-Year Data'!G28:J28) -> 0 | L40: =SUM('Year-by-Year Data'!H28:K28) -> 0 | M40: =SUM('Year-by-Year Data'!I28:L28) -> 0
... C43: ='Year-by-Year Data'!C31 -> Big Donor #15 | D43: N/A | E43: N/A | F43: N/A | G43: N/A | H43: =SUM('Year-by-Year Data'!D31:G31) -> 0 | I43: =SUM('Year-by-Year Data'!E31:H31) -> 0 | J43: =SUM('Year-by-Year Data'!F31:I31) -> 0 | K43: =SUM('Year-by-Year Data'!G31:J31) -> 0 | L43: =SUM('Year-by-Year Data'!H31:K31) -> 0 | M43: =SUM('Year-by-Year Data'!I31:L31) -> 0
B45: Amounts in Excess of Threshold Amount
C46: =C29 -> Big Donor #1 | D46: N/A | E46: N/A | F46: N/A | G46: N/A | H46: =IF(H29-H$17<0.01,0,H29-H$17) -> 0 | I46: =IF(I29-I$17<0.01,0,I29-I$17) -> 0 | J46: =IF(J29-J$17<0.01,0,J29-J$17) -> 0 | K46: =IF(K29-K$17<0.01,0,K29-K$17) -> 0 | L46: =IF(L29-L$17<0.01,0,L29-L$17) -> 0 | M46: =IF(M29-M$17<0.01,0,M29-M$17) -> 0
C47: =C30 -> Big Donor #2 | D47: N/A | E47: N/A | F47: N/A | G47: N/A | H47: =IF(H30-H$17<0.01,0,H30-H$17) -> 0 | I47: =IF(I30-I$17<0.01,0,I30-I$17) -> 0 | J47: =IF(J30-J$17<0.01,0,J30-J$17) -> 0 | K47: =IF(K30-K$17<0.01,0,K30-K$17) -> 0 | L47: =IF(L30-L$17<0.01,0,L30-L$17) -> 0 | M47: =IF(M30-M$17<0.01,0,M30-M$17) -> 0
C48: =C31 -> Big Donor #3 | D48: N/A | E48: N/A | F48: N/A | G48: N/A | H48: =IF(H31-H$17<0.01,0,H31-H$17) -> 0 | I48: =IF(I31-I$17<0.01,0,I31-I$17) -> 0 | J48: =IF(J31-J$17<0.01,0,J31-J$17) -> 0 | K48: =IF(K31-K$17<0.01,0,K31-K$17) -> 0 | L48: =IF(L31-L$17<0.01,0,L31-L$17) -> 0 | M48: =IF(M31-M$17<0.01,0,M31-M$17) -> 0
C49: =C32 -> Big Donor #4 | D49: N/A | E49: N/A | F49: N/A | G49: N/A | H49: =IF(H32-H$17<0.01,0,H32-H$17) -> 0 | I49: =IF(I32-I$17<0.01,0,I32-I$17) -> 0 | J49: =IF(J32-J$17<0.01,0,J32-J$17) -> 0 | K49: =IF(K32-K$17<0.01,0,K32-K$17) -> 0 | L49: =IF(L32-L$17<0.01,0,L32-L$17) -> 0 | M49: =IF(M32-M$17<0.01,0,M32-M$17) -> 0
C50: =C33 -> Big Donor #5 | D50: N/A | E50: N/A | F50: N/A | G50: N/A | H50: =IF(H33-H$17<0.01,0,H33-H$17) -> 0 | I50: =IF(I33-I$17<0.01,0,I33-I$17) -> 0 | J50: =IF(J33-J$17<0.01,0,J33-J$17) -> 0 | K50: =IF(K33-K$17<0.01,0,K33-K$17) -> 0 | L50: =IF(L33-L$17<0.01,0,L33-L$17) -> 0 | M50: =IF(M33-M$17<0.01,0,M33-M$17) -> 0
C51: =C34 -> Big Donor #6 | D51: N/A | E51: N/A | F51: N/A | G51: N/A | H51: =IF(H34-H$17<0.01,0,H34-H$17) -> 0 | I51: =IF(I34-I$17<0.01,0,I34-I$17) -> 0 | J51: =IF(J34-J$17<0.01,0,J34-J$17) -> 0 | K51: =IF(K34-K$17<0.01,0,K34-K$17) -> 0 | L51: =IF(L34-L$17<0.01,0,L34-L$17) -> 0 | M51: =IF(M34-M$17<0.01,0,M34-M$17) -> 0
C52: =C35 -> Big Donor #7 | D52: N/A | E52: N/A | F52: N/A | G52: N/A | H52: =IF(H35-H$17<0.01,0,H35-H$17) -> 0 | I52: =IF(I35-I$17<0.01,0,I35-I$17) -> 0 | J52: =IF(J35-J$17<0.01,0,J35-J$17) -> 0 | K52: =IF(K35-K$17<0.01,0,K35-K$17) -> 0 | L52: =IF(L35-L$17<0.01,0,L35-L$17) -> 0 | M52: =IF(M35-M$17<0.01,0,M35-M$17) -> 0
...
