Workbook
Name Correlations: RDERets1!$C$110:$Q$124
Name Covariances: RDERets1!$C$92:$Q$106
Name Returns: RDERets1!$C$5:$Q$17

Sheet RDERets1
A1: Homework 7
A2: Financial Management
A4: Returns (with dividends)
B5: Prob | C5: CMB | D5: COL | E5: F | F5: GLD | G5: HWP | H5: INTC | I5: KO | J5: LPX | K5: LUV | L5: MO | M5: MOB | N5: MSFT | O5: PCG | P5: PG | Q5: X | R5: Portfolio
A6: Jan '96 | B6: 0.04 | C6: 0.1511 | D6: 0.0967 | E6: 0.0338 | F6: 0.3505 | G6: 0.0119 | H6: -0.026 | I6: 0.0181 | J6: 0.0573 | K6: 0.1417 | L6: 0.0388 | M6: -0.0007 | N6: 0.0871 | O6: -0.0048 | P6: 0.0139 | Q6: 0.1585
A7: Feb '96 | B7: 0.05 | C7: 0.0797 | D7: -0.0157 | E7: 0.0593 | F7: -0.0458 | G7: 0.1912 | H7: 0.0648 | I7: 0.0713 | J7: -0.0931 | K7: 0.1714 | L7: 0.0674 | M7: -0.0102 | N7: 0.0669 | O7: -0.0766 | P7: -0.0209 | Q7: -0.0742
A8: Mar '96 | B8: 0.06 | C8: -0.0134 | D8: 0.0548 | E8: 0.1 | F8: 0.024 | G8: -0.0657 | H8: -0.033 | I8: 0.0248 | J8: 0.0541 | K8: -0.0325 | L8: -0.1136 | M8: 0.057 | N8: 0.045 | O8: -0.1268 | P8: 0.0335 | Q8: 0.0573
A9: Apr '96 | B9: 0.1 | C9: -0.0536 | D9: -0.0796 | E9: 0.0538 | F9: -0.0703 | G9: 0.1248 | H9: 0.1919 | I9: -0.0121 | J9: 0.0314 | K9: 0.0004 | L9: 0.0385 | M9: 0.0004 | N9: 0.1286 | O9: 0.0387 | P9: 0.0018 | Q9: -0.0397
A10: May '96 | B10: 0.1 | C10: 0.0145 | D10: 0.0141 | E10: 0.0174 | F10: 0.0252 | G10: 0.0078 | H10: 0.1144 | I10: 0.1288 | J10: -0.015 | K10: -0.0798 | L10: 0.1026 | M10: -0.0185 | N10: 0.0486 | O10: 0.022 | P10: 0.0399 | Q10: -0.0606
A11: Jun '96 | B11: 0.15 | C11: 0.0089 | D11: -0.0046 | E11: -0.113 | F11: -0.0738 | G11: -0.0645 | H11: -0.0273 | I11: 0.0652 | J11: -0.1015 | K11: 0.0639 | L11: 0.0465 | M11: -0.0044 | N11: 0.0116 | O11: 0 | P11: 0.0313 | Q11: -0.0847
A12: Jul '96 | B12: 0.15 | C12: -0.008 | D12: -0.0437 | E12: 0.0108 | F12: -0.085 | G12: -0.1167 | H12: 0.0237 | I12: -0.0408 | J12: -0.0671 | K12: -0.1498 | L12: 0.0156 | M12: -0.01 | N12: 0.0098 | O12: -0.1295 | P12: -0.0108 | Q12: -0.0969
A13: Aug '96 | B13: 0.1 | C13: 0.0701 | D13: 0.1 | E13: 0.0347 | F13: 0.0097 | G13: -0.0002 | H13: 0.0624 | I13: 0.0667 | J13: 0.061 | K13: -0.0808 | L13: -0.1422 | M13: 0.0249 | N13: 0.0392 | O13: 0.1456 | P13: -0.0042 | Q13: 0.0837
A14: Sep '96 | B14: 0.1 | C14: 0.0773 | D14: 0.0089 | E14: -0.0672 | F14: -0.0385 | G14: 0.1143 | H14: 0.1958 | I14: 0.0175 | J14: 0.046 | K14: 0.0055 | L14: 0 | M14: 0.0243 | N14: 0.0765 | O14: -0.0387 | P14: 0.097 | Q14: 0.0364
A15: Oct '96 | B15: 0.06 | C15: 0.0772 | D15: -0.0599 | E15: 0.0123 | F15: -0.05 | G15: -0.0949 | H15: 0.1518 | I15: -0.0049 | J15: -0.0763 | K15: -0.0159 | L15: 0.0426 | M15: 0.0173 | N15: 0.068 | O15: 0.0972 | P15: 0.02 | Q15: -0.0395
A16: Nov '96 | B16: 0.05 | C16: 0.102 | D16: 0.1228 | E16: 0.048 | F16: -0.0316 | G16: 0.221 | H16: 0.1547 | I16: 0.0124 | J16: 0.0838 | K16: 0.1056 | L16: 0.1177 | M16: 0.0375 | N16: 0.143 | O16: 0.0321 | P16: 0.0985 | Q16: 0.1106
A17: Dec '96 | B17: 0.04 | C17: -0.0542 | D17: 0.0188 | E17: -0.0153 | F17: 0.337 | G17: -0.0673 | H17: 0.0325 | I17: 0.0293 | J17: -0.0663 | K17: -0.1156 | L17: 0.0944 | M17: 0.0093 | N17: 0.0534 | O17: -0.1295 | P17: -0.0103 | Q17: 0.0415
A19: Problem 1
A20: E (Rj) | C20: =[1]!ExpValue($B$6:$B$17,C6:C17) -> 0.027754 | D20: =[1]!ExpValue($B$6:$B$17,D6:D17) -> 0.006764 | E20: =[1]!ExpValue($B$6:$B$17,E6:E17) -> 0.001383 | F20: =[1]!ExpValue($B$6:$B$17,F6:F17) -> -0.00914 | G20: =[1]!ExpValue($B$6:$B$17,G6:G17) -> 0.006248 | H20: =[1]!ExpValue($B$6:$B$17,H6:H17) -> 0.074273 | I20: =[1]!ExpValue($B$6:$B$17,I6:I17) -> 0.031025 | J20: =[1]!ExpValue($B$6:$B$17,J6:J17) -> -0.015107 | ... Q20: =[1]!ExpValue($B$6:$B$17,Q6:Q17) -> -0.014372 | R20: =R80 -> 0.012414933
A21: s 2 (Rj) | C21: =[1]!PVar($B$6:$B$17,C6:C17) -> 0.0028853705 | D21: =[1]!PVar($B$6:$B$17,D6:D17) -> 0.0034552465 | E21: =[1]!PVar($B$6:$B$17,E6:E17) -> 0.0037778094 | F21: =[1]!PVar($B$6:$B$17,F6:F17) -> 0.012328663 | G21: =[1]!PVar($B$6:$B$17,G6:G17) -> 0.010753982 | H21: =[1]!PVar($B$6:$B$17,H6:H17) -> 0.0068177864 | I21: =[1]!PVar($B$6:$B$17,I6:I17) -> 0.0024215599 | J21: =[1]!PVar($B$6:$B$17,J6:J17) -> 0.0043138453 | ... Q21: =[1]!PVar($B$6:$B$17,Q6:Q17) -> 0.005887203 | R21: =R81 -> 0.0012503124
A22: s (Rj) | C22: =[1]!PStDev($B$6:$B$17,C6:C17) -> 0.053715645 | D22: =[1]!PStDev($B$6:$B$17,D6:D17) -> 0.058781345 | E22: =[1]!PStDev($B$6:$B$17,E6:E17) -> 0.061463887 | F22: =[1]!PStDev($B$6:$B$17,F6:F17) -> 0.11103451 | G22: =[1]!PStDev($B$6:$B$17,G6:G17) -> 0.10370141 | H22: =[1]!PStDev($B$6:$B$17,H6:H17) -> 0.082569888 | I22: =[1]!PStDev($B$6:$B$17,I6:I17) -> 0.049209347 | J22: =[1]!PStDev($B$6:$B$17,J6:J17) -> 0.065679869 | ... Q22: =[1]!PStDev($B$6:$B$17,Q6:Q17) -> 0.076728111 | R22: =R82 -> 0.035359757
A24: Covariance Matrix using Probabilities
C25: CMB | D25: COL | E25: F | F25: GLD | G25: HWP | H25: INTC | I25: KO | J25: LPX | K25: LUV | L25: MO | M25: MOB | N25: MSFT | O25: PCG | P25: PG | Q25: X
A26: CMB | C26: =[1]!PCovar($B$6:$B$17,$C$6:$C$17,C$6:C$17) -> 0.0028853705 | D26: =[1]!PCovar($B$6:$B$17,$C$6:$C$17,D$6:D$17) -> 0.0018613648 | E26: =[1]!PCovar($B$6:$B$17,$C$6:$C$17,E$6:E$17) -> -4.6404082e-05 | F26: =[1]!PCovar($B$6:$B$17,$C$6:$C$17,F$6:F$17) -> 0.0012341256 | G26: =[1]!PCovar($B$6:$B$17,$C$6:$C$17,G$6:G$17) -> 0.0018251525 | H26: =[1]!PCovar($B$6:$B$17,$C$6:$C$17,H$6:H$17) -> 0.00051125926 | I26: =[1]!PCovar($B$6:$B$17,$C$6:$C$17,I$6:I$17) -> 0.00048000065 | J26: =[1]!PCovar($B$6:$B$17,$C$6:$C$17,J$6:J$17) -> 0.0011069513 | ... Q26: =[1]!PCovar($B$6:$B$17,$C$6:$C$17,Q$6:Q$17) -> 0.0023024588
A27: COL | D27: =[1]!PCovar($B$6:$B$17,$D$6:$D$17,D$6:D$17) -> 0.0034552465 | E27: =[1]!PCovar($B$6:$B$17,$D$6:$D$17,E$6:E$17) -> 0.00053329549 | F27: =[1]!PCovar($B$6:$B$17,$D$6:$D$17,F$6:F$17) -> 0.003037474 | G27: =[1]!PCovar($B$6:$B$17,$D$6:$D$17,G$6:G$17) -> 0.0012118456 | H27: =[1]!PCovar($B$6:$B$17,$D$6:$D$17,H$6:H$17) -> -0.0010380683 | I27: =[1]!PCovar($B$6:$B$17,$D$6:$D$17,I$6:I$17) -> 0.0011844648 | J27: =[1]!PCovar($B$6:$B$17,$D$6:$D$17,J$6:J$17) -> 0.0022034025 | K27: =[1]!PCovar($B$6:$B$17,$D$6:$D$17,K$6:K$17) -> 0.0010550179 | ... Q27: =[1]!PCovar($B$6:$B$17,$D$6:$D$17,Q$6:Q$17) -> 0.0036027791
A28: F | E28: =[1]!PCovar($B$6:$B$17,$E$6:$E$17,E$6:E$17) -> 0.0037778094 | F28: =[1]!PCovar($B$6:$B$17,$E$6:$E$17,F$6:F$17) -> 0.0012469586 | G28: =[1]!PCovar($B$6:$B$17,$E$6:$E$17,G$6:G$17) -> 0.0015021342 | H28: =[1]!PCovar($B$6:$B$17,$E$6:$E$17,H$6:H$17) -> 0.00095303784 | I28: =[1]!PCovar($B$6:$B$17,$E$6:$E$17,I$6:I$17) -> -0.00054839267 | J28: =[1]!PCovar($B$6:$B$17,$E$6:$E$17,J$6:J$17) -> 0.0019894123 | K28: =[1]!PCovar($B$6:$B$17,$E$6:$E$17,K$6:K$17) -> -0.0009399518 | L28: =[1]!PCovar($B$6:$B$17,$E$6:$E$17,L$6:L$17) -> -0.0010708456 | ... Q28: =[1]!PCovar($B$6:$B$17,$E$6:$E$17,Q$6:Q$17) -> 0.0015743445
A29: GLD | F29: =[1]!PCovar($B$6:$B$17,$F$6:$F$17,F$6:F$17) -> 0.012328663 | G29: =[1]!PCovar($B$6:$B$17,$F$6:$F$17,G$6:G$17) -> -0.00037619228 | H29: =[1]!PCovar($B$6:$B$17,$F$6:$F$17,H$6:H$17) -> -0.0018973378 | I29: =[1]!PCovar($B$6:$B$17,$F$6:$F$17,I$6:I$17) -> 0.0010052365 | J29: =[1]!PCovar($B$6:$B$17,$F$6:$F$17,J$6:J$17) -> 0.001761801 | K29: =[1]!PCovar($B$6:$B$17,$F$6:$F$17,K$6:K$17) -> 0.0006194339 | L29: =[1]!PCovar($B$6:$B$17,$F$6:$F$17,L$6:L$17) -> 0.00049958592 | M29: =[1]!PCovar($B$6:$B$17,$F$6:$F$17,M$6:M$17) -> 0.00023226138 | ... Q29: =[1]!PCovar($B$6:$B$17,$F$6:$F$17,Q$6:Q$17) -> 0.0050869439
A30: HWP | G30: =[1]!PCovar($B$6:$B$17,$G$6:$G$17,G$6:G$17) -> 0.010753982 | H30: =[1]!PCovar($B$6:$B$17,$G$6:$G$17,H$6:H$17) -> 0.0056008851 | I30: =[1]!PCovar($B$6:$B$17,$G$6:$G$17,I$6:I$17) -> 0.0007162238 | J30: =[1]!PCovar($B$6:$B$17,$G$6:$G$17,J$6:J$17) -> 0.0036186169 | K30: =[1]!PCovar($B$6:$B$17,$G$6:$G$17,K$6:K$17) -> 0.005516252 | L30: =[1]!PCovar($B$6:$B$17,$G$6:$G$17,L$6:L$17) -> 0.0016328954 | M30: =[1]!PCovar($B$6:$B$17,$G$6:$G$17,M$6:M$17) -> 0.00040925998 | N30: =[1]!PCovar($B$6:$B$17,$G$6:$G$17,N$6:N$17) -> 0.0034393988 | ... Q30: =[1]!PCovar($B$6:$B$17,$G$6:$G$17,Q$6:Q$17) -> 0.0029526997
A31: INTC | H31: =[1]!PCovar($B$6:$B$17,$H$6:$H$17,H$6:H$17) -> 0.0068177864 | I31: =[1]!PCovar($B$6:$B$17,$H$6:$H$17,I$6:I$17) -> -0.00046376802 | J31: =[1]!PCovar($B$6:$B$17,$H$6:$H$17,J$6:J$17) -> 0.0024101388 | K31: =[1]!PCovar($B$6:$B$17,$H$6:$H$17,K$6:K$17) -> 0.00011356695 | L31: =[1]!PCovar($B$6:$B$17,$H$6:$H$17,L$6:L$17) -> 0.0012639507 | M31: =[1]!PCovar($B$6:$B$17,$H$6:$H$17,M$6:M$17) -> 0.00019561396 | N31: =[1]!PCovar($B$6:$B$17,$H$6:$H$17,N$6:N$17) -> 0.0024712212 | O31: =[1]!PCovar($B$6:$B$17,$H$6:$H$17,O$6:O$17) -> 0.00255197 | ... Q31: =[1]!PCovar($B$6:$B$17,$H$6:$H$17,Q$6:Q$17) -> 0.00088068456
A32: KO | I32: =[1]!PCovar($B$6:$B$17,$I$6:$I$17,I$6:I$17) -> 0.0024215599 | J32: =[1]!PCovar($B$6:$B$17,$I$6:$I$17,J$6:J$17) -> -7.0378225e-05 | K32: =[1]!PCovar($B$6:$B$17,$I$6:$I$17,K$6:K$17) -> 0.0010917583 | L32: =[1]!PCovar($B$6:$B$17,$I$6:$I$17,L$6:L$17) -> 0.0003502926 | M32: =[1]!PCovar($B$6:$B$17,$I$6:$I$17,M$6:M$17) -> -0.00015578332 | N32: =[1]!PCovar($B$6:$B$17,$I$6:$I$17,N$6:N$17) -> -0.00029968518 | O32: =[1]!PCovar($B$6:$B$17,$I$6:$I$17,O$6:O$17) -> 0.0016802976 | P32: =[1]!PCovar($B$6:$B$17,$I$6:$I$17,P$6:P$17) -> 0.00031707852 | Q32: =[1]!PCovar($B$6:$B$17,$I$6:$I$17,Q$6:Q$17) -> 0.0001643577
A33: LPX | J33: =[1]!PCovar($B$6:$B$17,$J$6:$J$17,J$6:J$17) -> 0.0043138453 | K33: =[1]!PCovar($B$6:$B$17,$J$6:$J$17,K$6:K$17) -> 0.00018424924 | L33: =[1]!PCovar($B$6:$B$17,$J$6:$J$17,L$6:L$17) -> -0.0020161686 | M33: =[1]!PCovar($B$6:$B$17,$J$6:$J$17,M$6:M$17) -> 0.00085199312 | N33: =[1]!PCovar($B$6:$B$17,$J$6:$J$17,N$6:N$17) -> 0.0016640622 | O33: =[1]!PCovar($B$6:$B$17,$J$6:$J$17,O$6:O$17) -> 0.0018871474 | P33: =[1]!PCovar($B$6:$B$17,$J$6:$J$17,P$6:P$17) -> 0.00094382861 | Q33: =[1]!PCovar($B$6:$B$17,$J$6:$J$17,Q$6:Q$17) -> 0.004120856
A34: LUV | K34: =[1]!PCovar($B$6:$B$17,$K$6:$K$17,K$6:K$17) -> 0.0084460829 | L34: =[1]!PCovar($B$6:$B$17,$K$6:$K$17,L$6:L$17) -> 0.0019098806 | M34: =[1]!PCovar($B$6:$B$17,$K$6:$K$17,M$6:M$17) -> 0.00019477571 | N34: =[1]!PCovar($B$6:$B$17,$K$6:$K$17,N$6:N$17) -> 0.0015626864 | O34: =[1]!PCovar($B$6:$B$17,$K$6:$K$17,O$6:O$17) -> 0.0015802769 | P34: =[1]!PCovar($B$6:$B$17,$K$6:$K$17,P$6:P$17) -> 0.0010834329 | Q34: =[1]!PCovar($B$6:$B$17,$K$6:$K$17,Q$6:Q$17) -> 0.0015365237
A35: MO | L35: =[1]!PCovar($B$6:$B$17,$L$6:$L$17,L$6:L$17) -> 0.0054221414 | M35: =[1]!PCovar($B$6:$B$17,$L$6:$L$17,M$6:M$17) -> -0.00085936808 | N35: =[1]!PCovar($B$6:$B$17,$L$6:$L$17,N$6:N$17) -> 0.00072932404 | O35: =[1]!PCovar($B$6:$B$17,$L$6:$L$17,O$6:O$17) -> -0.001216632 | P35: =[1]!PCovar($B$6:$B$17,$L$6:$L$17,P$6:P$17) -> 0.00051981125 | Q35: =[1]!PCovar($B$6:$B$17,$L$6:$L$17,Q$6:Q$17) -> -0.0021896829
A36: MOB | M36: =[1]!PCovar($B$6:$B$17,$M$6:$M$17,M$6:M$17) -> 0.00041443441 | N36: =[1]!PCovar($B$6:$B$17,$M$6:$M$17,N$6:N$17) -> 0.00025805079 | O36: =[1]!PCovar($B$6:$B$17,$M$6:$M$17,O$6:O$17) -> 0.00022772695 | P36: =[1]!PCovar($B$6:$B$17,$M$6:$M$17,P$6:P$17) -> 0.0003044139 | Q36: =[1]!PCovar($B$6:$B$17,$M$6:$M$17,Q$6:Q$17) -> 0.0011221065
A37: MSFT | N37: =[1]!PCovar($B$6:$B$17,$N$6:$N$17,N$6:N$17) -> 0.0016575543 | O37: =[1]!PCovar($B$6:$B$17,$N$6:$N$17,O$6:O$17) -> 0.0010899478 | P37: =[1]!PCovar($B$6:$B$17,$N$6:$N$17,P$6:P$17) -> 0.00049794549 | Q37: =[1]!PCovar($B$6:$B$17,$N$6:$N$17,Q$6:Q$17) -> 0.0014848209
A38: PCG | O38: =[1]!PCovar($B$6:$B$17,$O$6:$O$17,O$6:O$17) -> 0.007386693 | P38: =[1]!PCovar($B$6:$B$17,$O$6:$O$17,P$6:P$17) -> 0.00030460154 | Q38: =[1]!PCovar($B$6:$B$17,$O$6:$O$17,Q$6:Q$17) -> 0.002050112
A39: PG | P39: =[1]!PCovar($B$6:$B$17,$P$6:$P$17,P$6:P$17) -> 0.0013124084 | Q39: =[1]!PCovar($B$6:$B$17,$P$6:$P$17,Q$6:Q$17) -> 0.00093080685
A40: X | Q40: =[1]!PCovar($B$6:$B$17,$Q$6:$Q$17,Q$6:Q$17) -> 0.005887203
A42: Correlation Matrix using Probabilities
C43: CMB | D43: COL | E43: F | F43: GLD | G43: HWP | H43: INTC | I43: KO | J43: LPX | K43: LUV | L43: MO | M43: MOB | N43: MSFT | O43: PCG | P43: PG | Q43: X
A44: CMB | C44: =[1]!PCorr($B$6:$B$17,$C$6:$C$17,C$6:C$17) -> 1 | D44: =[1]!PCorr($B$6:$B$17,$C$6:$C$17,D$6:D$17) -> 0.58951003 | E44: =[1]!PCorr($B$6:$B$17,$C$6:$C$17,E$6:E$17) -> -0.014055146 | F44: =[1]!PCorr($B$6:$B$17,$C$6:$C$17,F$6:F$17) -> 0.20691909 | G44: =[1]!PCorr($B$6:$B$17,$C$6:$C$17,G$6:G$17) -> 0.32765266 | H44: =[1]!PCorr($B$6:$B$17,$C$6:$C$17,H$6:H$17) -> 0.11527064 | I44: =[1]!PCorr($B$6:$B$17,$C$6:$C$17,I$6:I$17) -> 0.18159063 | J44: =[1]!PCorr($B$6:$B$17,$C$6:$C$17,J$6:J$17) -> 0.31375845 | ... Q44: =[1]!PCorr($B$6:$B$17,$C$6:$C$17,Q$6:Q$17) -> 0.55864584
...

Sheet Sheet2
A1: 3.7633333
A2: 1.7716667
A3: 1.455
A4: 2.9283333
A5: 2.1808333
A6: 7.5475
A7: 3.1358333
A8: -0.71416667
A9: 0.1175
A10: 2.5691667
A11: 1.0575
A12: 6.4808333
... A15: 0.77

Sheet Sheet3
A1: 41.622588 | B1: 21.804467 | C1: 1.9198727 | D1: 11.160288 | E1: 26.851442 | F1: 3.4368 | G1: 2.4304515 | H1: 14.139733 | I1: 41.941091 | J1: 0.97901212 | K1: 1.4303182 | L1: 7.328697 | M1: 23.245861 | N1: 8.4393303 | O1: 27.022409
A2: 21.804467 | B2: 42.181979 | C2: 7.7061182 | D2: 41.622385 | E2: 16.399826 | F2: -15.872995 | G2: 7.9801985 | H2: 29.361617 | I2: 16.174241 | J2: -10.955062 | K2: 6.8929045 | L2: 4.6536712 | M2: 8.7239712 | N2: 9.3366288 | O2: 45.769645
A3: 1.9198727 | B3: 7.7061182 | C3: 33.282409 | D3: 5.5742909 | E3: 15.475695 | F3: -0.050404545 | G3: -2.8620591 | H3: 16.699805 | I3: 4.3284864 | J3: -10.883695 | K3: 4.0140682 | L3: 8.8707227 | M3: -1.3362045 | N3: -5.4815227 | O3: 13.930373
A4: 11.160288 | B4: 41.622385 | C4: 5.5742909 | D4: 229.20563 | E4: -33.677026 | F4: -53.146586 | G4: 4.6432015 | H4: 14.917192 | I4: 3.7329682 | J4: 16.784944 | K4: -0.95978636 | L4: 3.4344833 | M4: -30.911517 | N4: -12.474683 | O4: 77.499282
A5: 26.851442 | B5: 16.399826 | C5: 15.475695 | D5: -33.677026 | E5: 131.05832 | F5: 52.996584 | G5: 6.6209674 | H5: 31.675504 | I5: 74.858593 | J5: 27.743819 | K5: 1.5252932 | L5: 35.217745 | M5: 17.807572 | N5: 17.345005 | O5: 20.7323
A6: 3.4368 | B6: -15.872995 | C6: -0.050404545 | D6: -53.146586 | E6: 52.996584 | F6: 71.89933 | G6: -5.1717295 | H6: 13.355034 | I6: -0.65053409 | J6: 19.030934 | K6: 0.712075 | L6: 21.497411 | M6: 32.811957 | N6: 14.348111 | O6: -6.8334273
A7: 2.4304515 | B7: 7.9801985 | C7: -2.8620591 | D7: 4.6432015 | E7: 6.6209674 | F7: -5.1717295 | G7: 20.608299 | H7: -3.1088826 | I7: 5.6723977 | J7: 2.4537417 | K7: -2.5758386 | L7: -4.4607144 | M7: 8.5980311 | N7: 0.31401894 | O7: -3.4465273
A8: 14.139733 | B8: 29.361617 | C8: 16.699805 | D8: 14.917192 | E8: 31.675504 | F8: 13.355034 | G8: -3.1088826 | H8: 48.507372 | I8: 7.5733977 | J8: -20.374849 | K8: 9.2270614 | L8: 15.808958 | M8: 17.559831 | N8: 13.860264 | O8: 46.201936
A9: 41.941091 | B9: 16.174241 | C9: 4.3284864 | D9: 3.7329682 | E9: 74.858593 | F9: -0.65053409 | G9: 5.6723977 | H9: 7.5733977 | I9: 104.28582 | J9: 22.883052 | K9: -0.38563409 | L9: 19.980675 | M9: 11.825302 | N9: 8.6727023 | O9: 20.582991
A10: 0.97901212 | B10: -10.955062 | C10: -10.883695 | D10: 16.784944 | E10: 27.743819 | F10: 19.030934 | G10: 2.4537417 | H10: -20.374849 | I10: 22.883052 | J10: 63.861172 | K10: -9.2777659 | L10: 11.473173 | M10: -8.9568992 | N10: 4.911422 | O10: -15.982082
A11: 1.4303182 | B11: 6.8929045 | C11: 4.0140682 | D11: -0.95978636 | E11: 1.5252932 | F11: 0.712075 | G11: -2.5758386 | H11: 9.2270614 | I11: -0.38563409 | J11: -9.2777659 | K11: 4.9780568 | L11: 2.2466568 | M11: 0.57042955 | N11: 4.0715477 | O11: 11.091373
A12: 7.328697 | B12: 4.6536712 | C12: 8.8707227 | D12: 3.4344833 | E12: 35.217745 | F12: 21.497411 | G12: -4.4607144 | H12: 15.808958 | I12: 19.980675 | J12: 11.473173 | K12: 2.2466568 | L12: 16.481408 | M12: 10.542481 | N12: 6.4765508 | O12: 15.327636
... A15: 27.022409 | B15: 45.769645 | C15: 13.930373 | D15: 77.499282 | E15: 20.7323 | F15: -6.8334273 | G15: -3.4465273 | H15: 46.201936 | I15: 20.582991 | J15: -15.982082 | K15: 11.091373 | L15: 15.327636 | M15: 12.511091 | N15: 11.095191 | O15: 71.688509

Sheet Sheet4
B1: 15.11 | C1: 9.67 | D1: 3.38 | E1: 35.05 | F1: 1.19 | G1: -2.6 | H1: 1.81 | I1: 5.73 | J1: 14.17 | K1: 3.88 | L1: -0.07 | M1: 8.71 | N1: -0.48 | O1: 1.39 | P1: 15.85
B2: 7.97 | C2: -1.57 | D2: 5.93 | E2: -4.58 | F2: 19.12 | G2: 6.48 | H2: 7.13 | I2: -9.31 | J2: 17.14 | K2: 6.74 | L2: -1.02 | M2: 6.69 | N2: -7.66 | O2: -2.09 | P2: -7.42
B3: -1.34 | C3: 5.48 | D3: 10 | E3: 2.4 | F3: -6.57 | G3: -3.3 | H3: 2.48 | I3: 5.41 | J3: -3.25 | K3: -11.36 | L3: 5.7 | M3: 4.5 | N3: -12.68 | O3: 3.35 | P3: 5.73
B4: -5.36 | C4: -7.96 | D4: 5.38 | E4: -7.03 | F4: 12.48 | G4: 19.19 | H4: -1.21 | I4: 3.14 | J4: 0.04 | K4: 3.85 | L4: 0.04 | M4: 12.86 | N4: 3.87 | O4: 0.18 | P4: -3.97
B5: 1.45 | C5: 1.41 | D5: 1.74 | E5: 2.52 | F5: 0.78 | G5: 11.44 | H5: 12.88 | I5: -1.5 | J5: -7.98 | K5: 10.26 | L5: -1.85 | M5: 4.86 | N5: 2.2 | O5: 3.99 | P5: -6.06
B6: 0.89 | C6: -0.46 | D6: -11.3 | E6: -7.38 | F6: -6.45 | G6: -2.73 | H6: 6.52 | I6: -10.15 | J6: 6.39 | K6: 4.65 | L6: -0.44 | M6: 1.16 | N6: 0 | O6: 3.13 | P6: -8.47
B7: -0.8 | C7: -4.37 | D7: 1.08 | E7: -8.5 | F7: -11.67 | G7: 2.37 | H7: -4.08 | I7: -6.71 | J7: -14.98 | K7: 1.56 | L7: -1 | M7: 0.98 | N7: -12.95 | O7: -1.08 | P7: -9.69
B8: 7.01 | C8: 10 | D8: 3.47 | E8: 0.97 | F8: -0.02 | G8: 6.24 | H8: 6.67 | I8: 6.1 | J8: -8.08 | K8: -14.22 | L8: 2.49 | M8: 3.92 | N8: 14.56 | O8: -0.42 | P8: 8.37
B9: 7.73 | C9: 0.89 | D9: -6.72 | E9: -3.85 | F9: 11.43 | G9: 19.58 | H9: 1.75 | I9: 4.6 | J9: 0.55 | K9: 0 | L9: 2.43 | M9: 7.65 | N9: -3.87 | O9: 9.7 | P9: 3.64
B10: 7.72 | C10: -5.99 | D10: 1.23 | E10: -5 | F10: -9.49 | G10: 15.18 | H10: -0.49 | I10: -7.63 | J10: -1.59 | K10: 4.26 | L10: 1.73 | M10: 6.8 | N10: 9.72 | O10: 2 | P10: -3.95
B11: 10.2 | C11: 12.28 | D11: 4.8 | E11: -3.16 | F11: 22.1 | G11: 15.47 | H11: 1.24 | I11: 8.38 | J11: 10.56 | K11: 11.77 | L11: 3.75 | M11: 14.3 | N11: 3.21 | O11: 9.85 | P11: 11.06
B12: -5.42 | C12: 1.88 | D12: -1.53 | E12: 33.7 | F12: -6.73 | G12: 3.25 | H12: 2.93 | I12: -6.63 | J12: -11.56 | K12: 9.44 | L12: 0.93 | M12: 5.34 | N12: -12.95 | O12: -1.03 | P12: 4.15
B20: Column 1 | C20: Column 2 | D20: Column 3 | E20: Column 4 | F20: Column 5 | G20: Column 6 | H20: Column 7 | I20: Column 8 | J20: Column 9 | K20: Column 10 | L20: Column 11 | M20: Column 12 | N20: Column 13 | O20: Column 14 | P20: Column 15
A21: Column 1 | B21: =VAR(Sheet4!$B$1:$B$12) -> 41.622588
A22: Column 2 | B22: 21.804467 | C22: =VAR(Sheet4!$C$1:$C$12) -> 42.181979
A23: Column 3 | B23: 1.9198727 | C23: 7.7061182 | D23: =VAR(Sheet4!$D$1:$D$12) -> 33.282409
A24: Column 4 | B24: 11.160288 | C24: 41.622385 | D24: 5.5742909 | E24: =VAR(Sheet4!$E$1:$E$12) -> 229.20563
A25: Column 5 | B25: 26.851442 | C25: 16.399826 | D25: 15.475695 | E25: -33.677026 | F25: =VAR(Sheet4!$F$1:$F$12) -> 131.05832
A26: Column 6 | B26: 3.4368 | C26: -15.872995 | D26: -0.050404545 | E26: -53.146586 | F26: 52.996584 | G26: =VAR(Sheet4!$G$1:$G$12) -> 71.89933
A27: Column 7 | B27: 2.4304515 | C27: 7.9801985 | D27: -2.8620591 | E27: 4.6432015 | F27: 6.6209674 | G27: -5.1717295 | H27: =VAR(Sheet4!$H$1:$H$12) -> 20.608299
A28: Column 8 | B28: 14.139733 | C28: 29.361617 | D28: 16.699805 | E28: 14.917192 | F28: 31.675504 | G28: 13.355034 | H28: -3.1088826 | I28: =VAR(Sheet4!$I$1:$I$12) -> 48.507372
A29: Column 9 | B29: 41.941091 | C29: 16.174241 | D29: 4.3284864 | E29: 3.7329682 | F29: 74.858593 | G29: -0.65053409 | H29: 5.6723977 | I29: 7.5733977 | J29: =VAR(Sheet4!$J$1:$J$12) -> 104.28582
A30: Column 10 | B30: 0.97901212 | C30: -10.955062 | D30: -10.883695 | E30: 16.784944 | F30: 27.743819 | G30: 19.030934 | H30: 2.4537417 | I30: -20.374849 | J30: 22.883052 | K30: =VAR(Sheet4!$K$1:$K$12) -> 63.861172
A31: Column 11 | B31: 1.4303182 | C31: 6.8929045 | D31: 4.0140682 | E31: -0.95978636 | F31: 1.5252932 | G31: 0.712075 | H31: -2.5758386 | I31: 9.2270614 | J31: -0.38563409 | K31: -9.2777659 | L31: =VAR(Sheet4!$L$1:$L$12) -> 4.9780568
A32: Column 12 | B32: 7.328697 | C32: 4.6536712 | D32: 8.8707227 | E32: 3.4344833 | F32: 35.217745 | G32: 21.497411 | H32: -4.4607144 | I32: 15.808958 | J32: 19.980675 | K32: 11.473173 | L32: 2.2466568 | M32: =VAR(Sheet4!$M$1:$M$12) -> 16.481408
A33: Column 13 | B33: 23.245861 | C33: 8.7239712 | D33: -1.3362045 | E33: -30.911517 | F33: 17.807572 | G33: 32.811957 | H33: 8.5980311 | I33: 17.559831 | J33: 11.825302 | K33: -8.9568992 | L33: 0.57042955 | M33: 10.542481 | N33: =VAR(Sheet4!$N$1:$N$12) -> 80.226808
A34: Column 14 | B34: 8.4393303 | C34: 9.3366288 | D34: -5.4815227 | E34: -12.474683 | F34: 17.345005 | G34: 14.348111 | H34: 0.31401894 | I34: 13.860264 | J34: 8.6727023 | K34: 4.911422 | L34: 4.0715477 | M34: 6.4765508 | N34: 5.2891689 | O34: =VAR(Sheet4!$O$1:$O$12) -> 15.531808
A35: Column 15 | B35: 27.022409 | C35: 45.769645 | D35: 13.930373 | E35: 77.499282 | F35: 20.7323 | G35: -6.8334273 | H35: -3.4465273 | I35: 46.201936 | J35: 20.582991 | K35: -15.982082 | L35: 11.091373 | M35: 15.327636 | N35: 12.511091 | O35: 11.095191 | P35: =VAR(Sheet4!$P$1:$P$12) -> 71.688509

Sheet Sheet5

Sheet Sheet6

Sheet Sheet7

Sheet Sheet8

Sheet Sheet9

Sheet Sheet10

Sheet Sheet11

Sheet Sheet12

Sheet Sheet13

Sheet Sheet14

Sheet Sheet15

Sheet Sheet16
