Workbook

Sheet Sheet1
A1: FINPACK Balance Sheet | F1: *=input
D2: Debt Level
C3: Low | D3: Medium | E3: High
A4: Current Farm Assets | C4: 431000 | D4: 431000 | E4: 431000 | F4: *
A5: Intermed. Farm Assets | B5: + | C5: 616000 | D5: 616000 | E5: 616000 | F5: *
A6: Long Term Farm Assets | B6: + | C6: 974000 | D6: 974000 | E6: 974000 | F6: *
A7: Total Farm Assets | B7: = | C7: =SUM(C4:C6) -> 2021000 | D7: =SUM(D4:D6) -> 2021000 | E7: =SUM(E4:E6) -> 2021000
A9: Current Farm Liabilities | C9: 50782 | D9: 311689 | E9: 376586 | F9: *
A10: Intermed. Farm Liabilities | B10: + | C10: 82014 | D10: 253300 | E10: 412502 | F10: *
A11: Long Term Farm Liabilites | B11: + | C11: 271458 | D11: 344461 | E11: 524562 | F11: *
A12: Total Liablilities | B12: = | C12: =C9+C10+C11 -> 404254 | D12: =D9+D10+D11 -> 909450 | E12: =E9+E10+E11 -> 1313650
A14: Equity | C14: =C7-C12 -> 1616746 | D14: =D7-D12 -> 1111550 | E14: =E7-E12 -> 707350
A15: Debt to Asset Ratio | C15: =C12/C7*100 -> 20.002672 | D15: =D12/D7*100 -> 45 | E15: =E12/E7*100 -> 65
A16: Equity to Asset Ratio | C16: =C14/C7*100 -> 79.997328 | D16: =D14/D7*100 -> 55 | E16: =E14/E7*100 -> 35
A20: Total Cash Farm Exp. | B20: - | C20: 417521 | D20: 456755 | E20: 496216 | F20: *
A21: Income Statement
D22: Debt Level
C23: Low | D23: Medium | E23: High
A24: Gross Farm Income | B24: + | C24: 550434 | D24: 550434 | E24: 550434 | F24: *
A25: Non Interest Cash Exp. | B25: - | C25: =C20-C26 -> 386945 | D25: =D20-D26 -> 386945 | E25: =E20-E26 -> 386945
A26: Interest Expense | B26: - | C26: 30576 | D26: 69810 | E26: 109271 | F26: *
A27: Net Cash Farm Income | B27: = | C27: =C24-C25-C26 -> 132913 | D27: =D24-D25-D26 -> 93679 | E27: =E24-E25-E26 -> 54218
A28: Inventory/Accrual Adj. | B28: + | C28: 0 | D28: 0 | E28: 0
A29: Net Operating Profit | B29: = | C29: =C27-C28 -> 132913 | D29: =D27-D28 -> 93679 | E29: =E27-E28 -> 54218
A30: Depreciation | B30: - | C30: 60000 | D30: 60000 | E30: 60000
A31: Net Farm Income | B31: = | C31: =C29-C30 -> 72913 | D31: =D29-D30 -> 33679 | E31: =E29-E30 -> -5782 | F31: *
A35: Cash Flow Statement
D36: Debt Level
C37: Low | D37: Medium | E37: High
A38: Net Cash Farm Income | B38: + | C38: =C27 -> 132913 | D38: =D27 -> 93679 | E38: =E27 -> 54218
A39: Nonfarm Income | B39: + | C39: 0 | D39: 0 | E39: 0
A40: Net Cash Available | B40: = | C40: =C38-C39 -> 132913 | D40: =D38-D39 -> 93679 | E40: =E38-E39 -> 54218
A41: Family Living | B41: - | C41: 30000 | D41: 30000 | E41: 30000 | F41: *
A42: Income Taxes & Social Security | B42: - | C42: 23550 | D42: 8945 | E42: 0 | F42: *
A43: Cash Avail. for Princ. Payments | B43: = | C43: =C40-C41-C42 -> 79363 | D43: =D40-D41-D42 -> 54734 | E43: =E40-E41-E42 -> 24218
A44: Farm Interest Paid | B44: + | C44: =C26 -> 30576 | D44: =D26 -> 69810 | E44: =E26 -> 109271
A45: Cash Avail. for P& I Payments | B45: = | C45: =C43+C44 -> 109939 | D45: =D43+D44 -> 124544 | E45: =E43+E44 -> 133489
A46: Total Sched. Principal & Interest | B46: - | C46: 58655 | D46: 178601 | E46: 176312 | F46: *
A47: Cash Avail. after Loan Payments | B47: = | C47: =C45-C46 -> 51284 | D47: =D45-D46 -> -54057 | E47: =E45-E46 -> -42823
A48: Cash Required for Replacement | B48: - | C48: 40978 | D48: 0 | E48: 13521 | F48: *
...

Sheet Sheet2 (3)
A1: COST OF PRODUCTION WORKSHEET - Page 2
A2: Low Debt Farm
B3: CORN | C3: SOYS | D3: WHEAT | E3: OTHER1 | F3: OTHER2 | G3: OTHER3 | H3: OTHER4
A4: 1. Paid on Yield per Acre in Bushels | B4: 128.5 | C4: 43 | D4: Bu______ | E4: Bu______ | F4: Bu______ | G4: Bu______ | H4: Bu______
A5: 2. TIMES Selling Price per Bu x | B5: =Sheet1!C223 -> 2 | C5: =Sheet1!D223 -> 5.3 | D5: $________ | E5: $________ | F5: $________ | G5: $________ | H5: $________
A6: 3. EQUALS Gross Income per Acre = | B6: =B4*B5 -> 257 | C6: =C4*C5 -> 227.9 | D6: =D4*D5 -> #VALUE! | E6: =E4*E5 -> #VALUE! | F6: =F4*F5 -> #VALUE! | G6: =G4*G5 -> #VALUE! | H6: =H4*H5 -> #VALUE!
A8: DIRECT COST/AC
A9: 4. Seed | B9: 25 | C9: 26.4 | D9: $________ | E9: $________ | F9: $________ | G9: $________ | H9: $________
A10: 5. Fertilizer | B10: 54.8 | C10: 13 | D10: $________ | E10: $________ | F10: $________ | G10: $________ | H10: $________
A11: 6. Herbicides | B11: 20.35 | C11: 18.75 | D11: $________ | E11: $________ | F11: $________ | G11: $________ | H11: $________
A12: 7. Insecticides | B12: $__________ | C12: $__________ | D12: $________ | E12: $________ | F12: $________ | G12: $________ | H12: $________
A13: 8. Drying Fuel | B13: 7 | C13: $__________ | D13: $________ | E13: $________ | F13: $________ | G13: $________ | H13: $________
A14: 9. Crop Fuel & Oil | B14: 9.35 | C14: 7.5 | D14: $________ | E14: $________ | F14: $________ | G14: $________ | H14: $________
A15: 10. Crop Repairs | B15: 23.6 | C15: 20.2 | D15: $________ | E15: $________ | F15: $________ | G15: $________ | H15: $________
A16: 12. Crop Utilities | B16: 2.4 | C16: 1.5 | D16: $________ | E16: $________ | F16: $________ | G16: $________ | H16: $________
A17: 13. Crop Haul & Truck | B17: 15.42 | C17: 5.16 | D17: $________ | E17: $________ | F17: $________ | G17: $________ | H17: $________
A18: 14. Crop Marketing | B18: $__________ | C18: 1.72 | D18: $________ | E18: $________ | F18: $________ | G18: $________ | H18: $________
A19: 15. Crop Insurance | B19: $__________ | C19: $__________ | D19: $________ | E19: $________ | F19: $________ | G19: $________ | H19: $________
A20: 16. Other | B20: $__________ | C20: $__________ | D20: $________ | E20: $________ | F20: $________ | G20: $________ | H20: $________
A21: 17. TOTAL DIRECT COST/Ac | B21: =SUM(B9:B20) -> 157.92 | C21: =SUM(C9:C20) -> 94.23 | D21: =SUM(D9:D20) -> 0 | E21: =SUM(E9:E20) -> 0 | F21: =SUM(F9:F20) -> 0 | G21: =SUM(G9:G20) -> 0 | H21: =SUM(H9:H20) -> 0
A23: 18. GROSS MARGIN=G.I.-D.C./Ac | B23: =IF(B21>0,(B6-B21),0) -> 99.08 | C23: =IF(C21>0,(C6-C21),0) -> 133.67 | D23: =IF(D21>0,(D6-D21),0) -> 0 | E23: =IF(E21>0,(E6-E21),0) -> 0 | F23: =IF(F21>0,(F6-F21),0) -> 0 | G23: =IF(G21>0,(G6-G21),0) -> 0 | H23: =IF(H21>0,(H6-H21),0) -> 0
A24: For each crop (line 3) MINUS (line 17)
A25: OVERHEAD COSTS for Farm | B25: Column 1 | C25: 1.Gross Margin can be used in determining which crops will contribute
A26: 19. Acres Cropped | B26: =SUM(B53:H53) -> 2000 | C26: more toward Overhead Cost.
A27: 20. Interest | B27: 25498 | C27: 2. Accounting Costs of Production is the summation of direct
A28: 21. Hired Labor | B28: 25000 | C28: variable (or allocable) and of overhead (or non-allocable) cost.
A29: 22. Land Rents | B29: 82500 | C29: 3. Economic Costs is the summation of total accounting costs plus
A30: 23. Machinery Leases | B30: 0 | C30: the opportunity costs of resources used in the business; e.g. for
A31: 24. Real Estate Taxes | B31: 14100 | C31: equity capital and for unpaid family labor. Being able to price a
A32: 25. Farm Insurance | B32: 12000 | C32: commodity at your economic cost would provide the returns to unpaid
A33: 26. Farm Utilities | B33: 1200 | C33: resources (lines 30 and 31). Selling at less than the economic cost
A34: 27. Other Expenses | B34: 0 | C34: indicates that the price received is not adequate to earn the desired
A35: 28. Depreciation | B35: 60000 | C35: rates of return on unpaid resources.
A36: 29. Total Accounting Overhead Cost | B36: =SUM(B27:B35) -> 220298 | C36: ADD (lines 20 through lines 28)
A38: 30. Value of Unpaid Labor | B38: 45786 | C38: 4.Economic Cost includes a value for any unpaid labor.
A39: 31. Value of Unpaid Equity Capital | B39: =0.06*Sheet1!C14 -> 97004.76 | C39: 5.Economic Cost includes opportunity cost of Equity. (6%? of Net Worth)
A40: 32. Total Economic Overhead Cost | B40: =SUM(B36:B39) -> 363088.76 | C40: ADD(lines 29, 30 and 31)
A42: 33. Total Economic Overhead Cost/Ac | B42: =B40/B26 -> 181.54438 | C42: (line 32) DIVIDED BY (line 19)
B44: =B3 -> CORN | C44: =C3 -> SOYS | D44: =D3 -> WHEAT | E44: =E3 -> OTHER1 | F44: =F3 -> OTHER2 | G44: =G3 -> OTHER3 | H44: =H3 -> OTHER4
A45: 34. Total Economic Costs/Ac | B45: =IF(B21>0,(B21+$B42),0) -> 339.46438 | C45: =IF(C21>0,(C21+$B42),0) -> 275.77438 | D45: =IF(D21>0,(D21+$B42),0) -> 0 | E45: =IF(E21>0,(E21+$B42),0) -> 0 | F45: =IF(F21>0,(F21+$B42),0) -> 0 | G45: =IF(G21>0,(G21+$B42),0) -> 0 | H45: =IF(H21>0,(H21+$B42),0) -> 0
...

Sheet Sheet2 (4)
A1: COST OF PRODUCTION WORKSHEET - Page 2
A2: Medium Debt Farm
A3: Medium Debt Farm | B3: CORN | C3: SOYS | D3: WHEAT | E3: OTHER1 | F3: OTHER2 | G3: OTHER3 | H3: OTHER4
A4: 1. Paid on Yield per Acre in Bushels | B4: 128.5 | C4: 43 | D4: Bu______ | E4: Bu______ | F4: Bu______ | G4: Bu______ | H4: Bu______
A5: 2. TIMES Selling Price per Bu x | B5: =Sheet1!C223 -> 2 | C5: =Sheet1!D223 -> 5.3 | D5: $________ | E5: $________ | F5: $________ | G5: $________ | H5: $________
A6: 3. EQUALS Gross Income per Acre = | B6: =B4*B5 -> 257 | C6: =C4*C5 -> 227.9 | D6: =D4*D5 -> #VALUE! | E6: =E4*E5 -> #VALUE! | F6: =F4*F5 -> #VALUE! | G6: =G4*G5 -> #VALUE! | H6: =H4*H5 -> #VALUE!
A8: DIRECT COST/AC
A9: 4. Seed | B9: 25 | C9: 26.4 | D9: $________ | E9: $________ | F9: $________ | G9: $________ | H9: $________
A10: 5. Fertilizer | B10: 54.8 | C10: 13 | D10: $________ | E10: $________ | F10: $________ | G10: $________ | H10: $________
A11: 6. Herbicides | B11: 20.35 | C11: 18.75 | D11: $________ | E11: $________ | F11: $________ | G11: $________ | H11: $________
A12: 7. Insecticides | B12: $__________ | C12: $__________ | D12: $________ | E12: $________ | F12: $________ | G12: $________ | H12: $________
A13: 8. Drying Fuel | B13: 7 | C13: $__________ | D13: $________ | E13: $________ | F13: $________ | G13: $________ | H13: $________
A14: 9. Crop Fuel & Oil | B14: 9.35 | C14: 7.5 | D14: $________ | E14: $________ | F14: $________ | G14: $________ | H14: $________
A15: 10. Crop Repairs | B15: 23.6 | C15: 20.2 | D15: $________ | E15: $________ | F15: $________ | G15: $________ | H15: $________
A16: 12. Crop Utilities | B16: 2.4 | C16: 1.5 | D16: $________ | E16: $________ | F16: $________ | G16: $________ | H16: $________
A17: 13. Crop Haul & Truck | B17: 15.42 | C17: 5.16 | D17: $________ | E17: $________ | F17: $________ | G17: $________ | H17: $________
A18: 14. Crop Marketing | B18: $__________ | C18: 1.72 | D18: $________ | E18: $________ | F18: $________ | G18: $________ | H18: $________
A19: 15. Crop Insurance | B19: $__________ | C19: $__________ | D19: $________ | E19: $________ | F19: $________ | G19: $________ | H19: $________
A20: 16. Other | B20: $__________ | C20: $__________ | D20: $________ | E20: $________ | F20: $________ | G20: $________ | H20: $________
A21: 17. TOTAL DIRECT COST/Ac | B21: =SUM(B9:B20) -> 157.92 | C21: =SUM(C9:C20) -> 94.23 | D21: =SUM(D9:D20) -> 0 | E21: =SUM(E9:E20) -> 0 | F21: =SUM(F9:F20) -> 0 | G21: =SUM(G9:G20) -> 0 | H21: =SUM(H9:H20) -> 0
A23: 18. GROSS MARGIN=G.I.-D.C./Ac | B23: =IF(B21>0,(B6-B21),0) -> 99.08 | C23: =IF(C21>0,(C6-C21),0) -> 133.67 | D23: =IF(D21>0,(D6-D21),0) -> 0 | E23: =IF(E21>0,(E6-E21),0) -> 0 | F23: =IF(F21>0,(F6-F21),0) -> 0 | G23: =IF(G21>0,(G6-G21),0) -> 0 | H23: =IF(H21>0,(H6-H21),0) -> 0
A24: For each crop (line 3) MINUS (line 17)
A25: OVERHEAD COSTS for Farm | B25: Column 1 | C25: 1.Gross Margin can be used in determining which crops will contribute
A26: 19. Acres Cropped | B26: =SUM(B52:H52) -> 2000 | C26: more toward Overhead Cost.
A27: 20. Interest | B27: =Sheet1!D190 -> 69810 | C27: 2. Accounting Costs of Production is the summation of direct
A28: 21. Hired Labor | B28: 25000 | C28: variable (or allocable) and of overhead (or non-allocable) cost.
A29: 22. Land Rents | B29: 82500 | C29: 3. Economic Costs is the summation of total accounting costs plus
A30: 23. Machinery Leases | B30: 0 | C30: the opportunity costs of resources used in the business; e.g. for
A31: 24. Real Estate Taxes | B31: 14100 | C31: equity capital and for unpaid family labor. Being able to price a
A32: 25. Farm Insurance | B32: 12000 | C32: commodity at your economic cost would provide the returns to unpaid
A33: 26. Farm Utilities | B33: 1200 | C33: resources (lines 30 and 31). Selling at less than the economic cost
A34: 27. Other Expenses | B34: 0 | C34: indicates that the price received is not adequate to earn the desired
A35: 28. Depreciation | B35: 60000 | C35: rates of return on unpaid resources.
A36: 29. Total Accounting Overhead Cost | B36: =SUM(B27:B35) -> 264610 | C36: ADD (lines 20 through lines 28)
A38: 30. Value of Unpaid Labor | B38: =Sheet1!D182 -> 45022 | C38: 4.Economic Cost includes a value for any unpaid labor.
A39: 31. Value of Unpaid Equity Capital | B39: =(0.06*Sheet1!D14) -> 66693 | C39: 5.Economic Cost includes opportunity cost of Equity. (6%? of Net Worth)
A40: 32. Total Economic Overhead Cost | B40: =SUM(B36:B39) -> 376325 | C40: ADD(lines 29, 30 and 31)
A42: 33. Total Economic Overhead Cost/Ac | B42: =B40/B26 -> 188.1625 | C42: (line 32) DIVIDED BY (line 19)
B44: =B3 -> CORN | C44: =C3 -> SOYS | D44: =D3 -> WHEAT | E44: =E3 -> OTHER1 | F44: =F3 -> OTHER2 | G44: =G3 -> OTHER3 | H44: =H3 -> OTHER4
A45: 34. Total Economic Costs/Ac | B45: =IF(B21>0,(B21+$B42),0) -> 346.0825 | C45: =IF(C21>0,(C21+$B42),0) -> 282.3925 | D45: =IF(D21>0,(D21+$B42),0) -> 0 | E45: =IF(E21>0,(E21+$B42),0) -> 0 | F45: =IF(F21>0,(F21+$B42),0) -> 0 | G45: =IF(G21>0,(G21+$B42),0) -> 0 | H45: =IF(H21>0,(H21+$B42),0) -> 0
...

Sheet Sheet2 (5)
A1: COST OF PRODUCTION WORKSHEET - Page 2
A2: High Debt Farm
B3: CORN | C3: SOYS | D3: WHEAT | E3: OTHER1 | F3: OTHER2 | G3: OTHER3 | H3: OTHER4
A4: 1. Paid on Yield per Acre in Bushels | B4: 128.5 | C4: 43 | D4: Bu______ | E4: Bu______ | F4: Bu______ | G4: Bu______ | H4: Bu______
A5: 2. TIMES Selling Price per Bu x | B5: 2 | C5: =Sheet1!D223 -> 5.3 | D5: $________ | E5: $________ | F5: $________ | G5: $________ | H5: $________
A6: 3. EQUALS Gross Income per Acre = | B6: =B4*B5 -> 257 | C6: =C4*C5 -> 227.9 | D6: =D4*D5 -> #VALUE! | E6: =E4*E5 -> #VALUE! | F6: =F4*F5 -> #VALUE! | G6: =G4*G5 -> #VALUE! | H6: =H4*H5 -> #VALUE!
A8: DIRECT COST/AC
A9: 4. Seed | B9: 25 | C9: 26.4 | D9: $________ | E9: $________ | F9: $________ | G9: $________ | H9: $________
A10: 5. Fertilizer | B10: 54.8 | C10: 13 | D10: $________ | E10: $________ | F10: $________ | G10: $________ | H10: $________
A11: 6. Herbicides | B11: 20.35 | C11: 18.75 | D11: $________ | E11: $________ | F11: $________ | G11: $________ | H11: $________
A12: 7. Insecticides | B12: $__________ | C12: $__________ | D12: $________ | E12: $________ | F12: $________ | G12: $________ | H12: $________
A13: 8. Drying Fuel | B13: 7 | C13: $__________ | D13: $________ | E13: $________ | F13: $________ | G13: $________ | H13: $________
A14: 9. Crop Fuel & Oil | B14: 9.35 | C14: 7.5 | D14: $________ | E14: $________ | F14: $________ | G14: $________ | H14: $________
A15: 10. Crop Repairs | B15: 23.6 | C15: 20.2 | D15: $________ | E15: $________ | F15: $________ | G15: $________ | H15: $________
A16: 12. Crop Utilities | B16: 2.4 | C16: 1.5 | D16: $________ | E16: $________ | F16: $________ | G16: $________ | H16: $________
A17: 13. Crop Haul & Truck | B17: 15.42 | C17: 5.16 | D17: $________ | E17: $________ | F17: $________ | G17: $________ | H17: $________
A18: 14. Crop Marketing | B18: $__________ | C18: 1.72 | D18: $________ | E18: $________ | F18: $________ | G18: $________ | H18: $________
A19: 15. Crop Insurance | B19: $__________ | C19: $__________ | D19: $________ | E19: $________ | F19: $________ | G19: $________ | H19: $________
A20: 16. Other | B20: $__________ | C20: $__________ | D20: $________ | E20: $________ | F20: $________ | G20: $________ | H20: $________
A21: 17. TOTAL DIRECT COST/Ac | B21: =SUM(B9:B20) -> 157.92 | C21: =SUM(C9:C20) -> 94.23 | D21: =SUM(D9:D20) -> 0 | E21: =SUM(E9:E20) -> 0 | F21: =SUM(F9:F20) -> 0 | G21: =SUM(G9:G20) -> 0 | H21: =SUM(H9:H20) -> 0
A23: 18. GROSS MARGIN=G.I.-D.C./Ac | B23: =IF(B21>0,(B6-B21),0) -> 99.08 | C23: =IF(C21>0,(C6-C21),0) -> 133.67 | D23: =IF(D21>0,(D6-D21),0) -> 0 | E23: =IF(E21>0,(E6-E21),0) -> 0 | F23: =IF(F21>0,(F6-F21),0) -> 0 | G23: =IF(G21>0,(G6-G21),0) -> 0 | H23: =IF(H21>0,(H6-H21),0) -> 0
A24: For each crop (line 3) MINUS (line 17)
A25: OVERHEAD COSTS for Farm | B25: Column 1 | C25: 1.Gross Margin can be used in determining which crops will contribute
A26: 19. Acres Cropped | B26: =SUM(B54:H54) -> 2000 | C26: more toward Overhead Cost.
A27: 20. Interest | B27: =Sheet1!E44 -> 109271 | C27: 2. Accounting Costs of Production is the summation of direct
A28: 21. Hired Labor | B28: 25000 | C28: variable (or allocable) and of overhead (or non-allocable) cost.
A29: 22. Land Rents | B29: 82500 | C29: 3. Economic Costs is the summation of total accounting costs plus
A30: 23. Machinery Leases | B30: 0 | C30: the opportunity costs of resources used in the business; e.g. for
A31: 24. Real Estate Taxes | B31: 14100 | C31: equity capital and for unpaid family labor. Being able to price a
A32: 25. Farm Insurance | B32: 12000 | C32: commodity at your economic cost would provide the returns to unpaid
A33: 26. Farm Utilities | B33: 1200 | C33: resources (lines 30 and 31). Selling at less than the economic cost
A34: 27. Other Expenses | B34: 0 | C34: indicates that the price received is not adequate to earn the desired
A35: 28. Depreciation | B35: 60000 | C35: rates of return on unpaid resources.
A36: 29. Total Accounting Overhead Cost | B36: =SUM(B27:B35) -> 304071 | C36: ADD (lines 20 through lines 28)
A38: 30. Value of Unpaid Labor | B38: =Sheet1!E182 -> 45022 | C38: 4.Economic Cost includes a value for any unpaid labor.
A39: 31. Value of Unpaid Equity Capital | B39: =0.06*Sheet1!E14 -> 42441 | C39: 5.Economic Cost includes opportunity cost of Equity. (6%? of Net Worth)
A40: 32. Total Economic Overhead Cost | B40: =SUM(B36:B39) -> 391534 | C40: ADD(lines 29, 30 and 31)
A42: 33. Total Economic Overhead Cost/Ac | B42: =B40/B26 -> 195.767 | C42: (line 32) DIVIDED BY (line 19)
B45: =B3 -> CORN | C45: =C3 -> SOYS | D45: =D3 -> WHEAT | E45: =E3 -> OTHER1 | F45: =F3 -> OTHER2 | G45: =G3 -> OTHER3 | H45: =H3 -> OTHER4
A46: 34. Total Economic Costs/Ac | B46: =IF(B21>0,(B21+$B42),0) -> 353.687 | C46: =IF(C21>0,(C21+$B42),0) -> 289.997 | D46: =IF(D21>0,(D21+$B42),0) -> 0 | E46: =IF(E21>0,(E21+$B42),0) -> 0 | F46: =IF(F21>0,(F21+$B42),0) -> 0 | G46: =IF(G21>0,(G21+$B42),0) -> 0 | H46: =IF(H21>0,(H21+$B42),0) -> 0
...
