Workbook

Sheet Correlation Matrix
D1: TIMMS GRADES 5 -8
C2: =VLOOKUP(C4,Sheet2!$A1:$B107,2,FALSE) -> Algebra | D2: =VLOOKUP(D4,Sheet2!$A1:$B107,2,FALSE) -> Algebra | E2: =VLOOKUP(E4,Sheet2!$A1:$B107,2,FALSE) -> Algebra | F2: =VLOOKUP(F4,Sheet2!$A1:$B107,2,FALSE) -> Algebra | G2: =VLOOKUP(G4,Sheet2!$A1:$B107,2,FALSE) -> Algebra | H2: =VLOOKUP(H4,Sheet2!$A1:$B107,2,FALSE) -> Algebra | I2: =VLOOKUP(I4,Sheet2!$A1:$B107,2,FALSE) -> Algebra | J2: =VLOOKUP(J4,Sheet2!$A1:$B107,2,FALSE) -> Algebra | ... DA2: =VLOOKUP(DA4,Sheet2!$A1:$B107,2,FALSE) -> Proportionality
C3: 1 | D3: =C3+1 -> 2 | E3: =D3+1 -> 3 | F3: =E3+1 -> 4 | G3: =F3+1 -> 5 | H3: =G3+1 -> 6 | I3: =H3+1 -> 7 | J3: =I3+1 -> 8 | K3: =J3+1 -> 9 | ... DA3: =CZ3+1 -> 103
C4: I-01 | D4: I-04 | E4: J-18 | F4: K-04 | G4: L-11 | H4: L-16 | I4: N-13 | J4: O-07 | K4: P-10 | L4: P-15 | M4: Q-01 | N4: Q-02 | O4: Q-07 | P4: R-11 | Q4: S01a | R4: S01b | S4: T01a | T4: T01b | U4: I-09 | V4: J-13 | W4: K-07 | X4: L-10 | Y4: M-03 | Z4: N-18 | AA4: O-01 | AB4: O-05 | AC4: Q-04 | AD4: R-08 | AE4: V-02 | AF4: P-17 | AG4: I-02 | AH4: I-05 | AI4: I-06 | AJ4: I-07 | AK4: J-12 | AL4: J-14 | AM4: J-17 | AN4: K-01 | AO4: K-02 | AP4: K-06 | AQ4: K-09 | AR4: L-08 | AS4: L-09 | AT4: L-17 | AU4: M-04 | AV4: M-08 | AW4: N-11 | AX4: N-14 | AY4: N-16 | AZ4: N-17 | BA4: N-19 | BB4: O-09 | BC4: P-12 | BD4: P-13 | BE4: P-14 | BF4: P-16 | BG4: Q-06 | BH4: Q-08 | BI4: Q-09 | BJ4: R-07 | BK4: R-12 | BL4: R-13 | BM4: U-01a | BN4: U-01b | BO4: V-01 | BP4: I-08 | BQ4: J-11 | BR4: J-15 | BS4: J-16 | BT4: K-03 | BU4: K-08 | BV4: L-15 | BW4: M-02 | BX4: M-05 | BY4: M-07 | BZ4: N-12 | CA4: O-03 | CB4: O-08 | CC4: P-08 | CD4: P-09 | CE4: Q-10 | CF4: R-10 | CG4: O-03 | CH4: I-03 | CI4: J-10 | CJ4: K-05 | CK4: L-13 | CL4: M-01 | CM4: N-15 | CN4: O-06 | CO4: P-11 | CP4: Q-03 | CQ4: S02a | CR4: S02b | CS4: S02c | CT4: U02a | CU4: U02b | CV4: V-04 | CW4: L-14 | CX4: R-14 | CY4: T02a | CZ4: T02b | DA4: V-03
A5: Problem Solving | B5: 1.1 | G5: X | AY5: X | BB5: X | BE5: X | CJ5: X | CQ5: X | CR5: X | CS5: X | CT5: X | DB5: {=SUM(IF(C5:DA5<>"",1,0))} -> 9
A6: Problem Solving | B6: 1.2 | P6: X | AH6: X | DB6: {=SUM(IF(C6:DA6<>"",1,0))} -> 2
A7: Problem Solving | B7: 1.3 | D7: X | G7: X | P7: X | R7: X | S7: X | T7: X | V7: X | X7: X | AA7: X | AC7: X | AD7: X | AE7: X | AF7: X | AG7: X | AJ7: X | AY7: X | BB7: X | BE7: X | BG7: X | BL7: X | BY7: X | CJ7: X | CQ7: X | CR7: X | CS7: X | CT7: X | CX7: X | CY7: X | CZ7: X | DB7: {=SUM(IF(C7:DA7<>"",1,0))} -> 29
A8: Problem Solving | B8: 1.4 | AG8: X | CX8: X | DB8: {=SUM(IF(C8:DA8<>"",1,0))} -> 2
A9: Problem Solving | B9: 1.5 | G9: X | S9: X | AD9: X | AE9: X | AY9: X | BB9: X | BE9: X | CJ9: X | CQ9: X | CR9: X | CS9: X | CT9: X | CY9: X | CZ9: X | DB9: {=SUM(IF(C9:DA9<>"",1,0))} -> 14
A10: Problem Solving | B10: 1.6 | P10: X | S10: X | AH10: X | DB10: {=SUM(IF(C10:DA10<>"",1,0))} -> 3 | DC10: =SUM(DB5:DB10) -> 59
A11: Communication | B11: 2.1 | E11: X | G11: X | K11: X | M11: X | S11: X | T11: X | AA11: X | AN11: X | AU11: X | AY11: X | BB11: X | BE11: X | BF11: X | BP11: X | BY11: X | CJ11: X | CQ11: X | CX11: X | DB11: {=SUM(IF(C11:DA11<>"",1,0))} -> 18
A12: Communication | B12: 2.2 | T12: X | DB12: {=SUM(IF(C12:DA12<>"",1,0))} -> 1
A13: Communication | B13: 2.3 | DB13: {=SUM(IF(C13:DA13<>"",1,0))} -> 0
A14: Communication | B14: 2.4 | V14: X | AC14: X | AS14: X | CU14: X | DA14: X | DB14: {=SUM(IF(C14:DA14<>"",1,0))} -> 5
A15: Communication | B15: 2.5 | T15: X | DB15: {=SUM(IF(C15:DA15<>"",1,0))} -> 1
A16: Communication | B16: 2.6 | Z16: X | AB16: X | DB16: {=SUM(IF(C16:DA16<>"",1,0))} -> 2 | DC16: =SUM(DB11:DB16) -> 27
A17: Reasoning | B17: 3.1 | DB17: {=SUM(IF(C17:DA17<>"",1,0))} -> 0
A18: Reasoning | B18: 3.2 | R18: X | AC18: X | CQ18: X | CR18: X | CS18: X | CT18: X | CX18: X | CY18: X | CZ18: X | DB18: {=SUM(IF(C18:DA18<>"",1,0))} -> 9
A19: Reasoning | B19: 3.3 | T19: X | DB19: {=SUM(IF(C19:DA19<>"",1,0))} -> 1
A20: Reasoning | B20: 3.4 | T20: X | AC20: X | CX20: X | DB20: {=SUM(IF(C20:DA20<>"",1,0))} -> 3
A21: Reasoning | B21: 3.5 | T21: X | AC21: X | CQ21: X | CR21: X | CS21: X | CT21: X | DB21: {=SUM(IF(C21:DA21<>"",1,0))} -> 6 | DC21: =SUM(DB17:DB21) -> 19
A22: Connections | B22: 4.1 | K22: X | M22: X | R22: X | T22: X | AA22: X | AJ22: X | BP22: X | CQ22: X | CR22: X | CS22: X | CT22: X | DB22: {=SUM(IF(C22:DA22<>"",1,0))} -> 11
A23: Connections | B23: 4.2 | E23: X | G23: X | K23: X | M23: X | S23: X | T23: X | AA23: X | AG23: X | AN23: X | AU23: X | AY23: X | BB23: X | BE23: X | BF23: X | BP23: X | BY23: X | CJ23: X | CQ23: X | CX23: X | DB23: {=SUM(IF(C23:DA23<>"",1,0))} -> 19
A24: Connections | B24: 4.3 | AJ24: X | DB24: {=SUM(IF(C24:DA24<>"",1,0))} -> 1
A25: Connections | B25: 4.4 | DB25: {=SUM(IF(C25:DA25<>"",1,0))} -> 0
A26: Connections | B26: 4.5 | M26: X | P26: X | AA26: X | AF26: X | AH26: X | BU26: X | CH26: X | DB26: {=SUM(IF(C26:DA26<>"",1,0))} -> 7 | DC26: =SUM(DB22:DB26) -> 38
A27: Number relations | B27: 5.1 | L27: X | AN27: X | AP27: X | AS27: X | AT27: X | AU27: X | AX27: X | BA27: X | BF27: X | BH27: X | CC27: X | CG27: X | CN27: X | CY27: X | CZ27: X | DB27: {=SUM(IF(C27:DA27<>"",1,0))} -> 15
A28: Number relations | B28: 5.2 | G28: X | L28: X | R28: X | S28: X | AI28: X | AN28: X | AS28: X | AT28: X | AU28: X | AX28: X | AY28: X | BA28: X | BB28: X | BE28: X | BF28: X | BH28: X | CC28: X | CN28: X | CY28: X | CZ28: X | DB28: {=SUM(IF(C28:DA28<>"",1,0))} -> 20
A29: Number relations | B29: 5.3 | AN29: X | AP29: X | CC29: X | CD29: X | CG29: X | CU29: X | CW29: X | CX29: X | CY29: X | CZ29: X | DA29: X | DB29: {=SUM(IF(C29:DA29<>"",1,0))} -> 11
A30: Number relations | B30: 5.4 | AN30: X | AP30: X | BF30: X | BH30: X | CG30: X | CY30: X | CZ30: X | DB30: {=SUM(IF(C30:DA30<>"",1,0))} -> 7
A31: Number relations | B31: 5.5 | AN31: X | AU31: X | BF31: X | BZ31: X | DB31: {=SUM(IF(C31:DA31<>"",1,0))} -> 4 | DC31: =SUM(DB27:DB31) -> 57
A32: Number systems & number theory | B32: 6.1 | DB32: {=SUM(IF(C32:DA32<>"",1,0))} -> 0
A33: Number systems & number theory | B33: 6.2 | AI33: X | AU33: X | BH33: X | BZ33: X | DB33: {=SUM(IF(C33:DA33<>"",1,0))} -> 4
A34: Number systems & number theory | B34: 6.3 | AJ34: X | DB34: {=SUM(IF(C34:DA34<>"",1,0))} -> 1
A35: Number systems & number theory | B35: 6.4 | BG35: X | BK35: X | DB35: {=SUM(IF(C35:DA35<>"",1,0))} -> 2
A36: Number systems & number theory | B36: 6.5 | R36: X | BF36: X | DB36: {=SUM(IF(C36:DA36<>"",1,0))} -> 2 | DC36: =SUM(DB32:DB36) -> 9
A37: Computation & Estimation | B37: 7.1 | N37: X | AG37: X | AH37: X | AK37: X | AL37: X | AO37: X | AQ37: X | AR37: X | AT37: X | AV37: X | AX37: X | BB37: X | BE37: X | BF37: X | BH37: X | BI37: X | BJ37: X | BK37: X | BL37: X | CN37: X | CT37: X | DB37: {=SUM(IF(C37:DA37<>"",1,0))} -> 21
A38: Computation & Estimation | B38: 7.2 | N38: X | AG38: X | AH38: X | AJ38: X | AK38: X | AL38: X | AO38: X | AQ38: X | AR38: X | AT38: X | AV38: X | AW38: X | AX38: X | BB38: X | BC38: X | BD38: X | BF38: X | BH38: X | BI38: X | BJ38: X | BL38: X | BO38: X | CN38: X | CT38: X | DB38: {=SUM(IF(C38:DA38<>"",1,0))} -> 24
A39: Computation & Estimation | B39: 7.3 | AR39: X | CD39: X | CX39: X | CY39: X | CZ39: X | DB39: {=SUM(IF(C39:DA39<>"",1,0))} -> 5
A40: Computation & Estimation | B40: 7.4 | AJ40: X | DB40: {=SUM(IF(C40:DA40<>"",1,0))} -> 1
...

Sheet Category Counts
D1: TIMSS Content Categories
B2: NCTM Standards Categories | C2: Proportionality | D2: Fractions & Number Sense | E2: Algebra | F2: Data Representation, Analysis & Probability | G2: Geometry | H2: Measurement | I2: TOTAL | J2: Standards/Category | K2: Correlations/Standard
B3: 1.Problem Solving | C3: 6 | D3: {=SUM(IF('Correlation Matrix'!AG5:BO10="X",1,0))} -> 16 | E3: {=SUM(IF('Correlation Matrix'!C5:T10="X",1,0))} -> 12 | F3: 9 | G3: 1 | H3: {=SUM(IF('Correlation Matrix'!CH5:CV10="X",1,0))} -> 15 | I3: =SUM(C3:H3) -> 59 | J3: 6 | K3: =I3/J3 -> 9.8333333
B4: 2.Communication | C4: 2 | D4: {=SUM(IF('Correlation Matrix'!AG11:BO16="X",1,0))} -> 7 | E4: 8 | F4: 5 | G4: 2 | H4: 3 | I4: =SUM(C4:H4) -> 27 | J4: 6 | K4: =I4/J4 -> 4.5
B5: 3.Reasoning | C5: 4 | D5: 0 | E5: 4 | F5: 3 | G5: 0 | H5: 8 | I5: =SUM(C5:H5) -> 19 | J5: 5 | K5: =I5/J5 -> 3.8
B6: 4.Connections | C6: 1 | D6: {=SUM(IF('Correlation Matrix'!AG22:BO26="X",1,0))} -> 10 | E6: 12 | F6: 4 | G6: 4 | H6: 7 | I6: =SUM(C6:H6) -> 38 | J6: 5 | K6: =I6/J6 -> 7.6
B7: 5.Number relations | C7: 11 | D7: {=SUM(IF('Correlation Matrix'!AG27:BO31="X",1,0))} -> 30 | E7: 5 | F7: 0 | G7: 8 | H7: 3 | I7: =SUM(C7:H7) -> 57 | J7: 5 | K7: =I7/J7 -> 11.4
B8: 6.NumberSystems&Theory | C8: 0 | D8: {=SUM(IF('Correlation Matrix'!AG32:BO36="X",1,0))} -> 7 | E8: 1 | F8: 0 | G8: 1 | H8: 0 | I8: =SUM(C8:H8) -> 9 | J8: 5 | K8: =I8/J8 -> 1.8
A9: NCTM Standards | B9: 7.Computation&Estimation | C9: 8 | D9: {=SUM(IF('Correlation Matrix'!AG37:BO42="X",1,0))} -> 66 | E9: 3 | F9: 0 | G9: 2 | H9: 6 | I9: =SUM(C9:H9) -> 85 | J9: 6 | K9: =I9/J9 -> 14.166667
B10: 8.Patterns & Functions | C10: 0 | D10: 0 | E10: 8 | F10: 6 | G10: 1 | H10: 1 | I10: =SUM(C10:H10) -> 16 | J10: 4 | K10: =I10/J10 -> 4
B11: 9.Algebra | C11: 4 | D11: {=SUM(IF('Correlation Matrix'!AG47:BO52="X",1,0))} -> 2 | E11: {=SUM(IF('Correlation Matrix'!C47:T52="X",1,0))} -> 36 | F11: 5 | G11: 9 | H11: 2 | I11: =SUM(C11:H11) -> 58 | J11: 6 | K11: =I11/J11 -> 9.6666667
B12: 10.Statistics | C12: 0 | D12: 0 | E12: 2 | F12: 11 | G12: 0 | H12: 0 | I12: =SUM(C12:H12) -> 13 | J12: 5 | K12: =I12/J12 -> 2.6
B13: 11.Probability | C13: 0 | D13: 0 | E13: 0 | F13: 21 | G13: 0 | H13: 0 | I13: =SUM(C13:H13) -> 21 | J13: 5 | K13: =I13/J13 -> 4.2
B14: 12.Geometry | C14: 0 | D14: {=SUM(IF('Correlation Matrix'!AG62:BO66="X",1,0))} -> 6 | E14: 4 | F14: 0 | G14: {=SUM(IF('Correlation Matrix'!BP62:CG68="X",1,0))} -> 21 | H14: 13 | I14: =SUM(C14:H14) -> 44 | J14: 6 | K14: =I14/J14 -> 7.3333333
B15: 13.Measurement | C15: 0 | D15: {=SUM(IF('Correlation Matrix'!AG67:BO75="X",1,0))} -> 19 | E15: 0 | F15: 1 | G15: {=SUM(IF('Correlation Matrix'!BP69:CG75="X",1,0))} -> 18 | H15: {=SUM(IF('Correlation Matrix'!CH69:CV75="X",1,0))} -> 35 | I15: =SUM(C15:H15) -> 73 | J15: 7 | K15: =I15/J15 -> 10.428571
B16: TOTAL | C16: =SUM(C3:C15) -> 36 | D16: =SUM(D3:D15) -> 163 | E16: =SUM(E3:E15) -> 95 | F16: =SUM(F3:F15) -> 65 | G16: =SUM(G3:G15) -> 67 | H16: =SUM(H3:H15) -> 93 | I16: =SUM(C16:H16) -> 519 | J16: =SUM(J3:J15) -> 71 | K16: =I16/J16 -> 7.3098592
B17: Items/Content Category | C17: 5 | D17: 34 | E17: 18 | F17: 12 | G17: 18 | H17: 16 | I17: =SUM(C17:H17) -> 103
B18: Correlations/Item | C18: =C16/C17 -> 7.2 | D18: =D16/D17 -> 4.7941176 | E18: =E16/E17 -> 5.2777778 | F18: =F16/F17 -> 5.4166667 | G18: =G16/G17 -> 3.7222222 | H18: =H16/H17 -> 5.8125 | I18: =I16/I17 -> 5.038835

Sheet Sheet2
A1: I-01 | B1: Algebra
A2: I-02 | B2: Fractions & Number Sense
A3: I-03 | B3: Measurement
A4: I-04 | B4: Algebra
A5: I-05 | B5: Fractions & Number Sense
A6: I-06 | B6: Fractions & Number Sense
A7: I-07 | B7: Fractions & Number Sense
A8: I-08 | B8: Geometry
A9: I-09 | B9: Data Representation, Analysis & Probability
A10: J-10 | B10: Measurement
A11: J-11 | B11: Geometry
A12: J-12 | B12: Fractions & Number Sense
... A107: V-04 | B107: Measurement

Sheet Sheet4
