Workbook

Sheet Instructions and documentation
A2: T-RFLP Analysis Matching Program (TRAMP)
A3: Version 1.0
A4: Developed by I. A. Dickie
A6: Description:
A7: TRAMP is a simple Excel spreadsheet to match output from TRFLP analysis to a database of known species. The majority of the "guts" of the spreadsheet are simply found in worksheet formulas. Some additional VBA code is used to prevent certain problems with broken links caused by pasting data, and to present output in as clear a fashion as possible.
A9: Instructions:
A10: 1. On all sheets, data should only be entered in yellow cells. Comments have been embedded in some cells, indicated by a red triangle. Positioning the cursor over these cells will reveal further documentation and hints.
A11: 2. Data is entered on the "Unknown Data Entry" worksheet, usually pasted directly from the electropherogram output. Two columns are required for each enzyme / primer combination. The first column is the size of each peak in base pairs, the second column is the height or intensity of that peak.
A12: 3. Data from known samples (sporocarps or root tips) is entered into the "Knowns" datasheet. Only the size of peaks (in base pairs) is required.
A13: 4. On the "unknown" sheet a threshold value must be set for band intensity. The threshold is the percentage of the maximum band length below which other bands are not considered in analysis. This serves to reduce noise in the data. "To include all bands in analysis, set the threshold equal to 0.
A14: 5. On the "parameters" sheet a maximum error value must be set. We normally use 1.5 bp as our maximum allowable error, but this may vary with other laboratories.
A15: 6. The names of enzymes should also be entered on the "parameters" sheet. This should be done once (during initial setup) and not changed.
... A27: This program was developed largely while I.A.D. was a post-doc in the lab of Roger Koide at the Pennsylvania State University. Funding was provided by the A. W. Mellon Foundation.

Sheet Parameters
A1: PARAMETERS
A3: Maximum acceptable error (bp): | B3: 3
B5: 1 | C5: 2 | D5: 3 | E5: 4 | F5: 5 | G5: 6
A6: Enzyme/primer cobinations: | B6: Hinf1-ITS4 | C6: Hinf1-ITS1F | D6: HaeIII-ITS4 | E6: HaeIII-ITS1 | F6: DpnII-ITS4 | G6: (none)

Sheet Unknown Data Entry
A1: Sample: | B1: L-24 | E1: Threshold parameter: | F1: 5 | G1: (percentage of max band height, 0 to 100)
A2: Line 2:
A3: Line 3: | I3: Click on this button to update the text output:
A4: Type: | B4: Soil Core
B6: =Parameters!B6 -> Hinf1-ITS4 | D6: =Parameters!C6 -> Hinf1-ITS1F | F6: =Parameters!D6 -> HaeIII-ITS4 | H6: =Parameters!E6 -> HaeIII-ITS1 | J6: =Parameters!F6 -> DpnII-ITS4 | L6: =Parameters!G6 -> (none)
B7: Size | C7: Height | D7: Size | E7: Height | F7: Size | G7: Height | H7: Size | I7: Height | J7: Size | K7: Height | L7: Size | M7: Height
A8: (Threshold ---->) | C8: =($F$1/100)*MAX(C10:C59) -> 158.5 | E8: =($F$1/100)*MAX(E10:E59) -> 94.95 | G8: =($F$1/100)*MAX(G10:G59) -> 196.65 | I8: =($F$1/100)*MAX(I10:I59) -> 78.2 | K8: =($F$1/100)*MAX(K10:K59) -> 0 | M8: =($F$1/100)*MAX(M10:M59) -> 0
A9: (# Bands ---->) | C9: =COUNTIF(ThresholdCalc!A:A, "<> 9999")-1 -> 65491 | E9: =COUNTIF(ThresholdCalc!B:B, "<> 9999")-1 -> 65496 | G9: =COUNTIF(ThresholdCalc!C:C, "<> 9999")-1 -> 65495 | I9: =COUNTIF(ThresholdCalc!D:D, "<> 9999")-1 -> 65497 | K9: =COUNTIF(ThresholdCalc!E:E, "<> 9999")-1 -> 65485 | M9: =COUNTIF(ThresholdCalc!F:F, "<> 9999")-1 -> 65485
A10: 1 | B10: 42.91 | C10: 619 | D10: 44.26 | E10: 519 | F10: 42.91 | G10: 492 | H10: 44.26 | I10: 402
A11: 2 | B11: 46.28 | C11: 1319 | D11: 64.01 | E11: 38 | F11: 54.83 | G11: 310 | H11: 64.35 | I11: 33
A12: 3 | B12: 65.69 | C12: 71 | D12: 82.89 | E12: 99 | F12: 68.7 | G12: 61 | H12: 79.62 | I12: 136
A13: 4 | B13: 79.95 | C13: 258 | D13: 91.87 | E13: 28 | F13: 79.29 | G13: 248 | H13: 99.07 | I13: 1564
A14: 5 | B14: 92.19 | C14: 97 | D14: 99.07 | E14: 107 | F14: 92.18 | G14: 103 | H14: 112.32 | I14: 178
A15: 6 | B15: 99.07 | C15: 1178 | D15: 106.56 | E15: 1899 | F15: 94.7 | G15: 114 | H15: 131.93 | I15: 1074
A16: 7 | B16: 112.23 | C16: 77 | D16: 191.81 | E16: 73 | F16: 112.32 | G16: 1703 | H16: 161.87 | I16: 160
A17: 8 | B17: 117.89 | C17: 141 | D17: 224.35 | E17: 36 | F17: 129.95 | G17: 2152 | H17: 247.05 | I17: 298
A18: 9 | B18: 123.81 | C18: 101 | D18: 245.24 | E18: 1371 | F18: 139.31 | G18: 237 | H18: 266.83 | I18: 1468
A19: 10 | B19: 128.32 | C19: 85 | D19: 255.82 | E19: 50 | F19: 144.26 | G19: 136 | H19: 431.93 | I19: 90
A20: 11 | B20: 138.16 | C20: 107 | D20: 269.06 | E20: 25 | F20: 149.7 | G20: 129 | H20: 455.63 | I20: 125
A21: 12 | B21: 149.4 | C21: 84 | D21: 299.05 | E21: 72 | F21: 153.04 | G21: 124 | H21: 459.29 | I21: 107
... A25: 16 | B25: 175.4 | C25: 80 | D25: 335.78 | E25: 31 | F25: 195.96 | G25: 102 | H25: 653.3187 | I25: 53
A26: 17 | B26: 179.64 | C26: 74 | D26: 343.78 | E26: 112 | F26: 202.53 | G26: 125
A27: 18 | B27: 185.2 | C27: 73 | D27: 360.78 | E27: 245 | F27: 210.09 | G27: 98
A28: 19 | B28: 188.9 | C28: 72 | D28: 365.24 | E28: 1635 | F28: 212.6 | G28: 107
A29: 20 | B29: 194.19 | C29: 73 | D29: 387.48 | E29: 213 | F29: 218.42 | G29: 216
A30: 21 | B30: 200.55 | C30: 90 | F30: 232.97 | G30: 98
A31: 22 | B31: 207.18 | C31: 74 | F31: 237.86 | G31: 100
A32: 23 | B32: 212.66 | C32: 90 | F32: 247.05 | G32: 3933
A33: 24 | B33: 215.94 | C33: 112 | F33: 339.74 | G33: 31
A34: 25 | B34: 222.46 | C34: 86 | F34: 374.72 | G34: 32
A35: 26 | B35: 225.71 | C35: 69 | F35: 379.49 | G35: 37
A36: 27 | B36: 231.63 | C36: 87 | F36: 384 | G36: 32
A37: 28 | B37: 237.25 | C37: 94 | F37: 392.78 | G37: 26
A38: 29 | B38: 241.52 | C38: 92 | F38: 400 | G38: 38
A39: 30 | B39: 249.47 | C39: 35 | F39: 405.95 | G39: 32
A40: 31 | B40: 262.57 | C40: 69 | F40: 414.92 | G40: 27
A41: 32 | B41: 265.7 | C41: 18 | F41: 418.47 | G41: 28
... A48: 39 | B48: 387.22 | C48: 3170 | F48: 460.7 | G48: 107
A49: 40 | F49: 476.01 | G49: 33
A50: 41 | F50: 480 | G50: 28
...

Sheet Unknown
A1: Sample: | B1: L-24 | E1: Threshold parameter: | F1: 5 | G1: (percentage of max band height, 0 to 100)
A2: Line 2:
A3: Line 3: | I3: Click on this button to update the text output:
A4: Type: | B4: Soil Core
B6: Hinf1-ITS4 | D6: Hinf1-ITS1F | F6: HaeIII-ITS4 | H6: HaeIII-ITS1 | J6: DpnII-ITS4 | L6: (none)
B7: Size | C7: Height | D7: Size | E7: Height | F7: Size | G7: Height | H7: Size | I7: Height | J7: Size | K7: Height | L7: Size | M7: Height
A8: (Threshold ---->) | C8: 158.5 | E8: 94.95 | G8: 196.65 | I8: 78.2 | K8: 0 | M8: 0
A9: (# Bands ---->) | C9: 6 | E9: 11 | G9: 10 | I9: 12 | K9: 0 | M9: 0
A10: 1 | B10: 42.91 | C10: 619 | D10: 44.26 | E10: 519 | F10: 42.91 | G10: 492 | H10: 44.26 | I10: 402
A11: 2 | B11: 46.28 | C11: 1319 | D11: 64.01 | E11: 38 | F11: 54.83 | G11: 310 | H11: 64.35 | I11: 33
A12: 3 | B12: 65.69 | C12: 71 | D12: 82.89 | E12: 99 | F12: 68.7 | G12: 61 | H12: 79.62 | I12: 136
A13: 4 | B13: 79.95 | C13: 258 | D13: 91.87 | E13: 28 | F13: 79.29 | G13: 248 | H13: 99.07 | I13: 1564
A14: 5 | B14: 92.19 | C14: 97 | D14: 99.07 | E14: 107 | F14: 92.18 | G14: 103 | H14: 112.32 | I14: 178
A15: 6 | B15: 99.07 | C15: 1178 | D15: 106.56 | E15: 1899 | F15: 94.7 | G15: 114 | H15: 131.93 | I15: 1074
A16: 7 | B16: 112.23 | C16: 77 | D16: 191.81 | E16: 73 | F16: 112.32 | G16: 1703 | H16: 161.87 | I16: 160
A17: 8 | B17: 117.89 | C17: 141 | D17: 224.35 | E17: 36 | F17: 129.95 | G17: 2152 | H17: 247.05 | I17: 298
A18: 9 | B18: 123.81 | C18: 101 | D18: 245.24 | E18: 1371 | F18: 139.31 | G18: 237 | H18: 266.83 | I18: 1468
A19: 10 | B19: 128.32 | C19: 85 | D19: 255.82 | E19: 50 | F19: 144.26 | G19: 136 | H19: 431.93 | I19: 90
A20: 11 | B20: 138.16 | C20: 107 | D20: 269.06 | E20: 25 | F20: 149.7 | G20: 129 | H20: 455.63 | I20: 125
A21: 12 | B21: 149.4 | C21: 84 | D21: 299.05 | E21: 72 | F21: 153.04 | G21: 124 | H21: 459.29 | I21: 107
... A25: 16 | B25: 175.4 | C25: 80 | D25: 335.78 | E25: 31 | F25: 195.96 | G25: 102 | H25: 653.3187 | I25: 53
A26: 17 | B26: 179.64 | C26: 74 | D26: 343.78 | E26: 112 | F26: 202.53 | G26: 125
A27: 18 | B27: 185.2 | C27: 73 | D27: 360.78 | E27: 245 | F27: 210.09 | G27: 98
A28: 19 | B28: 188.9 | C28: 72 | D28: 365.24 | E28: 1635 | F28: 212.6 | G28: 107
A29: 20 | B29: 194.19 | C29: 73 | D29: 387.48 | E29: 213 | F29: 218.42 | G29: 216
A30: 21 | B30: 200.55 | C30: 90 | F30: 232.97 | G30: 98
A31: 22 | B31: 207.18 | C31: 74 | F31: 237.86 | G31: 100
A32: 23 | B32: 212.66 | C32: 90 | F32: 247.05 | G32: 3933
A33: 24 | B33: 215.94 | C33: 112 | F33: 339.74 | G33: 31
A34: 25 | B34: 222.46 | C34: 86 | F34: 374.72 | G34: 32
A35: 26 | B35: 225.71 | C35: 69 | F35: 379.49 | G35: 37
A36: 27 | B36: 231.63 | C36: 87 | F36: 384 | G36: 32
A37: 28 | B37: 237.25 | C37: 94 | F37: 392.78 | G37: 26
A38: 29 | B38: 241.52 | C38: 92 | F38: 400 | G38: 38
A39: 30 | B39: 249.47 | C39: 35 | F39: 405.95 | G39: 32
A40: 31 | B40: 262.57 | C40: 69 | F40: 414.92 | G40: 27
A41: 32 | B41: 265.7 | C41: 18 | F41: 418.47 | G41: 28
... A48: 39 | B48: 387.22 | C48: 3170 | F48: 460.7 | G48: 107
A49: 40 | F49: 476.01 | G49: 33
A50: 41 | F50: 480 | G50: 28
...

Sheet Output (short report)
A2: Sample: | B2: =Unknown!B1 -> L-24 | D2: Output Date: | E2: =TODAY() -> 43857
A3: Line 1: | B3: =Unknown!B2 -> 0
A4: Line 2: | B4: =Unknown!B3 -> 0
A5: Type: | B5: =Unknown!B4 -> Soil Core
A7: Top 30 matches in database.
E8: Matching Band Lengths
A9: Known Species | B9: Max error (bp) | C9: Accept | E9: =Knowns!B1 -> Hinf1-ITS4 | F9: =Knowns!C1 -> Hinf1-ITS1F | G9: =Knowns!D1 -> HaeIII-ITS4 | H9: =Knowns!E1 -> HaeIII-ITS1 | I9: =Knowns!F1 -> DpnII-ITS4 | J9: =Knowns!G1 -> (none)
A10: Unknown TRFLP 006 | B10: 0.63 | C10: yes | E10: 99.7 | F10: 314.8 | G10: 161.9 | H10: 132 | I10: ****
A11: Unknown TRFLP 005 | B11: 0.84 | C11: yes | E11: 342.4 | F11: 245.2 | G11: 111.8 | H11: 99.1 | I11: ****
A12: Lactarius oculatus | B12: 0.86 | C12: yes | E12: 387.8 | F12: 105.7 | G12: 247 | H12: 522.2
A13: MT S | B13: 0.95 | C13: yes | E13: **** | F13: **** | G13: 129 | H13: 266.3
A14: Clavulina cristata (=MT F,G,U,W) | B14: 1.28 | C14: yes | E14: 45 | F14: 366 | G14: 129.8 | H14: 266.4
A15: Ramaria concolor | B15: 3.41 | C15: no
A16: Unknown TRFLP 001 | B16: 6.16 | C16: no
A17: Amanita muscaria var. formosa | B17: 6.48 | C17: no
A18: Russula silvicola | B18: 12.65 | C18: no
A19: Unknown TRFLP 011 | B19: 13.82 | C19: no
A20: Clavarioid 2 | B20: 15.96 | C20: no
A21: Cenococcum geophilum (=MT B) | B21: 16.02 | C21: no
A22: Russula sp. red 1 | B22: 16.92 | C22: no
A23: Unknown TRFLP 007 | B23: 18.63 | C23: no
A24: Russula pseudolepida | B24: 18.96 | C24: no
A25: Boletus cf. miniato-pallescens | B25: 19.03 | C25: no
A26: Russula cf. vesca | B26: 19.808007 | C26: no
... A39: Unknown TRFLP 012 | B39: 58.14 | C39: no
A41: **** indicates no data in the known database for this enzyme / primer pair.
A43: Parameters.
A44: Max Error: | B44: =Parameters!B3 -> 3 | C44: bp
A45: Peak intensity threshold: | B45: ='Unknown Data Entry'!F1 -> 5 | C45: %

Sheet Complete report
A2: Sample: | B2: =Unknown!B1 -> L-24 | D2: Output Date: | E2: =TODAY() -> 43857
A3: Line 1: | B3: =Unknown!B2 -> 0
A4: Line 2: | B4: =Unknown!B3 -> 0
A5: Type: | B5: =Unknown!B4 -> Soil Core
A7: Full list of all species in database with max error.
E8: Matching Band Lengths
A9: Known Species | B9: Max error (bp) | C9: Accept | E9: =Knowns!B1 -> Hinf1-ITS4 | F9: =Knowns!C1 -> Hinf1-ITS1F | G9: =Knowns!D1 -> HaeIII-ITS4 | H9: =Knowns!E1 -> HaeIII-ITS1 | I9: =Knowns!F1 -> DpnII-ITS4 | J9: =Knowns!G1 -> (none)
A10: =IF(Knowns!A2<>"", Knowns!A2, "") -> Amanita brunnescens | B10: =IF(A10<>"", MAX('Error Calc (bp)'!B2:G2), "") -> 444.85 | C10: =IF(A10<>"", IF(B10<Parameters!B$3, "yes", "no"), "") -> no | E10: =IF(MIN('Clean Unknown'!A:A) < 9999, IF($C10="yes", IF(Knowns!B2<>0, Knowns!B2, "****"), ""), "") | F10: =IF(MIN('Clean Unknown'!B:B) < 9999, IF($C10="yes", IF(Knowns!C2<>0, Knowns!C2, "****"), ""), "") | G10: =IF(MIN('Clean Unknown'!C:C) < 9999, IF($C10="yes", IF(Knowns!D2<>0, Knowns!D2, "****"), ""), "") | H10: =IF(MIN('Clean Unknown'!D:D) < 9999, IF($C10="yes", IF(Knowns!E2<>0, Knowns!E2, "****"), ""), "") | I10: =IF(MIN('Clean Unknown'!E:E) < 9999, IF($C10="yes", IF(Knowns!F2<>0, Knowns!F2, "****"), ""), "") | J10: =IF(MIN('Clean Unknown'!F:F) < 9999, IF($C10="yes", IF(Knowns!G2<>0, Knowns!G2, "****"), ""), "")
A11: =IF(Knowns!A3<>"", Knowns!A3, "") -> Amanita vaginata | B11: =IF(A11<>"", MAX('Error Calc (bp)'!B3:G3), "") -> 76.44 | C11: =IF(A11<>"", IF(B11<Parameters!B$3, "yes", "no"), "") -> no | E11: =IF(MIN('Clean Unknown'!A:A) < 9999, IF($C11="yes", IF(Knowns!B3<>0, Knowns!B3, "****"), ""), "") | F11: =IF(MIN('Clean Unknown'!B:B) < 9999, IF($C11="yes", IF(Knowns!C3<>0, Knowns!C3, "****"), ""), "") | G11: =IF(MIN('Clean Unknown'!C:C) < 9999, IF($C11="yes", IF(Knowns!D3<>0, Knowns!D3, "****"), ""), "") | H11: =IF(MIN('Clean Unknown'!D:D) < 9999, IF($C11="yes", IF(Knowns!E3<>0, Knowns!E3, "****"), ""), "") | I11: =IF(MIN('Clean Unknown'!E:E) < 9999, IF($C11="yes", IF(Knowns!F3<>0, Knowns!F3, "****"), ""), "") | J11: =IF(MIN('Clean Unknown'!F:F) < 9999, IF($C11="yes", IF(Knowns!G3<>0, Knowns!G3, "****"), ""), "")
A12: =IF(Knowns!A4<>"", Knowns!A4, "") -> Amanita citrina | B12: =IF(A12<>"", MAX('Error Calc (bp)'!B4:G4), "") -> 445.45 | C12: =IF(A12<>"", IF(B12<Parameters!B$3, "yes", "no"), "") -> no | E12: =IF(MIN('Clean Unknown'!A:A) < 9999, IF($C12="yes", IF(Knowns!B4<>0, Knowns!B4, "****"), ""), "") | F12: =IF(MIN('Clean Unknown'!B:B) < 9999, IF($C12="yes", IF(Knowns!C4<>0, Knowns!C4, "****"), ""), "") | G12: =IF(MIN('Clean Unknown'!C:C) < 9999, IF($C12="yes", IF(Knowns!D4<>0, Knowns!D4, "****"), ""), "") | H12: =IF(MIN('Clean Unknown'!D:D) < 9999, IF($C12="yes", IF(Knowns!E4<>0, Knowns!E4, "****"), ""), "") | I12: =IF(MIN('Clean Unknown'!E:E) < 9999, IF($C12="yes", IF(Knowns!F4<>0, Knowns!F4, "****"), ""), "") | J12: =IF(MIN('Clean Unknown'!F:F) < 9999, IF($C12="yes", IF(Knowns!G4<>0, Knowns!G4, "****"), ""), "")
A13: =IF(Knowns!A5<>"", Knowns!A5, "") -> Amanita flavoconia | B13: =IF(A13<>"", MAX('Error Calc (bp)'!B5:G5), "") -> 428.65 | C13: =IF(A13<>"", IF(B13<Parameters!B$3, "yes", "no"), "") -> no | E13: =IF(MIN('Clean Unknown'!A:A) < 9999, IF($C13="yes", IF(Knowns!B5<>0, Knowns!B5, "****"), ""), "") | F13: =IF(MIN('Clean Unknown'!B:B) < 9999, IF($C13="yes", IF(Knowns!C5<>0, Knowns!C5, "****"), ""), "") | G13: =IF(MIN('Clean Unknown'!C:C) < 9999, IF($C13="yes", IF(Knowns!D5<>0, Knowns!D5, "****"), ""), "") | H13: =IF(MIN('Clean Unknown'!D:D) < 9999, IF($C13="yes", IF(Knowns!E5<>0, Knowns!E5, "****"), ""), "") | I13: =IF(MIN('Clean Unknown'!E:E) < 9999, IF($C13="yes", IF(Knowns!F5<>0, Knowns!F5, "****"), ""), "") | J13: =IF(MIN('Clean Unknown'!F:F) < 9999, IF($C13="yes", IF(Knowns!G5<>0, Knowns!G5, "****"), ""), "")
A14: =IF(Knowns!A6<>"", Knowns!A6, "") -> Amanita muscaria var. formosa | B14: =IF(A14<>"", MAX('Error Calc (bp)'!B6:G6), "") -> 6.48 | C14: =IF(A14<>"", IF(B14<Parameters!B$3, "yes", "no"), "") -> no | E14: =IF(MIN('Clean Unknown'!A:A) < 9999, IF($C14="yes", IF(Knowns!B6<>0, Knowns!B6, "****"), ""), "") | F14: =IF(MIN('Clean Unknown'!B:B) < 9999, IF($C14="yes", IF(Knowns!C6<>0, Knowns!C6, "****"), ""), "") | G14: =IF(MIN('Clean Unknown'!C:C) < 9999, IF($C14="yes", IF(Knowns!D6<>0, Knowns!D6, "****"), ""), "") | H14: =IF(MIN('Clean Unknown'!D:D) < 9999, IF($C14="yes", IF(Knowns!E6<>0, Knowns!E6, "****"), ""), "") | I14: =IF(MIN('Clean Unknown'!E:E) < 9999, IF($C14="yes", IF(Knowns!F6<>0, Knowns!F6, "****"), ""), "") | J14: =IF(MIN('Clean Unknown'!F:F) < 9999, IF($C14="yes", IF(Knowns!G6<>0, Knowns!G6, "****"), ""), "")
A15: =IF(Knowns!A7<>"", Knowns!A7, "") -> Amanita rubescens | B15: =IF(A15<>"", MAX('Error Calc (bp)'!B7:G7), "") -> 485.55 | C15: =IF(A15<>"", IF(B15<Parameters!B$3, "yes", "no"), "") -> no | E15: =IF(MIN('Clean Unknown'!A:A) < 9999, IF($C15="yes", IF(Knowns!B7<>0, Knowns!B7, "****"), ""), "") | F15: =IF(MIN('Clean Unknown'!B:B) < 9999, IF($C15="yes", IF(Knowns!C7<>0, Knowns!C7, "****"), ""), "") | G15: =IF(MIN('Clean Unknown'!C:C) < 9999, IF($C15="yes", IF(Knowns!D7<>0, Knowns!D7, "****"), ""), "") | H15: =IF(MIN('Clean Unknown'!D:D) < 9999, IF($C15="yes", IF(Knowns!E7<>0, Knowns!E7, "****"), ""), "") | I15: =IF(MIN('Clean Unknown'!E:E) < 9999, IF($C15="yes", IF(Knowns!F7<>0, Knowns!F7, "****"), ""), "") | J15: =IF(MIN('Clean Unknown'!F:F) < 9999, IF($C15="yes", IF(Knowns!G7<>0, Knowns!G7, "****"), ""), "")
A16: =IF(Knowns!A8<>"", Knowns!A8, "") -> Amanita sp. | B16: =IF(A16<>"", MAX('Error Calc (bp)'!B8:G8), "") -> 272.95 | C16: =IF(A16<>"", IF(B16<Parameters!B$3, "yes", "no"), "") -> no | E16: =IF(MIN('Clean Unknown'!A:A) < 9999, IF($C16="yes", IF(Knowns!B8<>0, Knowns!B8, "****"), ""), "") | F16: =IF(MIN('Clean Unknown'!B:B) < 9999, IF($C16="yes", IF(Knowns!C8<>0, Knowns!C8, "****"), ""), "") | G16: =IF(MIN('Clean Unknown'!C:C) < 9999, IF($C16="yes", IF(Knowns!D8<>0, Knowns!D8, "****"), ""), "") | H16: =IF(MIN('Clean Unknown'!D:D) < 9999, IF($C16="yes", IF(Knowns!E8<>0, Knowns!E8, "****"), ""), "") | I16: =IF(MIN('Clean Unknown'!E:E) < 9999, IF($C16="yes", IF(Knowns!F8<>0, Knowns!F8, "****"), ""), "") | J16: =IF(MIN('Clean Unknown'!F:F) < 9999, IF($C16="yes", IF(Knowns!G8<>0, Knowns!G8, "****"), ""), "")
A17: =IF(Knowns!A9<>"", Knowns!A9, "") -> Boletus cf. miniato-pallescens | B17: =IF(A17<>"", MAX('Error Calc (bp)'!B9:G9), "") -> 19.03 | C17: =IF(A17<>"", IF(B17<Parameters!B$3, "yes", "no"), "") -> no | E17: =IF(MIN('Clean Unknown'!A:A) < 9999, IF($C17="yes", IF(Knowns!B9<>0, Knowns!B9, "****"), ""), "") | F17: =IF(MIN('Clean Unknown'!B:B) < 9999, IF($C17="yes", IF(Knowns!C9<>0, Knowns!C9, "****"), ""), "") | G17: =IF(MIN('Clean Unknown'!C:C) < 9999, IF($C17="yes", IF(Knowns!D9<>0, Knowns!D9, "****"), ""), "") | H17: =IF(MIN('Clean Unknown'!D:D) < 9999, IF($C17="yes", IF(Knowns!E9<>0, Knowns!E9, "****"), ""), "") | I17: =IF(MIN('Clean Unknown'!E:E) < 9999, IF($C17="yes", IF(Knowns!F9<>0, Knowns!F9, "****"), ""), "") | J17: =IF(MIN('Clean Unknown'!F:F) < 9999, IF($C17="yes", IF(Knowns!G9<>0, Knowns!G9, "****"), ""), "")
A18: =IF(Knowns!A10<>"", Knowns!A10, "") -> Boletus cf. pallidus | B18: =IF(A18<>"", MAX('Error Calc (bp)'!B10:G10), "") -> 31.24 | C18: =IF(A18<>"", IF(B18<Parameters!B$3, "yes", "no"), "") -> no | E18: =IF(MIN('Clean Unknown'!A:A) < 9999, IF($C18="yes", IF(Knowns!B10<>0, Knowns!B10, "****"), ""), "") | F18: =IF(MIN('Clean Unknown'!B:B) < 9999, IF($C18="yes", IF(Knowns!C10<>0, Knowns!C10, "****"), ""), "") | G18: =IF(MIN('Clean Unknown'!C:C) < 9999, IF($C18="yes", IF(Knowns!D10<>0, Knowns!D10, "****"), ""), "") | H18: =IF(MIN('Clean Unknown'!D:D) < 9999, IF($C18="yes", IF(Knowns!E10<>0, Knowns!E10, "****"), ""), "") | I18: =IF(MIN('Clean Unknown'!E:E) < 9999, IF($C18="yes", IF(Knowns!F10<>0, Knowns!F10, "****"), ""), "") | J18: =IF(MIN('Clean Unknown'!F:F) < 9999, IF($C18="yes", IF(Knowns!G10<>0, Knowns!G10, "****"), ""), "")
A19: =IF(Knowns!A11<>"", Knowns!A11, "") -> Boletus cf. projectellus | B19: =IF(A19<>"", MAX('Error Calc (bp)'!B11:G11), "") -> 67.38 | C19: =IF(A19<>"", IF(B19<Parameters!B$3, "yes", "no"), "") -> no | E19: =IF(MIN('Clean Unknown'!A:A) < 9999, IF($C19="yes", IF(Knowns!B11<>0, Knowns!B11, "****"), ""), "") | F19: =IF(MIN('Clean Unknown'!B:B) < 9999, IF($C19="yes", IF(Knowns!C11<>0, Knowns!C11, "****"), ""), "") | G19: =IF(MIN('Clean Unknown'!C:C) < 9999, IF($C19="yes", IF(Knowns!D11<>0, Knowns!D11, "****"), ""), "") | H19: =IF(MIN('Clean Unknown'!D:D) < 9999, IF($C19="yes", IF(Knowns!E11<>0, Knowns!E11, "****"), ""), "") | I19: =IF(MIN('Clean Unknown'!E:E) < 9999, IF($C19="yes", IF(Knowns!F11<>0, Knowns!F11, "****"), ""), "") | J19: =IF(MIN('Clean Unknown'!F:F) < 9999, IF($C19="yes", IF(Knowns!G11<>0, Knowns!G11, "****"), ""), "")
A20: =IF(Knowns!A12<>"", Knowns!A12, "") -> Boletus sp. | B20: =IF(A20<>"", MAX('Error Calc (bp)'!B12:G12), "") -> 60.93 | C20: =IF(A20<>"", IF(B20<Parameters!B$3, "yes", "no"), "") -> no | E20: =IF(MIN('Clean Unknown'!A:A) < 9999, IF($C20="yes", IF(Knowns!B12<>0, Knowns!B12, "****"), ""), "") | F20: =IF(MIN('Clean Unknown'!B:B) < 9999, IF($C20="yes", IF(Knowns!C12<>0, Knowns!C12, "****"), ""), "") | G20: =IF(MIN('Clean Unknown'!C:C) < 9999, IF($C20="yes", IF(Knowns!D12<>0, Knowns!D12, "****"), ""), "") | H20: =IF(MIN('Clean Unknown'!D:D) < 9999, IF($C20="yes", IF(Knowns!E12<>0, Knowns!E12, "****"), ""), "") | I20: =IF(MIN('Clean Unknown'!E:E) < 9999, IF($C20="yes", IF(Knowns!F12<>0, Knowns!F12, "****"), ""), "") | J20: =IF(MIN('Clean Unknown'!F:F) < 9999, IF($C20="yes", IF(Knowns!G12<>0, Knowns!G12, "****"), ""), "")
A21: =IF(Knowns!A13<>"", Knowns!A13, "") -> Cantharellula umbonata | B21: =IF(A21<>"", MAX('Error Calc (bp)'!B13:G13), "") -> 443.05 | C21: =IF(A21<>"", IF(B21<Parameters!B$3, "yes", "no"), "") -> no | E21: =IF(MIN('Clean Unknown'!A:A) < 9999, IF($C21="yes", IF(Knowns!B13<>0, Knowns!B13, "****"), ""), "") | F21: =IF(MIN('Clean Unknown'!B:B) < 9999, IF($C21="yes", IF(Knowns!C13<>0, Knowns!C13, "****"), ""), "") | G21: =IF(MIN('Clean Unknown'!C:C) < 9999, IF($C21="yes", IF(Knowns!D13<>0, Knowns!D13, "****"), ""), "") | H21: =IF(MIN('Clean Unknown'!D:D) < 9999, IF($C21="yes", IF(Knowns!E13<>0, Knowns!E13, "****"), ""), "") | I21: =IF(MIN('Clean Unknown'!E:E) < 9999, IF($C21="yes", IF(Knowns!F13<>0, Knowns!F13, "****"), ""), "") | J21: =IF(MIN('Clean Unknown'!F:F) < 9999, IF($C21="yes", IF(Knowns!G13<>0, Knowns!G13, "****"), ""), "")
... A54: =IF(Knowns!A46<>"", Knowns!A46, "") -> Tricholoma virgatum | B54: =IF(A54<>"", MAX('Error Calc (bp)'!B46:G46), "") -> 438.05 | C54: =IF(A54<>"", IF(B54<Parameters!B$3, "yes", "no"), "") -> no | E54: =IF(MIN('Clean Unknown'!A:A) < 9999, IF($C54="yes", IF(Knowns!B46<>0, Knowns!B46, "****"), ""), "") | F54: =IF(MIN('Clean Unknown'!B:B) < 9999, IF($C54="yes", IF(Knowns!C46<>0, Knowns!C46, "****"), ""), "") | G54: =IF(MIN('Clean Unknown'!C:C) < 9999, IF($C54="yes", IF(Knowns!D46<>0, Knowns!D46, "****"), ""), "") | H54: =IF(MIN('Clean Unknown'!D:D) < 9999, IF($C54="yes", IF(Knowns!E46<>0, Knowns!E46, "****"), ""), "") | I54: =IF(MIN('Clean Unknown'!E:E) < 9999, IF($C54="yes", IF(Knowns!F46<>0, Knowns!F46, "****"), ""), "") | J54: =IF(MIN('Clean Unknown'!F:F) < 9999, IF($C54="yes", IF(Knowns!G46<>0, Knowns!G46, "****"), ""), "")
A55: =IF(Knowns!A47<>"", Knowns!A47, "") -> Tylopilus felleus (=MT D,O) | B55: =IF(A55<>"", MAX('Error Calc (bp)'!B47:G47), "") -> 37.491993 | C55: =IF(A55<>"", IF(B55<Parameters!B$3, "yes", "no"), "") -> no | E55: =IF($C55="yes", IF(Knowns!B47<>0, Knowns!B47, "****"), "") | F55: =IF($C55="yes", IF(Knowns!C47<>0, Knowns!C47, "****"), "") | G55: =IF($C55="yes", IF(Knowns!D47<>0, Knowns!D47, "****"), "") | H55: =IF($C55="yes", IF(Knowns!E47<>0, Knowns!E47, "****"), "") | I55: =IF($C55="yes", IF(Knowns!F47<>0, Knowns!F47, "****"), "")
A56: =IF(Knowns!A48<>"", Knowns!A48, "") -> Unknown TRFLP 001 | B56: =IF(A56<>"", MAX('Error Calc (bp)'!B48:G48), "") -> 6.16 | C56: =IF(A56<>"", IF(B56<Parameters!B$3, "yes", "no"), "") -> no | E56: =IF($C56="yes", IF(Knowns!B48<>0, Knowns!B48, "****"), "") | F56: =IF($C56="yes", IF(Knowns!C48<>0, Knowns!C48, "****"), "") | G56: =IF($C56="yes", IF(Knowns!D48<>0, Knowns!D48, "****"), "") | H56: =IF($C56="yes", IF(Knowns!E48<>0, Knowns!E48, "****"), "") | I56: =IF($C56="yes", IF(Knowns!F48<>0, Knowns!F48, "****"), "")
A57: =IF(Knowns!A49<>"", Knowns!A49, "") -> Unknown TRFLP 002 | B57: =IF(A57<>"", MAX('Error Calc (bp)'!B49:G49), "") -> 40.04 | C57: =IF(A57<>"", IF(B57<Parameters!B$3, "yes", "no"), "") -> no | E57: =IF($C57="yes", IF(Knowns!B49<>0, Knowns!B49, "****"), "") | F57: =IF($C57="yes", IF(Knowns!C49<>0, Knowns!C49, "****"), "") | G57: =IF($C57="yes", IF(Knowns!D49<>0, Knowns!D49, "****"), "") | H57: =IF($C57="yes", IF(Knowns!E49<>0, Knowns!E49, "****"), "") | I57: =IF($C57="yes", IF(Knowns!F49<>0, Knowns!F49, "****"), "")
A58: =IF(Knowns!A50<>"", Knowns!A50, "") -> Unknown TRFLP 003 | B58: =IF(A58<>"", MAX('Error Calc (bp)'!B50:G50), "") -> 77.64 | C58: =IF(A58<>"", IF(B58<Parameters!B$3, "yes", "no"), "") -> no | E58: =IF($C58="yes", IF(Knowns!B50<>0, Knowns!B50, "****"), "") | F58: =IF($C58="yes", IF(Knowns!C50<>0, Knowns!C50, "****"), "") | G58: =IF($C58="yes", IF(Knowns!D50<>0, Knowns!D50, "****"), "") | H58: =IF($C58="yes", IF(Knowns!E50<>0, Knowns!E50, "****"), "") | I58: =IF($C58="yes", IF(Knowns!F50<>0, Knowns!F50, "****"), "")
A59: =IF(Knowns!A51<>"", Knowns!A51, "") -> Unknown TRFLP 004 | B59: =IF(A59<>"", MAX('Error Calc (bp)'!B51:G51), "") -> 332.95 | C59: =IF(A59<>"", IF(B59<Parameters!B$3, "yes", "no"), "") -> no | E59: =IF($C59="yes", IF(Knowns!B51<>0, Knowns!B51, "****"), "") | F59: =IF($C59="yes", IF(Knowns!C51<>0, Knowns!C51, "****"), "") | G59: =IF($C59="yes", IF(Knowns!D51<>0, Knowns!D51, "****"), "") | H59: =IF($C59="yes", IF(Knowns!E51<>0, Knowns!E51, "****"), "") | I59: =IF($C59="yes", IF(Knowns!F51<>0, Knowns!F51, "****"), "")
A60: =IF(Knowns!A52<>"", Knowns!A52, "") -> Unknown TRFLP 005 | B60: =IF(A60<>"", MAX('Error Calc (bp)'!B52:G52), "") -> 0.84 | C60: =IF(A60<>"", IF(B60<Parameters!B$3, "yes", "no"), "") -> yes | E60: =IF($C60="yes", IF(Knowns!B52<>0, Knowns!B52, "****"), "") -> 342.4 | F60: =IF($C60="yes", IF(Knowns!C52<>0, Knowns!C52, "****"), "") -> 245.2 | G60: =IF($C60="yes", IF(Knowns!D52<>0, Knowns!D52, "****"), "") -> 111.8 | H60: =IF($C60="yes", IF(Knowns!E52<>0, Knowns!E52, "****"), "") -> 99.1 | I60: =IF($C60="yes", IF(Knowns!F52<>0, Knowns!F52, "****"), "") -> ****
A61: =IF(Knowns!A53<>"", Knowns!A53, "") -> Unknown TRFLP 006 | B61: =IF(A61<>"", MAX('Error Calc (bp)'!B53:G53), "") -> 0.63 | C61: =IF(A61<>"", IF(B61<Parameters!B$3, "yes", "no"), "") -> yes | E61: =IF($C61="yes", IF(Knowns!B53<>0, Knowns!B53, "****"), "") -> 99.7 | F61: =IF($C61="yes", IF(Knowns!C53<>0, Knowns!C53, "****"), "") -> 314.8 | G61: =IF($C61="yes", IF(Knowns!D53<>0, Knowns!D53, "****"), "") -> 161.9 | H61: =IF($C61="yes", IF(Knowns!E53<>0, Knowns!E53, "****"), "") -> 132 | I61: =IF($C61="yes", IF(Knowns!F53<>0, Knowns!F53, "****"), "") -> ****
A62: =IF(Knowns!A54<>"", Knowns!A54, "") -> Unknown TRFLP 007 | B62: =IF(A62<>"", MAX('Error Calc (bp)'!B54:G54), "") -> 18.63 | C62: =IF(A62<>"", IF(B62<Parameters!B$3, "yes", "no"), "") -> no | E62: =IF($C62="yes", IF(Knowns!B54<>0, Knowns!B54, "****"), "") | F62: =IF($C62="yes", IF(Knowns!C54<>0, Knowns!C54, "****"), "") | G62: =IF($C62="yes", IF(Knowns!D54<>0, Knowns!D54, "****"), "") | H62: =IF($C62="yes", IF(Knowns!E54<>0, Knowns!E54, "****"), "") | I62: =IF($C62="yes", IF(Knowns!F54<>0, Knowns!F54, "****"), "")
A63: =IF(Knowns!A55<>"", Knowns!A55, "") -> Unknown TRFLP 008 | B63: =IF(A63<>"", MAX('Error Calc (bp)'!B55:G55), "") -> 56.74 | C63: =IF(A63<>"", IF(B63<Parameters!B$3, "yes", "no"), "") -> no | E63: =IF($C63="yes", IF(Knowns!B55<>0, Knowns!B55, "****"), "") | F63: =IF($C63="yes", IF(Knowns!C55<>0, Knowns!C55, "****"), "") | G63: =IF($C63="yes", IF(Knowns!D55<>0, Knowns!D55, "****"), "") | H63: =IF($C63="yes", IF(Knowns!E55<>0, Knowns!E55, "****"), "") | I63: =IF($C63="yes", IF(Knowns!F55<>0, Knowns!F55, "****"), "")
A64: =IF(Knowns!A56<>"", Knowns!A56, "") -> Unknown TRFLP 009 | B64: =IF(A64<>"", MAX('Error Calc (bp)'!B56:G56), "") -> 102.64 | C64: =IF(A64<>"", IF(B64<Parameters!B$3, "yes", "no"), "") -> no | E64: =IF($C64="yes", IF(Knowns!B56<>0, Knowns!B56, "****"), "") | F64: =IF($C64="yes", IF(Knowns!C56<>0, Knowns!C56, "****"), "") | G64: =IF($C64="yes", IF(Knowns!D56<>0, Knowns!D56, "****"), "") | H64: =IF($C64="yes", IF(Knowns!E56<>0, Knowns!E56, "****"), "") | I64: =IF($C64="yes", IF(Knowns!F56<>0, Knowns!F56, "****"), "")
A65: =IF(Knowns!A57<>"", Knowns!A57, "") -> Unknown TRFLP 010 | B65: =IF(A65<>"", MAX('Error Calc (bp)'!B57:G57), "") -> 406.05 | C65: =IF(A65<>"", IF(B65<Parameters!B$3, "yes", "no"), "") -> no | E65: =IF($C65="yes", IF(Knowns!B57<>0, Knowns!B57, "****"), "") | F65: =IF($C65="yes", IF(Knowns!C57<>0, Knowns!C57, "****"), "") | G65: =IF($C65="yes", IF(Knowns!D57<>0, Knowns!D57, "****"), "") | H65: =IF($C65="yes", IF(Knowns!E57<>0, Knowns!E57, "****"), "") | I65: =IF($C65="yes", IF(Knowns!F57<>0, Knowns!F57, "****"), "")
A66: =IF(Knowns!A58<>"", Knowns!A58, "") -> Unknown TRFLP 011 | B66: =IF(A66<>"", MAX('Error Calc (bp)'!B58:G58), "") -> 13.82 | C66: =IF(A66<>"", IF(B66<Parameters!B$3, "yes", "no"), "") -> no | E66: =IF($C66="yes", IF(Knowns!B58<>0, Knowns!B58, "****"), "") | F66: =IF($C66="yes", IF(Knowns!C58<>0, Knowns!C58, "****"), "") | G66: =IF($C66="yes", IF(Knowns!D58<>0, Knowns!D58, "****"), "") | H66: =IF($C66="yes", IF(Knowns!E58<>0, Knowns!E58, "****"), "") | I66: =IF($C66="yes", IF(Knowns!F58<>0, Knowns!F58, "****"), "")
... A209: =IF(Knowns!A201<>"", Knowns!A201, "") | B209: =IF(A209<>"", MAX('Error Calc (bp)'!B201:G201), "") | C209: =IF(A209<>"", IF(B209<Parameters!B$3, "yes", "no"), "") | E209: =IF($C209="yes", IF(Knowns!B201<>0, Knowns!B201, "****"), "") | F209: =IF($C209="yes", IF(Knowns!C201<>0, Knowns!C201, "****"), "") | G209: =IF($C209="yes", IF(Knowns!D201<>0, Knowns!D201, "****"), "") | H209: =IF($C209="yes", IF(Knowns!E201<>0, Knowns!E201, "****"), "") | I209: =IF($C209="yes", IF(Knowns!F201<>0, Knowns!F201, "****"), "")

Sheet Scratch Pad
A1: Unknown TRFLP 006 | B1: 0.63 | C1: yes | E1: 99.7 | F1: 314.8 | G1: 161.9 | H1: 132 | I1: ****
A2: Unknown TRFLP 005 | B2: 0.84 | C2: yes | E2: 342.4 | F2: 245.2 | G2: 111.8 | H2: 99.1 | I2: ****
A3: Lactarius oculatus | B3: 0.86 | C3: yes | E3: 387.8 | F3: 105.7 | G3: 247 | H3: 522.2
A4: MT S | B4: 0.95 | C4: yes | E4: **** | F4: **** | G4: 129 | H4: 266.3
A5: Clavulina cristata (=MT F,G,U,W) | B5: 1.28 | C5: yes | E5: 45 | F5: 366 | G5: 129.8 | H5: 266.4
A6: Ramaria concolor | B6: 3.41 | C6: no
A7: Unknown TRFLP 001 | B7: 6.16 | C7: no
A8: Amanita muscaria var. formosa | B8: 6.48 | C8: no
A9: Russula silvicola | B9: 12.65 | C9: no
A10: Unknown TRFLP 011 | B10: 13.82 | C10: no
A11: Clavarioid 2 | B11: 15.96 | C11: no
A12: Cenococcum geophilum (=MT B) | B12: 16.02 | C12: no
A13: Russula sp. red 1 | B13: 16.92 | C13: no
A14: Unknown TRFLP 007 | B14: 18.63 | C14: no
A15: Russula pseudolepida | B15: 18.96 | C15: no
A16: Boletus cf. miniato-pallescens | B16: 19.03 | C16: no
A17: Russula cf. vesca | B17: 19.808007 | C17: no
... A65: Clitocybe clavipes | B65: 630.45 | C65: no

Sheet Knowns
A1: Species | B1: =Parameters!B6 -> Hinf1-ITS4 | C1: =Parameters!C6 -> Hinf1-ITS1F | D1: =Parameters!D6 -> HaeIII-ITS4 | E1: =Parameters!E6 -> HaeIII-ITS1 | F1: =Parameters!F6 -> DpnII-ITS4 | G1: =Parameters!G6 -> (none)
A2: Amanita brunnescens | B2: 319.9 | C2: 414.8 | D2: 691.9 | E2: 696.8
A3: Amanita vaginata | B3: 266.8 | C3: 335.7 | D3: 81.7 | E3: 104.3 | F3: 193.8
A4: Amanita citrina | B4: 324.6 | C4: 228.8 | D4: 692.5 | E4: 700.5
A5: Amanita flavoconia | B5: 318.7 | C5: 390.6 | D5: 675.7 | E5: 682.3
A6: Amanita muscaria var. formosa | B6: 343.7 | C6: 354.3 | E6: 108.5
A7: Amanita rubescens | B7: 317.5 | C7: 406.2 | D7: 732.6 | E7: 742.3 | F7: 99.6
A8: Amanita sp. | B8: 285.5 | C8: 325.2 | D8: 520 | E8: 107.1
A9: Boletus cf. miniato-pallescens | B9: 89.7 | C9: 377.7 | D9: 176.7 | E9: 180.9
A10: Boletus cf. pallidus | B10: 368.4 | C10: 214 | D10: 194.8 | E10: 528.2
A11: Boletus cf. projectellus | B11: 454.6 | C11: 355.2 | D11: 120.4 | E11: 110.1 | F11: 169.3
A12: Boletus sp. | B12: 160 | C12: 71.1 | D12: 216.9 | E12: 197.3
A13: Cantharellula umbonata | B13: 100 | C13: 305.6 | D13: 690.1 | E13: 697.4 | F13: 153.1
A14: Cenococcum geophilum (=MT B) | B14: 97.7 | C14: 349.9 | D14: 202.4 | E14: 98.4 | F14: 106.8
A15: Clavarioid 2 | B15: 359.2 | C15: 366.2 | D15: 129 | E15: 268.5
A16: Clavulina cristata (=MT F,G,U,W) | B16: 45 | C16: 366 | D16: 129.8 | E16: 266.4
A17: Clitocybe clavipes | B17: 332.3 | C17: 159.1 | D17: 877.5 | E17: 93.5 | F17: 130.3
A18: Clitocybe robusta | B18: 315.9 | C18: 387.2 | D18: 436.1 | E18: 278
A19: Collybia cf. dryophila | B19: 466.6 | C19: 377.4 | D19: 580.1 | E19: 101.2
A20: Collybia sp. | B20: 393 | C20: 107.9 | D20: 753.2 | E20: 763.5
A21: Cortinarius a (=MT X) | B21: 320.8 | C21: 389.3 | D21: 440.4 | E21: 232.5
A22: Cortinarius b | B22: 187.9 | C22: 59.8 | F22: 186.2
A23: Cortinarius c | B23: 319 | C23: 120.3 | D23: 437.9 | E23: 277.7
A24: Hygrophoropsis aurantiaca | B24: 341.1 | C24: 408.5 | D24: 606.6 | E24: 133.1
A25: Laccaria laccata | B25: 323.7 | C25: 393.9 | D25: 727.2 | E25: 735.3 | F25: 400.9
A26: Lactarius sp. (=MT C) | B26: 388 | C26: 107 | D26: 702.1 | E26: 86.1 | F26: 201.4
A27: Lactarius oculatus | B27: 387.8 | C27: 105.7 | D27: 247 | E27: 522.2
A28: MT Q | B28: 343 | C28: 363.3 | D28: 85.8 | E28: 183.5
A29: MT R | B29: 195.2 | C29: 357.3 | D29: 216.3 | E29: 178.1
A30: MT S | D30: 129 | E30: 266.3
A31: Penicillium sp. | B31: 139.9 | C31: 325.5 | D31: 92.5 | E31: 79.7
A32: Polyporus sulphurea | B32: 316.1 | C32: 149.3 | D32: 560 | E32: 81.5
A33: Ramaria concolor | B33: 340 | C33: 345.3 | D33: 158.2 | E33: 99.7
A34: Russula cf. vesca | B34: 71 | C34: 365.8 | D34: 221.3 | E34: 502.9
A35: Russula pseudolepida | B35: 362.2 | C35: 344.2 | D35: 129.6 | E35: 266.5
A36: Russula sp. red 1 | B36: 370.3 | C36: 345.3 | E36: 170.8 | F36: 343.2
A37: Russula silvicola | B37: 91.6 | C37: 352.8 | D37: 259.7 | E37: 469.5
A38: Russula sp. white 1 (=MT A,C',H,J) | B38: 322.1 | C38: 361.4 | D38: 698.7 | E38: 700.1 | F38: 146.2
A39: Russula sp. white 2 | B39: 380 | C39: 363.4 | D39: 105.9 | E39: 498.5
A40: Saprotroph 6 (THW) | B40: 323.9 | C40: 423.3 | D40: 75.3 | E40: 76.5
...

Sheet ThresholdCalc
A1: =Parameters!B6 -> Hinf1-ITS4 | B1: =Parameters!C6 -> Hinf1-ITS1F | C1: =Parameters!D6 -> HaeIII-ITS4 | D1: =Parameters!E6 -> HaeIII-ITS1 | E1: =Parameters!F6 -> DpnII-ITS4 | F1: =Parameters!G6 -> (none)
A2: =IF('Unknown Data Entry'!C10>'Unknown Data Entry'!C$8, 'Unknown Data Entry'!B10, 9999) -> 42.91 | B2: =IF('Unknown Data Entry'!E10>'Unknown Data Entry'!E$8, 'Unknown Data Entry'!D10, 9999) -> 44.26 | C2: =IF('Unknown Data Entry'!G10>'Unknown Data Entry'!G$8, 'Unknown Data Entry'!F10, 9999) -> 42.91 | D2: =IF('Unknown Data Entry'!I10>'Unknown Data Entry'!I$8, 'Unknown Data Entry'!H10, 9999) -> 44.26 | E2: =IF('Unknown Data Entry'!K10>'Unknown Data Entry'!K$8, 'Unknown Data Entry'!J10, 9999) -> 9999 | F2: =IF('Unknown Data Entry'!M10>'Unknown Data Entry'!M$8, 'Unknown Data Entry'!L10, 9999) -> 9999
A3: =IF('Unknown Data Entry'!C11>'Unknown Data Entry'!C$8, 'Unknown Data Entry'!B11, 9999) -> 46.28 | B3: =IF('Unknown Data Entry'!E11>'Unknown Data Entry'!E$8, 'Unknown Data Entry'!D11, 9999) -> 9999 | C3: =IF('Unknown Data Entry'!G11>'Unknown Data Entry'!G$8, 'Unknown Data Entry'!F11, 9999) -> 54.83 | D3: =IF('Unknown Data Entry'!I11>'Unknown Data Entry'!I$8, 'Unknown Data Entry'!H11, 9999) -> 9999 | E3: =IF('Unknown Data Entry'!K11>'Unknown Data Entry'!K$8, 'Unknown Data Entry'!J11, 9999) -> 9999 | F3: =IF('Unknown Data Entry'!M11>'Unknown Data Entry'!M$8, 'Unknown Data Entry'!L11, 9999) -> 9999
A4: =IF('Unknown Data Entry'!C12>'Unknown Data Entry'!C$8, 'Unknown Data Entry'!B12, 9999) -> 9999 | B4: =IF('Unknown Data Entry'!E12>'Unknown Data Entry'!E$8, 'Unknown Data Entry'!D12, 9999) -> 82.89 | C4: =IF('Unknown Data Entry'!G12>'Unknown Data Entry'!G$8, 'Unknown Data Entry'!F12, 9999) -> 9999 | D4: =IF('Unknown Data Entry'!I12>'Unknown Data Entry'!I$8, 'Unknown Data Entry'!H12, 9999) -> 79.62 | E4: =IF('Unknown Data Entry'!K12>'Unknown Data Entry'!K$8, 'Unknown Data Entry'!J12, 9999) -> 9999 | F4: =IF('Unknown Data Entry'!M12>'Unknown Data Entry'!M$8, 'Unknown Data Entry'!L12, 9999) -> 9999
A5: =IF('Unknown Data Entry'!C13>'Unknown Data Entry'!C$8, 'Unknown Data Entry'!B13, 9999) -> 79.95 | B5: =IF('Unknown Data Entry'!E13>'Unknown Data Entry'!E$8, 'Unknown Data Entry'!D13, 9999) -> 9999 | C5: =IF('Unknown Data Entry'!G13>'Unknown Data Entry'!G$8, 'Unknown Data Entry'!F13, 9999) -> 79.29 | D5: =IF('Unknown Data Entry'!I13>'Unknown Data Entry'!I$8, 'Unknown Data Entry'!H13, 9999) -> 99.07 | E5: =IF('Unknown Data Entry'!K13>'Unknown Data Entry'!K$8, 'Unknown Data Entry'!J13, 9999) -> 9999 | F5: =IF('Unknown Data Entry'!M13>'Unknown Data Entry'!M$8, 'Unknown Data Entry'!L13, 9999) -> 9999
A6: =IF('Unknown Data Entry'!C14>'Unknown Data Entry'!C$8, 'Unknown Data Entry'!B14, 9999) -> 9999 | B6: =IF('Unknown Data Entry'!E14>'Unknown Data Entry'!E$8, 'Unknown Data Entry'!D14, 9999) -> 99.07 | C6: =IF('Unknown Data Entry'!G14>'Unknown Data Entry'!G$8, 'Unknown Data Entry'!F14, 9999) -> 9999 | D6: =IF('Unknown Data Entry'!I14>'Unknown Data Entry'!I$8, 'Unknown Data Entry'!H14, 9999) -> 112.32 | E6: =IF('Unknown Data Entry'!K14>'Unknown Data Entry'!K$8, 'Unknown Data Entry'!J14, 9999) -> 9999 | F6: =IF('Unknown Data Entry'!M14>'Unknown Data Entry'!M$8, 'Unknown Data Entry'!L14, 9999) -> 9999
A7: =IF('Unknown Data Entry'!C15>'Unknown Data Entry'!C$8, 'Unknown Data Entry'!B15, 9999) -> 99.07 | B7: =IF('Unknown Data Entry'!E15>'Unknown Data Entry'!E$8, 'Unknown Data Entry'!D15, 9999) -> 106.56 | C7: =IF('Unknown Data Entry'!G15>'Unknown Data Entry'!G$8, 'Unknown Data Entry'!F15, 9999) -> 9999 | D7: =IF('Unknown Data Entry'!I15>'Unknown Data Entry'!I$8, 'Unknown Data Entry'!H15, 9999) -> 131.93 | E7: =IF('Unknown Data Entry'!K15>'Unknown Data Entry'!K$8, 'Unknown Data Entry'!J15, 9999) -> 9999 | F7: =IF('Unknown Data Entry'!M15>'Unknown Data Entry'!M$8, 'Unknown Data Entry'!L15, 9999) -> 9999
A8: =IF('Unknown Data Entry'!C16>'Unknown Data Entry'!C$8, 'Unknown Data Entry'!B16, 9999) -> 9999 | B8: =IF('Unknown Data Entry'!E16>'Unknown Data Entry'!E$8, 'Unknown Data Entry'!D16, 9999) -> 9999 | C8: =IF('Unknown Data Entry'!G16>'Unknown Data Entry'!G$8, 'Unknown Data Entry'!F16, 9999) -> 112.32 | D8: =IF('Unknown Data Entry'!I16>'Unknown Data Entry'!I$8, 'Unknown Data Entry'!H16, 9999) -> 161.87 | E8: =IF('Unknown Data Entry'!K16>'Unknown Data Entry'!K$8, 'Unknown Data Entry'!J16, 9999) -> 9999 | F8: =IF('Unknown Data Entry'!M16>'Unknown Data Entry'!M$8, 'Unknown Data Entry'!L16, 9999) -> 9999
A9: =IF('Unknown Data Entry'!C17>'Unknown Data Entry'!C$8, 'Unknown Data Entry'!B17, 9999) -> 9999 | B9: =IF('Unknown Data Entry'!E17>'Unknown Data Entry'!E$8, 'Unknown Data Entry'!D17, 9999) -> 9999 | C9: =IF('Unknown Data Entry'!G17>'Unknown Data Entry'!G$8, 'Unknown Data Entry'!F17, 9999) -> 129.95 | D9: =IF('Unknown Data Entry'!I17>'Unknown Data Entry'!I$8, 'Unknown Data Entry'!H17, 9999) -> 247.05 | E9: =IF('Unknown Data Entry'!K17>'Unknown Data Entry'!K$8, 'Unknown Data Entry'!J17, 9999) -> 9999 | F9: =IF('Unknown Data Entry'!M17>'Unknown Data Entry'!M$8, 'Unknown Data Entry'!L17, 9999) -> 9999
A10: =IF('Unknown Data Entry'!C18>'Unknown Data Entry'!C$8, 'Unknown Data Entry'!B18, 9999) -> 9999 | B10: =IF('Unknown Data Entry'!E18>'Unknown Data Entry'!E$8, 'Unknown Data Entry'!D18, 9999) -> 245.24 | C10: =IF('Unknown Data Entry'!G18>'Unknown Data Entry'!G$8, 'Unknown Data Entry'!F18, 9999) -> 139.31 | D10: =IF('Unknown Data Entry'!I18>'Unknown Data Entry'!I$8, 'Unknown Data Entry'!H18, 9999) -> 266.83 | E10: =IF('Unknown Data Entry'!K18>'Unknown Data Entry'!K$8, 'Unknown Data Entry'!J18, 9999) -> 9999 | F10: =IF('Unknown Data Entry'!M18>'Unknown Data Entry'!M$8, 'Unknown Data Entry'!L18, 9999) -> 9999
A11: =IF('Unknown Data Entry'!C19>'Unknown Data Entry'!C$8, 'Unknown Data Entry'!B19, 9999) -> 9999 | B11: =IF('Unknown Data Entry'!E19>'Unknown Data Entry'!E$8, 'Unknown Data Entry'!D19, 9999) -> 9999 | C11: =IF('Unknown Data Entry'!G19>'Unknown Data Entry'!G$8, 'Unknown Data Entry'!F19, 9999) -> 9999 | D11: =IF('Unknown Data Entry'!I19>'Unknown Data Entry'!I$8, 'Unknown Data Entry'!H19, 9999) -> 431.93 | E11: =IF('Unknown Data Entry'!K19>'Unknown Data Entry'!K$8, 'Unknown Data Entry'!J19, 9999) -> 9999 | F11: =IF('Unknown Data Entry'!M19>'Unknown Data Entry'!M$8, 'Unknown Data Entry'!L19, 9999) -> 9999
A12: =IF('Unknown Data Entry'!C20>'Unknown Data Entry'!C$8, 'Unknown Data Entry'!B20, 9999) -> 9999 | B12: =IF('Unknown Data Entry'!E20>'Unknown Data Entry'!E$8, 'Unknown Data Entry'!D20, 9999) -> 9999 | C12: =IF('Unknown Data Entry'!G20>'Unknown Data Entry'!G$8, 'Unknown Data Entry'!F20, 9999) -> 9999 | D12: =IF('Unknown Data Entry'!I20>'Unknown Data Entry'!I$8, 'Unknown Data Entry'!H20, 9999) -> 455.63 | E12: =IF('Unknown Data Entry'!K20>'Unknown Data Entry'!K$8, 'Unknown Data Entry'!J20, 9999) -> 9999 | F12: =IF('Unknown Data Entry'!M20>'Unknown Data Entry'!M$8, 'Unknown Data Entry'!L20, 9999) -> 9999
A13: =IF('Unknown Data Entry'!C21>'Unknown Data Entry'!C$8, 'Unknown Data Entry'!B21, 9999) -> 9999 | B13: =IF('Unknown Data Entry'!E21>'Unknown Data Entry'!E$8, 'Unknown Data Entry'!D21, 9999) -> 9999 | C13: =IF('Unknown Data Entry'!G21>'Unknown Data Entry'!G$8, 'Unknown Data Entry'!F21, 9999) -> 9999 | D13: =IF('Unknown Data Entry'!I21>'Unknown Data Entry'!I$8, 'Unknown Data Entry'!H21, 9999) -> 459.29 | E13: =IF('Unknown Data Entry'!K21>'Unknown Data Entry'!K$8, 'Unknown Data Entry'!J21, 9999) -> 9999 | F13: =IF('Unknown Data Entry'!M21>'Unknown Data Entry'!M$8, 'Unknown Data Entry'!L21, 9999) -> 9999
... A51: =IF('Unknown Data Entry'!C59>'Unknown Data Entry'!C$8, 'Unknown Data Entry'!B59, 9999) -> 9999 | B51: =IF('Unknown Data Entry'!E59>'Unknown Data Entry'!E$8, 'Unknown Data Entry'!D59, 9999) -> 9999 | C51: =IF('Unknown Data Entry'!G59>'Unknown Data Entry'!G$8, 'Unknown Data Entry'!F59, 9999) -> 9999 | D51: =IF('Unknown Data Entry'!I59>'Unknown Data Entry'!I$8, 'Unknown Data Entry'!H59, 9999) -> 9999 | E51: =IF('Unknown Data Entry'!K59>'Unknown Data Entry'!K$8, 'Unknown Data Entry'!J59, 9999) -> 9999 | F51: =IF('Unknown Data Entry'!M59>'Unknown Data Entry'!M$8, 'Unknown Data Entry'!L59, 9999) -> 9999

Sheet Clean Unknown
A1: =Parameters!B6 -> Hinf1-ITS4 | B1: =Parameters!C6 -> Hinf1-ITS1F | C1: =Parameters!D6 -> HaeIII-ITS4 | D1: =Parameters!E6 -> HaeIII-ITS1 | E1: =Parameters!F6 -> DpnII-ITS4 | F1: =Parameters!G6 -> (none)
A2: =IF(Unknown!C10>Unknown!C$8, Unknown!B10, 9999) -> 42.91 | B2: =IF(Unknown!E10>Unknown!E$8, Unknown!D10, 9999) -> 44.26 | C2: =IF(Unknown!G10>Unknown!G$8, Unknown!F10, 9999) -> 42.91 | D2: =IF(Unknown!I10>Unknown!I$8, Unknown!H10, 9999) -> 44.26 | E2: =IF(Unknown!K10>Unknown!K$8, Unknown!J10, 9999) -> 9999 | F2: =IF(Unknown!M10>Unknown!M$8, Unknown!L10, 9999) -> 9999
A3: =IF(Unknown!C11>Unknown!C$8, Unknown!B11, 9999) -> 46.28 | B3: =IF(Unknown!E11>Unknown!E$8, Unknown!D11, 9999) -> 9999 | C3: =IF(Unknown!G11>Unknown!G$8, Unknown!F11, 9999) -> 54.83 | D3: =IF(Unknown!I11>Unknown!I$8, Unknown!H11, 9999) -> 9999 | E3: =IF(Unknown!K11>Unknown!K$8, Unknown!J11, 9999) -> 9999 | F3: =IF(Unknown!M11>Unknown!M$8, Unknown!L11, 9999) -> 9999
A4: =IF(Unknown!C12>Unknown!C$8, Unknown!B12, 9999) -> 9999 | B4: =IF(Unknown!E12>Unknown!E$8, Unknown!D12, 9999) -> 82.89 | C4: =IF(Unknown!G12>Unknown!G$8, Unknown!F12, 9999) -> 9999 | D4: =IF(Unknown!I12>Unknown!I$8, Unknown!H12, 9999) -> 79.62 | E4: =IF(Unknown!K12>Unknown!K$8, Unknown!J12, 9999) -> 9999 | F4: =IF(Unknown!M12>Unknown!M$8, Unknown!L12, 9999) -> 9999
A5: =IF(Unknown!C13>Unknown!C$8, Unknown!B13, 9999) -> 79.95 | B5: =IF(Unknown!E13>Unknown!E$8, Unknown!D13, 9999) -> 9999 | C5: =IF(Unknown!G13>Unknown!G$8, Unknown!F13, 9999) -> 79.29 | D5: =IF(Unknown!I13>Unknown!I$8, Unknown!H13, 9999) -> 99.07 | E5: =IF(Unknown!K13>Unknown!K$8, Unknown!J13, 9999) -> 9999 | F5: =IF(Unknown!M13>Unknown!M$8, Unknown!L13, 9999) -> 9999
A6: =IF(Unknown!C14>Unknown!C$8, Unknown!B14, 9999) -> 9999 | B6: =IF(Unknown!E14>Unknown!E$8, Unknown!D14, 9999) -> 99.07 | C6: =IF(Unknown!G14>Unknown!G$8, Unknown!F14, 9999) -> 9999 | D6: =IF(Unknown!I14>Unknown!I$8, Unknown!H14, 9999) -> 112.32 | E6: =IF(Unknown!K14>Unknown!K$8, Unknown!J14, 9999) -> 9999 | F6: =IF(Unknown!M14>Unknown!M$8, Unknown!L14, 9999) -> 9999
A7: =IF(Unknown!C15>Unknown!C$8, Unknown!B15, 9999) -> 99.07 | B7: =IF(Unknown!E15>Unknown!E$8, Unknown!D15, 9999) -> 106.56 | C7: =IF(Unknown!G15>Unknown!G$8, Unknown!F15, 9999) -> 9999 | D7: =IF(Unknown!I15>Unknown!I$8, Unknown!H15, 9999) -> 131.93 | E7: =IF(Unknown!K15>Unknown!K$8, Unknown!J15, 9999) -> 9999 | F7: =IF(Unknown!M15>Unknown!M$8, Unknown!L15, 9999) -> 9999
A8: =IF(Unknown!C16>Unknown!C$8, Unknown!B16, 9999) -> 9999 | B8: =IF(Unknown!E16>Unknown!E$8, Unknown!D16, 9999) -> 9999 | C8: =IF(Unknown!G16>Unknown!G$8, Unknown!F16, 9999) -> 112.32 | D8: =IF(Unknown!I16>Unknown!I$8, Unknown!H16, 9999) -> 161.87 | E8: =IF(Unknown!K16>Unknown!K$8, Unknown!J16, 9999) -> 9999 | F8: =IF(Unknown!M16>Unknown!M$8, Unknown!L16, 9999) -> 9999
A9: =IF(Unknown!C17>Unknown!C$8, Unknown!B17, 9999) -> 9999 | B9: =IF(Unknown!E17>Unknown!E$8, Unknown!D17, 9999) -> 9999 | C9: =IF(Unknown!G17>Unknown!G$8, Unknown!F17, 9999) -> 129.95 | D9: =IF(Unknown!I17>Unknown!I$8, Unknown!H17, 9999) -> 247.05 | E9: =IF(Unknown!K17>Unknown!K$8, Unknown!J17, 9999) -> 9999 | F9: =IF(Unknown!M17>Unknown!M$8, Unknown!L17, 9999) -> 9999
A10: =IF(Unknown!C18>Unknown!C$8, Unknown!B18, 9999) -> 9999 | B10: =IF(Unknown!E18>Unknown!E$8, Unknown!D18, 9999) -> 245.24 | C10: =IF(Unknown!G18>Unknown!G$8, Unknown!F18, 9999) -> 139.31 | D10: =IF(Unknown!I18>Unknown!I$8, Unknown!H18, 9999) -> 266.83 | E10: =IF(Unknown!K18>Unknown!K$8, Unknown!J18, 9999) -> 9999 | F10: =IF(Unknown!M18>Unknown!M$8, Unknown!L18, 9999) -> 9999
A11: =IF(Unknown!C19>Unknown!C$8, Unknown!B19, 9999) -> 9999 | B11: =IF(Unknown!E19>Unknown!E$8, Unknown!D19, 9999) -> 9999 | C11: =IF(Unknown!G19>Unknown!G$8, Unknown!F19, 9999) -> 9999 | D11: =IF(Unknown!I19>Unknown!I$8, Unknown!H19, 9999) -> 431.93 | E11: =IF(Unknown!K19>Unknown!K$8, Unknown!J19, 9999) -> 9999 | F11: =IF(Unknown!M19>Unknown!M$8, Unknown!L19, 9999) -> 9999
A12: =IF(Unknown!C20>Unknown!C$8, Unknown!B20, 9999) -> 9999 | B12: =IF(Unknown!E20>Unknown!E$8, Unknown!D20, 9999) -> 9999 | C12: =IF(Unknown!G20>Unknown!G$8, Unknown!F20, 9999) -> 9999 | D12: =IF(Unknown!I20>Unknown!I$8, Unknown!H20, 9999) -> 455.63 | E12: =IF(Unknown!K20>Unknown!K$8, Unknown!J20, 9999) -> 9999 | F12: =IF(Unknown!M20>Unknown!M$8, Unknown!L20, 9999) -> 9999
A13: =IF(Unknown!C21>Unknown!C$8, Unknown!B21, 9999) -> 9999 | B13: =IF(Unknown!E21>Unknown!E$8, Unknown!D21, 9999) -> 9999 | C13: =IF(Unknown!G21>Unknown!G$8, Unknown!F21, 9999) -> 9999 | D13: =IF(Unknown!I21>Unknown!I$8, Unknown!H21, 9999) -> 459.29 | E13: =IF(Unknown!K21>Unknown!K$8, Unknown!J21, 9999) -> 9999 | F13: =IF(Unknown!M21>Unknown!M$8, Unknown!L21, 9999) -> 9999
... A51: =IF(Unknown!C59>Unknown!C$8, Unknown!B59, 9999) -> 9999 | B51: =IF(Unknown!E59>Unknown!E$8, Unknown!D59, 9999) -> 9999 | C51: =IF(Unknown!G59>Unknown!G$8, Unknown!F59, 9999) -> 9999 | D51: =IF(Unknown!I59>Unknown!I$8, Unknown!H59, 9999) -> 9999 | E51: =IF(Unknown!K59>Unknown!K$8, Unknown!J59, 9999) -> 9999 | F51: =IF(Unknown!M59>Unknown!M$8, Unknown!L59, 9999) -> 9999

Sheet Error Calc (bp)
A1: Species | B1: =Parameters!B6 -> Hinf1-ITS4 | C1: =Parameters!C6 -> Hinf1-ITS1F | D1: =Parameters!D6 -> HaeIII-ITS4 | E1: =Parameters!E6 -> HaeIII-ITS1 | F1: =Parameters!F6 -> DpnII-ITS4 | G1: =Parameters!G6 -> (none)
A2: =Knowns!A2 -> Amanita brunnescens | B2: {=IF(Knowns!B2<>"",IF(MIN('Clean Unknown'!A$2:A$52) < 9999,MIN(ABS(Knowns!B2-'Clean Unknown'!A$2:A$52)),""),"")} -> 23.34 | C2: {=IF(Knowns!C2<>"",IF(MIN('Clean Unknown'!B$2:B$52) < 9999,MIN(ABS(Knowns!C2-'Clean Unknown'!B$2:B$52)),""),"")} -> 27.32 | D2: {=IF(Knowns!D2<>"",IF(MIN('Clean Unknown'!C$2:C$52) < 9999,MIN(ABS(Knowns!D2-'Clean Unknown'!C$2:C$52)),""),"")} -> 444.85 | E2: {=IF(Knowns!E2<>"",IF(MIN('Clean Unknown'!D$2:D$52) < 9999,MIN(ABS(Knowns!E2-'Clean Unknown'!D$2:D$52)),""),"")} -> 174.09199 | F2: {=IF(Knowns!F2<>"",IF(MIN('Clean Unknown'!E$2:E$52) < 9999,MIN(ABS(Knowns!F2-'Clean Unknown'!E$2:E$52)),""),"")} | G2: {=IF(Knowns!G2<>"",IF(MIN('Clean Unknown'!F$2:F$52) < 9999,MIN(ABS(Knowns!G2-'Clean Unknown'!F$2:F$52)),""),"")}
A3: =Knowns!A3 -> Amanita vaginata | B3: {=IF(Knowns!B3<>"",IF(MIN('Clean Unknown'!A$2:A$52) < 9999,MIN(ABS(Knowns!B3-'Clean Unknown'!A$2:A$52)),""),"")} -> 76.44 | C3: {=IF(Knowns!C3<>"",IF(MIN('Clean Unknown'!B$2:B$52) < 9999,MIN(ABS(Knowns!C3-'Clean Unknown'!B$2:B$52)),""),"")} -> 8.08 | D3: {=IF(Knowns!D3<>"",IF(MIN('Clean Unknown'!C$2:C$52) < 9999,MIN(ABS(Knowns!D3-'Clean Unknown'!C$2:C$52)),""),"")} -> 2.41 | E3: {=IF(Knowns!E3<>"",IF(MIN('Clean Unknown'!D$2:D$52) < 9999,MIN(ABS(Knowns!E3-'Clean Unknown'!D$2:D$52)),""),"")} -> 5.23 | F3: {=IF(Knowns!F3<>"",IF(MIN('Clean Unknown'!E$2:E$52) < 9999,MIN(ABS(Knowns!F3-'Clean Unknown'!E$2:E$52)),""),"")} | G3: {=IF(Knowns!G3<>"",IF(MIN('Clean Unknown'!F$2:F$52) < 9999,MIN(ABS(Knowns!G3-'Clean Unknown'!F$2:F$52)),""),"")}
A4: =Knowns!A4 -> Amanita citrina | B4: {=IF(Knowns!B4<>"",IF(MIN('Clean Unknown'!A$2:A$52) < 9999,MIN(ABS(Knowns!B4-'Clean Unknown'!A$2:A$52)),""),"")} -> 18.64 | C4: {=IF(Knowns!C4<>"",IF(MIN('Clean Unknown'!B$2:B$52) < 9999,MIN(ABS(Knowns!C4-'Clean Unknown'!B$2:B$52)),""),"")} -> 16.44 | D4: {=IF(Knowns!D4<>"",IF(MIN('Clean Unknown'!C$2:C$52) < 9999,MIN(ABS(Knowns!D4-'Clean Unknown'!C$2:C$52)),""),"")} -> 445.45 | E4: {=IF(Knowns!E4<>"",IF(MIN('Clean Unknown'!D$2:D$52) < 9999,MIN(ABS(Knowns!E4-'Clean Unknown'!D$2:D$52)),""),"")} -> 177.79199 | F4: {=IF(Knowns!F4<>"",IF(MIN('Clean Unknown'!E$2:E$52) < 9999,MIN(ABS(Knowns!F4-'Clean Unknown'!E$2:E$52)),""),"")} | G4: {=IF(Knowns!G4<>"",IF(MIN('Clean Unknown'!F$2:F$52) < 9999,MIN(ABS(Knowns!G4-'Clean Unknown'!F$2:F$52)),""),"")}
A5: =Knowns!A5 -> Amanita flavoconia | B5: {=IF(Knowns!B5<>"",IF(MIN('Clean Unknown'!A$2:A$52) < 9999,MIN(ABS(Knowns!B5-'Clean Unknown'!A$2:A$52)),""),"")} -> 24.54 | C5: {=IF(Knowns!C5<>"",IF(MIN('Clean Unknown'!B$2:B$52) < 9999,MIN(ABS(Knowns!C5-'Clean Unknown'!B$2:B$52)),""),"")} -> 3.12 | D5: {=IF(Knowns!D5<>"",IF(MIN('Clean Unknown'!C$2:C$52) < 9999,MIN(ABS(Knowns!D5-'Clean Unknown'!C$2:C$52)),""),"")} -> 428.65 | E5: {=IF(Knowns!E5<>"",IF(MIN('Clean Unknown'!D$2:D$52) < 9999,MIN(ABS(Knowns!E5-'Clean Unknown'!D$2:D$52)),""),"")} -> 159.59199 | F5: {=IF(Knowns!F5<>"",IF(MIN('Clean Unknown'!E$2:E$52) < 9999,MIN(ABS(Knowns!F5-'Clean Unknown'!E$2:E$52)),""),"")} | G5: {=IF(Knowns!G5<>"",IF(MIN('Clean Unknown'!F$2:F$52) < 9999,MIN(ABS(Knowns!G5-'Clean Unknown'!F$2:F$52)),""),"")}
A6: =Knowns!A6 -> Amanita muscaria var. formosa | B6: {=IF(Knowns!B6<>"",IF(MIN('Clean Unknown'!A$2:A$52) < 9999,MIN(ABS(Knowns!B6-'Clean Unknown'!A$2:A$52)),""),"")} -> 0.46 | C6: {=IF(Knowns!C6<>"",IF(MIN('Clean Unknown'!B$2:B$52) < 9999,MIN(ABS(Knowns!C6-'Clean Unknown'!B$2:B$52)),""),"")} -> 6.48 | D6: {=IF(Knowns!D6<>"",IF(MIN('Clean Unknown'!C$2:C$52) < 9999,MIN(ABS(Knowns!D6-'Clean Unknown'!C$2:C$52)),""),"")} | E6: {=IF(Knowns!E6<>"",IF(MIN('Clean Unknown'!D$2:D$52) < 9999,MIN(ABS(Knowns!E6-'Clean Unknown'!D$2:D$52)),""),"")} -> 3.82 | F6: {=IF(Knowns!F6<>"",IF(MIN('Clean Unknown'!E$2:E$52) < 9999,MIN(ABS(Knowns!F6-'Clean Unknown'!E$2:E$52)),""),"")} | G6: {=IF(Knowns!G6<>"",IF(MIN('Clean Unknown'!F$2:F$52) < 9999,MIN(ABS(Knowns!G6-'Clean Unknown'!F$2:F$52)),""),"")}
A7: =Knowns!A7 -> Amanita rubescens | B7: {=IF(Knowns!B7<>"",IF(MIN('Clean Unknown'!A$2:A$52) < 9999,MIN(ABS(Knowns!B7-'Clean Unknown'!A$2:A$52)),""),"")} -> 25.74 | C7: {=IF(Knowns!C7<>"",IF(MIN('Clean Unknown'!B$2:B$52) < 9999,MIN(ABS(Knowns!C7-'Clean Unknown'!B$2:B$52)),""),"")} -> 18.72 | D7: {=IF(Knowns!D7<>"",IF(MIN('Clean Unknown'!C$2:C$52) < 9999,MIN(ABS(Knowns!D7-'Clean Unknown'!C$2:C$52)),""),"")} -> 485.55 | E7: {=IF(Knowns!E7<>"",IF(MIN('Clean Unknown'!D$2:D$52) < 9999,MIN(ABS(Knowns!E7-'Clean Unknown'!D$2:D$52)),""),"")} -> 219.59199 | F7: {=IF(Knowns!F7<>"",IF(MIN('Clean Unknown'!E$2:E$52) < 9999,MIN(ABS(Knowns!F7-'Clean Unknown'!E$2:E$52)),""),"")} | G7: {=IF(Knowns!G7<>"",IF(MIN('Clean Unknown'!F$2:F$52) < 9999,MIN(ABS(Knowns!G7-'Clean Unknown'!F$2:F$52)),""),"")}
A8: =Knowns!A8 -> Amanita sp. | B8: {=IF(Knowns!B8<>"",IF(MIN('Clean Unknown'!A$2:A$52) < 9999,MIN(ABS(Knowns!B8-'Clean Unknown'!A$2:A$52)),""),"")} -> 57.74 | C8: {=IF(Knowns!C8<>"",IF(MIN('Clean Unknown'!B$2:B$52) < 9999,MIN(ABS(Knowns!C8-'Clean Unknown'!B$2:B$52)),""),"")} -> 10.01 | D8: {=IF(Knowns!D8<>"",IF(MIN('Clean Unknown'!C$2:C$52) < 9999,MIN(ABS(Knowns!D8-'Clean Unknown'!C$2:C$52)),""),"")} -> 272.95 | E8: {=IF(Knowns!E8<>"",IF(MIN('Clean Unknown'!D$2:D$52) < 9999,MIN(ABS(Knowns!E8-'Clean Unknown'!D$2:D$52)),""),"")} -> 5.22 | F8: {=IF(Knowns!F8<>"",IF(MIN('Clean Unknown'!E$2:E$52) < 9999,MIN(ABS(Knowns!F8-'Clean Unknown'!E$2:E$52)),""),"")} | G8: {=IF(Knowns!G8<>"",IF(MIN('Clean Unknown'!F$2:F$52) < 9999,MIN(ABS(Knowns!G8-'Clean Unknown'!F$2:F$52)),""),"")}
A9: =Knowns!A9 -> Boletus cf. miniato-pallescens | B9: {=IF(Knowns!B9<>"",IF(MIN('Clean Unknown'!A$2:A$52) < 9999,MIN(ABS(Knowns!B9-'Clean Unknown'!A$2:A$52)),""),"")} -> 9.37 | C9: {=IF(Knowns!C9<>"",IF(MIN('Clean Unknown'!B$2:B$52) < 9999,MIN(ABS(Knowns!C9-'Clean Unknown'!B$2:B$52)),""),"")} -> 9.78 | D9: {=IF(Knowns!D9<>"",IF(MIN('Clean Unknown'!C$2:C$52) < 9999,MIN(ABS(Knowns!D9-'Clean Unknown'!C$2:C$52)),""),"")} -> 5.98 | E9: {=IF(Knowns!E9<>"",IF(MIN('Clean Unknown'!D$2:D$52) < 9999,MIN(ABS(Knowns!E9-'Clean Unknown'!D$2:D$52)),""),"")} -> 19.03 | F9: {=IF(Knowns!F9<>"",IF(MIN('Clean Unknown'!E$2:E$52) < 9999,MIN(ABS(Knowns!F9-'Clean Unknown'!E$2:E$52)),""),"")} | G9: {=IF(Knowns!G9<>"",IF(MIN('Clean Unknown'!F$2:F$52) < 9999,MIN(ABS(Knowns!G9-'Clean Unknown'!F$2:F$52)),""),"")}
A10: =Knowns!A10 -> Boletus cf. pallidus | B10: {=IF(Knowns!B10<>"",IF(MIN('Clean Unknown'!A$2:A$52) < 9999,MIN(ABS(Knowns!B10-'Clean Unknown'!A$2:A$52)),""),"")} -> 18.82 | C10: {=IF(Knowns!C10<>"",IF(MIN('Clean Unknown'!B$2:B$52) < 9999,MIN(ABS(Knowns!C10-'Clean Unknown'!B$2:B$52)),""),"")} -> 31.24 | D10: {=IF(Knowns!D10<>"",IF(MIN('Clean Unknown'!C$2:C$52) < 9999,MIN(ABS(Knowns!D10-'Clean Unknown'!C$2:C$52)),""),"")} -> 23.62 | E10: {=IF(Knowns!E10<>"",IF(MIN('Clean Unknown'!D$2:D$52) < 9999,MIN(ABS(Knowns!E10-'Clean Unknown'!D$2:D$52)),""),"")} -> 5.4919928 | F10: {=IF(Knowns!F10<>"",IF(MIN('Clean Unknown'!E$2:E$52) < 9999,MIN(ABS(Knowns!F10-'Clean Unknown'!E$2:E$52)),""),"")} | G10: {=IF(Knowns!G10<>"",IF(MIN('Clean Unknown'!F$2:F$52) < 9999,MIN(ABS(Knowns!G10-'Clean Unknown'!F$2:F$52)),""),"")}
A11: =Knowns!A11 -> Boletus cf. projectellus | B11: {=IF(Knowns!B11<>"",IF(MIN('Clean Unknown'!A$2:A$52) < 9999,MIN(ABS(Knowns!B11-'Clean Unknown'!A$2:A$52)),""),"")} -> 67.38 | C11: {=IF(Knowns!C11<>"",IF(MIN('Clean Unknown'!B$2:B$52) < 9999,MIN(ABS(Knowns!C11-'Clean Unknown'!B$2:B$52)),""),"")} -> 5.58 | D11: {=IF(Knowns!D11<>"",IF(MIN('Clean Unknown'!C$2:C$52) < 9999,MIN(ABS(Knowns!D11-'Clean Unknown'!C$2:C$52)),""),"")} -> 8.08 | E11: {=IF(Knowns!E11<>"",IF(MIN('Clean Unknown'!D$2:D$52) < 9999,MIN(ABS(Knowns!E11-'Clean Unknown'!D$2:D$52)),""),"")} -> 2.22 | F11: {=IF(Knowns!F11<>"",IF(MIN('Clean Unknown'!E$2:E$52) < 9999,MIN(ABS(Knowns!F11-'Clean Unknown'!E$2:E$52)),""),"")} | G11: {=IF(Knowns!G11<>"",IF(MIN('Clean Unknown'!F$2:F$52) < 9999,MIN(ABS(Knowns!G11-'Clean Unknown'!F$2:F$52)),""),"")}
A12: =Knowns!A12 -> Boletus sp. | B12: {=IF(Knowns!B12<>"",IF(MIN('Clean Unknown'!A$2:A$52) < 9999,MIN(ABS(Knowns!B12-'Clean Unknown'!A$2:A$52)),""),"")} -> 60.93 | C12: {=IF(Knowns!C12<>"",IF(MIN('Clean Unknown'!B$2:B$52) < 9999,MIN(ABS(Knowns!C12-'Clean Unknown'!B$2:B$52)),""),"")} -> 11.79 | D12: {=IF(Knowns!D12<>"",IF(MIN('Clean Unknown'!C$2:C$52) < 9999,MIN(ABS(Knowns!D12-'Clean Unknown'!C$2:C$52)),""),"")} -> 1.52 | E12: {=IF(Knowns!E12<>"",IF(MIN('Clean Unknown'!D$2:D$52) < 9999,MIN(ABS(Knowns!E12-'Clean Unknown'!D$2:D$52)),""),"")} -> 35.43 | F12: {=IF(Knowns!F12<>"",IF(MIN('Clean Unknown'!E$2:E$52) < 9999,MIN(ABS(Knowns!F12-'Clean Unknown'!E$2:E$52)),""),"")} | G12: {=IF(Knowns!G12<>"",IF(MIN('Clean Unknown'!F$2:F$52) < 9999,MIN(ABS(Knowns!G12-'Clean Unknown'!F$2:F$52)),""),"")}
A13: =Knowns!A13 -> Cantharellula umbonata | B13: {=IF(Knowns!B13<>"",IF(MIN('Clean Unknown'!A$2:A$52) < 9999,MIN(ABS(Knowns!B13-'Clean Unknown'!A$2:A$52)),""),"")} -> 0.93 | C13: {=IF(Knowns!C13<>"",IF(MIN('Clean Unknown'!B$2:B$52) < 9999,MIN(ABS(Knowns!C13-'Clean Unknown'!B$2:B$52)),""),"")} -> 5.06 | D13: {=IF(Knowns!D13<>"",IF(MIN('Clean Unknown'!C$2:C$52) < 9999,MIN(ABS(Knowns!D13-'Clean Unknown'!C$2:C$52)),""),"")} -> 443.05 | E13: {=IF(Knowns!E13<>"",IF(MIN('Clean Unknown'!D$2:D$52) < 9999,MIN(ABS(Knowns!E13-'Clean Unknown'!D$2:D$52)),""),"")} -> 174.69199 | F13: {=IF(Knowns!F13<>"",IF(MIN('Clean Unknown'!E$2:E$52) < 9999,MIN(ABS(Knowns!F13-'Clean Unknown'!E$2:E$52)),""),"")} | G13: {=IF(Knowns!G13<>"",IF(MIN('Clean Unknown'!F$2:F$52) < 9999,MIN(ABS(Knowns!G13-'Clean Unknown'!F$2:F$52)),""),"")}
... A201: =Knowns!A201 -> 0 | B201: {=IF(Knowns!B201<>"",IF(MIN('Clean Unknown'!A$2:A$52) < 9999,MIN(ABS(Knowns!B201-'Clean Unknown'!A$2:A$52)),""),"")} | C201: {=IF(Knowns!C201<>"",IF(MIN('Clean Unknown'!B$2:B$52) < 9999,MIN(ABS(Knowns!C201-'Clean Unknown'!B$2:B$52)),""),"")} | D201: {=IF(Knowns!D201<>"",IF(MIN('Clean Unknown'!C$2:C$52) < 9999,MIN(ABS(Knowns!D201-'Clean Unknown'!C$2:C$52)),""),"")} | E201: {=IF(Knowns!E201<>"",IF(MIN('Clean Unknown'!D$2:D$52) < 9999,MIN(ABS(Knowns!E201-'Clean Unknown'!D$2:D$52)),""),"")} | F201: {=IF(Knowns!F201<>"",IF(MIN('Clean Unknown'!E$2:E$52) < 9999,MIN(ABS(Knowns!F201-'Clean Unknown'!E$2:E$52)),""),"")} | G201: {=IF(Knowns!G201<>"",IF(MIN('Clean Unknown'!F$2:F$52) < 9999,MIN(ABS(Knowns!G201-'Clean Unknown'!F$2:F$52)),""),"")}
