Workbook

Sheet Instructions
B2: HIPAA EDI TRANSACTION RISK SELF ASSESSMENT CHECKLIST
B4: Checklist Information
B5: This risk assessment checklist is provided as a self-assessment tool to allow States or agencies to gauge where they are in the overall picture of HIPAA implementation. This checklist is intended to be used by the HIPAA Coordinator, HIPAA Project Lead, or other key agency representative in the State, Medicaid agency, or other agency. Use of this checklist is voluntary; it is intended to assist the agency and is not required to be submitted to CMS.
B7: It is in the organization’s best interest to answer the questions as honestly and accurately as possible. The HIPAA Project Lead or HIPAA Project Coordinator is usually in the best position to provide accurate answers to the questions and can act as the best judge of the status of each project area in the checklist. The Green, Yellow, and Red indicators correspond to levels of risk. The intent of this tool is to highlight areas within the HIPAA project that may be in need of attention. If a segment of the checklist is not green, then each question for which a "No" answer was supplied should be examined, and the reason for which the "No" was given should be understood.
B9: "Yes" Criteria
B10: The "Yes" box following each item can be checked if the person completing the checklist can respond positively to the question (i.e., the item is completed or in progress). The "Yes" box can also be checked if adequate resources and planning have been allocated for future efforts. If these criteria are not met, the "No" column should be checked.
B12: Using the Checklist
B13: To begin using the tool, click on the "Data Input" tab at the lower left hand corner of this spreadsheet. Scroll through the sections and answer each question "yes" or "no" as appropriate by clicking in the corresponding box. There is a color-coded cell in the header of each section that will change according to the risk associated with that section. When all sections have been completed, you may scroll back through the sections and look for the yellow and red cells or proceeed to the results worksheet by clicking on the "Results" tab at the bottom of the screen.
B15: Results
B16: Each question in the checklist has been individually weighted (i.e., answering yes to 3 out of 4 questions in one section may yield a different score than answering 3 out of 4 in another section). These individually weighted scores are then combined to produce a score for that section. The results worksheet provides a bar graph and table that display the risk score for each part of the checklist. Very low scores indicate areas of probable high risk. High scores do not indicate no risk, rather areas of the project that, based on the answers given, should not be a problem for the project.
B18: Help
B19: For technical assistance with this checklist you may contact Bob Guenther (robert.guenther@titan.com). For general questions, or for more information regarding the tool you may contact Henry Chao in the CMS Central Office (hchao@cms.hhs.gov).

Sheet Data Input
B2: HIPAA EDI Transaction Risk Assessment Checklist
C6: =SUM(C8,C66,C82,C129,C160,C195,C212,C225,C261,C291)/10 -> 0
B8: Part A – HIPAA Project Office, Budgets, Resources, Contracts, and Plans | C8: =SUM(C10,C19,C40,C53)/46*100 -> 0
B9: Part A | C9: =SUM(C10,C19,C40,C53)/46*100 -> 0
B10: 1.0 HIPAA Project Office (HPO) Established | C10: =SUM(F11,F13,F15,F17) -> 0 | J10: =SUM(C10,C19,C40,C53)/46*100 -> 0 | K10: Part A
B11: Is an HPO established? | D11: FALSE | E11: FALSE | F11: =IF(D11,3,0) -> 0 | G11: =IF(E11,1,0) -> 0 | J11: =SUM(C69)/10*100 -> 0 | K11: Part B
J12: =SUM(C85,C96,C103,C112,C119)/31*100 -> 0 | K12: Part C
B13: Does the HPO have a written charter and a defined role? | D13: FALSE | E13: FALSE | F13: =IF(D13,1,0) -> 0 | G13: =IF(E13,1,0) -> 0 | J13: =SUM(C131,C148)/27*100 -> 0 | K13: Part D
J14: =SUM(C163,C174,C185)/32*100 -> 0 | K14: Part E
B15: Does the HPO have support at the highest State executive levels? | D15: FALSE | E15: FALSE | F15: =IF(D15,1,0) -> 0 | G15: =IF(E15,1,0) -> 0 | J15: =SUM(C198)/16*100 -> 0 | K15: Part F
J16: =SUM(C215)/9*100 -> 0 | K16: Part G
B17: Is there a current Organization chart and Charter document? | D17: FALSE | E17: FALSE | F17: =IF(D17,1,0) -> 0 | G17: =IF(E17,1,0) -> 0 | J17: =SUM(C228,C243)/30*100 -> 0 | K17: Part H
J18: =SUM(C264,C275)/31*100 -> 0 | K18: Part I
B19: 2.0 HIPAA Budgets, Resources, And Contracts | C19: =SUM(F20,F22,F24,F26,F28,F30,F32,F34,F36,F38) -> 0 | J19: =SUM(C294)/13*100 -> 0 | K19: Part J
B20: Are the HIPAA budget requirements known in detail? | D20: FALSE | E20: FALSE | F20: =IF(D20,3,0) -> 0 | G20: =IF(E20,1,0) -> 0
B22: Are the needed APDs submitted and approved for HIPAA? | D22: FALSE | E22: FALSE | F22: =IF(D22,3,0) -> 0 | G22: =IF(E22,1,0) -> 0
B24: Is there a resource plan? | D24: FALSE | E24: FALSE | F24: =IF(D24,3,0) -> 0 | G24: =IF(E24,1,0) -> 0
B26: Are the staffing requirements assessed for the entire project? | D26: FALSE | E26: FALSE | F26: =IF(D26,2,0) -> 0 | G26: =IF(E26,1,0) -> 0
B28: Are staffing resources available when needed? | D28: FALSE | E28: FALSE | F28: =IF(D28,2,0) -> 0 | G28: =IF(E28,1,0) -> 0
B30: Does the HPO have a firm commitment of resources and staff to meet the requirements? | D30: FALSE | E30: FALSE | F30: =IF(D30,1,0) -> 0 | G30: =IF(E30,1,0) -> 0
B32: Are all necessary RFPs for resources and staff completed? | D32: FALSE | E32: FALSE | F32: =IF(D32,1,0) -> 0 | G32: =IF(E32,1,0) -> 0
E33: FALSE
B34: Are contracts in place for additional resources and staff? | D34: FALSE | E34: FALSE | F34: =IF(D34,1,0) -> 0 | G34: =IF(E34,1,0) -> 0
B36: Are contracts in place for needed software (translators, for example)? | D36: FALSE | E36: FALSE | F36: =IF(D36,1,0) -> 0 | G36: =IF(E36,1,0) -> 0
B38: Are other needed services and support contracts in place? | D38: FALSE | E38: FALSE | F38: =IF(D38,1,0) -> 0 | G38: =IF(E38,1,0) -> 0
B40: 3.0 State or Agency HIPAA Plan | C40: =SUM(F41,F43,F45,F47,F49,F51) -> 0
B41: Is there an overall State or Agency (or comparable) HIPAA plan? | D41: FALSE | E41: FALSE | F41: =IF(D41,3,0) -> 0 | G41: =IF(E41,1,0) -> 0
B43: If needed, are there individual department plans? | D43: FALSE | E43: FALSE | F43: =IF(D43,3,0) -> 0 | G43: =IF(E43,1,0) -> 0
B45: Are reasonable timelines established for critical activities? | D45: FALSE | E45: FALSE | F45: =IF(D45,3,0) -> 0 | G45: =IF(E45,1,0) -> 0
B47: Are specific individuals responsible for updating the plan? | D47: FALSE | E47: FALSE | F47: =IF(D47,2,0) -> 0 | G47: =IF(E47,1,0) -> 0
B49: Does the plan include outreach activities? | D49: FALSE | E49: FALSE | F49: =IF(D49,2,0) -> 0 | G49: =IF(E49,1,0) -> 0
B51: Is there a plan for implementation of future HIPAA rules (NPI, Transaction Version Changes, Plan ID, Claims Attachments)? | D51: FALSE | E51: FALSE | F51: =IF(D51,1,0) -> 0 | G51: =IF(E51,1,0) -> 0
B53: 4.0 Scheduling and Tracking Project Activities | C53: =SUM(F54,F56,F58,F60,F62) -> 0
B54: Do HIPAA schedules define tasks and milestones, indicating responsible entities and dependencies? | D54: FALSE | E54: FALSE | F54: =IF(D54,3,0) -> 0 | G54: =IF(E54,1,0) -> 0
B56: Is there a process and tools to support maintaining HIPAA project plans and schedules? | D56: FALSE | E56: FALSE | F56: =IF(D56,1,0) -> 0 | G56: =IF(E56,1,0) -> 0
B58: Do all departments, divisions, and units report to the HPO on HIPAA progress? | D58: FALSE | E58: FALSE | F58: =IF(D58,2,0) -> 0 | G58: =IF(E58,1,0) -> 0
B60: Is there periodic Executive level review of progress and deadlines? | D60: FALSE | E60: FALSE | F60: =IF(D60,1,0) -> 0 | G60: =IF(E60,1,0) -> 0
B62: Has a request for a one-year implementation delay been submitted (by Oct 16, 2002)? | D62: FALSE | E62: FALSE | F62: =IF(D62,1,0) -> 0 | G62: =IF(E62,1,0) -> 0
B66: Part B - Definition of Covered Entity Status | C66: =SUM(F70,F72,F74,F76,F78)/10*100 -> 0
B68: Part B | C68: =SUM(F70,F72,F74,F76,F78)/10*100 -> 0
...

Sheet Results
C3: Overall Self Assessment Score Is: | E3: ='Data Input'!$C6 -> 0
D30: Risk by Section
C32: Part A | D32: HIPAA Project Office, Budgets, Resources, Contracts, and Plans | E32: ='Data Input'!$C8 -> 0
C34: Part B | D34: Definition of Covered Entity Status | E34: ='Data Input'!$C66 -> 0
C36: Part C | D36: Coordination of State Medicaid (or Other Agency) Enterprise | E36: ='Data Input'!$C82 -> 0
C38: Part D | D38: Impact on Medicaid (or Other Agency) Business Processes | E38: ='Data Input'!$C129 -> 0
C40: Part E | D40: System Impact Assessment | E40: ='Data Input'!$C160 -> 0
C42: Part F | D42: Design of System and Business Process Changes | E42: ='Data Input'!$C195 -> 0
C44: Part G | D44: System Renovation | E44: ='Data Input'!$C212 -> 0
C46: Part H | D46: Validation and Testing | E46: ='Data Input'!$C225 -> 0
C48: Part I | D48: Implementation and Transition | E48: ='Data Input'!$C261 -> 0
C50: Part J | D50: Contingency Planning | E50: ='Data Input'!$C291 -> 0
