Workbook

Sheet Emission Graphs

Sheet Total Emissions
A1: SUMMARY OF TOTAL EMISSIONS | H1: =NOW() -> 43857.445
A3: ENTITY: | B3: =IF('Tufts Summary Data'!B2="Enter Entity Name Here","*****",'Tufts Summary Data'!B2) -> Tufts University GHG Emissions
A5: SHORT TONS in Carbon Equivalents
A6: Year | B6: CO2 | C6: CH4 | D6: N2O | E6: CF4 | F6: C2F6 | G6: Total
C7: (methane) | D7: (nitrous oxide) | E7: perfluoromethane | F7: perfluoroethane | G7: Carbon Equivalents
A8: 1990 | B8: ='Energy Use Emissions'!K8*'Conversion Factors'!B$26*(12/44) -> 17368.082 | C8: =('Agriculture Emissions'!H8+'Agriculture Emissions'!H25)*'Conversion Factors'!B$27*(12/44) -> 69.734848 | G8: =SUM(B8:F8) -> 17437.817
A9: 1991 | B9: ='Energy Use Emissions'!K9*'Conversion Factors'!B$26*(12/44) -> 0 | C9: =('Agriculture Emissions'!H9+'Agriculture Emissions'!H26)*'Conversion Factors'!B$27*(12/44) -> 0 | G9: =SUM(B9:F9) -> 0
A10: 1992 | B10: ='Energy Use Emissions'!K10*'Conversion Factors'!B$26*(12/44) -> 0 | C10: =('Agriculture Emissions'!H10+'Agriculture Emissions'!H27)*'Conversion Factors'!B$27*(12/44) -> 0 | G10: =SUM(B10:F10) -> 0
A11: 1993 | B11: ='Energy Use Emissions'!K11*'Conversion Factors'!B$26*(12/44) -> 0 | C11: =('Agriculture Emissions'!H11+'Agriculture Emissions'!H28)*'Conversion Factors'!B$27*(12/44) -> 0 | G11: =SUM(B11:F11) -> 0
A12: 1994 | B12: ='Energy Use Emissions'!K12*'Conversion Factors'!B$26*(12/44) -> 0 | C12: =('Agriculture Emissions'!H12+'Agriculture Emissions'!H29)*'Conversion Factors'!B$27*(12/44) -> 0 | G12: =SUM(B12:F12) -> 0
A13: 1995 | B13: ='Energy Use Emissions'!K13*'Conversion Factors'!B$26*(12/44) -> 0 | C13: =('Agriculture Emissions'!H13+'Agriculture Emissions'!H30)*'Conversion Factors'!B$27*(12/44) -> 0 | G13: =SUM(B13:F13) -> 0
A14: 1996 | B14: ='Energy Use Emissions'!K14*'Conversion Factors'!B$26*(12/44) -> 0 | C14: =('Agriculture Emissions'!H14+'Agriculture Emissions'!H31)*'Conversion Factors'!B$27*(12/44) -> 0 | G14: =SUM(B14:F14) -> 0
A15: 1997 | B15: ='Energy Use Emissions'!K15*'Conversion Factors'!B$26*(12/44) -> 0 | C15: =('Agriculture Emissions'!H15+'Agriculture Emissions'!H32)*'Conversion Factors'!B$27*(12/44) -> 0 | G15: =SUM(B15:F15) -> 0
A16: 1998 | B16: ='Energy Use Emissions'!K16*'Conversion Factors'!B$26*(12/44) -> 19516.788 | C16: =('Agriculture Emissions'!H16+'Agriculture Emissions'!H33)*'Conversion Factors'!B$27*(12/44) -> 85.150694 | G16: =SUM(B16:F16) -> 19601.939
A17: 1999 | B17: ='Energy Use Emissions'!K17*'Conversion Factors'!B$26*(12/44) -> 0 | C17: =('Agriculture Emissions'!H17+'Agriculture Emissions'!H34)*'Conversion Factors'!B$27*(12/44) -> 0 | G17: =SUM(B17:F17) -> 0
A18: 2000 | B18: ='Energy Use Emissions'!K18*'Conversion Factors'!B$26*(12/44) -> 0 | C18: =('Agriculture Emissions'!H18+'Agriculture Emissions'!H35)*'Conversion Factors'!B$27*(12/44) -> 0 | G18: =SUM(B18:F18) -> 0
A21: METRIC TONS in Carbon Equivalents
A22: Year | B22: CO2 | C22: CH4 | D22: N2O | E22: CF4 | F22: C2F6 | G22: Total | H22: Total | I22: Total
C23: (methane) | D23: (nitrous oxide) | E23: (perfluoromethane) | F23: (perfluoroethane) | G23: MTCE | H23: MTCE/Area (sqft) | I23: MTCE/FTE Student
A24: 1990 | B24: =B8*0.9072 -> 15756.324 | C24: =C8*0.9072 -> 63.263455 | G24: =SUM(B24:F24) -> 15819.588 | H24: =IF('Tufts Summary Data'!B72 > 0, G24/'Tufts Summary Data'!B72) -> 0.0043401087 | I24: =IF('Tufts Summary Data'!D72 > 0, G24/'Tufts Summary Data'!D72) -> 2.04546
A25: 1991 | B25: =B9*0.9072 -> 0 | C25: =C9*0.9072 -> 0 | G25: =SUM(B25:F25) -> 0 | H25: =IF('Tufts Summary Data'!B73 > 0, G25/'Tufts Summary Data'!B73) -> FALSE | I25: =IF('Tufts Summary Data'!D73 > 0, G25/'Tufts Summary Data'!D73) -> FALSE
A26: 1992 | B26: =B10*0.9072 -> 0 | C26: =C10*0.9072 -> 0 | G26: =SUM(B26:F26) -> 0 | H26: =IF('Tufts Summary Data'!B74 > 0, G26/'Tufts Summary Data'!B74) -> FALSE | I26: =IF('Tufts Summary Data'!D74 > 0, G26/'Tufts Summary Data'!D74) -> FALSE
A27: 1993 | B27: =B11*0.9072 -> 0 | C27: =C11*0.9072 -> 0 | G27: =SUM(B27:F27) -> 0 | H27: =IF('Tufts Summary Data'!B75 > 0, G27/'Tufts Summary Data'!B75) -> FALSE | I27: =IF('Tufts Summary Data'!D75 > 0, G27/'Tufts Summary Data'!D75) -> FALSE
A28: 1994 | B28: =B12*0.9072 -> 0 | C28: =C12*0.9072 -> 0 | G28: =SUM(B28:F28) -> 0 | H28: =IF('Tufts Summary Data'!B76 > 0, G28/'Tufts Summary Data'!B76) -> FALSE | I28: =IF('Tufts Summary Data'!D76 > 0, G28/'Tufts Summary Data'!D76) -> FALSE
A29: 1995 | B29: =B13*0.9072 -> 0 | C29: =C13*0.9072 -> 0 | G29: =SUM(B29:F29) -> 0 | H29: =IF('Tufts Summary Data'!B77 > 0, G29/'Tufts Summary Data'!B77) -> FALSE | I29: =IF('Tufts Summary Data'!D77 > 0, G29/'Tufts Summary Data'!D77) -> FALSE
A30: 1996 | B30: =B14*0.9072 -> 0 | C30: =C14*0.9072 -> 0 | G30: =SUM(B30:F30) -> 0 | H30: =IF('Tufts Summary Data'!B78 > 0, G30/'Tufts Summary Data'!B78) -> FALSE | I30: =IF('Tufts Summary Data'!D78 > 0, G30/'Tufts Summary Data'!D78) -> FALSE
A31: 1997 | B31: =B15*0.9072 -> 0 | C31: =C15*0.9072 -> 0 | G31: =SUM(B31:F31) -> 0 | H31: =IF('Tufts Summary Data'!B79 > 0, G31/'Tufts Summary Data'!B79) -> FALSE | I31: =IF('Tufts Summary Data'!D79 > 0, G31/'Tufts Summary Data'!D79) -> FALSE
A32: 1998 | B32: =B16*0.9072 -> 17705.63 | C32: =C16*0.9072 -> 77.24871 | G32: =SUM(B32:F32) -> 17782.879 | H32: =IF('Tufts Summary Data'!B80 > 0, G32/'Tufts Summary Data'!B80) -> 0.0045775839 | I32: =IF('Tufts Summary Data'!D80 > 0, G32/'Tufts Summary Data'!D80) -> 2.1800759
A33: 1999 | B33: =B17*0.9072 -> 0 | C33: =C17*0.9072 -> 0 | G33: =SUM(B33:F33) -> 0 | H33: =IF('Tufts Summary Data'!B81 > 0, G33/'Tufts Summary Data'!B81) -> FALSE | I33: =IF('Tufts Summary Data'!D81 > 0, G33/'Tufts Summary Data'!D81) -> FALSE
A34: 2000 | B34: =B18*0.9072 -> 0 | C34: =C18*0.9072 -> 0 | G34: =SUM(B34:F34) -> 0 | H34: =IF('Tufts Summary Data'!B82 > 0, G34/'Tufts Summary Data'!B82) -> FALSE | I34: =IF('Tufts Summary Data'!D82 > 0, G34/'Tufts Summary Data'!D82) -> FALSE
B36: Inventory Estimates | D36: Reduction Requirements | G36: Emissions Intensity
B38: Year | C38: Emissions | D38: Emissions | E38: Percent | G38: Year | H38: By student | I38: By Area
C39: (MTCE) | D39: (MTCE) | E39: Reduction | H39: MTCE/FTE Student | I39: MTCE/Area (sqft)
B40: 1990 | C40: =G24 -> 15819.588 | D40: - | E40: - | G40: 1990 | H40: =I24 -> 2.04546 | I40: =H24 -> 0.0043401087
B41: 1998 | C41: =G32 -> 17782.879 | D41: =C41-C43 -> 3070.6623 | E41: =D41/C41 -> 0.17267521 | G41: 1998 | H41: =I32 -> 2.1800759 | I41: =H32 -> 0.0045775839
B42: 2010 | C42: =FORECAST(2010,C40:C41,$B40:$B41) -> 20727.816 | D42: =C42-C43 -> 6015.5991 | E42: =D42/C42 -> 0.29021867 | G42: 2010 | H42: =FORECAST(2010,H40:H41,$B40:$B41) -> 2.3819997 | I42: =FORECAST(2010,I40:I41,$B40:$B41) -> 0.0049337967
B43: Target | C43: =G24*0.93 -> 14712.217 | D43: - | E43: -
B44: (7% below 1990)
A47: Tufts University Categories of Emissions Released (MTCE):
H48: Gasoline | I48: Gasoline
...

Sheet Tufts Summary Data
A1: QUANTITIES OF ENERGY AND MATERIALS USED | G1: =NOW() -> 43857.445
A2: ENTITY: | B2: Tufts University GHG Emissions
A4: Total Quantities of Fuel Used:
A5: Year | H5: Gasoline | I5: Gasoline
B6: Electricity | C6: Gas | D6: #6 Oil | E6: #2 Oil | F6: Propane | G6: Steam | H6: On Campus | I6: Commuters | J6: Diesel
B7: (kWh) | C7: (Ccf)* | D7: (gal.) | E7: (gal.) | F7: (gal.) | G7: (Mlb.)** | H7: (gal.) | I7: (gal.) | J7: (gal.)
A8: 1990 | B8: =SUM('Medford Data:Boston Data'!B8) -> 38102663 | C8: =SUM('Medford Data:Boston Data'!C8) -> 327856 | D8: =SUM('Medford Data:Boston Data'!D8) -> 795000 | E8: =SUM('Medford Data:Boston Data'!E8) -> 444870 | F8: =SUM('Medford Data:Boston Data'!F8) -> 0 | G8: =SUM('Medford Data:Boston Data'!G8) -> 39904 | H8: =SUM('Medford Data:Boston Data'!H8) -> 55800 | I8: =SUM('Medford Data:Boston Data'!I8) -> 351000 | J8: =SUM('Medford Data:Boston Data'!J8) -> 0
A9: 1991 | B9: =SUM('Medford Data:Boston Data'!B9) -> 0 | C9: =SUM('Medford Data:Boston Data'!C9) -> 0 | D9: =SUM('Medford Data:Boston Data'!D9) -> 0 | E9: =SUM('Medford Data:Boston Data'!E9) -> 0 | F9: =SUM('Medford Data:Boston Data'!F9) -> 0 | G9: =SUM('Medford Data:Boston Data'!G9) -> 0 | H9: =SUM('Medford Data:Boston Data'!H9) -> 0 | I9: =SUM('Medford Data:Boston Data'!I9) -> 0 | J9: =SUM('Medford Data:Boston Data'!J9) -> 0
A10: 1992 | B10: =SUM('Medford Data:Boston Data'!B10) -> 0 | C10: =SUM('Medford Data:Boston Data'!C10) -> 0 | D10: =SUM('Medford Data:Boston Data'!D10) -> 0 | E10: =SUM('Medford Data:Boston Data'!E10) -> 0 | F10: =SUM('Medford Data:Boston Data'!F10) -> 0 | G10: =SUM('Medford Data:Boston Data'!G10) -> 0 | H10: =SUM('Medford Data:Boston Data'!H10) -> 0 | I10: =SUM('Medford Data:Boston Data'!I10) -> 0 | J10: =SUM('Medford Data:Boston Data'!J10) -> 0
A11: 1993 | B11: =SUM('Medford Data:Boston Data'!B11) -> 0 | C11: =SUM('Medford Data:Boston Data'!C11) -> 0 | D11: =SUM('Medford Data:Boston Data'!D11) -> 0 | E11: =SUM('Medford Data:Boston Data'!E11) -> 0 | F11: =SUM('Medford Data:Boston Data'!F11) -> 0 | G11: =SUM('Medford Data:Boston Data'!G11) -> 0 | H11: =SUM('Medford Data:Boston Data'!H11) -> 0 | I11: =SUM('Medford Data:Boston Data'!I11) -> 0 | J11: =SUM('Medford Data:Boston Data'!J11) -> 0
A12: 1994 | B12: =SUM('Medford Data:Boston Data'!B12) -> 0 | C12: =SUM('Medford Data:Boston Data'!C12) -> 0 | D12: =SUM('Medford Data:Boston Data'!D12) -> 0 | E12: =SUM('Medford Data:Boston Data'!E12) -> 0 | F12: =SUM('Medford Data:Boston Data'!F12) -> 0 | G12: =SUM('Medford Data:Boston Data'!G12) -> 0 | H12: =SUM('Medford Data:Boston Data'!H12) -> 0 | I12: =SUM('Medford Data:Boston Data'!I12) -> 0 | J12: =SUM('Medford Data:Boston Data'!J12) -> 0
A13: 1995 | B13: =SUM('Medford Data:Boston Data'!B13) -> 0 | C13: =SUM('Medford Data:Boston Data'!C13) -> 0 | D13: =SUM('Medford Data:Boston Data'!D13) -> 0 | E13: =SUM('Medford Data:Boston Data'!E13) -> 0 | F13: =SUM('Medford Data:Boston Data'!F13) -> 0 | G13: =SUM('Medford Data:Boston Data'!G13) -> 0 | H13: =SUM('Medford Data:Boston Data'!H13) -> 0 | I13: =SUM('Medford Data:Boston Data'!I13) -> 0 | J13: =SUM('Medford Data:Boston Data'!J13) -> 0
A14: 1996 | B14: =SUM('Medford Data:Boston Data'!B14) -> 0 | C14: =SUM('Medford Data:Boston Data'!C14) -> 0 | D14: =SUM('Medford Data:Boston Data'!D14) -> 0 | E14: =SUM('Medford Data:Boston Data'!E14) -> 0 | F14: =SUM('Medford Data:Boston Data'!F14) -> 0 | G14: =SUM('Medford Data:Boston Data'!G14) -> 0 | H14: =SUM('Medford Data:Boston Data'!H14) -> 0 | I14: =SUM('Medford Data:Boston Data'!I14) -> 0 | J14: =SUM('Medford Data:Boston Data'!J14) -> 0
A15: 1997 | B15: =SUM('Medford Data:Boston Data'!B15) -> 0 | C15: =SUM('Medford Data:Boston Data'!C15) -> 0 | D15: =SUM('Medford Data:Boston Data'!D15) -> 0 | E15: =SUM('Medford Data:Boston Data'!E15) -> 0 | F15: =SUM('Medford Data:Boston Data'!F15) -> 0 | G15: =SUM('Medford Data:Boston Data'!G15) -> 0 | H15: =SUM('Medford Data:Boston Data'!H15) -> 0 | I15: =SUM('Medford Data:Boston Data'!I15) -> 0 | J15: =SUM('Medford Data:Boston Data'!J15) -> 0
A16: 1998 | B16: =SUM('Medford Data:Boston Data'!B16) -> 49656638 | C16: =SUM('Medford Data:Boston Data'!C16) -> 869418 | D16: =SUM('Medford Data:Boston Data'!D16) -> 676893 | E16: =SUM('Medford Data:Boston Data'!E16) -> 450240 | F16: =SUM('Medford Data:Boston Data'!F16) -> 13346 | G16: =SUM('Medford Data:Boston Data'!G16) -> 40653 | H16: =SUM('Medford Data:Boston Data'!H16) -> 61852 | I16: =SUM('Medford Data:Boston Data'!I16) -> 349000 | J16: =SUM('Medford Data:Boston Data'!J16) -> 0
A17: 1999 | B17: =SUM('Medford Data:Boston Data'!B17) -> 0 | C17: =SUM('Medford Data:Boston Data'!C17) -> 0 | D17: =SUM('Medford Data:Boston Data'!D17) -> 0 | E17: =SUM('Medford Data:Boston Data'!E17) -> 0 | F17: =SUM('Medford Data:Boston Data'!F17) -> 0 | G17: =SUM('Medford Data:Boston Data'!G17) -> 0 | H17: =SUM('Medford Data:Boston Data'!H17) -> 0 | I17: =SUM('Medford Data:Boston Data'!I17) -> 0 | J17: =SUM('Medford Data:Boston Data'!J17) -> 0
A18: 2000 | B18: =SUM('Medford Data:Boston Data'!B18) -> 0 | C18: =SUM('Medford Data:Boston Data'!C18) -> 0 | D18: =SUM('Medford Data:Boston Data'!D18) -> 0 | E18: =SUM('Medford Data:Boston Data'!E18) -> 0 | F18: =SUM('Medford Data:Boston Data'!F18) -> 0 | G18: =SUM('Medford Data:Boston Data'!G18) -> 0 | H18: =SUM('Medford Data:Boston Data'!H18) -> 0 | I18: =SUM('Medford Data:Boston Data'!I18) -> 0 | J18: =SUM('Medford Data:Boston Data'!J18) -> 0
A21: Quantities of Solid Waste Materials in Short Tons:
B22: Landfill | C22: Landfill | E22: Composted | F22: Composted
A23: Year | B23: No LFG | C23: Electricity | D23: Incineration | E23: Food | F23: Landscaping
B24: Recovery | C24: Generation | E24: Wastes | F24: Wastes
A25: 1990 | B25: =SUM('Medford Data:Boston Data'!B25) -> 0 | C25: =SUM('Medford Data:Boston Data'!C25) -> 3400 | D25: =SUM('Medford Data:Boston Data'!D25) -> 70 | E25: =SUM('Medford Data:Boston Data'!E25) -> 0 | F25: =SUM('Medford Data:Boston Data'!F25) -> 0 | G25: =SUM('Medford Data:Boston Data'!G25) -> 0 | H25: =SUM('Medford Data:Boston Data'!H25) -> 0 | I25: =SUM('Medford Data:Boston Data'!I25) -> 0 | J25: =SUM('Medford Data:Boston Data'!J25) -> 0
A26: 1991 | B26: =SUM('Medford Data:Boston Data'!B26) -> 0 | C26: =SUM('Medford Data:Boston Data'!C26) -> 0 | D26: =SUM('Medford Data:Boston Data'!D26) -> 0 | E26: =SUM('Medford Data:Boston Data'!E26) -> 0 | F26: =SUM('Medford Data:Boston Data'!F26) -> 0 | G26: =SUM('Medford Data:Boston Data'!G26) -> 0 | H26: =SUM('Medford Data:Boston Data'!H26) -> 0 | I26: =SUM('Medford Data:Boston Data'!I26) -> 0 | J26: =SUM('Medford Data:Boston Data'!J26) -> 0
A27: 1992 | B27: =SUM('Medford Data:Boston Data'!B27) -> 0 | C27: =SUM('Medford Data:Boston Data'!C27) -> 0 | D27: =SUM('Medford Data:Boston Data'!D27) -> 0 | E27: =SUM('Medford Data:Boston Data'!E27) -> 0 | F27: =SUM('Medford Data:Boston Data'!F27) -> 0 | G27: =SUM('Medford Data:Boston Data'!G27) -> 0 | H27: =SUM('Medford Data:Boston Data'!H27) -> 0 | I27: =SUM('Medford Data:Boston Data'!I27) -> 0 | J27: =SUM('Medford Data:Boston Data'!J27) -> 0
A28: 1993 | B28: =SUM('Medford Data:Boston Data'!B28) -> 0 | C28: =SUM('Medford Data:Boston Data'!C28) -> 0 | D28: =SUM('Medford Data:Boston Data'!D28) -> 0 | E28: =SUM('Medford Data:Boston Data'!E28) -> 0 | F28: =SUM('Medford Data:Boston Data'!F28) -> 0 | G28: =SUM('Medford Data:Boston Data'!G28) -> 0 | H28: =SUM('Medford Data:Boston Data'!H28) -> 0 | I28: =SUM('Medford Data:Boston Data'!I28) -> 0 | J28: =SUM('Medford Data:Boston Data'!J28) -> 0
A29: 1994 | B29: =SUM('Medford Data:Boston Data'!B29) -> 0 | C29: =SUM('Medford Data:Boston Data'!C29) -> 0 | D29: =SUM('Medford Data:Boston Data'!D29) -> 0 | E29: =SUM('Medford Data:Boston Data'!E29) -> 0 | F29: =SUM('Medford Data:Boston Data'!F29) -> 0 | G29: =SUM('Medford Data:Boston Data'!G29) -> 0 | H29: =SUM('Medford Data:Boston Data'!H29) -> 0 | I29: =SUM('Medford Data:Boston Data'!I29) -> 0 | J29: =SUM('Medford Data:Boston Data'!J29) -> 0
A30: 1995 | B30: =SUM('Medford Data:Boston Data'!B30) -> 0 | C30: =SUM('Medford Data:Boston Data'!C30) -> 0 | D30: =SUM('Medford Data:Boston Data'!D30) -> 0 | E30: =SUM('Medford Data:Boston Data'!E30) -> 0 | F30: =SUM('Medford Data:Boston Data'!F30) -> 0 | G30: =SUM('Medford Data:Boston Data'!G30) -> 0 | H30: =SUM('Medford Data:Boston Data'!H30) -> 0 | I30: =SUM('Medford Data:Boston Data'!I30) -> 0 | J30: =SUM('Medford Data:Boston Data'!J30) -> 0
A31: 1996 | B31: =SUM('Medford Data:Boston Data'!B31) -> 0 | C31: =SUM('Medford Data:Boston Data'!C31) -> 0 | D31: =SUM('Medford Data:Boston Data'!D31) -> 0 | E31: =SUM('Medford Data:Boston Data'!E31) -> 0 | F31: =SUM('Medford Data:Boston Data'!F31) -> 0 | G31: =SUM('Medford Data:Boston Data'!G31) -> 0 | H31: =SUM('Medford Data:Boston Data'!H31) -> 0 | I31: =SUM('Medford Data:Boston Data'!I31) -> 0 | J31: =SUM('Medford Data:Boston Data'!J31) -> 0
A32: 1997 | B32: =SUM('Medford Data:Boston Data'!B32) -> 0 | C32: =SUM('Medford Data:Boston Data'!C32) -> 0 | D32: =SUM('Medford Data:Boston Data'!D32) -> 0 | E32: =SUM('Medford Data:Boston Data'!E32) -> 0 | F32: =SUM('Medford Data:Boston Data'!F32) -> 0 | G32: =SUM('Medford Data:Boston Data'!G32) -> 0 | H32: =SUM('Medford Data:Boston Data'!H32) -> 0 | I32: =SUM('Medford Data:Boston Data'!I32) -> 0 | J32: =SUM('Medford Data:Boston Data'!J32) -> 0
A33: 1998 | B33: =SUM('Medford Data:Boston Data'!B33) -> 0 | C33: =SUM('Medford Data:Boston Data'!C33) -> 4000 | D33: =SUM('Medford Data:Boston Data'!D33) -> 500 | E33: =SUM('Medford Data:Boston Data'!E33) -> 50 | F33: =SUM('Medford Data:Boston Data'!F33) -> 0 | G33: =SUM('Medford Data:Boston Data'!G33) -> 0 | H33: =SUM('Medford Data:Boston Data'!H33) -> 0 | I33: =SUM('Medford Data:Boston Data'!I33) -> 0 | J33: =SUM('Medford Data:Boston Data'!J33) -> 0
A34: 1999 | B34: =SUM('Medford Data:Boston Data'!B34) -> 0 | C34: =SUM('Medford Data:Boston Data'!C34) -> 0 | D34: =SUM('Medford Data:Boston Data'!D34) -> 0 | E34: =SUM('Medford Data:Boston Data'!E34) -> 0 | F34: =SUM('Medford Data:Boston Data'!F34) -> 0 | G34: =SUM('Medford Data:Boston Data'!G34) -> 0 | H34: =SUM('Medford Data:Boston Data'!H34) -> 0 | I34: =SUM('Medford Data:Boston Data'!I34) -> 0 | J34: =SUM('Medford Data:Boston Data'!J34) -> 0
A35: 2000 | B35: =SUM('Medford Data:Boston Data'!B35) -> 0 | C35: =SUM('Medford Data:Boston Data'!C35) -> 0 | D35: =SUM('Medford Data:Boston Data'!D35) -> 0 | E35: =SUM('Medford Data:Boston Data'!E35) -> 0 | F35: =SUM('Medford Data:Boston Data'!F35) -> 0 | G35: =SUM('Medford Data:Boston Data'!G35) -> 0 | H35: =SUM('Medford Data:Boston Data'!H35) -> 0 | I35: =SUM('Medford Data:Boston Data'!I35) -> 0 | J35: =SUM('Medford Data:Boston Data'!J35) -> 0
A38: Quantities of Recycled Materials in Short Tons:
A39: Year | B39: Newspaper | C39: Office | D39: MIxed | E39: Corregated | F39: Aluminum | G39: Steel | H39: HDPE | I39: LDPE | J39: PET | K39: Wooden
C40: Paper | D40: Paper | E40: Cardboard | F40: Cans | K40: Pallets
A41: 1990 | B41: =SUM('Medford Data:Boston Data'!B41) -> 0 | C41: =SUM('Medford Data:Boston Data'!C41) -> 0 | D41: =SUM('Medford Data:Boston Data'!D41) -> 0 | E41: =SUM('Medford Data:Boston Data'!E41) -> 0 | F41: =SUM('Medford Data:Boston Data'!F41) -> 0 | G41: =SUM('Medford Data:Boston Data'!G41) -> 0 | H41: =SUM('Medford Data:Boston Data'!H41) -> 0 | I41: =SUM('Medford Data:Boston Data'!I41) -> 0 | ... K41: =SUM('Medford Data:Boston Data'!K41) -> 0
A42: 1991 | B42: =SUM('Medford Data:Boston Data'!B42) -> 0 | C42: =SUM('Medford Data:Boston Data'!C42) -> 0 | D42: =SUM('Medford Data:Boston Data'!D42) -> 0 | E42: =SUM('Medford Data:Boston Data'!E42) -> 0 | F42: =SUM('Medford Data:Boston Data'!F42) -> 0 | G42: =SUM('Medford Data:Boston Data'!G42) -> 0 | H42: =SUM('Medford Data:Boston Data'!H42) -> 0 | I42: =SUM('Medford Data:Boston Data'!I42) -> 0 | ... K42: =SUM('Medford Data:Boston Data'!K42) -> 0
A43: 1992 | B43: =SUM('Medford Data:Boston Data'!B43) -> 0 | C43: =SUM('Medford Data:Boston Data'!C43) -> 0 | D43: =SUM('Medford Data:Boston Data'!D43) -> 0 | E43: =SUM('Medford Data:Boston Data'!E43) -> 0 | F43: =SUM('Medford Data:Boston Data'!F43) -> 0 | G43: =SUM('Medford Data:Boston Data'!G43) -> 0 | H43: =SUM('Medford Data:Boston Data'!H43) -> 0 | I43: =SUM('Medford Data:Boston Data'!I43) -> 0 | ... K43: =SUM('Medford Data:Boston Data'!K43) -> 0
A44: 1993 | B44: =SUM('Medford Data:Boston Data'!B44) -> 0 | C44: =SUM('Medford Data:Boston Data'!C44) -> 0 | D44: =SUM('Medford Data:Boston Data'!D44) -> 0 | E44: =SUM('Medford Data:Boston Data'!E44) -> 0 | F44: =SUM('Medford Data:Boston Data'!F44) -> 0 | G44: =SUM('Medford Data:Boston Data'!G44) -> 0 | H44: =SUM('Medford Data:Boston Data'!H44) -> 0 | I44: =SUM('Medford Data:Boston Data'!I44) -> 0 | ... K44: =SUM('Medford Data:Boston Data'!K44) -> 0
A45: 1994 | B45: =SUM('Medford Data:Boston Data'!B45) -> 0 | C45: =SUM('Medford Data:Boston Data'!C45) -> 0 | D45: =SUM('Medford Data:Boston Data'!D45) -> 0 | E45: =SUM('Medford Data:Boston Data'!E45) -> 0 | F45: =SUM('Medford Data:Boston Data'!F45) -> 0 | G45: =SUM('Medford Data:Boston Data'!G45) -> 0 | H45: =SUM('Medford Data:Boston Data'!H45) -> 0 | I45: =SUM('Medford Data:Boston Data'!I45) -> 0 | ... K45: =SUM('Medford Data:Boston Data'!K45) -> 0
...

Sheet Medford Data
A1: QUANTITIES OF ENERGY AND MATERIALS USED | G1: =NOW() -> 43857.445
A2: ENTITY: | B2: Medford - Tufts University Main Campus
A4: Enter Quantities of Fuel Used:
A5: Year | H5: Gasoline | I5: Gasoline
B6: Electricity | C6: Gas | D6: #6 Oil | E6: #2 Oil | F6: Propane | G6: Steam | H6: On Campus | I6: Commuters | J6: Diesel
B7: (kWh) | C7: (Ccf)* | D7: (gal.) | E7: (gal.) | F7: (gal.) | G7: (Mlb.) | H7: (gal.) | I7: (gal.) | J7: (gal.)
A8: 1990 | B8: 21807302 | C8: 261000 | D8: 795000 | E8: 343434 | F8: 0 | G8: 0 | H8: 55800 | I8: 351000 | J8: 0
A9: 1991
A10: 1992
A11: 1993
A12: 1994
A13: 1995
A14: 1996
A15: 1997
A16: 1998 | B16: 29584987 | C16: 704470 | D16: 676893 | E16: 337250 | F16: 0 | G16: 0 | H16: 61852 | I16: 349000 | J16: 0
A17: 1999
A18: 2000
A21: Enter Quantities of Solid Waste Materials in Short Tons:
B22: Landfill | C22: Landfill | E22: Composted | F22: Composted
A23: Year | B23: No LFG | C23: Electricity | D23: Incineration | E23: Food | F23: Landscaping
B24: Recovery | C24: Generation | E24: Wastes | F24: Wastes
A25: 1990 | C25: 3400
A26: 1991
A27: 1992
A28: 1993
A29: 1994
A30: 1995
A31: 1996
A32: 1997
A33: 1998 | C33: 4000 | E33: 50
A34: 1999
A35: 2000
A38: Enter Quantities of Recycled Materials in Short Tons:
A39: Year | B39: Newspaper | C39: Office | D39: MIxed | E39: Corregated | F39: Aluminum | G39: Steel | H39: HDPE | I39: LDPE | J39: PET | K39: Wooden
C40: Paper | D40: Paper | E40: Cardboard | F40: Cans | K40: Pallets
A41: 1990
A42: 1991
A43: 1992
A44: 1993
A45: 1994
...

Sheet Grafton Data
A1: QUANTITIES OF ENERGY AND MATERIALS USED | G1: =NOW() -> 43857.445
A2: ENTITY: | B2: Grafton Campus
A4: Enter Quantities of Fuel Used:
A5: Year | H5: Gasoline | I5: Gasoline
B6: Electricity | C6: Gas | D6: #6 Oil | E6: #2 Oil | F6: Propane | G6: Steam | H6: On Campus | I6: Commuters | J6: Diesel
B7: (kWh) | C7: (Ccf)* | D7: (gal.) | E7: (gal.) | F7: (gal.) | G7: (Mlb.) | H7: (gal.) | I7: (gal.) | J7: (gal.)
A8: 1990 | B8: 3097552 | C8: 16582 | D8: 0 | E8: 101436 | F8: 0 | G8: 0 | H8: 0 | I8: 0 | J8: 0
A9: 1991
A10: 1992
A11: 1993
A12: 1994
A13: 1995
A14: 1996
A15: 1997
A16: 1998 | B16: 5751319 | C16: 114013 | D16: 0 | E16: 112990 | F16: 13346 | G16: 0 | H16: 0 | I16: 0 | J16: 0
A17: 1999
A18: 2000
A21: Enter Quantities of Solid Waste Materials in Short Tons:
B22: Landfill | C22: Landfill | E22: Composted | F22: Composted
A23: Year | B23: No LFG | C23: Electricity | D23: Incineration | E23: Food | F23: Landscaping
B24: Recovery | C24: Generation | E24: Wastes | F24: Wastes
A25: 1990 | D25: 70
A26: 1991
A27: 1992
A28: 1993
A29: 1994
A30: 1995
A31: 1996
A32: 1997
A33: 1998 | D33: 500
A34: 1999
A35: 2000
A38: Enter Quantities of Recycled Materials in Short Tons:
A39: Year | B39: Newspaper | C39: Office | D39: MIxed | E39: Corregated | F39: Aluminum | G39: Steel | H39: HDPE | I39: LDPE | J39: PET | K39: Wooden
C40: Paper | D40: Paper | E40: Cardboard | F40: Cans | K40: Pallets
A41: 1990
A42: 1991
A43: 1992
A44: 1993
A45: 1994
...

Sheet Boston Data
A1: QUANTITIES OF ENERGY AND MATERIALS USED | G1: =NOW() -> 43857.445
A2: ENTITY: | B2: Boston Campus
A4: Enter Quantities of Fuel Used:
A5: Year | H5: Gasoline | I5: Gasoline
B6: Electricity | C6: Gas | D6: #6 Oil | E6: #2 Oil | F6: Propane | G6: Steam | H6: On Campus | I6: Commuters | J6: Diesel
B7: (kWh) | C7: (Ccf)* | D7: (gal.) | E7: (gal.) | F7: (gal.) | G7: (Mlb.) | H7: (gal.) | I7: (gal.) | J7: (gal.)
A8: 1990 | B8: 13197809 | C8: 50274 | D8: 0 | E8: 0 | F8: 0 | G8: 39904 | H8: 0 | I8: 0 | J8: 0
A9: 1991
A10: 1992
A11: 1993
A12: 1994
A13: 1995
A14: 1996
A15: 1997
A16: 1998 | B16: 14320332 | C16: 50935 | D16: 0 | E16: 0 | F16: 0 | G16: 40653 | H16: 0 | I16: 0 | J16: 0
A17: 1999
A18: 2000
A21: Enter Quantities of Solid Waste Materials in Short Tons:
B22: Landfill | C22: Landfill | E22: Composted | F22: Composted
A23: Year | B23: No LFG | C23: Electricity | D23: Incineration | E23: Food | F23: Landscaping
B24: Recovery | C24: Generation | E24: Wastes | F24: Wastes
A25: 1990
A26: 1991
A27: 1992
A28: 1993
A29: 1994
A30: 1995
A31: 1996
A32: 1997
A33: 1998
A34: 1999
A35: 2000
A38: Enter Quantities of Recycled Materials in Short Tons:
A39: Year | B39: Newspaper | C39: Office | D39: MIxed | E39: Corregated | F39: Aluminum | G39: Steel | H39: HDPE | I39: LDPE | J39: PET | K39: Wooden
C40: Paper | D40: Paper | E40: Cardboard | F40: Cans | K40: Pallets
A41: 1990
A42: 1991
A43: 1992
A44: 1993
A45: 1994
...

Sheet Energy Use Emissions
A1: QUANTITIES OF CO2 EMISSIONS BY ENERGY USED | G1: =NOW() -> 43857.445
A2: ENTITY: | B2: Tufts University Summary Data
A4: Categories of Emissions Released by Fuel Used(short tons of CO2):
H5: Gasoline | I5: Gasoline
A6: Year | B6: Electricity | C6: Gas | D6: #6 Oil | E6: #2 Oil | F6: Propane | G6: Steam | H6: On Campus | I6: Commuters | J6: Diesel | K6: Totals
A8: 1990 | B8: =('Tufts Summary Data'!B8*'Conversion Factors'!B8)/2000 -> 30482.13 | C8: =('Tufts Summary Data'!C8*'Conversion Factors'!C8)/2000 -> 1976.9717 | D8: =('Tufts Summary Data'!D8*'Conversion Factors'!D8)/2000 -> 10348.118 | E8: =('Tufts Summary Data'!E8*'Conversion Factors'!E8)/2000 -> 4978.985 | F8: =('Tufts Summary Data'!F8*'Conversion Factors'!F8)/2000 -> 0 | G8: =('Tufts Summary Data'!G8*'Conversion Factors'!G8)/2000 -> 11911.344 | H8: =('Tufts Summary Data'!H8*'Conversion Factors'!H8)/2000 -> 546.6726 | I8: =('Tufts Summary Data'!I8*'Conversion Factors'!I8)/2000 -> 3438.747 | J8: =('Tufts Summary Data'!J8*'Conversion Factors'!J8)/2000 -> 0 | K8: =SUM(B8:J8) -> 63682.968
A9: 1991 | B9: =('Tufts Summary Data'!B9*'Conversion Factors'!B9)/2000 -> 0 | C9: =('Tufts Summary Data'!C9*'Conversion Factors'!C9)/2000 -> 0 | D9: =('Tufts Summary Data'!D9*'Conversion Factors'!D9)/2000 -> 0 | E9: =('Tufts Summary Data'!E9*'Conversion Factors'!E9)/2000 -> 0 | F9: =('Tufts Summary Data'!F9*'Conversion Factors'!F9)/2000 -> 0 | G9: =('Tufts Summary Data'!G9*'Conversion Factors'!G9)/2000 -> 0 | H9: =('Tufts Summary Data'!H9*'Conversion Factors'!H9)/2000 -> 0 | I9: =('Tufts Summary Data'!I9*'Conversion Factors'!I9)/2000 -> 0 | J9: =('Tufts Summary Data'!J9*'Conversion Factors'!J9)/2000 -> 0 | K9: =SUM(B9:J9) -> 0
A10: 1992 | B10: =('Tufts Summary Data'!B10*'Conversion Factors'!B10)/2000 -> 0 | C10: =('Tufts Summary Data'!C10*'Conversion Factors'!C10)/2000 -> 0 | D10: =('Tufts Summary Data'!D10*'Conversion Factors'!D10)/2000 -> 0 | E10: =('Tufts Summary Data'!E10*'Conversion Factors'!E10)/2000 -> 0 | F10: =('Tufts Summary Data'!F10*'Conversion Factors'!F10)/2000 -> 0 | G10: =('Tufts Summary Data'!G10*'Conversion Factors'!G10)/2000 -> 0 | H10: =('Tufts Summary Data'!H10*'Conversion Factors'!H10)/2000 -> 0 | I10: =('Tufts Summary Data'!I10*'Conversion Factors'!I10)/2000 -> 0 | J10: =('Tufts Summary Data'!J10*'Conversion Factors'!J10)/2000 -> 0 | K10: =SUM(B10:J10) -> 0
A11: 1993 | B11: =('Tufts Summary Data'!B11*'Conversion Factors'!B11)/2000 -> 0 | C11: =('Tufts Summary Data'!C11*'Conversion Factors'!C11)/2000 -> 0 | D11: =('Tufts Summary Data'!D11*'Conversion Factors'!D11)/2000 -> 0 | E11: =('Tufts Summary Data'!E11*'Conversion Factors'!E11)/2000 -> 0 | F11: =('Tufts Summary Data'!F11*'Conversion Factors'!F11)/2000 -> 0 | G11: =('Tufts Summary Data'!G11*'Conversion Factors'!G11)/2000 -> 0 | H11: =('Tufts Summary Data'!H11*'Conversion Factors'!H11)/2000 -> 0 | I11: =('Tufts Summary Data'!I11*'Conversion Factors'!I11)/2000 -> 0 | J11: =('Tufts Summary Data'!J11*'Conversion Factors'!J11)/2000 -> 0 | K11: =SUM(B11:J11) -> 0
A12: 1994 | B12: =('Tufts Summary Data'!B12*'Conversion Factors'!B12)/2000 -> 0 | C12: =('Tufts Summary Data'!C12*'Conversion Factors'!C12)/2000 -> 0 | D12: =('Tufts Summary Data'!D12*'Conversion Factors'!D12)/2000 -> 0 | E12: =('Tufts Summary Data'!E12*'Conversion Factors'!E12)/2000 -> 0 | F12: =('Tufts Summary Data'!F12*'Conversion Factors'!F12)/2000 -> 0 | G12: =('Tufts Summary Data'!G12*'Conversion Factors'!G12)/2000 -> 0 | H12: =('Tufts Summary Data'!H12*'Conversion Factors'!H12)/2000 -> 0 | I12: =('Tufts Summary Data'!I12*'Conversion Factors'!I12)/2000 -> 0 | J12: =('Tufts Summary Data'!J12*'Conversion Factors'!J12)/2000 -> 0 | K12: =SUM(B12:J12) -> 0
A13: 1995 | B13: =('Tufts Summary Data'!B13*'Conversion Factors'!B13)/2000 -> 0 | C13: =('Tufts Summary Data'!C13*'Conversion Factors'!C13)/2000 -> 0 | D13: =('Tufts Summary Data'!D13*'Conversion Factors'!D13)/2000 -> 0 | E13: =('Tufts Summary Data'!E13*'Conversion Factors'!E13)/2000 -> 0 | F13: =('Tufts Summary Data'!F13*'Conversion Factors'!F13)/2000 -> 0 | G13: =('Tufts Summary Data'!G13*'Conversion Factors'!G13)/2000 -> 0 | H13: =('Tufts Summary Data'!H13*'Conversion Factors'!H13)/2000 -> 0 | I13: =('Tufts Summary Data'!I13*'Conversion Factors'!I13)/2000 -> 0 | J13: =('Tufts Summary Data'!J13*'Conversion Factors'!J13)/2000 -> 0 | K13: =SUM(B13:J13) -> 0
A14: 1996 | B14: =('Tufts Summary Data'!B14*'Conversion Factors'!B14)/2000 -> 0 | C14: =('Tufts Summary Data'!C14*'Conversion Factors'!C14)/2000 -> 0 | D14: =('Tufts Summary Data'!D14*'Conversion Factors'!D14)/2000 -> 0 | E14: =('Tufts Summary Data'!E14*'Conversion Factors'!E14)/2000 -> 0 | F14: =('Tufts Summary Data'!F14*'Conversion Factors'!F14)/2000 -> 0 | G14: =('Tufts Summary Data'!G14*'Conversion Factors'!G14)/2000 -> 0 | H14: =('Tufts Summary Data'!H14*'Conversion Factors'!H14)/2000 -> 0 | I14: =('Tufts Summary Data'!I14*'Conversion Factors'!I14)/2000 -> 0 | J14: =('Tufts Summary Data'!J14*'Conversion Factors'!J14)/2000 -> 0 | K14: =SUM(B14:J14) -> 0
A15: 1997 | B15: =('Tufts Summary Data'!B15*'Conversion Factors'!B15)/2000 -> 0 | C15: =('Tufts Summary Data'!C15*'Conversion Factors'!C15)/2000 -> 0 | D15: =('Tufts Summary Data'!D15*'Conversion Factors'!D15)/2000 -> 0 | E15: =('Tufts Summary Data'!E15*'Conversion Factors'!E15)/2000 -> 0 | F15: =('Tufts Summary Data'!F15*'Conversion Factors'!F15)/2000 -> 0 | G15: =('Tufts Summary Data'!G15*'Conversion Factors'!G15)/2000 -> 0 | H15: =('Tufts Summary Data'!H15*'Conversion Factors'!H15)/2000 -> 0 | I15: =('Tufts Summary Data'!I15*'Conversion Factors'!I15)/2000 -> 0 | J15: =('Tufts Summary Data'!J15*'Conversion Factors'!J15)/2000 -> 0 | K15: =SUM(B15:J15) -> 0
A16: 1998 | B16: =('Tufts Summary Data'!B16*'Conversion Factors'!B16)/2000 -> 36224.517 | C16: =('Tufts Summary Data'!C16*'Conversion Factors'!C16)/2000 -> 5242.5905 | D16: =('Tufts Summary Data'!D16*'Conversion Factors'!D16)/2000 -> 8810.7777 | E16: =('Tufts Summary Data'!E16*'Conversion Factors'!E16)/2000 -> 5039.0861 | F16: =('Tufts Summary Data'!F16*'Conversion Factors'!F16)/2000 -> 84.54691 | G16: =('Tufts Summary Data'!G16*'Conversion Factors'!G16)/2000 -> 12134.921 | H16: =('Tufts Summary Data'!H16*'Conversion Factors'!H16)/2000 -> 605.96404 | I16: =('Tufts Summary Data'!I16*'Conversion Factors'!I16)/2000 -> 3419.153 | J16: =('Tufts Summary Data'!J16*'Conversion Factors'!J16)/2000 -> 0 | K16: =SUM(B16:J16) -> 71561.556
A17: 1999 | B17: =('Tufts Summary Data'!B17*'Conversion Factors'!B17)/2000 -> 0 | C17: =('Tufts Summary Data'!C17*'Conversion Factors'!C17)/2000 -> 0 | D17: =('Tufts Summary Data'!D17*'Conversion Factors'!D17)/2000 -> 0 | E17: =('Tufts Summary Data'!E17*'Conversion Factors'!E17)/2000 -> 0 | F17: =('Tufts Summary Data'!F17*'Conversion Factors'!F17)/2000 -> 0 | G17: =('Tufts Summary Data'!G17*'Conversion Factors'!G17)/2000 -> 0 | H17: =('Tufts Summary Data'!H17*'Conversion Factors'!H17)/2000 -> 0 | I17: =('Tufts Summary Data'!I17*'Conversion Factors'!I17)/2000 -> 0 | J17: =('Tufts Summary Data'!J17*'Conversion Factors'!J17)/2000 -> 0 | K17: =SUM(B17:J17) -> 0
A18: 2000 | B18: =('Tufts Summary Data'!B18*'Conversion Factors'!B18)/2000 -> 0 | C18: =('Tufts Summary Data'!C18*'Conversion Factors'!C18)/2000 -> 0 | D18: =('Tufts Summary Data'!D18*'Conversion Factors'!D18)/2000 -> 0 | E18: =('Tufts Summary Data'!E18*'Conversion Factors'!E18)/2000 -> 0 | F18: =('Tufts Summary Data'!F18*'Conversion Factors'!F18)/2000 -> 0 | G18: =('Tufts Summary Data'!G18*'Conversion Factors'!G18)/2000 -> 0 | H18: =('Tufts Summary Data'!H18*'Conversion Factors'!H18)/2000 -> 0 | I18: =('Tufts Summary Data'!I18*'Conversion Factors'!I18)/2000 -> 0 | J18: =('Tufts Summary Data'!J18*'Conversion Factors'!J18)/2000 -> 0 | K18: =SUM(B18:J18) -> 0

Sheet Agriculture Emissions
A1: QUANTITIES OF GHG EMISSIONS BY AGRICULTURAL SOURCES | J1: =NOW() -> 43857.445
A2: ENTITY: | B2: Tufts University Summary Data
A4: Categories of Enteric Fermentation (short tons of CH4):
B5: Dairy | C5: Beef
A6: Year | B6: Cattle | C6: Cattle | D6: Sheep | E6: Goats | F6: Horses | G6: Swine | H6: Total
A8: 1990 | B8: =('Tufts Summary Data'!B57*'Conversion Factors'!E26) -> 0 | C8: =('Tufts Summary Data'!C57*'Conversion Factors'!F26) -> 3.3895503 | D8: =('Tufts Summary Data'!D57*'Conversion Factors'!G26) -> 0.88183422 | E8: =('Tufts Summary Data'!E57*'Conversion Factors'!H26) -> 0 | F8: =('Tufts Summary Data'!F57*'Conversion Factors'!I26) -> 0 | G8: =('Tufts Summary Data'!G57*'Conversion Factors'!J26) -> 1.3227513 | H8: =SUM(B8:G8) -> 5.5941358
A9: 1991 | B9: =('Tufts Summary Data'!B58*'Conversion Factors'!E27) -> 0 | C9: =('Tufts Summary Data'!C58*'Conversion Factors'!F27) -> 0 | D9: =('Tufts Summary Data'!D58*'Conversion Factors'!G27) -> 0 | E9: =('Tufts Summary Data'!E58*'Conversion Factors'!H27) -> 0 | F9: =('Tufts Summary Data'!F58*'Conversion Factors'!I27) -> 0 | G9: =('Tufts Summary Data'!G58*'Conversion Factors'!J27) -> 0 | H9: =SUM(B9:G9) -> 0
A10: 1992 | B10: =('Tufts Summary Data'!B59*'Conversion Factors'!E28) -> 0 | C10: =('Tufts Summary Data'!C59*'Conversion Factors'!F28) -> 0 | D10: =('Tufts Summary Data'!D59*'Conversion Factors'!G28) -> 0 | E10: =('Tufts Summary Data'!E59*'Conversion Factors'!H28) -> 0 | F10: =('Tufts Summary Data'!F59*'Conversion Factors'!I28) -> 0 | G10: =('Tufts Summary Data'!G59*'Conversion Factors'!J28) -> 0 | H10: =SUM(B10:G10) -> 0
A11: 1993 | B11: =('Tufts Summary Data'!B60*'Conversion Factors'!E29) -> 0 | C11: =('Tufts Summary Data'!C60*'Conversion Factors'!F29) -> 0 | D11: =('Tufts Summary Data'!D60*'Conversion Factors'!G29) -> 0 | E11: =('Tufts Summary Data'!E60*'Conversion Factors'!H29) -> 0 | F11: =('Tufts Summary Data'!F60*'Conversion Factors'!I29) -> 0 | G11: =('Tufts Summary Data'!G60*'Conversion Factors'!J29) -> 0 | H11: =SUM(B11:G11) -> 0
A12: 1994 | B12: =('Tufts Summary Data'!B61*'Conversion Factors'!E30) -> 0 | C12: =('Tufts Summary Data'!C61*'Conversion Factors'!F30) -> 0 | D12: =('Tufts Summary Data'!D61*'Conversion Factors'!G30) -> 0 | E12: =('Tufts Summary Data'!E61*'Conversion Factors'!H30) -> 0 | F12: =('Tufts Summary Data'!F61*'Conversion Factors'!I30) -> 0 | G12: =('Tufts Summary Data'!G61*'Conversion Factors'!J30) -> 0 | H12: =SUM(B12:G12) -> 0
A13: 1995 | B13: =('Tufts Summary Data'!B62*'Conversion Factors'!E31) -> 0 | C13: =('Tufts Summary Data'!C62*'Conversion Factors'!F31) -> 0 | D13: =('Tufts Summary Data'!D62*'Conversion Factors'!G31) -> 0 | E13: =('Tufts Summary Data'!E62*'Conversion Factors'!H31) -> 0 | F13: =('Tufts Summary Data'!F62*'Conversion Factors'!I31) -> 0 | G13: =('Tufts Summary Data'!G62*'Conversion Factors'!J31) -> 0 | H13: =SUM(B13:G13) -> 0
A14: 1996 | B14: =('Tufts Summary Data'!B63*'Conversion Factors'!E32) -> 0 | C14: =('Tufts Summary Data'!C63*'Conversion Factors'!F32) -> 0 | D14: =('Tufts Summary Data'!D63*'Conversion Factors'!G32) -> 0 | E14: =('Tufts Summary Data'!E63*'Conversion Factors'!H32) -> 0 | F14: =('Tufts Summary Data'!F63*'Conversion Factors'!I32) -> 0 | G14: =('Tufts Summary Data'!G63*'Conversion Factors'!J32) -> 0 | H14: =SUM(B14:G14) -> 0
A15: 1997 | B15: =('Tufts Summary Data'!B64*'Conversion Factors'!E33) -> 0 | C15: =('Tufts Summary Data'!C64*'Conversion Factors'!F33) -> 0 | D15: =('Tufts Summary Data'!D64*'Conversion Factors'!G33) -> 0 | E15: =('Tufts Summary Data'!E64*'Conversion Factors'!H33) -> 0 | F15: =('Tufts Summary Data'!F64*'Conversion Factors'!I33) -> 0 | G15: =('Tufts Summary Data'!G64*'Conversion Factors'!J33) -> 0 | H15: =SUM(B15:G15) -> 0
A16: 1998 | B16: =('Tufts Summary Data'!B65*'Conversion Factors'!E34) -> 6.9334215 | C16: =('Tufts Summary Data'!C65*'Conversion Factors'!F34) -> 0 | D16: =('Tufts Summary Data'!D65*'Conversion Factors'!G34) -> 0.57319224 | E16: =('Tufts Summary Data'!E65*'Conversion Factors'!H34) -> 0.82671958 | F16: =('Tufts Summary Data'!F65*'Conversion Factors'!I34) -> 0.15873016 | G16: =('Tufts Summary Data'!G65*'Conversion Factors'!J34) -> 0.49603175 | H16: =SUM(B16:G16) -> 8.9880952
A17: 1999 | B17: =('Tufts Summary Data'!B66*'Conversion Factors'!E35) -> 0 | C17: =('Tufts Summary Data'!C66*'Conversion Factors'!F35) -> 0 | D17: =('Tufts Summary Data'!D66*'Conversion Factors'!G35) -> 0 | E17: =('Tufts Summary Data'!E66*'Conversion Factors'!H35) -> 0 | F17: =('Tufts Summary Data'!F66*'Conversion Factors'!I35) -> 0 | G17: =('Tufts Summary Data'!G66*'Conversion Factors'!J35) -> 0 | H17: =SUM(B17:G17) -> 0
A18: 2000 | B18: =('Tufts Summary Data'!B67*'Conversion Factors'!E36) -> 0 | C18: =('Tufts Summary Data'!C67*'Conversion Factors'!F36) -> 0 | D18: =('Tufts Summary Data'!D67*'Conversion Factors'!G36) -> 0 | E18: =('Tufts Summary Data'!E67*'Conversion Factors'!H36) -> 0 | F18: =('Tufts Summary Data'!F67*'Conversion Factors'!I36) -> 0 | G18: =('Tufts Summary Data'!G67*'Conversion Factors'!J36) -> 0 | H18: =SUM(B18:G18) -> 0
A21: Categories of Manure Management (short tons of CH4):
B22: Dairy | C22: Beef
A23: Year | B23: Cattle | C23: Cattle | D23: Sheep | E23: Goats | F23: Horses | G23: Swine | H23: Total
A25: 1990 | B25: =('Tufts Summary Data'!B57*'Conversion Factors'!E43) -> 0 | C25: =('Tufts Summary Data'!C57*'Conversion Factors'!F43) -> 4.9052028 | D25: =('Tufts Summary Data'!D57*'Conversion Factors'!G43) -> 0.18628748 | E25: =('Tufts Summary Data'!E57*'Conversion Factors'!H43) -> 0 | F25: =('Tufts Summary Data'!F57*'Conversion Factors'!I43) -> 0 | G25: =('Tufts Summary Data'!G57*'Conversion Factors'!J43) -> 1.4902998 | H25: =SUM(B25:G25) -> 6.5817901
A26: 1991 | B26: =('Tufts Summary Data'!B58*'Conversion Factors'!E44) -> 0 | C26: =('Tufts Summary Data'!C58*'Conversion Factors'!F44) -> 0 | D26: =('Tufts Summary Data'!D58*'Conversion Factors'!G44) -> 0 | E26: =('Tufts Summary Data'!E58*'Conversion Factors'!H44) -> 0 | F26: =('Tufts Summary Data'!F58*'Conversion Factors'!I44) -> 0 | G26: =('Tufts Summary Data'!G58*'Conversion Factors'!J44) -> 0 | H26: =SUM(B26:G26) -> 0
A27: 1992 | B27: =('Tufts Summary Data'!B59*'Conversion Factors'!E45) -> 0 | C27: =('Tufts Summary Data'!C59*'Conversion Factors'!F45) -> 0 | D27: =('Tufts Summary Data'!D59*'Conversion Factors'!G45) -> 0 | E27: =('Tufts Summary Data'!E59*'Conversion Factors'!H45) -> 0 | F27: =('Tufts Summary Data'!F59*'Conversion Factors'!I45) -> 0 | G27: =('Tufts Summary Data'!G59*'Conversion Factors'!J45) -> 0 | H27: =SUM(B27:G27) -> 0
A28: 1993 | B28: =('Tufts Summary Data'!B60*'Conversion Factors'!E46) -> 0 | C28: =('Tufts Summary Data'!C60*'Conversion Factors'!F46) -> 0 | D28: =('Tufts Summary Data'!D60*'Conversion Factors'!G46) -> 0 | E28: =('Tufts Summary Data'!E60*'Conversion Factors'!H46) -> 0 | F28: =('Tufts Summary Data'!F60*'Conversion Factors'!I46) -> 0 | G28: =('Tufts Summary Data'!G60*'Conversion Factors'!J46) -> 0 | H28: =SUM(B28:G28) -> 0
A29: 1994 | B29: =('Tufts Summary Data'!B61*'Conversion Factors'!E47) -> 0 | C29: =('Tufts Summary Data'!C61*'Conversion Factors'!F47) -> 0 | D29: =('Tufts Summary Data'!D61*'Conversion Factors'!G47) -> 0 | E29: =('Tufts Summary Data'!E61*'Conversion Factors'!H47) -> 0 | F29: =('Tufts Summary Data'!F61*'Conversion Factors'!I47) -> 0 | G29: =('Tufts Summary Data'!G61*'Conversion Factors'!J47) -> 0 | H29: =SUM(B29:G29) -> 0
A30: 1995 | B30: =('Tufts Summary Data'!B62*'Conversion Factors'!E48) -> 0 | C30: =('Tufts Summary Data'!C62*'Conversion Factors'!F48) -> 0 | D30: =('Tufts Summary Data'!D62*'Conversion Factors'!G48) -> 0 | E30: =('Tufts Summary Data'!E62*'Conversion Factors'!H48) -> 0 | F30: =('Tufts Summary Data'!F62*'Conversion Factors'!I48) -> 0 | G30: =('Tufts Summary Data'!G62*'Conversion Factors'!J48) -> 0 | H30: =SUM(B30:G30) -> 0
A31: 1996 | B31: =('Tufts Summary Data'!B63*'Conversion Factors'!E49) -> 0 | C31: =('Tufts Summary Data'!C63*'Conversion Factors'!F49) -> 0 | D31: =('Tufts Summary Data'!D63*'Conversion Factors'!G49) -> 0 | E31: =('Tufts Summary Data'!E63*'Conversion Factors'!H49) -> 0 | F31: =('Tufts Summary Data'!F63*'Conversion Factors'!I49) -> 0 | G31: =('Tufts Summary Data'!G63*'Conversion Factors'!J49) -> 0 | H31: =SUM(B31:G31) -> 0
A32: 1997 | B32: =('Tufts Summary Data'!B64*'Conversion Factors'!E50) -> 0 | C32: =('Tufts Summary Data'!C64*'Conversion Factors'!F50) -> 0 | D32: =('Tufts Summary Data'!D64*'Conversion Factors'!G50) -> 0 | E32: =('Tufts Summary Data'!E64*'Conversion Factors'!H50) -> 0 | F32: =('Tufts Summary Data'!F64*'Conversion Factors'!I50) -> 0 | G32: =('Tufts Summary Data'!G64*'Conversion Factors'!J50) -> 0 | H32: =SUM(B32:G32) -> 0
A33: 1998 | B33: =('Tufts Summary Data'!B65*'Conversion Factors'!E51) -> 4.9052028 | C33: =('Tufts Summary Data'!C65*'Conversion Factors'!F51) -> 0 | D33: =('Tufts Summary Data'!D65*'Conversion Factors'!G51) -> 0.12108686 | E33: =('Tufts Summary Data'!E65*'Conversion Factors'!H51) -> 0.27943122 | F33: =('Tufts Summary Data'!F65*'Conversion Factors'!I51) -> 0.014902998 | G33: =('Tufts Summary Data'!G65*'Conversion Factors'!J51) -> 0.55886243 | H33: =SUM(B33:G33) -> 5.8794863
A34: 1999 | B34: =('Tufts Summary Data'!B66*'Conversion Factors'!E52) -> 0 | C34: =('Tufts Summary Data'!C66*'Conversion Factors'!F52) -> 0 | D34: =('Tufts Summary Data'!D66*'Conversion Factors'!G52) -> 0 | E34: =('Tufts Summary Data'!E66*'Conversion Factors'!H52) -> 0 | F34: =('Tufts Summary Data'!F66*'Conversion Factors'!I52) -> 0 | G34: =('Tufts Summary Data'!G66*'Conversion Factors'!J52) -> 0 | H34: =SUM(B34:G34) -> 0
A35: 2000 | B35: =('Tufts Summary Data'!B67*'Conversion Factors'!E53) -> 0 | C35: =('Tufts Summary Data'!C67*'Conversion Factors'!F53) -> 0 | D35: =('Tufts Summary Data'!D67*'Conversion Factors'!G53) -> 0 | E35: =('Tufts Summary Data'!E67*'Conversion Factors'!H53) -> 0 | F35: =('Tufts Summary Data'!F67*'Conversion Factors'!I53) -> 0 | G35: =('Tufts Summary Data'!G67*'Conversion Factors'!J53) -> 0 | H35: =SUM(B35:G35) -> 0

Sheet Conversion Factors
A1: CONVERSION FACTORS | G1: =NOW() -> 43857.445
A2: ENTITY: | B2: =IF('Tufts Summary Data'!B2="Enter Entity Name Here","*****",'Tufts Summary Data'!B2) -> Tufts University GHG Emissions
A4: Pounds of CO2 per unit
H5: Gasoline | I5: Gasoline
A6: Year | B6: Electricity | C6: Natural Gas | D6: #6 Oil | E6: #2 Oil | F6: Propane | G6: Steam | H6: On Campus | I6: Commuters | J6: Diesel
B7: (kWh) | C7: (Ccf)* | D7: (gal.) | E7: (gal.) | F7: (gal.) | G7: (Mlbs.) | H7: (gal.) | I7: (gal.) | J7: (gal.)
A8: 1990 | B8: 1.6 | C8: 12.06 | D8: 26.033 | E8: 22.384 | F8: 12.67 | G8: 597 | H8: 19.594 | I8: 19.594 | J8: 22.384
A9: 1991 | B9: 1.6 | C9: 12.06 | D9: 26.033 | E9: 22.384 | F9: 12.67 | G9: 597 | H9: 19.594 | I9: 19.594 | J9: 22.384
A10: 1992 | B10: 1.6 | C10: 12.06 | D10: 26.033 | E10: 22.384 | F10: 12.67 | G10: 597 | H10: 19.594 | I10: 19.594 | J10: 22.384
A11: 1993 | B11: 1.6 | C11: 12.06 | D11: 26.033 | E11: 22.384 | F11: 12.67 | G11: 597 | H11: 19.594 | I11: 19.594 | J11: 22.384
A12: 1994 | B12: 1.6 | C12: 12.06 | D12: 26.033 | E12: 22.384 | F12: 12.67 | G12: 597 | H12: 19.594 | I12: 19.594 | J12: 22.384
A13: 1995 | B13: 1.6 | C13: 12.06 | D13: 26.033 | E13: 22.384 | F13: 12.67 | G13: 597 | H13: 19.594 | I13: 19.594 | J13: 22.384
A14: 1996 | B14: 1.6 | C14: 12.06 | D14: 26.033 | E14: 22.384 | F14: 12.67 | G14: 597 | H14: 19.594 | I14: 19.594 | J14: 22.384
A15: 1997 | B15: 1.6 | C15: 12.06 | D15: 26.033 | E15: 22.384 | F15: 12.67 | G15: 597 | H15: 19.594 | I15: 19.594 | J15: 22.384
A16: 1998 | B16: 1.459 | C16: 12.06 | D16: 26.033 | E16: 22.384 | F16: 12.67 | G16: 597 | H16: 19.594 | I16: 19.594 | J16: 22.384
A17: 1999 | B17: 1.459 | C17: 12.06 | D17: 26.033 | E17: 22.384 | F17: 12.67 | G17: 597 | H17: 19.594 | I17: 19.594 | J17: 22.384
A18: 2000 | B18: 1.459 | C18: 12.06 | D18: 26.033 | E18: 22.384 | F18: 12.67 | G18: 597 | H18: 19.594 | I18: 19.594 | J18: 22.384
A22: Global Warming Potential | D22: Emission Releases/head of via Enteric Fermentation (short tons of CH4 / head)
A23: Chemical | E23: Dairy | F23: Beef
A24: Compound | B24: GWP | D24: Year | E24: Cattle | F24: Cattle | G24: Sheep | H24: Goats | I24: Horses | J24: Swine
A26: Carbon Dioxide | B26: 1 | D26: 1990 | E26: =0.1258/0.9072 -> 0.13866843 | F26: =0.0615/0.9072 -> 0.067791005 | G26: =0.008/0.9072 -> 0.0088183422 | H26: =0.005/0.9072 -> 0.0055114638 | I26: =0.018/0.9072 -> 0.01984127 | J26: =0.0015/0.9072 -> 0.0016534392
A27: Methane | B27: 21 | D27: 1991 | E27: =0.1258/0.9072 -> 0.13866843 | F27: =0.0615/0.9072 -> 0.067791005 | G27: =0.008/0.9072 -> 0.0088183422 | H27: =0.005/0.9072 -> 0.0055114638 | I27: =0.018/0.9072 -> 0.01984127 | J27: =0.0015/0.9072 -> 0.0016534392
A28: Nitrous Oxide | B28: 310 | D28: 1992 | E28: =0.1258/0.9072 -> 0.13866843 | F28: =0.0615/0.9072 -> 0.067791005 | G28: =0.008/0.9072 -> 0.0088183422 | H28: =0.005/0.9072 -> 0.0055114638 | I28: =0.018/0.9072 -> 0.01984127 | J28: =0.0015/0.9072 -> 0.0016534392
A29: HFC-134a | B29: 1300 | D29: 1993 | E29: =0.1258/0.9072 -> 0.13866843 | F29: =0.0615/0.9072 -> 0.067791005 | G29: =0.008/0.9072 -> 0.0088183422 | H29: =0.005/0.9072 -> 0.0055114638 | I29: =0.018/0.9072 -> 0.01984127 | J29: =0.0015/0.9072 -> 0.0016534392
A30: HFC-23 | B30: 12100 | D30: 1994 | E30: =0.1258/0.9072 -> 0.13866843 | F30: =0.0615/0.9072 -> 0.067791005 | G30: =0.008/0.9072 -> 0.0088183422 | H30: =0.005/0.9072 -> 0.0055114638 | I30: =0.018/0.9072 -> 0.01984127 | J30: =0.0015/0.9072 -> 0.0016534392
A31: HFC-152a | B31: 140 | D31: 1995 | E31: =0.1258/0.9072 -> 0.13866843 | F31: =0.0615/0.9072 -> 0.067791005 | G31: =0.008/0.9072 -> 0.0088183422 | H31: =0.005/0.9072 -> 0.0055114638 | I31: =0.018/0.9072 -> 0.01984127 | J31: =0.0015/0.9072 -> 0.0016534392
A32: HCF-227ea | B32: 2900 | D32: 1996 | E32: =0.1258/0.9072 -> 0.13866843 | F32: =0.0615/0.9072 -> 0.067791005 | G32: =0.008/0.9072 -> 0.0088183422 | H32: =0.005/0.9072 -> 0.0055114638 | I32: =0.018/0.9072 -> 0.01984127 | J32: =0.0015/0.9072 -> 0.0016534392
A33: PFCs | B33: 7850 | D33: 1997 | E33: =0.1258/0.9072 -> 0.13866843 | F33: =0.0615/0.9072 -> 0.067791005 | G33: =0.008/0.9072 -> 0.0088183422 | H33: =0.005/0.9072 -> 0.0055114638 | I33: =0.018/0.9072 -> 0.01984127 | J33: =0.0015/0.9072 -> 0.0016534392
A34: SF6 | B34: 23900 | D34: 1998 | E34: =0.1258/0.9072 -> 0.13866843 | F34: =0.0615/0.9072 -> 0.067791005 | G34: =0.008/0.9072 -> 0.0088183422 | H34: =0.005/0.9072 -> 0.0055114638 | I34: =0.018/0.9072 -> 0.01984127 | J34: =0.0015/0.9072 -> 0.0016534392
D35: 1999 | E35: =0.1258/0.9072 -> 0.13866843 | F35: =0.0615/0.9072 -> 0.067791005 | G35: =0.008/0.9072 -> 0.0088183422 | H35: =0.005/0.9072 -> 0.0055114638 | I35: =0.018/0.9072 -> 0.01984127 | J35: =0.0015/0.9072 -> 0.0016534392
D36: 2000 | E36: =0.1258/0.9072 -> 0.13866843 | F36: =0.0615/0.9072 -> 0.067791005 | G36: =0.008/0.9072 -> 0.0088183422 | H36: =0.005/0.9072 -> 0.0055114638 | I36: =0.018/0.9072 -> 0.01984127 | J36: =0.0015/0.9072 -> 0.0016534392
D39: Emission Releases/head of via Manure Management (short tons of CH4 / head)
E40: Dairy | F40: Beef
D41: Year | E41: Cattle | F41: Cattle | G41: Sheep | H41: Goats | I41: Horses | J41: Swine
D43: 1990 | E43: =0.089/0.9072 -> 0.098104056 | F43: =0.089/0.9072 -> 0.098104056 | G43: =0.00169/0.9072 -> 0.0018628748 | H43: =0.00169/0.9072 -> 0.0018628748 | I43: =0.00169/0.9072 -> 0.0018628748 | J43: =0.00169/0.9072 -> 0.0018628748
D44: 1991 | E44: =0.089/0.9072 -> 0.098104056 | F44: =0.089/0.9072 -> 0.098104056 | G44: =0.00169/0.9072 -> 0.0018628748 | H44: =0.00169/0.9072 -> 0.0018628748 | I44: =0.00169/0.9072 -> 0.0018628748 | J44: =0.00169/0.9072 -> 0.0018628748
D45: 1992 | E45: =0.089/0.9072 -> 0.098104056 | F45: =0.089/0.9072 -> 0.098104056 | G45: =0.00169/0.9072 -> 0.0018628748 | H45: =0.00169/0.9072 -> 0.0018628748 | I45: =0.00169/0.9072 -> 0.0018628748 | J45: =0.00169/0.9072 -> 0.0018628748
D46: 1993 | E46: =0.089/0.9072 -> 0.098104056 | F46: =0.089/0.9072 -> 0.098104056 | G46: =0.00169/0.9072 -> 0.0018628748 | H46: =0.00169/0.9072 -> 0.0018628748 | I46: =0.00169/0.9072 -> 0.0018628748 | J46: =0.00169/0.9072 -> 0.0018628748
D47: 1994 | E47: =0.089/0.9072 -> 0.098104056 | F47: =0.089/0.9072 -> 0.098104056 | G47: =0.00169/0.9072 -> 0.0018628748 | H47: =0.00169/0.9072 -> 0.0018628748 | I47: =0.00169/0.9072 -> 0.0018628748 | J47: =0.00169/0.9072 -> 0.0018628748
D48: 1995 | E48: =0.089/0.9072 -> 0.098104056 | F48: =0.089/0.9072 -> 0.098104056 | G48: =0.00169/0.9072 -> 0.0018628748 | H48: =0.00169/0.9072 -> 0.0018628748 | I48: =0.00169/0.9072 -> 0.0018628748 | J48: =0.00169/0.9072 -> 0.0018628748
...
