Workbook

Sheet Non-Functional Summary
A1: Non-Functional Requirements Analysis - Weighted Results | I1: Non-Functional Requirements Analysis - Weighted Score - Summary | P1: Non-Functional Requirements Analysis - Weighted % - Summary
A2: Criteria | B2: Total Points | C2: Custom | D2: Peoplesoft | E2: SCT Banner | I2: Criteria | J2: Total Points | K2: Custom (ISIS) | L2: Peoplesoft | M2: SCT Banner | P2: Criteria | Q2: Total Points | R2: Custom (ISIS) | S2: Peoplesoft | T2: SCT Banner
A3: Software Costs | I3: =A6 -> Software Costs | J3: =B6 -> 60 | K3: =C6 -> 60 | L3: =D6 -> 33 | M3: =E6 -> 33 | P3: =I3 -> Software Costs | Q3: =B7 -> 1 | R3: =C7 -> 1 | S3: =D7 -> 0.55 | T3: =E7 -> 0.55
A4: Total vendor software licenses | B4: ='Non-Functional Detail'!D4 -> 45 | C4: ='Non-Functional Detail'!H4 -> 45 | D4: ='Non-Functional Detail'!N4 -> 18 | E4: ='Non-Functional Detail'!K4 -> 18 | I4: =A11 -> Implementation Costs | J4: =B11 -> 90 | K4: =C11 -> 16.428571 | L4: =D11 -> 90 | M4: =E11 -> 75 | P4: =I4 -> Implementation Costs | Q4: =B12 -> 1 | R4: =C12 -> 0.18253968 | S4: =D12 -> 1 | T4: =E12 -> 0.83333333
A5: Database license | B5: ='Non-Functional Detail'!D5 -> 15 | C5: ='Non-Functional Detail'!H5 -> 15 | D5: ='Non-Functional Detail'!N5 -> 15 | E5: ='Non-Functional Detail'!K5 -> 15 | I5: =A15 -> Annual Costs | J5: =B15 -> 30 | K5: =C15 -> 30 | L5: =D15 -> 12 | M5: =E15 -> 10 | P5: =I5 -> Annual Costs | Q5: =B16 -> 1 | R5: =C16 -> 1 | S5: =D16 -> 0.4 | T5: =E16 -> 0.33333333
A6: Software Costs | B6: =SUM(B4:B5) -> 60 | C6: =SUM(C4:C5) -> 60 | D6: =SUM(D4:D5) -> 33 | E6: =SUM(E4:E5) -> 33 | I6: =A20 -> Vendor Reputation | J6: =B20 -> 30 | K6: =C20 -> 6.6 | L6: =D20 -> 14.4 | M6: =E20 -> 30 | P6: =I6 -> Vendor Reputation | Q6: =B21 -> 1 | R6: =C21 -> 0.22 | S6: =D21 -> 0.48 | T6: =E21 -> 1
A7: % of Total Points | B7: =B6/B6 -> 1 | C7: =C6/$B6 -> 1 | D7: =D6/$B6 -> 0.55 | E7: =E6/$B6 -> 0.55 | I7: =A32 -> Product | J7: =B32 -> 90 | K7: =C32 -> 56 | L7: =D32 -> 73 | M7: =E32 -> 84 | P7: =I7 -> Product | Q7: =B33 -> 1 | R7: =C33 -> 0.62222222 | S7: =D33 -> 0.81111111 | T7: =E33 -> 0.93333333
A8: Implementation Cost | I8: Total | J8: =SUM(J3:J7) -> 300 | K8: =SUM(K3:K7) -> 169.02857 | L8: =SUM(L3:L7) -> 222.4 | M8: =SUM(M3:M7) -> 232 | P8: =I8 -> Total | Q8: =B36 -> 1 | R8: =C36 -> 0.56342857 | S8: =D36 -> 0.74133333 | T8: =E36 -> 0.77333333
A9: Total Development Cost (1) | B9: ='Non-Functional Detail'!D9 -> 60 | C9: ='Non-Functional Detail'!H9 -> 10 | D9: ='Non-Functional Detail'!N9 -> 60 | E9: ='Non-Functional Detail'!K9 -> 60
A10: Estimated Project Duration | B10: ='Non-Functional Detail'!D10 -> 30 | C10: ='Non-Functional Detail'!H10 -> 6.4285714 | D10: ='Non-Functional Detail'!N10 -> 30 | E10: ='Non-Functional Detail'!K10 -> 15
A11: Implementation Costs | B11: =SUM(B9:B10) -> 90 | C11: =SUM(C9:C10) -> 16.428571 | D11: =SUM(D9:D10) -> 90 | E11: =SUM(E9:E10) -> 75
A12: % of Total Points | B12: =B11/B11 -> 1 | C12: =C11/$B11 -> 0.18253968 | D12: =D11/$B11 -> 1 | E12: =E11/$B11 -> 0.83333333
A13: Annual Costs
A14: Estimated total annual support | B14: ='Non-Functional Detail'!D14 -> 30 | C14: ='Non-Functional Detail'!H14 -> 30 | D14: ='Non-Functional Detail'!N14 -> 12 | E14: ='Non-Functional Detail'!K14 -> 10
A15: Annual Costs | B15: =SUM(B14) -> 30 | C15: =SUM(C14) -> 30 | D15: =SUM(D14) -> 12 | E15: =SUM(E14) -> 10
A16: % of Total Points | B16: =B15/B15 -> 1 | C16: =C15/$B15 -> 1 | D16: =D15/$B15 -> 0.4 | E16: =E15/$B15 -> 0.33333333
A17: Vendor
A18: Reputation/Financial Stability | B18: ='Non-Functional Detail'!D18 -> 6 | C18: ='Non-Functional Detail'!H18 -> 6 | D18: ='Non-Functional Detail'!N18 -> 6 | E18: ='Non-Functional Detail'!K18 -> 6
A19: Number of Canadian Student application sites | B19: ='Non-Functional Detail'!D19 -> 24 | C19: ='Non-Functional Detail'!H19 -> 0.6 | D19: ='Non-Functional Detail'!N19 -> 8.4 | E19: ='Non-Functional Detail'!K19 -> 24
A20: Vendor Reputation | B20: =SUM(B18:B19) -> 30 | C20: =SUM(C18:C19) -> 6.6 | D20: =SUM(D18:D19) -> 14.4 | E20: =SUM(E18:E19) -> 30
A21: % of Total Points | B21: =B20/B20 -> 1 | C21: =C20/$B20 -> 0.22 | D21: =D20/$B20 -> 0.48 | E21: =E20/$B20 -> 1
A22: Product
A23: Product stability (2) | B23: ='Non-Functional Detail'!D23 -> 12 | C23: ='Non-Functional Detail'!H23 -> 4 | D23: ='Non-Functional Detail'!N23 -> 8 | E23: ='Non-Functional Detail'!K23 -> 12
A24: Product flexibility | B24: ='Non-Functional Detail'!D24 -> 12 | C24: ='Non-Functional Detail'!H24 -> 4 | D24: ='Non-Functional Detail'!N24 -> 12 | E24: ='Non-Functional Detail'!K24 -> 12
A25: Product adaptability to Canadian requirements | B25: ='Non-Functional Detail'!D25 -> 12 | C25: ='Non-Functional Detail'!H25 -> 12 | D25: ='Non-Functional Detail'!N25 -> 8 | E25: ='Non-Functional Detail'!K25 -> 12
A26: Product adaptability for customization | B26: ='Non-Functional Detail'!D26 -> 9 | C26: ='Non-Functional Detail'!H26 -> 9 | D26: ='Non-Functional Detail'!N26 -> 9 | E26: ='Non-Functional Detail'!K26 -> 9
A27: Product adaptability for upgrades | B27: ='Non-Functional Detail'!D27 -> 9 | C27: ='Non-Functional Detail'!H27 -> 9 | D27: ='Non-Functional Detail'!N27 -> 9 | E27: ='Non-Functional Detail'!K27 -> 9
A28: Product deployability | B28: ='Non-Functional Detail'!D28 -> 9 | C28: ='Non-Functional Detail'!H28 -> 3 | D28: ='Non-Functional Detail'!N28 -> 9 | E28: ='Non-Functional Detail'!K28 -> 9
A29: Product technology base | B29: ='Non-Functional Detail'!D29 -> 9 | C29: ='Non-Functional Detail'!H29 -> 9 | D29: ='Non-Functional Detail'!N29 -> 9 | E29: ='Non-Functional Detail'!K29 -> 6
A30: Interfaces to other same vendor modules | B30: ='Non-Functional Detail'!D30 -> 9 | C30: ='Non-Functional Detail'!H30 -> 3 | D30: ='Non-Functional Detail'!N30 -> 3 | E30: ='Non-Functional Detail'!K30 -> 9
A31: Interfaces to other vendor systems | B31: ='Non-Functional Detail'!D31 -> 9 | C31: ='Non-Functional Detail'!H31 -> 3 | D31: ='Non-Functional Detail'!N31 -> 6 | E31: ='Non-Functional Detail'!K31 -> 6
A32: Product | B32: =SUM(B23:B31) -> 90 | C32: =SUM(C23:C31) -> 56 | D32: =SUM(D23:D31) -> 73 | E32: =SUM(E23:E31) -> 84
A33: % of Total Points | B33: =B32/B32 -> 1 | C33: =C32/$B32 -> 0.62222222 | D33: =D32/$B32 -> 0.81111111 | E33: =E32/$B32 -> 0.93333333
A35: Overall Total | B35: =SUM(B6,B11,B15,B20,B32) -> 300 | C35: =SUM(C6,C11,C15,C20,C32) -> 169.02857 | D35: =SUM(D6,D11,D15,D20,D32) -> 222.4 | E35: =SUM(E6,E11,E15,E20,E32) -> 232
A36: Overall % of Total Points | B36: =B35/B35 -> 1 | C36: =C35/$B35 -> 0.56342857 | D36: =D35/$B35 -> 0.74133333 | E36: =E35/$B35 -> 0.77333333
A38: Non-Functional Requirements Analysis - Un-weighted Results | I38: Non-Functional Requirements Analysis Summary - Un-weighted | P38: Non-Functional Requirements Analysis Summary - Un-weighted %
A39: Criteria | B39: Total Points | C39: Custom | D39: Peoplesoft | E39: SCT Banner | I39: Criteria | J39: Total Points | K39: Custom (ISIS) | L39: Peoplesoft | M39: SCT Banner | P39: Criteria | Q39: Total Points | R39: Custom (ISIS) | S39: Peoplesoft | T39: SCT Banner
A40: Software Costs | I40: =A43 -> Software Costs | J40: =B43 -> 6 | K40: =C43 -> 6 | L40: =D43 -> 4.2 | M40: =E43 -> 4.2 | P40: =I40 -> Software Costs | Q40: =B44 -> 1 | R40: =C44 -> 1 | S40: =D44 -> 0.7 | T40: =E44 -> 0.7
A41: Total vendor software licenses | B41: ='Non-Functional Detail'!B4 -> 3 | C41: ='Non-Functional Detail'!G4 -> 3 | D41: ='Non-Functional Detail'!M4 -> 1.2 | E41: ='Non-Functional Detail'!J4 -> 1.2 | I41: =A48 -> Implementation Costs | J41: =B48 -> 6 | K41: =C48 -> 1.1428571 | L41: =D48 -> 6 | M41: =E48 -> 4.5 | P41: =I41 -> Implementation Costs | Q41: =B49 -> 1 | R41: =C49 -> 0.19047619 | S41: =D49 -> 1 | T41: =E49 -> 0.75
A42: Database license | B42: ='Non-Functional Detail'!B5 -> 3 | C42: ='Non-Functional Detail'!G5 -> 3 | D42: ='Non-Functional Detail'!M5 -> 3 | E42: ='Non-Functional Detail'!J5 -> 3 | I42: =A52 -> Annual Costs | J42: =B52 -> 3 | K42: =C52 -> 3 | L42: =D52 -> 1.2 | M42: =E52 -> 1 | P42: =I42 -> Annual Costs | Q42: =B53 -> 1 | R42: =C53 -> 1 | S42: =D53 -> 0.4 | T42: =E53 -> 0.33333333
...

Sheet Weighting Summary
B2: Weighting
A3: Software Costs
A4: Total vendor software licenses | B4: 15
A5: Database license | B5: 5
A6: Total Development Cost (1) | B6: 20
A7: Estimated Project Duration | B7: 10
A8: Estimated total annual support | B8: 10
A9: Reputation/Financial Stability | B9: 2
A10: Number of Canadian Student application sites | B10: 8
A11: Product stability (2) | B11: 4
A12: Product flexibility | B12: 4
A13: Product adaptability to Canadian requirements | B13: 4
A14: Product adaptability for customization | B14: 3
A15: Product adaptability for upgrades | B15: 3
... A19: Interfaces to other vendor systems | B19: 3
B20: =SUM(B4:B19) -> 100
A21: Software Costs | B21: Weighting
A22: Software Costs | B22: 20
A23: Implementation Costs | B23: 30
A24: Annual Costs | B24: 10
A25: Vendor Reputation | B25: 10
A26: Product | B26: 30
A27: Total | B27: =SUM(B22:B26) -> 100

Sheet Non-Functional Detail
A1: Criteria | F1: Custom | I1: Banner | L1: PeopleSoft | O1: Calculation
B2: Un-weighted | C2: Weighting | D2: Weighted | E2: Scoring Comments | F2: Data | G2: Un-weighted Score | H2: Weighted Score | I2: Data | J2: Un-weighted Score | K2: Weighted Score | L2: Data | M2: Un-weighted Score | N2: Weighted Score
A3: Software Costs
A4: Total vendor software licenses | B4: 3 | C4: 15 | D4: =B4*C4 -> 45 | E4: Lowest price receives 3 points. Other prices receive 3 x Lowest Price/Other Price | F4: 400000 | G4: =3*$O4/F4 -> 3 | H4: =G4*C4 -> 45 | I4: 1000000 | J4: =3*$O4/I4 -> 1.2 | K4: =J4*C4 -> 18 | L4: 1000000 | M4: =3*$O4/L4 -> 1.2 | N4: =M4*C4 -> 18 | O4: =MIN(F4,I4,L4) -> 400000
A5: Database license | B5: 3 | C5: 5 | D5: =B5*C5 -> 15 | E5: Lowest price receives 3 points. Other prices receive 3 x Lowest Price/Other Price | F5: 350000 | G5: =3*$O5/F5 -> 3 | H5: =G5*C5 -> 15 | I5: 350000 | J5: =3*$O5/I5 -> 3 | K5: =J5*C5 -> 15 | L5: 350000 | M5: =3*$O5/L5 -> 3 | N5: =M5*C5 -> 15 | O5: =MIN(F5,I5,L5) -> 350000
A6: Software Costs Points | B6: =SUM(B4:B5) -> 6 | D6: =SUM(D4:D5) -> 60 | G6: =SUM(G4:G5) -> 6 | H6: =SUM(H4:H5) -> 60 | J6: =SUM(J4:J5) -> 4.2 | K6: =SUM(K4:K5) -> 33 | M6: =SUM(M4:M5) -> 4.2 | N6: =SUM(N4:N5) -> 33
A7: % of Total Points | G7: =G6/B6 -> 1 | H7: =H6/D6 -> 1 | J7: =J6/B6 -> 0.7 | K7: =K6/D6 -> 0.55 | M7: =M6/B6 -> 0.7 | N7: =N6/D6 -> 0.55
A8: Implementation Cost
A9: Total Development Cost (1) | B9: 3 | C9: 20 | D9: =B9*C9 -> 60 | E9: Lowest price receives 3 points. Other prices receive 3 x Lowest Price/Other Price | F9: 6000000 | G9: =3*$O9/F9 -> 0.5 | H9: =G9*C9 -> 10 | I9: 1000000 | J9: =3*$O9/I9 -> 3 | K9: =J9*C9 -> 60 | L9: 1000000 | M9: =3*$O9/L9 -> 3 | N9: =M9*C9 -> 60 | O9: =MIN(F9,I9,L9) -> 1000000
A10: Estimated Project Duration | B10: 3 | C10: 10 | D10: =B10*C10 -> 30 | E10: Shortest duration receives 3 points. Other durations receive 3 x Shortest Duration/Other Duration | F10: 7 | G10: =3*$O10/F10 -> 0.64285714 | H10: =G10*C10 -> 6.4285714 | I10: 3 | J10: =3*$O10/I10 -> 1.5 | K10: =J10*C10 -> 15 | L10: 1.5 | M10: =3*$O10/L10 -> 3 | N10: =M10*C10 -> 30 | O10: =MIN(F10,I10,L10) -> 1.5
A11: Implementation Costs Points | B11: =SUM(B9:B10) -> 6 | D11: =SUM(D9:D10) -> 90 | G11: =SUM(G9:G10) -> 1.1428571 | H11: =SUM(H9:H10) -> 16.428571 | J11: =SUM(J9:J10) -> 4.5 | K11: =SUM(K9:K10) -> 75 | M11: =SUM(M9:M10) -> 6 | N11: =SUM(N9:N10) -> 90
A12: % of Total Points | G12: =G11/B11 -> 0.19047619 | H12: =H11/D11 -> 0.18253968 | J12: =J11/B11 -> 0.75 | K12: =K11/D11 -> 0.83333333 | M12: =M11/B11 -> 1 | N12: =N11/D11 -> 1
A13: Annual Costs
A14: Estimated total annual support | B14: 3 | C14: 10 | D14: =B14*C14 -> 30 | E14: Lowest price receives 3 points. Other prices receive 3 x Lowest Price/Other Price | F14: 100000 | G14: =3*$O14/F14 -> 3 | H14: =G14*C14 -> 30 | I14: 300000 | J14: =3*$O14/I14 -> 1 | K14: =J14*C14 -> 10 | L14: 250000 | M14: =3*$O14/L14 -> 1.2 | N14: =M14*C14 -> 12 | O14: =MIN(F14,I14,L14) -> 100000
A15: Annual Costs Points | B15: =SUM(B14) -> 3 | D15: =SUM(D14) -> 30 | G15: =SUM(G14) -> 3 | H15: =SUM(H14) -> 30 | J15: =SUM(J14) -> 1 | K15: =SUM(K14) -> 10 | M15: =SUM(M14) -> 1.2 | N15: =SUM(N14) -> 12
A16: % of Total Points | M16: =M15/B15 -> 0.4 | N16: =N15/D15 -> 0.4
A17: Vendor
A18: Reputation/Financial Stability | B18: 3 | C18: 2 | D18: =B18*C18 -> 6 | E18: Rated Low, Medium or High. Low = 1 point, Medium = 2 points, High = 3 points | F18: High | G18: 3 | H18: =G18*C18 -> 6 | I18: high | J18: 3 | K18: =J18*C18 -> 6 | L18: high | M18: 3 | N18: =M18*C18 -> 6
A19: Number of Canadian Student application sites | B19: 3 | C19: 8 | D19: =B19*C19 -> 24 | E19: Highest Number of Sites receives 3 points. Other number of sites receive 3 x Number of Sites/Highest Number of Sites | F19: 1 | G19: =3*F19/$O19 -> 0.075 | H19: =G19*C19 -> 0.6 | I19: 40 | J19: =3*I19/$O19 -> 3 | K19: =J19*C19 -> 24 | L19: 14 | M19: =3*L19/$O19 -> 1.05 | N19: =M19*C19 -> 8.4 | O19: =MAX(F19,I19,L19) -> 40
A20: Vendor Points | B20: =SUM(B18:B19) -> 6 | D20: =SUM(D18:D19) -> 30 | G20: =SUM(G18:G19) -> 3.075 | H20: =SUM(H18:H19) -> 6.6 | J20: =SUM(J18:J19) -> 6 | K20: =SUM(K18:K19) -> 30 | M20: =SUM(M18:M19) -> 4.05 | N20: =SUM(N18:N19) -> 14.4
A21: % of Total Points | G21: =G20/B20 -> 0.5125 | H21: =H20/D20 -> 0.22 | J21: =J20/B20 -> 1 | K21: =K20/D20 -> 1 | M21: =M20/B20 -> 0.675 | N21: =N20/D20 -> 0.48
A22: Product
A23: Product stability (2) | B23: 3 | C23: 4 | D23: =B23*C23 -> 12 | E23: Rated Unknown or Low, Medium or High. Low = 1 point, Medium = 2 points, High = 3 points | F23: unknown | G23: 1 | H23: =G23*C23 -> 4 | I23: High | J23: 3 | K23: =J23*C23 -> 12 | L23: Medium | M23: 2 | N23: =M23*C23 -> 8
A24: Product flexibility | B24: 3 | C24: 4 | D24: =B24*C24 -> 12 | E24: Rated Low, Medium or High. Low = 1 point, Medium = 2 points, High = 3 points | F24: unknown | G24: 1 | H24: =G24*C24 -> 4 | I24: high | J24: 3 | K24: =J24*C24 -> 12 | L24: high | M24: 3 | N24: =M24*C24 -> 12
A25: Product adaptability to Canadian requirements | B25: 3 | C25: 4 | D25: =B25*C25 -> 12 | E25: Rated Low, Medium or High. Low = 1 point, Medium = 2 points, High = 3 points | F25: high | G25: 3 | H25: =G25*C25 -> 12 | I25: high | J25: 3 | K25: =J25*C25 -> 12 | L25: Medium | M25: 2 | N25: =M25*C25 -> 8
A26: Product adaptability for customization | B26: 3 | C26: 3 | D26: =B26*C26 -> 9 | E26: Rated Low, Medium or High. Low = 1 point, Medium = 2 points, High = 3 points | F26: high | G26: 3 | H26: =G26*C26 -> 9 | I26: high | J26: 3 | K26: =J26*C26 -> 9 | L26: high | M26: 3 | N26: =M26*C26 -> 9
A27: Product adaptability for upgrades | B27: 3 | C27: 3 | D27: =B27*C27 -> 9 | E27: Rated Low, Medium or High. Low = 1 point, Medium = 2 points, High = 3 points | F27: high | G27: 3 | H27: =G27*C27 -> 9 | I27: high | J27: 3 | K27: =J27*C27 -> 9 | L27: high | M27: 3 | N27: =M27*C27 -> 9
A28: Product deployability | B28: 3 | C28: 3 | D28: =B28*C28 -> 9 | E28: Rated Low, Medium or High. Low = 1 point, Medium = 2 points, High = 3 points | F28: unknown | G28: 1 | H28: =G28*C28 -> 3 | I28: high | J28: 3 | K28: =J28*C28 -> 9 | L28: high | M28: 3 | N28: =M28*C28 -> 9
A29: Product technology base | B29: 3 | C29: 3 | D29: =B29*C29 -> 9 | E29: Multiple, current DB = 3 points, Single current DB = 2 points, Proprietary or legacy DB = 1 point | F29: To be determined - could be anything | G29: 3 | H29: =G29*C29 -> 9 | I29: Oracle | J29: 2 | K29: =J29*C29 -> 6 | L29: Oracle, MS SQL, DB2 | M29: 3 | N29: =M29*C29 -> 9
A30: Interfaces to other same vendor modules | B30: 3 | C30: 3 | D30: =B30*C30 -> 9 | E30: Included =3, Custom/Available = 2, Custom = 1 | F30: Custom | G30: 1 | H30: =G30*C30 -> 3 | I30: Included | J30: 3 | K30: =J30*C30 -> 9 | L30: Custom | M30: 1 | N30: =M30*C30 -> 3
A31: Interfaces to other vendor systems | B31: 3 | C31: 3 | D31: =B31*C31 -> 9 | E31: Included =3, Custom/Available = 2, Custom = 1 | F31: Custom | G31: 1 | H31: =G31*C31 -> 3 | I31: available/ custom | J31: 2 | K31: =J31*C31 -> 6 | L31: available/ custom | M31: 2 | N31: =M31*C31 -> 6
A32: Product Points | B32: =SUM(B23:B31) -> 27 | D32: =SUM(D23:D31) -> 90 | G32: =SUM(G23:G31) -> 17 | H32: =SUM(H23:H31) -> 56 | J32: =SUM(J23:J31) -> 25 | K32: =SUM(K23:K31) -> 84 | M32: =SUM(M23:M31) -> 22 | N32: =SUM(N23:N31) -> 73
A33: % of Total Points | G33: =G32/B32 -> 0.62962963 | H33: =H32/D32 -> 0.62222222 | J33: =J32/B32 -> 0.92592593 | K33: =K32/D32 -> 0.93333333 | M33: =M32/B32 -> 0.81481481 | N33: =N32/D32 -> 0.81111111
A35: Overall Total | B35: =SUM(B6,B11,B15,B20,B32) -> 48 | D35: =SUM(D6,D11,D15,D20,D32) -> 300 | G35: =SUM(G6,G11,G15,G20,G32) -> 30.217857 | H35: =SUM(H6,H11,H15,H20,H32) -> 169.02857 | J35: =SUM(J6,J11,J15,J20,J32) -> 40.7 | K35: =SUM(K6,K11,K15,K20,K32) -> 232 | L35: =K35/$D35 -> 0.77333333 | M35: =SUM(M6,M11,M15,M20,M32) -> 37.45 | N35: =SUM(N6,N11,N15,N20,N32) -> 222.4
A36: Overall % of Total Points | G36: =G35/B35 -> 0.62953869 | H36: =H35/D35 -> 0.56342857 | J36: =J35/B35 -> 0.84791667 | K36: =K35/D35 -> 0.77333333 | M36: =M35/B35 -> 0.78020833 | N36: =N35/D35 -> 0.74133333
