Workbook

Sheet INSTRUCTIONS

Sheet Inv CC
A1: ESTIMATED INVENTORY CARRYING COST (PRE-TAX)
C2: $ (000) | D2: %
B3: Estimated Average Inventory Balance (from Balance Sheet, otherwise hardinput) | C3: =Financials!B14 -> 485
A5: Cost of Capital of Inventory
A6: Method 1- | B6: 1 Corporate after-tax Opportunity Cost of Capital/Hurdle Rate | D6: 0.15
A7: OR
A8: Method 2- | B8: 2. Estimate after-tax Opportunity Cost of Capital via CAPM & WACC
B9: Debt % of Total Capital | D9: =Financials!C41 -> 0.52380952
B10: Equity % of Total Capital | D10: =Financials!C46 -> 0.47619048
B11: Beta of Equity (or proxy) | C11: 1.2
B12: Risk Free Rate (short-term) | C12: 0.06
B13: Historical Market Premium (short-term) | C13: 0.08
B14: Cost of Equity (per CAPM) | D14: =C12+(C11*C13) -> 0.156
B15: Cost of Debt (short-term) | D15: 0.07
B16: Weighted Average Cost of Capital (after-tax) | D16: =(D9*D15*(1-D18))+(D10*D14) -> 0.096285714
B18: Overall Corporate Income Tax Rate | D18: 0.4
B19: Cost of Capital (pre-tax) | E19: =IF(D6>0,D6/(1-D18),D16/(1-D18)) -> 0.25
A21: Service Costs of Inventory (variable costs)
B22: Personal Property Taxes (ad-valorum) | C22: 4.85 | D22: =C22/$C$3 -> 0.01
B23: Insurance (fire and theft) | C23: 8.1 | D23: =C23/$C$3 -> 0.016701031 | E23: =D23+D22 -> 0.026701031
A25: Storage Costs of Inventory (variable costs)
B26: Plant Warehouse | C26: 0 | D26: =C26/$C$3 -> 0
B27: Public Warehouse | C27: 2.425 | D27: =C27/$C$3 -> 0.005
B28: Rented/Leased Warehouse | C28: 0 | D28: =C28/$C$3 -> 0
B29: Company-Owned Warehouse | C29: 0 | D29: =C29/$C$3 -> 0 | E29: =SUM(D26:D29) -> 0.005
A31: Risk Costs of Inventory (variable costs)
B32: Obsolescence/Write-Down | C32: 3.5 | D32: =C32/$C$3 -> 0.0072164948
B33: Damage | C33: 2 | D33: =C33/$C$3 -> 0.0041237113
B34: Shrinkage | C34: 2 | D34: =C34/$C$3 -> 0.0041237113
B35: Relocation/Transfer (to other facility) | C35: 0 | D35: =C35/$C$3 -> 0 | E35: =SUM(D32:D35) -> 0.015463918
A37: ESTIMATED TOTAL PRE-TAX INVENTORY CARRYING COST | E37: =E19+E23+E29+E35 -> 0.29716495

Sheet Financials
A1: WHOLESALER STRATEGIC PROFIT MODEL
A2: BASELINE INPUTS:
A3: Total Assets | B3: 1000
A4: Asset Turnover (Sales/T. Assets) | B4: 2.7
A5: Debt to Equity Ratio | B5: 1.1
A6: Gross Margin | B6: 0.248
A7: Operating Margin | B7: 0.026
A8: PreTax Margin | B8: 0.025
B9: BASELINE | E9: SCENARIO 1: INVENTORY DOWN 20% | H9: SCENARIO 2: WAREHOUSING EXPENSES DOWN 20% | K9: SCENARIO 3: TRANSPORTATION EXPENSES DOWN 20% | N9: SCENARIO 4: SCENARIOS 1-3 COMBINED
B10: 'AS-IS' ($000) | C10: Common Size | E10: 'TO-BE' ($000) | F10: Common Size | H10: 'TO-BE' ($000) | I10: Common Size | K10: 'TO-BE' ($000) | L10: Common Size | N10: 'TO-BE' ($000) | O10: Common Size
A11: BALANCE SHEET
A12: Cash & Equivlnts, ST Investments | B12: =C12*$B$28 -> 25 | C12: 0.025 | E12: =B12 -> 25 | F12: =E12/E$28 -> 0.027685493 | H12: =B12 -> 25 | I12: =H12/H$28 -> 0.025 | K12: =B12 -> 25 | L12: =K12/K$28 -> 0.025 | N12: =B12 -> 25 | O12: =N12/N$28 -> 0.027685493
A13: Accounts Receivable | B13: =C13*$B$28 -> 354 | C13: 0.354 | E13: =B13 -> 354 | F13: =E13/E$28 -> 0.39202658 | H13: =B13 -> 354 | I13: =H13/H$28 -> 0.354 | K13: =B13 -> 354 | L13: =K13/K$28 -> 0.354 | N13: =B13 -> 354 | O13: =N13/N$28 -> 0.39202658
A14: Inventory | B14: =C14*$B$28 -> 485 | C14: 0.485 | E14: =B14*0.8 -> 388 | F14: =E14/E$28 -> 0.42967885 | H14: =B14 -> 485 | I14: =H14/H$28 -> 0.485 | K14: =B14 -> 485 | L14: =K14/K$28 -> 0.485 | N14: =E14 -> 388 | O14: =N14/N$28 -> 0.42967885
A15: Other Current Assets | B15: =C15*$B$28 -> 22 | C15: 0.022 | E15: =B15 -> 22 | F15: =E15/E$28 -> 0.024363234 | H15: =B15 -> 22 | I15: =H15/H$28 -> 0.022 | K15: =B15 -> 22 | L15: =K15/K$28 -> 0.022 | N15: =B15 -> 22 | O15: =N15/N$28 -> 0.024363234
A16: TOTAL CURRENT ASSETS | B16: =SUM(B12:B15) -> 886 | C16: =B16/$B$28 -> 0.886 | E16: =SUM(E12:E15) -> 789 | F16: =E16/E$28 -> 0.87375415 | H16: =SUM(H12:H15) -> 886 | I16: =H16/H$28 -> 0.886 | K16: =SUM(K12:K15) -> 886 | L16: =K16/K$28 -> 0.886 | N16: =SUM(N12:N15) -> 789 | O16: =N16/N$28 -> 0.87375415
A18: Property, Plant & Equipment (PP&E)
A19: Warehouse/Distribution Gross | B19: =C19*$B$28 -> 128.25 | C19: =2*C21 -> 0.12825 | E19: =B19 -> 128.25 | F19: =E19/E$28 -> 0.14202658 | H19: =B19 -> 128.25 | I19: =H19/H$28 -> 0.12825 | K19: =B19 -> 128.25 | L19: =K19/K$28 -> 0.12825 | N19: =B19 -> 128.25 | O19: =N19/N$28 -> 0.14202658
A20: Warehouse/Distribution Accum Depreciation | B20: =C20*$B$28 -> -64.125 | C20: =-C21 -> -0.064125 | E20: =B20 -> -64.125 | F20: =E20/E$28 -> -0.071013289 | H20: =B20 -> -64.125 | I20: =H20/H$28 -> -0.064125 | K20: =B20 -> -64.125 | L20: =K20/K$28 -> -0.064125 | N20: =B20 -> -64.125 | O20: =N20/N$28 -> -0.071013289
A21: Net Warehouse/Distribution PP&E | B21: =C21*$B$28 -> 64.125 | C21: =0.75*$C$25 -> 0.064125 | E21: =SUM(E19:E20) -> 64.125 | F21: =E21/E$28 -> 0.071013289 | H21: =SUM(H19:H20) -> 64.125 | I21: =H21/H$28 -> 0.064125 | K21: =SUM(K19:K20) -> 64.125 | L21: =K21/K$28 -> 0.064125 | N21: =SUM(N19:N20) -> 64.125 | O21: =N21/N$28 -> 0.071013289
A22: Other PP&E Gross | B22: =C22*$B$28 -> 42.75 | C22: =2*C24 -> 0.04275 | E22: =B22 -> 42.75 | F22: =E22/E$28 -> 0.047342193 | H22: =B22 -> 42.75 | I22: =H22/H$28 -> 0.04275 | K22: =B22 -> 42.75 | L22: =K22/K$28 -> 0.04275 | N22: =B22 -> 42.75 | O22: =N22/N$28 -> 0.047342193
A23: Other PP&E Accum Depreciation | B23: =C23*$B$28 -> -21.375 | C23: =-C24 -> -0.021375 | E23: =B23 -> -21.375 | F23: =E23/E$28 -> -0.023671096 | H23: =B23 -> -21.375 | I23: =H23/H$28 -> -0.021375 | K23: =B23 -> -21.375 | L23: =K23/K$28 -> -0.021375 | N23: =B23 -> -21.375 | O23: =N23/N$28 -> -0.023671096
A24: Net Other PP&E | B24: =C24*$B$28 -> 21.375 | C24: =0.25*$C$25 -> 0.021375 | E24: =SUM(E22:E23) -> 21.375 | F24: =E24/E$28 -> 0.023671096 | H24: =SUM(H22:H23) -> 21.375 | I24: =H24/H$28 -> 0.021375 | K24: =SUM(K22:K23) -> 21.375 | L24: =K24/K$28 -> 0.021375 | N24: =SUM(N22:N23) -> 21.375 | O24: =N24/N$28 -> 0.023671096
A25: Net Total PP&E | B25: =C25*$B$28 -> 85.5 | C25: =0.75*$C$27 -> 0.0855 | E25: =E24+E21 -> 85.5 | F25: =E25/E$28 -> 0.094684385 | H25: =H24+H21 -> 85.5 | I25: =H25/H$28 -> 0.0855 | K25: =K24+K21 -> 85.5 | L25: =K25/K$28 -> 0.0855 | N25: =N24+N21 -> 85.5 | O25: =N25/N$28 -> 0.094684385
A26: Other NonCurrent Assets | B26: =C26*$B$28 -> 28.5 | C26: =0.25*$C$27 -> 0.0285 | E26: =B26 -> 28.5 | F26: =E26/E$28 -> 0.031561462 | H26: =B26 -> 28.5 | I26: =H26/H$28 -> 0.0285 | K26: =B26 -> 28.5 | L26: =K26/K$28 -> 0.0285 | N26: =B26 -> 28.5 | O26: =N26/N$28 -> 0.031561462
A27: TOTAL NONCURRENT ASSETS | B27: =C27*$B$28 -> 114 | C27: 0.114 | E27: =E26+E21+E24 -> 114 | F27: =E27/E$28 -> 0.12624585 | H27: =H26+H21+H24 -> 114 | I27: =H27/H$28 -> 0.114 | K27: =K26+K21+K24 -> 114 | L27: =K27/K$28 -> 0.114 | N27: =N26+N21+N24 -> 114 | O27: =N27/N$28 -> 0.12624585
A28: TOTAL ASSETS | B28: =B3 -> 1000 | C28: =B28/$B$28 -> 1 | E28: =E27+E16 -> 903 | F28: =E28/E$28 -> 1 | H28: =H27+H16 -> 1000 | I28: =H28/H$28 -> 1 | K28: =K27+K16 -> 1000 | L28: =K28/K$28 -> 1 | N28: =N27+N16 -> 903 | O28: =N28/N$28 -> 1
A30: Accounts Payable
A31: Inventory/COGS Payables | B31: =C31*$B$48 -> 194.25 | C31: =0.75*0.259 -> 0.19425 | E31: =(B31-(B14-E14)) -> 97.25 | F31: =E31/E$28 -> 0.10769657 | H31: =B31 -> 194.25 | I31: =H31/H$28 -> 0.19425 | K31: =B31 -> 194.25 | L31: =K31/K$28 -> 0.19425 | N31: =E31 -> 97.25 | O31: =N31/N$28 -> 0.10769657
A32: Other Payables | B32: =C32*$B$48 -> 64.75 | C32: =0.25*0.259 -> 0.06475 | E32: =B32 -> 64.75 | F32: =E32/E$28 -> 0.071705426 | H32: =B32 -> 64.75 | I32: =H32/H$28 -> 0.06475 | K32: =B32 -> 64.75 | L32: =K32/K$28 -> 0.06475 | N32: =B32 -> 64.75 | O32: =N32/N$28 -> 0.071705426
A33: Current Debt | B33: =C33*$B$48 -> 107 | C33: 0.107 | E33: =B33 -> 107 | F33: =E33/E$28 -> 0.11849391 | H33: =B33 -> 107 | I33: =H33/H$28 -> 0.107 | K33: =B33 -> 107 | L33: =K33/K$28 -> 0.107 | N33: =B33 -> 107 | O33: =N33/N$28 -> 0.11849391
A34: Accrued Expenses | B34: =C34*$B$48 -> 20.25 | C34: =0.25*0.081 -> 0.02025 | E34: =B34 -> 20.25 | F34: =E34/E$28 -> 0.022425249 | H34: =B34 -> 20.25 | I34: =H34/H$28 -> 0.02025 | K34: =B34 -> 20.25 | L34: =K34/K$28 -> 0.02025 | N34: =B34 -> 20.25 | O34: =N34/N$28 -> 0.022425249
A35: Other Current Liabilities | B35: =C35*$B$48 -> 60.75 | C35: =0.75*0.081 -> 0.06075 | E35: =B35 -> 60.75 | F35: =E35/E$28 -> 0.067275748 | H35: =B35 -> 60.75 | I35: =H35/H$28 -> 0.06075 | K35: =B35 -> 60.75 | L35: =K35/K$28 -> 0.06075 | N35: =B35 -> 60.75 | O35: =N35/N$28 -> 0.067275748
A36: TOTAL CURRENT LIABILITIES | B36: =SUM(B31:B35) -> 447 | C36: =SUM(C31:C35) -> 0.447 | E36: =SUM(E31:E35) -> 350 | F36: =E36/E$28 -> 0.3875969 | H36: =SUM(H31:H35) -> 447 | I36: =H36/H$28 -> 0.447 | K36: =SUM(K31:K35) -> 447 | L36: =K36/K$28 -> 0.447 | N36: =SUM(N31:N35) -> 350 | O36: =N36/N$28 -> 0.3875969
A38: NonCurrent Debt | B38: =C38*$B$48 -> 57.607143 | C38: =0.75*$C$40 -> 0.057607143 | E38: =B38 -> 57.607143 | F38: =E38/E$28 -> 0.063795286 | H38: =B38 -> 57.607143 | I38: =H38/H$28 -> 0.057607143 | K38: =B38 -> 57.607143 | L38: =K38/K$28 -> 0.057607143 | N38: =B38 -> 57.607143 | O38: =N38/N$28 -> 0.063795286
A39: Other NonCurrent Liabilities | B39: =C39*$B$48 -> 19.202381 | C39: =0.25*$C$40 -> 0.019202381 | E39: =B39 -> 19.202381 | F39: =E39/E$28 -> 0.021265095 | H39: =B39 -> 19.202381 | I39: =H39/H$28 -> 0.019202381 | K39: =B39 -> 19.202381 | L39: =K39/K$28 -> 0.019202381 | N39: =B39 -> 19.202381 | O39: =N39/N$28 -> 0.021265095
A40: TOTAL NONCURRENT LIABILITIES | B40: =SUM(B38:B39) -> 76.809524 | C40: =(C41-C36) -> 0.076809524 | E40: =SUM(E38:E39) -> 76.809524 | F40: =E40/E$28 -> 0.085060381 | H40: =SUM(H38:H39) -> 76.809524 | I40: =H40/H$28 -> 0.076809524 | K40: =SUM(K38:K39) -> 76.809524 | L40: =K40/K$28 -> 0.076809524 | N40: =SUM(N38:N39) -> 76.809524 | O40: =N40/N$28 -> 0.085060381
A41: TOTAL LIABILITIES | B41: =C41*$B$48 -> 523.80952 | C41: =(B5/(1+B5)) -> 0.52380952 | E41: =E40+E36 -> 426.80952 | F41: =E41/E$28 -> 0.47265728 | H41: =H40+H36 -> 523.80952 | I41: =H41/H$28 -> 0.52380952 | K41: =K40+K36 -> 523.80952 | L41: =K41/K$28 -> 0.52380952 | N41: =N40+N36 -> 426.80952 | O41: =N41/N$28 -> 0.47265728
A43: Stock - Par | B43: =C43*$B$48 -> 4.7619048 | C43: =0.01*$C$46 -> 0.0047619048 | E43: =B43 -> 4.7619048 | F43: =E43/E$28 -> 0.0052734272 | H43: =B43 -> 4.7619048 | I43: =H43/H$28 -> 0.0047619048 | K43: =B43 -> 4.7619048 | L43: =K43/K$28 -> 0.0047619048 | N43: =B43 -> 4.7619048 | O43: =N43/N$28 -> 0.0052734272
A44: Stock - Surplus | B44: =C44*$B$48 -> 95.238095 | C44: =0.2*$C$46 -> 0.095238095 | E44: =B44 -> 95.238095 | F44: =E44/E$28 -> 0.10546854 | H44: =B44 -> 95.238095 | I44: =H44/H$28 -> 0.095238095 | K44: =B44 -> 95.238095 | L44: =K44/K$28 -> 0.095238095 | N44: =B44 -> 95.238095 | O44: =N44/N$28 -> 0.10546854
...

Sheet Baseline SPM
A1: STRATEGIC PROFIT MODEL FOR HYPOTHETICAL WHOLESALER - Baseline/'As-Is'
F2: ROE (Pre-Tax) | G2: =E14*H8*K9 -> 0.14175
F3: ROE (Post-Tax) | G3: =G6*K9 -> 0.074865 | H3: =IF(G3<>Financials!B87/Financials!B46,"ERROR","") | I3: =IF(G3<>(Financials!B87/Financials!B46),"ERROR","")
F6: ROA | G6: =E9*H8 -> 0.03565 | H6: =IF(G6<>(Financials!B87/Financials!B28),"ERROR","")
G8: Asset T/O | H8: =E43/H13 -> 2.7
D9: Net Margin | E9: =Financials!C87 -> 0.013203704 | I9: =IF((E43/H13)<>H8,"ERROR","") | J9: Leverage | K9: =H13/K11 -> 2.1
E10: =IF(E14-E11<>E9,"ERROR","")
D11: Taxes & Discnt'd/Extrord | E11: =SUM(Financials!C84:C86) -> 0.011796296 | J11: Total Equity | K11: =Financials!B46 -> 476.19048
E13: =IF(ABS(E44-E37-E32-E27-E23-E18-E16-E14)>0.0001,"ERROR","") | G13: Total Assets $ | H13: =Financials!B28 -> 1000
D14: Pretax Margin | E14: =Financials!C82 -> 0.025 | H14: =Financials!C28 -> 1
H15: =IF(H14<>(H17+K17),"ERROR","")
D16: Non-Operating Expense | E16: =Financials!C81 -> -0.006
G17: Total NonCurrent Assets | H17: =Financials!C27 -> 0.114 | J17: Total Current Assets | K17: =Financials!C16 -> 0.886
D18: Interest Expense | E18: =SUM(C19:C21) -> 0.007 | K18: =IF(K17<>(K19+K21+K23+K25),"ERROR","")
B19: General Corporate Interest | C19: =Financials!C78 -> 0.002 | G19: Other NonCurrent Assets | H19: =Financials!C26 -> 0.0285 | J19: Inventory | K19: =Financials!C14 -> 0.485
B20: Warehsng/Distrib Interest | C20: =Financials!C79 -> 0.003
B21: Excess Inventory Interest | C21: =Financials!C80 -> 0.002 | G21: Net Total PP&E | H21: =Financials!C25 -> 0.0855 | J21: Accounts Receivable | K21: =Financials!C13 -> 0.354
H22: =IF(H21<>(H25+H26+H28+H29),"ERROR","")
D23: Depreciation Expense | E23: =SUM(C24:C25) -> 0.004 | J23: Other Current Assets | K23: =Financials!C15 -> 0.022
B24: Genrl Corporate Depreciation | C24: =Financials!C74 -> 0.002
B25: Warehsng/Dist Depreciation | C25: =Financials!C75 -> 0.002 | G25: Warehsng/Dist Gross PP&E | H25: =Financials!C19 -> 0.12825 | J25: Cash, Equiv & ST Inv | K25: =Financials!C12 -> 0.025
G26: Warehsng/Dist Accum Dep | H26: =Financials!C20 -> -0.064125
D27: Selling, Genrl & Admin Expense | E27: =SUM(C28:C30) -> 0.10609333
B28: General SG&A | C28: =Financials!C70 -> 0.066 | E28: =IF((E44-E37)<>E35,"ERROR","") | G28: Other Gross PP&E | H28: =Financials!C22 -> 0.04275
B29: Out-bound Freight | C29: =Financials!C71 -> 0.035093333 | G29: Other Accum Dep | H29: =Financials!C23 -> -0.021375
B30: Customer Service Expense | C30: =Financials!C72 -> 0.005
D32: Warehousing/Distribtn Expense | E32: =SUM(C33:C37) -> 0.11190667
B33: General Warehsng/Dist Exp | C33: =Financials!C60 -> 0.10223074
B34: Public/Leased Facilities Exp | C34: =Financials!C61 -> 0.00089814815
B35: Warehsng/Dist Insurance | C35: =Financials!C63 -> 0.003 | D35: Gross Margin | E35: =E44-E37 -> 0.248
B36: Inventory Insurance | C36: =Financials!C64 -> 0.003
B37: Risk-related inventory CC | C37: =SUM(Financials!C65:C68) -> 0.0027777778 | D37: Cost of Goods Sold | E37: =SUM(C39:C40) -> 0.752
B39: Product Costs | C39: =Financials!C55 -> 0.73696
B40: In-Bound Freight | C40: =Financials!C56 -> 0.01504
D41: Gross Sales | E41: =Financials!C51 -> 1.03
D42: Returns, Allowances, Discounts | E42: =Financials!C52 -> 0.03
D43: Net Sales $ | E43: =Financials!B53 -> 2700
E44: =Financials!C53 -> 1
B47: INCOME STATEMENT | G47: BALANCE SHEET

Sheet SC1 SPM 
A1: STRATEGIC PROFIT MODEL TREE - 'Scenario 1' - 20% Decrease in Inventory
F2: ROE (Pre-Tax) | G2: =E14*H8*K9 -> 0.1517565
F3: ROE (Post-Tax) | G3: =G6*K9 -> 0.0829059 | H3: =IF(G3<>Financials!E87/Financials!E46,"ERROR","")
F6: ROA | G6: =E9*H8 -> 0.043719823 | H6: =IF(G6<>(Financials!E87/Financials!E28),"ERROR","")
G8: Asset T/O | H8: =E43/H13 -> 2.9900332
D9: Net Margin | E9: =Financials!F87 -> 0.014621852 | I9: =IF((E43/H13)<>H8,"ERROR","") | J9: Leverage | K9: =H13/K11 -> 1.8963
E10: =IF(E14-E11<>E9,"ERROR","")
D11: Taxes & Discnt'd/Extrord | E11: =SUM(Financials!F84:F86) -> 0.012142963 | J11: Total Equity | K11: =Financials!E46 -> 476.19048
E13: =IF(ABS(E44-E37-E32-E27-E23-E18-E16-E14)>0.0001,"ERROR","") | G13: Total Assets $ | H13: =Financials!E28 -> 903
D14: Pretax Margin | E14: =Financials!F82 -> 0.026764815 | H14: =Financials!F28 -> 1
H15: =IF(H14<>(H17+K17),"ERROR","")
D16: Non-Operating Expense | E16: =Financials!F81 -> -0.006
G17: Total NonCurrent Assets | H17: =Financials!F27 -> 0.12624585 | J17: Total Current Assets | K17: =Financials!F16 -> 0.87375415
D18: Interest Expense | E18: =SUM(C19:C21) -> 0.0066 | K18: =IF(K17<>(K19+K21+K23+K25),"ERROR","")
B19: General Corporate Interest | C19: =Financials!F78 -> 0.002 | G19: Other NonCurrent Assets | H19: =Financials!F26 -> 0.031561462 | J19: Inventory | K19: =Financials!F14 -> 0.42967885
B20: Warehsng/Distrib Interest | C20: =Financials!F79 -> 0.003
B21: Excess Inventory Interest | C21: =Financials!F80 -> 0.0016 | G21: Net Total PP&E | H21: =Financials!F25 -> 0.094684385 | J21: Accounts Receivable | K21: =Financials!F13 -> 0.39202658
H22: =IF(H21<>(H25+H26+H28+H29),"ERROR","")
D23: Depreciation Expense | E23: =SUM(C24:C25) -> 0.004 | J23: Other Current Assets | K23: =Financials!F15 -> 0.024363234
B24: Genrl Corporate Depreciation | C24: =Financials!F74 -> 0.002
B25: Warehsng/Dist Depreciation | C25: =Financials!F75 -> 0.002 | G25: Warehsng/Dist Gross PP&E | H25: =Financials!F19 -> 0.14202658 | J25: Cash, Equiv & ST Inv | K25: =Financials!F12 -> 0.027685493
G26: Warehsng/Dist Accum Dep | H26: =Financials!F20 -> -0.071013289
D27: Selling, Genrl & Admin Expense | E27: =SUM(C28:C30) -> 0.10609333
B28: General SG&A | C28: =Financials!F70 -> 0.066 | E28: =IF((E44-E37)<>E35,"ERROR","") | G28: Other Gross PP&E | H28: =Financials!F22 -> 0.047342193
B29: Out-bound Freight | C29: =Financials!F71 -> 0.035093333 | G29: Other Accum Dep | H29: =Financials!F23 -> -0.023671096
B30: Customer Service Expense | C30: =Financials!F72 -> 0.005
D32: Warehousing/Distribtn Expense | E32: =SUM(C33:C37) -> 0.11054185
B33: General Warehsng/Dist Exp | C33: =Financials!F60 -> 0.10223074
B34: Public/Leased Facilities Exp | C34: =Financials!F61 -> 0.00071851852
B35: Warehsng/Dist Insurance | C35: =Financials!F63 -> 0.0029703704 | D35: Gross Margin | E35: =E44-E37 -> 0.248
B36: Inventory Insurance | C36: =Financials!F64 -> 0.0024
B37: Risk-related inventory CC | C37: =SUM(Financials!F65:F68) -> 0.0022222222 | D37: Cost of Goods Sold | E37: =SUM(C39:C40) -> 0.752
B39: Product Costs | C39: =Financials!F55 -> 0.73696
B40: In-Bound Freight | C40: =Financials!F56 -> 0.01504
D41: Gross Sales | E41: =Financials!F51 -> 1.03
D42: Returns, Allowances, Discounts | E42: =Financials!F52 -> 0.03
D43: Net Sales $ | E43: =Financials!E53 -> 2700
E44: =Financials!F53 -> 1
B47: INCOME STATEMENT | G47: BALANCE SHEET

Sheet SC2 SPM
A1: STRATEGIC PROFIT MODEL TREE - 'Scenario 2' - 20% Decrease in Warehousing Expense
F2: ROE (Pre-Tax) | G2: =E14*H8*K9 -> 0.26334966
F3: ROE (Post-Tax) | G3: =G6*K9 -> 0.1478248 | H3: =IF(G3<>Financials!H87/Financials!H46,"ERROR","")
F6: ROA | G6: =E9*H8 -> 0.07039276 | H6: =IF(G6<>(Financials!H87/Financials!H28),"ERROR","")
G8: Asset T/O | H8: =E43/H13 -> 2.7
D9: Net Margin | E9: =Financials!I87 -> 0.026071393 | I9: =IF((E43/H13)<>H8,"ERROR","") | J9: Leverage | K9: =H13/K11 -> 2.1
E10: =IF(E14-E11<>E9,"ERROR","")
D11: Taxes & Discnt'd/Extrord | E11: =SUM(Financials!I84:I86) -> 0.020374756 | J11: Total Equity | K11: =Financials!H46 -> 476.19048
E13: =IF(ABS(E44-E37-E32-E27-E23-E18-E16-E14)>0.0001,"ERROR","") | G13: Total Assets $ | H13: =Financials!H28 -> 1000
D14: Pretax Margin | E14: =Financials!I82 -> 0.046446148 | H14: =Financials!I28 -> 1
H15: =IF(H14<>(H17+K17),"ERROR","")
D16: Non-Operating Expense | E16: =Financials!I81 -> -0.006
G17: Total NonCurrent Assets | H17: =Financials!I27 -> 0.114 | J17: Total Current Assets | K17: =Financials!I16 -> 0.886
D18: Interest Expense | E18: =SUM(C19:C21) -> 0.007 | K18: =IF(K17<>(K19+K21+K23+K25),"ERROR","")
B19: General Corporate Interest | C19: =Financials!I78 -> 0.002 | G19: Other NonCurrent Assets | H19: =Financials!I26 -> 0.0285 | J19: Inventory | K19: =Financials!I14 -> 0.485
B20: Warehsng/Distrib Interest | C20: =Financials!I79 -> 0.003
B21: Excess Inventory Interest | C21: =Financials!I80 -> 0.002 | G21: Net Total PP&E | H21: =Financials!I25 -> 0.0855 | J21: Accounts Receivable | K21: =Financials!I13 -> 0.354
H22: =IF(H21<>(H25+H26+H28+H29),"ERROR","")
D23: Depreciation Expense | E23: =SUM(C24:C25) -> 0.004 | J23: Other Current Assets | K23: =Financials!I15 -> 0.022
B24: Genrl Corporate Depreciation | C24: =Financials!I74 -> 0.002
B25: Warehsng/Dist Depreciation | C25: =Financials!I75 -> 0.002 | G25: Warehsng/Dist Gross PP&E | H25: =Financials!I19 -> 0.12825 | J25: Cash, Equiv & ST Inv | K25: =Financials!I12 -> 0.025
G26: Warehsng/Dist Accum Dep | H26: =Financials!I20 -> -0.064125
D27: Selling, Genrl & Admin Expense | E27: =SUM(C28:C30) -> 0.10509333
B28: General SG&A | C28: =Financials!I70 -> 0.066 | E28: =IF((E44-E37)<>E35,"ERROR","") | G28: Other Gross PP&E | H28: =Financials!I22 -> 0.04275
B29: Out-bound Freight | C29: =Financials!I71 -> 0.035093333 | G29: Other Accum Dep | H29: =Financials!I23 -> -0.021375
B30: Customer Service Expense | C30: =Financials!I72 -> 0.004
D32: Warehousing/Distribtn Expense | E32: =SUM(C33:C37) -> 0.091460519
B33: General Warehsng/Dist Exp | C33: =Financials!I60 -> 0.081784593
B34: Public/Leased Facilities Exp | C34: =Financials!I61 -> 0.00089814815
B35: Warehsng/Dist Insurance | C35: =Financials!I63 -> 0.003 | D35: Gross Margin | E35: =E44-E37 -> 0.248
B36: Inventory Insurance | C36: =Financials!I64 -> 0.003
B37: Risk-related inventory CC | C37: =SUM(Financials!I65:I68) -> 0.0027777778 | D37: Cost of Goods Sold | E37: =SUM(C39:C40) -> 0.752
B39: Product Costs | C39: =Financials!I55 -> 0.73696
B40: In-Bound Freight | C40: =Financials!I56 -> 0.01504
D41: Gross Sales | E41: =Financials!I51 -> 1.03
D42: Returns, Allowances, Discounts | E42: =Financials!I52 -> 0.03
D43: Net Sales $ | E43: =Financials!H53 -> 2700
E44: =Financials!I53 -> 1
B47: INCOME STATEMENT | G47: BALANCE SHEET

Sheet SC3 SPM
A1: STRATEGIC PROFIT MODEL TREE - 'Scenario 3' - 20% Decrease in Transportation Expense
F2: ROE (Pre-Tax) | G2: =E14*H8*K9 -> 0.1986012
F3: ROE (Post-Tax) | G3: =G6*K9 -> 0.10897572 | H3: =IF(G3<>Financials!K87/Financials!K46,"ERROR","")
F6: ROA | G6: =E9*H8 -> 0.0518932 | H6: =IF(G6<>(Financials!K87/Financials!K28),"ERROR","")
G8: Asset T/O | H8: =E43/H13 -> 2.7
D9: Net Margin | E9: =Financials!L87 -> 0.019219704 | I9: =IF((E43/H13)<>H8,"ERROR","") | J9: Leverage | K9: =H13/K11 -> 2.1
E10: =IF(E14-E11<>E9,"ERROR","")
D11: Taxes & Discnt'd/Extrord | E11: =SUM(Financials!L84:L86) -> 0.015806963 | J11: Total Equity | K11: =Financials!K46 -> 476.19048
E13: =IF(ABS(E44-E37-E32-E27-E23-E18-E16-E14)>0.0001,"ERROR","") | G13: Total Assets $ | H13: =Financials!K28 -> 1000
D14: Pretax Margin | E14: =Financials!L82 -> 0.035026667 | H14: =Financials!L28 -> 1
H15: =IF(H14<>(H17+K17),"ERROR","")
D16: Non-Operating Expense | E16: =Financials!L81 -> -0.006
G17: Total NonCurrent Assets | H17: =Financials!L27 -> 0.114 | J17: Total Current Assets | K17: =Financials!L16 -> 0.886
D18: Interest Expense | E18: =SUM(C19:C21) -> 0.007 | K18: =IF(K17<>(K19+K21+K23+K25),"ERROR","")
B19: General Corporate Interest | C19: =Financials!L78 -> 0.002 | G19: Other NonCurrent Assets | H19: =Financials!L26 -> 0.0285 | J19: Inventory | K19: =Financials!L14 -> 0.485
B20: Warehsng/Distrib Interest | C20: =Financials!L79 -> 0.003
B21: Excess Inventory Interest | C21: =Financials!L80 -> 0.002 | G21: Net Total PP&E | H21: =Financials!L25 -> 0.0855 | J21: Accounts Receivable | K21: =Financials!L13 -> 0.354
H22: =IF(H21<>(H25+H26+H28+H29),"ERROR","")
D23: Depreciation Expense | E23: =SUM(C24:C25) -> 0.004 | J23: Other Current Assets | K23: =Financials!L15 -> 0.022
B24: Genrl Corporate Depreciation | C24: =Financials!L74 -> 0.002
B25: Warehsng/Dist Depreciation | C25: =Financials!L75 -> 0.002 | G25: Warehsng/Dist Gross PP&E | H25: =Financials!L19 -> 0.12825 | J25: Cash, Equiv & ST Inv | K25: =Financials!L12 -> 0.025
G26: Warehsng/Dist Accum Dep | H26: =Financials!L20 -> -0.064125
D27: Selling, Genrl & Admin Expense | E27: =SUM(C28:C30) -> 0.099074667
B28: General SG&A | C28: =Financials!L70 -> 0.066 | E28: =IF((E44-E37)<>E35,"ERROR","") | G28: Other Gross PP&E | H28: =Financials!L22 -> 0.04275
B29: Out-bound Freight | C29: =Financials!L71 -> 0.028074667 | G29: Other Accum Dep | H29: =Financials!L23 -> -0.021375
B30: Customer Service Expense | C30: =Financials!L72 -> 0.005
D32: Warehousing/Distribtn Expense | E32: =SUM(C33:C37) -> 0.11190667
B33: General Warehsng/Dist Exp | C33: =Financials!L60 -> 0.10223074
B34: Public/Leased Facilities Exp | C34: =Financials!L61 -> 0.00089814815
B35: Warehsng/Dist Insurance | C35: =Financials!L63 -> 0.003 | D35: Gross Margin | E35: =E44-E37 -> 0.251008
B36: Inventory Insurance | C36: =Financials!L64 -> 0.003
B37: Risk-related inventory CC | C37: =SUM(Financials!L65:L68) -> 0.0027777778 | D37: Cost of Goods Sold | E37: =SUM(C39:C40) -> 0.748992
B39: Product Costs | C39: =Financials!L55 -> 0.73696
B40: In-Bound Freight | C40: =Financials!L56 -> 0.012032
D41: Gross Sales | E41: =Financials!L51 -> 1.03
D42: Returns, Allowances, Discounts | E42: =Financials!L52 -> 0.03
D43: Net Sales $ | E43: =Financials!K53 -> 2700
E44: =Financials!L53 -> 1
B47: INCOME STATEMENT | G47: BALANCE SHEET

Sheet SC4 SPM
A1: STRATEGIC PROFIT MODEL TREE - 'Scenario 4' - Combination of Scenarios 1 - 3
F2: ROE (Pre-Tax) | G2: =E14*H8*K9 -> 0.33020736
F3: ROE (Post-Tax) | G3: =G6*K9 -> 0.18997642 | H3: =IF(G3<>Financials!N87/Financials!N46,"ERROR","")
F6: ROA | G6: =E9*H8 -> 0.10018268 | H6: =IF(G6<>(Financials!N87/Financials!N28),"ERROR","")
G8: Asset T/O | H8: =E43/H13 -> 2.9900332
D9: Net Margin | E9: =Financials!O87 -> 0.033505541 | I9: =IF((E43/H13)<>H8,"ERROR","") | J9: Leverage | K9: =H13/K11 -> 1.8963
E10: =IF(E14-E11<>E9,"ERROR","")
D11: Taxes & Discnt'd/Extrord | E11: =SUM(Financials!O84:O86) -> 0.024732089 | J11: Total Equity | K11: =Financials!N46 -> 476.19048
E13: =IF(ABS(E44-E37-E32-E27-E23-E18-E16-E14)>0.0001,"ERROR","") | G13: Total Assets $ | H13: =Financials!N28 -> 903
D14: Pretax Margin | E14: =Financials!O82 -> 0.05823763 | H14: =Financials!O28 -> 1
H15: =IF(H14<>(H17+K17),"ERROR","")
D16: Non-Operating Expense | E16: =Financials!O81 -> -0.006
G17: Total NonCurrent Assets | H17: =Financials!O27 -> 0.12624585 | J17: Total Current Assets | K17: =Financials!O16 -> 0.87375415
D18: Interest Expense | E18: =SUM(C19:C21) -> 0.0066 | K18: =IF(K17<>(K19+K21+K23+K25),"ERROR","")
B19: General Corporate Interest | C19: =Financials!O78 -> 0.002 | G19: Other NonCurrent Assets | H19: =Financials!O26 -> 0.031561462 | J19: Inventory | K19: =Financials!O14 -> 0.42967885
B20: Warehsng/Distrib Interest | C20: =Financials!O79 -> 0.003
B21: Excess Inventory Interest | C21: =Financials!O80 -> 0.0016 | G21: Net Total PP&E | H21: =Financials!O25 -> 0.094684385 | J21: Accounts Receivable | K21: =Financials!O13 -> 0.39202658
H22: =IF(H21<>(H25+H26+H28+H29),"ERROR","")
D23: Depreciation Expense | E23: =SUM(C24:C25) -> 0.004 | J23: Other Current Assets | K23: =Financials!O15 -> 0.024363234
B24: Genrl Corporate Depreciation | C24: =Financials!O74 -> 0.002
B25: Warehsng/Dist Depreciation | C25: =Financials!O75 -> 0.002 | G25: Warehsng/Dist Gross PP&E | H25: =Financials!O19 -> 0.14202658 | J25: Cash, Equiv & ST Inv | K25: =Financials!O12 -> 0.027685493
G26: Warehsng/Dist Accum Dep | H26: =Financials!O20 -> -0.071013289
D27: Selling, Genrl & Admin Expense | E27: =SUM(C28:C30) -> 0.098074667
B28: General SG&A | C28: =Financials!O70 -> 0.066 | E28: =IF((E44-E37)<>E35,"ERROR","") | G28: Other Gross PP&E | H28: =Financials!O22 -> 0.047342193
B29: Out-bound Freight | C29: =Financials!O71 -> 0.028074667 | G29: Other Accum Dep | H29: =Financials!O23 -> -0.023671096
B30: Customer Service Expense | C30: =Financials!O72 -> 0.004
D32: Warehousing/Distribtn Expense | E32: =SUM(C33:C37) -> 0.090095704
B33: General Warehsng/Dist Exp | C33: =Financials!O60 -> 0.081784593
B34: Public/Leased Facilities Exp | C34: =Financials!O61 -> 0.00071851852
B35: Warehsng/Dist Insurance | C35: =Financials!O63 -> 0.0029703704 | D35: Gross Margin | E35: =E44-E37 -> 0.251008
B36: Inventory Insurance | C36: =Financials!O64 -> 0.0024
B37: Risk-related inventory CC | C37: =SUM(Financials!O65:O68) -> 0.0022222222 | D37: Cost of Goods Sold | E37: =SUM(C39:C40) -> 0.748992
B39: Product Costs | C39: =Financials!O55 -> 0.73696
B40: In-Bound Freight | C40: =Financials!O56 -> 0.012032
D41: Gross Sales | E41: =Financials!O51 -> 1.03
D42: Returns, Allowances, Discounts | E42: =Financials!O52 -> 0.03
D43: Net Sales $ | E43: =Financials!N53 -> 2700
E44: =Financials!O53 -> 1
B47: INCOME STATEMENT | G47: BALANCE SHEET

Sheet Composition Graphs
B1: TYPICAL WHOLESALER
A2: BALANCE SHEET | B2: % | C2: $
A3: Cash & Equivalents | B3: =Financials!C12 -> 0.025
A4: Accounts Receivables | B4: =Financials!C13 -> 0.354
A5: Inventory | B5: =Financials!C14 -> 0.485
A6: Other Current | B6: =Financials!C15 -> 0.022
A7: NonCurrent-Fixed Assets & Other | B7: =SUM(Financials!C25:C26) -> 0.114
A8: TOTAL ASSETS | B8: =SUM(B3:B7) -> 1
A10: INCOME STATEMENT - % of Gross Sales
A11: Gross Sales | C11: =Financials!B51 -> 2781
A12: Cost of Goods Sold | C12: =SUM(Financials!B55:B56) -> 2030.4
A13: Gross Sales (net of COGS) | C13: =C11-C12 -> 750.6
A14: Returns and Allowances | B14: =C14/$C$13 -> 0.10791367 | C14: =Financials!B52 -> 81
A15: Warehousing Expense | B15: =C15/$C$13 -> 0.36773648 | C15: =Financials!B60 -> 276.023
A16: Insurance & Obsolescence | B16: =C16/$C$13 -> 0.02624567 | C16: =SUM(Financials!B63:B65) -> 19.7
A17: Sales, General & Admin | B17: =C17/$C$13 -> 0.3816307 | C17: =SUM(Financials!B70:B72) -> 286.452
A18: Depreciation | B18: =C18/$C$13 -> 0.014388489 | C18: =SUM(Financials!B74:B75) -> 10.8
A19: Interest & Non-Operating | B19: =C19/$C$13 -> 0.0035971223 | C19: =SUM(Financials!B78:B81) -> 2.7
A20: Pretax Income | B20: =C20/$C$13 -> 0.089928058 | C20: =Financials!B82 -> 67.5
A23: Gross Sales | B23: =Financials!C51 -> 1.03
A24: Returns and Allowances | B24: =Financials!C52 -> 0.03
A25: Net Sales | B25: =B23-B24 -> 1
A26: Cost of Goods Sold | B26: =SUM(Financials!C55:C56) -> 0.752
A27: Gross Profit | B27: =B25-B26 -> 0.248
A28: Warehousing Expense | B28: =SUM(Financials!C60:C61) -> 0.10312889
A29: Insurance & Inv Carrying Costs | B29: =SUM(Financials!C63:C68) -> 0.0087777778
A30: Sales, General & Admin | B30: =SUM(Financials!C70:C72) -> 0.10609333
A31: Depreciation | B31: =SUM(Financials!C74:C75) -> 0.004
A32: Interest & Non-Operating | B32: =SUM(Financials!C78:C81) -> 0.001
A33: Pretax Income | B33: =Financials!C82 -> 0.025

Sheet Sheet3
