Workbook

Sheet Overview
A2: Profits and Cash Flow | E2: Monthly | F2: Yearly
B3: 1.Source of Revenues | E3: =SUM(Summary!H15) -> #DIV/0! | F3: =SUM(Summary!I15) -> #DIV/0!
B4: 2.Operating Costs | E4: =SUM(Summary!H29) -> #DIV/0! | F4: =SUM(Summary!I29) -> #DIV/0!
B5: 4. Net Profits | E5: =SUM(Summary!H31) -> #DIV/0! | F5: =SUM(Summary!I31) -> #DIV/0!
B6: 5. Value | C6: 1.5 | F6: =SUM(F5*C6) -> #DIV/0!
A8: Assets
B9: 1.Technology | F9: =SUM(Summary!H39) -> 0
B10: 2. Value of Content | F10: =SUM(Assests!E54) -> 0
B11: 3.Branding | F11: =SUM(Assests!E31) -> 0
B12: 4.Databases | F12: =SUM(Summary!H70) -> 0
A14: Traffic
B15: Value of traffic | E15: =SUM(Traffic!B45) -> 0 | F15: =SUM(Traffic!C45) -> 0
B16: Value of links | F16: =SUM(Summary!H79) -> #DIV/0!
B18: Book Value | F18: =SUM(F6) -> #DIV/0!
B19: Internet Value | F19: =SUM(F9:F12,F15:F17,F16,F17,F16) -> #DIV/0!
A21: Total | F21: =SUM(F18:F19) -> #DIV/0!

Sheet Summary
A2: Profits and Cash Flow
A4: Sources of Revenue | H4: Monthly | I4: Yearly
A5: a.Monthly products / services sales | H5: =SUM(Revenues!C4) -> #DIV/0! | I5: =SUM(H5*12) -> #DIV/0!
A6: b.Monthly membership dues | H6: =SUM(Revenues!C5) -> #DIV/0! | I6: =SUM(H6*12) -> #DIV/0!
A7: c.Commissions from other sources | H7: =SUM(Revenues!C6) -> #DIV/0! | I7: =SUM(H7*12) -> #DIV/0!
A8: d.Revenue from partnership deals | H8: =SUM(Revenues!C7) -> #DIV/0! | I8: =SUM(H8*12) -> #DIV/0!
A9: e.Subscription | H9: =SUM(Revenues!C8) -> #DIV/0! | I9: =SUM(H9*12) -> #DIV/0!
A10: f.Ancilliary | H10: =SUM(Revenues!C7) -> #DIV/0! | I10: =SUM(H10*12) -> #DIV/0!
A11: g.Advertising Revenue | H11: =SUM(Revenues!C10) -> #DIV/0! | I11: =SUM(H11*12) -> #DIV/0!
A12: Advertising available | H12: =SUM(Revenues!C11) -> #DIV/0! | I12: =SUM(H12*12) -> #DIV/0!
A13: Sell through rate | H13: =SUM(Revenues!C12) -> #DIV/0! | I13: =SUM(H13*12) -> #DIV/0!
A15: Total Income | H15: =SUM(Revenues!C14) -> #DIV/0! | I15: =SUM(H15*12) -> #DIV/0!
A18: Expenses
A19: Monthly server cost | H19: =SUM(Revenues!C18) -> #DIV/0! | I19: =SUM(H19*12) -> #DIV/0!
A20: Monthly hosting | H20: =SUM(Revenues!C19) -> #DIV/0! | I20: =SUM(H20*12) -> #DIV/0!
A21: Monthly fees | H21: =SUM(Revenues!C20) -> #DIV/0! | I21: =SUM(H21*12) -> #DIV/0!
A22: Monthly bandwidth excess charges | H22: =SUM(Revenues!C21) -> #DIV/0! | I22: =SUM(H22*12) -> #DIV/0!
A23: Staff | H23: =SUM(Revenues!C22) -> #DIV/0! | I23: =SUM(H23*12) -> #DIV/0!
A24: Owner time | H24: =SUM(Revenues!C23) -> #DIV/0! | I24: =SUM(H24*12) -> #DIV/0!
A25: Monthly outside labor | H25: =SUM(Revenues!C24) -> #DIV/0! | I25: =SUM(H25*12) -> #DIV/0!
A26: Monthly Advertising | H26: =SUM(Revenues!C25) -> #DIV/0! | I26: =SUM(H26*12) -> #DIV/0!
A27: Office | H27: =SUM(Revenues!C26) -> 0 | I27: =SUM(H27*12) -> 0
A29: Total Expenses | H29: =SUM(Revenues!C28) -> #DIV/0! | I29: =SUM(H29*12) -> #DIV/0!
A31: Net Profit | H31: =SUM(H15-H29) -> #DIV/0! | I31: =SUM(H31*12) -> #DIV/0!
A33: Assets
A35: Technology | B35: a.Hardware included | H35: =SUM(Assests!E8) -> 0
B36: b.Software included | H36: =SUM(Assests!E15) -> 0
B37: c.Rights included with the site (hosting, access) | H37: =SUM(Assests!E21) -> 0
B39: Total Technology | H39: =SUM(H35:H37) -> 0
A41: Branding | B41: a.Value of domain name | H41: =SUM(Assests!D26) -> 0
B42: b.Trademarks | H42: =SUM(Assests!D27) -> 0
B43: c.How long around | H43: =SUM(Assests!D28) -> 0
B44: d.Good will | H44: =SUM(Assests!D29) -> 0
A46: Content
B47: Number of original Pages | H47: =SUM(Assests!E37) -> 0
B48: Number of Pages | H48: =SUM(Assests!E38) -> 0
B49: Value per page | H49: =SUM(Assests!E39) -> 0
B51: Value of Pages | H51: =SUM(Assests!E41) -> 0
B54: Number of Graphics | H54: =SUM(Assests!E44) -> 0
B55: Value per Graphic | H55: =SUM(Assests!E45) -> 0
...

Sheet Links
B2: Average | D2: Own Stats | E2: Alta Vista | F2: Infoseek | G2: HotBot
A3: Number of links to Site | B3: =AVERAGE(D3:G3) -> #DIV/0!
A6: Value of each link in ($/yr)
A7: Value based on link $ | B7: =SUM(B3*B6) -> #DIV/0!
A9: Average views of each link / year
A10: CPM Value
A11: Link value based on impressions | B11: =SUM(B3*B9/1000*B10) -> #DIV/0!
B14: Alta | C14: Yahoo | D14: HotBot | E14: Lycos | F14: Excite | G14: AOL | H14: Info | I14: Webcrawl | K14: Total
A15: Traffic from Search Engines | B15: =SUM(C27) -> #DIV/0! | C15: =SUM(D27) -> #DIV/0! | D15: =SUM(E27) -> #DIV/0! | E15: =SUM(F27) -> #DIV/0! | F15: =SUM(G27) -> #DIV/0! | G15: =SUM(H27) -> #DIV/0! | H15: =SUM(I27) -> #DIV/0! | I15: =SUM(J27) -> #DIV/0! | K15: =SUM(L27) -> #DIV/0!
A16: Percentage links / search | B16: =SUM(B15/Traffic!B13) -> #DIV/0! | C16: =SUM(C15/Traffic!B13) -> #DIV/0! | D16: =SUM(D15/Traffic!B13) -> #DIV/0! | E16: =SUM(E15/Traffic!B13) -> #DIV/0! | F16: =SUM(F15/Traffic!B13) -> #DIV/0! | G16: =SUM(G15/Traffic!B13) -> #DIV/0! | H16: =SUM(H15/Traffic!B13) -> #DIV/0! | I16: =SUM(I15/Traffic!B13) -> #DIV/0! | K16: =SUM(K15/Traffic!B13) -> #DIV/0!
A18: Total Pages of traffic
A21: Sample of Visitors by Engine | B21: Sample | C21: Alta | D21: Yahoo | E21: HotBot | F21: Lycos | G21: Excite | H21: AOL | I21: Info | J21: Webcrawl | L21: Total
B22: Last Month | L22: =SUM(C22:J22) -> 0
B23: Month 2 | L23: =SUM(C23:J23) -> 0
B24: Month 3 | L24: =SUM(C24:J24) -> 0
B25: Month 4
B26: Month 5
B27: Average | C27: =AVERAGE(C22:C26) -> #DIV/0! | D27: =AVERAGE(D22:D26) -> #DIV/0! | E27: =AVERAGE(E22:E26) -> #DIV/0! | F27: =AVERAGE(F22:F26) -> #DIV/0! | G27: =AVERAGE(G22:G26) -> #DIV/0! | H27: =AVERAGE(H22:H26) -> #DIV/0! | I27: =AVERAGE(I22:I26) -> #DIV/0! | J27: =AVERAGE(J22:J26) -> #DIV/0! | L27: =SUM(C27:J27) -> #DIV/0!

Sheet Traffic
B2: Daily | C2: Monthly | E2: Yearly | F2: Yearly on Mo.
A3: Unique IPs per day | C3: =SUM(B3*30) -> 0 | E3: =SUM(B3*365) -> 0 | F3: =SUM(C3*12) -> 0
A4: Pages per day | C4: =SUM(B4*30) -> 0 | E4: =SUM(B4*365) -> 0 | F4: =SUM(C4*12) -> 0
A5: People / Pages Ratio | B5: =SUM(B4/B3) -> #DIV/0! | C5: =SUM(C4/C3) -> #DIV/0! | E5: =SUM(E4/E3) -> #DIV/0! | F5: =SUM(F4/F3) -> #DIV/0!
A7: CPM High
A8: CPM Mid
A9: CPM Low
O10: Projections
B11: Average | C11: 35521 | D11: 35551 | E11: 35582 | F11: 35612 | G11: 35643 | H11: 35674 | I11: 35704 | J11: 35735 | K11: 35765 | L11: 35796 | M11: 35827 | N11: 35855 | O11: 35886 | P11: 35916
A12: Pages | B12: =AVERAGE(C12:N12) -> #DIV/0!
A13: People | B13: =AVERAGE(C13:N13) -> #DIV/0!
A16: Traffic Growth Pages | B16: =AVERAGE(C16:N16) -> #DIV/0! | D16: =SUM((D12-C12)/C12) -> #DIV/0! | E16: =SUM((E12-D12)/D12) -> #DIV/0! | H16: =SUM((H12-G12)/G12) -> #DIV/0! | I16: =SUM((I12-H12)/H12) -> #DIV/0! | J16: =SUM((J12-I12)/I12) -> #DIV/0! | K16: =SUM((K12-J12)/J12) -> #DIV/0! | L16: =SUM((L12-K12)/K12) -> #DIV/0! | M16: =SUM((M12-L12)/L12) -> #DIV/0! | N16: =SUM((N12-M12)/M12) -> #DIV/0!
A17: Traffic Growth People | B17: =AVERAGE(C17:N17) -> #DIV/0! | D17: =SUM((D13-C13)/C13) -> #DIV/0! | E17: =SUM((E13-D13)/D13) -> #DIV/0! | H17: =SUM((H13-G13)/G13) -> #DIV/0! | I17: =SUM((I13-H13)/H13) -> #DIV/0! | J17: =SUM((J13-I13)/I13) -> #DIV/0! | K17: =SUM((K13-J13)/J13) -> #DIV/0! | L17: =SUM((L13-K13)/K13) -> #DIV/0! | M17: =SUM((M13-L13)/L13) -> #DIV/0! | N17: =SUM((N13-M13)/M13) -> #DIV/0!
A19: Sell through Rate
B21: Monthly | C21: Yearly
A22: Traffic Value High | B22: =SUM(B7*C4/1000) -> 0 | C22: =SUM(B22*12) -> 0
A23: Traffic Value Mid | B23: =SUM(B8*C4/1000) -> 0 | C23: =SUM(B23*12) -> 0
A24: Traffic Value Low | B24: =SUM(B9*C4/1000) -> 0 | C24: =SUM(B24*12) -> 0
B26: Monthly Adjusted | C26: (Value x sellthrough)
A27: Traffic Value High | B27: =SUM(B22*B19) -> 0
A28: Traffic Value Mid | B28: =SUM(B23*B19) -> 0
A29: Traffic Value Low | B29: =SUM(B24*B19) -> 0
A32: Mailing List
A33: Other Traffic
A34: Subscribers in List
A35: Mailings per mo
A36: Total monthly mailings | B36: =SUM(B34*B35) -> 0
A38: Automatic msgs x mo.
A40: Monthly Mailings
A42: Total Monthly Impressions | C42: =SUM(B36,C4,B38,B40) -> 0
B44: Monthly | C44: Yearly
A45: Traffic Value High | B45: =SUM(B7*C42/1000) -> 0 | C45: =SUM(B45*12) -> 0
A46: Traffic Value Mid | B46: =SUM(B8*C42/1000) -> 0 | C46: =SUM(B46*12) -> 0
A47: Traffic Value Low | B47: =SUM(B9*C42/1000) -> 0 | C47: =SUM(B47*12) -> 0

Sheet Revenues
A2: Source of Revenues
C3: Average | D3: Last Month | E3: 2 | F3: 3 | G3: 4 | H3: 5 | I3: 6 | J3: 7 | K3: 8 | L3: 9 | M3: 10 | N3: 11 | O3: 12
A4: a.Monthly products / services sales | C4: =AVERAGE(D4:H4) -> #DIV/0!
A5: b.Monthly membership dues | C5: =AVERAGE(D5:H5) -> #DIV/0!
A6: c.Commissions from other sources | C6: =AVERAGE(D6:H6) -> #DIV/0!
A7: d.Revenue from partnership deals | C7: =AVERAGE(D7:H7) -> #DIV/0!
A8: e.Subscription | C8: =AVERAGE(D8:H8) -> #DIV/0!
A9: f.Ancilliary | C9: =AVERAGE(D9:H9) -> #DIV/0!
A10: g.Advertising Revenue | C10: =AVERAGE(D10:H10) -> #DIV/0!
A11: Advertising available | C11: =AVERAGE(D11:H11) -> #DIV/0!
A12: Sell through rate | C12: =AVERAGE(D12:H12) -> #DIV/0! | D12: =SUM(D10/D11) -> #DIV/0! | E12: =SUM(E10/E11) -> #DIV/0! | F12: =SUM(F10/F11) -> #DIV/0! | G12: =SUM(G10/G11) -> #DIV/0! | H12: =SUM(H10/H11) -> #DIV/0!
A14: Total Revenues | C14: =SUM(C4:C10) -> #DIV/0! | D14: =SUM(D4:D10) -> 0 | E14: =SUM(E4:E10) -> 0 | F14: =SUM(F4:F10) -> 0 | G14: =SUM(G4:G10) -> 0 | H14: =SUM(H4:H10) -> 0
A16: Operating Costs
C17: Average | D17: Last Month | E17: -2 | F17: -3 | G17: -4 | H17: -5 | I17: -6
A18: Monthly server cost | C18: =AVERAGE(D18:I18) -> #DIV/0!
A19: Monthly hosting | C19: =AVERAGE(D19:I19) -> #DIV/0!
A20: Monthly fees | C20: =AVERAGE(D20:I20) -> #DIV/0!
A21: Monthly bandwidth excess charges | C21: =AVERAGE(D21:I21) -> #DIV/0!
A22: Staff | C22: =AVERAGE(D22:I22) -> #DIV/0!
A23: Owner time | C23: =AVERAGE(D23:I23) -> #DIV/0!
A24: Monthly outside labor | C24: =AVERAGE(D24:I24) -> #DIV/0!
A25: Monthly Advertising | C25: =AVERAGE(D25:I25) -> #DIV/0!
A26: Office
A28: Total Costs | C28: =SUM(C18:C26) -> #DIV/0! | D28: =SUM(D18:D26) -> 0 | E28: =SUM(E18:E26) -> 0 | F28: =SUM(F18:F26) -> 0 | G28: =SUM(G18:G26) -> 0 | H28: =SUM(H18:H26) -> 0 | I28: =SUM(I18:I26) -> 0
A30: Total spent from start

Sheet Assests
A1: Technology
A3: Hardware
B4: Server
B5: Other HW
C8: Total Hardware | E8: =SUM(D4:D5) -> 0
A10: Software
B11: Custom CGI
B12: Off Shelf Software
B13: Ad Delivery Software
C15: Total Software | E15: =SUM(D11) -> 0
A17: Rights included with site
B18: Access
B19: Bandwidth
C21: Total Rights | E21: =SUM(D18:D19) -> 0
B23: Total Technology | E23: =SUM(E8:E17) -> 0
A25: Branding
B26: a.Value of domain name
B27: b.Trademarks
B28: c.How long around
B29: d.Good will
B31: Total Branding | E31: =SUM(D26:D29) -> 0
A33: Total Assets | E33: =SUM(E23,E31,E62,E67) -> 0
A35: 2.Content
A37: Number of original Pages
A38: Number of Pages
A39: Value per page
A41: Value of Pages | E41: =SUM(E38*E39) -> 0
A44: Number of Graphics
A45: Value per Graphic
A47: Value of Graphics | E47: =SUM(E44*E45) -> 0
A49: Value of each link out
A50: Number of links out
A52: Value of links out | E52: =SUM(E49*E50) -> 0
A54: Total Content Value | E54: =SUM(E41,E47) -> 0
A56: Databases
A58: E-mail Dbase | B58: a.Dbase of e-mails of previous visitors
B59: b.Database of past customer | E59: 0
B61: Value of each name
B62: Value of database | E62: =SUM(E58*E61) -> 0
A63: Other Databases
...

Sheet Instructions
C4: This is an early "beta" version of an Excel template that can
C5: help in valuing an already existing web site. It was written
C6: as an Excel spreadsheet, but I am sure that other programs
C7: should be able to convert Excel spreadsheets to their own
C8: format. It is based on the article about web site valuation
C9: we have written.
C11: You will find no other instructions on the template itself,
C12: but it is fairly self explanatory (at least to us). Basically,
C13: you should enter the the numbers in the fields that are "green".
C14: The numbers in red are automatically calculated based on the
C15: numbers elsewhere. The first two pages (Overview and Summary)
C16: are based on the information and numbers on the other pages
... C33: information should not be relied on without proper advice.

Sheet Sheet10

Sheet Sheet11

Sheet Sheet12

Sheet Sheet13

Sheet Sheet14

Sheet Sheet15

Sheet Sheet16
