Workbook

Sheet Summary
C1: SAMPLE
A3: Region XI Spring Conference
A4: Jackson, MS
A6: BUDGET/FINANCIAL REPORT
A8: DO NOT ENTER ANY NUMBERS IN THIS PAGE
A9: ALL COLUMNS ARE LINKED TO APPROPRIATE
A10: TOTAL ON ACCOMPANYING SPREADSHEETS
A15: Income | B15: Budget | C15: Actual
A16: Registration Fees | B16: =SUM(Income!B16) -> 11675 | C16: =SUM(Income!C16) -> 0
A17: Donations | B17: =SUM(Income!B21) -> 200 | C17: =SUM(Income!C21) -> 200
A18: Booth Sales | B18: =SUM(Income!B33) -> 0 | C18: =SUM(Income!C33) -> 0
A19: Advertising | B19: =SUM(Income!B40) -> 0 | C19: =SUM(Income!C40) -> 0
A20: Section Allocation Percentage | B20: =SUM(Income!B42) -> 3793.5 | C20: =SUM(Income!C42) -> 0
A21: Other | B21: =SUM(Income!B49) -> 2000 | C21: =SUM(Income!C49) -> 0
A22: Total Income | B22: =SUM(B16:B21) -> 17668.5 | C22: =SUM(C16:C21) -> 200
A24: Expenses | B24: Budget | C24: Actual
A25: Room Rental | B25: =SUM(Expenses!C14) -> 1750 | C25: =SUM(Expenses!D14) -> 0
A26: A/V Equipment | B26: =SUM(Expenses!C31) -> 3800 | C26: =SUM(Expenses!D31) -> 0
A27: Food Service | B27: =SUM(Expenses!C53) -> 21311.85 | C27: =SUM(Expenses!D53) -> 0
A28: Transportation | B28: =SUM(Expenses!C59) -> 200 | C28: =SUM(Expenses!D59) -> 0
A29: Printing | B29: =SUM(Expenses!C64) -> 2250 | C29: =SUM(Expenses!D64) -> 0
A30: Other | B30: =SUM(Expenses!C77) -> 5225 | C30: =SUM(Expenses!D77) -> 0
A31: Total Expenses | B31: =SUM(B25:B30) -> 34536.85 | C31: =SUM(C25:C30) -> 0
A33: Balance (Income - Expenses) | B33: =SUM(B22-B31) -> -16868.35 | C33: =SUM(C22-C31) -> 200
A36: Estimated Cost Per Person (Base = 230 persons) | B36: =SUM(B31/230) -> 150.16022

Sheet Income
A1: Region XI Spring Conference | D1: SAMPLE
A2: Jackson, MS
A4: BUDGET/FINANCIAL REPORT
A6: Income | B6: Budget | C6: Actual | D6: Comments
A8: Registration Fees
A9: RAC Delegates | B9: =40*90 -> 3600 | D9: 40 at $90 each (Budget)
A10: SSA's | B10: =10*90 -> 900 | D10: 10 at $90 each (Budget)
A11: Guests | B11: =15*45 -> 675 | D11: 15 at $45 each (Budget)
A12: Students | B12: =125*45 -> 5625 | D12: 125 at $45 each (Budget)
A13: GSTC | B13: =15*45 -> 675 | D13: 15 at $45 each (Budget)
A14: Other (Tours, Etc) | B14: =10*20 -> 200 | D14: 10 at $20 each (Budget)
A15: RSC/RAC Delegates | B15: =15*130 -> 1950 | D15: 15 at $130 each (Budget)
A16: Total Registration Fees | B16: =SUM(B9:B14) -> 11675 | C16: =SUM(C9:C14) -> 0
A18: Donations
A19: ASME International (CMA) | B19: 200 | C19: 200 | D19: Give these recognition in the program
A21: Total Donations | B21: =SUM(B19:B20) -> 200 | C21: =SUM(C19:C20) -> 200
A23: Booth Sales
A24: ABC Company | D24: These should all get (at minimum):
A25: JKL Company | D25: Booth and/or Table
A26: XYZ Company | D26: Ad in Program
A27: DEF Company
A28: GHI Company
A29: MNO Company
A30: PQR Company
A31: STU Company
A33: Total Booth Sales | B33: =SUM(B23:B32) -> 0 | C33: =SUM(C23:C32) -> 0
A35: Advertising
A36: AAA Company
A37: BBB Company
A38: CCC Company
A40: Total Advertising | B40: =SUM(B35:B39) -> 0 | C40: =SUM(C35:C39) -> 0
A42: Ten Percent Allocation | B42: 3793.5 | C42: 0 | D42: Budget 75% of Possible $5,058.00
A44: Other
A45: Dinner Only (Saturday) | D45: 10 at $15 each
A46: MMM Company (Sponsor Lunch on Friday) | D46: Ad in Program plus Big Sign in lunch area
A47: PreConference Tour and Optional Spouse Tour | B47: =100*20 -> 2000 | D47: 100 at $20 each (Charge ACTUAL COST)
A49: Total Other | B49: =SUM(B45:B48) -> 2000 | C49: =SUM(C45:C48) -> 0
A51: Total Income | B51: =SUM(B16+B21+B33+B40+B49) -> 13875 | C51: =SUM(C16+C21+C33+C40+C49) -> 200
A54: Non-Monetary Donations - Recognize the following in Program
A56: GGG Movie Theatres | B56: 10 Movie Tickets | D56: Give these a small ad (at no charge) in
...

Sheet Expenses
A1: Region XI Spring Conference | E1: SAMPLE
A2: Jackson, MS
A4: BUDGET/FINANCIAL REPORT
A10: Expenses | C10: Budget | D10: Actual | E10: Comments
A11: Room Rental
A12: Hilton by Contract | C12: 1750
A14: Room Rental | C14: =SUM(C12:C13) -> 1750 | D14: =SUM(D12:D13) -> 0
A16: A/V Equipment
A17: Thursday | B17: Reception | C17: 0
A19: Friday | B19: RSC | C19: 1500
A20: Friday | B20: Lunch | C20: 100
A21: Friday | B21: Dinner | C21: 100
A22: Friday | B22: SDC | C22: 100
A24: Saturday | B24: RAC/RSC | C24: 1500
A25: Saturday | B25: GSTC | C25: 300
A26: Saturday | B26: Lunch | C26: 200
A27: Saturday | B27: Dinner | C27: 0
A29: Sunday | B29: RAC | C29: 200
A31: A/V Equipment | C31: =SUM(C17:C27) -> 3800 | D31: =SUM(D17:D27) -> 0
A33: Food Service
A34: Thursday | B34: Reception | C34: 2000 | E34: Chips/Dips/Sodas/Snacks
A36: Friday | B36: Breakfast | C36: =165*10.31 -> 1701.15 | E36: 165 at $10.31 each
A37: Friday | B37: Morning Break - RSC | C37: =165*3 -> 495 | E37: 165 at 3.00 each
A38: Friday | B38: Lunch - RSC | C38: =165*17.5 -> 2887.5 | E38: 165 at $17.50 each
A39: Friday | B39: Afternoon Break - RSC | C39: =165*5 -> 825 | E39: 165 at $5.00 each
B40: Consider Using All Day Pkg at $22.95++)($28.68 each)
A41: Friday | B41: Dinner (All) | C41: =220*26.25 -> 5775 | E41: 220 at $26.25 each
A42: Friday | B42: Comp Meals | C42: 300 | E42: Judges/Vendors/Special Guests
A44: Saturday | B44: Breakfast | C44: =220*10.31 -> 2268.2 | E44: 220 at $10.31 each
A45: Saturday | B45: Morning Break - All | C45: =220*3 -> 660 | E45: 220 at 3.00 each
A46: Saturday | B46: Lunch - All | C46: =220*17.5 -> 3850 | E46: 220 at $17.50 each
A47: Saturday | B47: Afternoon Break - All | C47: =50*5 -> 250 | E47: 50 at $5.00 each
A48: Saturday | B48: Dinner - RAC | C48: 0 | E48: Dutch Treat
A49: Saturday | B49: Comp Meals | C49: 300 | E49: Judges/Vendors/Special Guests
A51: Sunday | B51: Breakfast RAC | C51: =55*10.31 -> 567.05 | E51: 55 at $10.31 each
A53: Food Service | C53: =SUM(C34:C49) -> 21311.85 | D53: =SUM(D34:D49) -> 0
B54: Note: Don't forget to factor in service/tip/gratuity charge into all functions as necessary.
A56: Transportation
A57: Spouse Program/Plant Tour | C57: 200 | E57: Possibly may need to rent a couple vans
A59: Transportation | C59: =SUM(C57:C58) -> 200 | D59: =SUM(D57:D58) -> 0
...
